Workbook
Name partner_id: Configuracion!$B$332

Sheet Configuracion
F1: CUIT | G1: Cargar sin guiones
F2: RAZON SOCIAL | G2: Maximo 30 caracteres
A3: CUIT | B3: RAZON SOCIAL | C3: DETALLE | F3: DETALLE | G3: Cargar tipo de gasto
A4: 30628205090 | B4: ALBAMIE SA | C4: CLIENTE
A5: 30711678820 | B5: 2PSI INGENIERIA SRL | C5: PROVEEDOR
A6: 33716367539 | B6: 3PI S.A.S. | C6: PROVEEDOR
A7: 30660373108 | B7: ABC SA | C7: VARIOS
A8: 20300210881 | B8: ABOY DIEGO OSCAR | C8: PROVEEDOR
A9: 27229910782 | B9: ABUGAUCH MARIA DE LOS ANGELES | C9: PROVEEDOR
A10: 20242709897 | B10: ABUGAUCH VICTOR HUGO | C10: PROVEEDOR
A11: 20281669053 | B11: ACOSTA JAVIER GUSTAVO | C11: FLETE
A12: 20174240125 | B12: ACOSTA OSCAR ISIDRO | C12: VARIOS
A13: 30641659106 | B13: AGRISOL SA | C13: VARIOS
A14: 33709914109 | B14: ALAN COLLECTION SA | C14: VARIOS
A15: 20267161616 | B15: ALBAJARI DIEGO MARCOS | C15: VARIOS
... A155: 30537679855 | B155: ESTACION LIMA SA | C155: VARIOS
A156: 30-56864959-8 | B156: EXPRESO BISONTE SRL | C156: FLETE
A157: 30708542349 | B157: EXPRESO FORMOSA SRL | C157: FLETE
A158: 30526582884 | B158: EXPRESO MAR DEL PLATA SA | C158: FLETE
A159: 30577744579 | B159: EXPRESO TROLE SRL | C159: FLETE
A160: 30715949292 | B160: EYPAPEL SAS | C160: GASTOS VARIOS
A161: 30715980807 | B161: FABORT SRL | C161: PROVEEDOR
A162: 20359718765 | B162: FAIL ABRAHAM | C162: VARIOS
A163: 30643518364 | B163: FARMACIA DE MEDRANO SCS | C163: PROVEEDOR
A164: 30692138747 | B164: FARMACITY SA | C164: VARIOS
A165: 33712234429 | B165: FEDAGAS SA | C165: VARIOS
A166: 20353576012 | B166: FEDERICO PABLO FEOLA | C166: VARIOS
A167: 20343766441 | B167: FERNANDEZ MAURO | C167: TALLER
A168: 27062343449 | B168: FERREIRA LILIANA INES | C168: FLETE
... A530: 30606274161 | B530: EGESAC SA | C530: CLIENTE

Sheet Julio 
A1: ORTOPEDIA GEMINIS S.A. | J1: 45108
A4: LIBRO IVA COMPRAS
A6: FACTURAS A
A7: FECHA | B7: PTO VTA | C7: FAC A | D7: CUIT | E7: RAZON SOCIAL | F7: NETO | G7: IVA 21% | H7: IVA 27% | I7: IVA 10,5% | J7: P IVA | K7: IIBB CF | L7: IIBB BS | M7: NO GRAV | N7: OTROS | O7: TOTAL | P7: DETALLE
A8: 19/07/2023 | B8: 4 | C8: 1241 | D8: 20224819049 | E8: =VLOOKUP(D8,Configuracion!$A$4:$C$591,2,FALSE) -> ALFONSO BOAVENTURA | F8: 29008.27 | G8: =F8*21% -> 6091.7367 | O8: =SUM(F8:N8) -> 35100.007 | P8: =VLOOKUP(D8,Configuracion!$A$4:$C$591,3,FALSE) -> VARIOS
A9: 31/07/2023 | B9: 8 | C9: 1493 | D9: 30708973501 | E9: =VLOOKUP(D9,Configuracion!$A$4:$C$591,2,FALSE) -> ASIAL SRL | F9: 290825 | G9: =F9*21% -> 61073.25 | O9: =SUM(F9:N9) -> 351898.25 | P9: =VLOOKUP(D9,Configuracion!$A$4:$C$591,3,FALSE) -> INSUMOS
A10: 31/07/2023 | B10: 8 | C10: 1494 | D10: 30708973501 | E10: =VLOOKUP(D10,Configuracion!$A$4:$C$591,2,FALSE) -> ASIAL SRL | F10: 94600 | G10: =F10*21% -> 19866 | O10: =SUM(F10:N10) -> 114466 | P10: =VLOOKUP(D10,Configuracion!$A$4:$C$591,3,FALSE) -> INSUMOS
A11: 20/07/2023 | B11: 4 | C11: 411 | D11: 20379223185 | E11: =VLOOKUP(D11,Configuracion!$A$4:$C$591,2,FALSE) -> AYALA MAURICIO JUAN JOSE | F11: 74720 | G11: =F11*21% -> 15691.2 | O11: =SUM(F11:N11) -> 90411.2 | P11: =VLOOKUP(D11,Configuracion!$A$4:$C$591,3,FALSE) -> PROVEEDOR
A12: 19/07/2023 | B12: 11 | C12: 985 | D12: 20920321292 | E12: =VLOOKUP(D12,Configuracion!$A$4:$C$591,2,FALSE) -> BELLINI FILIPPINI ALBERTO | F12: 77008.35 | G12: =F12*21% -> 16171.754 | O12: =SUM(F12:N12) -> 93180.104 | P12: =VLOOKUP(D12,Configuracion!$A$4:$C$591,3,FALSE) -> VARIOS
A13: 18/07/2023 | B13: 4 | C13: 4062 | D13: 20129871947 | E13: =VLOOKUP(D13,Configuracion!$A$4:$C$591,2,FALSE) -> CARLOS RODOLFO FERNANDEZ | F13: 23310.01 | G13: =F13*21% -> 4895.1021 | O13: =SUM(F13:N13) -> 28205.112 | P13: =VLOOKUP(D13,Configuracion!$A$4:$C$591,3,FALSE) -> PROVEEDOR
A14: 17/07/2023 | B14: 27 | C14: 5383 | D14: 33712276539 | E14: =VLOOKUP(D14,Configuracion!$A$4:$C$591,2,FALSE) -> CASTAÑO AUTOVOX SRL | F14: 12929.87 | G14: =F14*21% -> 2715.2727 | K14: 452.55 | N14: 855.21 | O14: =SUM(F14:N14) -> 16952.903 | P14: =VLOOKUP(D14,Configuracion!$A$4:$C$591,3,FALSE) -> VARIOS
A15: 21/07/2023 | B15: 34 | C15: 46 | D15: 33712276539 | E15: =VLOOKUP(D15,Configuracion!$A$4:$C$591,2,FALSE) -> CASTAÑO AUTOVOX SRL | F15: 7836.04 | G15: =F15*21% -> 1645.5684 | K15: 274.26 | N15: 518.29 | O15: =SUM(F15:N15) -> 10274.158 | P15: =VLOOKUP(D15,Configuracion!$A$4:$C$591,3,FALSE) -> VARIOS
A16: 03/07/2023 | B16: 2 | C16: 188 | D16: 30605344352 | E16: =VLOOKUP(D16,Configuracion!$A$4:$C$591,2,FALSE) -> CONSORCIO BARTOLME MITRE 2466 | F16: 230000 | G16: =F16*21% -> 48300 | O16: =SUM(F16:N16) -> 278300 | P16: =VLOOKUP(D16,Configuracion!$A$4:$C$591,3,FALSE) -> CONSORCIO
A17: 45107 | B17: 20 | C17: 153063 | D17: 30696850972 | E17: =VLOOKUP(D17,Configuracion!$A$4:$C$591,2,FALSE) -> CPS COMUNICACIONES SA | F17: 4125.01 | H17: 1113.75 | K17: 144.37 | O17: =SUM(F17:N17) -> 5383.13 | P17: =VLOOKUP(D17,Configuracion!$A$4:$C$591,3,FALSE) -> SERVICIO
A18: 26/07/2023 | B18: 2016 | C18: 45392 | D18: 30516186670 | E18: =VLOOKUP(D18,Configuracion!$A$4:$C$591,2,FALSE) -> DEHEZA SAICFeI | F18: 14541.31 | G18: =F18*21% -> 3053.6751 | J18: 436.24 | K18: 543.89 | N18: =102.19+896.12 -> 998.31 | O18: =SUM(F18:N18) -> 19573.425 | P18: =VLOOKUP(D18,Configuracion!$A$4:$C$591,3,FALSE) -> VARIOS
A19: 06/07/2023 | B19: 2019 | C19: 144251 | D19: 30516186670 | E19: =VLOOKUP(D19,Configuracion!$A$4:$C$591,2,FALSE) -> DEHEZA SAICFeI | F19: 7341.38 | G19: =F19*21% -> 1541.6898 | J19: 220.24 | K19: 296.7 | N19: =1070.32+65.58 -> 1135.9 | O19: =SUM(F19:N19) -> 10535.91 | P19: =VLOOKUP(D19,Configuracion!$A$4:$C$591,3,FALSE) -> VARIOS
A20: 06/07/2023 | B20: 3 | C20: 7899 | D20: 20045615473 | E20: =VLOOKUP(D20,Configuracion!$A$4:$C$591,2,FALSE) -> DI FEO HUGO PASCUAL GUILLERMO | F20: 35930 | G20: =F20*21% -> 7545.3 | O20: =SUM(F20:N20) -> 43475.3 | P20: =VLOOKUP(D20,Configuracion!$A$4:$C$591,3,FALSE) -> INSUMOS
A21: 13/07/2023 | B21: 3 | C21: 7909 | D21: 20045615473 | E21: =VLOOKUP(D21,Configuracion!$A$4:$C$591,2,FALSE) -> DI FEO HUGO PASCUAL GUILLERMO | F21: 33340 | G21: =F21*21% -> 7001.4 | O21: =SUM(F21:N21) -> 40341.4 | P21: =VLOOKUP(D21,Configuracion!$A$4:$C$591,3,FALSE) -> INSUMOS
A22: 20/07/2023 | B22: 3 | C22: 7927 | D22: 20045615473 | E22: =VLOOKUP(D22,Configuracion!$A$4:$C$591,2,FALSE) -> DI FEO HUGO PASCUAL GUILLERMO | F22: 34710 | G22: =F22*21% -> 7289.1 | O22: =SUM(F22:N22) -> 41999.1 | P22: =VLOOKUP(D22,Configuracion!$A$4:$C$591,3,FALSE) -> INSUMOS
A23: 27/07/2023 | B23: 3 | C23: 7942 | D23: 20045615473 | E23: =VLOOKUP(D23,Configuracion!$A$4:$C$591,2,FALSE) -> DI FEO HUGO PASCUAL GUILLERMO | F23: 88020 | G23: =F23*21% -> 18484.2 | O23: =SUM(F23:N23) -> 106504.2 | P23: =VLOOKUP(D23,Configuracion!$A$4:$C$591,3,FALSE) -> INSUMOS
A24: 27/07/2023 | B24: 3 | C24: 7943 | D24: 20045615473 | E24: =VLOOKUP(D24,Configuracion!$A$4:$C$591,2,FALSE) -> DI FEO HUGO PASCUAL GUILLERMO | F24: 3680 | G24: =F24*21% -> 772.8 | O24: =SUM(F24:N24) -> 4452.8 | P24: =VLOOKUP(D24,Configuracion!$A$4:$C$591,3,FALSE) -> INSUMOS
A25: 05/07/2023 | B25: 7 | C25: 27447 | D25: 20271532483 | E25: =VLOOKUP(D25,Configuracion!$A$4:$C$591,2,FALSE) -> DIEGO MARTIN RIOS | F25: 1283367.4 | G25: =F25*21% -> 269507.15 | K25: 44917.86 | O25: =SUM(F25:N25) -> 1597792.4 | P25: =VLOOKUP(D25,Configuracion!$A$4:$C$591,3,FALSE) -> PROVEEDOR
A26: 05/07/2023 | B26: 7 | C26: 27449 | D26: 20271532483 | E26: =VLOOKUP(D26,Configuracion!$A$4:$C$591,2,FALSE) -> DIEGO MARTIN RIOS | F26: 2069487.7 | G26: =F26*21% -> 434592.42 | K26: 72432.07 | O26: =SUM(F26:N26) -> 2576512.2 | P26: =VLOOKUP(D26,Configuracion!$A$4:$C$591,3,FALSE) -> PROVEEDOR
A27: 10/07/2023 | B27: 7 | C27: 27491 | D27: 20271532483 | E27: =VLOOKUP(D27,Configuracion!$A$4:$C$591,2,FALSE) -> DIEGO MARTIN RIOS | F27: 2169893.8 | G27: =F27*21% -> 455677.7 | K27: 75946.28 | O27: =SUM(F27:N27) -> 2701517.8 | P27: =VLOOKUP(D27,Configuracion!$A$4:$C$591,3,FALSE) -> PROVEEDOR
A28: 10/07/2023 | B28: 7 | C28: 27501 | D28: 20271532483 | E28: =VLOOKUP(D28,Configuracion!$A$4:$C$591,2,FALSE) -> DIEGO MARTIN RIOS | F28: 1343840.6 | G28: =F28*21% -> 282206.52 | K28: 47034.42 | O28: =SUM(F28:N28) -> 1673081.5 | P28: =VLOOKUP(D28,Configuracion!$A$4:$C$591,3,FALSE) -> PROVEEDOR
A29: 14/07/2023 | B29: 7 | C29: 27571 | D29: 20271532483 | E29: =VLOOKUP(D29,Configuracion!$A$4:$C$591,2,FALSE) -> DIEGO MARTIN RIOS | F29: 892899.98 | G29: =F29*21% -> 187509 | K29: 31251.5 | O29: =SUM(F29:N29) -> 1111660.5 | P29: =VLOOKUP(D29,Configuracion!$A$4:$C$591,3,FALSE) -> PROVEEDOR
A30: 19/07/2023 | B30: 7 | C30: 925 | D30: 20271532483 | E30: =VLOOKUP(D30,Configuracion!$A$4:$C$591,2,FALSE) -> DIEGO MARTIN RIOS | F30: -764001.73 | G30: =F30*21% -> -160440.36 | K30: -26740.06 | O30: =SUM(F30:N30) -> -951182.15 | P30: =VLOOKUP(D30,Configuracion!$A$4:$C$591,3,FALSE) -> PROVEEDOR
A31: 21/07/2023 | B31: 18 | C31: 1090 | D31: 30711727236 | E31: =VLOOKUP(D31,Configuracion!$A$4:$C$591,2,FALSE) -> DULCE ESTILO SA | F31: 22092.27 | G31: =F31*21% -> 4639.3767 | O31: =SUM(F31:N31) -> 26731.647 | P31: =VLOOKUP(D31,Configuracion!$A$4:$C$591,3,FALSE) -> VARIOS
A32: 18/07/2023 | B32: 3 | C32: 47573 | D32: 30577744579 | E32: =VLOOKUP(D32,Configuracion!$A$4:$C$591,2,FALSE) -> EXPRESO TROLE SRL | F32: 10495.87 | G32: =F32*21% -> 2204.1327 | O32: =SUM(F32:N32) -> 12700.003 | P32: =VLOOKUP(D32,Configuracion!$A$4:$C$591,3,FALSE) -> FLETE
A33: 19/07/2023 | B33: 3 | C33: 784 | D33: 30715869663 | E33: =VLOOKUP(D33,Configuracion!$A$4:$C$591,2,FALSE) -> F & F COLOR SRL | F33: 24109.01 | G33: =F33*21% -> 5062.8921 | O33: =SUM(F33:N33) -> 29171.902 | P33: =VLOOKUP(D33,Configuracion!$A$4:$C$591,3,FALSE) -> VARIOS
A34: 06/07/2023 | B34: 3 | C34: 1180 | D34: 30715980807 | E34: =VLOOKUP(D34,Configuracion!$A$4:$C$591,2,FALSE) -> FABORT SRL | F34: 180800 | G34: =F34*21% -> 37968 | O34: =SUM(F34:N34) -> 218768 | P34: =VLOOKUP(D34,Configuracion!$A$4:$C$591,3,FALSE) -> PROVEEDOR
A35: 18/07/2023 | B35: 3648 | C35: 513 | D35: 30526874249 | E35: =VLOOKUP(D35,Configuracion!$A$4:$C$591,2,FALSE) -> FRAVEGA SACIEI | F35: 190081.82 | G35: =F35*21% -> 39917.182 | O35: =SUM(F35:N35) -> 229999 | P35: =VLOOKUP(D35,Configuracion!$A$4:$C$591,3,FALSE) -> VARIOS
A36: 04/07/2023 | B36: 5 | C36: 2807 | D36: 27119878468 | E36: =VLOOKUP(D36,Configuracion!$A$4:$C$591,2,FALSE) -> FREUND GABRIELA | F36: 126446.28 | G36: =F36*21% -> 26553.719 | O36: =SUM(F36:N36) -> 153000 | P36: =VLOOKUP(D36,Configuracion!$A$4:$C$591,3,FALSE) -> PROVEEDOR
A37: 25/07/2023 | B37: 7 | C37: 2026 | D37: 20284183534 | E37: =VLOOKUP(D37,Configuracion!$A$4:$C$591,2,FALSE) -> FURLANETTO MARTIN | F37: 2471.07 | G37: =F37*21% -> 518.9247 | O37: =SUM(F37:N37) -> 2989.9947 | P37: =VLOOKUP(D37,Configuracion!$A$4:$C$591,3,FALSE) -> VARIOS
A38: 14/07/2023 | B38: 2 | C38: 26557 | D38: 30714696153 | E38: =VLOOKUP(D38,Configuracion!$A$4:$C$591,2,FALSE) -> HOSPIMED SA | F38: 62155.1 | G38: =F38*21% -> 13052.571 | O38: =SUM(F38:N38) -> 75207.671 | P38: =VLOOKUP(D38,Configuracion!$A$4:$C$591,3,FALSE) -> PROVEEDOR
A39: 26/07/2023 | B39: 2 | C39: 26697 | D39: 30714696153 | E39: =VLOOKUP(D39,Configuracion!$A$4:$C$591,2,FALSE) -> HOSPIMED SA | F39: 20592 | G39: =F39*21% -> 4324.32 | O39: =SUM(F39:N39) -> 24916.32 | P39: =VLOOKUP(D39,Configuracion!$A$4:$C$591,3,FALSE) -> PROVEEDOR
A40: 31/07/2023 | B40: 5 | C40: 771 | D40: 20242126158 | E40: =VLOOKUP(D40,Configuracion!$A$4:$C$591,2,FALSE) -> IALLONARDO SERGIO | F40: 141483 | G40: =F40*21% -> 29711.43 | O40: =SUM(F40:N40) -> 171194.43 | P40: =VLOOKUP(D40,Configuracion!$A$4:$C$591,3,FALSE) -> PROVEEDOR
A41: 07/07/2023 | B41: 5 | C41: 1305 | D41: 30712187316 | E41: =VLOOKUP(D41,Configuracion!$A$4:$C$591,2,FALSE) -> ITALOMED PRODUCTOS SRL | F41: 84321.97 | G41: =F41*21% -> 17707.614 | O41: =SUM(F41:N41) -> 102029.58 | P41: =VLOOKUP(D41,Configuracion!$A$4:$C$591,3,FALSE) -> PROVEEDOR
A42: 07/07/2023 | B42: 5 | C42: 1306 | D42: 30712187316 | E42: =VLOOKUP(D42,Configuracion!$A$4:$C$591,2,FALSE) -> ITALOMED PRODUCTOS SRL | F42: 84321.97 | G42: =F42*21% -> 17707.614 | O42: =SUM(F42:N42) -> 102029.58 | P42: =VLOOKUP(D42,Configuracion!$A$4:$C$591,3,FALSE) -> PROVEEDOR
A43: 24/07/2023 | B43: 5 | C43: 1330 | D43: 30712187316 | E43: =VLOOKUP(D43,Configuracion!$A$4:$C$591,2,FALSE) -> ITALOMED PRODUCTOS SRL | F43: 86801.3 | G43: =F43*21% -> 18228.273 | O43: =SUM(F43:N43) -> 105029.57 | P43: =VLOOKUP(D43,Configuracion!$A$4:$C$591,3,FALSE) -> PROVEEDOR
...

Sheet Calculo IVA
B1: ORTOPEDIA GEMINIS
A2: Calculo Iva | D2: 45108
B4: VENTAS
B5: Neto | C5: Iva | D5: Total
A6: FAC. "A" | B6: =+'Julio '!F202 -> 0 | C6: =(B6*0.21) -> 0 | D6: =(B6+C6) -> 0
A7: FAC. "B" | B7: =+'Julio '!F212 -> 0 | C7: =(B7*0.21) -> 0 | D7: =(B7+C7) -> 0
A8: FAC. "A" - Odoo | B8: =+'Julio '!B221+'Julio '!B223+'Julio '!B224+'Julio '!B222 -> 48946882 | C8: =+B8*0.21 -> 10278845 | D8: =(B8+C8) -> 59225727
A9: FAC. "B" - Odoo | B9: =+'Julio '!B225+'Julio '!B226 -> 3568047.7 | C9: =+B9*0.21 -> 749290.01 | D9: =(B9+C9) -> 4317337.7
B10: =SUM(B6:B9) -> 52514930 | C10: =SUM(C6:C9) -> 11028135 | D10: =SUM(D6:D9) -> 63543065
B13: COMPRAS
B14: Neto | C14: Iva | D14: Total
B15: =+'Julio '!F116 -> 18282027 | C15: =+'Julio '!G116+'Julio '!H116+'Julio '!I116 -> 3829928.2 | D15: =(B15+C15) -> 22111955
B17: =SUM(B15:B16) -> 18282027 | C17: =SUM(C15:C16) -> 3829928.2 | D17: =SUM(D15:D16) -> 22111955
A20: RETENCIONES | B20: N° Cuit | C20: Importe | D20: Nro. Retencion | E20: Fecha
A21: AFIP - No están informadas las retenciones de IVA en el sistema de AFIP
C36: =+'Julio '!G189 -> 884.57
A38: PERCEPCIONES | B38: N° Cuit | C38: Importe | D38: Nro. Retencion | E38: Fecha
C42: =SUM(C39:C41) -> 0
A44: Total Deducciociones | C44: =+C42+C36 -> 884.57
C47: (Montos en Positivo)
A48: 1er Saldo Tecnico del Período | C48: =+C10-C17 -> 7198207.1
A50: Saldo Tecnico de período Anterior (a favor) | D50: (resta en el total)
A52: Saldo Neto Técnico | C52: =+C48-C50 -> 7198207.1
A56: Saldo L.D. del Período | C56: =+C42+C36 -> 884.57
A58: Saldo L.D. del Período Anterior
A60: Neto S.L.D | C60: =+C56+C58 -> 884.57
A63: I V A | C63: =+C52-C60 -> 7197322.5
A64: NOTA: Sin Tomar posibles Retenciones que se hayan hecho

Sheet Ventas Odoo 07 2023
A1: Ventas Libro de IVA 01/07/2023 - 31/07/2023
A2: Ortopedia Geminis S.A.
A4: Fecha | B4: Comprobante | C4: Nombre | D4: Cond. IVA | E4: CUIT o Doc. | F4: Gravado | G4: No Gravado | H4: IVA 2,5% | I4: IVA 5% | J4: IVA 10.5% | K4: IVA 21% | L4: IVA 27% | M4: Otros Imp | N4: Total Compr.
A5: 03/07/2023 | B5: FA-B 0005-00008258 | C5: .CONSUMIDOR FINAL | D5: Consumidor Final | F5: 12066.12 | G5: 0 | H5: 0 | I5: 0 | J5: 0 | K5: 2533.88 | L5: 0 | M5: 0 | N5: 14600
A6: 03/07/2023 | B6: FA-B 0005-00008259 | C6: .CONSUMIDOR FINAL | D6: Consumidor Final | F6: 6776.86 | G6: 0 | H6: 0 | I6: 0 | J6: 0 | K6: 1423.14 | L6: 0 | M6: 0 | N6: 8200
A7: 03/07/2023 | B7: FA-B 0005-00008260 | C7: .CONSUMIDOR FINAL | D7: Consumidor Final | F7: 13388.43 | G7: 0 | H7: 0 | I7: 0 | J7: 0 | K7: 2811.57 | L7: 0 | M7: 0 | N7: 16200
A8: 03/07/2023 | B8: FA-B 0005-00008261 | C8: .CONSUMIDOR FINAL | D8: Consumidor Final | F8: 3966.94 | G8: 0 | H8: 0 | I8: 0 | J8: 0 | K8: 833.06 | L8: 0 | M8: 0 | N8: 4800
A9: 03/07/2023 | B9: FA-B 0005-00008262 | C9: .CONSUMIDOR FINAL | D9: Consumidor Final | F9: 7024.79 | G9: 0 | H9: 0 | I9: 0 | J9: 0 | K9: 1475.21 | L9: 0 | M9: 0 | N9: 8500
A10: 03/07/2023 | B10: FA-B 0005-00008263 | C10: .CONSUMIDOR FINAL | D10: Consumidor Final | F10: 2727.27 | G10: 0 | H10: 0 | I10: 0 | J10: 0 | K10: 572.73 | L10: 0 | M10: 0 | N10: 3300
A11: 03/07/2023 | B11: FA-B 0005-00008264 | C11: .CONSUMIDOR FINAL | D11: Consumidor Final | F11: 7024.79 | G11: 0 | H11: 0 | I11: 0 | J11: 0 | K11: 1475.21 | L11: 0 | M11: 0 | N11: 8500
A12: 03/07/2023 | B12: FA-B 0005-00008265 | C12: .CONSUMIDOR FINAL | D12: Consumidor Final | F12: 4462.81 | G12: 0 | H12: 0 | I12: 0 | J12: 0 | K12: 937.19 | L12: 0 | M12: 0 | N12: 5400
A13: 03/07/2023 | B13: FA-B 0005-00008266 | C13: .CONSUMIDOR FINAL | D13: Consumidor Final | F13: 3347.11 | G13: 0 | H13: 0 | I13: 0 | J13: 0 | K13: 702.89 | L13: 0 | M13: 0 | N13: 4050
A14: 03/07/2023 | B14: FA-A 0006-00000363 | C14: Galeno Argentina Sociedad Anonima | D14: IVA Responsable Inscripto | E14: 30522428163 | F14: 4682644.6 | G14: 0 | H14: 0 | I14: 0 | J14: 0 | K14: 983355.36 | L14: 0 | M14: 0 | N14: 5666000
A15: 03/07/2023 | B15: NC-A 0007-00000095 | C15: Alexander Fleming S A | D15: IVA Responsable Inscripto | E15: 30645337979 | F15: -12167.57 | G15: 0 | H15: 0 | I15: 0 | J15: 0 | K15: -2555.19 | L15: 0 | M15: 0 | N15: -14722.76
A16: 03/07/2023 | B16: FA-A 0007-00001499 | C16: Hc Homecare Internacion Domiciliaria S.A. | D16: IVA Responsable Inscripto | E16: 30710538014 | F16: 18800 | G16: 0 | H16: 0 | I16: 0 | J16: 0 | K16: 3948 | L16: 0 | M16: 0 | N16: 22748
A17: 03/07/2023 | B17: FA-A 0007-00001500 | C17: Amparo Salud S.R.L. | D17: IVA Responsable Inscripto | E17: 30715186655 | F17: 73448.76 | G17: 0 | H17: 0 | I17: 0 | J17: 0 | K17: 15424.24 | L17: 0 | M17: 0 | N17: 88873
A18: 03/07/2023 | B18: FA-A 0007-00001501 | C18: Zc Diabetes Srl | D18: IVA Responsable Inscripto | E18: 30710961790 | F18: 43133.88 | G18: 0 | H18: 0 | I18: 0 | J18: 0 | K18: 9058.11 | L18: 0 | M18: 0 | N18: 52191.99
A19: 03/07/2023 | B19: FA-A 0007-00001502 | C19: Login Door S.A | D19: IVA Responsable Inscripto | E19: 30711244383 | F19: 6375.37 | G19: 0 | H19: 0 | I19: 0 | J19: 0 | K19: 1338.83 | L19: 0 | M19: 0 | N19: 7714.2
A20: 03/07/2023 | B20: FA-A 0007-00001503 | C20: Alexander Fleming S A | D20: IVA Responsable Inscripto | E20: 30645337979 | F20: 12167.57 | G20: 0 | H20: 0 | I20: 0 | J20: 0 | K20: 2555.19 | L20: 0 | M20: 0 | N20: 14722.76
A21: 03/07/2023 | B21: FA-A 0007-00001504 | C21: Alexander Fleming S A | D21: IVA Responsable Inscripto | E21: 30645337979 | F21: 12167.57 | G21: 0 | H21: 0 | I21: 0 | J21: 0 | K21: 2555.19 | L21: 0 | M21: 0 | N21: 14722.76
A22: 03/07/2023 | B22: FA-A 0007-00001505 | C22: Medicus Sociedad Anonima De Asistencia Medica Y Cientifica | D22: IVA Responsable Inscripto | E22: 30546771314 | F22: 10880.99 | G22: 0 | H22: 0 | I22: 0 | J22: 0 | K22: 2285.01 | L22: 0 | M22: 0 | N22: 13166
A23: 03/07/2023 | B23: FA-A 0007-00001506 | C23: Medincare Argentina S.A. | D23: IVA Responsable Inscripto | E23: 30713669004 | F23: 9404.96 | G23: 0 | H23: 0 | I23: 0 | J23: 0 | K23: 1975.04 | L23: 0 | M23: 0 | N23: 11380
A24: 03/07/2023 | B24: FA-A 0007-00001507 | C24: Centro Medico Amenabar Srl | D24: IVA Responsable Inscripto | E24: 30707612971 | F24: 15487.6 | G24: 0 | H24: 0 | I24: 0 | J24: 0 | K24: 3252.4 | L24: 0 | M24: 0 | N24: 18740
A25: 03/07/2023 | B25: FA-A 0007-00001508 | C25: Fundacion Empresaria Maderera | D25: IVA Responsable Inscripto | E25: 30657418877 | F25: 3325.53 | G25: 0 | H25: 0 | I25: 0 | J25: 0 | K25: 698.36 | L25: 0 | M25: 0 | N25: 4023.89
... A27: 03/07/2023 | B27: FA-B 0007-00004469 | C27: Obra Social De Los Trabajadores De La Industria Del Gas | D27: IVA Sujeto Exento | E27: 30658137642 | F27: 55438.84 | G27: 0 | H27: 0 | I27: 0 | J27: 0 | K27: 11642.16 | L27: 0 | M27: 0 | N27: 67081
A28: 04/07/2023 | B28: FA-B 0005-00008267 | C28: .CONSUMIDOR FINAL | D28: Consumidor Final | F28: 3636.36 | G28: 0 | H28: 0 | I28: 0 | J28: 0 | K28: 763.64 | L28: 0 | M28: 0 | N28: 4400
A29: 04/07/2023 | B29: FA-B 0005-00008268 | C29: .CONSUMIDOR FINAL | D29: Consumidor Final | F29: 3305.79 | G29: 0 | H29: 0 | I29: 0 | J29: 0 | K29: 694.21 | L29: 0 | M29: 0 | N29: 4000
A30: 04/07/2023 | B30: FA-B 0005-00008269 | C30: .CONSUMIDOR FINAL | D30: Consumidor Final | F30: 3388.43 | G30: 0 | H30: 0 | I30: 0 | J30: 0 | K30: 711.57 | L30: 0 | M30: 0 | N30: 4100
A31: 04/07/2023 | B31: FA-B 0005-00008270 | C31: .CONSUMIDOR FINAL | D31: Consumidor Final | F31: 12066.12 | G31: 0 | H31: 0 | I31: 0 | J31: 0 | K31: 2533.88 | L31: 0 | M31: 0 | N31: 14600
A32: 04/07/2023 | B32: FA-B 0005-00008271 | C32: .CONSUMIDOR FINAL | D32: Consumidor Final | F32: 2644.63 | G32: 0 | H32: 0 | I32: 0 | J32: 0 | K32: 555.37 | L32: 0 | M32: 0 | N32: 3200
A33: 04/07/2023 | B33: FA-B 0005-00008272 | C33: .CONSUMIDOR FINAL | D33: Consumidor Final | F33: 11570.25 | G33: 0 | H33: 0 | I33: 0 | J33: 0 | K33: 2429.75 | L33: 0 | M33: 0 | N33: 14000
A34: 04/07/2023 | B34: FA-B 0005-00008273 | C34: .CONSUMIDOR FINAL | D34: Consumidor Final | F34: 5785.12 | G34: 0 | H34: 0 | I34: 0 | J34: 0 | K34: 1214.88 | L34: 0 | M34: 0 | N34: 7000
A35: 04/07/2023 | B35: FA-B 0005-00008274 | C35: .CONSUMIDOR FINAL | D35: Consumidor Final | F35: 2809.92 | G35: 0 | H35: 0 | I35: 0 | J35: 0 | K35: 590.08 | L35: 0 | M35: 0 | N35: 3400
A36: 04/07/2023 | B36: FA-B 0005-00008275 | C36: .CONSUMIDOR FINAL | D36: Consumidor Final | F36: 9090.91 | G36: 0 | H36: 0 | I36: 0 | J36: 0 | K36: 1909.09 | L36: 0 | M36: 0 | N36: 11000
A37: 04/07/2023 | B37: FA-B 0005-00008276 | C37: .CONSUMIDOR FINAL | D37: Consumidor Final | F37: 2727.27 | G37: 0 | H37: 0 | I37: 0 | J37: 0 | K37: 572.73 | L37: 0 | M37: 0 | N37: 3300
A38: 04/07/2023 | B38: FA-A 0006-00000364 | C38: Galeno Argentina Sociedad Anonima | D38: IVA Responsable Inscripto | E38: 30522428163 | F38: 19008264 | G38: 0 | H38: 0 | I38: 0 | J38: 0 | K38: 3991735.5 | L38: 0 | M38: 0 | N38: 23000000
A39: 04/07/2023 | B39: FA-A 0006-00000365 | C39: Galeno Argentina Sociedad Anonima | D39: IVA Responsable Inscripto | E39: 30522428163 | F39: 5227520.7 | G39: 0 | H39: 0 | I39: 0 | J39: 0 | K39: 1097779.3 | L39: 0 | M39: 0 | N39: 6325300
A40: 04/07/2023 | B40: NC-A 0007-00000096 | C40: Galeno Argentina Sociedad Anonima | D40: IVA Responsable Inscripto | E40: 30522428163 | F40: -4682644.6 | G40: 0 | H40: 0 | I40: 0 | J40: 0 | K40: -983355.36 | L40: 0 | M40: 0 | N40: -5666000
A41: 04/07/2023 | B41: FA-A 0007-00001510 | C41: Obra Social Del Personal De Las Telecomunicaciones De La Republica Argentina | D41: IVA Responsable Inscripto | E41: 30608716390 | F41: 14545.46 | G41: 0 | H41: 0 | I41: 0 | J41: 0 | K41: 3054.55 | L41: 0 | M41: 0 | N41: 17600.01
A42: 04/07/2023 | B42: FA-A 0007-00001511 | C42: Obra Social Del Personal De Las Telecomunicaciones De La Republica Argentina | D42: IVA Responsable Inscripto | E42: 30608716390 | F42: 16727.26 | G42: 0 | H42: 0 | I42: 0 | J42: 0 | K42: 3512.72 | L42: 0 | M42: 0 | N42: 20239.98
...
