Workbook

Sheet Lista_CUIT
A1: CUIT | B1: RAZON SOCIAL | C1: Tipo de Gasto | D1: PROVINCIA
A2: 30575019524 | B2: 100000 LAMPARAS SRL | G2: Mercaderia
A3: 30709829730 | B3: 4KRC SA | C3: Mantenimiento | G3: Servicios Gas, Luz, etc.
A4: 30715223704 | B4: 5 CEPAS S.R.L. | C4: MERCADERIA | G4: Gastos catering
A5: 30714869937 | B5: 60 LIBRAS SRL | G5: Combustibe
A6: 30692212130 | B6: A R C CONSTRUCCIONES S.A. | G6: Gastos Varios
A7: 30687722007 | B7: A. RUSSONIELLO SA | C7: SERVICIOS | G7: Gastos seguridad
A8: 30503874497 | B8: A.M. PESCIO S.C.A | C8: Mercaderia | G8: Librería
A9: 30702017498 | B9: ABBS POINT DESING S.A. | G9: Gastos mantenimiento
A10: 20182999661 | B10: ABEL JAVIER KLAINER | C10: Mercaderia | G10: Gastos comercializacion
A11: 30652000076 | B11: ABELSON SA | C11: Mercaderia | G11: Alquiler
A12: 30690536079 | B12: ACCESOR SRL | C12: Gastos Varios | G12: Honorarios contables
A13: 30515585415 | B13: ACEROSALFA SA | C13: Mercaderia | G13: Gastos administrativos
A14: 33711942659 | B14: ACLOS ASOC. CIVIL PARA LA LONG | C14: Mercaderia | G14: Seguro
A15: 30715243349 | B15: ADSE S.A | G15: Extracto
A16: 20174004146 | B16: ADUEARDO FRANCISCO NARDOMARINO | C16: Mercaderia | G16: Flete
A17: 30708555548 | B17: AGH S.A | C17: Mercaderia | G17: Honorarios Legales
A18: 30708263342 | B18: AGRACO S.A | C18: MERCADERIA | G18: Insumo
A19: 30709565075 | B19: AGUA Y SANEAMIENTOS ARG SA | C19: SERVICIOS | G19: Muebles y Utiles
A20: 30500229973 | B20: AKIAN GRAFICA EDITORA SA | C20: Mercaderia | G20: Otros
A21: 30710799241 | B21: ALANAR S.R.L. | G21: Telefonia
A22: 20236101127 | B22: ALEJANDRO DARIO LOPEZ | G22: Alojamiento-Varios
A23: 20291929126 | B23: ALEJANDRO MIGUEL DAUBLER
A24: 30709604887 | B24: ALFABIS SRL. | C24: Mantenimiento
A25: 20083925680 | B25: ALFREDO DANIEL FERNANDEZ | C25: Gastos Varios
A26: 30656038752 | B26: ALFREDO OMAR POTENZA SRL | C26: Mercaderia
A27: 30504563894 | B27: ALI HERMANOS SRL | C27: Mercaderia
A28: 30602699826 | B28: ALKO SRL
A29: 30715190385 | B29: ALL FEDERAL SA.
A30: 23945042079 | B30: ALVARENGA VILLAR LUIS F | C30: Gastos Varios
A31: 20040616498 | B31: ALVAREZ MARCELINO
A32: 30710587147 | B32: AMAKOR SA | C32: SERVICIOS
A33: 30663288497 | B33: AMX ARG SA
A34: 27108310559 | B34: ANA MARIA VALDEZ
A35: 30502375535 | B35: ANAVI S.C.A.
A36: 30709251739 | B36: ANDES LINEAS AEREAS SA
A37: 30709948667 | B37: ANTAGGER SRL | C37: Mercaderia
A38: 30683702060 | B38: ANTARES INDUST. ORTOP SA | C38: Mercaderia
A39: 30715985124 | B39: ANTOLFO S.R.L.
A40: 30714344656 | B40: AQUALAF S.A. | C40: Mercaderia
...

Sheet Abr-26
B1: LIBRO IVA COMPRAS | G1: CORITEC S. R. L. | N1: 45748
B3: TOTAL COMPRAS NETAS | G3: TOTAL CREDITO FISCAL | J3: TOTAL VENTAS NETAS | M3: TOTAL DEBITO FISCAL | P3: RESULTADO
B4: =SUM('Abr-26'!$H$40)+'Abr-26'!$G$57 -> 4745586.6 | G4: ='Abr-26'!$I$40+'Abr-26'!$J$40+'Abr-26'!$K$40+I58 -> 862296.52 | J4: ='Abr-26'!$H$96+'Abr-26'!$H$106 -> 82452311 | M4: ='Abr-26'!$I$96+'Abr-26'!$J$96+'Abr-26'!$I$106+'Abr-26'!$J$106 -> 10463262 | P4: =G4-M4 -> -9600965.4
B8: FECHA | C8: TIPO | D8: PTO VTA | E8: NRO. CPTE | F8: CUIT | G8: RAZON SOCIAL | H8: NETO GRAVADO | I8: IVA 21 % | J8: IVA 27% | K8: IVA 10,5% | L8: PERC. IVA | M8: PERC IIBB BS AS | N8: PERC. IIBB CABA | O8: Otros / No Grav. | P8: TOTAL | Q8: Tipo de Gasto | R8: Provincia
B9: 46113 | C9: 1 | D9: 5 | E9: 7888 | F9: 20231333593 | G9: =IFERROR(IF('Abr-26'!$F9="","-",VLOOKUP('Abr-26'!$F9,Lista_CUIT!$A$1:$D$2241,2,0)),"CUIT NO CARGADO") -> BOLLINI CLAUDIO DANIEL | H9: 80000 | I9: ='Abr-26'!$H9*0.21 -> 16800 | P9: =SUM('Abr-26'!$H9:$O9) -> 96800 | Q9: =IFERROR(IF('Abr-26'!$F9="","-",VLOOKUP('Abr-26'!$F9,Lista_CUIT!$A$1:$D$2241,3,0)),"CUIT NO CARGADO") -> Mantenimiento | R9: =IFERROR(IF('Abr-26'!$F9="","-",VLOOKUP('Abr-26'!$F9,Lista_CUIT!$A$1:$D$2241,4,0)),"CUIT NO CARGADO") -> 0
B10: 46113 | C10: 1 | D10: 3 | E10: 302589 | F10: 30707135596 | G10: =IFERROR(IF('Abr-26'!$F10="","-",VLOOKUP('Abr-26'!$F10,Lista_CUIT!$A$1:$D$2241,2,0)),"CUIT NO CARGADO") -> CITILAN ARGENTINA S.A. | H10: 43155 | I10: ='Abr-26'!$H10*0.21 -> 9062.55 | P10: =SUM('Abr-26'!$H10:$O10) -> 52217.55 | Q10: =IFERROR(IF('Abr-26'!$F10="","-",VLOOKUP('Abr-26'!$F10,Lista_CUIT!$A$1:$D$2241,3,0)),"CUIT NO CARGADO") -> Telefonia | R10: =IFERROR(IF('Abr-26'!$F10="","-",VLOOKUP('Abr-26'!$F10,Lista_CUIT!$A$1:$D$2241,4,0)),"CUIT NO CARGADO") -> 0
B11: 46113 | C11: 1 | D11: 3 | E11: 944 | F11: 30715402765 | G11: =IFERROR(IF('Abr-26'!$F11="","-",VLOOKUP('Abr-26'!$F11,Lista_CUIT!$A$1:$D$2241,2,0)),"CUIT NO CARGADO") -> RIO 265 S.R.L. | H11: 140495.86 | I11: ='Abr-26'!$H11*0.21 -> 29504.131 | P11: =SUM('Abr-26'!$H11:$O11) -> 169999.99 | Q11: =IFERROR(IF('Abr-26'!$F11="","-",VLOOKUP('Abr-26'!$F11,Lista_CUIT!$A$1:$D$2241,3,0)),"CUIT NO CARGADO") -> GASTOS VARIOS | R11: =IFERROR(IF('Abr-26'!$F11="","-",VLOOKUP('Abr-26'!$F11,Lista_CUIT!$A$1:$D$2241,4,0)),"CUIT NO CARGADO") -> 0
B12: 46114 | C12: 1 | D12: 4 | E12: 28806 | F12: 30714440779 | G12: =IFERROR(IF('Abr-26'!$F12="","-",VLOOKUP('Abr-26'!$F12,Lista_CUIT!$A$1:$D$2241,2,0)),"CUIT NO CARGADO") -> KITA S.R.L. | H12: 18165.29 | I12: ='Abr-26'!$H12*0.21 -> 3814.7109 | P12: =SUM('Abr-26'!$H12:$O12) -> 21980.001 | Q12: =IFERROR(IF('Abr-26'!$F12="","-",VLOOKUP('Abr-26'!$F12,Lista_CUIT!$A$1:$D$2241,3,0)),"CUIT NO CARGADO") -> 0 | R12: =IFERROR(IF('Abr-26'!$F12="","-",VLOOKUP('Abr-26'!$F12,Lista_CUIT!$A$1:$D$2241,4,0)),"CUIT NO CARGADO") -> 0
B13: 46117 | C13: 1 | D13: 6 | E13: 129364 | F13: 30714971782 | G13: =IFERROR(IF('Abr-26'!$F13="","-",VLOOKUP('Abr-26'!$F13,Lista_CUIT!$A$1:$D$2241,2,0)),"CUIT NO CARGADO") -> PINTOS SCHMIDT ALDANA MARCELA Y SACK ADRIANA CRISTINA SH | H13: 18380.99 | I13: ='Abr-26'!$H13*0.21 -> 3860.0079 | P13: =SUM('Abr-26'!$H13:$O13) -> 22240.998 | Q13: =IFERROR(IF('Abr-26'!$F13="","-",VLOOKUP('Abr-26'!$F13,Lista_CUIT!$A$1:$D$2241,3,0)),"CUIT NO CARGADO") -> 0 | R13: =IFERROR(IF('Abr-26'!$F13="","-",VLOOKUP('Abr-26'!$F13,Lista_CUIT!$A$1:$D$2241,4,0)),"CUIT NO CARGADO") -> 0
B14: 46118 | C14: 1 | D14: 1 | E14: 3389 | F14: 30717248267 | G14: =IFERROR(IF('Abr-26'!$F14="","-",VLOOKUP('Abr-26'!$F14,Lista_CUIT!$A$1:$D$2241,2,0)),"CUIT NO CARGADO") -> KARTELACRIL | H14: 85000 | I14: ='Abr-26'!$H14*0.21 -> 17850 | P14: =SUM('Abr-26'!$H14:$O14) -> 102850 | Q14: =IFERROR(IF('Abr-26'!$F14="","-",VLOOKUP('Abr-26'!$F14,Lista_CUIT!$A$1:$D$2241,3,0)),"CUIT NO CARGADO") -> 0 | R14: =IFERROR(IF('Abr-26'!$F14="","-",VLOOKUP('Abr-26'!$F14,Lista_CUIT!$A$1:$D$2241,4,0)),"CUIT NO CARGADO") -> 0
B15: 46119 | C15: 1 | D15: 63 | E15: 3750571 | F15: 30640897267 | G15: =IFERROR(IF('Abr-26'!$F15="","-",VLOOKUP('Abr-26'!$F15,Lista_CUIT!$A$1:$D$2241,2,0)),"CUIT NO CARGADO") -> TELECENTRO SA | H15: 75540 | I15: ='Abr-26'!$H15*0.21 -> 15863.4 | O15: 2266.2 | P15: =SUM('Abr-26'!$H15:$O15) -> 93669.6 | Q15: =IFERROR(IF('Abr-26'!$F15="","-",VLOOKUP('Abr-26'!$F15,Lista_CUIT!$A$1:$D$2241,3,0)),"CUIT NO CARGADO") -> SERVICIOS | R15: =IFERROR(IF('Abr-26'!$F15="","-",VLOOKUP('Abr-26'!$F15,Lista_CUIT!$A$1:$D$2241,4,0)),"CUIT NO CARGADO") -> 0
B16: 46127 | C16: 1 | D16: 3 | E16: 443194 | F16: 33643358749 | G16: =IFERROR(IF('Abr-26'!$F16="","-",VLOOKUP('Abr-26'!$F16,Lista_CUIT!$A$1:$D$2241,2,0)),"CUIT NO CARGADO") -> POLYTECH S A | H16: 1357772.5 | I16: 33370.73 | K16: 125880.75 | P16: =SUM('Abr-26'!$H16:$O16) -> 1517024 | Q16: =IFERROR(IF('Abr-26'!$F16="","-",VLOOKUP('Abr-26'!$F16,Lista_CUIT!$A$1:$D$2241,3,0)),"CUIT NO CARGADO") -> Servicios Informaticos | R16: =IFERROR(IF('Abr-26'!$F16="","-",VLOOKUP('Abr-26'!$F16,Lista_CUIT!$A$1:$D$2241,4,0)),"CUIT NO CARGADO") -> 0
B17: 46128 | C17: 1 | D17: 4 | E17: 1821707 | F17: 30716620634 | G17: =IFERROR(IF('Abr-26'!$F17="","-",VLOOKUP('Abr-26'!$F17,Lista_CUIT!$A$1:$D$2241,2,0)),"CUIT NO CARGADO") -> FIRSTLABEL SRL | H17: 8806.61 | I17: ='Abr-26'!$H17*0.21 -> 1849.3881 | P17: =SUM('Abr-26'!$H17:$O17) -> 10655.998 | Q17: =IFERROR(IF('Abr-26'!$F17="","-",VLOOKUP('Abr-26'!$F17,Lista_CUIT!$A$1:$D$2241,3,0)),"CUIT NO CARGADO") -> GASTOS VARIOS | R17: =IFERROR(IF('Abr-26'!$F17="","-",VLOOKUP('Abr-26'!$F17,Lista_CUIT!$A$1:$D$2241,4,0)),"CUIT NO CARGADO") -> 0
B18: 46128 | C18: 1 | D18: 7 | E18: 2924 | F18: 20324801236 | G18: =IFERROR(IF('Abr-26'!$F18="","-",VLOOKUP('Abr-26'!$F18,Lista_CUIT!$A$1:$D$2241,2,0)),"CUIT NO CARGADO") -> CAMPAGNA SEBASTIAN PABLO | H18: 18428.1 | I18: ='Abr-26'!$H18*0.21 -> 3869.901 | P18: =SUM('Abr-26'!$H18:$O18) -> 22298.001 | Q18: =IFERROR(IF('Abr-26'!$F18="","-",VLOOKUP('Abr-26'!$F18,Lista_CUIT!$A$1:$D$2241,3,0)),"CUIT NO CARGADO") -> Papeleria | R18: =IFERROR(IF('Abr-26'!$F18="","-",VLOOKUP('Abr-26'!$F18,Lista_CUIT!$A$1:$D$2241,4,0)),"CUIT NO CARGADO") -> 0
B19: 46128 | C19: 1 | D19: 106 | E19: 940902 | F19: 30594494187 | G19: =IFERROR(IF('Abr-26'!$F19="","-",VLOOKUP('Abr-26'!$F19,Lista_CUIT!$A$1:$D$2241,2,0)),"CUIT NO CARGADO") -> FEDERAL EXPRESS CORPORATION | H19: 0 | I19: ='Abr-26'!$H19*0.21 -> 0 | O19: 1103171 | P19: =SUM('Abr-26'!$H19:$O19) -> 1103171 | Q19: =IFERROR(IF('Abr-26'!$F19="","-",VLOOKUP('Abr-26'!$F19,Lista_CUIT!$A$1:$D$2241,3,0)),"CUIT NO CARGADO") -> Mercaderia | R19: =IFERROR(IF('Abr-26'!$F19="","-",VLOOKUP('Abr-26'!$F19,Lista_CUIT!$A$1:$D$2241,4,0)),"CUIT NO CARGADO") -> 0
B20: 46128 | C20: 1 | D20: 7 | E20: 3179 | F20: 30716542773 | G20: =IFERROR(IF('Abr-26'!$F20="","-",VLOOKUP('Abr-26'!$F20,Lista_CUIT!$A$1:$D$2241,2,0)),"CUIT NO CARGADO") -> CFV | H20: 12059.5 | I20: ='Abr-26'!$H20*0.21 -> 2532.495 | P20: =SUM('Abr-26'!$H20:$O20) -> 14591.995 | Q20: =IFERROR(IF('Abr-26'!$F20="","-",VLOOKUP('Abr-26'!$F20,Lista_CUIT!$A$1:$D$2241,3,0)),"CUIT NO CARGADO") -> GASTOS VARIOS | R20: =IFERROR(IF('Abr-26'!$F20="","-",VLOOKUP('Abr-26'!$F20,Lista_CUIT!$A$1:$D$2241,4,0)),"CUIT NO CARGADO") -> 0
B21: 46129 | C21: 1 | D21: 13 | E21: 120984 | F21: 30709256420 | G21: =IFERROR(IF('Abr-26'!$F21="","-",VLOOKUP('Abr-26'!$F21,Lista_CUIT!$A$1:$D$2241,2,0)),"CUIT NO CARGADO") -> NGA SRL | H21: 3490.45 | I21: ='Abr-26'!$H21*0.21 -> 732.9945 | P21: =SUM('Abr-26'!$H21:$O21) -> 4223.4445 | Q21: =IFERROR(IF('Abr-26'!$F21="","-",VLOOKUP('Abr-26'!$F21,Lista_CUIT!$A$1:$D$2241,3,0)),"CUIT NO CARGADO") -> GASTOS VARIOS | R21: =IFERROR(IF('Abr-26'!$F21="","-",VLOOKUP('Abr-26'!$F21,Lista_CUIT!$A$1:$D$2241,4,0)),"CUIT NO CARGADO") -> 0
B22: 46129 | C22: 1 | D22: 3 | E22: 10961 | F22: 30715039369 | G22: =IFERROR(IF('Abr-26'!$F22="","-",VLOOKUP('Abr-26'!$F22,Lista_CUIT!$A$1:$D$2241,2,0)),"CUIT NO CARGADO") -> GIANGIU S.A. | H22: 7891.74 | I22: ='Abr-26'!$H22*0.21 -> 1657.2654 | P22: =SUM('Abr-26'!$H22:$O22) -> 9549.0054 | Q22: =IFERROR(IF('Abr-26'!$F22="","-",VLOOKUP('Abr-26'!$F22,Lista_CUIT!$A$1:$D$2241,3,0)),"CUIT NO CARGADO") -> 0 | R22: =IFERROR(IF('Abr-26'!$F22="","-",VLOOKUP('Abr-26'!$F22,Lista_CUIT!$A$1:$D$2241,4,0)),"CUIT NO CARGADO") -> 0
B23: 46129 | C23: 1 | D23: 50 | E23: 544339 | F23: 30610333822 | G23: =IFERROR(IF('Abr-26'!$F23="","-",VLOOKUP('Abr-26'!$F23,Lista_CUIT!$A$1:$D$2241,2,0)),"CUIT NO CARGADO") -> MASIVOS S A | H23: 4475.21 | I23: ='Abr-26'!$H23*0.21 -> 939.7941 | P23: =SUM('Abr-26'!$H23:$O23) -> 5415.0041 | Q23: =IFERROR(IF('Abr-26'!$F23="","-",VLOOKUP('Abr-26'!$F23,Lista_CUIT!$A$1:$D$2241,3,0)),"CUIT NO CARGADO") -> GASTOS VARIOS | R23: =IFERROR(IF('Abr-26'!$F23="","-",VLOOKUP('Abr-26'!$F23,Lista_CUIT!$A$1:$D$2241,4,0)),"CUIT NO CARGADO") -> 0
B24: 46131 | C24: 1 | D24: 30 | E24: 3215 | F24: 27259980815 | G24: =IFERROR(IF('Abr-26'!$F24="","-",VLOOKUP('Abr-26'!$F24,Lista_CUIT!$A$1:$D$2241,2,0)),"CUIT NO CARGADO") -> COLOMBO LORENA ALEJANDRA | H24: 3305.79 | I24: ='Abr-26'!$H24*0.21 -> 694.2159 | P24: =SUM('Abr-26'!$H24:$O24) -> 4000.0059 | Q24: =IFERROR(IF('Abr-26'!$F24="","-",VLOOKUP('Abr-26'!$F24,Lista_CUIT!$A$1:$D$2241,3,0)),"CUIT NO CARGADO") -> 0 | R24: =IFERROR(IF('Abr-26'!$F24="","-",VLOOKUP('Abr-26'!$F24,Lista_CUIT!$A$1:$D$2241,4,0)),"CUIT NO CARGADO") -> 0
B25: 46132 | C25: 1 | D25: 3 | E25: 382 | F25: 20921575743 | G25: =IFERROR(IF('Abr-26'!$F25="","-",VLOOKUP('Abr-26'!$F25,Lista_CUIT!$A$1:$D$2241,2,0)),"CUIT NO CARGADO") -> RIOS GOMEZ JOSE ANTONIO | H25: 372500 | I25: ='Abr-26'!$H25*0.21 -> 78225 | P25: =SUM('Abr-26'!$H25:$O25) -> 450725 | Q25: =IFERROR(IF('Abr-26'!$F25="","-",VLOOKUP('Abr-26'!$F25,Lista_CUIT!$A$1:$D$2241,3,0)),"CUIT NO CARGADO") -> Papeleria | R25: =IFERROR(IF('Abr-26'!$F25="","-",VLOOKUP('Abr-26'!$F25,Lista_CUIT!$A$1:$D$2241,4,0)),"CUIT NO CARGADO") -> 0
B26: 46133 | C26: 1 | D26: 3 | E26: 16172 | F26: 20936786775 | G26: =IFERROR(IF('Abr-26'!$F26="","-",VLOOKUP('Abr-26'!$F26,Lista_CUIT!$A$1:$D$2241,2,0)),"CUIT NO CARGADO") -> HUNG HSI PAO | H26: 15280.17 | I26: ='Abr-26'!$H26*0.21 -> 3208.8357 | P26: =SUM('Abr-26'!$H26:$O26) -> 18489.006 | Q26: =IFERROR(IF('Abr-26'!$F26="","-",VLOOKUP('Abr-26'!$F26,Lista_CUIT!$A$1:$D$2241,3,0)),"CUIT NO CARGADO") -> 0 | R26: =IFERROR(IF('Abr-26'!$F26="","-",VLOOKUP('Abr-26'!$F26,Lista_CUIT!$A$1:$D$2241,4,0)),"CUIT NO CARGADO") -> 0
B27: 46134 | C27: 1 | D27: 122 | E27: 427147 | F27: 30594494187 | G27: =IFERROR(IF('Abr-26'!$F27="","-",VLOOKUP('Abr-26'!$F27,Lista_CUIT!$A$1:$D$2241,2,0)),"CUIT NO CARGADO") -> FEDERAL EXPRESS CORPORATION | H27: 99036 | I27: ='Abr-26'!$H27*0.21 -> 20797.56 | O27: 495014.94 | P27: =SUM('Abr-26'!$H27:$O27) -> 614848.5 | Q27: =IFERROR(IF('Abr-26'!$F27="","-",VLOOKUP('Abr-26'!$F27,Lista_CUIT!$A$1:$D$2241,3,0)),"CUIT NO CARGADO") -> Mercaderia | R27: =IFERROR(IF('Abr-26'!$F27="","-",VLOOKUP('Abr-26'!$F27,Lista_CUIT!$A$1:$D$2241,4,0)),"CUIT NO CARGADO") -> 0
B28: 46135 | C28: 1 | D28: 9 | E28: 52531 | F28: 30710879199 | G28: =IFERROR(IF('Abr-26'!$F28="","-",VLOOKUP('Abr-26'!$F28,Lista_CUIT!$A$1:$D$2241,2,0)),"CUIT NO CARGADO") -> C C AGRO & TEC S.A. | H28: 113487.6 | I28: ='Abr-26'!$H28*0.21 -> 23832.396 | P28: =SUM('Abr-26'!$H28:$O28) -> 137320 | Q28: =IFERROR(IF('Abr-26'!$F28="","-",VLOOKUP('Abr-26'!$F28,Lista_CUIT!$A$1:$D$2241,3,0)),"CUIT NO CARGADO") -> 0 | R28: =IFERROR(IF('Abr-26'!$F28="","-",VLOOKUP('Abr-26'!$F28,Lista_CUIT!$A$1:$D$2241,4,0)),"CUIT NO CARGADO") -> 0
B29: 46136 | C29: 1 | D29: 2 | E29: 4327 | F29: 30718133412 | G29: =IFERROR(IF('Abr-26'!$F29="","-",VLOOKUP('Abr-26'!$F29,Lista_CUIT!$A$1:$D$2241,2,0)),"CUIT NO CARGADO") -> FULL HOUSE TIENDA S.R.L. | H29: 230926.29 | I29: ='Abr-26'!$H29*0.21 -> 48494.521 | P29: =SUM('Abr-26'!$H29:$O29) -> 279420.81 | Q29: =IFERROR(IF('Abr-26'!$F29="","-",VLOOKUP('Abr-26'!$F29,Lista_CUIT!$A$1:$D$2241,3,0)),"CUIT NO CARGADO") -> 0 | R29: =IFERROR(IF('Abr-26'!$F29="","-",VLOOKUP('Abr-26'!$F29,Lista_CUIT!$A$1:$D$2241,4,0)),"CUIT NO CARGADO") -> 0
B30: 46136 | C30: 1 | D30: 2 | E30: 4328 | F30: 30718133412 | G30: =IFERROR(IF('Abr-26'!$F30="","-",VLOOKUP('Abr-26'!$F30,Lista_CUIT!$A$1:$D$2241,2,0)),"CUIT NO CARGADO") -> FULL HOUSE TIENDA S.R.L. | H30: 293465.29 | I30: ='Abr-26'!$H30*0.21 -> 61627.711 | P30: =SUM('Abr-26'!$H30:$O30) -> 355093 | Q30: =IFERROR(IF('Abr-26'!$F30="","-",VLOOKUP('Abr-26'!$F30,Lista_CUIT!$A$1:$D$2241,3,0)),"CUIT NO CARGADO") -> 0 | R30: =IFERROR(IF('Abr-26'!$F30="","-",VLOOKUP('Abr-26'!$F30,Lista_CUIT!$A$1:$D$2241,4,0)),"CUIT NO CARGADO") -> 0
B31: 46136 | C31: 1 | D31: 100 | E31: 11979 | F31: 30562265844 | G31: =IFERROR(IF('Abr-26'!$F31="","-",VLOOKUP('Abr-26'!$F31,Lista_CUIT!$A$1:$D$2241,2,0)),"CUIT NO CARGADO") -> LA MADRILEÑA SOCIEDAD ANONIMA COMERCIAL INDUSTRIAL AGROPECUARIA FINANCIERA E INMOBILIARIA | H31: 99877.52 | I31: ='Abr-26'!$H31*0.21 -> 20974.279 | P31: =SUM('Abr-26'!$H31:$O31) -> 120851.8 | Q31: =IFERROR(IF('Abr-26'!$F31="","-",VLOOKUP('Abr-26'!$F31,Lista_CUIT!$A$1:$D$2241,3,0)),"CUIT NO CARGADO") -> Ropa de Trabajo | R31: =IFERROR(IF('Abr-26'!$F31="","-",VLOOKUP('Abr-26'!$F31,Lista_CUIT!$A$1:$D$2241,4,0)),"CUIT NO CARGADO") -> 0
B32: 46136 | C32: 1 | D32: 2 | E32: 1127 | F32: 30500805222 | G32: =IFERROR(IF('Abr-26'!$F32="","-",VLOOKUP('Abr-26'!$F32,Lista_CUIT!$A$1:$D$2241,2,0)),"CUIT NO CARGADO") -> KAVCIC SRL | H32: 1227160 | I32: ='Abr-26'!$H32*0.21 -> 257703.6 | P32: =SUM('Abr-26'!$H32:$O32) -> 1484863.6 | Q32: =IFERROR(IF('Abr-26'!$F32="","-",VLOOKUP('Abr-26'!$F32,Lista_CUIT!$A$1:$D$2241,3,0)),"CUIT NO CARGADO") -> Mercaderia | R32: =IFERROR(IF('Abr-26'!$F32="","-",VLOOKUP('Abr-26'!$F32,Lista_CUIT!$A$1:$D$2241,4,0)),"CUIT NO CARGADO") -> 0
B33: 46140 | C33: 1 | D33: 3 | E33: 34267 | F33: 33718350749 | G33: =IFERROR(IF('Abr-26'!$F33="","-",VLOOKUP('Abr-26'!$F33,Lista_CUIT!$A$1:$D$2241,2,0)),"CUIT NO CARGADO") -> MTL3 | H33: 14033.06 | I33: ='Abr-26'!$H33*0.21 -> 2946.9426 | P33: =SUM('Abr-26'!$H33:$O33) -> 16980.003 | Q33: =IFERROR(IF('Abr-26'!$F33="","-",VLOOKUP('Abr-26'!$F33,Lista_CUIT!$A$1:$D$2241,3,0)),"CUIT NO CARGADO") -> 0 | R33: =IFERROR(IF('Abr-26'!$F33="","-",VLOOKUP('Abr-26'!$F33,Lista_CUIT!$A$1:$D$2241,4,0)),"CUIT NO CARGADO") -> 0
B34: 46140 | C34: 1 | D34: 106 | E34: 944699 | F34: 30594494187 | G34: =IFERROR(IF('Abr-26'!$F34="","-",VLOOKUP('Abr-26'!$F34,Lista_CUIT!$A$1:$D$2241,2,0)),"CUIT NO CARGADO") -> FEDERAL EXPRESS CORPORATION | H34: 101880 | I34: ='Abr-26'!$H34*0.21 -> 21394.8 | O34: 495014.94 | P34: =SUM('Abr-26'!$H34:$O34) -> 618289.74 | Q34: =IFERROR(IF('Abr-26'!$F34="","-",VLOOKUP('Abr-26'!$F34,Lista_CUIT!$A$1:$D$2241,3,0)),"CUIT NO CARGADO") -> Mercaderia | R34: =IFERROR(IF('Abr-26'!$F34="","-",VLOOKUP('Abr-26'!$F34,Lista_CUIT!$A$1:$D$2241,4,0)),"CUIT NO CARGADO") -> 0
B35: 46140 | C35: 1 | D35: 443 | E35: 471995 | F35: 30546764040 | G35: =IFERROR(IF('Abr-26'!$F35="","-",VLOOKUP('Abr-26'!$F35,Lista_CUIT!$A$1:$D$2241,2,0)),"CUIT NO CARGADO") -> NESTLE ARG S.A | H35: 15702.48 | I35: ='Abr-26'!$H35*0.21 -> 3297.5208 | O35: 471.08 | P35: =SUM('Abr-26'!$H35:$O35) -> 19471.081 | Q35: =IFERROR(IF('Abr-26'!$F35="","-",VLOOKUP('Abr-26'!$F35,Lista_CUIT!$A$1:$D$2241,3,0)),"CUIT NO CARGADO") -> CATERING | R35: =IFERROR(IF('Abr-26'!$F35="","-",VLOOKUP('Abr-26'!$F35,Lista_CUIT!$A$1:$D$2241,4,0)),"CUIT NO CARGADO") -> 0
B36: 46141 | C36: 1 | D36: 7 | E36: 66133 | F36: 20372347296 | G36: =IFERROR(IF('Abr-26'!$F36="","-",VLOOKUP('Abr-26'!$F36,Lista_CUIT!$A$1:$D$2241,2,0)),"CUIT NO CARGADO") -> GHERTNER SEBASTIAN | H36: 79961.09 | K36: 8395.91 | P36: =SUM('Abr-26'!$H36:$O36) -> 88357 | Q36: =IFERROR(IF('Abr-26'!$F36="","-",VLOOKUP('Abr-26'!$F36,Lista_CUIT!$A$1:$D$2241,3,0)),"CUIT NO CARGADO") -> 0 | R36: =IFERROR(IF('Abr-26'!$F36="","-",VLOOKUP('Abr-26'!$F36,Lista_CUIT!$A$1:$D$2241,4,0)),"CUIT NO CARGADO") -> 0
B37: 46142 | C37: 1 | D37: 5 | E37: 114890 | F37: 30708166673 | G37: =IFERROR(IF('Abr-26'!$F37="","-",VLOOKUP('Abr-26'!$F37,Lista_CUIT!$A$1:$D$2241,2,0)),"CUIT NO CARGADO") -> SUMINISTROS WHITE S.A. | H37: 28924.79 | I37: ='Abr-26'!$H37*0.21 -> 6074.2059 | P37: =SUM('Abr-26'!$H37:$O37) -> 34998.996 | Q37: =IFERROR(IF('Abr-26'!$F37="","-",VLOOKUP('Abr-26'!$F37,Lista_CUIT!$A$1:$D$2241,3,0)),"CUIT NO CARGADO") -> 0 | R37: =IFERROR(IF('Abr-26'!$F37="","-",VLOOKUP('Abr-26'!$F37,Lista_CUIT!$A$1:$D$2241,4,0)),"CUIT NO CARGADO") -> 0
B38: 46135 | C38: 3 | D38: 122 | E38: 85443 | F38: 30594494187 | G38: =IFERROR(IF('Abr-26'!$F38="","-",VLOOKUP('Abr-26'!$F38,Lista_CUIT!$A$1:$D$2241,2,0)),"CUIT NO CARGADO") -> FEDERAL EXPRESS CORPORATION | H38: -99036 | I38: ='Abr-26'!$H38*0.21 -> -20797.56 | O38: -495014.94 | P38: =SUM('Abr-26'!$H38:$O38) -> -614848.5 | Q38: =IFERROR(IF('Abr-26'!$F38="","-",VLOOKUP('Abr-26'!$F38,Lista_CUIT!$A$1:$D$2241,3,0)),"CUIT NO CARGADO") -> Mercaderia | R38: =IFERROR(IF('Abr-26'!$F38="","-",VLOOKUP('Abr-26'!$F38,Lista_CUIT!$A$1:$D$2241,4,0)),"CUIT NO CARGADO") -> 0
G39: =IFERROR(IF('Abr-26'!$F39="","-",VLOOKUP('Abr-26'!$F39,Lista_CUIT!$A$1:$D$2241,2,0)),"CUIT NO CARGADO") -> - | I39: ='Abr-26'!$H39*0.21 -> 0 | P39: =SUM('Abr-26'!$H39:$O39) -> 0 | Q39: =IFERROR(IF('Abr-26'!$F39="","-",VLOOKUP('Abr-26'!$F39,Lista_CUIT!$A$1:$D$2241,3,0)),"CUIT NO CARGADO") -> - | R39: =IFERROR(IF('Abr-26'!$F39="","-",VLOOKUP('Abr-26'!$F39,Lista_CUIT!$A$1:$D$2241,4,0)),"CUIT NO CARGADO") -> -
B40: Total | H40: =SUBTOTAL(109,'Abr-26'!$H$9:$H$39) -> 4470165.3 | I40: =SUBTOTAL(109,'Abr-26'!$I$9:$I$39) -> 670181.4 | J40: =SUBTOTAL(109,'Abr-26'!$J$9:$J$39) -> 0 | K40: =SUBTOTAL(109,'Abr-26'!$K$9:$K$39) -> 134276.66 | L40: =SUBTOTAL(109,'Abr-26'!$L$9:$L$39) -> 0 | M40: =SUBTOTAL(109,'Abr-26'!$M$9:$M$39) -> 0 | N40: =SUBTOTAL(109,'Abr-26'!$N$9:$N$39) -> 0 | O40: =SUBTOTAL(109,'Abr-26'!$O$9:$O$39) -> 1600923.2 | P40: =SUBTOTAL(109,'Abr-26'!$P$9:$P$39) -> 6875546.6
D45: LIQUIDACION EXTRACTOS BANCARIOS-TARJETAS
D46: FECHA | E46: NRO CPTE | F46: BANCO | G46: NETO | H46: IVA 21% | I46: IVA 10,5% | J46: RET IIBB CABA | K46: PERC IVA | L46: PERC IIBB | M46: total
F47: CREDICOOP | G47: =57838.46/0.21 -> 275421.24 | H47: ='Abr-26'!$G47*0.21 -> 57838.46 | K47: 8172.64 | M47: ='Abr-26'!$G47+'Abr-26'!$H47+'Abr-26'!$I47+'Abr-26'!$J47+'Abr-26'!$K47 -> 341432.34
H48: ='Abr-26'!$G48*0.21 -> 0 | M48: ='Abr-26'!$G48+'Abr-26'!$H48+'Abr-26'!$I48+'Abr-26'!$J48+'Abr-26'!$K48 -> 0
...

Sheet May-26
B1: LIBRO IVA COMPRAS | G1: ='Abr-26'!G1:M1 -> CORITEC S. R. L. | N1: 45778
B3: TOTAL COMPRAS | G3: TOTAL CREDITO FISCAL | J3: TOTAL VENTAS NETAS | M3: TOTAL DEBITO FISCAL | P3: RESULTADO
B4: =SUM('May-26'!$H$30)+'May-26'!$G$43 -> 6550641.4 | G4: ='May-26'!$I$30+'May-26'!$J$30+'May-26'!$K$30+'May-26'!$H$43+'May-26'!$I$43 -> 1377661.8 | J4: =SUM('May-26'!$H$81+'May-26'!$H$93) -> 1.2597229e+08 | M4: =SUM('May-26'!$I$81+'May-26'!$J$81+'May-26'!$I$93+'May-26'!$J$93) -> 15754768 | P4: =G4-M4 -> -14377106
B8: FECHA | C8: TIPO | D8: PTO VTA | E8: NRO. CPTE | F8: CUIT | G8: RAZON SOCIAL | H8: NETO GRAVADO | I8: IVA 21 % | J8: IVA 27% | K8: IVA 10,5% | L8: PERC. IVA | M8: PERC IIBB BS AS | N8: PERC. IIBB CABA | O8: Otros / No Grav. | P8: TOTAL | Q8: Tipo de Gasto | R8: Provincia
B9: 45778 | C9: 1 | D9: 3 | E9: 265149 | F9: 30707135596 | G9: =IFERROR(IF('May-26'!$F9="","-",VLOOKUP('May-26'!$F9,Lista_CUIT!$A$1:$D$2241,2,0)),"CUIT NO CARGADO") -> CITILAN ARGENTINA S.A. | H9: 28785 | I9: =IF('May-26'!$H9="","",'May-26'!$H9*0.21) -> 6044.85 | P9: =SUM('May-26'!$H9:$O9) -> 34829.85 | Q9: =IFERROR(IF('May-26'!$F9="","-",VLOOKUP('May-26'!$F9,Lista_CUIT!$A$1:$D$2241,3,0)),"CUIT NO CARGADO") -> Telefonia | R9: =IFERROR(IF('May-26'!$F9="","-",VLOOKUP('May-26'!$F9,Lista_CUIT!$A$1:$D$2241,4,0)),"CUIT NO CARGADO") -> 0
B10: 45778 | C10: 1 | D10: 3 | E10: 857 | F10: 30715402765 | G10: =IFERROR(IF('May-26'!$F10="","-",VLOOKUP('May-26'!$F10,Lista_CUIT!$A$1:$D$2241,2,0)),"CUIT NO CARGADO") -> RIO 265 S.R.L. | H10: 90909.1 | I10: =IF('May-26'!$H10="","",'May-26'!$H10*0.21) -> 19090.911 | P10: =SUM('May-26'!$H10:$O10) -> 110000.01 | Q10: =IFERROR(IF('May-26'!$F10="","-",VLOOKUP('May-26'!$F10,Lista_CUIT!$A$1:$D$2241,3,0)),"CUIT NO CARGADO") -> GASTOS VARIOS | R10: =IFERROR(IF('May-26'!$F10="","-",VLOOKUP('May-26'!$F10,Lista_CUIT!$A$1:$D$2241,4,0)),"CUIT NO CARGADO") -> 0
B11: 45782 | C11: 1 | D11: 2 | E11: 864 | F11: 20296550184 | G11: =IFERROR(IF('May-26'!$F11="","-",VLOOKUP('May-26'!$F11,Lista_CUIT!$A$1:$D$2241,2,0)),"CUIT NO CARGADO") -> COSTA DIEGO ALEJANDRO | H11: 763250 | I11: =IF('May-26'!$H11="","",'May-26'!$H11*0.21) -> 160282.5 | P11: =SUM('May-26'!$H11:$O11) -> 923532.5 | Q11: =IFERROR(IF('May-26'!$F11="","-",VLOOKUP('May-26'!$F11,Lista_CUIT!$A$1:$D$2241,3,0)),"CUIT NO CARGADO") -> Mat. Prima | R11: =IFERROR(IF('May-26'!$F11="","-",VLOOKUP('May-26'!$F11,Lista_CUIT!$A$1:$D$2241,4,0)),"CUIT NO CARGADO") -> 0
B12: 45784 | C12: 1 | D12: 2 | E12: 213 | F12: 20125142851 | G12: =IFERROR(IF('May-26'!$F12="","-",VLOOKUP('May-26'!$F12,Lista_CUIT!$A$1:$D$2241,2,0)),"CUIT NO CARGADO") -> FEDERICI NICOLAS JOSE | H12: 2228424.5 | I12: =IF('May-26'!$H12="","",'May-26'!$H12*0.21) -> 467969.14 | P12: =SUM('May-26'!$H12:$O12) -> 2696393.6 | Q12: =IFERROR(IF('May-26'!$F12="","-",VLOOKUP('May-26'!$F12,Lista_CUIT!$A$1:$D$2241,3,0)),"CUIT NO CARGADO") -> INSUMO | R12: =IFERROR(IF('May-26'!$F12="","-",VLOOKUP('May-26'!$F12,Lista_CUIT!$A$1:$D$2241,4,0)),"CUIT NO CARGADO") -> 0
B13: 45788 | C13: 1 | D13: 2466 | E13: 789845 | F13: 30678814357 | G13: =IFERROR(IF('May-26'!$F13="","-",VLOOKUP('May-26'!$F13,Lista_CUIT!$A$1:$D$2241,2,0)),"CUIT NO CARGADO") -> TELEFONICA MOVILES ARG | H13: 33785 | J13: 9121.95 | L13: 1013.55 | O13: 1778.14 | P13: =SUM('May-26'!$H13:$O13) -> 45698.64 | Q13: =IFERROR(IF('May-26'!$F13="","-",VLOOKUP('May-26'!$F13,Lista_CUIT!$A$1:$D$2241,3,0)),"CUIT NO CARGADO") -> Telefonia | R13: =IFERROR(IF('May-26'!$F13="","-",VLOOKUP('May-26'!$F13,Lista_CUIT!$A$1:$D$2241,4,0)),"CUIT NO CARGADO") -> 0
B14: 45792 | C14: 1 | D14: 5 | E14: 23382 | F14: 30716006391 | G14: =IFERROR(IF('May-26'!$F14="","-",VLOOKUP('May-26'!$F14,Lista_CUIT!$A$1:$D$2241,2,0)),"CUIT NO CARGADO") -> ALLISING | H14: 31885.95 | I14: =IF('May-26'!$H14="","",'May-26'!$H14*0.21) -> 6696.0495 | P14: =SUM('May-26'!$H14:$O14) -> 38581.999 | Q14: =IFERROR(IF('May-26'!$F14="","-",VLOOKUP('May-26'!$F14,Lista_CUIT!$A$1:$D$2241,3,0)),"CUIT NO CARGADO") -> GASTOS VARIOS | R14: =IFERROR(IF('May-26'!$F14="","-",VLOOKUP('May-26'!$F14,Lista_CUIT!$A$1:$D$2241,4,0)),"CUIT NO CARGADO") -> 0
B15: 45793 | C15: 1 | D15: 106 | E15: 841105 | F15: 30594494187 | G15: =IFERROR(IF('May-26'!$F15="","-",VLOOKUP('May-26'!$F15,Lista_CUIT!$A$1:$D$2241,2,0)),"CUIT NO CARGADO") -> FEDERAL EXPRESS CORPORATION | H15: 0 | I15: =IF('May-26'!$H15="","",'May-26'!$H15*0.21) -> 0 | O15: 581628.9 | P15: =SUM('May-26'!$H15:$O15) -> 581628.9 | Q15: =IFERROR(IF('May-26'!$F15="","-",VLOOKUP('May-26'!$F15,Lista_CUIT!$A$1:$D$2241,3,0)),"CUIT NO CARGADO") -> Mercaderia | R15: =IFERROR(IF('May-26'!$F15="","-",VLOOKUP('May-26'!$F15,Lista_CUIT!$A$1:$D$2241,4,0)),"CUIT NO CARGADO") -> 0
B16: 45797 | C16: 1 | D16: 4 | E16: 108370 | F16: 30559932236 | G16: =IFERROR(IF('May-26'!$F16="","-",VLOOKUP('May-26'!$F16,Lista_CUIT!$A$1:$D$2241,2,0)),"CUIT NO CARGADO") -> ELECTRONICA ELEMON S A | H16: 225187.46 | I16: =IF('May-26'!$H16="","",'May-26'!$H16*0.21) -> 47289.367 | P16: =SUM('May-26'!$H16:$O16) -> 272476.83 | Q16: =IFERROR(IF('May-26'!$F16="","-",VLOOKUP('May-26'!$F16,Lista_CUIT!$A$1:$D$2241,3,0)),"CUIT NO CARGADO") -> Mat. Prima | R16: =IFERROR(IF('May-26'!$F16="","-",VLOOKUP('May-26'!$F16,Lista_CUIT!$A$1:$D$2241,4,0)),"CUIT NO CARGADO") -> 0
B17: 45797 | C17: 1 | D17: 1 | E17: 813 | F17: 30717231135 | G17: =IFERROR(IF('May-26'!$F17="","-",VLOOKUP('May-26'!$F17,Lista_CUIT!$A$1:$D$2241,2,0)),"CUIT NO CARGADO") -> WAREHOUSE ARGENTINA S.A.S. | H17: 125619.86 | I17: =IF('May-26'!$H17="","",'May-26'!$H17*0.21) -> 26380.171 | P17: =SUM('May-26'!$H17:$O17) -> 152000.03 | Q17: =IFERROR(IF('May-26'!$F17="","-",VLOOKUP('May-26'!$F17,Lista_CUIT!$A$1:$D$2241,3,0)),"CUIT NO CARGADO") -> INSUMO | R17: =IFERROR(IF('May-26'!$F17="","-",VLOOKUP('May-26'!$F17,Lista_CUIT!$A$1:$D$2241,4,0)),"CUIT NO CARGADO") -> 0
B18: 45799 | C18: 1 | D18: 251 | E18: 4102 | F18: 30710276273 | G18: =IFERROR(IF('May-26'!$F18="","-",VLOOKUP('May-26'!$F18,Lista_CUIT!$A$1:$D$2241,2,0)),"CUIT NO CARGADO") -> SEDEX ARGENTINA SA | H18: 15206.62 | I18: =IF('May-26'!$H18="","",'May-26'!$H18*0.21) -> 3193.3902 | P18: =SUM('May-26'!$H18:$O18) -> 18400.01 | Q18: =IFERROR(IF('May-26'!$F18="","-",VLOOKUP('May-26'!$F18,Lista_CUIT!$A$1:$D$2241,3,0)),"CUIT NO CARGADO") -> FLETE-LOGISTICA | R18: =IFERROR(IF('May-26'!$F18="","-",VLOOKUP('May-26'!$F18,Lista_CUIT!$A$1:$D$2241,4,0)),"CUIT NO CARGADO") -> 0
B19: 45799 | C19: 1 | D19: 5 | E19: 84621 | F19: 30692857611 | G19: =IFERROR(IF('May-26'!$F19="","-",VLOOKUP('May-26'!$F19,Lista_CUIT!$A$1:$D$2241,2,0)),"CUIT NO CARGADO") -> BAGUI S A | H19: 1106796.6 | I19: =IF('May-26'!$H19="","",'May-26'!$H19*0.21) -> 232427.29 | P19: =SUM('May-26'!$H19:$O19) -> 1339223.9 | Q19: =IFERROR(IF('May-26'!$F19="","-",VLOOKUP('May-26'!$F19,Lista_CUIT!$A$1:$D$2241,3,0)),"CUIT NO CARGADO") -> INSUMO | R19: =IFERROR(IF('May-26'!$F19="","-",VLOOKUP('May-26'!$F19,Lista_CUIT!$A$1:$D$2241,4,0)),"CUIT NO CARGADO") -> 0
B20: 45799 | C20: 1 | D20: 2 | E20: 17544 | F20: 30624684628 | G20: =IFERROR(IF('May-26'!$F20="","-",VLOOKUP('May-26'!$F20,Lista_CUIT!$A$1:$D$2241,2,0)),"CUIT NO CARGADO") -> MITSUKO ARGENTINA S R L | H20: 844740 | I20: =IF('May-26'!$H20="","",'May-26'!$H20*0.21) -> 177395.4 | P20: =SUM('May-26'!$H20:$O20) -> 1022135.4 | Q20: =IFERROR(IF('May-26'!$F20="","-",VLOOKUP('May-26'!$F20,Lista_CUIT!$A$1:$D$2241,3,0)),"CUIT NO CARGADO") -> INSUMO | R20: =IFERROR(IF('May-26'!$F20="","-",VLOOKUP('May-26'!$F20,Lista_CUIT!$A$1:$D$2241,4,0)),"CUIT NO CARGADO") -> 0
B21: 45802 | C21: 1 | D21: 3326 | E21: 16665 | F21: 30526874249 | G21: =IFERROR(IF('May-26'!$F21="","-",VLOOKUP('May-26'!$F21,Lista_CUIT!$A$1:$D$2241,2,0)),"CUIT NO CARGADO") -> FRAVEGA | H21: 330577.69 | I21: =IF('May-26'!$H21="","",'May-26'!$H21*0.21) -> 69421.315 | P21: =SUM('May-26'!$H21:$O21) -> 399999 | Q21: =IFERROR(IF('May-26'!$F21="","-",VLOOKUP('May-26'!$F21,Lista_CUIT!$A$1:$D$2241,3,0)),"CUIT NO CARGADO") -> Gastos Varios | R21: =IFERROR(IF('May-26'!$F21="","-",VLOOKUP('May-26'!$F21,Lista_CUIT!$A$1:$D$2241,4,0)),"CUIT NO CARGADO") -> 0
B22: 45803 | C22: 1 | D22: 700 | E22: 794725 | F22: 30580111315 | G22: =IFERROR(IF('May-26'!$F22="","-",VLOOKUP('May-26'!$F22,Lista_CUIT!$A$1:$D$2241,2,0)),"CUIT NO CARGADO") -> DHL EXPRESS (ARGENTINA) S.A. | H22: 0 | I22: =IF('May-26'!$H22="","",'May-26'!$H22*0.21) -> 0 | O22: =202.59*1150 -> 232978.5 | P22: =SUM('May-26'!$H22:$O22) -> 232978.5 | Q22: =IFERROR(IF('May-26'!$F22="","-",VLOOKUP('May-26'!$F22,Lista_CUIT!$A$1:$D$2241,3,0)),"CUIT NO CARGADO") -> Mercaderia | R22: =IFERROR(IF('May-26'!$F22="","-",VLOOKUP('May-26'!$F22,Lista_CUIT!$A$1:$D$2241,4,0)),"CUIT NO CARGADO") -> 0
B23: 45805 | C23: 1 | D23: 122 | E23: 368811 | F23: 30594494187 | G23: =IFERROR(IF('May-26'!$F23="","-",VLOOKUP('May-26'!$F23,Lista_CUIT!$A$1:$D$2241,2,0)),"CUIT NO CARGADO") -> FEDERAL EXPRESS CORPORATION | H23: 83232 | I23: =IF('May-26'!$H23="","",'May-26'!$H23*0.21) -> 17478.72 | O23: 277532.48 | P23: =SUM('May-26'!$H23:$O23) -> 378243.2 | Q23: =IFERROR(IF('May-26'!$F23="","-",VLOOKUP('May-26'!$F23,Lista_CUIT!$A$1:$D$2241,3,0)),"CUIT NO CARGADO") -> Mercaderia | R23: =IFERROR(IF('May-26'!$F23="","-",VLOOKUP('May-26'!$F23,Lista_CUIT!$A$1:$D$2241,4,0)),"CUIT NO CARGADO") -> 0
B24: 45805 | C24: 1 | D24: 5 | E24: 33681 | F24: 30646938755 | G24: =IFERROR(IF('May-26'!$F24="","-",VLOOKUP('May-26'!$F24,Lista_CUIT!$A$1:$D$2241,2,0)),"CUIT NO CARGADO") -> LASARTE HNOS SRL | H24: 209583 | I24: =IF('May-26'!$H24="","",'May-26'!$H24*0.21) -> 44012.43 | P24: =SUM('May-26'!$H24:$O24) -> 253595.43 | Q24: =IFERROR(IF('May-26'!$F24="","-",VLOOKUP('May-26'!$F24,Lista_CUIT!$A$1:$D$2241,3,0)),"CUIT NO CARGADO") -> Mantenimiento | R24: =IFERROR(IF('May-26'!$F24="","-",VLOOKUP('May-26'!$F24,Lista_CUIT!$A$1:$D$2241,4,0)),"CUIT NO CARGADO") -> 0
B25: 45807 | C25: 1 | D25: 5 | E25: 6083 | F25: 20231333593 | G25: =IFERROR(IF('May-26'!$F25="","-",VLOOKUP('May-26'!$F25,Lista_CUIT!$A$1:$D$2241,2,0)),"CUIT NO CARGADO") -> BOLLINI CLAUDIO DANIEL | H25: 80000 | I25: =IF('May-26'!$H25="","",'May-26'!$H25*0.21) -> 16800 | P25: =SUM('May-26'!$H25:$O25) -> 96800 | Q25: =IFERROR(IF('May-26'!$F25="","-",VLOOKUP('May-26'!$F25,Lista_CUIT!$A$1:$D$2241,3,0)),"CUIT NO CARGADO") -> Mantenimiento | R25: =IFERROR(IF('May-26'!$F25="","-",VLOOKUP('May-26'!$F25,Lista_CUIT!$A$1:$D$2241,4,0)),"CUIT NO CARGADO") -> 0
B26: 45807 | C26: 1 | D26: 35 | E26: 3756 | F26: 30516199292 | G26: =IFERROR(IF('May-26'!$F26="","-",VLOOKUP('May-26'!$F26,Lista_CUIT!$A$1:$D$2241,2,0)),"CUIT NO CARGADO") -> S V A SACIFI | H26: 246385.21 | I26: =IF('May-26'!$H26="","",'May-26'!$H26*0.21) -> 51740.894 | P26: =SUM('May-26'!$H26:$O26) -> 298126.1 | Q26: =IFERROR(IF('May-26'!$F26="","-",VLOOKUP('May-26'!$F26,Lista_CUIT!$A$1:$D$2241,3,0)),"CUIT NO CARGADO") -> Mant. Vehiculo | R26: =IFERROR(IF('May-26'!$F26="","-",VLOOKUP('May-26'!$F26,Lista_CUIT!$A$1:$D$2241,4,0)),"CUIT NO CARGADO") -> 0
B27: 45808 | C27: 1 | D27: 3 | E27: 9638 | F27: 30710585411 | G27: =IFERROR(IF('May-26'!$F27="","-",VLOOKUP('May-26'!$F27,Lista_CUIT!$A$1:$D$2241,2,0)),"CUIT NO CARGADO") -> POSITIF PLANIFIER S.A. | H27: 107563.64 | I27: =IF('May-26'!$H27="","",'May-26'!$H27*0.21) -> 22588.364 | P27: =SUM('May-26'!$H27:$O27) -> 130152 | Q27: =IFERROR(IF('May-26'!$F27="","-",VLOOKUP('May-26'!$F27,Lista_CUIT!$A$1:$D$2241,3,0)),"CUIT NO CARGADO") -> Gastos de Comercializacion | R27: =IFERROR(IF('May-26'!$F27="","-",VLOOKUP('May-26'!$F27,Lista_CUIT!$A$1:$D$2241,4,0)),"CUIT NO CARGADO") -> 0
B28: 45806 | C28: 3 | D28: 122 | E28: 71417 | F28: 30594494187 | G28: =IFERROR(IF('May-26'!$F28="","-",VLOOKUP('May-26'!$F28,Lista_CUIT!$A$1:$D$2241,2,0)),"CUIT NO CARGADO") -> FEDERAL EXPRESS CORPORATION | H28: -83232 | I28: =IF('May-26'!$H28="","",'May-26'!$H28*0.21) -> -17478.72 | O28: -277532.48 | P28: =SUM('May-26'!$H28:$O28) -> -378243.2 | Q28: =IFERROR(IF('May-26'!$F28="","-",VLOOKUP('May-26'!$F28,Lista_CUIT!$A$1:$D$2241,3,0)),"CUIT NO CARGADO") -> Mercaderia | R28: =IFERROR(IF('May-26'!$F28="","-",VLOOKUP('May-26'!$F28,Lista_CUIT!$A$1:$D$2241,4,0)),"CUIT NO CARGADO") -> 0
G29: =IFERROR(IF('May-26'!$F29="","-",VLOOKUP('May-26'!$F29,Lista_CUIT!$A$1:$D$2241,2,0)),"CUIT NO CARGADO") -> - | I29: =IF('May-26'!$H29="","",'May-26'!$H29*0.21) | P29: =SUM('May-26'!$H29:$O29) -> 0 | Q29: =IFERROR(IF('May-26'!$F29="","-",VLOOKUP('May-26'!$F29,Lista_CUIT!$A$1:$D$2241,3,0)),"CUIT NO CARGADO") -> - | R29: =IFERROR(IF('May-26'!$F29="","-",VLOOKUP('May-26'!$F29,Lista_CUIT!$A$1:$D$2241,4,0)),"CUIT NO CARGADO") -> -
B30: Total | H30: =SUBTOTAL(109,'May-26'!$H$9:$H$29) -> 6468699.6 | I30: =SUBTOTAL(109,'May-26'!$I$9:$I$29) -> 1351332.1 | J30: =SUBTOTAL(109,'May-26'!$J$9:$J$29) -> 9121.95 | K30: =SUBTOTAL(109,'May-26'!$K$9:$K$29) -> 0 | L30: =SUBTOTAL(109,'May-26'!$L$9:$L$29) -> 1013.55 | M30: =SUBTOTAL(109,'May-26'!$M$9:$M$29) -> 0 | N30: =SUBTOTAL(109,'May-26'!$N$9:$N$29) -> 0 | O30: =SUBTOTAL(109,'May-26'!$O$9:$O$29) -> 816385.54 | P30: =SUBTOTAL(109,'May-26'!$P$9:$P$29) -> 8646552.7
D35: LIQUIDACION EXTRACTOS BANCARIOS-TARJETAS
D36: FECHA | E36: NRO CPTE | F36: BANCO | G36: NETO | H36: IVA 21% | I36: IVA 10,5% | J36: RET IIBB CABA | K36: PERC IVA | L36: PERC IIBB
D37: 45808 | F37: CREDICOOP | G37: 81941.81 | H37: ='May-26'!$G37*0.21 -> 17207.78 | K37: 2216.75
H38: ='May-26'!$G38*0.21 -> 0
H39: ='May-26'!$G39*0.21 -> 0
H40: ='May-26'!$G40*0.21 -> 0
H41: ='May-26'!$G41*0.21 -> 0
H42: ='May-26'!$G42*0.21 -> 0
D43: Total | G43: =SUBTOTAL(109,'May-26'!$G$37:$G$42) -> 81941.81 | H43: =SUBTOTAL(109,'May-26'!$H$37:$H$42) -> 17207.78 | I43: =SUBTOTAL(109,'May-26'!$I$37:$I$42) -> 0 | J43: =SUBTOTAL(109,'May-26'!$J$37:$J$42) -> 0 | K43: =SUBTOTAL(109,'May-26'!$K$37:$K$42) -> 2216.75 | L43: =SUBTOTAL(109,'May-26'!$L$37:$L$42) -> 0
D47: FACTURAS C
D48: FECHA | E48: PTO VTA | F48: FC Nº | G48: CUIT | H48: RAZON SOCIAL | I48: TOTAL | J48: TIPO DE GASTO | K48: Provincia
D49: 45778 | E49: 4 | F49: 20 | G49: 20086277523 | H49: =IFERROR(IF('May-26'!$G49="","-",VLOOKUP('May-26'!$G49,Lista_CUIT!$A$1:$D$2241,2,0)),"CUIT NO CARGADO") -> ESTUDIO BOTINDARI | I49: 335000 | J49: =IFERROR(IF('May-26'!$G49="","-",VLOOKUP('May-26'!$G49,Lista_CUIT!$A$1:$D$2241,3,0)),"CUIT NO CARGADO") -> Honorarios Contables | K49: =IFERROR(IF('May-26'!$G49="","-",VLOOKUP('May-26'!$G49,Lista_CUIT!$A$1:$D$2241,4,0)),"CUIT NO CARGADO") -> 0
D50: 45778 | E50: 1 | F50: 49 | G50: 20365938688 | H50: =IFERROR(IF('May-26'!$G50="","-",VLOOKUP('May-26'!$G50,Lista_CUIT!$A$1:$D$2241,2,0)),"CUIT NO CARGADO") -> LIPANOVICH JUAN CRUZ | I50: 1583679 | J50: =IFERROR(IF('May-26'!$G50="","-",VLOOKUP('May-26'!$G50,Lista_CUIT!$A$1:$D$2241,3,0)),"CUIT NO CARGADO") -> SOFTWARE | K50: =IFERROR(IF('May-26'!$G50="","-",VLOOKUP('May-26'!$G50,Lista_CUIT!$A$1:$D$2241,4,0)),"CUIT NO CARGADO") -> 0
D51: 45778 | E51: 2 | F51: 183 | G51: 20136544625 | H51: =IFERROR(IF('May-26'!$G51="","-",VLOOKUP('May-26'!$G51,Lista_CUIT!$A$1:$D$2241,2,0)),"CUIT NO CARGADO") -> RODRIGUEZ DE LA FUEN HECTOR MARCELO | I51: 1283000 | J51: =IFERROR(IF('May-26'!$G51="","-",VLOOKUP('May-26'!$G51,Lista_CUIT!$A$1:$D$2241,3,0)),"CUIT NO CARGADO") -> Honorarios Admin | K51: =IFERROR(IF('May-26'!$G51="","-",VLOOKUP('May-26'!$G51,Lista_CUIT!$A$1:$D$2241,4,0)),"CUIT NO CARGADO") -> 0
...

Sheet Jun-26
B1: LIBRO IVA COMPRAS | G1: ='Abr-26'!G1:M1 -> CORITEC S. R. L. | N1: =EDATE('Abr-26'!N1,2) -> 45809
B3: TOTAL COMPRAS | G3: TOTAL CREDITO FISCAL | J3: TOTAL VENTAS NETAS | M3: TOTAL DEBITO FISCAL | P3: RESULTADO
B4: =SUM('Jun-26'!$H$44)+'Jun-26'!$G$53 -> 12776359 | G4: ='Jun-26'!$I$44+'Jun-26'!$J$44+'Jun-26'!$K$44+'Jun-26'!$H$53+'Jun-26'!$I$53 -> 2683035.3 | J4: ='Jun-26'!$H$93+'Jun-26'!$H$104 -> 68234426 | M4: ='Jun-26'!$I$93+'Jun-26'!$J$93+'Jun-26'!$I$104+'Jun-26'!$J$104 -> 8091956 | P4: =G4-M4 -> -5408920.7
B8: FECHA | C8: TIPO | D8: PTO VTA | E8: NRO. CPTE | F8: CUIT | G8: RAZON SOCIAL | H8: NETO GRAVADO | I8: IVA 21 % | J8: IVA 27% | K8: IVA 10,5% | L8: PERC. IVA | M8: PERC IIBB BS AS | N8: PERC. IIBB CABA | O8: Otros / No Grav. | P8: TOTAL | Q8: Tipo de Gasto | R8: Provincia
B9: 45809 | C9: 1 | D9: 3 | E9: 268474 | F9: 30707135596 | G9: =IFERROR(IF('Jun-26'!$F9="","-",VLOOKUP('Jun-26'!$F9,Lista_CUIT!$A$1:$D$2241,2,0)),"CUIT NO CARGADO") -> CITILAN ARGENTINA S.A. | H9: 28851.11 | I9: =IF('Jun-26'!$H9="","",'Jun-26'!$H9*0.21) -> 6058.7331 | P9: =SUM('Jun-26'!$H9:$O9) -> 34909.843 | Q9: =IFERROR(IF('Jun-26'!$F9="","-",VLOOKUP('Jun-26'!$F9,Lista_CUIT!$A$1:$D$2241,3,0)),"CUIT NO CARGADO") -> Telefonia | R9: =IFERROR(IF('Jun-26'!$F9="","-",VLOOKUP('Jun-26'!$F9,Lista_CUIT!$A$1:$D$2241,4,0)),"CUIT NO CARGADO") -> 0
B10: 45809 | C10: 1 | D10: 3 | E10: 866 | F10: 30715402765 | G10: =IFERROR(IF('Jun-26'!$F10="","-",VLOOKUP('Jun-26'!$F10,Lista_CUIT!$A$1:$D$2241,2,0)),"CUIT NO CARGADO") -> RIO 265 S.R.L. | H10: 93388.43 | I10: =IF('Jun-26'!$H10="","",'Jun-26'!$H10*0.21) -> 19611.57 | P10: =SUM('Jun-26'!$H10:$O10) -> 113000 | Q10: =IFERROR(IF('Jun-26'!$F10="","-",VLOOKUP('Jun-26'!$F10,Lista_CUIT!$A$1:$D$2241,3,0)),"CUIT NO CARGADO") -> GASTOS VARIOS | R10: =IFERROR(IF('Jun-26'!$F10="","-",VLOOKUP('Jun-26'!$F10,Lista_CUIT!$A$1:$D$2241,4,0)),"CUIT NO CARGADO") -> 0
B11: 45810 | C11: 1 | D11: 106 | E11: 846433 | F11: 30594494187 | G11: =IFERROR(IF('Jun-26'!$F11="","-",VLOOKUP('Jun-26'!$F11,Lista_CUIT!$A$1:$D$2241,2,0)),"CUIT NO CARGADO") -> FEDERAL EXPRESS CORPORATION | H11: 86040 | I11: =IF('Jun-26'!$H11="","",'Jun-26'!$H11*0.21) -> 18068.4 | O11: 277532.48 | P11: =SUM('Jun-26'!$H11:$O11) -> 381640.88 | Q11: =IFERROR(IF('Jun-26'!$F11="","-",VLOOKUP('Jun-26'!$F11,Lista_CUIT!$A$1:$D$2241,3,0)),"CUIT NO CARGADO") -> Mercaderia | R11: =IFERROR(IF('Jun-26'!$F11="","-",VLOOKUP('Jun-26'!$F11,Lista_CUIT!$A$1:$D$2241,4,0)),"CUIT NO CARGADO") -> 0
B12: 45811 | C12: 1 | D12: 10 | E12: 50250 | F12: 20357275882 | G12: =IFERROR(IF('Jun-26'!$F12="","-",VLOOKUP('Jun-26'!$F12,Lista_CUIT!$A$1:$D$2241,2,0)),"CUIT NO CARGADO") -> LAVADERO BLANCANIEVES | H12: 7429.75 | I12: =IF('Jun-26'!$H12="","",'Jun-26'!$H12*0.21) -> 1560.2475 | P12: =SUM('Jun-26'!$H12:$O12) -> 8989.9975 | Q12: =IFERROR(IF('Jun-26'!$F12="","-",VLOOKUP('Jun-26'!$F12,Lista_CUIT!$A$1:$D$2241,3,0)),"CUIT NO CARGADO") -> Seg e Higiene | R12: =IFERROR(IF('Jun-26'!$F12="","-",VLOOKUP('Jun-26'!$F12,Lista_CUIT!$A$1:$D$2241,4,0)),"CUIT NO CARGADO") -> 0
B13: 45811 | C13: 1 | D13: 3 | E13: 5326 | F13: 30718266420 | G13: =IFERROR(IF('Jun-26'!$F13="","-",VLOOKUP('Jun-26'!$F13,Lista_CUIT!$A$1:$D$2241,2,0)),"CUIT NO CARGADO") -> GOLDEN CAN ARGENTINA S.A.S. | H13: 28522.31 | I13: =IF('Jun-26'!$H13="","",'Jun-26'!$H13*0.21) -> 5989.6851 | P13: =SUM('Jun-26'!$H13:$O13) -> 34511.995 | Q13: =IFERROR(IF('Jun-26'!$F13="","-",VLOOKUP('Jun-26'!$F13,Lista_CUIT!$A$1:$D$2241,3,0)),"CUIT NO CARGADO") -> Gastos Oficina | R13: =IFERROR(IF('Jun-26'!$F13="","-",VLOOKUP('Jun-26'!$F13,Lista_CUIT!$A$1:$D$2241,4,0)),"CUIT NO CARGADO") -> 0
B14: 45811 | C14: 1 | D14: 5 | E14: 85054 | F14: 30692857611 | G14: =IFERROR(IF('Jun-26'!$F14="","-",VLOOKUP('Jun-26'!$F14,Lista_CUIT!$A$1:$D$2241,2,0)),"CUIT NO CARGADO") -> BAGUI S A | H14: 436035.6 | I14: =IF('Jun-26'!$H14="","",'Jun-26'!$H14*0.21) -> 91567.476 | P14: =SUM('Jun-26'!$H14:$O14) -> 527603.08 | Q14: =IFERROR(IF('Jun-26'!$F14="","-",VLOOKUP('Jun-26'!$F14,Lista_CUIT!$A$1:$D$2241,3,0)),"CUIT NO CARGADO") -> INSUMO | R14: =IFERROR(IF('Jun-26'!$F14="","-",VLOOKUP('Jun-26'!$F14,Lista_CUIT!$A$1:$D$2241,4,0)),"CUIT NO CARGADO") -> 0
B15: 45812 | C15: 1 | D15: 10 | E15: 50297 | F15: 20357275882 | G15: =IFERROR(IF('Jun-26'!$F15="","-",VLOOKUP('Jun-26'!$F15,Lista_CUIT!$A$1:$D$2241,2,0)),"CUIT NO CARGADO") -> LAVADERO BLANCANIEVES | H15: 7429.75 | I15: =IF('Jun-26'!$H15="","",'Jun-26'!$H15*0.21) -> 1560.2475 | P15: =SUM('Jun-26'!$H15:$O15) -> 8989.9975 | Q15: =IFERROR(IF('Jun-26'!$F15="","-",VLOOKUP('Jun-26'!$F15,Lista_CUIT!$A$1:$D$2241,3,0)),"CUIT NO CARGADO") -> Seg e Higiene | R15: =IFERROR(IF('Jun-26'!$F15="","-",VLOOKUP('Jun-26'!$F15,Lista_CUIT!$A$1:$D$2241,4,0)),"CUIT NO CARGADO") -> 0
B16: 45812 | C16: 1 | D16: 8 | E16: 46596 | F16: 30709953482 | G16: =IFERROR(IF('Jun-26'!$F16="","-",VLOOKUP('Jun-26'!$F16,Lista_CUIT!$A$1:$D$2241,2,0)),"CUIT NO CARGADO") -> HONRE S.A | H16: 7189.26 | I16: =IF('Jun-26'!$H16="","",'Jun-26'!$H16*0.21) -> 1509.7446 | P16: =SUM('Jun-26'!$H16:$O16) -> 8699.0046 | Q16: =IFERROR(IF('Jun-26'!$F16="","-",VLOOKUP('Jun-26'!$F16,Lista_CUIT!$A$1:$D$2241,3,0)),"CUIT NO CARGADO") -> GASTOS VARIOS | R16: =IFERROR(IF('Jun-26'!$F16="","-",VLOOKUP('Jun-26'!$F16,Lista_CUIT!$A$1:$D$2241,4,0)),"CUIT NO CARGADO") -> 0
B17: 45812 | C17: 1 | D17: 8 | E17: 46506 | F17: 30709953482 | G17: =IFERROR(IF('Jun-26'!$F17="","-",VLOOKUP('Jun-26'!$F17,Lista_CUIT!$A$1:$D$2241,2,0)),"CUIT NO CARGADO") -> HONRE S.A | H17: 7189.26 | I17: =IF('Jun-26'!$H17="","",'Jun-26'!$H17*0.21) -> 1509.7446 | P17: =SUM('Jun-26'!$H17:$O17) -> 8699.0046 | Q17: =IFERROR(IF('Jun-26'!$F17="","-",VLOOKUP('Jun-26'!$F17,Lista_CUIT!$A$1:$D$2241,3,0)),"CUIT NO CARGADO") -> GASTOS VARIOS | R17: =IFERROR(IF('Jun-26'!$F17="","-",VLOOKUP('Jun-26'!$F17,Lista_CUIT!$A$1:$D$2241,4,0)),"CUIT NO CARGADO") -> 0
B18: 45812 | C18: 1 | D18: 3 | E18: 1588 | F18: 30717805174 | G18: =IFERROR(IF('Jun-26'!$F18="","-",VLOOKUP('Jun-26'!$F18,Lista_CUIT!$A$1:$D$2241,2,0)),"CUIT NO CARGADO") -> LUXONO S. R. L. | H18: 29326.83 | I18: =IF('Jun-26'!$H18="","",'Jun-26'!$H18*0.21) -> 6158.6343 | P18: =SUM('Jun-26'!$H18:$O18) -> 35485.464 | Q18: =IFERROR(IF('Jun-26'!$F18="","-",VLOOKUP('Jun-26'!$F18,Lista_CUIT!$A$1:$D$2241,3,0)),"CUIT NO CARGADO") -> INSUMO | R18: =IFERROR(IF('Jun-26'!$F18="","-",VLOOKUP('Jun-26'!$F18,Lista_CUIT!$A$1:$D$2241,4,0)),"CUIT NO CARGADO") -> 0
B19: 45812 | C19: 1 | D19: 14 | E19: 92231 | F19: 20271822058 | G19: =IFERROR(IF('Jun-26'!$F19="","-",VLOOKUP('Jun-26'!$F19,Lista_CUIT!$A$1:$D$2241,2,0)),"CUIT NO CARGADO") -> CASSINI MARTIN | H19: 5697.2 | I19: =IF('Jun-26'!$H19="","",'Jun-26'!$H19*0.21) -> 1196.412 | P19: =SUM('Jun-26'!$H19:$O19) -> 6893.612 | Q19: =IFERROR(IF('Jun-26'!$F19="","-",VLOOKUP('Jun-26'!$F19,Lista_CUIT!$A$1:$D$2241,3,0)),"CUIT NO CARGADO") -> Seg e Higiene | R19: =IFERROR(IF('Jun-26'!$F19="","-",VLOOKUP('Jun-26'!$F19,Lista_CUIT!$A$1:$D$2241,4,0)),"CUIT NO CARGADO") -> 0
B20: 45813 | C20: 1 | D20: 8 | E20: 181168 | F20: 33606484599 | G20: =IFERROR(IF('Jun-26'!$F20="","-",VLOOKUP('Jun-26'!$F20,Lista_CUIT!$A$1:$D$2241,2,0)),"CUIT NO CARGADO") -> JORVICAL ACEROS S A | H20: 6346990.8 | I20: =IF('Jun-26'!$H20="","",'Jun-26'!$H20*0.21) -> 1332868.1 | P20: =SUM('Jun-26'!$H20:$O20) -> 7679858.9 | Q20: =IFERROR(IF('Jun-26'!$F20="","-",VLOOKUP('Jun-26'!$F20,Lista_CUIT!$A$1:$D$2241,3,0)),"CUIT NO CARGADO") -> INSUMO | R20: =IFERROR(IF('Jun-26'!$F20="","-",VLOOKUP('Jun-26'!$F20,Lista_CUIT!$A$1:$D$2241,4,0)),"CUIT NO CARGADO") -> 0
B21: 45813 | C21: 1 | D21: 1 | E21: 947 | F21: 30715048066 | G21: =IFERROR(IF('Jun-26'!$F21="","-",VLOOKUP('Jun-26'!$F21,Lista_CUIT!$A$1:$D$2241,2,0)),"CUIT NO CARGADO") -> ROLLS Y EMPANADAS SA | H21: 780930 | I21: =IF('Jun-26'!$H21="","",'Jun-26'!$H21*0.21) -> 163995.3 | P21: =SUM('Jun-26'!$H21:$O21) -> 944925.3 | Q21: =IFERROR(IF('Jun-26'!$F21="","-",VLOOKUP('Jun-26'!$F21,Lista_CUIT!$A$1:$D$2241,3,0)),"CUIT NO CARGADO") -> CATERING | R21: =IFERROR(IF('Jun-26'!$F21="","-",VLOOKUP('Jun-26'!$F21,Lista_CUIT!$A$1:$D$2241,4,0)),"CUIT NO CARGADO") -> 0
B22: 45815 | C22: 1 | D22: 6 | E22: 14894 | F22: 20304916401 | G22: =IFERROR(IF('Jun-26'!$F22="","-",VLOOKUP('Jun-26'!$F22,Lista_CUIT!$A$1:$D$2241,2,0)),"CUIT NO CARGADO") -> RODRIGUEZ ADRIAN EZEQUIEL | H22: 3694.21 | I22: =IF('Jun-26'!$H22="","",'Jun-26'!$H22*0.21) -> 775.7841 | P22: =SUM('Jun-26'!$H22:$O22) -> 4469.9941 | Q22: =IFERROR(IF('Jun-26'!$F22="","-",VLOOKUP('Jun-26'!$F22,Lista_CUIT!$A$1:$D$2241,3,0)),"CUIT NO CARGADO") -> INSUMO | R22: =IFERROR(IF('Jun-26'!$F22="","-",VLOOKUP('Jun-26'!$F22,Lista_CUIT!$A$1:$D$2241,4,0)),"CUIT NO CARGADO") -> 0
B23: 45817 | C23: 1 | D23: 2 | E23: 799 | F23: 30718028112 | G23: =IFERROR(IF('Jun-26'!$F23="","-",VLOOKUP('Jun-26'!$F23,Lista_CUIT!$A$1:$D$2241,2,0)),"CUIT NO CARGADO") -> WARDON S. R. L. | H23: 3363.62 | I23: =IF('Jun-26'!$H23="","",'Jun-26'!$H23*0.21) -> 706.3602 | P23: =SUM('Jun-26'!$H23:$O23) -> 4069.9802 | Q23: =IFERROR(IF('Jun-26'!$F23="","-",VLOOKUP('Jun-26'!$F23,Lista_CUIT!$A$1:$D$2241,3,0)),"CUIT NO CARGADO") -> Servicios Informaticos | R23: =IFERROR(IF('Jun-26'!$F23="","-",VLOOKUP('Jun-26'!$F23,Lista_CUIT!$A$1:$D$2241,4,0)),"CUIT NO CARGADO") -> 0
B24: 45817 | C24: 1 | D24: 2 | E24: 214 | F24: 20125142851 | G24: =IFERROR(IF('Jun-26'!$F24="","-",VLOOKUP('Jun-26'!$F24,Lista_CUIT!$A$1:$D$2241,2,0)),"CUIT NO CARGADO") -> FEDERICI NICOLAS JOSE | H24: 96536 | I24: =IF('Jun-26'!$H24="","",'Jun-26'!$H24*0.21) -> 20272.56 | P24: =SUM('Jun-26'!$H24:$O24) -> 116808.56 | Q24: =IFERROR(IF('Jun-26'!$F24="","-",VLOOKUP('Jun-26'!$F24,Lista_CUIT!$A$1:$D$2241,3,0)),"CUIT NO CARGADO") -> INSUMO | R24: =IFERROR(IF('Jun-26'!$F24="","-",VLOOKUP('Jun-26'!$F24,Lista_CUIT!$A$1:$D$2241,4,0)),"CUIT NO CARGADO") -> 0
B25: 45825 | C25: 1 | D25: 106 | E25: 849425 | F25: 30594494187 | G25: =IFERROR(IF('Jun-26'!$F25="","-",VLOOKUP('Jun-26'!$F25,Lista_CUIT!$A$1:$D$2241,2,0)),"CUIT NO CARGADO") -> FEDERAL EXPRESS CORPORATION | H25: 100800 | I25: =IF('Jun-26'!$H25="","",'Jun-26'!$H25*0.21) -> 21168 | O25: 546498.3 | P25: =SUM('Jun-26'!$H25:$O25) -> 668466.3 | Q25: =IFERROR(IF('Jun-26'!$F25="","-",VLOOKUP('Jun-26'!$F25,Lista_CUIT!$A$1:$D$2241,3,0)),"CUIT NO CARGADO") -> Mercaderia | R25: =IFERROR(IF('Jun-26'!$F25="","-",VLOOKUP('Jun-26'!$F25,Lista_CUIT!$A$1:$D$2241,4,0)),"CUIT NO CARGADO") -> 0
B26: 45825 | C26: 1 | D26: 106 | E26: 850560 | F26: 30594494187 | G26: =IFERROR(IF('Jun-26'!$F26="","-",VLOOKUP('Jun-26'!$F26,Lista_CUIT!$A$1:$D$2241,2,0)),"CUIT NO CARGADO") -> FEDERAL EXPRESS CORPORATION | H26: 0 | I26: =IF('Jun-26'!$H26="","",'Jun-26'!$H26*0.21) -> 0 | O26: 492360 | P26: =SUM('Jun-26'!$H26:$O26) -> 492360 | Q26: =IFERROR(IF('Jun-26'!$F26="","-",VLOOKUP('Jun-26'!$F26,Lista_CUIT!$A$1:$D$2241,3,0)),"CUIT NO CARGADO") -> Mercaderia | R26: =IFERROR(IF('Jun-26'!$F26="","-",VLOOKUP('Jun-26'!$F26,Lista_CUIT!$A$1:$D$2241,4,0)),"CUIT NO CARGADO") -> 0
B27: 45826 | C27: 1 | D27: 2 | E27: 215 | F27: 20125142851 | G27: =IFERROR(IF('Jun-26'!$F27="","-",VLOOKUP('Jun-26'!$F27,Lista_CUIT!$A$1:$D$2241,2,0)),"CUIT NO CARGADO") -> FEDERICI NICOLAS JOSE | H27: 2285563.7 | I27: =IF('Jun-26'!$H27="","",'Jun-26'!$H27*0.21) -> 479968.37 | P27: =SUM('Jun-26'!$H27:$O27) -> 2765532 | Q27: =IFERROR(IF('Jun-26'!$F27="","-",VLOOKUP('Jun-26'!$F27,Lista_CUIT!$A$1:$D$2241,3,0)),"CUIT NO CARGADO") -> INSUMO | R27: =IFERROR(IF('Jun-26'!$F27="","-",VLOOKUP('Jun-26'!$F27,Lista_CUIT!$A$1:$D$2241,4,0)),"CUIT NO CARGADO") -> 0
B28: 45827 | C28: 1 | D28: 9 | E28: 13627 | F28: 30709531960 | G28: =IFERROR(IF('Jun-26'!$F28="","-",VLOOKUP('Jun-26'!$F28,Lista_CUIT!$A$1:$D$2241,2,0)),"CUIT NO CARGADO") -> CENTRO DE DISTRIBUCION SUR S R L | H28: 34518.43 | I28: =IF('Jun-26'!$H28="","",'Jun-26'!$H28*0.21) -> 7248.8703 | P28: =SUM('Jun-26'!$H28:$O28) -> 41767.3 | Q28: =IFERROR(IF('Jun-26'!$F28="","-",VLOOKUP('Jun-26'!$F28,Lista_CUIT!$A$1:$D$2241,3,0)),"CUIT NO CARGADO") -> LIMPIEZA | R28: =IFERROR(IF('Jun-26'!$F28="","-",VLOOKUP('Jun-26'!$F28,Lista_CUIT!$A$1:$D$2241,4,0)),"CUIT NO CARGADO") -> 0
B29: 45827 | C29: 1 | D29: 9 | E29: 13628 | F29: 30709531960 | G29: =IFERROR(IF('Jun-26'!$F29="","-",VLOOKUP('Jun-26'!$F29,Lista_CUIT!$A$1:$D$2241,2,0)),"CUIT NO CARGADO") -> CENTRO DE DISTRIBUCION SUR S R L | H29: 27561.59 | I29: =IF('Jun-26'!$H29="","",'Jun-26'!$H29*0.21) -> 5787.9339 | P29: =SUM('Jun-26'!$H29:$O29) -> 33349.524 | Q29: =IFERROR(IF('Jun-26'!$F29="","-",VLOOKUP('Jun-26'!$F29,Lista_CUIT!$A$1:$D$2241,3,0)),"CUIT NO CARGADO") -> LIMPIEZA | R29: =IFERROR(IF('Jun-26'!$F29="","-",VLOOKUP('Jun-26'!$F29,Lista_CUIT!$A$1:$D$2241,4,0)),"CUIT NO CARGADO") -> 0
B30: 45828 | C30: 1 | D30: 7002 | E30: 22393 | F30: 30678774495 | G30: =IFERROR(IF('Jun-26'!$F30="","-",VLOOKUP('Jun-26'!$F30,Lista_CUIT!$A$1:$D$2241,2,0)),"CUIT NO CARGADO") -> OPER. DE EST. DE SERV. SA | H30: 32105.45 | I30: =IF('Jun-26'!$H30="","",'Jun-26'!$H30*0.21) -> 6742.1445 | O30: 8962.43 | P30: =SUM('Jun-26'!$H30:$O30) -> 47810.024 | Q30: =IFERROR(IF('Jun-26'!$F30="","-",VLOOKUP('Jun-26'!$F30,Lista_CUIT!$A$1:$D$2241,3,0)),"CUIT NO CARGADO") -> COMBUSTIBLE | R30: =IFERROR(IF('Jun-26'!$F30="","-",VLOOKUP('Jun-26'!$F30,Lista_CUIT!$A$1:$D$2241,4,0)),"CUIT NO CARGADO") -> 0
B31: 45831 | C31: 1 | D31: 1 | E31: 955 | F31: 30715048066 | G31: =IFERROR(IF('Jun-26'!$F31="","-",VLOOKUP('Jun-26'!$F31,Lista_CUIT!$A$1:$D$2241,2,0)),"CUIT NO CARGADO") -> ROLLS Y EMPANADAS SA | H31: 845210 | I31: =IF('Jun-26'!$H31="","",'Jun-26'!$H31*0.21) -> 177494.1 | P31: =SUM('Jun-26'!$H31:$O31) -> 1022704.1 | Q31: =IFERROR(IF('Jun-26'!$F31="","-",VLOOKUP('Jun-26'!$F31,Lista_CUIT!$A$1:$D$2241,3,0)),"CUIT NO CARGADO") -> CATERING | R31: =IFERROR(IF('Jun-26'!$F31="","-",VLOOKUP('Jun-26'!$F31,Lista_CUIT!$A$1:$D$2241,4,0)),"CUIT NO CARGADO") -> 0
B32: 45831 | C32: 1 | D32: 2 | E32: 216 | F32: 20125142851 | G32: =IFERROR(IF('Jun-26'!$F32="","-",VLOOKUP('Jun-26'!$F32,Lista_CUIT!$A$1:$D$2241,2,0)),"CUIT NO CARGADO") -> FEDERICI NICOLAS JOSE | H32: 245728 | I32: =IF('Jun-26'!$H32="","",'Jun-26'!$H32*0.21) -> 51602.88 | P32: =SUM('Jun-26'!$H32:$O32) -> 297330.88 | Q32: =IFERROR(IF('Jun-26'!$F32="","-",VLOOKUP('Jun-26'!$F32,Lista_CUIT!$A$1:$D$2241,3,0)),"CUIT NO CARGADO") -> INSUMO | R32: =IFERROR(IF('Jun-26'!$F32="","-",VLOOKUP('Jun-26'!$F32,Lista_CUIT!$A$1:$D$2241,4,0)),"CUIT NO CARGADO") -> 0
B33: 45832 | C33: 1 | D33: 2 | E33: 882 | F33: 20296550184 | G33: =IFERROR(IF('Jun-26'!$F33="","-",VLOOKUP('Jun-26'!$F33,Lista_CUIT!$A$1:$D$2241,2,0)),"CUIT NO CARGADO") -> COSTA DIEGO ALEJANDRO | H33: 1007200 | I33: =IF('Jun-26'!$H33="","",'Jun-26'!$H33*0.21) -> 211512 | P33: =SUM('Jun-26'!$H33:$O33) -> 1218712 | Q33: =IFERROR(IF('Jun-26'!$F33="","-",VLOOKUP('Jun-26'!$F33,Lista_CUIT!$A$1:$D$2241,3,0)),"CUIT NO CARGADO") -> Mat. Prima | R33: =IFERROR(IF('Jun-26'!$F33="","-",VLOOKUP('Jun-26'!$F33,Lista_CUIT!$A$1:$D$2241,4,0)),"CUIT NO CARGADO") -> 0
B34: 45833 | C34: 1 | D34: 6 | E34: 33256 | F34: 30708855533 | G34: =IFERROR(IF('Jun-26'!$F34="","-",VLOOKUP('Jun-26'!$F34,Lista_CUIT!$A$1:$D$2241,2,0)),"CUIT NO CARGADO") -> NOVARCHEM SA | H34: 107004 | I34: =IF('Jun-26'!$H34="","",'Jun-26'!$H34*0.21) -> 22470.84 | P34: =SUM('Jun-26'!$H34:$O34) -> 129474.84 | Q34: =IFERROR(IF('Jun-26'!$F34="","-",VLOOKUP('Jun-26'!$F34,Lista_CUIT!$A$1:$D$2241,3,0)),"CUIT NO CARGADO") -> INSUMO | R34: =IFERROR(IF('Jun-26'!$F34="","-",VLOOKUP('Jun-26'!$F34,Lista_CUIT!$A$1:$D$2241,4,0)),"CUIT NO CARGADO") -> 0
B35: 45833 | C35: 1 | D35: 11 | E35: 4271 | F35: 30646811062 | G35: =IFERROR(IF('Jun-26'!$F35="","-",VLOOKUP('Jun-26'!$F35,Lista_CUIT!$A$1:$D$2241,2,0)),"CUIT NO CARGADO") -> POLINORTE S A | H35: 107157.02 | I35: =IF('Jun-26'!$H35="","",'Jun-26'!$H35*0.21) -> 22502.974 | P35: =SUM('Jun-26'!$H35:$O35) -> 129659.99 | Q35: =IFERROR(IF('Jun-26'!$F35="","-",VLOOKUP('Jun-26'!$F35,Lista_CUIT!$A$1:$D$2241,3,0)),"CUIT NO CARGADO") -> INSUMO | R35: =IFERROR(IF('Jun-26'!$F35="","-",VLOOKUP('Jun-26'!$F35,Lista_CUIT!$A$1:$D$2241,4,0)),"CUIT NO CARGADO") -> 0
B36: 45834 | C36: 1 | D36: 11 | E36: 4282 | F36: 30646811062 | G36: =IFERROR(IF('Jun-26'!$F36="","-",VLOOKUP('Jun-26'!$F36,Lista_CUIT!$A$1:$D$2241,2,0)),"CUIT NO CARGADO") -> POLINORTE S A | H36: 107122.31 | I36: =IF('Jun-26'!$H36="","",'Jun-26'!$H36*0.21) -> 22495.685 | P36: =SUM('Jun-26'!$H36:$O36) -> 129618 | Q36: =IFERROR(IF('Jun-26'!$F36="","-",VLOOKUP('Jun-26'!$F36,Lista_CUIT!$A$1:$D$2241,3,0)),"CUIT NO CARGADO") -> INSUMO | R36: =IFERROR(IF('Jun-26'!$F36="","-",VLOOKUP('Jun-26'!$F36,Lista_CUIT!$A$1:$D$2241,4,0)),"CUIT NO CARGADO") -> 0
B37: 45838 | C37: 1 | D37: 106 | E37: 854361 | F37: 30594494187 | G37: =IFERROR(IF('Jun-26'!$F37="","-",VLOOKUP('Jun-26'!$F37,Lista_CUIT!$A$1:$D$2241,2,0)),"CUIT NO CARGADO") -> FEDERAL EXPRESS CORPORATION | H37: 0 | I37: =IF('Jun-26'!$H37="","",'Jun-26'!$H37*0.21) -> 0 | O37: 769778.1 | P37: =SUM('Jun-26'!$H37:$O37) -> 769778.1 | Q37: =IFERROR(IF('Jun-26'!$F37="","-",VLOOKUP('Jun-26'!$F37,Lista_CUIT!$A$1:$D$2241,3,0)),"CUIT NO CARGADO") -> Mercaderia | R37: =IFERROR(IF('Jun-26'!$F37="","-",VLOOKUP('Jun-26'!$F37,Lista_CUIT!$A$1:$D$2241,4,0)),"CUIT NO CARGADO") -> 0
B38: 45812 | C38: 3 | D38: 8 | E38: 6302 | F38: 30709953482 | G38: =IFERROR(IF('Jun-26'!$F38="","-",VLOOKUP('Jun-26'!$F38,Lista_CUIT!$A$1:$D$2241,2,0)),"CUIT NO CARGADO") -> HONRE S.A | H38: -7189.26 | I38: =IF('Jun-26'!$H38="","",'Jun-26'!$H38*0.21) -> -1509.7446 | P38: =SUM('Jun-26'!$H38:$O38) -> -8699.0046 | Q38: =IFERROR(IF('Jun-26'!$F38="","-",VLOOKUP('Jun-26'!$F38,Lista_CUIT!$A$1:$D$2241,3,0)),"CUIT NO CARGADO") -> GASTOS VARIOS | R38: =IFERROR(IF('Jun-26'!$F38="","-",VLOOKUP('Jun-26'!$F38,Lista_CUIT!$A$1:$D$2241,4,0)),"CUIT NO CARGADO") -> 0
B39: 45812 | C39: 3 | D39: 10 | E39: 4501 | F39: 20357275882 | G39: =IFERROR(IF('Jun-26'!$F39="","-",VLOOKUP('Jun-26'!$F39,Lista_CUIT!$A$1:$D$2241,2,0)),"CUIT NO CARGADO") -> LAVADERO BLANCANIEVES | H39: -7429.75 | I39: =IF('Jun-26'!$H39="","",'Jun-26'!$H39*0.21) -> -1560.2475 | P39: =SUM('Jun-26'!$H39:$O39) -> -8989.9975 | Q39: =IFERROR(IF('Jun-26'!$F39="","-",VLOOKUP('Jun-26'!$F39,Lista_CUIT!$A$1:$D$2241,3,0)),"CUIT NO CARGADO") -> Seg e Higiene | R39: =IFERROR(IF('Jun-26'!$F39="","-",VLOOKUP('Jun-26'!$F39,Lista_CUIT!$A$1:$D$2241,4,0)),"CUIT NO CARGADO") -> 0
B40: 45834 | C40: 3 | D40: 11 | E40: 247 | F40: 30646811062 | G40: =IFERROR(IF('Jun-26'!$F40="","-",VLOOKUP('Jun-26'!$F40,Lista_CUIT!$A$1:$D$2241,2,0)),"CUIT NO CARGADO") -> POLINORTE S A | H40: -107157.02 | I40: =IF('Jun-26'!$H40="","",'Jun-26'!$H40*0.21) -> -22502.974 | P40: =SUM('Jun-26'!$H40:$O40) -> -129659.99 | Q40: =IFERROR(IF('Jun-26'!$F40="","-",VLOOKUP('Jun-26'!$F40,Lista_CUIT!$A$1:$D$2241,3,0)),"CUIT NO CARGADO") -> INSUMO | R40: =IFERROR(IF('Jun-26'!$F40="","-",VLOOKUP('Jun-26'!$F40,Lista_CUIT!$A$1:$D$2241,4,0)),"CUIT NO CARGADO") -> 0
G41: =IFERROR(IF('Jun-26'!$F41="","-",VLOOKUP('Jun-26'!$F41,Lista_CUIT!$A$1:$D$2241,2,0)),"CUIT NO CARGADO") -> - | I41: =IF('Jun-26'!$H41="","",'Jun-26'!$H41*0.21) | P41: =SUM('Jun-26'!$H41:$O41) -> 0 | Q41: =IFERROR(IF('Jun-26'!$F41="","-",VLOOKUP('Jun-26'!$F41,Lista_CUIT!$A$1:$D$2241,3,0)),"CUIT NO CARGADO") -> - | R41: =IFERROR(IF('Jun-26'!$F41="","-",VLOOKUP('Jun-26'!$F41,Lista_CUIT!$A$1:$D$2241,4,0)),"CUIT NO CARGADO") -> - | S41: COD 5
G42: =IFERROR(IF('Jun-26'!$F42="","-",VLOOKUP('Jun-26'!$F42,Lista_CUIT!$A$1:$D$2241,2,0)),"CUIT NO CARGADO") -> - | I42: =IF('Jun-26'!$H42="","",'Jun-26'!$H42*0.21) | P42: =SUM('Jun-26'!$H42:$O42) -> 0 | Q42: =IFERROR(IF('Jun-26'!$F42="","-",VLOOKUP('Jun-26'!$F42,Lista_CUIT!$A$1:$D$2241,3,0)),"CUIT NO CARGADO") -> - | R42: =IFERROR(IF('Jun-26'!$F42="","-",VLOOKUP('Jun-26'!$F42,Lista_CUIT!$A$1:$D$2241,4,0)),"CUIT NO CARGADO") -> - | S42: COD 5
G43: =IFERROR(IF('Jun-26'!$F43="","-",VLOOKUP('Jun-26'!$F43,Lista_CUIT!$A$1:$D$2241,2,0)),"CUIT NO CARGADO") -> - | I43: =IF('Jun-26'!$H43="","",'Jun-26'!$H43*0.21) | P43: =SUM('Jun-26'!$H43:$O43) -> 0 | Q43: =IFERROR(IF('Jun-26'!$F43="","-",VLOOKUP('Jun-26'!$F43,Lista_CUIT!$A$1:$D$2241,3,0)),"CUIT NO CARGADO") -> - | R43: =IFERROR(IF('Jun-26'!$F43="","-",VLOOKUP('Jun-26'!$F43,Lista_CUIT!$A$1:$D$2241,4,0)),"CUIT NO CARGADO") -> -
B44: Total | H44: =SUBTOTAL(109,'Jun-26'!$H$9:$H$43) -> 12746809 | I44: =SUBTOTAL(109,'Jun-26'!$I$9:$I$43) -> 2676829.8 | J44: =SUBTOTAL(109,'Jun-26'!$J$9:$J$43) -> 0 | K44: =SUBTOTAL(109,'Jun-26'!$K$9:$K$43) -> 0 | L44: =SUBTOTAL(109,'Jun-26'!$L$9:$L$43) -> 0 | M44: =SUBTOTAL(109,'Jun-26'!$M$9:$M$43) -> 0 | N44: =SUBTOTAL(109,'Jun-26'!$N$9:$N$43) -> 0 | O44: =SUBTOTAL(109,'Jun-26'!$O$9:$O$43) -> 2095131.3 | P44: =SUBTOTAL(109,'Jun-26'!$P$9:$P$43) -> 17518770
...

Sheet Jul-26
B1: LIBRO IVA COMPRAS | G1: ='Abr-26'!G1:M1 -> CORITEC S. R. L. | N1: =EDATE('Abr-26'!N1,3) -> 45839
B3: TOTAL COMPRAS | G3: TOTAL CREDITO FISCAL | J3: TOTAL VENTAS NETAS | M3: TOTAL DEBITO FISCAL | P3: RESULTADO
B4: =SUM('Jul-26'!$H$35)+'Jul-26'!$G$47 -> 15690898 | G4: ='Jul-26'!$I$35+'Jul-26'!$J$35+'Jul-26'!$K$35+'Jul-26'!$H$47+'Jul-26'!$I$47 -> 3289065 | J4: ='Jul-26'!$H$90+'Jul-26'!$H$100 -> 52120400 | M4: ='Jul-26'!$I$90+'Jul-26'!$J$90+'Jul-26'!$I$100+'Jul-26'!$J$100 -> 5472642 | P4: =G4-M4 -> -2183577
B8: FECHA | C8: TIPO | D8: PTO VTA | E8: NRO. CPTE | F8: CUIT | G8: RAZON SOCIAL | H8: NETO GRAVADO | I8: IVA 21 % | J8: IVA 27% | K8: IVA 10,5% | L8: PERC. IVA | M8: PERC IIBB BS AS | N8: PERC. IIBB CABA | O8: Otros / No Grav. | P8: TOTAL | Q8: Tipo de Gasto | R8: Provincia
B9: 45839 | C9: 1 | D9: 3 | E9: 273296 | F9: 30707135596 | G9: =IFERROR(IF('Jul-26'!$F9="","-",VLOOKUP('Jul-26'!$F9,Lista_CUIT!$A$1:$D$2241,2,0)),"CUIT NO CARGADO") -> CITILAN ARGENTINA S.A. | H9: 32638.02 | I9: =IF('Jul-26'!$H9="","",'Jul-26'!$H9*0.21) -> 6853.9842 | P9: =SUM('Jul-26'!$H9:$O9) -> 39492.004 | Q9: =IFERROR(IF('Jul-26'!$F9="","-",VLOOKUP('Jul-26'!$F9,Lista_CUIT!$A$1:$D$2241,3,0)),"CUIT NO CARGADO") -> Telefonia | R9: =IFERROR(IF('Jul-26'!$F9="","-",VLOOKUP('Jul-26'!$F9,Lista_CUIT!$A$1:$D$2241,4,0)),"CUIT NO CARGADO") -> 0
B10: 45839 | C10: 1 | D10: 3 | E10: 184 | F10: 20297899830 | G10: =IFERROR(IF('Jul-26'!$F10="","-",VLOOKUP('Jul-26'!$F10,Lista_CUIT!$A$1:$D$2241,2,0)),"CUIT NO CARGADO") -> FUNK MATIAS NICOLAS | H10: 8621775 | I10: =IF('Jul-26'!$H10="","",'Jul-26'!$H10*0.21) -> 1810572.8 | P10: =SUM('Jul-26'!$H10:$O10) -> 10432348 | Q10: =IFERROR(IF('Jul-26'!$F10="","-",VLOOKUP('Jul-26'!$F10,Lista_CUIT!$A$1:$D$2241,3,0)),"CUIT NO CARGADO") -> INSUMO | R10: =IFERROR(IF('Jul-26'!$F10="","-",VLOOKUP('Jul-26'!$F10,Lista_CUIT!$A$1:$D$2241,4,0)),"CUIT NO CARGADO") -> 0
B11: 45839 | C11: 1 | D11: 3 | E11: 872 | F11: 30715402765 | G11: =IFERROR(IF('Jul-26'!$F11="","-",VLOOKUP('Jul-26'!$F11,Lista_CUIT!$A$1:$D$2241,2,0)),"CUIT NO CARGADO") -> RIO 265 S.R.L. | H11: 95867.76 | I11: =IF('Jul-26'!$H11="","",'Jul-26'!$H11*0.21) -> 20132.23 | P11: =SUM('Jul-26'!$H11:$O11) -> 115999.99 | Q11: =IFERROR(IF('Jul-26'!$F11="","-",VLOOKUP('Jul-26'!$F11,Lista_CUIT!$A$1:$D$2241,3,0)),"CUIT NO CARGADO") -> GASTOS VARIOS | R11: =IFERROR(IF('Jul-26'!$F11="","-",VLOOKUP('Jul-26'!$F11,Lista_CUIT!$A$1:$D$2241,4,0)),"CUIT NO CARGADO") -> 0
B12: 45842 | C12: 1 | D12: 4 | E12: 14068 | F12: 33710719549 | G12: =IFERROR(IF('Jul-26'!$F12="","-",VLOOKUP('Jul-26'!$F12,Lista_CUIT!$A$1:$D$2241,2,0)),"CUIT NO CARGADO") -> FIVELEC S.R.L. | H12: 45828.45 | I12: =IF('Jul-26'!$H12="","",'Jul-26'!$H12*0.21) -> 9623.9745 | P12: =SUM('Jul-26'!$H12:$O12) -> 55452.424 | Q12: =IFERROR(IF('Jul-26'!$F12="","-",VLOOKUP('Jul-26'!$F12,Lista_CUIT!$A$1:$D$2241,3,0)),"CUIT NO CARGADO") -> INSUMO | R12: =IFERROR(IF('Jul-26'!$F12="","-",VLOOKUP('Jul-26'!$F12,Lista_CUIT!$A$1:$D$2241,4,0)),"CUIT NO CARGADO") -> 0
