Workbook

Sheet Lista_CUIT
A1: CUIT | B1: RAZON SOCIAL | C1: Tipo de Gasto | D1: PROVINCIA
A2: 30575019524 | B2: 100000 LAMPARAS SRL | G2: Mercaderia
A3: 30709829730 | B3: 4KRC SA | C3: Mantenimiento | G3: Servicios Gas, Luz, etc.
A4: 30715223704 | B4: 5 CEPAS S.R.L. | C4: MERCADERIA | G4: Gastos catering
A5: 30714869937 | B5: 60 LIBRAS SRL | G5: Combustibe
A6: 30692212130 | B6: A R C CONSTRUCCIONES S.A. | G6: Gastos Varios
A7: 30687722007 | B7: A. RUSSONIELLO SA | C7: SERVICIOS | G7: Gastos seguridad
A8: 30503874497 | B8: A.M. PESCIO S.C.A | C8: Mercaderia | G8: Librería
A9: 30702017498 | B9: ABBS POINT DESING S.A. | G9: Gastos mantenimiento
A10: 20182999661 | B10: ABEL JAVIER KLAINER | C10: Mercaderia | G10: Gastos comercializacion
A11: 30652000076 | B11: ABELSON SA | C11: Mercaderia | G11: Alquiler
A12: 30690536079 | B12: ACCESOR SRL | C12: Gastos Varios | G12: Honorarios contables
A13: 30515585415 | B13: ACEROSALFA SA | C13: Mercaderia | G13: Gastos administrativos
A14: 33711942659 | B14: ACLOS ASOC. CIVIL PARA LA LONG | C14: Mercaderia | G14: Seguro
A15: 30715243349 | B15: ADSE S.A | G15: Extracto
A16: 20174004146 | B16: ADUEARDO FRANCISCO NARDOMARINO | C16: Mercaderia | G16: Flete
A17: 30708555548 | B17: AGH S.A | C17: Mercaderia | G17: Honorarios Legales
A18: 30708263342 | B18: AGRACO S.A | C18: MERCADERIA | G18: Insumo
A19: 30709565075 | B19: AGUA Y SANEAMIENTOS ARG SA | C19: SERVICIOS | G19: Muebles y Utiles
A20: 30500229973 | B20: AKIAN GRAFICA EDITORA SA | C20: Mercaderia | G20: Otros
A21: 30710799241 | B21: ALANAR S.R.L. | G21: Telefonia
A22: 20236101127 | B22: ALEJANDRO DARIO LOPEZ | G22: Alojamiento-Varios
A23: 20291929126 | B23: ALEJANDRO MIGUEL DAUBLER
A24: 30709604887 | B24: ALFABIS SRL. | C24: Mantenimiento
A25: 20083925680 | B25: ALFREDO DANIEL FERNANDEZ | C25: Gastos Varios
A26: 30656038752 | B26: ALFREDO OMAR POTENZA SRL | C26: Mercaderia
A27: 30504563894 | B27: ALI HERMANOS SRL | C27: Mercaderia
A28: 30602699826 | B28: ALKO SRL
A29: 30715190385 | B29: ALL FEDERAL SA.
A30: 23945042079 | B30: ALVARENGA VILLAR LUIS F | C30: Gastos Varios
A31: 20040616498 | B31: ALVAREZ MARCELINO
A32: 30710587147 | B32: AMAKOR SA | C32: SERVICIOS
A33: 30663288497 | B33: AMX ARG SA
A34: 27108310559 | B34: ANA MARIA VALDEZ
A35: 30502375535 | B35: ANAVI S.C.A.
A36: 30709251739 | B36: ANDES LINEAS AEREAS SA
A37: 30709948667 | B37: ANTAGGER SRL | C37: Mercaderia
A38: 30683702060 | B38: ANTARES INDUST. ORTOP SA | C38: Mercaderia
A39: 30715985124 | B39: ANTOLFO S.R.L.
A40: 30714344656 | B40: AQUALAF S.A. | C40: Mercaderia
...

Sheet Hoja1
B3: FACTURAS C
B4: FECHA | C4: PTO VTA | D4: FC Nº | E4: CUIT | F4: RAZON SOCIAL | G4: TOTAL | H4: TIPO DE GASTO | I4: Provincia
F5: =IFERROR(IF(factura_c_mes182[[#This Row],[CUIT]]="","-",VLOOKUP(factura_c_mes182[[#This Row],[CUIT]],Lista_CUIT[#All],2,0)),"CUIT NO CARGADO") -> - | H5: =IFERROR(IF(factura_c_mes182[[#This Row],[CUIT]]="","-",VLOOKUP(factura_c_mes182[[#This Row],[CUIT]],Lista_CUIT[#All],3,0)),"CUIT NO CARGADO") -> - | I5: =IFERROR(IF(factura_c_mes182[[#This Row],[CUIT]]="","-",VLOOKUP(factura_c_mes182[[#This Row],[CUIT]],Lista_CUIT[#All],4,0)),"CUIT NO CARGADO") -> -
B6: 45026 | C6: 4 | D6: 12 | E6: 20341462933 | F6: =IFERROR(IF(factura_c_mes182[[#This Row],[CUIT]]="","-",VLOOKUP(factura_c_mes182[[#This Row],[CUIT]],Lista_CUIT[#All],2,0)),"CUIT NO CARGADO") -> CASTIGLIONI MATIAS EZEQUIEL | G6: 590500 | H6: Ingenieria Aplicada | I6: =IFERROR(IF(factura_c_mes182[[#This Row],[CUIT]]="","-",VLOOKUP(factura_c_mes182[[#This Row],[CUIT]],Lista_CUIT[#All],4,0)),"CUIT NO CARGADO") -> BUENOS AIRES | K6: 510.12 | L6: Honorarios Ingeniero | M6: 590500
B7: 45026 | C7: 8 | D7: 157469 | E7: 30709953482 | F7: =IFERROR(IF(factura_c_mes182[[#This Row],[CUIT]]="","-",VLOOKUP(factura_c_mes182[[#This Row],[CUIT]],Lista_CUIT[#All],2,0)),"CUIT NO CARGADO") -> HONRE S.A | G7: 1221.95 | H7: =IFERROR(IF(factura_c_mes182[[#This Row],[CUIT]]="","-",VLOOKUP(factura_c_mes182[[#This Row],[CUIT]],Lista_CUIT[#All],3,0)),"CUIT NO CARGADO") -> Gastos Varios | I7: =IFERROR(IF(factura_c_mes182[[#This Row],[CUIT]]="","-",VLOOKUP(factura_c_mes182[[#This Row],[CUIT]],Lista_CUIT[#All],4,0)),"CUIT NO CARGADO") -> 0 | K7: 500.05 | L7: Gastos varios | M7: 19561.95
B8: 45028 | C8: 4 | D8: 35528 | E8: 30716998718 | F8: =IFERROR(IF(factura_c_mes182[[#This Row],[CUIT]]="","-",VLOOKUP(factura_c_mes182[[#This Row],[CUIT]],Lista_CUIT[#All],2,0)),"CUIT NO CARGADO") -> FIDO ARGENTINA SRL | G8: 18340 | H8: =IFERROR(IF(factura_c_mes182[[#This Row],[CUIT]]="","-",VLOOKUP(factura_c_mes182[[#This Row],[CUIT]],Lista_CUIT[#All],3,0)),"CUIT NO CARGADO") -> Gastos Varios | I8: =IFERROR(IF(factura_c_mes182[[#This Row],[CUIT]]="","-",VLOOKUP(factura_c_mes182[[#This Row],[CUIT]],Lista_CUIT[#All],4,0)),"CUIT NO CARGADO") -> 0 | K8: 500.016 | L8: Honorarios Admnistrativos | M8: 148480
B9: 45041 | C9: 3 | D9: 50 | E9: 20403931420 | F9: =IFERROR(IF(factura_c_mes182[[#This Row],[CUIT]]="","-",VLOOKUP(factura_c_mes182[[#This Row],[CUIT]],Lista_CUIT[#All],2,0)),"CUIT NO CARGADO") -> FIORENTINO JORGE IGNACIO | G9: 148480 | H9: Honorarios Administrativos | I9: =IFERROR(IF(factura_c_mes182[[#This Row],[CUIT]]="","-",VLOOKUP(factura_c_mes182[[#This Row],[CUIT]],Lista_CUIT[#All],4,0)),"CUIT NO CARGADO") -> 0 | K9: 510.1 | L9: Honorarios Contables | M9: 79860
B10: 45019 | C10: 3 | D10: 717 | E10: 20086277523 | F10: =IFERROR(IF(factura_c_mes182[[#This Row],[CUIT]]="","-",VLOOKUP(factura_c_mes182[[#This Row],[CUIT]],Lista_CUIT[#All],2,0)),"CUIT NO CARGADO") -> ESTUDIO BOTINDARI | G10: 67000 | H10: Honorario Contable | I10: =IFERROR(IF(factura_c_mes182[[#This Row],[CUIT]]="","-",VLOOKUP(factura_c_mes182[[#This Row],[CUIT]],Lista_CUIT[#All],4,0)),"CUIT NO CARGADO") -> 0 | K10: 500.035 | L10: Desarrollo Software | M10: 90000
B11: 45028 | C11: 2 | D11: 200 | E11: 27173820866 | F11: =IFERROR(IF(factura_c_mes182[[#This Row],[CUIT]]="","-",VLOOKUP(factura_c_mes182[[#This Row],[CUIT]],Lista_CUIT[#All],2,0)),"CUIT NO CARGADO") -> FREIER SANDRA DANIELA | G11: 90000 | H11: Desarrollo Software | I11: =IFERROR(IF(factura_c_mes182[[#This Row],[CUIT]]="","-",VLOOKUP(factura_c_mes182[[#This Row],[CUIT]],Lista_CUIT[#All],4,0)),"CUIT NO CARGADO") -> 0 | K11: 500.03 | L11: Mantenimiento Software | M11: 373750
B12: 45029 | C12: 3 | D12: 723 | E12: 20086277523 | F12: =IFERROR(IF(factura_c_mes182[[#This Row],[CUIT]]="","-",VLOOKUP(factura_c_mes182[[#This Row],[CUIT]],Lista_CUIT[#All],2,0)),"CUIT NO CARGADO") -> ESTUDIO BOTINDARI | G12: 12860 | H12: Honorario Contable | I12: =IFERROR(IF(factura_c_mes182[[#This Row],[CUIT]]="","-",VLOOKUP(factura_c_mes182[[#This Row],[CUIT]],Lista_CUIT[#All],4,0)),"CUIT NO CARGADO") -> 0 | K12: 500.027 | L12: Mantenimiento Oficina | M12: 148935
B13: 45021 | C13: 1 | D13: 98 | E13: 20341465134 | F13: =IFERROR(IF(factura_c_mes182[[#This Row],[CUIT]]="","-",VLOOKUP(factura_c_mes182[[#This Row],[CUIT]],Lista_CUIT[#All],2,0)),"CUIT NO CARGADO") -> ABELEDO AGUSTIN ENRIQUE | G13: 373750 | H13: Mantenimiento Sofware | I13: =IFERROR(IF(factura_c_mes182[[#This Row],[CUIT]]="","-",VLOOKUP(factura_c_mes182[[#This Row],[CUIT]],Lista_CUIT[#All],4,0)),"CUIT NO CARGADO") -> CABA | K13: 500.034 | L13: Seguimientos de Clientes | M13: 128690
B14: 45041 | C14: 2 | D14: 21 | E14: 23326777269 | F14: =IFERROR(IF(factura_c_mes182[[#This Row],[CUIT]]="","-",VLOOKUP(factura_c_mes182[[#This Row],[CUIT]],Lista_CUIT[#All],2,0)),"CUIT NO CARGADO") -> DE BONIS IGNACIO LUIS | G14: 148935 | H14: Mantenimiento Oficvina | I14: =IFERROR(IF(factura_c_mes182[[#This Row],[CUIT]]="","-",VLOOKUP(factura_c_mes182[[#This Row],[CUIT]],Lista_CUIT[#All],4,0)),"CUIT NO CARGADO") -> 0 | K14: 500.03 | L14: Mantenimiento Software | M14: 371000
B15: 45043 | C15: 1 | D15: 17 | E15: 20417805878 | F15: =IFERROR(IF(factura_c_mes182[[#This Row],[CUIT]]="","-",VLOOKUP(factura_c_mes182[[#This Row],[CUIT]],Lista_CUIT[#All],2,0)),"CUIT NO CARGADO") -> FERABOLI OSPAL SANTIAGO HERNAN | G15: 128690 | H15: Control de Materiales | I15: =IFERROR(IF(factura_c_mes182[[#This Row],[CUIT]]="","-",VLOOKUP(factura_c_mes182[[#This Row],[CUIT]],Lista_CUIT[#All],4,0)),"CUIT NO CARGADO") -> 0 | M15: =SUM(M6:M14) -> 1950776.9
B16: 45040 | C16: 2 | D16: 82 | E16: 20244271740 | F16: =IFERROR(IF(factura_c_mes182[[#This Row],[CUIT]]="","-",VLOOKUP(factura_c_mes182[[#This Row],[CUIT]],Lista_CUIT[#All],2,0)),"CUIT NO CARGADO") -> KENNEL SEBASTIAN | G16: 371000 | H16: =IFERROR(IF(factura_c_mes182[[#This Row],[CUIT]]="","-",VLOOKUP(factura_c_mes182[[#This Row],[CUIT]],Lista_CUIT[#All],3,0)),"CUIT NO CARGADO") -> Software Mantenimiento | I16: =IFERROR(IF(factura_c_mes182[[#This Row],[CUIT]]="","-",VLOOKUP(factura_c_mes182[[#This Row],[CUIT]],Lista_CUIT[#All],4,0)),"CUIT NO CARGADO") -> 0
B17: Total | G17: =SUBTOTAL(109,factura_c_mes182[TOTAL]) -> 1950776.9
B19: FACTURAS C
B20: FECHA | C20: PTO VTA | D20: FC Nº | E20: CUIT | F20: RAZON SOCIAL | G20: TOTAL | H20: TIPO DE GASTO | I20: Provincia
B21: 45047 | C21: 1 | D21: 7 | E21: 27387896150 | F21: =IFERROR(IF(factura_c_mes283[[#This Row],[CUIT]]="","-",VLOOKUP(factura_c_mes283[[#This Row],[CUIT]],Lista_CUIT[#All],2,0)),"CUIT NO CARGADO") -> LIPANOVICH MARIA SOL | G21: 400000 | H21: Desarrollo Software | I21: =IFERROR(IF(factura_c_mes283[[#This Row],[CUIT]]="","-",VLOOKUP(factura_c_mes283[[#This Row],[CUIT]],Lista_CUIT[#All],4,0)),"CUIT NO CARGADO") -> 0 | K21: 510.12 | L21: Honorarios Ingeniero | M21: 510000
B22: 45077 | C22: 1 | D22: 8 | E22: 27387896150 | F22: =IFERROR(IF(factura_c_mes283[[#This Row],[CUIT]]="","-",VLOOKUP(factura_c_mes283[[#This Row],[CUIT]],Lista_CUIT[#All],2,0)),"CUIT NO CARGADO") -> LIPANOVICH MARIA SOL | G22: 400000 | H22: Desarrollo Software | I22: =IFERROR(IF(factura_c_mes283[[#This Row],[CUIT]]="","-",VLOOKUP(factura_c_mes283[[#This Row],[CUIT]],Lista_CUIT[#All],4,0)),"CUIT NO CARGADO") -> 0 | K22: 500.05 | L22: Gastos varios | M22: 108932.98
B23: 45062 | C23: 2 | D23: 203 | E23: 27173820866 | F23: =IFERROR(IF(factura_c_mes283[[#This Row],[CUIT]]="","-",VLOOKUP(factura_c_mes283[[#This Row],[CUIT]],Lista_CUIT[#All],2,0)),"CUIT NO CARGADO") -> FREIER SANDRA DANIELA | G23: 400000 | H23: Desarrollo Software | I23: =IFERROR(IF(factura_c_mes283[[#This Row],[CUIT]]="","-",VLOOKUP(factura_c_mes283[[#This Row],[CUIT]],Lista_CUIT[#All],4,0)),"CUIT NO CARGADO") -> 0 | K23: 500.016 | L23: Honorarios Admnistrativos | M23: 848510
B24: 45047 | C24: 1 | D24: 23 | E24: 20365938688 | F24: =IFERROR(IF(factura_c_mes283[[#This Row],[CUIT]]="","-",VLOOKUP(factura_c_mes283[[#This Row],[CUIT]],Lista_CUIT[#All],2,0)),"CUIT NO CARGADO") -> LIPANOVICH JUAN CRUZ | G24: 450000 | H24: Desarrollo Software | I24: =IFERROR(IF(factura_c_mes283[[#This Row],[CUIT]]="","-",VLOOKUP(factura_c_mes283[[#This Row],[CUIT]],Lista_CUIT[#All],4,0)),"CUIT NO CARGADO") -> 0 | K24: 510.1 | L24: Honorarios Contables | M24: 93860
B25: 45049 | C25: 2 | D25: 81043 | E25: 30554466806 | F25: =IFERROR(IF(factura_c_mes283[[#This Row],[CUIT]]="","-",VLOOKUP(factura_c_mes283[[#This Row],[CUIT]],Lista_CUIT[#All],2,0)),"CUIT NO CARGADO") -> ASOCIACION DE IMPORTADORES Y EXPORTADORES DE LA REPUBLICA ARGENTINA | G25: 3200 | H25: =IFERROR(IF(factura_c_mes283[[#This Row],[CUIT]]="","-",VLOOKUP(factura_c_mes283[[#This Row],[CUIT]],Lista_CUIT[#All],3,0)),"CUIT NO CARGADO") -> FLETE-LOGISTICA | I25: =IFERROR(IF(factura_c_mes283[[#This Row],[CUIT]]="","-",VLOOKUP(factura_c_mes283[[#This Row],[CUIT]],Lista_CUIT[#All],4,0)),"CUIT NO CARGADO") -> 0 | K25: 500.035 | L25: Desarrollo Software | M25: 850000
B26: 45054 | C26: 11 | D26: 37129 | E26: 30714867322 | F26: =IFERROR(IF(factura_c_mes283[[#This Row],[CUIT]]="","-",VLOOKUP(factura_c_mes283[[#This Row],[CUIT]],Lista_CUIT[#All],2,0)),"CUIT NO CARGADO") -> INITIUM SRL | G26: 3488.98 | H26: Gastos varios | I26: =IFERROR(IF(factura_c_mes283[[#This Row],[CUIT]]="","-",VLOOKUP(factura_c_mes283[[#This Row],[CUIT]],Lista_CUIT[#All],4,0)),"CUIT NO CARGADO") -> 0 | K26: 500.027 | L26: Mantenimiento Oficina | M26: -148935
B27: 45055 | C27: 1 | D27: 36 | E27: 27925308868 | F27: =IFERROR(IF(factura_c_mes283[[#This Row],[CUIT]]="","-",VLOOKUP(factura_c_mes283[[#This Row],[CUIT]],Lista_CUIT[#All],2,0)),"CUIT NO CARGADO") -> LOPEZ MOLINA MARIA | G27: 19200 | H27: Gastos varios | I27: =IFERROR(IF(factura_c_mes283[[#This Row],[CUIT]]="","-",VLOOKUP(factura_c_mes283[[#This Row],[CUIT]],Lista_CUIT[#All],4,0)),"CUIT NO CARGADO") -> 0 | K27: 500.034 | L27: Seguimientos de Clientes | M27: 128970
B28: 45061 | C28: 9 | D28: 3739576 | E28: 33715179119 | F28: =IFERROR(IF(factura_c_mes283[[#This Row],[CUIT]]="","-",VLOOKUP(factura_c_mes283[[#This Row],[CUIT]],Lista_CUIT[#All],2,0)),"CUIT NO CARGADO") -> FONDO DE COOPERACION TECNICA Y FINANCIERA - CECBA - SL Y T - LEY 23.412 | G28: 855 | H28: Gastos varios | I28: =IFERROR(IF(factura_c_mes283[[#This Row],[CUIT]]="","-",VLOOKUP(factura_c_mes283[[#This Row],[CUIT]],Lista_CUIT[#All],4,0)),"CUIT NO CARGADO") -> 0 | K28: 500.03 | L28: Mantenimiento Software | M28: 718570
B29: 45062 | C29: 2 | D29: 103 | E29: 27125997835 | F29: =IFERROR(IF(factura_c_mes283[[#This Row],[CUIT]]="","-",VLOOKUP(factura_c_mes283[[#This Row],[CUIT]],Lista_CUIT[#All],2,0)),"CUIT NO CARGADO") -> DANSKY ULLMANN VIVIANA EVA YOLANDA | G29: 50000 | H29: Gastos varios | I29: =IFERROR(IF(factura_c_mes283[[#This Row],[CUIT]]="","-",VLOOKUP(factura_c_mes283[[#This Row],[CUIT]],Lista_CUIT[#All],4,0)),"CUIT NO CARGADO") -> 0 | K29: 500.035 | L29: Desarrollo Software | M29: 800000
B30: 45057 | C30: 7 | D30: 313886 | E30: 20259150249 | F30: =IFERROR(IF(factura_c_mes283[[#This Row],[CUIT]]="","-",VLOOKUP(factura_c_mes283[[#This Row],[CUIT]],Lista_CUIT[#All],2,0)),"CUIT NO CARGADO") -> BIANCHI CRISTIAN MAXIMILIANO | G30: 18590 | H30: =IFERROR(IF(factura_c_mes283[[#This Row],[CUIT]]="","-",VLOOKUP(factura_c_mes283[[#This Row],[CUIT]],Lista_CUIT[#All],3,0)),"CUIT NO CARGADO") -> Gastos Varios | I30: =IFERROR(IF(factura_c_mes283[[#This Row],[CUIT]]="","-",VLOOKUP(factura_c_mes283[[#This Row],[CUIT]],Lista_CUIT[#All],4,0)),"CUIT NO CARGADO") -> 0 | K30: 507.13 | L30: Fletes-Logisdtica | M30: 3200
B31: 45061 | C31: 7 | D31: 314857 | E31: 20259150249 | F31: =IFERROR(IF(factura_c_mes283[[#This Row],[CUIT]]="","-",VLOOKUP(factura_c_mes283[[#This Row],[CUIT]],Lista_CUIT[#All],2,0)),"CUIT NO CARGADO") -> BIANCHI CRISTIAN MAXIMILIANO | G31: 16799 | H31: =IFERROR(IF(factura_c_mes283[[#This Row],[CUIT]]="","-",VLOOKUP(factura_c_mes283[[#This Row],[CUIT]],Lista_CUIT[#All],3,0)),"CUIT NO CARGADO") -> Gastos Varios | I31: =IFERROR(IF(factura_c_mes283[[#This Row],[CUIT]]="","-",VLOOKUP(factura_c_mes283[[#This Row],[CUIT]],Lista_CUIT[#All],4,0)),"CUIT NO CARGADO") -> 0 | K31: 121.122 | L31: Insumos --Accesorios | M31: 37400
B32: 45054 | C32: 2 | D32: 140 | E32: 20136544625 | F32: =IFERROR(IF(factura_c_mes283[[#This Row],[CUIT]]="","-",VLOOKUP(factura_c_mes283[[#This Row],[CUIT]],Lista_CUIT[#All],2,0)),"CUIT NO CARGADO") -> RODRIGUEZ DE LA FUEN HECTOR MARCELO | G32: 160000 | H32: =IFERROR(IF(factura_c_mes283[[#This Row],[CUIT]]="","-",VLOOKUP(factura_c_mes283[[#This Row],[CUIT]],Lista_CUIT[#All],3,0)),"CUIT NO CARGADO") -> Hon. Admin. | I32: =IFERROR(IF(factura_c_mes283[[#This Row],[CUIT]]="","-",VLOOKUP(factura_c_mes283[[#This Row],[CUIT]],Lista_CUIT[#All],4,0)),"CUIT NO CARGADO") -> 0 | K32: 500.034 | L32: Seguimientos de Clientes | M32: 84196
B33: 45054 | C33: 2 | D33: 141 | E33: 20136544625 | F33: =IFERROR(IF(factura_c_mes283[[#This Row],[CUIT]]="","-",VLOOKUP(factura_c_mes283[[#This Row],[CUIT]],Lista_CUIT[#All],2,0)),"CUIT NO CARGADO") -> RODRIGUEZ DE LA FUEN HECTOR MARCELO | G33: 140000 | H33: =IFERROR(IF(factura_c_mes283[[#This Row],[CUIT]]="","-",VLOOKUP(factura_c_mes283[[#This Row],[CUIT]],Lista_CUIT[#All],3,0)),"CUIT NO CARGADO") -> Hon. Admin. | I33: =IFERROR(IF(factura_c_mes283[[#This Row],[CUIT]]="","-",VLOOKUP(factura_c_mes283[[#This Row],[CUIT]],Lista_CUIT[#All],4,0)),"CUIT NO CARGADO") -> 0
B34: 45061 | C34: 2 | D34: 142 | E34: 20136544625 | F34: =IFERROR(IF(factura_c_mes283[[#This Row],[CUIT]]="","-",VLOOKUP(factura_c_mes283[[#This Row],[CUIT]],Lista_CUIT[#All],2,0)),"CUIT NO CARGADO") -> RODRIGUEZ DE LA FUEN HECTOR MARCELO | G34: 400000 | H34: =IFERROR(IF(factura_c_mes283[[#This Row],[CUIT]]="","-",VLOOKUP(factura_c_mes283[[#This Row],[CUIT]],Lista_CUIT[#All],3,0)),"CUIT NO CARGADO") -> Hon. Admin. | I34: =IFERROR(IF(factura_c_mes283[[#This Row],[CUIT]]="","-",VLOOKUP(factura_c_mes283[[#This Row],[CUIT]],Lista_CUIT[#All],4,0)),"CUIT NO CARGADO") -> 0 | M34: =SUM(M21:M32) -> 4034704
B35: 45069 | C35: 3 | D35: 52 | E35: 20403931420 | F35: =IFERROR(IF(factura_c_mes283[[#This Row],[CUIT]]="","-",VLOOKUP(factura_c_mes283[[#This Row],[CUIT]],Lista_CUIT[#All],2,0)),"CUIT NO CARGADO") -> FIORENTINO JORGE IGNACIO | G35: 148510 | H35: Honorarios Administrativos | I35: =IFERROR(IF(factura_c_mes283[[#This Row],[CUIT]]="","-",VLOOKUP(factura_c_mes283[[#This Row],[CUIT]],Lista_CUIT[#All],4,0)),"CUIT NO CARGADO") -> 0
B36: 45048 | C36: 3 | D36: 732 | E36: 20086277523 | F36: =IFERROR(IF(factura_c_mes283[[#This Row],[CUIT]]="","-",VLOOKUP(factura_c_mes283[[#This Row],[CUIT]],Lista_CUIT[#All],2,0)),"CUIT NO CARGADO") -> ESTUDIO BOTINDARI | G36: 81000 | H36: Honorarios Contables | I36: =IFERROR(IF(factura_c_mes283[[#This Row],[CUIT]]="","-",VLOOKUP(factura_c_mes283[[#This Row],[CUIT]],Lista_CUIT[#All],4,0)),"CUIT NO CARGADO") -> 0
B37: 45061 | C37: 3 | D37: 737 | E37: 20086277523 | F37: =IFERROR(IF(factura_c_mes283[[#This Row],[CUIT]]="","-",VLOOKUP(factura_c_mes283[[#This Row],[CUIT]],Lista_CUIT[#All],2,0)),"CUIT NO CARGADO") -> ESTUDIO BOTINDARI | G37: 12860 | H37: Honorarios Contables | I37: =IFERROR(IF(factura_c_mes283[[#This Row],[CUIT]]="","-",VLOOKUP(factura_c_mes283[[#This Row],[CUIT]],Lista_CUIT[#All],4,0)),"CUIT NO CARGADO") -> 0
B38: 45057 | C38: 4 | D38: 13 | E38: 20341462933 | F38: =IFERROR(IF(factura_c_mes283[[#This Row],[CUIT]]="","-",VLOOKUP(factura_c_mes283[[#This Row],[CUIT]],Lista_CUIT[#All],2,0)),"CUIT NO CARGADO") -> CASTIGLIONI MATIAS EZEQUIEL | G38: 510000 | H38: Ingenieria Aplicada | I38: =IFERROR(IF(factura_c_mes283[[#This Row],[CUIT]]="","-",VLOOKUP(factura_c_mes283[[#This Row],[CUIT]],Lista_CUIT[#All],4,0)),"CUIT NO CARGADO") -> BUENOS AIRES
B39: 45049 | C39: 1 | D39: 12 | E39: 20338344695 | F39: =IFERROR(IF(factura_c_mes283[[#This Row],[CUIT]]="","-",VLOOKUP(factura_c_mes283[[#This Row],[CUIT]],Lista_CUIT[#All],2,0)),"CUIT NO CARGADO") -> FUERTES DAMIAN MATIAS | G39: 37400 | H39: =IFERROR(IF(factura_c_mes283[[#This Row],[CUIT]]="","-",VLOOKUP(factura_c_mes283[[#This Row],[CUIT]],Lista_CUIT[#All],3,0)),"CUIT NO CARGADO") -> INSUMO | I39: =IFERROR(IF(factura_c_mes283[[#This Row],[CUIT]]="","-",VLOOKUP(factura_c_mes283[[#This Row],[CUIT]],Lista_CUIT[#All],4,0)),"CUIT NO CARGADO") -> 0
B40: 45049 | C40: 350 | D40: 186905 | E40: 30525558246 | F40: =IFERROR(IF(factura_c_mes283[[#This Row],[CUIT]]="","-",VLOOKUP(factura_c_mes283[[#This Row],[CUIT]],Lista_CUIT[#All],2,0)),"CUIT NO CARGADO") -> ANTONIO LUQUIN S A C I F E I | G40: 21399 | H40: Estaciones Mantenimiento | I40: =IFERROR(IF(factura_c_mes283[[#This Row],[CUIT]]="","-",VLOOKUP(factura_c_mes283[[#This Row],[CUIT]],Lista_CUIT[#All],4,0)),"CUIT NO CARGADO") -> 0
B41: 45049 | C41: 350 | D41: 186906 | E41: 30525558246 | F41: =IFERROR(IF(factura_c_mes283[[#This Row],[CUIT]]="","-",VLOOKUP(factura_c_mes283[[#This Row],[CUIT]],Lista_CUIT[#All],2,0)),"CUIT NO CARGADO") -> ANTONIO LUQUIN S A C I F E I | G41: 21399 | H41: Estaciones Mantenimiento | I41: =IFERROR(IF(factura_c_mes283[[#This Row],[CUIT]]="","-",VLOOKUP(factura_c_mes283[[#This Row],[CUIT]],Lista_CUIT[#All],4,0)),"CUIT NO CARGADO") -> 0
B42: 45049 | C42: 345 | D42: 332222 | E42: 30525558246 | F42: =IFERROR(IF(factura_c_mes283[[#This Row],[CUIT]]="","-",VLOOKUP(factura_c_mes283[[#This Row],[CUIT]],Lista_CUIT[#All],2,0)),"CUIT NO CARGADO") -> ANTONIO LUQUIN S A C I F E I | G42: 20699 | H42: Estaciones Mantenimiento | I42: =IFERROR(IF(factura_c_mes283[[#This Row],[CUIT]]="","-",VLOOKUP(factura_c_mes283[[#This Row],[CUIT]],Lista_CUIT[#All],4,0)),"CUIT NO CARGADO") -> 0
B43: 45049 | C43: 345 | D43: 332224 | E43: 30525558246 | F43: =IFERROR(IF(factura_c_mes283[[#This Row],[CUIT]]="","-",VLOOKUP(factura_c_mes283[[#This Row],[CUIT]],Lista_CUIT[#All],2,0)),"CUIT NO CARGADO") -> ANTONIO LUQUIN S A C I F E I | G43: 20699 | H43: Estaciones Mantenimiento | I43: =IFERROR(IF(factura_c_mes283[[#This Row],[CUIT]]="","-",VLOOKUP(factura_c_mes283[[#This Row],[CUIT]],Lista_CUIT[#All],4,0)),"CUIT NO CARGADO") -> 0
...

Sheet Abr-23
B1: LIBRO IVA COMPRAS | G1: CORITEC S. R. L. | N1: 45017
B3: TOTAL COMPRAS NETAS | G3: TOTAL CREDITO FISCAL | J3: TOTAL VENTAS NETAS | M3: TOTAL DEBITO FISCAL | P3: RESULTADO
B4: =SUM(compras_mes1[[#Totals],[NETO GRAVADO]])+extracto_banco_mes1[[#Totals],[NETO]] -> 4605652.9 | G4: =compras_mes1[[#Totals],[IVA 21 %]]+compras_mes1[[#Totals],[IVA 27%]]+compras_mes1[[#Totals],[IVA 10,5%]]+I76 -> 951044.47 | J4: =venta_a_mes1[[#Totals],[IMPORTE NETO]]+ventas_b_mes1[[#Totals],[IMPORTE NETO]] -> 9011565.4 | M4: =venta_a_mes1[[#Totals],[IVA 21%]]+venta_a_mes1[[#Totals],[IVA 10,5%]]+ventas_b_mes1[[#Totals],[IVA 21%]]+ventas_b_mes1[[#Totals],[IVA 10,5%]]+ventas_b_mes13[[#Totals],[IVA 21%]]+ventas_b_mes13[[#Totals],[Columna1]] -> 1894738.7 | P4: =G4-M4 -> -943694.27
B8: FECHA | C8: TIPO | D8: PTO VTA | E8: NRO. CPTE | F8: CUIT | G8: RAZON SOCIAL | H8: NETO GRAVADO | I8: IVA 21 % | J8: IVA 27% | K8: IVA 10,5% | L8: PERC. IVA | M8: PERC IIBB BS AS | N8: PERC. IIBB CABA | O8: Otros / No Grav. | P8: TOTAL | Q8: Tipo de Gasto | R8: Provincia
G9: =IFERROR(IF(compras_mes1[[#This Row],[CUIT]]="","-",VLOOKUP(compras_mes1[[#This Row],[CUIT]],Lista_CUIT[#All],2,0)),"CUIT NO CARGADO") -> - | I9: =compras_mes1[[#This Row],[NETO GRAVADO]]*0.21 -> 0 | P9: =SUM(compras_mes1[[#This Row],[NETO GRAVADO]:[Otros / No Grav.]]) -> 0 | Q9: =IFERROR(IF(compras_mes1[[#This Row],[CUIT]]="","-",VLOOKUP(compras_mes1[[#This Row],[CUIT]],Lista_CUIT[#All],3,0)),"CUIT NO CARGADO") -> - | R9: =IFERROR(IF(compras_mes1[[#This Row],[CUIT]]="","-",VLOOKUP(compras_mes1[[#This Row],[CUIT]],Lista_CUIT[#All],4,0)),"CUIT NO CARGADO") -> -
G10: =IFERROR(IF(compras_mes1[[#This Row],[CUIT]]="","-",VLOOKUP(compras_mes1[[#This Row],[CUIT]],Lista_CUIT[#All],2,0)),"CUIT NO CARGADO") -> - | I10: =compras_mes1[[#This Row],[NETO GRAVADO]]*0.21 -> 0 | P10: =SUM(compras_mes1[[#This Row],[NETO GRAVADO]:[Otros / No Grav.]]) -> 0 | Q10: =IFERROR(IF(compras_mes1[[#This Row],[CUIT]]="","-",VLOOKUP(compras_mes1[[#This Row],[CUIT]],Lista_CUIT[#All],3,0)),"CUIT NO CARGADO") -> - | R10: =IFERROR(IF(compras_mes1[[#This Row],[CUIT]]="","-",VLOOKUP(compras_mes1[[#This Row],[CUIT]],Lista_CUIT[#All],4,0)),"CUIT NO CARGADO") -> -
B11: 45044 | C11: 1 | D11: 1 | E11: 593 | F11: 30715048066 | G11: =IFERROR(IF(compras_mes1[[#This Row],[CUIT]]="","-",VLOOKUP(compras_mes1[[#This Row],[CUIT]],Lista_CUIT[#All],2,0)),"CUIT NO CARGADO") -> ROLLS Y EMPANADAS SA | H11: 105615 | I11: =compras_mes1[[#This Row],[NETO GRAVADO]]*0.21 -> 22179.15 | P11: =SUM(compras_mes1[[#This Row],[NETO GRAVADO]:[Otros / No Grav.]]) -> 127794.15 | Q11: =IFERROR(IF(compras_mes1[[#This Row],[CUIT]]="","-",VLOOKUP(compras_mes1[[#This Row],[CUIT]],Lista_CUIT[#All],3,0)),"CUIT NO CARGADO") -> CATERING | R11: =IFERROR(IF(compras_mes1[[#This Row],[CUIT]]="","-",VLOOKUP(compras_mes1[[#This Row],[CUIT]],Lista_CUIT[#All],4,0)),"CUIT NO CARGADO") -> 0
B12: 45017 | C12: 1 | D12: 11 | E12: 10726 | F12: 30708622423 | G12: =IFERROR(IF(compras_mes1[[#This Row],[CUIT]]="","-",VLOOKUP(compras_mes1[[#This Row],[CUIT]],Lista_CUIT[#All],2,0)),"CUIT NO CARGADO") -> TERGEN SRL | H12: 7921.33 | I12: =compras_mes1[[#This Row],[NETO GRAVADO]]*0.21 -> 1663.4793 | O12: 1816.21 | P12: =SUM(compras_mes1[[#This Row],[NETO GRAVADO]:[Otros / No Grav.]]) -> 11401.019 | Q12: =IFERROR(IF(compras_mes1[[#This Row],[CUIT]]="","-",VLOOKUP(compras_mes1[[#This Row],[CUIT]],Lista_CUIT[#All],3,0)),"CUIT NO CARGADO") -> COMBUSTIBLE | R12: =IFERROR(IF(compras_mes1[[#This Row],[CUIT]]="","-",VLOOKUP(compras_mes1[[#This Row],[CUIT]],Lista_CUIT[#All],4,0)),"CUIT NO CARGADO") -> 0
B13: 45032 | C13: 1 | D13: 12 | E13: 7602 | F13: 30708622423 | G13: =IFERROR(IF(compras_mes1[[#This Row],[CUIT]]="","-",VLOOKUP(compras_mes1[[#This Row],[CUIT]],Lista_CUIT[#All],2,0)),"CUIT NO CARGADO") -> TERGEN SRL | H13: 7954.67 | I13: =compras_mes1[[#This Row],[NETO GRAVADO]]*0.21 -> 1670.4807 | O13: 1675.53 | P13: =SUM(compras_mes1[[#This Row],[NETO GRAVADO]:[Otros / No Grav.]]) -> 11300.681 | Q13: =IFERROR(IF(compras_mes1[[#This Row],[CUIT]]="","-",VLOOKUP(compras_mes1[[#This Row],[CUIT]],Lista_CUIT[#All],3,0)),"CUIT NO CARGADO") -> COMBUSTIBLE | R13: =IFERROR(IF(compras_mes1[[#This Row],[CUIT]]="","-",VLOOKUP(compras_mes1[[#This Row],[CUIT]],Lista_CUIT[#All],4,0)),"CUIT NO CARGADO") -> 0
B14: 45019 | C14: 1 | D14: 2 | E14: 261 | F14: 20284880049 | G14: =IFERROR(IF(compras_mes1[[#This Row],[CUIT]]="","-",VLOOKUP(compras_mes1[[#This Row],[CUIT]],Lista_CUIT[#All],2,0)),"CUIT NO CARGADO") -> MOROLDO EMILIANO DANIEL | H14: 2361.4 | I14: 77.79 | K14: 209.05 | P14: =SUM(compras_mes1[[#This Row],[NETO GRAVADO]:[Otros / No Grav.]]) -> 2648.24 | Q14: =IFERROR(IF(compras_mes1[[#This Row],[CUIT]]="","-",VLOOKUP(compras_mes1[[#This Row],[CUIT]],Lista_CUIT[#All],3,0)),"CUIT NO CARGADO") -> Electronica | R14: =IFERROR(IF(compras_mes1[[#This Row],[CUIT]]="","-",VLOOKUP(compras_mes1[[#This Row],[CUIT]],Lista_CUIT[#All],4,0)),"CUIT NO CARGADO") -> 0
B15: 45020 | C15: 1 | D15: 50 | E15: 27861 | F15: 30710730845 | G15: =IFERROR(IF(compras_mes1[[#This Row],[CUIT]]="","-",VLOOKUP(compras_mes1[[#This Row],[CUIT]],Lista_CUIT[#All],2,0)),"CUIT NO CARGADO") -> D LED SOCIEDAD DE HECHO DE DIEGO NICOLAS BARSKY Y DAMIAN DANEL SPIVAK | H15: 3059.55 | I15: =compras_mes1[[#This Row],[NETO GRAVADO]]*0.21 -> 642.5055 | P15: =SUM(compras_mes1[[#This Row],[NETO GRAVADO]:[Otros / No Grav.]]) -> 3702.0555 | Q15: =IFERROR(IF(compras_mes1[[#This Row],[CUIT]]="","-",VLOOKUP(compras_mes1[[#This Row],[CUIT]],Lista_CUIT[#All],3,0)),"CUIT NO CARGADO") -> Electronica | R15: =IFERROR(IF(compras_mes1[[#This Row],[CUIT]]="","-",VLOOKUP(compras_mes1[[#This Row],[CUIT]],Lista_CUIT[#All],4,0)),"CUIT NO CARGADO") -> 0
B16: 45021 | C16: 1 | D16: 7 | E16: 3972 | F16: 30709788635 | G16: =IFERROR(IF(compras_mes1[[#This Row],[CUIT]]="","-",VLOOKUP(compras_mes1[[#This Row],[CUIT]],Lista_CUIT[#All],2,0)),"CUIT NO CARGADO") -> EMELINT S.R.L. | H16: 7230.05 | K16: 759.16 | P16: =SUM(compras_mes1[[#This Row],[NETO GRAVADO]:[Otros / No Grav.]]) -> 7989.21 | Q16: =IFERROR(IF(compras_mes1[[#This Row],[CUIT]]="","-",VLOOKUP(compras_mes1[[#This Row],[CUIT]],Lista_CUIT[#All],3,0)),"CUIT NO CARGADO") -> Electronica | R16: =IFERROR(IF(compras_mes1[[#This Row],[CUIT]]="","-",VLOOKUP(compras_mes1[[#This Row],[CUIT]],Lista_CUIT[#All],4,0)),"CUIT NO CARGADO") -> 0
B17: 45046 | C17: 1 | D17: 1 | E17: 308 | F17: 30715060759 | G17: =IFERROR(IF(compras_mes1[[#This Row],[CUIT]]="","-",VLOOKUP(compras_mes1[[#This Row],[CUIT]],Lista_CUIT[#All],2,0)),"CUIT NO CARGADO") -> BIRD COMERCIALIZACION IMPORTACION Y SERVICIOS S.R.L. | H17: 5650.43 | I17: =compras_mes1[[#This Row],[NETO GRAVADO]]*0.21 -> 1186.5903 | P17: =SUM(compras_mes1[[#This Row],[NETO GRAVADO]:[Otros / No Grav.]]) -> 6837.0203 | Q17: =IFERROR(IF(compras_mes1[[#This Row],[CUIT]]="","-",VLOOKUP(compras_mes1[[#This Row],[CUIT]],Lista_CUIT[#All],3,0)),"CUIT NO CARGADO") -> Electronica | R17: =IFERROR(IF(compras_mes1[[#This Row],[CUIT]]="","-",VLOOKUP(compras_mes1[[#This Row],[CUIT]],Lista_CUIT[#All],4,0)),"CUIT NO CARGADO") -> 0
B18: 45017 | C18: 1 | D18: 3 | E18: 635 | F18: 30715402765 | G18: =IFERROR(IF(compras_mes1[[#This Row],[CUIT]]="","-",VLOOKUP(compras_mes1[[#This Row],[CUIT]],Lista_CUIT[#All],2,0)),"CUIT NO CARGADO") -> RIO 265 S.R.L. | H18: 12809.9 | I18: =compras_mes1[[#This Row],[NETO GRAVADO]]*0.21 -> 2690.079 | P18: =SUM(compras_mes1[[#This Row],[NETO GRAVADO]:[Otros / No Grav.]]) -> 15499.979 | Q18: =IFERROR(IF(compras_mes1[[#This Row],[CUIT]]="","-",VLOOKUP(compras_mes1[[#This Row],[CUIT]],Lista_CUIT[#All],3,0)),"CUIT NO CARGADO") -> Gastos Varios | R18: =IFERROR(IF(compras_mes1[[#This Row],[CUIT]]="","-",VLOOKUP(compras_mes1[[#This Row],[CUIT]],Lista_CUIT[#All],4,0)),"CUIT NO CARGADO") -> 0
B19: 45019 | C19: 1 | D19: 5 | E19: 1990 | F19: 20309151489 | G19: =IFERROR(IF(compras_mes1[[#This Row],[CUIT]]="","-",VLOOKUP(compras_mes1[[#This Row],[CUIT]],Lista_CUIT[#All],2,0)),"CUIT NO CARGADO") -> GOMEZ FERNANDO ALBERTO | H19: 1206.61 | I19: =compras_mes1[[#This Row],[NETO GRAVADO]]*0.21 -> 253.3881 | P19: =SUM(compras_mes1[[#This Row],[NETO GRAVADO]:[Otros / No Grav.]]) -> 1459.9981 | Q19: =IFERROR(IF(compras_mes1[[#This Row],[CUIT]]="","-",VLOOKUP(compras_mes1[[#This Row],[CUIT]],Lista_CUIT[#All],3,0)),"CUIT NO CARGADO") -> Gastos Varios | R19: =IFERROR(IF(compras_mes1[[#This Row],[CUIT]]="","-",VLOOKUP(compras_mes1[[#This Row],[CUIT]],Lista_CUIT[#All],4,0)),"CUIT NO CARGADO") -> 0
B20: 45019 | C20: 1 | D20: 1 | E20: 2045 | F20: 20299039367 | G20: =IFERROR(IF(compras_mes1[[#This Row],[CUIT]]="","-",VLOOKUP(compras_mes1[[#This Row],[CUIT]],Lista_CUIT[#All],2,0)),"CUIT NO CARGADO") -> SIRTAUTAS ALBERTO IVAN | H20: 11860.53 | I20: 2263.02 | K20: 113.85 | P20: =SUM(compras_mes1[[#This Row],[NETO GRAVADO]:[Otros / No Grav.]]) -> 14237.4 | Q20: =IFERROR(IF(compras_mes1[[#This Row],[CUIT]]="","-",VLOOKUP(compras_mes1[[#This Row],[CUIT]],Lista_CUIT[#All],3,0)),"CUIT NO CARGADO") -> Gastos Varios | R20: =IFERROR(IF(compras_mes1[[#This Row],[CUIT]]="","-",VLOOKUP(compras_mes1[[#This Row],[CUIT]],Lista_CUIT[#All],4,0)),"CUIT NO CARGADO") -> 0
B21: 45020 | C21: 1 | D21: 5 | E21: 4539 | F21: 27217954369 | G21: =IFERROR(IF(compras_mes1[[#This Row],[CUIT]]="","-",VLOOKUP(compras_mes1[[#This Row],[CUIT]],Lista_CUIT[#All],2,0)),"CUIT NO CARGADO") -> FIGUEIRAS KARINA BEATRIZ | H21: 1287.6 | I21: =compras_mes1[[#This Row],[NETO GRAVADO]]*0.21 -> 270.396 | P21: =SUM(compras_mes1[[#This Row],[NETO GRAVADO]:[Otros / No Grav.]]) -> 1557.996 | Q21: =IFERROR(IF(compras_mes1[[#This Row],[CUIT]]="","-",VLOOKUP(compras_mes1[[#This Row],[CUIT]],Lista_CUIT[#All],3,0)),"CUIT NO CARGADO") -> Gastos Varios | R21: =IFERROR(IF(compras_mes1[[#This Row],[CUIT]]="","-",VLOOKUP(compras_mes1[[#This Row],[CUIT]],Lista_CUIT[#All],4,0)),"CUIT NO CARGADO") -> 0
B22: 45020 | C22: 1 | D22: 3 | E22: 22637 | F22: 30709511846 | G22: =IFERROR(IF(compras_mes1[[#This Row],[CUIT]]="","-",VLOOKUP(compras_mes1[[#This Row],[CUIT]],Lista_CUIT[#All],2,0)),"CUIT NO CARGADO") -> KURIABE S. A. | H22: 8196.39 | K22: 860.62 | P22: =SUM(compras_mes1[[#This Row],[NETO GRAVADO]:[Otros / No Grav.]]) -> 9057.01 | Q22: =IFERROR(IF(compras_mes1[[#This Row],[CUIT]]="","-",VLOOKUP(compras_mes1[[#This Row],[CUIT]],Lista_CUIT[#All],3,0)),"CUIT NO CARGADO") -> Gastos Varios | R22: =IFERROR(IF(compras_mes1[[#This Row],[CUIT]]="","-",VLOOKUP(compras_mes1[[#This Row],[CUIT]],Lista_CUIT[#All],4,0)),"CUIT NO CARGADO") -> 0
B23: 45020 | C23: 1 | D23: 3 | E23: 2360 | F23: 20319700081 | G23: =IFERROR(IF(compras_mes1[[#This Row],[CUIT]]="","-",VLOOKUP(compras_mes1[[#This Row],[CUIT]],Lista_CUIT[#All],2,0)),"CUIT NO CARGADO") -> REA PABLO | H23: 10037.19 | K23: 1053.91 | P23: =SUM(compras_mes1[[#This Row],[NETO GRAVADO]:[Otros / No Grav.]]) -> 11091.1 | Q23: =IFERROR(IF(compras_mes1[[#This Row],[CUIT]]="","-",VLOOKUP(compras_mes1[[#This Row],[CUIT]],Lista_CUIT[#All],3,0)),"CUIT NO CARGADO") -> Gastos Varios | R23: =IFERROR(IF(compras_mes1[[#This Row],[CUIT]]="","-",VLOOKUP(compras_mes1[[#This Row],[CUIT]],Lista_CUIT[#All],4,0)),"CUIT NO CARGADO") -> 0
B24: 45023 | C24: 1 | D24: 7 | E24: 1727 | F24: 20278028810 | G24: =IFERROR(IF(compras_mes1[[#This Row],[CUIT]]="","-",VLOOKUP(compras_mes1[[#This Row],[CUIT]],Lista_CUIT[#All],2,0)),"CUIT NO CARGADO") -> PONCE JUAN MANUEL | H24: 1454.55 | I24: =compras_mes1[[#This Row],[NETO GRAVADO]]*0.21 -> 305.4555 | P24: =SUM(compras_mes1[[#This Row],[NETO GRAVADO]:[Otros / No Grav.]]) -> 1760.0055 | Q24: =IFERROR(IF(compras_mes1[[#This Row],[CUIT]]="","-",VLOOKUP(compras_mes1[[#This Row],[CUIT]],Lista_CUIT[#All],3,0)),"CUIT NO CARGADO") -> Gastos Varios | R24: =IFERROR(IF(compras_mes1[[#This Row],[CUIT]]="","-",VLOOKUP(compras_mes1[[#This Row],[CUIT]],Lista_CUIT[#All],4,0)),"CUIT NO CARGADO") -> 0
B25: 45028 | C25: 1 | D25: 5 | E25: 312 | F25: 20247551337 | G25: =IFERROR(IF(compras_mes1[[#This Row],[CUIT]]="","-",VLOOKUP(compras_mes1[[#This Row],[CUIT]],Lista_CUIT[#All],2,0)),"CUIT NO CARGADO") -> HERRERO ANZORENA MATIAS | H25: 705.65 | I25: =compras_mes1[[#This Row],[NETO GRAVADO]]*0.21 -> 148.1865 | P25: =SUM(compras_mes1[[#This Row],[NETO GRAVADO]:[Otros / No Grav.]]) -> 853.8365 | Q25: =IFERROR(IF(compras_mes1[[#This Row],[CUIT]]="","-",VLOOKUP(compras_mes1[[#This Row],[CUIT]],Lista_CUIT[#All],3,0)),"CUIT NO CARGADO") -> Gastos Varios | R25: =IFERROR(IF(compras_mes1[[#This Row],[CUIT]]="","-",VLOOKUP(compras_mes1[[#This Row],[CUIT]],Lista_CUIT[#All],4,0)),"CUIT NO CARGADO") -> 0
B26: 45029 | C26: 1 | D26: 9 | E26: 73503 | F26: 33715571639 | G26: =IFERROR(IF(compras_mes1[[#This Row],[CUIT]]="","-",VLOOKUP(compras_mes1[[#This Row],[CUIT]],Lista_CUIT[#All],2,0)),"CUIT NO CARGADO") -> DUAITEK SRL | H26: 4463.62 | I26: 94.13 | K26: 421.61 | P26: =SUM(compras_mes1[[#This Row],[NETO GRAVADO]:[Otros / No Grav.]]) -> 4979.36 | Q26: =IFERROR(IF(compras_mes1[[#This Row],[CUIT]]="","-",VLOOKUP(compras_mes1[[#This Row],[CUIT]],Lista_CUIT[#All],3,0)),"CUIT NO CARGADO") -> Gastos Varios | R26: =IFERROR(IF(compras_mes1[[#This Row],[CUIT]]="","-",VLOOKUP(compras_mes1[[#This Row],[CUIT]],Lista_CUIT[#All],4,0)),"CUIT NO CARGADO") -> 0
B27: 45038 | C27: 1 | D27: 3 | E27: 1394130 | F27: 30712019359 | G27: =IFERROR(IF(compras_mes1[[#This Row],[CUIT]]="","-",VLOOKUP(compras_mes1[[#This Row],[CUIT]],Lista_CUIT[#All],2,0)),"CUIT NO CARGADO") -> LINKEDSTORE ARGENTINA S.R.L. | H27: 6032.23 | I27: =compras_mes1[[#This Row],[NETO GRAVADO]]*0.21 -> 1266.7683 | P27: =SUM(compras_mes1[[#This Row],[NETO GRAVADO]:[Otros / No Grav.]]) -> 7298.9983 | Q27: =IFERROR(IF(compras_mes1[[#This Row],[CUIT]]="","-",VLOOKUP(compras_mes1[[#This Row],[CUIT]],Lista_CUIT[#All],3,0)),"CUIT NO CARGADO") -> Gastos Varios | R27: =IFERROR(IF(compras_mes1[[#This Row],[CUIT]]="","-",VLOOKUP(compras_mes1[[#This Row],[CUIT]],Lista_CUIT[#All],4,0)),"CUIT NO CARGADO") -> 0
B28: 45019 | C28: 1 | D28: 106 | E28: 620759 | F28: 30594494187 | G28: =IFERROR(IF(compras_mes1[[#This Row],[CUIT]]="","-",VLOOKUP(compras_mes1[[#This Row],[CUIT]],Lista_CUIT[#All],2,0)),"CUIT NO CARGADO") -> FEDERAL EXPRESS CORPORATION | H28: 12441 | I28: =compras_mes1[[#This Row],[NETO GRAVADO]]*0.21 -> 2612.61 | O28: 4648.57 | P28: =SUM(compras_mes1[[#This Row],[NETO GRAVADO]:[Otros / No Grav.]]) -> 19702.18 | Q28: =IFERROR(IF(compras_mes1[[#This Row],[CUIT]]="","-",VLOOKUP(compras_mes1[[#This Row],[CUIT]],Lista_CUIT[#All],3,0)),"CUIT NO CARGADO") -> Gtos. Imp. | R28: =IFERROR(IF(compras_mes1[[#This Row],[CUIT]]="","-",VLOOKUP(compras_mes1[[#This Row],[CUIT]],Lista_CUIT[#All],4,0)),"CUIT NO CARGADO") -> 0
B29: 45025 | C29: 1 | D29: 280 | E29: 1424766 | F29: 30580111315 | G29: =IFERROR(IF(compras_mes1[[#This Row],[CUIT]]="","-",VLOOKUP(compras_mes1[[#This Row],[CUIT]],Lista_CUIT[#All],2,0)),"CUIT NO CARGADO") -> DHL EXPRESS (ARGENTINA) S.A. | H29: 228954.03 | I29: =compras_mes1[[#This Row],[NETO GRAVADO]]*0.21 -> 48080.347 | O29: -187073.32 | P29: =SUM(compras_mes1[[#This Row],[NETO GRAVADO]:[Otros / No Grav.]]) -> 89961.058 | Q29: =IFERROR(IF(compras_mes1[[#This Row],[CUIT]]="","-",VLOOKUP(compras_mes1[[#This Row],[CUIT]],Lista_CUIT[#All],3,0)),"CUIT NO CARGADO") -> Gtos. Imp. | R29: =IFERROR(IF(compras_mes1[[#This Row],[CUIT]]="","-",VLOOKUP(compras_mes1[[#This Row],[CUIT]],Lista_CUIT[#All],4,0)),"CUIT NO CARGADO") -> 0
B30: 45026 | C30: 1 | D30: 700 | E30: 508046 | F30: 30580111315 | G30: =IFERROR(IF(compras_mes1[[#This Row],[CUIT]]="","-",VLOOKUP(compras_mes1[[#This Row],[CUIT]],Lista_CUIT[#All],2,0)),"CUIT NO CARGADO") -> DHL EXPRESS (ARGENTINA) S.A. | H30: 0 | I30: =compras_mes1[[#This Row],[NETO GRAVADO]]*0.21 -> 0 | O30: 41814.345 | P30: =SUM(compras_mes1[[#This Row],[NETO GRAVADO]:[Otros / No Grav.]]) -> 41814.345 | Q30: =IFERROR(IF(compras_mes1[[#This Row],[CUIT]]="","-",VLOOKUP(compras_mes1[[#This Row],[CUIT]],Lista_CUIT[#All],3,0)),"CUIT NO CARGADO") -> Gtos. Imp. | R30: =IFERROR(IF(compras_mes1[[#This Row],[CUIT]]="","-",VLOOKUP(compras_mes1[[#This Row],[CUIT]],Lista_CUIT[#All],4,0)),"CUIT NO CARGADO") -> 0
B31: 45033 | C31: 1 | D31: 700 | E31: 510209 | F31: 30580111315 | G31: =IFERROR(IF(compras_mes1[[#This Row],[CUIT]]="","-",VLOOKUP(compras_mes1[[#This Row],[CUIT]],Lista_CUIT[#All],2,0)),"CUIT NO CARGADO") -> DHL EXPRESS (ARGENTINA) S.A. | H31: 3094 | I31: =compras_mes1[[#This Row],[NETO GRAVADO]]*0.21 -> 649.74 | O31: 92435.46 | P31: =SUM(compras_mes1[[#This Row],[NETO GRAVADO]:[Otros / No Grav.]]) -> 96179.2 | Q31: =IFERROR(IF(compras_mes1[[#This Row],[CUIT]]="","-",VLOOKUP(compras_mes1[[#This Row],[CUIT]],Lista_CUIT[#All],3,0)),"CUIT NO CARGADO") -> Gtos. Imp. | R31: =IFERROR(IF(compras_mes1[[#This Row],[CUIT]]="","-",VLOOKUP(compras_mes1[[#This Row],[CUIT]],Lista_CUIT[#All],4,0)),"CUIT NO CARGADO") -> 0
B32: 45033 | C32: 1 | D32: 280 | E32: 1425945 | F32: 30580111315 | G32: =IFERROR(IF(compras_mes1[[#This Row],[CUIT]]="","-",VLOOKUP(compras_mes1[[#This Row],[CUIT]],Lista_CUIT[#All],2,0)),"CUIT NO CARGADO") -> DHL EXPRESS (ARGENTINA) S.A. | H32: 229044.93 | I32: =compras_mes1[[#This Row],[NETO GRAVADO]]*0.21 -> 48099.436 | O32: -187050.96 | P32: =SUM(compras_mes1[[#This Row],[NETO GRAVADO]:[Otros / No Grav.]]) -> 90093.409 | Q32: =IFERROR(IF(compras_mes1[[#This Row],[CUIT]]="","-",VLOOKUP(compras_mes1[[#This Row],[CUIT]],Lista_CUIT[#All],3,0)),"CUIT NO CARGADO") -> Gtos. Imp. | R32: =IFERROR(IF(compras_mes1[[#This Row],[CUIT]]="","-",VLOOKUP(compras_mes1[[#This Row],[CUIT]],Lista_CUIT[#All],4,0)),"CUIT NO CARGADO") -> 0
B33: 45037 | C33: 1 | D33: 106 | E33: 625357 | F33: 30594494187 | G33: =IFERROR(IF(compras_mes1[[#This Row],[CUIT]]="","-",VLOOKUP(compras_mes1[[#This Row],[CUIT]],Lista_CUIT[#All],2,0)),"CUIT NO CARGADO") -> FEDERAL EXPRESS CORPORATION | H33: 16092 | I33: =compras_mes1[[#This Row],[NETO GRAVADO]]*0.21 -> 3379.32 | O33: 81504.98 | P33: =SUM(compras_mes1[[#This Row],[NETO GRAVADO]:[Otros / No Grav.]]) -> 100976.3 | Q33: =IFERROR(IF(compras_mes1[[#This Row],[CUIT]]="","-",VLOOKUP(compras_mes1[[#This Row],[CUIT]],Lista_CUIT[#All],3,0)),"CUIT NO CARGADO") -> Gtos. Imp. | R33: =IFERROR(IF(compras_mes1[[#This Row],[CUIT]]="","-",VLOOKUP(compras_mes1[[#This Row],[CUIT]],Lista_CUIT[#All],4,0)),"CUIT NO CARGADO") -> 0
B34: 45040 | C34: 1 | D34: 700 | E34: 512833 | F34: 30580111315 | G34: =IFERROR(IF(compras_mes1[[#This Row],[CUIT]]="","-",VLOOKUP(compras_mes1[[#This Row],[CUIT]],Lista_CUIT[#All],2,0)),"CUIT NO CARGADO") -> DHL EXPRESS (ARGENTINA) S.A. | H34: 3150 | I34: =compras_mes1[[#This Row],[NETO GRAVADO]]*0.21 -> 661.5 | O34: 155160 | P34: =SUM(compras_mes1[[#This Row],[NETO GRAVADO]:[Otros / No Grav.]]) -> 158971.5 | Q34: =IFERROR(IF(compras_mes1[[#This Row],[CUIT]]="","-",VLOOKUP(compras_mes1[[#This Row],[CUIT]],Lista_CUIT[#All],3,0)),"CUIT NO CARGADO") -> Gtos. Imp. | R34: =IFERROR(IF(compras_mes1[[#This Row],[CUIT]]="","-",VLOOKUP(compras_mes1[[#This Row],[CUIT]],Lista_CUIT[#All],4,0)),"CUIT NO CARGADO") -> 0
B35: 45040 | C35: 1 | D35: 280 | E35: 1427245 | F35: 30580111315 | G35: =IFERROR(IF(compras_mes1[[#This Row],[CUIT]]="","-",VLOOKUP(compras_mes1[[#This Row],[CUIT]],Lista_CUIT[#All],2,0)),"CUIT NO CARGADO") -> DHL EXPRESS (ARGENTINA) S.A. | H35: 241504.06 | I35: =compras_mes1[[#This Row],[NETO GRAVADO]]*0.21 -> 50715.852 | O35: -197435.3 | P35: =SUM(compras_mes1[[#This Row],[NETO GRAVADO]:[Otros / No Grav.]]) -> 94784.609 | Q35: =IFERROR(IF(compras_mes1[[#This Row],[CUIT]]="","-",VLOOKUP(compras_mes1[[#This Row],[CUIT]],Lista_CUIT[#All],3,0)),"CUIT NO CARGADO") -> Gtos. Imp. | R35: =IFERROR(IF(compras_mes1[[#This Row],[CUIT]]="","-",VLOOKUP(compras_mes1[[#This Row],[CUIT]],Lista_CUIT[#All],4,0)),"CUIT NO CARGADO") -> 0
B36: 45046 | C36: 1 | D36: 700 | E36: 516705 | F36: 30580111315 | G36: =IFERROR(IF(compras_mes1[[#This Row],[CUIT]]="","-",VLOOKUP(compras_mes1[[#This Row],[CUIT]],Lista_CUIT[#All],2,0)),"CUIT NO CARGADO") -> DHL EXPRESS (ARGENTINA) S.A. | H36: 3206 | I36: =compras_mes1[[#This Row],[NETO GRAVADO]]*0.21 -> 673.26 | O36: 128574.34 | P36: =SUM(compras_mes1[[#This Row],[NETO GRAVADO]:[Otros / No Grav.]]) -> 132453.6 | Q36: =IFERROR(IF(compras_mes1[[#This Row],[CUIT]]="","-",VLOOKUP(compras_mes1[[#This Row],[CUIT]],Lista_CUIT[#All],3,0)),"CUIT NO CARGADO") -> Gtos. Imp. | R36: =IFERROR(IF(compras_mes1[[#This Row],[CUIT]]="","-",VLOOKUP(compras_mes1[[#This Row],[CUIT]],Lista_CUIT[#All],4,0)),"CUIT NO CARGADO") -> 0
B37: 45022 | C37: 1 | D37: 6 | E37: 16511 | F37: 30714971782 | G37: =IFERROR(IF(compras_mes1[[#This Row],[CUIT]]="","-",VLOOKUP(compras_mes1[[#This Row],[CUIT]],Lista_CUIT[#All],2,0)),"CUIT NO CARGADO") -> PINTOS SCHMIDT ALDANA MARCELA Y SACK ADRIANA CRISTINA SH | H37: 1119.82 | I37: =compras_mes1[[#This Row],[NETO GRAVADO]]*0.21 -> 235.1622 | P37: =SUM(compras_mes1[[#This Row],[NETO GRAVADO]:[Otros / No Grav.]]) -> 1354.9822 | Q37: =IFERROR(IF(compras_mes1[[#This Row],[CUIT]]="","-",VLOOKUP(compras_mes1[[#This Row],[CUIT]],Lista_CUIT[#All],3,0)),"CUIT NO CARGADO") -> INSUMO | R37: =IFERROR(IF(compras_mes1[[#This Row],[CUIT]]="","-",VLOOKUP(compras_mes1[[#This Row],[CUIT]],Lista_CUIT[#All],4,0)),"CUIT NO CARGADO") -> 0
B38: 45027 | C38: 1 | D38: 2 | E38: 2385 | F38: 30709131733 | G38: =IFERROR(IF(compras_mes1[[#This Row],[CUIT]]="","-",VLOOKUP(compras_mes1[[#This Row],[CUIT]],Lista_CUIT[#All],2,0)),"CUIT NO CARGADO") -> DIGAS SRL | H38: 585234 | I38: =compras_mes1[[#This Row],[NETO GRAVADO]]*0.21 -> 122899.14 | P38: =SUM(compras_mes1[[#This Row],[NETO GRAVADO]:[Otros / No Grav.]]) -> 708133.14 | Q38: =IFERROR(IF(compras_mes1[[#This Row],[CUIT]]="","-",VLOOKUP(compras_mes1[[#This Row],[CUIT]],Lista_CUIT[#All],3,0)),"CUIT NO CARGADO") -> INSUMO | R38: =IFERROR(IF(compras_mes1[[#This Row],[CUIT]]="","-",VLOOKUP(compras_mes1[[#This Row],[CUIT]],Lista_CUIT[#All],4,0)),"CUIT NO CARGADO") -> 0
B39: 45027 | C39: 1 | D39: 9 | E39: 1554 | F39: 30631047145 | G39: =IFERROR(IF(compras_mes1[[#This Row],[CUIT]]="","-",VLOOKUP(compras_mes1[[#This Row],[CUIT]],Lista_CUIT[#All],2,0)),"CUIT NO CARGADO") -> SEMICONDUC. Y COMPON. SRL | H39: 164230 | I39: 9632.7 | K39: 12427.8 | P39: =SUM(compras_mes1[[#This Row],[NETO GRAVADO]:[Otros / No Grav.]]) -> 186290.5 | Q39: =IFERROR(IF(compras_mes1[[#This Row],[CUIT]]="","-",VLOOKUP(compras_mes1[[#This Row],[CUIT]],Lista_CUIT[#All],3,0)),"CUIT NO CARGADO") -> INSUMO | R39: =IFERROR(IF(compras_mes1[[#This Row],[CUIT]]="","-",VLOOKUP(compras_mes1[[#This Row],[CUIT]],Lista_CUIT[#All],4,0)),"CUIT NO CARGADO") -> 0
B40: 45028 | C40: 1 | D40: 2 | E40: 165 | F40: 20125142851 | G40: =IFERROR(IF(compras_mes1[[#This Row],[CUIT]]="","-",VLOOKUP(compras_mes1[[#This Row],[CUIT]],Lista_CUIT[#All],2,0)),"CUIT NO CARGADO") -> FEDERICI NICOLAS JOSE | H40: 10150.81 | I40: =compras_mes1[[#This Row],[NETO GRAVADO]]*0.21 -> 2131.6701 | P40: =SUM(compras_mes1[[#This Row],[NETO GRAVADO]:[Otros / No Grav.]]) -> 12282.48 | Q40: =IFERROR(IF(compras_mes1[[#This Row],[CUIT]]="","-",VLOOKUP(compras_mes1[[#This Row],[CUIT]],Lista_CUIT[#All],3,0)),"CUIT NO CARGADO") -> INSUMO | R40: =IFERROR(IF(compras_mes1[[#This Row],[CUIT]]="","-",VLOOKUP(compras_mes1[[#This Row],[CUIT]],Lista_CUIT[#All],4,0)),"CUIT NO CARGADO") -> 0
B41: 45028 | C41: 1 | D41: 2 | E41: 555 | F41: 30717334384 | G41: =IFERROR(IF(compras_mes1[[#This Row],[CUIT]]="","-",VLOOKUP(compras_mes1[[#This Row],[CUIT]],Lista_CUIT[#All],2,0)),"CUIT NO CARGADO") -> OLIVEAR S. R. L. | H41: 11320.66 | I41: =compras_mes1[[#This Row],[NETO GRAVADO]]*0.21 -> 2377.3386 | P41: =SUM(compras_mes1[[#This Row],[NETO GRAVADO]:[Otros / No Grav.]]) -> 13697.999 | Q41: =IFERROR(IF(compras_mes1[[#This Row],[CUIT]]="","-",VLOOKUP(compras_mes1[[#This Row],[CUIT]],Lista_CUIT[#All],3,0)),"CUIT NO CARGADO") -> INSUMO | R41: =IFERROR(IF(compras_mes1[[#This Row],[CUIT]]="","-",VLOOKUP(compras_mes1[[#This Row],[CUIT]],Lista_CUIT[#All],4,0)),"CUIT NO CARGADO") -> 0
B42: 45035 | C42: 1 | D42: 2 | E42: 166 | F42: 20125142851 | G42: =IFERROR(IF(compras_mes1[[#This Row],[CUIT]]="","-",VLOOKUP(compras_mes1[[#This Row],[CUIT]],Lista_CUIT[#All],2,0)),"CUIT NO CARGADO") -> FEDERICI NICOLAS JOSE | H42: 42633.38 | I42: =compras_mes1[[#This Row],[NETO GRAVADO]]*0.21 -> 8953.0098 | P42: =SUM(compras_mes1[[#This Row],[NETO GRAVADO]:[Otros / No Grav.]]) -> 51586.39 | Q42: =IFERROR(IF(compras_mes1[[#This Row],[CUIT]]="","-",VLOOKUP(compras_mes1[[#This Row],[CUIT]],Lista_CUIT[#All],3,0)),"CUIT NO CARGADO") -> INSUMO | R42: =IFERROR(IF(compras_mes1[[#This Row],[CUIT]]="","-",VLOOKUP(compras_mes1[[#This Row],[CUIT]],Lista_CUIT[#All],4,0)),"CUIT NO CARGADO") -> 0
B43: 45037 | C43: 1 | D43: 3 | E43: 7060 | F43: 30710212127 | G43: =IFERROR(IF(compras_mes1[[#This Row],[CUIT]]="","-",VLOOKUP(compras_mes1[[#This Row],[CUIT]],Lista_CUIT[#All],2,0)),"CUIT NO CARGADO") -> J Y M COMPONENTES ELECTRICOS S.A. | H43: 1810569.9 | I43: =compras_mes1[[#This Row],[NETO GRAVADO]]*0.21 -> 380219.67 | P43: =SUM(compras_mes1[[#This Row],[NETO GRAVADO]:[Otros / No Grav.]]) -> 2190789.5 | Q43: =IFERROR(IF(compras_mes1[[#This Row],[CUIT]]="","-",VLOOKUP(compras_mes1[[#This Row],[CUIT]],Lista_CUIT[#All],3,0)),"CUIT NO CARGADO") -> INSUMO | R43: =IFERROR(IF(compras_mes1[[#This Row],[CUIT]]="","-",VLOOKUP(compras_mes1[[#This Row],[CUIT]],Lista_CUIT[#All],4,0)),"CUIT NO CARGADO") -> 0
B44: 45041 | C44: 1 | D44: 2 | E44: 167 | F44: 20125142851 | G44: =IFERROR(IF(compras_mes1[[#This Row],[CUIT]]="","-",VLOOKUP(compras_mes1[[#This Row],[CUIT]],Lista_CUIT[#All],2,0)),"CUIT NO CARGADO") -> FEDERICI NICOLAS JOSE | H44: 66779.86 | I44: =compras_mes1[[#This Row],[NETO GRAVADO]]*0.21 -> 14023.771 | P44: =SUM(compras_mes1[[#This Row],[NETO GRAVADO]:[Otros / No Grav.]]) -> 80803.631 | Q44: =IFERROR(IF(compras_mes1[[#This Row],[CUIT]]="","-",VLOOKUP(compras_mes1[[#This Row],[CUIT]],Lista_CUIT[#All],3,0)),"CUIT NO CARGADO") -> INSUMO | R44: =IFERROR(IF(compras_mes1[[#This Row],[CUIT]]="","-",VLOOKUP(compras_mes1[[#This Row],[CUIT]],Lista_CUIT[#All],4,0)),"CUIT NO CARGADO") -> 0
...

Sheet May-23
B1: LIBRO IVA COMPRAS | G1: ='Abr-23'!G1:M1 -> CORITEC S. R. L. | N1: =EDATE('Abr-23'!N1,1) -> 45047
B3: TOTAL COMPRAS | G3: TOTAL CREDITO FISCAL | J3: TOTAL VENTAS NETAS | M3: TOTAL DEBITO FISCAL | P3: RESULTADO
B4: =SUM(compras_mes2[[#Totals],[NETO GRAVADO]])+extracto_banco_mes2[[#Totals],[NETO]] -> 5344969.9 | G4: =compras_mes2[[#Totals],[IVA 21 %]]+compras_mes2[[#Totals],[IVA 27%]]+compras_mes2[[#Totals],[IVA 10,5%]]+extracto_banco_mes2[[#Totals],[IVA 21%]]+extracto_banco_mes2[[#Totals],[IVA 10,5%]] -> 1119920 | J4: =venta_a_mes2[[#Totals],[IMPORTE NETO]]+ventas_b_mes2[[#Totals],[IMPORTE NETO]]+ventas_b_mes252[[#Totals],[IMPORTE NETO]] -> 13286930 | M4: =venta_a_mes2[[#Totals],[IVA 21%]]+venta_a_mes2[[#Totals],[IVA 10,5%]]+ventas_b_mes2[[#Totals],[IVA 21%]]+ventas_b_mes2[[#Totals],[IVA 10,5%]]+ventas_b_mes252[[#Totals],[IVA 21%]] -> 1647290.8 | P4: =G4-M4 -> -527370.89
B8: FECHA | C8: TIPO | D8: PTO VTA | E8: NRO. CPTE | F8: CUIT | G8: RAZON SOCIAL | H8: NETO GRAVADO | I8: IVA 21 % | J8: IVA 27% | K8: IVA 10,5% | L8: PERC. IVA | M8: PERC IIBB BS AS | N8: PERC. IIBB CABA | O8: Otros / No Grav. | P8: TOTAL | Q8: Tipo de Gasto | R8: Provincia
B9: 45063 | C9: 1 | D9: 2 | E9: 8665 | F9: 30707835563 | G9: =IFERROR(IF(compras_mes2[[#This Row],[CUIT]]="","-",VLOOKUP(compras_mes2[[#This Row],[CUIT]],Lista_CUIT[#All],2,0)),"CUIT NO CARGADO") -> SUTEL SRL | H9: 35796.69 | I9: =IF(compras_mes2[[#This Row],[NETO GRAVADO]]="","",compras_mes2[[#This Row],[NETO GRAVADO]]*0.21) -> 7517.3049 | P9: =SUM(compras_mes2[[#This Row],[NETO GRAVADO]:[Otros / No Grav.]]) -> 43313.995 | Q9: =IFERROR(IF(compras_mes2[[#This Row],[CUIT]]="","-",VLOOKUP(compras_mes2[[#This Row],[CUIT]],Lista_CUIT[#All],3,0)),"CUIT NO CARGADO") -> 0 | R9: =IFERROR(IF(compras_mes2[[#This Row],[CUIT]]="","-",VLOOKUP(compras_mes2[[#This Row],[CUIT]],Lista_CUIT[#All],4,0)),"CUIT NO CARGADO") -> 0
B10: 45064 | C10: 1 | D10: 2 | E10: 3885 | F10: 27271779289 | G10: =IFERROR(IF(compras_mes2[[#This Row],[CUIT]]="","-",VLOOKUP(compras_mes2[[#This Row],[CUIT]],Lista_CUIT[#All],2,0)),"CUIT NO CARGADO") -> BRACCO ROSANA | H10: 9600 | I10: =IF(compras_mes2[[#This Row],[NETO GRAVADO]]="","",compras_mes2[[#This Row],[NETO GRAVADO]]*0.21) -> 2016 | O10: 8832.23 | P10: =SUM(compras_mes2[[#This Row],[NETO GRAVADO]:[Otros / No Grav.]]) -> 20448.23 | Q10: =IFERROR(IF(compras_mes2[[#This Row],[CUIT]]="","-",VLOOKUP(compras_mes2[[#This Row],[CUIT]],Lista_CUIT[#All],3,0)),"CUIT NO CARGADO") -> 0 | R10: =IFERROR(IF(compras_mes2[[#This Row],[CUIT]]="","-",VLOOKUP(compras_mes2[[#This Row],[CUIT]],Lista_CUIT[#All],4,0)),"CUIT NO CARGADO") -> 0
B11: 45064 | C11: 1 | D11: 2 | E11: 11550 | F11: 30717014754 | G11: =IFERROR(IF(compras_mes2[[#This Row],[CUIT]]="","-",VLOOKUP(compras_mes2[[#This Row],[CUIT]],Lista_CUIT[#All],2,0)),"CUIT NO CARGADO") -> LITORAL TRADING SAS | H11: 4633.59 | I11: =IF(compras_mes2[[#This Row],[NETO GRAVADO]]="","",compras_mes2[[#This Row],[NETO GRAVADO]]*0.21) -> 973.0539 | P11: =SUM(compras_mes2[[#This Row],[NETO GRAVADO]:[Otros / No Grav.]]) -> 5606.6439 | Q11: =IFERROR(IF(compras_mes2[[#This Row],[CUIT]]="","-",VLOOKUP(compras_mes2[[#This Row],[CUIT]],Lista_CUIT[#All],3,0)),"CUIT NO CARGADO") -> 0 | R11: =IFERROR(IF(compras_mes2[[#This Row],[CUIT]]="","-",VLOOKUP(compras_mes2[[#This Row],[CUIT]],Lista_CUIT[#All],4,0)),"CUIT NO CARGADO") -> 0
B12: 45072 | C12: 1 | D12: 2 | E12: 8037 | F12: 30711726019 | G12: =IFERROR(IF(compras_mes2[[#This Row],[CUIT]]="","-",VLOOKUP(compras_mes2[[#This Row],[CUIT]],Lista_CUIT[#All],2,0)),"CUIT NO CARGADO") -> MAV GROUP S.A. | H12: 100050 | I12: =IF(compras_mes2[[#This Row],[NETO GRAVADO]]="","",compras_mes2[[#This Row],[NETO GRAVADO]]*0.21) -> 21010.5 | O12: 138310.26 | P12: =SUM(compras_mes2[[#This Row],[NETO GRAVADO]:[Otros / No Grav.]]) -> 259370.76 | Q12: =IFERROR(IF(compras_mes2[[#This Row],[CUIT]]="","-",VLOOKUP(compras_mes2[[#This Row],[CUIT]],Lista_CUIT[#All],3,0)),"CUIT NO CARGADO") -> 0 | R12: =IFERROR(IF(compras_mes2[[#This Row],[CUIT]]="","-",VLOOKUP(compras_mes2[[#This Row],[CUIT]],Lista_CUIT[#All],4,0)),"CUIT NO CARGADO") -> 0
B13: 45072 | C13: 1 | D13: 11 | E13: 670 | F13: 30711782997 | G13: =IFERROR(IF(compras_mes2[[#This Row],[CUIT]]="","-",VLOOKUP(compras_mes2[[#This Row],[CUIT]],Lista_CUIT[#All],2,0)),"CUIT NO CARGADO") -> GIOVO JUAN SEBASTIAN Y GIOVO JORGE DIEGO SOC. DE HECHO | H13: 14875.21 | I13: =IF(compras_mes2[[#This Row],[NETO GRAVADO]]="","",compras_mes2[[#This Row],[NETO GRAVADO]]*0.21) -> 3123.7941 | P13: =SUM(compras_mes2[[#This Row],[NETO GRAVADO]:[Otros / No Grav.]]) -> 17999.004 | Q13: =IFERROR(IF(compras_mes2[[#This Row],[CUIT]]="","-",VLOOKUP(compras_mes2[[#This Row],[CUIT]],Lista_CUIT[#All],3,0)),"CUIT NO CARGADO") -> 0 | R13: =IFERROR(IF(compras_mes2[[#This Row],[CUIT]]="","-",VLOOKUP(compras_mes2[[#This Row],[CUIT]],Lista_CUIT[#All],4,0)),"CUIT NO CARGADO") -> 0
B14: 45073 | C14: 1 | D14: 3 | E14: 199 | F14: 30716036711 | G14: =IFERROR(IF(compras_mes2[[#This Row],[CUIT]]="","-",VLOOKUP(compras_mes2[[#This Row],[CUIT]],Lista_CUIT[#All],2,0)),"CUIT NO CARGADO") -> POTENZA SHOP S.A.S. | H14: 10735.54 | I14: =IF(compras_mes2[[#This Row],[NETO GRAVADO]]="","",compras_mes2[[#This Row],[NETO GRAVADO]]*0.21) -> 2254.4634 | P14: =SUM(compras_mes2[[#This Row],[NETO GRAVADO]:[Otros / No Grav.]]) -> 12990.003 | Q14: =IFERROR(IF(compras_mes2[[#This Row],[CUIT]]="","-",VLOOKUP(compras_mes2[[#This Row],[CUIT]],Lista_CUIT[#All],3,0)),"CUIT NO CARGADO") -> 0 | R14: =IFERROR(IF(compras_mes2[[#This Row],[CUIT]]="","-",VLOOKUP(compras_mes2[[#This Row],[CUIT]],Lista_CUIT[#All],4,0)),"CUIT NO CARGADO") -> 0
B15: 45073 | C15: 1 | D15: 5 | E15: 977 | F15: 23287538839 | G15: =IFERROR(IF(compras_mes2[[#This Row],[CUIT]]="","-",VLOOKUP(compras_mes2[[#This Row],[CUIT]],Lista_CUIT[#All],2,0)),"CUIT NO CARGADO") -> MEIJOMIN PABLO MARTIN | H15: 7914.05 | I15: =IF(compras_mes2[[#This Row],[NETO GRAVADO]]="","",compras_mes2[[#This Row],[NETO GRAVADO]]*0.21) -> 1661.9505 | P15: =SUM(compras_mes2[[#This Row],[NETO GRAVADO]:[Otros / No Grav.]]) -> 9576.0005 | Q15: =IFERROR(IF(compras_mes2[[#This Row],[CUIT]]="","-",VLOOKUP(compras_mes2[[#This Row],[CUIT]],Lista_CUIT[#All],3,0)),"CUIT NO CARGADO") -> 0 | R15: =IFERROR(IF(compras_mes2[[#This Row],[CUIT]]="","-",VLOOKUP(compras_mes2[[#This Row],[CUIT]],Lista_CUIT[#All],4,0)),"CUIT NO CARGADO") -> 0
B16: 45074 | C16: 1 | D16: 7 | E16: 1503 | F16: 30716401525 | G16: =IFERROR(IF(compras_mes2[[#This Row],[CUIT]]="","-",VLOOKUP(compras_mes2[[#This Row],[CUIT]],Lista_CUIT[#All],2,0)),"CUIT NO CARGADO") -> SPOT VISION S.A.S. | H16: 40380.17 | I16: =IF(compras_mes2[[#This Row],[NETO GRAVADO]]="","",compras_mes2[[#This Row],[NETO GRAVADO]]*0.21) -> 8479.8357 | P16: =SUM(compras_mes2[[#This Row],[NETO GRAVADO]:[Otros / No Grav.]]) -> 48860.006 | Q16: =IFERROR(IF(compras_mes2[[#This Row],[CUIT]]="","-",VLOOKUP(compras_mes2[[#This Row],[CUIT]],Lista_CUIT[#All],3,0)),"CUIT NO CARGADO") -> 0 | R16: =IFERROR(IF(compras_mes2[[#This Row],[CUIT]]="","-",VLOOKUP(compras_mes2[[#This Row],[CUIT]],Lista_CUIT[#All],4,0)),"CUIT NO CARGADO") -> 0
B17: 45075 | C17: 1 | D17: 4 | E17: 496 | F17: 30716809893 | G17: =IFERROR(IF(compras_mes2[[#This Row],[CUIT]]="","-",VLOOKUP(compras_mes2[[#This Row],[CUIT]],Lista_CUIT[#All],2,0)),"CUIT NO CARGADO") -> BROCATTO SRL | H17: 6444.63 | I17: =IF(compras_mes2[[#This Row],[NETO GRAVADO]]="","",compras_mes2[[#This Row],[NETO GRAVADO]]*0.21) -> 1353.3723 | P17: =SUM(compras_mes2[[#This Row],[NETO GRAVADO]:[Otros / No Grav.]]) -> 7798.0023 | Q17: =IFERROR(IF(compras_mes2[[#This Row],[CUIT]]="","-",VLOOKUP(compras_mes2[[#This Row],[CUIT]],Lista_CUIT[#All],3,0)),"CUIT NO CARGADO") -> 0 | R17: =IFERROR(IF(compras_mes2[[#This Row],[CUIT]]="","-",VLOOKUP(compras_mes2[[#This Row],[CUIT]],Lista_CUIT[#All],4,0)),"CUIT NO CARGADO") -> 0
B18: 45077 | C18: 1 | D18: 1 | E18: 635 | F18: 30717405680 | G18: =IFERROR(IF(compras_mes2[[#This Row],[CUIT]]="","-",VLOOKUP(compras_mes2[[#This Row],[CUIT]],Lista_CUIT[#All],2,0)),"CUIT NO CARGADO") -> GLOBANS S.R.L. | H18: 4806.11 | I18: =IF(compras_mes2[[#This Row],[NETO GRAVADO]]="","",compras_mes2[[#This Row],[NETO GRAVADO]]*0.21) -> 1009.2831 | P18: =SUM(compras_mes2[[#This Row],[NETO GRAVADO]:[Otros / No Grav.]]) -> 5815.3931 | Q18: =IFERROR(IF(compras_mes2[[#This Row],[CUIT]]="","-",VLOOKUP(compras_mes2[[#This Row],[CUIT]],Lista_CUIT[#All],3,0)),"CUIT NO CARGADO") -> 0 | R18: =IFERROR(IF(compras_mes2[[#This Row],[CUIT]]="","-",VLOOKUP(compras_mes2[[#This Row],[CUIT]],Lista_CUIT[#All],4,0)),"CUIT NO CARGADO") -> 0
B19: 45062 | C19: 1 | D19: 2 | E19: 10325 | F19: 30712179909 | G19: =IFERROR(IF(compras_mes2[[#This Row],[CUIT]]="","-",VLOOKUP(compras_mes2[[#This Row],[CUIT]],Lista_CUIT[#All],2,0)),"CUIT NO CARGADO") -> LEPORT SH DE PORTELA JORGE FERNANDO Y LEAL JORGE ANGEL | H19: 110306 | I19: =IF(compras_mes2[[#This Row],[NETO GRAVADO]]="","",compras_mes2[[#This Row],[NETO GRAVADO]]*0.21) -> 23164.26 | P19: =SUM(compras_mes2[[#This Row],[NETO GRAVADO]:[Otros / No Grav.]]) -> 133470.26 | Q19: =IFERROR(IF(compras_mes2[[#This Row],[CUIT]]="","-",VLOOKUP(compras_mes2[[#This Row],[CUIT]],Lista_CUIT[#All],3,0)),"CUIT NO CARGADO") -> FLETE-LOGISTICA | R19: =IFERROR(IF(compras_mes2[[#This Row],[CUIT]]="","-",VLOOKUP(compras_mes2[[#This Row],[CUIT]],Lista_CUIT[#All],4,0)),"CUIT NO CARGADO") -> 0
B20: 45054 | C20: 1 | D20: 12 | E20: 21890 | F20: 30604942051 | G20: =IFERROR(IF(compras_mes2[[#This Row],[CUIT]]="","-",VLOOKUP(compras_mes2[[#This Row],[CUIT]],Lista_CUIT[#All],2,0)),"CUIT NO CARGADO") -> IMPORTADORA FOTOGRAFICA SOCIEDAD ANONIMA | H20: 52065.43 | I20: =IF(compras_mes2[[#This Row],[NETO GRAVADO]]="","",compras_mes2[[#This Row],[NETO GRAVADO]]*0.21) -> 10933.74 | P20: =SUM(compras_mes2[[#This Row],[NETO GRAVADO]:[Otros / No Grav.]]) -> 62999.17 | Q20: =IFERROR(IF(compras_mes2[[#This Row],[CUIT]]="","-",VLOOKUP(compras_mes2[[#This Row],[CUIT]],Lista_CUIT[#All],3,0)),"CUIT NO CARGADO") -> Gastos Oficina | R20: =IFERROR(IF(compras_mes2[[#This Row],[CUIT]]="","-",VLOOKUP(compras_mes2[[#This Row],[CUIT]],Lista_CUIT[#All],4,0)),"CUIT NO CARGADO") -> 0
B21: 45047 | C21: 1 | D21: 3 | E21: 644 | F21: 30715402765 | G21: =IFERROR(IF(compras_mes2[[#This Row],[CUIT]]="","-",VLOOKUP(compras_mes2[[#This Row],[CUIT]],Lista_CUIT[#All],2,0)),"CUIT NO CARGADO") -> RIO 265 S.R.L. | H21: 12809.92 | I21: =IF(compras_mes2[[#This Row],[NETO GRAVADO]]="","",compras_mes2[[#This Row],[NETO GRAVADO]]*0.21) -> 2690.0832 | P21: =SUM(compras_mes2[[#This Row],[NETO GRAVADO]:[Otros / No Grav.]]) -> 15500.003 | Q21: =IFERROR(IF(compras_mes2[[#This Row],[CUIT]]="","-",VLOOKUP(compras_mes2[[#This Row],[CUIT]],Lista_CUIT[#All],3,0)),"CUIT NO CARGADO") -> Gastos Varios | R21: =IFERROR(IF(compras_mes2[[#This Row],[CUIT]]="","-",VLOOKUP(compras_mes2[[#This Row],[CUIT]],Lista_CUIT[#All],4,0)),"CUIT NO CARGADO") -> 0
B22: 45065 | C22: 1 | D22: 5 | E22: 22491 | F22: 30708166673 | G22: =IFERROR(IF(compras_mes2[[#This Row],[CUIT]]="","-",VLOOKUP(compras_mes2[[#This Row],[CUIT]],Lista_CUIT[#All],2,0)),"CUIT NO CARGADO") -> SUMINISTROS WHITE S.A. | H22: 4725.45 | I22: =IF(compras_mes2[[#This Row],[NETO GRAVADO]]="","",compras_mes2[[#This Row],[NETO GRAVADO]]*0.21) -> 992.3445 | P22: =SUM(compras_mes2[[#This Row],[NETO GRAVADO]:[Otros / No Grav.]]) -> 5717.7945 | Q22: =IFERROR(IF(compras_mes2[[#This Row],[CUIT]]="","-",VLOOKUP(compras_mes2[[#This Row],[CUIT]],Lista_CUIT[#All],3,0)),"CUIT NO CARGADO") -> Gastos Varios | R22: =IFERROR(IF(compras_mes2[[#This Row],[CUIT]]="","-",VLOOKUP(compras_mes2[[#This Row],[CUIT]],Lista_CUIT[#All],4,0)),"CUIT NO CARGADO") -> 0
B23: 45077 | C23: 1 | D23: 3 | E23: 1449227 | F23: 30712019359 | G23: =IFERROR(IF(compras_mes2[[#This Row],[CUIT]]="","-",VLOOKUP(compras_mes2[[#This Row],[CUIT]],Lista_CUIT[#All],2,0)),"CUIT NO CARGADO") -> LINKEDSTORE ARGENTINA S.R.L. | H23: 6032.23 | I23: =IF(compras_mes2[[#This Row],[NETO GRAVADO]]="","",compras_mes2[[#This Row],[NETO GRAVADO]]*0.21) -> 1266.7683 | P23: =SUM(compras_mes2[[#This Row],[NETO GRAVADO]:[Otros / No Grav.]]) -> 7298.9983 | Q23: =IFERROR(IF(compras_mes2[[#This Row],[CUIT]]="","-",VLOOKUP(compras_mes2[[#This Row],[CUIT]],Lista_CUIT[#All],3,0)),"CUIT NO CARGADO") -> Gastos Varios | R23: =IFERROR(IF(compras_mes2[[#This Row],[CUIT]]="","-",VLOOKUP(compras_mes2[[#This Row],[CUIT]],Lista_CUIT[#All],4,0)),"CUIT NO CARGADO") -> 0
B24: 45048 | C24: 1 | D24: 106 | E24: 627952 | F24: 30594494187 | G24: =IFERROR(IF(compras_mes2[[#This Row],[CUIT]]="","-",VLOOKUP(compras_mes2[[#This Row],[CUIT]],Lista_CUIT[#All],2,0)),"CUIT NO CARGADO") -> FEDERAL EXPRESS CORPORATION | H24: 0 | I24: =IF(compras_mes2[[#This Row],[NETO GRAVADO]]="","",compras_mes2[[#This Row],[NETO GRAVADO]]*0.21) -> 0 | O24: 95430.75 | P24: =SUM(compras_mes2[[#This Row],[NETO GRAVADO]:[Otros / No Grav.]]) -> 95430.75 | Q24: =IFERROR(IF(compras_mes2[[#This Row],[CUIT]]="","-",VLOOKUP(compras_mes2[[#This Row],[CUIT]],Lista_CUIT[#All],3,0)),"CUIT NO CARGADO") -> Gtos. Imp. | R24: =IFERROR(IF(compras_mes2[[#This Row],[CUIT]]="","-",VLOOKUP(compras_mes2[[#This Row],[CUIT]],Lista_CUIT[#All],4,0)),"CUIT NO CARGADO") -> 0
