Workbook
Name partner_id: Configuracion!$B$332

Sheet Configuracion
F1: CUIT | G1: Cargar sin guiones
F2: RAZON SOCIAL | G2: Maximo 30 caracteres
A3: CUIT | B3: RAZON SOCIAL | C3: DETALLE | F3: DETALLE | G3: Cargar tipo de gasto
A4: 30628205090 | B4: ALBAMIE SA | C4: CLIENTE
A5: 30711678820 | B5: 2PSI INGENIERIA SRL | C5: PROVEEDOR
A6: 33716367539 | B6: 3PI S.A.S. | C6: PROVEEDOR
A7: 30660373108 | B7: ABC SA | C7: VARIOS
A8: 20300210881 | B8: ABOY DIEGO OSCAR | C8: PROVEEDOR
A9: 27229910782 | B9: ABUGAUCH MARIA DE LOS ANGELES | C9: PROVEEDOR
A10: 20242709897 | B10: ABUGAUCH VICTOR HUGO | C10: PROVEEDOR
A11: 20281669053 | B11: ACOSTA JAVIER GUSTAVO | C11: FLETE
A12: 20174240125 | B12: ACOSTA OSCAR ISIDRO | C12: VARIOS
A13: 30641659106 | B13: AGRISOL SA | C13: VARIOS
A14: 33709914109 | B14: ALAN COLLECTION SA | C14: VARIOS
A15: 20267161616 | B15: ALBAJARI DIEGO MARCOS | C15: VARIOS
... A155: 30537679855 | B155: ESTACION LIMA SA | C155: VARIOS
A156: 30-56864959-8 | B156: EXPRESO BISONTE SRL | C156: FLETE
A157: 30708542349 | B157: EXPRESO FORMOSA SRL | C157: FLETE
A158: 30526582884 | B158: EXPRESO MAR DEL PLATA SA | C158: FLETE
A159: 30577744579 | B159: EXPRESO TROLE SRL | C159: FLETE
A160: 30715949292 | B160: EYPAPEL SAS | C160: GASTOS VARIOS
A161: 30715980807 | B161: FABORT SRL | C161: PROVEEDOR
A162: 20359718765 | B162: FAIL ABRAHAM | C162: VARIOS
A163: 30643518364 | B163: FARMACIA DE MEDRANO SCS | C163: PROVEEDOR
A164: 30692138747 | B164: FARMACITY SA | C164: VARIOS
A165: 33712234429 | B165: FEDAGAS SA | C165: VARIOS
A166: 20353576012 | B166: FEDERICO PABLO FEOLA | C166: VARIOS
A167: 20343766441 | B167: FERNANDEZ MAURO | C167: TALLER
A168: 27062343449 | B168: FERREIRA LILIANA INES | C168: FLETE
... A570: 30661273093 | B570: OSETRA | C570: CLIENTE

Sheet Julio 25
A1: ORTOPEDIA GEMINIS S.A. | J1: 45839
A4: LIBRO IVA COMPRAS
A6: FACTURAS A
A7: FECHA | B7: PTO VTA | C7: FAC A | D7: CUIT | E7: RAZON SOCIAL | F7: NETO | G7: IVA 21% | H7: IVA 27% | I7: IVA 10,5% | J7: P IVA | K7: IIBB CF | L7: IIBB BS | M7: NO GRAV | N7: OTROS | O7: TOTAL | P7: DETALLE
E8: =VLOOKUP(D8,Configuracion!$A$4:$C$590,2,FALSE) -> #N/A | G8: =F8*21% -> 0 | O8: =SUM(F8:N8) -> 0 | P8: =VLOOKUP(D8,Configuracion!$A$4:$C$590,3,FALSE) -> #N/A
E9: =VLOOKUP(D9,Configuracion!$A$4:$C$590,2,FALSE) -> #N/A | G9: =F9*21% -> 0 | O9: =SUM(F9:N9) -> 0 | P9: =VLOOKUP(D9,Configuracion!$A$4:$C$590,3,FALSE) -> #N/A
E10: =VLOOKUP(D10,Configuracion!$A$4:$C$590,2,FALSE) -> #N/A | G10: =F10*21% -> 0 | O10: =SUM(F10:N10) -> 0 | P10: =VLOOKUP(D10,Configuracion!$A$4:$C$590,3,FALSE) -> #N/A
E11: =VLOOKUP(D11,Configuracion!$A$4:$C$590,2,FALSE) -> #N/A | G11: =F11*21% -> 0 | O11: =SUM(F11:N11) -> 0 | P11: =VLOOKUP(D11,Configuracion!$A$4:$C$590,3,FALSE) -> #N/A
E12: =VLOOKUP(D12,Configuracion!$A$4:$C$590,2,FALSE) -> #N/A | G12: =F12*21% -> 0 | O12: =SUM(F12:N12) -> 0 | P12: =VLOOKUP(D12,Configuracion!$A$4:$C$590,3,FALSE) -> #N/A
E13: =VLOOKUP(D13,Configuracion!$A$4:$C$590,2,FALSE) -> #N/A | G13: =F13*21% -> 0 | O13: =SUM(F13:N13) -> 0 | P13: =VLOOKUP(D13,Configuracion!$A$4:$C$590,3,FALSE) -> #N/A
E14: =VLOOKUP(D14,Configuracion!$A$4:$C$590,2,FALSE) -> #N/A | G14: =F14*21% -> 0 | O14: =SUM(F14:N14) -> 0 | P14: =VLOOKUP(D14,Configuracion!$A$4:$C$590,3,FALSE) -> #N/A
E15: =VLOOKUP(D15,Configuracion!$A$4:$C$590,2,FALSE) -> #N/A | G15: =F15*21% -> 0 | O15: =SUM(F15:N15) -> 0 | P15: =VLOOKUP(D15,Configuracion!$A$4:$C$590,3,FALSE) -> #N/A
E16: =VLOOKUP(D16,Configuracion!$A$4:$C$590,2,FALSE) -> #N/A | G16: =F16*21% -> 0 | O16: =SUM(F16:N16) -> 0 | P16: =VLOOKUP(D16,Configuracion!$A$4:$C$590,3,FALSE) -> #N/A
E17: =VLOOKUP(D17,Configuracion!$A$4:$C$590,2,FALSE) -> #N/A | G17: =F17*21% -> 0 | O17: =SUM(F17:N17) -> 0 | P17: =VLOOKUP(D17,Configuracion!$A$4:$C$590,3,FALSE) -> #N/A
A18: TOTAL | F18: =SUM(F8:F17) -> 0 | G18: =SUM(G8:G17) -> 0 | H18: =SUM(H8:H17) -> 0 | I18: =SUM(I8:I17) -> 0 | J18: =SUM(J8:J17) -> 0 | K18: =SUM(K8:K17) -> 0 | L18: =SUM(L8:L17) -> 0 | M18: =SUM(M8:M17) -> 0 | ... O18: =SUM(O8:O17) -> 0
F19: IVA | G19: =G18+H18+I18 -> 0
A21: FACTURAS B/C
A22: FECHA | B22: PTO VTA | C22: FAC C | D22: CUIT | E22: RAZON SOCIAL | F22: TOTAL | G22: DETALLE
E23: =VLOOKUP(D23,Configuracion!$A$4:$C$590,2,FALSE) -> #N/A | G23: =VLOOKUP(D23,Configuracion!$A$4:$C$590,3,FALSE) -> #N/A
E24: =VLOOKUP(D24,Configuracion!$A$4:$C$590,2,FALSE) -> #N/A | G24: =VLOOKUP(D24,Configuracion!$A$4:$C$590,3,FALSE) -> #N/A
E25: =VLOOKUP(D25,Configuracion!$A$4:$C$590,2,FALSE) -> #N/A | G25: =VLOOKUP(D25,Configuracion!$A$4:$C$590,3,FALSE) -> #N/A
E26: =VLOOKUP(D26,Configuracion!$A$4:$C$590,2,FALSE) -> #N/A | G26: =VLOOKUP(D26,Configuracion!$A$4:$C$590,3,FALSE) -> #N/A
E27: =VLOOKUP(D27,Configuracion!$A$4:$C$590,2,FALSE) -> #N/A | G27: =VLOOKUP(D27,Configuracion!$A$4:$C$590,3,FALSE) -> #N/A
E28: =VLOOKUP(D28,Configuracion!$A$4:$C$590,2,FALSE) -> #N/A | G28: =VLOOKUP(D28,Configuracion!$A$4:$C$590,3,FALSE) -> #N/A
E29: =VLOOKUP(D29,Configuracion!$A$4:$C$590,2,FALSE) -> #N/A | G29: =VLOOKUP(D29,Configuracion!$A$4:$C$590,3,FALSE) -> #N/A
E30: =VLOOKUP(D30,Configuracion!$A$4:$C$590,2,FALSE) -> #N/A | G30: =VLOOKUP(D30,Configuracion!$A$4:$C$590,3,FALSE) -> #N/A
E31: =VLOOKUP(D31,Configuracion!$A$4:$C$590,2,FALSE) -> #N/A | G31: =VLOOKUP(D31,Configuracion!$A$4:$C$590,3,FALSE) -> #N/A
E32: =VLOOKUP(D32,Configuracion!$A$4:$C$590,2,FALSE) -> #N/A | G32: =VLOOKUP(D32,Configuracion!$A$4:$C$590,3,FALSE) -> #N/A
E33: =VLOOKUP(D33,Configuracion!$A$4:$C$590,2,FALSE) -> #N/A | G33: =VLOOKUP(D33,Configuracion!$A$4:$C$590,3,FALSE) -> #N/A
E34: =VLOOKUP(D34,Configuracion!$A$4:$C$590,2,FALSE) -> #N/A | G34: =VLOOKUP(D34,Configuracion!$A$4:$C$590,3,FALSE) -> #N/A
... E41: =VLOOKUP(D41,Configuracion!$A$4:$C$590,2,FALSE) -> #N/A | G41: =VLOOKUP(D41,Configuracion!$A$4:$C$590,3,FALSE) -> #N/A
A42: TOTAL | F42: =SUM(F23:F41) -> 0
A44: RETENCIONES de IVA solamente
A45: FECHA | B45: COMPROBANTE NRO | D45: CUIT | E45: RAZON SOCIAL | F45: GANANCIAS | G45: IVA | H45: IIBB | I45: SUSS
A46: 45869 | B46: 66528 | D46: 30522428163 | E46: =VLOOKUP(D46,Configuracion!$A$4:$C$590,2,FALSE) -> GALENO ARGENTINA SA | G46: 48359.01
A47: 45869 | B47: 66484 | D47: 30522428163 | E47: =VLOOKUP(D47,Configuracion!$A$4:$C$590,2,FALSE) -> GALENO ARGENTINA SA | G47: 799478.14
D48: 0 | E48: =VLOOKUP(D48,Configuracion!$A$4:$C$590,2,FALSE) -> #N/A
D49: 0 | E49: =VLOOKUP(D49,Configuracion!$A$4:$C$590,2,FALSE) -> #N/A
D50: 0 | E50: =VLOOKUP(D50,Configuracion!$A$4:$C$590,2,FALSE) -> #N/A
D51: 0 | E51: =VLOOKUP(D51,Configuracion!$A$4:$C$590,2,FALSE) -> #N/A
...

Sheet Calculo IVA
B1: ORTOPEDIA GEMINIS
A2: Calculo Iva | D2: 45809
B4: VENTAS
B5: Neto | C5: Iva | D5: Total
A6: FAC. "A" | B6: =+'Ventas 07'!D4+'Ventas 07'!D5 -> 73784714 | C6: =+B6*0.21 -> 15494790 | D6: =+B6+C6 -> 89279504
A7: FAC. "B" | B7: =+'Ventas 07'!D6+'Ventas 07'!D7+'Ventas 07'!D8 -> 43898013 | C7: =+B7*0.21 -> 9218582.7 | D7: =+B7+C7 -> 53116596
B8: =SUM(B6:B7) -> 1.1768273e+08 | C8: =SUM(C6:C7) -> 24713373 | D8: =SUM(D6:D7) -> 1.423961e+08
B11: COMPRAS
B12: Neto | C12: IVA | D12: Total
A13: Comprobantes / Extractos | B13: =+'Compras 07'!G161+'Compras 07'!H161+'Compras 07'!I161 -> 69769155 | C13: =+'Compras 07'!L161 -> 13591497 | D13: 94654478
B16: =SUM(B13:B15) -> 69769155 | C16: =SUM(C13:C15) -> 13591497 | D16: =SUM(D13:D15) -> 94654478
A19: RETENCIONES | B19: N° Cuit | C19: Importe | D19: Nro. Retencion | E19: Fecha
A20: AFIP - No están informadas las retenciones de IVA en el sistema de AFIP
C35: =+'Julio 25'!G59 -> 847837.15
A37: PERCEPCIONES | B37: N° Cuit | C37: Importe | D37: Nro. Retencion | E37: Fecha
C41: =SUM(C38:C40) -> 0
A43: Total Deducciociones | C43: =+C41+C35 -> 847837.15
C46: (Montos en Positivo)
A47: 1er Saldo Tecnico del Período | C47: =+C8-C16 -> 11121875
A49: Saldo Tecnico de período Anterior (a favor) | D49: (resta en el total)
A51: Saldo Neto Técnico | C51: =+C47-C49 -> 11121875
A55: Saldo L.D. del Período | C55: =+C41+C35 -> 847837.15
A57: Saldo L.D. del Período Anterior
A59: Neto S.L.D | C59: =+C55+C57 -> 847837.15
A62: I V A | C62: =+C51-C59 -> 10274038
A63: NOTA: Sin Tomar posibles Retenciones que se hayan hecho

Sheet afip
A1: Fecha | B1: Tipo | C1: Punto de Venta | D1: Número Desde | E1: Número Hasta | F1: Cód. Autorización | G1: Tipo Doc. Emisor | H1: Nro. Doc. Emisor | I1: Denominación Emisor | J1: Tipo Cambio | K1: Moneda | L1: Imp. Neto Gravado | M1: Imp. Neto No Gravado | N1: Imp. Op. Exentas | O1: Otros Tributos | P1: IVA | Q1: Imp. Total
A2: 01/09/2024 | B2: 1 - Factura A | C2: 2189 | D2: 75919 | F2: 74356447170423 | G2: CUIT | H2: 30548083156 | I2: COTO CENTRO INTEGRAL DE COMERCIALIZACION SOCIEDAD ANONIMA | J2: 1 | K2: $ | L2: 6462.61 | M2: 0 | N2: 0 | O2: 452.38 | P2: 1357.15 | Q2: 8272.14
A3: 02/09/2024 | B3: 1 - Factura A | C3: 500 | D3: 1611886 | F3: 74357098226128 | G3: CUIT | H3: 30654118767 | I3: SOLUCIONES MULTIMEDIA S A | J3: 1 | K3: $ | L3: 89554.36 | M3: 0 | N3: 0 | O3: 0 | P3: 18806.42 | Q3: 112850.92
A4: 02/09/2024 | B4: 1 - Factura A | C4: 1 | D4: 4517 | F4: 74361573927319 | G4: CUIT | H4: 30715141201 | I4: REHAB S.R.L. | J4: 1 | K4: $ | L4: 1216380 | M4: 0 | N4: 0 | O4: 0 | P4: 255439.8 | Q4: 1471819.8
A5: 02/09/2024 | B5: 1 - Factura A | C5: 5 | D5: 158399 | F5: 74363528156508 | G5: CUIT | H5: 30598960093 | I5: SILVESTRIN FABRIS SOC RESP LTDA | J5: 1 | K5: $ | L5: 2376294.2 | M5: 0 | N5: 0 | O5: 0 | P5: 337808.56 | Q5: 2832917.5
A6: 02/09/2024 | B6: 1 - Factura A | C6: 17 | D6: 2245 | F6: 74361547632750 | G6: CUIT | H6: 30711764921 | I6: RELIEF CENTER S.R.L. | J6: 1 | K6: $ | L6: 93973 | M6: 0 | N6: 0 | O6: 0 | P6: 19734.33 | Q6: 113707.33
A7: 02/09/2024 | B7: 1 - Factura A | C7: 3051 | D7: 801967 | F7: 74367703518446 | G7: CUIT | H7: 30678814357 | I7: TELEFONICA MOVILES ARGENTINA SOCIEDAD ANONIMA | J7: 1 | K7: $ | L7: 14407 | M7: 0 | N7: 0 | O7: 0 | P7: 3889.89 | Q7: 20245.61
A8: 02/09/2024 | B8: 1 - Factura A | C8: 2 | D8: 248 | F8: 74363494027429 | G8: CUIT | H8: 27144282383 | I8: SCHEJTER LILA ELISA | J8: 1 | K8: $ | L8: 160000 | M8: 0 | N8: 0 | O8: 0 | P8: 33600 | Q8: 193600
A9: 02/09/2024 | B9: 1 - Factura A | C9: 5 | D9: 102 | F9: 74367559790009 | G9: CUIT | H9: 27329449357 | I9: ANDREANI AGUSTINA SUSANA | J9: 1 | K9: $ | L9: 64100 | M9: 16400 | N9: 0 | O9: 0 | P9: 13461 | Q9: 93961
A10: 02/09/2024 | B10: 11 - Factura C | C10: 3 | D10: 874 | F10: 74363563144286 | G10: CUIT | H10: 20086277523 | I10: BOTINDARI JUAN CARLOS | J10: 1 | K10: $ | O10: 0 | Q10: 275500
A11: 02/09/2024 | B11: 11 - Factura C | C11: 2 | D11: 302 | F11: 74368278674869 | G11: CUIT | H11: 27265832178 | I11: BLASCO MARIA GUADALUPE | J11: 1 | K11: $ | O11: 0 | Q11: 250000
A12: 03/09/2024 | B12: 1 - Factura A | C12: 629 | D12: 5407463 | F12: 34353802937243 | G12: CUIT | H12: 30663498513 | I12: GRUPO CONCESIONARIO DEL OESTE SA | J12: 1 | K12: $ | L12: 2121.64 | M12: 0 | N12: 0 | O12: 0 | P12: 445.54 | Q12: 2673.26
A13: 03/09/2024 | B13: 1 - Factura A | C13: 711 | D13: 6097149 | F13: 34359489663246 | G13: CUIT | H13: 30677237119 | I13: AUTOPISTAS DEL SOL S A | J13: 1 | K13: $ | L13: 7715.05 | M13: 0 | N13: 231.45 | O13: 0 | P13: 1620.16 | Q13: 9952.41
A14: 03/09/2024 | B14: 1 - Factura A | C14: 2635 | D14: 1369 | F14: 34359844249451 | G14: CUIT | H14: 33699685459 | I14: CORREO ANDREANI SA | J14: 1 | K14: $ | L14: 12449.6 | M14: 0 | N14: 0 | O14: 0 | P14: 2614.42 | Q14: 15064.02
A15: 03/09/2024 | B15: 1 - Factura A | C15: 2 | D15: 216 | F15: 74362687536018 | G15: CUIT | H15: 30605344352 | I15: CONSORCIO BARTOLOME MITRE 2466 | J15: 1 | K15: $ | L15: 834000 | M15: 0 | N15: 0 | O15: 0 | P15: 175140 | Q15: 1009140
A16: 04/09/2024 | B16: 1 - Factura A | C16: 17 | D16: 2255 | F16: 74361803741207 | G16: CUIT | H16: 30711764921 | I16: RELIEF CENTER S.R.L. | J16: 1 | K16: $ | L16: 527580 | M16: 0 | N16: 0 | O16: 0 | P16: 110791.8 | Q16: 638371.8
A17: 04/09/2024 | B17: 1 - Factura A | C17: 2 | D17: 50685 | F17: 74365825946417 | G17: CUIT | H17: 30595553535 | I17: RUBRICOM SOCIEDAD ANONIMA | J17: 1 | K17: $ | L17: 4793.39 | M17: 0 | N17: 0 | O17: 0 | P17: 1006.61 | Q17: 5800
A18: 04/09/2024 | B18: 1 - Factura A | C18: 120 | D18: 4949 | F18: 74365804898856 | G18: CUIT | H18: 30587197215 | I18: PANATEL SOCIEDAD ANONIMA | J18: 1 | K18: $ | L18: 68595.04 | M18: 0 | N18: 0 | O18: 0 | P18: 14404.96 | Q18: 86429.75
A19: 04/09/2024 | B19: 1 - Factura A | C19: 7 | D19: 3241 | F19: 74364799883128 | G19: CUIT | H19: 20284183534 | I19: FURLANETTO MARTIN | J19: 1 | K19: $ | L19: 4545.5 | M19: 0 | N19: 0 | O19: 0 | P19: 954.56 | Q19: 5500.06
A20: 04/09/2024 | B20: 1 - Factura A | C20: 120 | D20: 4948 | F20: 74365800262038 | G20: CUIT | H20: 30587197215 | I20: PANATEL SOCIEDAD ANONIMA | J20: 1 | K20: $ | L20: 68595.04 | M20: 0 | N20: 0 | O20: 0 | P20: 14404.96 | Q20: 86429.75
A21: 04/09/2024 | B21: 1 - Factura A | C21: 401 | D21: 66 | F21: 74364797895464 | G21: CUIT | H21: 30716234114 | I21: UZUMAKI S.A.S. | J21: 1305 | K21: USD | L21: 129.3 | M21: 0 | N21: 0 | O21: 0 | P21: 27.15 | Q21: 156.45
A22: 05/09/2024 | B22: 1 - Factura A | C22: 2 | D22: 760 | F22: 74369961703669 | G22: CUIT | H22: 20272865869 | I22: DI FEO MARTIN EZEQUIEL | J22: 1 | K22: $ | L22: 84450 | M22: 0 | N22: 0 | O22: 0 | P22: 17734.5 | Q22: 102184.5
A23: 05/09/2024 | B23: 1 - Factura A | C23: 5 | D23: 5331 | F23: 74363959099503 | G23: CUIT | H23: 30715833243 | I23: BIODINAMICA ASISTENCIA S.R.L. | J23: 1 | K23: $ | L23: 22238.59 | M23: 0 | N23: 0 | O23: 0 | P23: 4670.1 | Q23: 26908.69
... A35: 09/09/2024 | B35: 3 - Nota de Crédito A | C35: 5 | D35: 192 | F35: 74376416376753 | G35: CUIT | H35: 30712187316 | I35: ITALOMED PRODUCTOS SRL | J35: 1 | K35: $ | L35: 293619.94 | M35: 0 | N35: 0 | O35: 0 | P35: 61660.19 | Q35: 355280.13
A36: 09/09/2024 | B36: 11 - Factura C | C36: 1 | D36: 148 | F36: 74370408397319 | G36: CUIT | H36: 27338342840 | I36: CANCINO PAMELA RITA | J36: 1 | K36: $ | O36: 0 | Q36: 276800
A37: 10/09/2024 | B37: 1 - Factura A | C37: 2 | D37: 8403 | F37: 74372567359059 | G37: CUIT | H37: 27363810182 | I37: HECKER LAURA NOEMI | J37: 1 | K37: $ | L37: 3635.54 | M37: 0 | N37: 0 | O37: 0 | P37: 763.46 | Q37: 4399
A38: 10/09/2024 | B38: 1 - Factura A | C38: 5 | D38: 31858 | F38: 74370525870493 | G38: CUIT | H38: 30710804830 | I38: ZG MULTITEC SRL | J38: 1 | K38: $ | L38: 29410.86 | M38: 0 | N38: 0 | O38: 0 | P38: 3088.14 | Q38: 32499
A39: 10/09/2024 | B39: 1 - Factura A | C39: 8 | D39: 1684 | F39: 74371529941038 | G39: CUIT | H39: 30708973501 | I39: ASIAL S.R.L. | J39: 1 | K39: $ | L39: 740255 | M39: 0 | N39: 0 | O39: 0 | P39: 155453.55 | Q39: 895708.55
A40: 10/09/2024 | B40: 1 - Factura A | C40: 3 | D40: 4250 | F40: 74378552751950 | G40: CUIT | H40: 20184052858 | I40: ABOUD PABLO DANIEL | J40: 1 | K40: $ | L40: 16859.48 | M40: 0 | N40: 0 | O40: 0 | P40: 3540.49 | Q40: 20399.95
A41: 10/09/2024 | B41: 11 - Factura C | C41: 3 | D41: 986 | F41: 74379527477577 | G41: CUIT | H41: 20216451679 | I41: VAZQUEZ RICARDO OSCAR | J41: 1 | K41: $ | O41: 0 | Q41: 86000
A42: 11/09/2024 | B42: 1 - Factura A | C42: 1 | D42: 2468 | F42: 74379681409704 | G42: CUIT | H42: 30717179389 | I42: NICOLAS TOBIAS SEQUEIRA Y MARIA GABRIELA RATTNER SOCIEDAD DE LA SECCION IV LGS | J42: 1 | K42: $ | L42: 82644.62 | M42: 0 | N42: 0 | O42: 0 | P42: 17355.37 | Q42: 99999.99
A43: 11/09/2024 | B43: 1 - Factura A | C43: 5 | D43: 3378 | F43: 74379704726153 | G43: CUIT | H43: 30717179389 | I43: NICOLAS TOBIAS SEQUEIRA Y MARIA GABRIELA RATTNER SOCIEDAD DE LA SECCION IV LGS | J43: 1 | K43: $ | L43: 82644.63 | M43: 0 | N43: 0 | O43: 0 | P43: 17355.37 | Q43: 100000
A44: 11/09/2024 | B44: 1 - Factura A | C44: 3 | D44: 7676 | F44: 74379686794320 | G44: CUIT | H44: 33708218699 | I44: MANGGINI PABLO Y MANGGINI ULISES SOC. DE HECHO. | J44: 1 | K44: $ | L44: 15000 | M44: 0 | N44: 0 | O44: 0 | P44: 3150 | Q44: 18150
A45: 11/09/2024 | B45: 11 - Factura C | C45: 1 | D45: 9 | F45: 74373677716509 | G45: CUIT | H45: 20464199633 | I45: OVIEDO JIMENEZ TIZIANO LIONEL | J45: 1 | K45: $ | O45: 0 | Q45: 499950
A46: 12/09/2024 | B46: 1 - Factura A | C46: 2 | D46: 778 | F46: 74379814460759 | G46: CUIT | H46: 20272865869 | I46: DI FEO MARTIN EZEQUIEL | J46: 1 | K46: $ | L46: 128100 | M46: 0 | N46: 0 | O46: 0 | P46: 26901 | Q46: 155001
A47: 12/09/2024 | B47: 1 - Factura A | C47: 4 | D47: 38394 | F47: 74379814609856 | G47: CUIT | H47: 20289111329 | I47: LEDESMA EMILIANO RUBEN | J47: 1 | K47: $ | L47: 585730.8 | M47: 0 | N47: 0 | O47: 0 | P47: 123003.47 | Q47: 708734.27
A48: 12/09/2024 | B48: 1 - Factura A | C48: 5 | D48: 1915 | F48: 74376761404173 | G48: CUIT | H48: 30712187316 | I48: ITALOMED PRODUCTOS SRL | J48: 1 | K48: $ | L48: 254033.05 | M48: 0 | N48: 0 | O48: 0 | P48: 53346.94 | Q48: 307379.99
A49: 12/09/2024 | B49: 1 - Factura A | C49: 5 | D49: 1916 | F49: 74376766353942 | G49: CUIT | H49: 30712187316 | I49: ITALOMED PRODUCTOS SRL | J49: 1 | K49: $ | L49: 472751.65 | M49: 0 | N49: 0 | O49: 0 | P49: 99277.85 | Q49: 572029.5
A50: 13/09/2024 | B50: 1 - Factura A | C50: 1 | D50: 4620 | F50: 74371942773283 | G50: CUIT | H50: 30715141201 | I50: REHAB S.R.L. | J50: 1 | K50: $ | L50: 29295 | M50: 0 | N50: 0 | O50: 0 | P50: 6151.95 | Q50: 35446.95
A51: 13/09/2024 | B51: 1 - Factura A | C51: 5 | D51: 1920 | F51: 74376932362480 | G51: CUIT | H51: 30712187316 | I51: ITALOMED PRODUCTOS SRL | J51: 1 | K51: $ | L51: 34718.6 | M51: 0 | N51: 0 | O51: 0 | P51: 7290.91 | Q51: 42009.51
...

Sheet Hoja3
A1: Comprobante no recibido
A4: Fecha | B4: Comprobante | C4: Nombre | D4: Cond. IVA | E4: CUIT o Doc. | F4: Gravado | G4: No Gravado
A5: 02/09/2024 | B5: FA-C 0003-00000874 | C5: BOTINDARI JUAN CARLOS | D5: Responsable Monotributo | E5: 20086277523 | F5: 0 | G5: 275500
A6: 02/09/2024 | B6: 874 | C6: BOTINDARI JUAN CARLOS | E6: 20086277523
A7: 19/09/2024 | B7: FA-A 0007-00006066 | C7: Triveño Roma, Ramon | D7: IVA Responsable Inscripto | E7: 20131067446 | F7: 278865.6 | G7: 0
A8: 19/09/2024 | B8: 6066 | C8: TRIVEÑO ROMA RAMON | E8: 20131067446 | F8: 278865.6 | G8: 0
A9: 10/09/2024 | B9: FA-A 0003-00004250 | C9: Aboud, Pablo Daniel | D9: IVA Responsable Inscripto | E9: 20184052858 | F9: 16859.46 | G9: 0
A10: 30/09/2024 | B10: FA-A 0003-00004276 | C10: Aboud, Pablo Daniel | D10: IVA Responsable Inscripto | E10: 20184052858 | F10: 71074.3 | G10: 0
A11: 10/09/2024 | B11: 4250 | C11: ABOUD PABLO DANIEL | E11: 20184052858 | F11: 16859.48 | G11: 0
A12: 30/09/2024 | B12: 4276 | C12: ABOUD PABLO DANIEL | E12: 20184052858 | F12: 71074.33 | G12: 0
A13: 30/09/2024 | B13: 804 | C13: PAIS HECTOR GUILLERMO | E13: 20214946867 | F13: 37189.24 | G13: 0
A14: 10/09/2024 | B14: FA-C 0003-00000986 | C14: Vazquez, Ricardo Oscar | D14: Responsable Monotributo | E14: 20216451679 | F14: 0 | G14: 86000
A15: 27/09/2024 | B15: FA-C 0003-00000995 | C15: Vazquez, Ricardo Oscar | D15: Responsable Monotributo | E15: 20216451679 | F15: 0 | G15: 160000
A16: 10/09/2024 | B16: 986 | C16: VAZQUEZ RICARDO OSCAR | E16: 20216451679
A17: 19/09/2024 | B17: 991 | C17: VAZQUEZ RICARDO OSCAR | E17: 20216451679
A18: 27/09/2024 | B18: 995 | C18: VAZQUEZ RICARDO OSCAR | E18: 20216451679
A19: 12/09/2024 | B19: FA-A 0002-00000778 | C19: Di Feo, Martin Ezequiel | D19: IVA Responsable Inscripto | E19: 20272865869 | F19: 128100 | G19: 0
A20: 13/09/2024 | B20: FA-A 0002-00000783 | C20: Di Feo, Martin Ezequiel | D20: IVA Responsable Inscripto | E20: 20272865869 | F20: 9950 | G20: 0
A21: 19/09/2024 | B21: FA-A 0002-00000796 | C21: Di Feo, Martin Ezequiel | D21: IVA Responsable Inscripto | E21: 20272865869 | F21: 253100 | G21: 0
A22: 27/09/2024 | B22: FA-A 0002-00000816 | C22: Di Feo, Martin Ezequiel | D22: IVA Responsable Inscripto | E22: 20272865869 | F22: 9800 | G22: 0
A23: 27/09/2024 | B23: FA-A 0002-00000819 | C23: Di Feo, Martin Ezequiel | D23: IVA Responsable Inscripto | E23: 20272865869 | F23: 105000 | G23: 0
A24: 30/09/2024 | B24: FA-A 0002-00000814 | C24: Di Feo, Martin Ezequiel | D24: IVA Responsable Inscripto | E24: 20272865869 | F24: 149150 | G24: 0
A25: 05/09/2024 | B25: 760 | C25: DI FEO MARTIN EZEQUIEL | E25: 20272865869 | F25: 84450 | G25: 0
A26: 12/09/2024 | B26: 778 | C26: DI FEO MARTIN EZEQUIEL | E26: 20272865869 | F26: 128100 | G26: 0
A27: 13/09/2024 | B27: 783 | C27: DI FEO MARTIN EZEQUIEL | E27: 20272865869 | F27: 9950 | G27: 0
A28: 19/09/2024 | B28: 796 | C28: DI FEO MARTIN EZEQUIEL | E28: 20272865869 | F28: 253100 | G28: 0
A29: 26/09/2024 | B29: 814 | C29: DI FEO MARTIN EZEQUIEL | E29: 20272865869 | F29: 149150 | G29: 0
A30: 27/09/2024 | B30: 816 | C30: DI FEO MARTIN EZEQUIEL | E30: 20272865869 | F30: 9800 | G30: 0
A31: 27/09/2024 | B31: 819 | C31: DI FEO MARTIN EZEQUIEL | E31: 20272865869 | F31: 105000 | G31: 0
A32: 04/09/2024 | B32: FA-A 0007-00003241 | C32: Furlanetto, Martin | D32: IVA Responsable Inscripto | E32: 20284183534 | F32: 4545.5 | G32: 0
A33: 26/09/2024 | B33: TF-A0007-00003292 | C33: Furlanetto, Martin | D33: IVA Responsable Inscripto | E33: 20284183534 | F33: 9504.13 | G33: 0
A34: 04/09/2024 | B34: 3241 | C34: FURLANETTO MARTIN | E34: 20284183534 | F34: 4545.5 | G34: 0
A35: 26/09/2024 | B35: 3292 | C35: FURLANETTO MARTIN | E35: 20284183534 | F35: 9504.13 | G35: 0
A36: 12/09/2024 | B36: FA-A 0004-00038394 | C36: Ledesma, Emiliano Ruben | D36: IVA Responsable Inscripto | E36: 20289111329 | F36: 585730.8 | G36: 0
A37: 12/09/2024 | B37: 38394 | C37: LEDESMA EMILIANO RUBEN | E37: 20289111329 | F37: 585730.8 | G37: 0
A38: 20/09/2024 | B38: FA-A 0004-00000136 | C38: Villalba, Miguel Angel | D38: IVA Responsable Inscripto | E38: 20317488476 | F38: 1870000 | G38: 0
A39: 25/09/2024 | B39: FA-A 0004-00000137 | C39: Villalba, Miguel Angel | D39: IVA Responsable Inscripto | E39: 20317488476 | F39: 105000 | G39: 0
A40: 20/09/2024 | B40: 136 | C40: VILLALBA MIGUEL ANGEL | E40: 20317488476 | F40: 1870000 | G40: 0
A41: 25/09/2024 | B41: 137 | C41: VILLALBA MIGUEL ANGEL | E41: 20317488476 | F41: 105000 | G41: 0
A42: 13/09/2024 | B42: NC-A 0003-00000017 | C42: Nardomarino, Ezequiel Eduardo | D42: IVA Responsable Inscripto | E42: 20334976433 | F42: -188330 | G42: 0
...

Sheet Hoja1
A2: Mis Comprobantes Recibidos - CUIT 30710473168
A3: Fecha | B3: Tipo | C3: Punto de Venta | D3: Número Desde | E3: Número Hasta | F3: Cód. Autorización | G3: Tipo Doc. Emisor | H3: Nro. Doc. Emisor | I3: Denominación Emisor | J3: Tipo Cambio | K3: Moneda | L3: Imp. Neto Gravado | M3: Imp. Neto No Gravado | N3: Imp. Op. Exentas | O3: Otros Tributos | P3: IVA | Q3: Imp. Total
A4: 02/12/2024 | B4: 1 - Factura A | C4: 500 | D4: 1655637 | F4: 74487074766855 | G4: CUIT | H4: 30654118767 | I4: SOLUCIONES MULTIMEDIA S A | J4: 1 | K4: $ | L4: 105092.93 | M4: 0 | N4: 0 | O4: 5239.3 | P4: 22069.52 | Q4: 132401.75
A5: 02/12/2024 | B5: 1 - Factura A | C5: 6 | D5: 55227 | F5: 74498346789752 | G5: CUIT | H5: 30710177658 | I5: TARGET MEDICAL S.A. | J5: 1 | K5: $ | L5: 412110 | M5: 0 | N5: 0 | O5: 0 | P5: 86543.1 | Q5: 498653.1
A6: 02/12/2024 | B6: 1 - Factura A | C6: 4 | D6: 38976 | F6: 74499359858810 | G6: CUIT | H6: 20289111329 | I6: LEDESMA EMILIANO RUBEN | J6: 1 | K6: $ | L6: 2174566 | M6: 0 | N6: 0 | O6: 0 | P6: 456658.86 | Q6: 2631224.9
A7: 02/12/2024 | B7: 1 - Factura A | C7: 6 | D7: 55223 | F7: 74498341856485 | G7: CUIT | H7: 30710177658 | I7: TARGET MEDICAL S.A. | J7: 1 | K7: $ | L7: 3760920 | M7: 0 | N7: 0 | O7: 150436.8 | P7: 789793.2 | Q7: 4701150
A8: 02/12/2024 | B8: 1 - Factura A | C8: 711 | D8: 6455819 | F8: 34489322171051 | G8: CUIT | H8: 30677237119 | I8: AUTOPISTAS DEL SOL S A | J8: 1 | K8: $ | L8: 11433.18 | M8: 0 | N8: 343 | O8: 457.33 | P8: 2400.93 | Q8: 14634.44
A9: 02/12/2024 | B9: 1 - Factura A | C9: 101 | D9: 8845 | F9: 74499306271092 | G9: CUIT | H9: 33711430879 | I9: BALANZE S.A. | J9: 1 | K9: $ | L9: 1328291 | M9: 0 | N9: 0 | O9: 0 | P9: 278941.11 | Q9: 1607232.1
A10: 02/12/2024 | B10: 1 - Factura A | C10: 629 | D10: 5656259 | F10: 34483250539705 | G10: CUIT | H10: 30663498513 | I10: GRUPO CONCESIONARIO DEL OESTE SA | J10: 1 | K10: $ | L10: 558.01 | M10: 0 | N10: 0 | O10: 22.32 | P10: 117.18 | Q10: 697.51
A11: 02/12/2024 | B11: 1 - Factura A | C11: 3051 | D11: 844548 | F11: 74497516477337 | G11: CUIT | H11: 30678814357 | I11: TELEFONICA MOVILES ARGENTINA SOCIEDAD ANONIMA | J11: 1 | K11: $ | L11: 53954 | M11: 0 | N11: 0 | O11: 6730.02 | P11: 14567.58 | Q11: 75251.6
A12: 02/12/2024 | B12: 11 - Factura C | C12: 3 | D12: 905 | F12: 74493324806048 | G12: CUIT | H12: 20086277523 | I12: BOTINDARI JUAN CARLOS | J12: 1 | K12: $ | O12: 0 | Q12: 275500
A13: 02/12/2024 | B13: 11 - Factura C | C13: 2 | D13: 319 | F13: 74498730251438 | G13: CUIT | H13: 27265832178 | I13: BLASCO MARIA GUADALUPE | J13: 1 | K13: $ | O13: 0 | Q13: 3200000
A14: 03/12/2024 | B14: 1 - Factura A | C14: 1 | D14: 109430 | F14: 74499429713404 | G14: CUIT | H14: 30714864269 | I14: CONTABILIUM S.A. S. A. | J14: 1 | K14: $ | L14: 139127 | M14: 0 | N14: 0 | O14: 0 | P14: 29216.67 | Q14: 168343.67
A15: 03/12/2024 | B15: 1 - Factura A | C15: 1 | D15: 5589 | F15: 74491435507330 | G15: CUIT | H15: 30715141201 | I15: REHAB S.R.L. | J15: 1 | K15: $ | L15: 139185 | M15: 0 | N15: 0 | O15: 0 | P15: 29228.85 | Q15: 168413.85
A16: 03/12/2024 | B16: 1 - Factura A | C16: 4 | D16: 38981 | F16: 74499427712370 | G16: CUIT | H16: 20289111329 | I16: LEDESMA EMILIANO RUBEN | J16: 1 | K16: $ | L16: 727465.05 | M16: 0 | N16: 0 | O16: 0 | P16: 152767.66 | Q16: 880232.71
A17: 03/12/2024 | B17: 1 - Factura A | C17: 5 | D17: 161604 | F17: 74493439495197 | G17: CUIT | H17: 30598960093 | I17: SILVESTRIN FABRIS SOC RESP LTDA | J17: 1 | K17: $ | L17: 2554513.5 | M17: 0 | N17: 0 | O17: 102180.54 | P17: 536447.84 | Q17: 3193141.9
A18: 03/12/2024 | B18: 1 - Factura A | C18: 2 | D18: 223 | F18: 74492464692349 | G18: CUIT | H18: 30605344352 | I18: CONSORCIO BARTOLOME MITRE 2466 | J18: 1 | K18: $ | L18: 834000 | M18: 0 | N18: 0 | O18: 0 | P18: 175140 | Q18: 1009140
A19: 03/12/2024 | B19: 11 - Factura C | C19: 3 | D19: 61 | F19: 74499463827512 | G19: CUIT | H19: 23163457369 | I19: ASTORGA JORGE DANIEL | J19: 1 | K19: $ | O19: 0 | Q19: 450000
A20: 03/12/2024 | B20: 11 - Factura C | C20: 1 | D20: 162 | F20: 74490436597806 | G20: CUIT | H20: 27338342840 | I20: CANCINO PAMELA RITA | J20: 1 | K20: $ | O20: 0 | Q20: 130800
A21: 04/12/2024 | B21: 1 - Factura A | C21: 4 | D21: 20038 | F21: 74493616266425 | G21: CUIT | H21: 30504854023 | I21: NYLTEF SAICF | J21: 1 | K21: $ | L21: 72100 | M21: 0 | N21: 0 | O21: 2884 | P21: 15141 | Q21: 90125
A22: 04/12/2024 | B22: 1 - Factura A | C22: 7 | D22: 26242 | F22: 74497593058098 | G22: CUIT | H22: 30710951647 | I22: SOLUCIONES TECNOLOGICAS INTEGRALES SRL | J22: 1 | K22: $ | L22: 156102.4 | M22: 0 | N22: 0 | O22: 7805.12 | P22: 16390.75 | Q22: 180298.27
A23: 04/12/2024 | B23: 1 - Factura A | C23: 1 | D23: 666828 | F23: 74499002078073 | G23: CUIT | H23: 33716307749 | I23: VERISURE ARGENTINA MONITOREO DE ALARMAS SA | J23: 1 | K23: $ | L23: 41128 | M23: 0 | N23: 0 | O23: 1645.12 | P23: 8636.88 | Q23: 51410
A24: 04/12/2024 | B24: 1 - Factura A | C24: 4 | D24: 145 | F24: 74496651400602 | G24: CUIT | H24: 20317488476 | I24: VILLALBA MIGUEL ANGEL | J24: 1 | K24: $ | L24: 1155000 | M24: 0 | N24: 0 | O24: 0 | P24: 242550 | Q24: 1397550
A25: 04/12/2024 | B25: 3 - Nota de Crédito A | C25: 4 | D25: 3139 | F25: 74499588156578 | G25: CUIT | H25: 20289111329 | I25: LEDESMA EMILIANO RUBEN | J25: 1 | K25: $ | L25: 727465.05 | M25: 0 | N25: 0 | O25: 0 | P25: 152767.66 | Q25: 880232.71
A26: 05/12/2024 | B26: 1 - Factura A | C26: 7 | D26: 19690 | F26: 74498787252978 | G26: CUIT | H26: 30709214078 | I26: REHAVITA S.A. | J26: 1 | K26: $ | L26: 192492 | M26: 0 | N26: 0 | O26: 0 | P26: 40423.32 | Q26: 232915.32
A27: 05/12/2024 | B27: 1 - Factura A | C27: 2 | D27: 963 | F27: 74499785646902 | G27: CUIT | H27: 20272865869 | I27: DI FEO MARTIN EZEQUIEL | J27: 1 | K27: $ | L27: 93200.04 | M27: 0 | N27: 0 | O27: 0 | P27: 19572.01 | Q27: 112772.05
A28: 05/12/2024 | B28: 1 - Factura A | C28: 2 | D28: 26398 | F28: 74498783507894 | G28: CUIT | H28: 30642604488 | I28: HORIZONTE TRANSPORTES S R L | J28: 1 | K28: $ | L28: 67400 | M28: 0 | N28: 0 | O28: 0 | P28: 14154 | Q28: 81554
A29: 05/12/2024 | B29: 1 - Factura A | C29: 120 | D29: 5406 | F29: 74495750310742 | G29: CUIT | H29: 30587197215 | I29: PANATEL SOCIEDAD ANONIMA | J29: 1 | K29: $ | L29: 95041.32 | M29: 0 | N29: 0 | O29: 3801.65 | P29: 19958.68 | Q29: 118801.65
A30: 05/12/2024 | B30: 1 - Factura A | C30: 2 | D30: 11064 | F30: 74492783832650 | G30: CUIT | H30: 30714331082 | I30: ORTOPEDIA CASA ESCALADA S.R.L. | J30: 1 | K30: $ | L30: 81488.51 | M30: 0 | N30: 0 | O30: 0 | P30: 17112.59 | Q30: 98601.1
A31: 05/12/2024 | B31: 3 - Nota de Crédito A | C31: 7 | D31: 1322 | F31: 74498786515767 | G31: CUIT | H31: 30709214078 | I31: REHAVITA S.A. | J31: 1 | K31: $ | L31: 59820 | M31: 0 | N31: 0 | O31: 0 | P31: 12562.2 | Q31: 72382.2
A32: 05/12/2024 | B32: 11 - Factura C | C32: 1 | D32: 10 | F32: 74493727645078 | G32: CUIT | H32: 27443612713 | I32: MIGOYA MORIONDO SOFIA | J32: 1 | K32: $ | O32: 0 | Q32: 750000
A33: 06/12/2024 | B33: 1 - Factura A | C33: 2189 | D33: 81012 | F33: 74496980568402 | G33: CUIT | H33: 30548083156 | I33: COTO CENTRO INTEGRAL DE COMERCIALIZACION SOCIEDAD ANONIMA | J33: 1 | K33: $ | L33: 7639.42 | M33: 0 | N33: 0 | O33: 534.76 | P33: 1604.28 | Q33: 9778.46
A34: 06/12/2024 | B34: 1 - Factura A | C34: 5 | D34: 2261 | F34: 74498875569162 | G34: CUIT | H34: 20242126158 | I34: IALLONARDO SERGIO ALEJANDRO | J34: 1 | K34: $ | L34: 16470 | M34: 0 | N34: 0 | O34: 0 | P34: 3458.7 | Q34: 19928.7
A35: 06/12/2024 | B35: 1 - Factura A | C35: 7 | D35: 19693 | F35: 74498883622074 | G35: CUIT | H35: 30709214078 | I35: REHAVITA S.A. | J35: 1 | K35: $ | L35: 151800 | M35: 0 | N35: 0 | O35: 0 | P35: 15939 | Q35: 167739
A36: 06/12/2024 | B36: 1 - Factura A | C36: 3 | D36: 197 | F36: 74503230479910 | G36: CUIT | H36: 20334976433 | I36: NARDOMARINO EZEQUIEL EDUARDO | J36: 1 | K36: $ | L36: 947800 | M36: 0 | N36: 0 | O36: 0 | P36: 199038 | Q36: 1146838
A37: 06/12/2024 | B37: 11 - Factura C | C37: 2 | D37: 1 | F37: 74491890516333 | G37: CUIT | H37: 27344304551 | I37: BOCCACCI MARIA FLORENCIA | J37: 1 | K37: $ | O37: 0
A38: 08/12/2024 | B38: 1 - Factura A | C38: 5015 | D38: 673036 | F38: 74494155013792 | G38: CUIT | H38: 30574876474 | I38: AUTOPISTAS URBANAS S A | J38: 1 | K38: $ | L38: 3329.43 | M38: 0 | N38: 0 | O38: 432.82 | P38: 699.17 | Q38: 4461.42
A39: 09/12/2024 | B39: 1 - Factura A | C39: 12 | D39: 40989 | F39: 74504258923570 | G39: CUIT | H39: 30526582884 | I39: EXPRESO MAR DEL PLATA SOCIEDAD ANONIMA | J39: 1 | K39: $ | L39: 96958.68 | M39: 0 | N39: 0 | O39: 0 | P39: 20361.32 | Q39: 117320
A40: 09/12/2024 | B40: 1 - Factura A | C40: 17 | D40: 11167 | F40: 74500215673228 | G40: CUIT | H40: 30661143610 | I40: ORTOPEDIA BERNAT SRL | J40: 1 | K40: $ | L40: 1328690 | M40: 0 | N40: 0 | O40: 53147.6 | P40: 279024.9 | Q40: 1660862.5
A41: 09/12/2024 | B41: 1 - Factura A | C41: 4 | D41: 39047 | F41: 74509213670602 | G41: CUIT | H41: 20289111329 | I41: LEDESMA EMILIANO RUBEN | J41: 1 | K41: $ | L41: 585348.09 | M41: 0 | N41: 0 | O41: 0 | P41: 122923.1 | Q41: 708271.19
...

Sheet Hoja2

Sheet Comp No Recibidos
A6: Fecha | B6: Tipo | C6: Punto de Venta | D6: NOMBRE | E6: FC Nº | F6: Cód. Autorización | G6: Tipo Doc. Emisor | H6: Nro. Doc. Emisor | I6: Denominación Emisor | J6: Tipo Cambio | K6: Moneda | L6: Imp. Neto Gravado | M6: Imp. Neto No Gravado | N6: Imp. Op. Exentas | O6: Otros Tributos | P6: IVA | Q6: Imp. Total
A7: 01/03/2025 | B7: 1 - Factura A | C7: 1 | D7: CONTABILIUM S.A. S. A. | E7: 116458 | F7: 75099180081192 | G7: CUIT | H7: 30714864269 | I7: CONTABILIUM S.A. S. A. | J7: 1 | K7: $ | L7: 164170 | M7: 0 | N7: 0 | O7: 0 | P7: 34475.7 | Q7: 198645.7
A8: 15/03/2025 | B8: 1 - Factura A | C8: 50 | D8: AUTOPISTAS DE BUENOS AIRES (AUBASA) SA S. A. | E8: 4203840 | F8: 75116065667505 | G8: CUIT | H8: 30714112836 | I8: AUTOPISTAS DE BUENOS AIRES (AUBASA) SA S. A. | J8: 1 | K8: $ | L8: 1322.14 | M8: 0 | N8: 0 | O8: 0 | P8: 277.65 | Q8: 1599.79
A9: 31/03/2025 | B9: 1 - Factura A | C9: 50 | D9: AUTOPISTAS DE BUENOS AIRES (AUBASA) SA S. A. | E9: 4240541 | F9: 75146078835131 | G9: CUIT | H9: 30714112836 | I9: AUTOPISTAS DE BUENOS AIRES (AUBASA) SA S. A. | J9: 1 | K9: $ | L9: 4888.16 | M9: 0 | N9: 0 | O9: 146.64 | P9: 1026.52 | Q9: 6061.32
A10: 02/03/2025 | B10: 1 - Factura A | C10: 3051 | D10: TELEFONICA MOVILES ARGENTINA SOCIEDAD ANONIMA | E10: 885516 | F10: 75097440339951 | G10: CUIT | H10: 30678814357 | I10: TELEFONICA MOVILES ARGENTINA SOCIEDAD ANONIMA | J10: 1 | K10: $ | L10: 65394 | M10: 0 | N10: 0 | O10: 8157 | P10: 17656.38 | Q10: 91207.38
A11: 03/03/2025 | B11: 1 - Factura A | C11: 500 | D11: SOLUCIONES MULTIMEDIA S A | E11: 1694216 | F11: 75097875516122 | G11: CUIT | H11: 30654118767 | I11: SOLUCIONES MULTIMEDIA S A | J11: 1 | K11: $ | L11: 117349.04 | M11: 0 | N11: 0 | O11: 5851.32 | P11: 24643.3 | Q11: 147843.66
A12: 01/03/2025 | B12: 1 - Factura A | C12: 711 | D12: AUTOPISTAS DEL SOL S A | E12: 6809656 | F12: 35089654428747 | G12: CUIT | H12: 30677237119 | I12: AUTOPISTAS DEL SOL S A | J12: 1 | K12: $ | L12: 1155.52 | M12: 0 | N12: 0 | O12: 46.22 | P12: 242.66 | Q12: 1444.4
A13: 03/03/2025 | B13: 11 - Factura C | C13: 2 | D13: BLASCO MARIA GUADALUPE | E13: 338 | F13: 75108573083577 | G13: CUIT | H13: 27265832178 | I13: BLASCO MARIA GUADALUPE | J13: 1 | K13: $ | O13: 0 | Q13: 3200000
A14: 04/03/2025 | B14: 1 - Factura A | C14: 1 | D14: VERISURE ARGENTINA MONITOREO DE ALARMAS SA | E14: 753841 | F14: 75109679292275 | G14: CUIT | H14: 33716307749 | I14: VERISURE ARGENTINA MONITOREO DE ALARMAS SA | J14: 1 | K14: $ | L14: 49498.9 | M14: 0 | N14: 0 | O14: 1979.96 | P14: 10394.77 | Q14: 61873.63
A15: 05/03/2025 | B15: 1 - Factura A | C15: 3 | D15: VELEZ ALEJANDRO MARCELO | E15: 30 | F15: 75102640981500 | G15: CUIT | H15: 20216164262 | I15: VELEZ ALEJANDRO MARCELO | J15: 1 | K15: $ | L15: 1166562 | M15: 0 | N15: 0 | O15: 0 | P15: 244978.02 | Q15: 1411540
A16: 05/03/2025 | B16: 11 - Factura C | C16: 1 | D16: DRUETTA ANDREA MARIEL | E16: 78 | F16: 75104661596492 | G16: CUIT | H16: 23281233084 | I16: DRUETTA ANDREA MARIEL | J16: 1 | K16: $ | O16: 0 | Q16: 270000
A17: 05/03/2025 | B17: 11 - Factura C | C17: 3 | D17: BOTINDARI JUAN CARLOS | E17: 938 | F17: 75103578933928 | G17: CUIT | H17: 20086277523 | I17: BOTINDARI JUAN CARLOS | J17: 1 | K17: $ | O17: 0 | Q17: 275500
A18: 06/03/2025 | B18: 1 - Factura A | C18: 2 | D18: DI FEO MARTIN EZEQUIEL | E18: 1132 | F18: 75109793481045 | G18: CUIT | H18: 20272865869 | I18: DI FEO MARTIN EZEQUIEL | J18: 1 | K18: $ | L18: 155850 | M18: 0 | N18: 0 | O18: 0 | P18: 32728.5 | Q18: 188578.5
A19: 15/03/2025 | B19: 1 - Factura A | C19: 5009 | D19: AUTOPISTAS URBANAS S A | E19: 1272797 | F19: 75114998298974 | G19: CUIT | H19: 30574876474 | I19: AUTOPISTAS URBANAS S A | J19: 1 | K19: $ | L19: 1820.64 | M19: 0 | N19: 0 | O19: 182.06 | P19: 382.33 | Q19: 2385.03
A20: 31/03/2025 | B20: 1 - Factura A | C20: 5009 | D20: AUTOPISTAS URBANAS S A | E20: 1316261 | F20: 75144039185661 | G20: CUIT | H20: 30574876474 | I20: AUTOPISTAS URBANAS S A | J20: 1 | K20: $ | L20: 6798.01 | M20: 0 | N20: 0 | O20: 883.74 | P20: 1427.57 | Q20: 9109.32
A21: 07/03/2025 | B21: 1 - Factura A | C21: 2 | D21: DI FEO MARTIN EZEQUIEL | E21: 1133 | F21: 75109874477776 | G21: CUIT | H21: 20272865869 | I21: DI FEO MARTIN EZEQUIEL | J21: 1 | K21: $ | L21: 39000 | M21: 0 | N21: 0 | O21: 0 | P21: 8190 | Q21: 47190
A22: 07/03/2025 | B22: 1 - Factura A | C22: 2 | D22: DI FEO MARTIN EZEQUIEL | E22: 1135 | F22: 75109882194137 | G22: CUIT | H22: 20272865869 | I22: DI FEO MARTIN EZEQUIEL | J22: 1 | K22: $ | L22: 11006.61 | M22: 0 | N22: 0 | O22: 0 | P22: 2311.39 | Q22: 13318
A23: 07/03/2025 | B23: 1 - Factura A | C23: 5 | D23: SILVESTRIN FABRIS SOC RESP LTDA | E23: 164287 | F23: 75103948936244 | G23: CUIT | H23: 30598960093 | I23: SILVESTRIN FABRIS SOC RESP LTDA | J23: 1 | K23: $ | L23: 2026728 | M23: 0 | N23: 0 | O23: 81069.12 | P23: 425612.89 | Q23: 2533410
A24: 07/03/2025 | B24: 1 - Factura A | C24: 7 | D24: SOUSA ALDERETE ALEJANDRA MABEL | E24: 27 | F24: 75103887647271 | G24: CUIT | H24: 27325223273 | I24: SOUSA ALDERETE ALEJANDRA MABEL | J24: 1 | K24: $ | L24: 1650000 | M24: 0 | N24: 0 | O24: 0 | P24: 346500 | Q24: 1996500
A25: 07/03/2025 | B25: 1 - Factura A | C25: 2 | D25: 46 SPEED S.A. | E25: 487 | F25: 75106908089918 | G25: CUIT | H25: 30711610096 | I25: 46 SPEED S.A. | J25: 1 | K25: $ | L25: 698000 | M25: 0 | N25: 0 | O25: 0 | P25: 146580 | Q25: 844580
A26: 07/03/2025 | B26: 11 - Factura C | C26: 2 | D26: RIVERO GABRIELA ROCIO | E26: 123 | F26: 75108978118375 | G26: CUIT | H26: 27315710508 | I26: RIVERO GABRIELA ROCIO | J26: 1 | K26: $ | O26: 0 | Q26: 43200
A27: 08/03/2025 | B27: 1 - Factura A | C27: 5015 | D27: AUTOPISTAS URBANAS S A | E27: 778963 | F27: 75104071087297 | G27: CUIT | H27: 30574876474 | I27: AUTOPISTAS URBANAS S A | J27: 1 | K27: $ | L27: 13213.87 | M27: 0 | N27: 0 | O27: 1717.79 | P27: 2774.9 | Q27: 17706.56
A28: 31/03/2025 | B28: 1 - Factura A | C28: 5015 | D28: AUTOPISTAS URBANAS S A | E28: 801800 | F28: 75144032396028 | G28: CUIT | H28: 30574876474 | I28: AUTOPISTAS URBANAS S A | J28: 1 | K28: $ | L28: 33681.65 | M28: 0 | N28: 0 | O28: 4378.57 | P28: 7073.11 | Q28: 45133.33
A29: 09/03/2025 | B29: 1 - Factura A | C29: 3101 | D29: TELEFONICA MOVILES ARGENTINA SOCIEDAD ANONIMA | E29: 278864 | F29: 75107271721600 | G29: CUIT | H29: 30678814357 | I29: TELEFONICA MOVILES ARGENTINA SOCIEDAD ANONIMA | J29: 1 | K29: $ | L29: 82083.6 | M29: 0 | N29: 0 | O29: 5745.85 | P29: 22162.57 | Q29: 109992.02
A30: 10/03/2025 | B30: 1 - Factura A | C30: 2002 | D30: MERCADO TOTAL SAS | E30: 79578 | F30: 75105247782031 | G30: CUIT | H30: 30716425165 | I30: MERCADO TOTAL SAS | J30: 1 | K30: $ | L30: 4796.38 | M30: 0 | N30: 0 | O30: 0 | P30: 503.62 | Q30: 5300
A31: 11/03/2025 | B31: 1 - Factura A | C31: 7 | D31: SUPERFOTO S R L | E31: 268472 | F31: 75103434538841 | G31: CUIT | H31: 30708395443 | I31: SUPERFOTO S R L | J31: 1 | K31: $ | L31: 132230.58 | M31: 0 | N31: 0 | O31: 0 | P31: 27768.42 | Q31: 159999
A32: 11/03/2025 | B32: 1 - Factura A | C32: 2 | D32: ORTOPEDIA CASA ESCALADA S.R.L. | E32: 11604 | F32: 75102380894031 | G32: CUIT | H32: 30714331082 | I32: ORTOPEDIA CASA ESCALADA S.R.L. | J32: 1 | K32: $ | L32: 423275.07 | M32: 0 | N32: 0 | O32: 0 | P32: 88887.76 | Q32: 512162.83
A33: 11/03/2025 | B33: 1 - Factura A | C33: 120 | D33: PANATEL SOCIEDAD ANONIMA | E33: 5534 | F33: 75105438448648 | G33: CUIT | H33: 30587197215 | I33: PANATEL SOCIEDAD ANONIMA | J33: 1 | K33: $ | L33: 95041.32 | M33: 0 | N33: 0 | O33: 3801.65 | P33: 19958.68 | Q33: 118801.65
A34: 11/03/2025 | B34: 11 - Factura C | C34: 1 | D34: CHANCO VILLAVICENCIO ERNESTO ANTONIO | E34: 44 | F34: 75107404164811 | G34: CUIT | H34: 20190742297 | I34: CHANCO VILLAVICENCIO ERNESTO ANTONIO | J34: 1 | K34: $ | O34: 0 | Q34: 150000
A35: 11/03/2025 | B35: 11 - Factura C | C35: 1 | D35: MIGOYA MORIONDO SOFIA | E35: 12 | F35: 75103359390490 | G35: CUIT | H35: 27443612713 | I35: MIGOYA MORIONDO SOFIA | J35: 1 | K35: $ | O35: 0 | Q35: 850000
A36: 12/03/2025 | B36: 1 - Factura A | C36: 4 | D36: LEDESMA EMILIANO RUBEN | E36: 39572 | F36: 75119506172639 | G36: CUIT | H36: 20289111329 | I36: LEDESMA EMILIANO RUBEN | J36: 1 | K36: $ | L36: 585348.09 | M36: 0 | N36: 0 | O36: 0 | P36: 122923.1 | Q36: 708271.19
A37: 12/03/2025 | B37: 1 - Factura A | C37: 6 | D37: SALUDTEX SA | E37: 89635 | F37: 75114529251983 | G37: CUIT | H37: 30711553564 | I37: SALUDTEX SA | J37: 1 | K37: $ | L37: 846283.75 | M37: 0 | N37: 0 | O37: 0 | P37: 177719.59 | Q37: 1024003.3
A38: 12/03/2025 | B38: 1 - Factura A | C38: 4 | D38: LEDESMA EMILIANO RUBEN | E38: 39574 | F38: 75119529929350 | G38: CUIT | H38: 20289111329 | I38: LEDESMA EMILIANO RUBEN | J38: 1 | K38: $ | L38: 292865.41 | M38: 0 | N38: 0 | O38: 0 | P38: 61501.73 | Q38: 354367.14
A39: 12/03/2025 | B39: 11 - Factura C | C39: 3 | D39: KLAINER ABEL JAVIER | E39: 2395 | F39: 75111535985217 | G39: CUIT | H39: 20182999661 | I39: KLAINER ABEL JAVIER | J39: 1 | K39: $ | O39: 0 | Q39: 57000
A40: 12/03/2025 | B40: 11 - Factura C | C40: 1 | D40: CANCINO PAMELA RITA | E40: 167 | F40: 75110530978675 | G40: CUIT | H40: 27338342840 | I40: CANCINO PAMELA RITA | J40: 1 | K40: $ | O40: 0 | Q40: 652800
A41: 13/03/2025 | B41: 1 - Factura A | C41: 3 | D41: LIPROT S.R.L. | E41: 48479 | F41: 75118687675469 | G41: CUIT | H41: 30711454388 | I41: LIPROT S.R.L. | J41: 1 | K41: $ | L41: 213732 | M41: 0 | N41: 0 | O41: 0 | P41: 44883.72 | Q41: 258615.72
A42: 13/03/2025 | B42: 1 - Factura A | C42: 3 | D42: LIPROT S.R.L. | E42: 48480 | F42: 75118687920143 | G42: CUIT | H42: 30711454388 | I42: LIPROT S.R.L. | J42: 1 | K42: $ | L42: 137543 | M42: 0 | N42: 0 | O42: 0 | P42: 28884.03 | Q42: 166427.03
A43: 13/03/2025 | B43: 1 - Factura A | C43: 2 | D43: DI FEO MARTIN EZEQUIEL | E43: 1151 | F43: 75119693479565 | G43: CUIT | H43: 20272865869 | I43: DI FEO MARTIN EZEQUIEL | J43: 1 | K43: $ | L43: 87550 | M43: 0 | N43: 0 | O43: 0 | P43: 18385.5 | Q43: 105935.5
A44: 13/03/2025 | B44: 1 - Factura A | C44: 1000 | D44: ITPROUSER S.A. | E44: 215377 | F44: 75113683028005 | G44: CUIT | H44: 30715123483 | I44: ITPROUSER S.A. | J44: 1 | K44: $ | L44: 15170.24 | M44: 0 | N44: 0 | O44: 310.84 | P44: 3185.75 | Q44: 18666.83
A45: 13/03/2025 | B45: 1 - Factura A | C45: 5 | D45: PRADO MARISOL | E45: 1485 | F45: 75115688543714 | G45: CUIT | H45: 27265302225 | I45: PRADO MARISOL | J45: 1 | K45: $ | L45: 800000 | M45: 0 | N45: 0 | O45: 0 | P45: 168000 | Q45: 968000
...

Sheet Hoja5
A2: Fecha | B2: Tipo | C2: Punto de Venta | D2: FACTURA | E2: Número Hasta | F2: Cód. Autorización | G2: Tipo Doc. Emisor | H2: Nro. Doc. Emisor | I2: Denominación Emisor | J2: Tipo Cambio | K2: Moneda | L2: Imp. Neto Gravado | M2: Imp. Neto No Gravado | N2: Imp. Op. Exentas | O2: Otros Tributos | P2: IVA | Q2: Imp. Total
A3: 14/04/2025 | B3: 1 - Factura A | C3: 3 | D3: 40 | F3: 75155469337258 | G3: CUIT | H3: 30716651165 | I3: AMTRASK | J3: 1 | K3: $ | L3: 132230.58 | M3: 0 | N3: 0 | O3: 0 | P3: 27768.42 | Q3: 159999
A4: 30/04/2025 | B4: 1 - Factura A | C4: 50 | D4: 4308216 | F4: 75186472119221 | G4: CUIT | H4: 30714112836 | I4: AUTOPISTAS DE BUENOS AIRES (AUBASA) SA S. A. | J4: 1 | K4: $ | L4: 8566.66 | M4: 0 | N4: 0 | O4: 257 | P4: 1799 | Q4: 10622.66
A5: 01/04/2025 | B5: 1 - Factura A | C5: 711 | D5: 6930599 | F5: 35139646397105 | G5: CUIT | H5: 30677237119 | I5: AUTOPISTAS DEL SOL S A | J5: 1 | K5: $ | L5: 9359.78 | M5: 0 | N5: 280.79 | O5: 374.39 | P5: 1965.56 | Q5: 11980.52
A6: 14/04/2025 | B6: 1 - Factura A | C6: 5009 | D6: 1345646 | F6: 75154574924153 | G6: CUIT | H6: 30574876474 | I6: AUTOPISTAS URBANAS S A | J6: 1 | K6: $ | L6: 3801.48 | M6: 0 | N6: 0 | O6: 494.18 | P6: 798.31 | Q6: 5093.97
A7: 30/04/2025 | B7: 1 - Factura A | C7: 5015 | D7: 832362 | F7: 75184523307368 | G7: CUIT | H7: 30574876474 | I7: AUTOPISTAS URBANAS S A | J7: 1 | K7: $ | L7: 82310.49 | M7: 0 | N7: 0 | O7: 10700.35 | P7: 17285.14 | Q7: 110295.98
A8: 15/04/2025 | B8: 1 - Factura A | C8: 113 | D8: 4177115 | F8: 75160112855057 | G8: CUIT | H8: 30577207190 | I8: COORDINACION ECOLOGICA AREA METROPOLITANA SOCIEDAD DEL ESTADO | J8: 1 | K8: $ | L8: 3719.01 | M8: 0 | N8: 0 | O8: 111.57 | P8: 780.99 | Q8: 4611.57
A9: 30/04/2025 | B9: 1 - Factura A | C9: 113 | D9: 4205467 | F9: 75180616878598 | G9: CUIT | H9: 30577207190 | I9: COORDINACION ECOLOGICA AREA METROPOLITANA SOCIEDAD DEL ESTADO | J9: 1 | K9: $ | L9: 2479.34 | M9: 0 | N9: 0 | O9: 74.38 | P9: 520.66 | Q9: 3074.38
A10: 07/04/2025 | B10: 1 - Factura A | C10: 700 | D10: 2376670 | F10: 75142734003440 | G10: CUIT | H10: 30715804812 | I10: CORREDORES VIALES SOCIEDAD ANONIMA | J10: 1 | K10: $ | L10: 1871.97 | M10: 0 | N10: 0 | O10: 0 | P10: 393.11 | Q10: 2265.08
A11: 22/04/2025 | B11: 1 - Factura A | C11: 700 | D11: 2405995 | F11: 75162438670778 | G11: CUIT | H11: 30715804812 | I11: CORREDORES VIALES SOCIEDAD ANONIMA | J11: 1 | K11: $ | L11: 1663.97 | M11: 0 | N11: 0 | O11: 0 | P11: 349.43 | Q11: 2013.4
A12: 29/04/2025 | B12: 1 - Factura A | C12: 104 | D12: 8983014 | F12: 75172135088830 | G12: CUIT | H12: 30715804812 | I12: CORREDORES VIALES SOCIEDAD ANONIMA | J12: 1 | K12: $ | L12: 2079.97 | M12: 0 | N12: 0 | O12: 83.2 | P12: 436.79 | Q12: 2599.96
A13: 01/04/2025 | B13: 1 - Factura A | C13: 629 | D13: 5982817 | F13: 35133402229824 | G13: CUIT | H13: 30663498513 | I13: GRUPO CONCESIONARIO DEL OESTE SA | J13: 1 | K13: $ | L13: 5662.12 | M13: 0 | N13: 0 | O13: 226.48 | P13: 1189.05 | Q13: 7077.65
A14: 28/04/2025 | B14: 1 - Factura A | C14: 3 | D14: 8212 | F14: 75178083793588 | G14: CUIT | H14: 30710449658 | I14: PORTUMAT S.R.L. | J14: 1 | K14: $ | L14: 260330.52 | M14: 0 | N14: 0 | O14: 0 | P14: 54669.41 | Q14: 314999.93
... A17: 24/04/2025 | B17: 1 - Factura A | C17: 20 | D17: 40132 | F17: 75177648008643 | G17: CUIT | H17: 30717210847 | I17: STENDY | J17: 1 | K17: $ | L17: 7666.11 | M17: 0 | N17: 0 | O17: 0 | P17: 1609.89 | Q17: 9275.99

Sheet Ventas 07
C2: Totales por Tipo de Comprobante - ARCA
D3: Base | E3: IVA | F3: Otros Imp. | G3: Total Compr.
C4: FACTURAS A | D4: 76792881 | E4: =+D4*0.21 -> 16126505 | G4: =SUBTOTAL(9,D4:F4) -> 92919386
C5: NC A | D5: -3008166.8 | E5: =+D5*0.21 -> -631715.04 | G5: =SUBTOTAL(9,D5:F5) -> -3639881.9
C6: FACTURAS B | D6: 44738970 | E6: =+D6*0.21 -> 9395183.7 | G6: =SUBTOTAL(9,D6:F6) -> 54134154
C7: NC B | D7: -3413336 | E7: =+D7*0.21 -> -716800.56 | G7: =SUBTOTAL(9,D7:F7) -> -4130136.6
C8: ND B | D8: 2572378.7 | E8: =+D8*0.21 -> 540199.53 | G8: =SUBTOTAL(9,D8:F8) -> 3112578.2
D9: =SUBTOTAL(9,D4:D8) -> 1.1768273e+08 | E9: =SUBTOTAL(9,E4:E8) -> 24713373 | F9: 0 | G9: =+E9+D9 -> 1.423961e+08 | H9: =+SUBTOTAL(109,H14:H523) -> 1.1749865e+08
A13: Fecha | B13: Razon Social | C13: Cuit | D13: Provincia | E13: Ciudad | F13: Condicion IVA | G13: Nro Factura | H13: Importe Neto Gravado | I13: Importe No Grav | J13: IVA21 | K13: Total IVA | L13: Total Facturado
A14: 14/07/2025 | B14: ROMINA ELIZABETH TOBAR VALDES | C14: 27288300793 | D14: Buenos Aires | E14: BANFIELD | F14: RI | G14: FCA 0005-00000176 | H14: 55289.26 | I14: 0 | J14: 11610.74 | K14: 11610.74 | L14: 66900
A15: 03/07/2025 | B15: GALENO ARGENTINA SA | C15: 30522428163 | D15: Ciudad de Buenos Aires | E15: SIN IDENTIFICAR | F15: RI | G15: FCA 0006-00000617 | H15: 17797801 | I15: 0 | J15: 3737538.2 | K15: 3737538.2 | L15: 21535339
A16: 08/07/2025 | B16: GALENO ARGENTINA SA | C16: 30522428163 | D16: Ciudad de Buenos Aires | E16: SIN IDENTIFICAR | F16: RI | G16: FCA 0006-00000618 | H16: 5842843 | I16: 0 | J16: 1226997 | K16: 1226997 | L16: 7069840
A17: 10/07/2025 | B17: OBRA SOCIAL UNION PERSONAL DE LA UNION DEL PERSONAL CIVIL DE LA NACION | C17: 30683032227 | D17: Ciudad de Buenos Aires | E17: SIN IDENTIFICAR | F17: RI | G17: FCA 0006-00000619 | H17: 4756361.6 | I17: 0 | J17: 998835.94 | K17: 998835.94 | L17: 5755197.5
A18: 11/07/2025 | B18: GALENO ARGENTINA SA | C18: 30522428163 | D18: Ciudad de Buenos Aires | E18: SIN IDENTIFICAR | F18: RI | G18: FCA 0006-00000620 | H18: 3305669.4 | I18: 0 | J18: 694190.58 | K18: 694190.58 | L18: 3999860
A19: 17/07/2025 | B19: AVALIAN SALUD Y BIENESTAR COOPERATIVA LIMITADA | C19: 30604958640 | D19: Ciudad de Buenos Aires | E19: SIN IDENTIFICAR | F19: RI | G19: FCA 0006-00000621 | H19: 8386363.6 | I19: 0 | J19: 1761136.4 | K19: 1761136.4 | L19: 10147500
A20: 18/07/2025 | B20: GALENO ARGENTINA SA | C20: 30522428163 | D20: Ciudad de Buenos Aires | E20: SIN IDENTIFICAR | F20: RI | G20: FCA 0006-00000622 | H20: 9725534.7 | I20: 0 | J20: 2042362.3 | K20: 2042362.3 | L20: 11767897
A21: 29/07/2025 | B21: GALENO ARGENTINA SA | C21: 30522428163 | D21: Ciudad de Buenos Aires | E21: SIN IDENTIFICAR | F21: RI | G21: FCA 0006-00000623 | H21: 11252777 | I21: 0 | J21: 2363083.1 | K21: 2363083.1 | L21: 13615860
A22: 03/07/2025 | B22: GALENO ARGENTINA SA | C22: 30522428163 | D22: Ciudad de Buenos Aires | E22: SIN IDENTIFICAR | F22: RI | G22: FCA 0007-00002578 | H22: 2605258.3 | I22: 0 | J22: 547104.24 | K22: 547104.24 | L22: 3152362.5
A23: 03/07/2025 | B23: GALENO ARGENTINA SA | C23: 30522428163 | D23: Ciudad de Buenos Aires | E23: SIN IDENTIFICAR | F23: RI | G23: FCA 0007-00002579 | H23: 184088.84 | I23: 0 | J23: 38658.66 | K23: 38658.66 | L23: 222747.5
A24: 03/07/2025 | B24: GALENO ARGENTINA SA | C24: 30522428163 | D24: Ciudad de Buenos Aires | E24: SIN IDENTIFICAR | F24: RI | G24: FCA 0007-00002580 | H24: 1305528.7 | I24: 0 | J24: 274161.03 | K24: 274161.03 | L24: 1579689.7
A25: 04/07/2025 | B25: GALENO ARGENTINA SA | C25: 30522428163 | D25: Ciudad de Buenos Aires | E25: SIN IDENTIFICAR | F25: RI | G25: FCA 0007-00002581 | H25: 1338683.3 | I25: 0 | J25: 281123.49 | K25: 281123.49 | L25: 1619806.8
... A80: 30/07/2025 | B80: OBRA SOCIAL DEL PERSONAL DE LAS TELECOMUNICACIONES DE LA REPUBLICA ARGENTINA | C80: 30608716390 | D80: Ciudad de Buenos Aires | E80: SIN IDENTIFICAR | F80: RI | G80: FCA 0007-00002636 | H80: 133214.05 | I80: 0 | J80: 27974.95 | K80: 27974.95 | L80: 161189
A81: 01/07/2025 | B81: DANELLI RAQUEL | D81: Ciudad de Buenos Aires | E81: SIN IDENTIFICAR | F81: CF | G81: FCB 0003-00002891 | H81: 4328134 | J81: 5206.61 | K81: 5206.61 | L81: 30000
A82: 01/07/2025 | B82: . CONSUMIDOR FINAL ANÓNIMO | C82: 111 | D82: Ciudad de Buenos Aires | E82: SIN IDENTIFICAR | F82: CF | G82: FCB 0005-00013625 | H82: 16528.93 | I82: 0 | J82: 3471.07 | K82: 3471.07 | L82: 20000
A83: 01/07/2025 | B83: RAFAEL OSCAR AZNAR | C83: 20124538999 | D83: Ciudad de Buenos Aires | E83: SIN IDENTIFICAR | F83: CF | G83: FCB 0005-00013626 | H83: 170661.16 | I83: 0 | J83: 35838.84 | K83: 35838.84 | L83: 206500
A84: 01/07/2025 | B84: . CONSUMIDOR FINAL ANÓNIMO | C84: 111 | D84: Ciudad de Buenos Aires | E84: SIN IDENTIFICAR | F84: CF | G84: FCB 0005-00013627 | H84: 29752.07 | I84: 0 | J84: 6247.93 | K84: 6247.93 | L84: 36000
A85: 01/07/2025 | B85: . CONSUMIDOR FINAL ANÓNIMO | C85: 111 | D85: Ciudad de Buenos Aires | E85: SIN IDENTIFICAR | F85: CF | G85: FCB 0005-00013628 | H85: 33471.07 | I85: 0 | J85: 7028.93 | K85: 7028.93 | L85: 40500
A86: 01/07/2025 | B86: . CONSUMIDOR FINAL ANÓNIMO | C86: 111 | D86: Ciudad de Buenos Aires | E86: SIN IDENTIFICAR | F86: CF | G86: FCB 0005-00013629 | H86: 18181.82 | I86: 0 | J86: 3818.18 | K86: 3818.18 | L86: 22000
A87: 01/07/2025 | B87: . CONSUMIDOR FINAL ANÓNIMO | C87: 111 | D87: Ciudad de Buenos Aires | E87: SIN IDENTIFICAR | F87: CF | G87: FCB 0005-00013630 | H87: 16528.93 | I87: 0 | J87: 3471.07 | K87: 3471.07 | L87: 20000
A88: 01/07/2025 | B88: . CONSUMIDOR FINAL ANÓNIMO | C88: 111 | D88: Ciudad de Buenos Aires | E88: SIN IDENTIFICAR | F88: CF | G88: FCB 0005-00013631 | H88: 16528.93 | I88: 0 | J88: 3471.07 | K88: 3471.07 | L88: 20000
A89: 01/07/2025 | B89: . CONSUMIDOR FINAL ANÓNIMO | C89: 111 | D89: Ciudad de Buenos Aires | E89: SIN IDENTIFICAR | F89: CF | G89: FCB 0005-00013632 | H89: 36363.64 | I89: 0 | J89: 7636.36 | K89: 7636.36 | L89: 44000
A90: 01/07/2025 | B90: . CONSUMIDOR FINAL ANÓNIMO | C90: 111 | D90: Ciudad de Buenos Aires | E90: SIN IDENTIFICAR | F90: CF | G90: FCB 0005-00013633 | H90: 15702.48 | I90: 0 | J90: 3297.52 | K90: 3297.52 | L90: 19000
A91: 01/07/2025 | B91: . CONSUMIDOR FINAL ANÓNIMO | C91: 111 | D91: Ciudad de Buenos Aires | E91: SIN IDENTIFICAR | F91: CF | G91: FCB 0005-00013634 | H91: 20661.16 | I91: 0 | J91: 4338.84 | K91: 4338.84 | L91: 25000
A92: 01/07/2025 | B92: . CONSUMIDOR FINAL ANÓNIMO | C92: 111 | D92: Ciudad de Buenos Aires | E92: SIN IDENTIFICAR | F92: CF | G92: FCB 0005-00013635 | H92: 24793.39 | I92: 0 | J92: 5206.61 | K92: 5206.61 | L92: 30000
A93: 01/07/2025 | B93: . CONSUMIDOR FINAL ANÓNIMO | C93: 111 | D93: Ciudad de Buenos Aires | E93: SIN IDENTIFICAR | F93: CF | G93: FCB 0005-00013636 | H93: 14876.03 | I93: 0 | J93: 3123.97 | K93: 3123.97 | L93: 18000
... A397: 01/07/2025 | B397: SALLES ANA MARIA | C397: 17814995 | D397: Ciudad de Buenos Aires | E397: SIN IDENTIFICAR | F397: CF | G397: FCB 0007-00006136 | H397: 24793.39 | I397: 0 | J397: 5206.61 | K397: 5206.61 | L397: 30000
A398: 01/07/2025 | B398: VOLPI, ALBERTO JAVIER | D398: Ciudad de Buenos Aires | E398: SIN IDENTIFICAR | F398: CF | G398: FCB 0007-00006137 | H398: 22314.05 | I398: 0 | J398: 4685.95 | K398: 4685.95 | L398: 27000
A399: 01/07/2025 | B399: ARANA, MARCELLA OFELIA | C399: 10138957 | D399: Ciudad de Buenos Aires | E399: SIN IDENTIFICAR | F399: CF | G399: FCB 0007-00006138 | H399: 17355.37 | I399: 0 | J399: 3644.63 | K399: 3644.63 | L399: 21000
A400: 01/07/2025 | B400: NAJUS ANIBAL RUBEN | D400: Buenos Aires | E400: SIN IDENTIFICAR | F400: CF | G400: FCB 0007-00006139 | H400: 21487.6 | I400: 0 | J400: 4512.4 | K400: 4512.4 | L400: 26000
A401: 01/07/2025 | B401: MINERVINI, MARIA DEL CARMEN LILIANA | C401: 12791306 | D401: Buenos Aires | E401: SIN IDENTIFICAR | F401: CF | G401: FCB 0007-00006140 | H401: 28099.17 | I401: 0 | J401: 5900.83 | K401: 5900.83 | L401: 34000
...

Sheet arca 05
A1: Mis Comprobantes Recibidos - CUIT 30710473168
A2: Fecha | B2: Tipo | C2: Punto de Venta | D2: Número Desde | E2: Número Hasta | F2: Cód. Autorización | G2: Tipo Doc. Emisor | H2: Nro. Doc. Emisor | I2: Denominación Emisor | J2: Tipo Cambio | K2: Moneda | L2: Imp. Neto Gravado | M2: Imp. Neto No Gravado | N2: Imp. Op. Exentas | O2: Otros Tributos | P2: IVA | Q2: Imp. Total
A3: 01/05/2025 | B3: 1 - Factura A | C3: 1 | D3: 123356 | F3: 75189399505180 | G3: CUIT | H3: 30714864269 | I3: CONTABILIUM S.A. S. A. | J3: 1 | K3: $ | L3: 164170 | M3: 0 | N3: 0 | O3: 0 | P3: 34475.7 | Q3: 198645.7
A4: 01/05/2025 | B4: 1 - Factura A | C4: 4 | D4: 1518883 | F4: 75184421857692 | G4: CUIT | H4: 30716620634 | I4: FIRST LABEL S.R.L. | J4: 1 | K4: $ | L4: 867767.77 | M4: 0 | N4: 0 | O4: 34710.71 | P4: 182231.23 | Q4: 1084709.7
A5: 31/05/2025 | B5: 1 - Factura A | C5: 50 | D5: 4376000 | E5: ARCA | F5: 75226311242782 | G5: CUIT | H5: 30714112836 | I5: AUTOPISTAS DE BUENOS AIRES (AUBASA) SA S. A. | J5: 1 | K5: $ | L5: 2875.37 | M5: 0 | N5: 0 | O5: 86.26 | P5: 603.83 | Q5: 3565.46
A6: 01/05/2025 | B6: 1 - Factura A | C6: 711 | D6: 7055586 | E6: ARCA | F6: 35179521470241 | G6: CUIT | H6: 30677237119 | I6: AUTOPISTAS DEL SOL S A | J6: 1 | K6: $ | L6: 14559.75 | M6: 0 | N6: 436.79 | O6: 582.39 | P6: 3057.56 | Q6: 18636.49
A7: 01/05/2025 | B7: 11 - Factura C | C7: 4 | D7: 11 | F7: 75183419865716 | G7: CUIT | H7: 20086277523 | I7: BOTINDARI JUAN CARLOS | J7: 1 | K7: $ | O7: 0 | Q7: 290000
A8: 02/05/2025 | B8: 1 - Factura A | C8: 500 | D8: 1723166 | F8: 75177133592830 | G8: CUIT | H8: 30654118767 | I8: SOLUCIONES MULTIMEDIA S A | J8: 1 | K8: $ | L8: 127126.59 | M8: 0 | N8: 0 | O8: 5085.07 | P8: 26696.58 | Q8: 158908.24
A9: 02/05/2025 | B9: 1 - Factura A | C9: 3051 | D9: 911477 | F9: 75187657875181 | G9: CUIT | H9: 30678814357 | I9: TELEFONICA MOVILES ARGENTINA SOCIEDAD ANONIMA | J9: 1 | K9: $ | L9: 88958.37 | M9: 0 | N9: 0 | O9: 10832.74 | P9: 24018.76 | Q9: 123809.87
A10: 02/05/2025 | B10: 1 - Factura A | C10: 2 | D10: 239 | F10: 75182528347539 | G10: CUIT | H10: 30605344352 | I10: CONSORCIO BARTOLOME MITRE 2466 | J10: 1 | K10: $ | L10: 2000000 | M10: 0 | N10: 0 | O10: 0 | P10: 420000 | Q10: 2420000
A11: 03/05/2025 | B11: 1 - Factura A | C11: 1 | D11: 827481 | F11: 75199246715421 | G11: CUIT | H11: 33716307749 | I11: VERISURE ARGENTINA MONITOREO DE ALARMAS SA | J11: 1 | K11: $ | L11: 53953.8 | M11: 0 | N11: 0 | O11: 2158.15 | P11: 11330.3 | Q11: 67442.25
A12: 04/05/2025 | B12: 11 - Factura C | C12: 1 | D12: 24 | F12: 75205029806246 | G12: CUIT | H12: 27443612705 | I12: MIGOYA MORIONDO MARIA INES | J12: 1 | K12: $ | O12: 0 | Q12: 900000
A13: 05/05/2025 | B13: 1 - Factura A | C13: 3 | D13: 37 | F13: 75182868622117 | G13: CUIT | H13: 20216164262 | I13: VELEZ ALEJANDRO MARCELO | J13: 1 | K13: $ | L13: 1500000 | M13: 0 | N13: 0 | O13: 0 | P13: 315000 | Q13: 1815000
A14: 05/05/2025 | B14: 11 - Factura C | C14: 2 | D14: 127 | E14: ARCA | F14: 75188822266811 | G14: CUIT | H14: 27315710508 | I14: RIVERO GABRIELA ROCIO | J14: 1 | K14: $ | O14: 0 | Q14: 48600
A15: 05/05/2025 | B15: 11 - Factura C | C15: 1 | D15: 171 | F15: 75180808654353 | G15: CUIT | H15: 27338342840 | I15: CANCINO PAMELA RITA | J15: 1 | K15: $ | O15: 0 | Q15: 236000
A16: 05/05/2025 | B16: 11 - Factura C | C16: 2 | D16: 351 | F16: 75188019259251 | G16: CUIT | H16: 27265832178 | I16: BLASCO MARIA GUADALUPE | J16: 1 | K16: $ | O16: 0 | Q16: 3200000
A17: 05/05/2025 | B17: 11 - Factura C | C17: 1 | D17: 25 | F17: 75205030188537 | G17: CUIT | H17: 27443612705 | I17: MIGOYA MORIONDO MARIA INES | J17: 1 | K17: $ | O17: 0 | Q17: 900000
A18: 06/05/2025 | B18: 1 - Factura A | C18: 2 | D18: 11968 | F18: 75182968852300 | G18: CUIT | H18: 30714331082 | I18: ORTOPEDIA CASA ESCALADA S.R.L. | J18: 1 | K18: $ | L18: 493491.01 | M18: 0 | N18: 0 | O18: 0 | P18: 103633.11 | Q18: 597124.12
A19: 06/05/2025 | B19: 1 - Factura A | C19: 5 | D19: 1525 | F19: 75185012307446 | G19: CUIT | H19: 27265302225 | I19: PRADO MARISOL | J19: 1 | K19: $ | L19: 3500000 | M19: 0 | N19: 0 | O19: 0 | P19: 735000 | Q19: 4235000
A20: 06/05/2025 | B20: 1 - Factura A | C20: 6 | D20: 57343 | F20: 75188026619178 | G20: CUIT | H20: 30710177658 | I20: TARGET MEDICAL S.A. | J20: 1 | K20: $ | L20: 3155460 | M20: 0 | N20: 0 | O20: 126218.4 | P20: 662646.6 | Q20: 3944325
A21: 06/05/2025 | B21: 1 - Factura A | C21: 120 | D21: 5646 | F21: 75185964379405 | G21: CUIT | H21: 30587197215 | I21: PANATEL SOCIEDAD ANONIMA | J21: 1 | K21: $ | L21: 95041.32 | M21: 0 | N21: 0 | O21: 5702.48 | P21: 19958.68 | Q21: 120702.48
A22: 06/05/2025 | B22: 1 - Factura A | C22: 17 | D22: 12389 | F22: 75180001470373 | G22: CUIT | H22: 30661143610 | I22: ORTOPEDIA BERNAT SRL | J22: 1 | K22: $ | L22: 1154300 | M22: 0 | N22: 0 | O22: 46172 | P22: 242403 | Q22: 1442875
A23: 06/05/2025 | B23: 1 - Factura A | C23: 6 | D23: 50 | F23: 75181011299005 | G23: CUIT | H23: 30716401541 | I23: HIGH MOBILITY S.A.S. | J23: 1 | K23: $ | L23: 3122441 | M23: 0 | N23: 0 | O23: 0 | P23: 655712.61 | Q23: 3778153.6
A24: 06/05/2025 | B24: 11 - Factura C | C24: 2 | D24: 323 | F24: 75182991008641 | G24: CUIT | H24: 20326759792 | I24: VILLALTA MARIANO | J24: 1 | K24: $ | O24: 0 | Q24: 114000
A25: 07/05/2025 | B25: 1 - Factura A | C25: 700 | D25: 2440062 | F25: 75192224513566 | G25: CUIT | H25: 30715804812 | I25: CORREDORES VIALES SOCIEDAD ANONIMA | J25: 1 | K25: $ | L25: 27663.52 | M25: 0 | N25: 0 | O25: 1106.54 | P25: 5809.34 | Q25: 34579.4
A26: 08/05/2025 | B26: 1 - Factura A | C26: 4 | D26: 75883 | F26: 75199233815483 | G26: CUIT | H26: 33709738459 | I26: ORTOPEDICOS ALFOLATEX SA | J26: 1 | K26: $ | L26: 359845.2 | M26: 0 | N26: 0 | O26: 0 | P26: 75567.49 | Q26: 435412.69
A27: 08/05/2025 | B27: 1 - Factura A | C27: 8 | D27: 405 | F27: 75194305707004 | G27: CUIT | H27: 30643518364 | I27: FARMACIA DE MEDRANO 533 SOCIEDAD EN COMANDITA SIMPLE | J27: 1 | K27: $ | L27: 492200 | M27: 0 | N27: 0 | O27: 0 | P27: 103362 | Q27: 595562
A28: 14/05/2025 | B28: 1 - Factura A | C28: 5009 | D28: 1403394 | E28: ARCA | F28: 75204107232683 | G28: CUIT | H28: 30574876474 | I28: AUTOPISTAS URBANAS S A | J28: 1 | K28: $ | L28: 4856.3 | M28: 0 | N28: 0 | O28: 631.32 | P28: 1019.82 | Q28: 6507.44
A29: 09/05/2025 | B29: 1 - Factura A | C29: 2 | D29: 1260 | F29: 75199376111288 | G29: CUIT | H29: 20272865869 | I29: DI FEO MARTIN EZEQUIEL | J29: 1 | K29: $ | L29: 33000 | M29: 0 | N29: 0 | O29: 0 | P29: 6930 | Q29: 39930
A30: 09/05/2025 | B30: 1 - Factura A | C30: 14 | D30: 77344 | F30: 75190446175800 | G30: CUIT | H30: 30711069360 | I30: BIDCOM SRL | J30: 1 | K30: $ | L30: 123966.12 | M30: 0 | N30: 0 | O30: 0 | P30: 26032.89 | Q30: 149999
A31: 09/05/2025 | B31: 1 - Factura A | C31: 8 | D31: 406 | F31: 75194431209519 | G31: CUIT | H31: 30643518364 | I31: FARMACIA DE MEDRANO 533 SOCIEDAD EN COMANDITA SIMPLE | J31: 1 | K31: $ | L31: 76975 | M31: 0 | N31: 0 | O31: 0 | P31: 16164.75 | Q31: 93139.75
A32: 09/05/2025 | B32: 1 - Factura A | C32: 6 | D32: 57397 | F32: 75198419380202 | G32: CUIT | H32: 30710177658 | I32: TARGET MEDICAL S.A. | J32: 1 | K32: $ | L32: 475130.7 | M32: 0 | N32: 0 | O32: 19005.23 | P32: 99777.45 | Q32: 593913.38
