Workbook
Name partner_id: Configuracion!$B$332

Sheet Configuracion
F1: CUIT | G1: Cargar sin guiones
F2: RAZON SOCIAL | G2: Maximo 30 caracteres
A3: CUIT | B3: RAZON SOCIAL | C3: DETALLE | F3: DETALLE | G3: Cargar tipo de gasto
A4: 30628205090 | B4: ALBAMIE SA | C4: CLIENTE
A5: 30711678820 | B5: 2PSI INGENIERIA SRL | C5: PROVEEDOR
A6: 33716367539 | B6: 3PI S.A.S. | C6: PROVEEDOR
A7: 30660373108 | B7: ABC SA | C7: VARIOS
A8: 20300210881 | B8: ABOY DIEGO OSCAR | C8: PROVEEDOR
A9: 27229910782 | B9: ABUGAUCH MARIA DE LOS ANGELES | C9: PROVEEDOR
A10: 20242709897 | B10: ABUGAUCH VICTOR HUGO | C10: PROVEEDOR
A11: 20281669053 | B11: ACOSTA JAVIER GUSTAVO | C11: FLETE
A12: 20174240125 | B12: ACOSTA OSCAR ISIDRO | C12: VARIOS
A13: 30641659106 | B13: AGRISOL SA | C13: VARIOS
A14: 33709914109 | B14: ALAN COLLECTION SA | C14: VARIOS
A15: 20267161616 | B15: ALBAJARI DIEGO MARCOS | C15: VARIOS
... A155: 30537679855 | B155: ESTACION LIMA SA | C155: VARIOS
A156: 30-56864959-8 | B156: EXPRESO BISONTE SRL | C156: FLETE
A157: 30708542349 | B157: EXPRESO FORMOSA SRL | C157: FLETE
A158: 30526582884 | B158: EXPRESO MAR DEL PLATA SA | C158: FLETE
A159: 30577744579 | B159: EXPRESO TROLE SRL | C159: FLETE
A160: 30715949292 | B160: EYPAPEL SAS | C160: GASTOS VARIOS
A161: 30715980807 | B161: FABORT SRL | C161: PROVEEDOR
A162: 20359718765 | B162: FAIL ABRAHAM | C162: VARIOS
A163: 30643518364 | B163: FARMACIA DE MEDRANO SCS | C163: PROVEEDOR
A164: 30692138747 | B164: FARMACITY SA | C164: VARIOS
A165: 33712234429 | B165: FEDAGAS SA | C165: VARIOS
A166: 20353576012 | B166: FEDERICO PABLO FEOLA | C166: VARIOS
A167: 20343766441 | B167: FERNANDEZ MAURO | C167: TALLER
A168: 27062343449 | B168: FERREIRA LILIANA INES | C168: FLETE
... A570: 30661273093 | B570: OSETRA | C570: CLIENTE

Sheet Noviembre 25
A1: ORTOPEDIA GEMINIS S.A. | J1: 45962
A4: LIBRO IVA COMPRAS
A6: FACTURAS A
A7: FECHA | B7: PTO VTA | C7: FAC A | D7: CUIT | E7: RAZON SOCIAL | F7: NETO | G7: IVA 21% | H7: IVA 27% | I7: IVA 10,5% | J7: P IVA | K7: IIBB CF | L7: IIBB BS | M7: NO GRAV | N7: OTROS | O7: TOTAL | P7: DETALLE
E8: =VLOOKUP(D8,Configuracion!$A$4:$C$590,2,FALSE()) -> #N/A | G8: =F8*21% -> 0 | O8: =SUM(F8:N8) -> 0 | P8: =VLOOKUP(D8,Configuracion!$A$4:$C$590,3,FALSE()) -> #N/A
E9: =VLOOKUP(D9,Configuracion!$A$4:$C$590,2,FALSE()) -> #N/A | G9: =F9*21% -> 0 | O9: =SUM(F9:N9) -> 0 | P9: =VLOOKUP(D9,Configuracion!$A$4:$C$590,3,FALSE()) -> #N/A
E10: =VLOOKUP(D10,Configuracion!$A$4:$C$590,2,FALSE()) -> #N/A | G10: =F10*21% -> 0 | O10: =SUM(F10:N10) -> 0 | P10: =VLOOKUP(D10,Configuracion!$A$4:$C$590,3,FALSE()) -> #N/A
E11: =VLOOKUP(D11,Configuracion!$A$4:$C$590,2,FALSE()) -> #N/A | G11: =F11*21% -> 0 | O11: =SUM(F11:N11) -> 0 | P11: =VLOOKUP(D11,Configuracion!$A$4:$C$590,3,FALSE()) -> #N/A
E12: =VLOOKUP(D12,Configuracion!$A$4:$C$590,2,FALSE()) -> #N/A | G12: =F12*21% -> 0 | O12: =SUM(F12:N12) -> 0 | P12: =VLOOKUP(D12,Configuracion!$A$4:$C$590,3,FALSE()) -> #N/A
E13: =VLOOKUP(D13,Configuracion!$A$4:$C$590,2,FALSE()) -> #N/A | G13: =F13*21% -> 0 | O13: =SUM(F13:N13) -> 0 | P13: =VLOOKUP(D13,Configuracion!$A$4:$C$590,3,FALSE()) -> #N/A
E14: =VLOOKUP(D14,Configuracion!$A$4:$C$590,2,FALSE()) -> #N/A | G14: =F14*21% -> 0 | O14: =SUM(F14:N14) -> 0 | P14: =VLOOKUP(D14,Configuracion!$A$4:$C$590,3,FALSE()) -> #N/A
E15: =VLOOKUP(D15,Configuracion!$A$4:$C$590,2,FALSE()) -> #N/A | G15: =F15*21% -> 0 | O15: =SUM(F15:N15) -> 0 | P15: =VLOOKUP(D15,Configuracion!$A$4:$C$590,3,FALSE()) -> #N/A
E16: =VLOOKUP(D16,Configuracion!$A$4:$C$590,2,FALSE()) -> #N/A | G16: =F16*21% -> 0 | O16: =SUM(F16:N16) -> 0 | P16: =VLOOKUP(D16,Configuracion!$A$4:$C$590,3,FALSE()) -> #N/A
E17: =VLOOKUP(D17,Configuracion!$A$4:$C$590,2,FALSE()) -> #N/A | G17: =F17*21% -> 0 | O17: =SUM(F17:N17) -> 0 | P17: =VLOOKUP(D17,Configuracion!$A$4:$C$590,3,FALSE()) -> #N/A
A18: TOTAL | F18: =SUM(F8:F17) -> 0 | G18: =SUM(G8:G17) -> 0 | H18: =SUM(H8:H17) -> 0 | I18: =SUM(I8:I17) -> 0 | J18: =SUM(J8:J17) -> 0 | K18: =SUM(K8:K17) -> 0 | L18: =SUM(L8:L17) -> 0 | M18: =SUM(M8:M17) -> 0 | ... O18: =SUM(O8:O17) -> 0
F19: IVA | G19: =G18+H18+I18 -> 0
A21: FACTURAS B/C
A22: FECHA | B22: PTO VTA | C22: FAC C | D22: CUIT | E22: RAZON SOCIAL | F22: TOTAL | G22: DETALLE
E23: =VLOOKUP(D23,Configuracion!$A$4:$C$590,2,FALSE()) -> #N/A | G23: =VLOOKUP(D23,Configuracion!$A$4:$C$590,3,FALSE()) -> #N/A
E24: =VLOOKUP(D24,Configuracion!$A$4:$C$590,2,FALSE()) -> #N/A | G24: =VLOOKUP(D24,Configuracion!$A$4:$C$590,3,FALSE()) -> #N/A
E25: =VLOOKUP(D25,Configuracion!$A$4:$C$590,2,FALSE()) -> #N/A | G25: =VLOOKUP(D25,Configuracion!$A$4:$C$590,3,FALSE()) -> #N/A
E26: =VLOOKUP(D26,Configuracion!$A$4:$C$590,2,FALSE()) -> #N/A | G26: =VLOOKUP(D26,Configuracion!$A$4:$C$590,3,FALSE()) -> #N/A
E27: =VLOOKUP(D27,Configuracion!$A$4:$C$590,2,FALSE()) -> #N/A | G27: =VLOOKUP(D27,Configuracion!$A$4:$C$590,3,FALSE()) -> #N/A
E28: =VLOOKUP(D28,Configuracion!$A$4:$C$590,2,FALSE()) -> #N/A | G28: =VLOOKUP(D28,Configuracion!$A$4:$C$590,3,FALSE()) -> #N/A
E29: =VLOOKUP(D29,Configuracion!$A$4:$C$590,2,FALSE()) -> #N/A | G29: =VLOOKUP(D29,Configuracion!$A$4:$C$590,3,FALSE()) -> #N/A
E30: =VLOOKUP(D30,Configuracion!$A$4:$C$590,2,FALSE()) -> #N/A | G30: =VLOOKUP(D30,Configuracion!$A$4:$C$590,3,FALSE()) -> #N/A
E31: =VLOOKUP(D31,Configuracion!$A$4:$C$590,2,FALSE()) -> #N/A | G31: =VLOOKUP(D31,Configuracion!$A$4:$C$590,3,FALSE()) -> #N/A
E32: =VLOOKUP(D32,Configuracion!$A$4:$C$590,2,FALSE()) -> #N/A | G32: =VLOOKUP(D32,Configuracion!$A$4:$C$590,3,FALSE()) -> #N/A
E33: =VLOOKUP(D33,Configuracion!$A$4:$C$590,2,FALSE()) -> #N/A | G33: =VLOOKUP(D33,Configuracion!$A$4:$C$590,3,FALSE()) -> #N/A
E34: =VLOOKUP(D34,Configuracion!$A$4:$C$590,2,FALSE()) -> #N/A | G34: =VLOOKUP(D34,Configuracion!$A$4:$C$590,3,FALSE()) -> #N/A
... E41: =VLOOKUP(D41,Configuracion!$A$4:$C$590,2,FALSE()) -> #N/A | G41: =VLOOKUP(D41,Configuracion!$A$4:$C$590,3,FALSE()) -> #N/A
A42: TOTAL | F42: =SUM(F23:F41) -> 0
A44: RETENCIONES
A45: FECHA | B45: COMPROBANTE NRO | D45: CUIT | E45: RAZON SOCIAL | F45: GANANCIAS | G45: IVA | H45: IIBB | I45: SUSS
A46: 45964 | B46: 0000-2025-096416 | D46: 30522428163 | E46: =VLOOKUP(D46,Configuracion!$A$4:$C$590,2,FALSE()) -> GALENO ARGENTINA SA | F46: 258825.79 | G46: 2764710.7 | H46: 13165289 | I46: 131652.89
A47: 45986 | B47: 0000-2025-104354 | D47: 30522428163 | E47: =VLOOKUP(D47,Configuracion!$A$4:$C$590,2,FALSE()) -> GALENO ARGENTINA SA | F47: 597286.55 | G47: 6354868.2 | H47: 298643.41 | I47: 302612.77
A48: 45986 | B48: 0000-2025-104356 | D48: 30522428163 | E48: =VLOOKUP(D48,Configuracion!$A$4:$C$590,2,FALSE()) -> GALENO ARGENTINA SA | F48: 581321.62 | G48: 6159811.9 | H48: 29067301 | I48: 293324.38
A49: 45986 | B49: 0000-2025-104358 | D49: 30522428163 | E49: =VLOOKUP(D49,Configuracion!$A$4:$C$590,2,FALSE()) -> GALENO ARGENTINA SA | F49: 68041.69 | G49: 714563.01 | H49: 34026.81 | I49: 34026.81
A50: 45964 | B50: 0001-2025-00001837 | D50: 30710538014 | E50: =VLOOKUP(D50,Configuracion!$A$4:$C$590,2,FALSE()) -> HC HOMECARE INT DOM SA | F50: 7191.44 | H50: 14935.98
A51: 45964 | B51: 0001-2025-00001837 | D51: 30710538014 | E51: =VLOOKUP(D51,Configuracion!$A$4:$C$590,2,FALSE()) -> HC HOMECARE INT DOM SA | H51: 10668.55
...

Sheet Calculo IVA
B1: ORTOPEDIA GEMINIS
A2: Calculo Iva | D2: 45962
B4: VENTAS
B5: Neto | C5: Iva | D5: Total
A6: FAC. "A" | B6: =+'Ventas 11'!D4+'Ventas 11'!D5 -> 29668385 | C6: =+B6*0.21 -> 6230360.8 | D6: =+B6+C6 -> 35898745
A7: FAC. "B" | B7: =+'Ventas 11'!D6+'Ventas 11'!D7+'Ventas 11'!D8 -> 19371243 | C7: =+B7*0.21 -> 4067961 | D7: =+B7+C7 -> 23439204
B8: =SUM(B6:B7) -> 49039627 | C8: =SUM(C6:C7) -> 10298322 | D8: =SUM(D6:D7) -> 59337949
B11: COMPRAS
B12: Neto | C12: IVA | D12: Total
A13: Comprobantes / Extractos | B13: =+'Compras 11'!I148+'Compras 11'!J148+'Compras 11'!K148 -> 36735777 | C13: =+'Compras 11'!N148 -> 7503645.2 | D13: 58925894
B16: =SUM(B13:B15) -> 36735777 | C16: =SUM(C13:C15) -> 7503645.2 | D16: =SUM(D13:D15) -> 58925894
A19: RETENCIONES | B19: N° Cuit | C19: Importe | D19: Nro. Retencion | E19: Fecha
A20: AFIP - No están informadas las retenciones de IVA en el sistema de AFIP
C35: =+'Noviembre 25'!G78 -> 17282658
A37: PERCEPCIONES | B37: N° Cuit | C37: Importe | D37: Nro. Retencion | E37: Fecha
C41: =SUM(C38:C40) -> 0
A43: Total Deducciociones | C43: =+C41+C35 -> 17282658
C46: (Montos en Positivo)
A47: 1er Saldo Tecnico del Período | C47: =+C8-C16 -> 2794676.6
A49: Saldo Tecnico de período Anterior (a favor) | D49: (resta en el total)
A51: Saldo Neto Técnico | C51: =+C47-C49 -> 2794676.6
A55: Saldo L.D. del Período | C55: =+C41+C35 -> 17282658
A57: Saldo L.D. del Período Anterior
A59: Neto S.L.D | C59: =+C55+C57 -> 17282658
A62: I V A | C62: =+C51-C59 -> -14487981
A63: NOTA: Sin Tomar posibles Retenciones que se hayan hecho

Sheet Ventas 11
C2: Totales por Tipo de Comprobante - ARCA
D3: Base | E3: IVA | F3: Otros Imp. | G3: Total Compr.
C4: FACTURAS A | D4: 33129236 | E4: =+D4*0.21 -> 6957139.5 | G4: =SUBTOTAL(9,D4:F4) -> 40086375
C5: NC A | D5: -3460851.2 | E5: =+D5*0.21 -> -726778.74 | G5: =SUBTOTAL(9,D5:F5) -> -4187629.9
C6: FACTURAS B | D6: 27411739 | E6: =+D6*0.21 -> 5756465.1 | G6: =SUBTOTAL(9,D6:F6) -> 33168204
C7: NC B | D7: -8040495.9 | E7: =+D7*0.21 -> -1688504.1 | G7: =SUBTOTAL(9,D7:F7) -> -9729000
C8: ND B | E8: =+D8*0.21 -> 0 | G8: =SUBTOTAL(9,D8:F8) -> 0
D9: =SUBTOTAL(9,D4:D8) -> 49039627 | E9: =SUBTOTAL(9,E4:E8) -> 10298322 | F9: 0 | G9: =+E9+D9 -> 59337949 | H9: =+SUBTOTAL(109,H12:H431) -> 49039628
A11: Fecha | B11: Razon Social | C11: Cuit | D11: Provincia | E11: Ciudad | F11: Condicion IVA | G11: Nro Factura | H11: Importe Neto Gravado | I11: Importe No Grav | J11: IVA2 | K11: IVA5 | L11: IVA10 | M11: IVA21 | N11: IVA27 | O11: IIBB | P11: Percepcion IVA | Q11: Otros Impuestos | R11: Total IVA | S11: Total Facturado | T11: Observaciones
A12: 11/11/2025 | B12: ALEJANDRO AUGUSTO BALDASSARRE LABARRIERE | C12: 23136532979 | D12: Ciudad de Buenos Aires | E12: SIN IDENTIFICAR | F12: RI | G12: FCA 0005-00000188 | H12: 57851.24 | I12: 0 | J12: 0 | K12: 0 | L12: 0 | M12: 12148.76 | N12: 0 | O12: 0 | P12: 0 | Q12: 0 | R12: 12148.76 | S12: 70000
A13: 20/11/2025 | B13: GALENO ARGENTINA SA | C13: 30522428163 | D13: Ciudad de Buenos Aires | E13: SIN IDENTIFICAR | F13: RI | G13: FCA 0006-00000646 | H13: 4395454.5 | I13: 0 | J13: 0 | K13: 0 | L13: 0 | M13: 923045.45 | N13: 0 | O13: 0 | P13: 0 | Q13: 0 | R13: 923045.45 | S13: 5318500
A14: 25/11/2025 | B14: GALENO ARGENTINA SA | C14: 30522428163 | D14: Ciudad de Buenos Aires | E14: SIN IDENTIFICAR | F14: RI | G14: FCA 0006-00000647 | H14: 6012396.7 | I14: 0 | J14: 0 | K14: 0 | L14: 0 | M14: 1262603.3 | N14: 0 | O14: 0 | P14: 0 | Q14: 0 | R14: 1262603.3 | S14: 7275000
A15: 28/11/2025 | B15: GALENO ARGENTINA SA | C15: 30522428163 | D15: Ciudad de Buenos Aires | E15: SIN IDENTIFICAR | F15: RI | G15: FCA 0006-00000648 | H15: 6472562 | I15: 0 | J15: 0 | K15: 0 | L15: 0 | M15: 1359238 | N15: 0 | O15: 0 | P15: 0 | Q15: 0 | R15: 1359238 | S15: 7831800
A16: 01/11/2025 | B16: OBRA SOCIAL UNION PERSONAL DE LA UNION DEL PERSONAL CIVIL DE LA NACION | C16: 30683032227 | D16: Ciudad de Buenos Aires | E16: SIN IDENTIFICAR | F16: RI | G16: FCA 0007-00002768 | H16: 2681410.3 | I16: 0 | J16: 0 | K16: 0 | L16: 0 | M16: 563096.16 | N16: 0 | O16: 0 | P16: 0 | Q16: 0 | R16: 563096.16 | S16: 3244506.5
A17: 06/11/2025 | B17: GERMAN DARIO RAMOS | C17: 20258280416 | D17: Ciudad de Buenos Aires | E17: SIN IDENTIFICAR | F17: RI | G17: FCA 0007-00002769 | H17: 28925.62 | I17: 0 | J17: 0 | K17: 0 | L17: 0 | M17: 6074.38 | N17: 0 | O17: 0 | P17: 0 | Q17: 0 | R17: 6074.38 | S17: 35000
A18: 11/11/2025 | B18: PAULA ANDREA PIAGGIO | C18: 27182477368 | D18: Ciudad de Buenos Aires | E18: SIN IDENTIFICAR | F18: RI | G18: FCA 0007-00002770 | H18: 29752.07 | I18: 0 | J18: 0 | K18: 0 | L18: 0 | M18: 6247.93 | N18: 0 | O18: 0 | P18: 0 | Q18: 0 | R18: 6247.93 | S18: 36000
A19: 11/11/2025 | B19: AMPARO SALUD S.R.L. | C19: 30715186655 | D19: Ciudad de Buenos Aires | E19: SIN IDENTIFICAR | F19: RI | G19: FCA 0007-00002771 | H19: 419890.91 | I19: 0 | J19: 0 | K19: 0 | L19: 0 | M19: 88177.09 | N19: 0 | O19: 0 | P19: 0 | Q19: 0 | R19: 88177.09 | S19: 508068
A20: 11/11/2025 | B20: HC HOMECARE INTERNACION DOMICILIARIA S.A. | C20: 30710538014 | D20: Buenos Aires | E20: VILLA MARTELLI | F20: RI | G20: FCA 0007-00002772 | H20: 443114.05 | I20: 0 | J20: 0 | K20: 0 | L20: 0 | M20: 93053.95 | N20: 0 | O20: 0 | P20: 0 | Q20: 0 | R20: 93053.95 | S20: 536168
A21: 11/11/2025 | B21: PAULA ANDREA PIAGGIO | C21: 27182477368 | D21: Ciudad de Buenos Aires | E21: SIN IDENTIFICAR | F21: RI | G21: FCA 0007-00002773 | H21: 33884.3 | I21: 0 | J21: 0 | K21: 0 | L21: 0 | M21: 7115.7 | N21: 0 | O21: 0 | P21: 0 | Q21: 0 | R21: 7115.7 | S21: 41000
A22: 11/11/2025 | B22: OBRA SOCIAL DEL PERSONAL DE LAS TELECOMUNICACIONES DE LA REPUBLICA ARGENTINA | C22: 30608716390 | D22: Ciudad de Buenos Aires | E22: SIN IDENTIFICAR | F22: RI | G22: FCA 0007-00002774 | H22: 102500 | I22: 0 | J22: 0 | K22: 0 | L22: 0 | M22: 21525 | N22: 0 | O22: 0 | P22: 0 | Q22: 0 | R22: 21525 | S22: 124025
A23: 11/11/2025 | B23: OBRA SOCIAL DEL PERSONAL DE LAS TELECOMUNICACIONES DE LA REPUBLICA ARGENTINA | C23: 30608716390 | D23: Ciudad de Buenos Aires | F23: RI | G23: FCA 0007-00002775 | H23: 20500 | M23: 4305 | R23: 4305 | S23: 24805
A24: 11/11/2025 | B24: OBRA SOCIAL DEL PERSONAL DE LAS TELECOMUNICACIONES DE LA REPUBLICA ARGENTINA | C24: 30608716390 | D24: Ciudad de Buenos Aires | E24: SIN IDENTIFICAR | F24: RI | G24: FCA 0007-00002776 | H24: 20500 | I24: 0 | J24: 0 | K24: 0 | L24: 0 | M24: 4305 | N24: 0 | O24: 0 | P24: 0 | Q24: 0 | R24: 4305 | S24: 24805
A25: 11/11/2025 | B25: OBRA SOCIAL DEL PERSONAL DE LAS TELECOMUNICACIONES DE LA REPUBLICA ARGENTINA | C25: 30608716390 | D25: Ciudad de Buenos Aires | E25: SIN IDENTIFICAR | F25: RI | G25: FCA 0007-00002777 | H25: 147917.36 | I25: 0 | J25: 0 | K25: 0 | L25: 0 | M25: 31062.64 | N25: 0 | O25: 0 | P25: 0 | Q25: 0 | R25: 31062.64 | S25: 178980
A26: 11/11/2025 | B26: OBRA SOCIAL DEL PERSONAL DE LAS TELECOMUNICACIONES DE LA REPUBLICA ARGENTINA | C26: 30608716390 | D26: Ciudad de Buenos Aires | E26: SIN IDENTIFICAR | F26: RI | G26: FCA 0007-00002778 | H26: 102500 | I26: 0 | J26: 0 | K26: 0 | L26: 0 | M26: 21525 | N26: 0 | O26: 0 | P26: 0 | Q26: 0 | R26: 21525 | S26: 124025
A27: 11/11/2025 | B27: OBRA SOCIAL DEL PERSONAL DE LAS TELECOMUNICACIONES DE LA REPUBLICA ARGENTINA | C27: 30608716390 | D27: Ciudad de Buenos Aires | E27: SIN IDENTIFICAR | F27: RI | G27: FCA 0007-00002779 | H27: 59166.94 | I27: 0 | J27: 0 | K27: 0 | L27: 0 | M27: 12425.06 | N27: 0 | O27: 0 | P27: 0 | Q27: 0 | R27: 12425.06 | S27: 71592
A28: 11/11/2025 | B28: OBRA SOCIAL DEL PERSONAL DE LAS TELECOMUNICACIONES DE LA REPUBLICA ARGENTINA | C28: 30608716390 | D28: Ciudad de Buenos Aires | E28: SIN IDENTIFICAR | F28: RI | G28: FCA 0007-00002780 | H28: 41000 | I28: 0 | J28: 0 | K28: 0 | L28: 0 | M28: 8610 | N28: 0 | O28: 0 | P28: 0 | Q28: 0 | R28: 8610 | S28: 49610
A29: 12/11/2025 | B29: OBRA SOCIAL DEL PERSONAL DE LAS TELECOMUNICACIONES DE LA REPUBLICA ARGENTINA | C29: 30608716390 | D29: Ciudad de Buenos Aires | E29: SIN IDENTIFICAR | F29: RI | G29: FCA 0007-00002781 | H29: 137013.22 | I29: 0 | J29: 0 | K29: 0 | L29: 0 | M29: 28772.78 | N29: 0 | O29: 0 | P29: 0 | Q29: 0 | R29: 28772.78 | S29: 165786
A30: 12/11/2025 | B30: OBRA SOCIAL DEL PERSONAL DE LAS TELECOMUNICACIONES DE LA REPUBLICA ARGENTINA | C30: 30608716390 | D30: Ciudad de Buenos Aires | E30: SIN IDENTIFICAR | F30: RI | G30: FCA 0007-00002782 | H30: 123305.79 | I30: 0 | J30: 0 | K30: 0 | L30: 0 | M30: 25894.21 | N30: 0 | O30: 0 | P30: 0 | Q30: 0 | R30: 25894.21 | S30: 149200
A31: 12/11/2025 | B31: OBRA SOCIAL DEL PERSONAL DE LAS TELECOMUNICACIONES DE LA REPUBLICA ARGENTINA | C31: 30608716390 | D31: Ciudad de Buenos Aires | E31: SIN IDENTIFICAR | F31: RI | G31: FCA 0007-00002783 | H31: 87380.17 | I31: 0 | J31: 0 | K31: 0 | L31: 0 | M31: 18349.83 | N31: 0 | O31: 0 | P31: 0 | Q31: 0 | R31: 18349.83 | S31: 105730
A32: 12/11/2025 | B32: OBRA SOCIAL DEL PERSONAL DE LAS TELECOMUNICACIONES DE LA REPUBLICA ARGENTINA | C32: 30608716390 | D32: Ciudad de Buenos Aires | E32: SIN IDENTIFICAR | F32: RI | G32: FCA 0007-00002784 | H32: 41000 | I32: 0 | J32: 0 | K32: 0 | L32: 0 | M32: 8610 | N32: 0 | O32: 0 | P32: 0 | Q32: 0 | R32: 8610 | S32: 49610
A33: 12/11/2025 | B33: OBRA SOCIAL DEL PERSONAL DE LAS TELECOMUNICACIONES DE LA REPUBLICA ARGENTINA | C33: 30608716390 | D33: Ciudad de Buenos Aires | E33: SIN IDENTIFICAR | F33: RI | G33: FCA 0007-00002785 | H33: 41000 | I33: 0 | J33: 0 | K33: 0 | L33: 0 | M33: 8610 | N33: 0 | O33: 0 | P33: 0 | Q33: 0 | R33: 8610 | S33: 49610
A34: 12/11/2025 | B34: OBRA SOCIAL DEL PERSONAL DE LAS TELECOMUNICACIONES DE LA REPUBLICA ARGENTINA | C34: 30608716390 | D34: Ciudad de Buenos Aires | E34: SIN IDENTIFICAR | F34: RI | G34: FCA 0007-00002786 | H34: 41000 | I34: 0 | J34: 0 | K34: 0 | L34: 0 | M34: 8610 | N34: 0 | O34: 0 | P34: 0 | Q34: 0 | R34: 8610 | S34: 49610
A35: 12/11/2025 | B35: OBRA SOCIAL DEL PERSONAL DE LAS TELECOMUNICACIONES DE LA REPUBLICA ARGENTINA | C35: 30608716390 | D35: Ciudad de Buenos Aires | E35: SIN IDENTIFICAR | F35: RI | G35: FCA 0007-00002787 | H35: 41000 | I35: 0 | J35: 0 | K35: 0 | L35: 0 | M35: 8610 | N35: 0 | O35: 0 | P35: 0 | Q35: 0 | R35: 8610 | S35: 49610
... A324: 05/11/2025 | B324: ALVAREZ MARTA OLGA | C324: 9955440 | D324: Buenos Aires | E324: RAMOS MEJIA | F324: CF | G324: FCB 0007-00006542 | H324: 8603.31 | I324: 0 | J324: 0 | K324: 0 | L324: 0 | M324: 1806.69 | N324: 0 | O324: 0 | P324: 0 | Q324: 0 | R324: 1806.69 | S324: 10410
A325: 05/11/2025 | B325: BAUAB, CAROLINA | D325: Buenos Aires | E325: SIN IDENTIFICAR | F325: CF | G325: FCB 0007-00006543 | H325: 58677.69 | I325: 0 | J325: 0 | K325: 0 | L325: 0 | M325: 12322.31 | N325: 0 | O325: 0 | P325: 0 | Q325: 0 | R325: 12322.31 | S325: 71000
A326: 05/11/2025 | B326: SCHELGEL, LUIS ALBERTO | D326: Buenos Aires | E326: SIN IDENTIFICAR | F326: CF | G326: FCB 0007-00006544 | H326: 39669.42 | I326: 0 | J326: 0 | K326: 0 | L326: 0 | M326: 8330.58 | N326: 0 | O326: 0 | P326: 0 | Q326: 0 | R326: 8330.58 | S326: 48000
A327: 05/11/2025 | B327: SILVIA MONICA ROJAS | C327: 27141958807 | D327: Ciudad de Buenos Aires | E327: BALVANERA | F327: CF | G327: FCB 0007-00006545 | H327: 36363.64 | I327: 0 | J327: 0 | K327: 0 | L327: 0 | M327: 7636.36 | N327: 0 | O327: 0 | P327: 0 | Q327: 0 | R327: 7636.36 | S327: 44000
A328: 05/11/2025 | B328: AGOSTINO MIRIAM | C328: 17275405 | D328: Buenos Aires | E328: SIN IDENTIFICAR | F328: CF | G328: FCB 0007-00006546 | H328: 52066.12 | I328: 0 | J328: 0 | K328: 0 | L328: 0 | M328: 10933.88 | N328: 0 | O328: 0 | P328: 0 | Q328: 0 | R328: 10933.88 | S328: 63000
A329: 05/11/2025 | B329: CONEN SILVIA ADELA | C329: 334529 | D329: Ciudad de Buenos Aires | E329: SIN IDENTIFICAR | F329: CF | G329: FCB 0007-00006547 | H329: 37190.08 | I329: 0 | J329: 0 | K329: 0 | L329: 0 | M329: 7809.92 | N329: 0 | O329: 0 | P329: 0 | Q329: 0 | R329: 7809.92 | S329: 45000
A330: 05/11/2025 | B330: CECILIA DEL PILAR TELLO MARTEL | C330: 27951120370 | D330: Ciudad de Buenos Aires | E330: SIN IDENTIFICAR | F330: CF | G330: FCB 0007-00006548 | H330: 28925.62 | I330: 0 | J330: 0 | K330: 0 | L330: 0 | M330: 6074.38 | N330: 0 | O330: 0 | P330: 0 | Q330: 0 | R330: 6074.38 | S330: 35000
...

Sheet Compras 11
A1: Fecha Emision | B1: Fecha Contable | C1: Nro Factura | D1: Razon Social | E1: Cuit | F1: Condicion Iva | G1: Monto Gravado Iva 2 | H1: Monto Gravado Iva 5 | I1: Monto Gravado Iva 10,5 | J1: Monto Gravado Iva 21 | K1: Monto Gravado Iva 27 | L1: Monto No Gravado Y Exentos | M1: Monto Gravado Monotributistas | N1: Iva Facturado | O1: Imp Interno | P1: Imp Municipal | Q1: Imp Nacional | R1: Otros | S1: Percepcion IVA | T1: IIBB | U1: Total Facturado | V1: Rubro | W1: Cod Fa | X1: COMPR.
A2: 19/11/2025 | B2: 19/11/2025 | C2: FCA 00001-00009484 | D2: REHAB SRL | E2: 30715141201 | F2: RI | G2: 0 | H2: 0 | I2: 0 | J2: 300318.75 | K2: 0 | L2: 0 | M2: 0 | N2: 63066.94 | O2: 0 | P2: 0 | Q2: 0 | R2: 0 | S2: 0 | T2: 0 | U2: =SUM(G2:T2) -> 363385.69 | V2: Bienes | W2: Buenos Aires
A3: 01/11/2025 | B3: 01/11/2025 | C3: FCA 00001-00143079 | D3: CONTABILIUM SA | E3: 30714864269 | F3: RI | G3: 0 | H3: 0 | I3: 0 | J3: 184800 | K3: 0 | L3: 0 | M3: 0 | N3: 38808 | O3: 0 | P3: 0 | Q3: 0 | R3: 0 | S3: 0 | T3: 0 | U3: =SUM(G3:T3) -> 223608 | V3: Servicios | W3: Ciudad de Buenos Aires
A4: 03/11/2025 | B4: 03/11/2025 | C4: FCA 00001-01071638 | D4: VERISURE ARGENTINA MONITOREO DE ALARMAS SA | E4: 33716307749 | F4: RI | G4: 0 | H4: 0 | I4: 0 | J4: 62349.01 | K4: 0 | L4: 0 | M4: 0 | N4: 13093.29 | O4: 0 | P4: 0 | Q4: 0 | R4: 2493.96 | S4: 0 | T4: 0 | U4: =SUM(G4:T4) -> 77936.26 | V4: Servicios | W4: Ciudad de Buenos Aires | X4: Sin comprobante
A5: 27/11/2025 | B5: 27/11/2025 | C5: FCA 00002-00000053 | D5: BARD MARISA SILVIA | E5: 27243660535 | F5: RI | G5: 0 | H5: 0 | I5: 0 | J5: 489161.16 | K5: 0 | L5: 0 | M5: 0 | N5: 102723.84 | O5: 0 | P5: 0 | Q5: 0 | R5: 0 | S5: 0 | T5: 0 | U5: =SUM(G5:T5) -> 591885 | V5: Locaciones | W5: Buenos Aires
A6: 03/11/2025 | B6: 03/11/2025 | C6: FCA 00002-00000254 | D6: CONSORCIO BARTOLME MITRE 2466 | E6: 30605344352 | F6: RI | G6: 0 | H6: 0 | I6: 0 | J6: 2160580 | K6: 0 | L6: 0 | M6: 0 | N6: 453721.8 | O6: 0 | P6: 0 | Q6: 0 | R6: 0 | S6: 0 | T6: 0 | U6: =SUM(G6:T6) -> 2614301.8 | V6: Servicios | W6: Buenos Aires
A7: 06/11/2025 | B7: 14/11/2025 | C7: FCA 00002-00000289 | D7: SCHEJTER LILA ELISA | E7: 27144282383 | F7: RI | G7: 0 | H7: 0 | I7: 0 | J7: 70000 | K7: 0 | L7: 0 | M7: 0 | N7: 14700 | O7: 0 | P7: 0 | Q7: 0 | R7: 0 | S7: 0 | T7: 0 | U7: =SUM(G7:T7) -> 84700 | V7: Servicios | W7: Buenos Aires
A8: 06/11/2025 | B8: 06/11/2025 | C8: FCA 00002-00001649 | D8: MARTIN EZEQUIEL DI FEO | E8: 20272865869 | F8: RI | G8: 0 | H8: 0 | I8: 0 | J8: 109300 | K8: 0 | L8: 0 | M8: 0 | N8: 22953 | O8: 0 | P8: 0 | Q8: 0 | R8: 0 | S8: 0 | T8: 0 | U8: =SUM(G8:T8) -> 132253 | V8: Bienes | W8: Buenos Aires
A9: 12/11/2025 | B9: 12/11/2025 | C9: FCA 00002-00001667 | D9: MARTIN EZEQUIEL DI FEO | E9: 20272865869 | F9: RI | G9: 0 | H9: 0 | I9: 0 | J9: 126400 | K9: 0 | L9: 0 | M9: 0 | N9: 26544 | O9: 0 | P9: 0 | Q9: 0 | R9: 0 | S9: 0 | T9: 0 | U9: =SUM(G9:T9) -> 152944 | V9: Bienes | W9: Buenos Aires
A10: 14/11/2025 | B10: 14/11/2025 | C10: FCA 00002-00001673 | D10: MARTIN EZEQUIEL DI FEO | E10: 20272865869 | F10: RI | G10: 0 | H10: 0 | I10: 0 | J10: 19500 | K10: 0 | L10: 0 | M10: 0 | N10: 4095 | O10: 0 | P10: 0 | Q10: 0 | R10: 0 | S10: 0 | T10: 0 | U10: =SUM(G10:T10) -> 23595 | V10: Bienes | W10: Buenos Aires | X10: Sin comprobante
A11: 19/11/2025 | B11: 19/11/2025 | C11: FCA 00002-00001686 | D11: MARTIN EZEQUIEL DI FEO | E11: 20272865869 | F11: RI | G11: 0 | H11: 0 | I11: 0 | J11: 150700 | K11: 0 | L11: 0 | M11: 0 | N11: 31647 | O11: 0 | P11: 0 | Q11: 0 | R11: 0 | S11: 0 | T11: 0 | U11: =SUM(G11:T11) -> 182347 | V11: Bienes | W11: Buenos Aires
A12: 20/11/2025 | B12: 20/11/2025 | C12: FCA 00002-00001687 | D12: MARTIN EZEQUIEL DI FEO | E12: 20272865869 | F12: RI | G12: 0 | H12: 0 | I12: 0 | J12: 15700 | K12: 0 | L12: 0 | M12: 0 | N12: 3297 | O12: 0 | P12: 0 | Q12: 0 | R12: 0 | S12: 0 | T12: 0 | U12: =SUM(G12:T12) -> 18997 | V12: Bienes | W12: Buenos Aires
A13: 28/11/2025 | B13: 28/11/2025 | C13: FCA 00002-00001697 | D13: MARTIN EZEQUIEL DI FEO | E13: 20272865869 | F13: RI | G13: 0 | H13: 0 | I13: 0 | J13: 131009.09 | K13: 0 | L13: 0 | M13: 0 | N13: 27511.91 | O13: 0 | P13: 0 | Q13: 0 | R13: 0 | S13: 0 | T13: 0 | U13: =SUM(G13:T13) -> 158521 | V13: Bienes | W13: Buenos Aires
A14: 13/11/2025 | B14: 13/11/2025 | C14: FCA 00002-00005595 | D14: CIEN POR CIENTO FOLLETOS SRL | E14: 30718329805 | F14: RI | G14: 0 | H14: 0 | I14: 0 | J14: 73057.85 | K14: 0 | L14: 0 | M14: 0 | N14: 15342.15 | O14: 0 | P14: 0 | Q14: 0 | R14: 0 | S14: 0 | T14: 0 | U14: =SUM(G14:T14) -> 88400 | W14: Ciudad de Buenos Aires
A15: 18/11/2025 | B15: 18/11/2025 | C15: FCA 00002-00005665 | D15: CIEN POR CIENTO FOLLETOS SRL | E15: 30718329805 | F15: RI | G15: 0 | H15: 0 | I15: 0 | J15: 73057.85 | K15: 0 | L15: 0 | M15: 0 | N15: 15342.15 | O15: 0 | P15: 0 | Q15: 0 | R15: 0 | S15: 0 | T15: 0 | U15: =SUM(G15:T15) -> 88400 | W15: Ciudad de Buenos Aires | X15: Sin comprobante
A16: 03/11/2025 | B16: 14/11/2025 | C16: FCA 00002-00006005 | D16: LEONARDO JAVIER VIDAL | E16: 24253769951 | F16: RI | G16: 0 | H16: 0 | I16: 0 | J16: 315957 | K16: 0 | L16: 0 | M16: 0 | N16: 66350.97 | O16: 0 | P16: 0 | Q16: 0 | R16: 0 | S16: 0 | T16: 0 | U16: =SUM(G16:T16) -> 382307.97 | V16: Bienes | W16: Buenos Aires
A17: 11/11/2025 | B17: 11/11/2025 | C17: FCA 00002-00007991 | D17: DISEÑOS JERY S R L | E17: 30694549817 | F17: RI | G17: 0 | H17: 0 | I17: 0 | J17: 193893 | K17: 0 | L17: 0 | M17: 0 | N17: 40717.53 | O17: 0 | P17: 0 | Q17: 0 | R17: 0 | S17: 0 | T17: 0 | U17: =SUM(G17:T17) -> 234610.53 | V17: Bienes | W17: Ciudad de Buenos Aires | X17: Sin comprobante
A18: 12/11/2025 | B18: 12/11/2025 | C18: FCA 00002-00010010 | D18: MANGGINI PABLO Y M ULISES SH | E18: 33708218699 | F18: RI | G18: 0 | H18: 0 | I18: 0 | J18: 90000 | K18: 0 | L18: 0 | M18: 0 | N18: 18900 | O18: 0 | P18: 0 | Q18: 0 | R18: 0 | S18: 0 | T18: 0 | U18: =SUM(G18:T18) -> 108900 | V18: Locaciones | W18: Buenos Aires
A19: 29/11/2025 | B19: 29/11/2025 | C19: FCA 00002-00474231 | D19: MERCADOLIBRE S.R.L. | E19: 30703088534 | F19: RI | G19: 0 | H19: 0 | I19: 0 | J19: 147998.62 | K19: 0 | L19: 0 | M19: 0 | N19: 31079.71 | O19: 5919.94 | P19: 0 | Q19: 0 | R19: 0 | S19: 4439.96 | T19: 0 | U19: =SUM(G19:T19) -> 189438.23 | V19: Servicios | W19: Ciudad de Buenos Aires
A20: 17/11/2025 | B20: 17/11/2025 | C20: FCA 00003-00010027 | D20: MANGGINI PABLO Y M ULISES SH | E20: 33708218699 | F20: RI | G20: 0 | H20: 0 | I20: 0 | J20: 45000 | K20: 0 | L20: 0 | M20: 0 | N20: 9450 | O20: 0 | P20: 0 | Q20: 0 | R20: 0 | S20: 0 | T20: 0 | U20: =SUM(G20:T20) -> 54450 | V20: Locaciones | W20: Buenos Aires
A21: 04/11/2025 | B21: 04/11/2025 | C21: FCA 00003-00055382 | D21: EXPRESO TROLE S R L | E21: 30577744579 | F21: RI | G21: 0 | H21: 0 | I21: 0 | J21: 130554.62 | K21: 0 | L21: 0 | M21: 0 | N21: 27416.47 | O21: 0 | P21: 0 | Q21: 0 | R21: 0 | S21: 0 | T21: 0 | U21: =SUM(G21:T21) -> 157971.09 | V21: Servicios | W21: Ciudad de Buenos Aires
A22: 07/11/2025 | B22: 07/11/2025 | C22: FCA 00003-00057712 | D22: LIPROT S.R.L. | E22: 30711454388 | F22: RI | G22: 0 | H22: 0 | I22: 0 | J22: 197766 | K22: 0 | L22: 0 | M22: 0 | N22: 41530.86 | O22: 0 | P22: 0 | Q22: 0 | R22: 0 | S22: 0 | T22: 0 | U22: =SUM(G22:T22) -> 239296.86 | V22: Bienes | W22: Buenos Aires
A23: 17/11/2025 | B23: 17/11/2025 | C23: FCA 00003-03596545 | D23: LINKEDSTORE ARGENTINA S.R.L. | E23: 30712019359 | F23: RI | G23: 0 | H23: 0 | I23: 0 | J23: 17767.77 | K23: 0 | L23: 0 | M23: 0 | N23: 3731.23 | O23: 0 | P23: 0 | Q23: 0 | R23: 710.72 | S23: 0 | T23: 0 | U23: =SUM(G23:T23) -> 22209.72 | V23: Servicios | W23: Ciudad de Buenos Aires | X23: Sin comprobante
A24: 05/11/2025 | B24: 05/11/2025 | C24: FCA 00004-00000138 | D24: EDUARDO FRANCISCO NARDOMARINO | E24: 20174004146 | F24: RI | G24: 0 | H24: 0 | I24: 0 | J24: 270000 | K24: 0 | L24: 0 | M24: 0 | N24: 56700 | O24: 0 | P24: 0 | Q24: 0 | R24: 0 | S24: 0 | T24: 0 | U24: =SUM(G24:T24) -> 326700 | V24: Servicios | W24: Ciudad de Buenos Aires
A25: 17/11/2025 | B25: 17/11/2025 | C25: FCA 00004-00000141 | D25: EDUARDO FRANCISCO NARDOMARINO | E25: 20174004146 | F25: RI | G25: 0 | H25: 0 | I25: 0 | J25: 280000 | K25: 0 | L25: 0 | M25: 0 | N25: 58800 | O25: 0 | P25: 0 | Q25: 0 | R25: 0 | S25: 0 | T25: 0 | U25: =SUM(G25:T25) -> 338800 | V25: Servicios | W25: Ciudad de Buenos Aires
A26: 18/11/2025 | B26: 18/11/2025 | C26: FCA 00004-00000142 | D26: EDUARDO FRANCISCO NARDOMARINO | E26: 20174004146 | F26: RI | G26: 0 | H26: 0 | I26: 0 | J26: 332500 | K26: 0 | L26: 0 | M26: 0 | N26: 69825 | O26: 0 | P26: 0 | Q26: 0 | R26: 0 | S26: 0 | T26: 0 | U26: =SUM(G26:T26) -> 402325 | V26: Servicios | W26: Ciudad de Buenos Aires
A27: 20/11/2025 | B27: 20/11/2025 | C27: FCA 00004-00000143 | D27: EDUARDO FRANCISCO NARDOMARINO | E27: 20174004146 | F27: RI | G27: 0 | H27: 0 | I27: 0 | J27: 262500 | K27: 0 | L27: 0 | M27: 0 | N27: 55125 | O27: 0 | P27: 0 | Q27: 0 | R27: 0 | S27: 0 | T27: 0 | U27: =SUM(G27:T27) -> 317625 | V27: Servicios | W27: Ciudad de Buenos Aires
A28: 20/11/2025 | B28: 20/11/2025 | C28: FCA 00004-00000179 | D28: VILLALBA MIGUEL ANGEL | E28: 20317488476 | F28: RI | G28: 0 | H28: 0 | I28: 0 | J28: 900000 | K28: 0 | L28: 0 | M28: 0 | N28: 189000 | O28: 0 | P28: 0 | Q28: 0 | R28: 0 | S28: 0 | T28: 0 | U28: =SUM(G28:T28) -> 1089000 | V28: Bienes de uso | W28: Buenos Aires
A29: 06/11/2025 | B29: 06/11/2025 | C29: FCA 00004-00016201 | D29: TRINIDAD INSUMOS S.R.L. | E29: 30712305513 | F29: RI | G29: 0 | H29: 0 | I29: 0 | J29: 1084000 | K29: 0 | L29: 0 | M29: 0 | N29: 227640 | O29: 0 | P29: 0 | Q29: 0 | R29: 0 | S29: 0 | T29: 0 | U29: =SUM(G29:T29) -> 1311640 | V29: Bienes | W29: Buenos Aires
A30: 14/11/2025 | B30: 14/11/2025 | C30: FCA 00004-00016244 | D30: TRINIDAD INSUMOS S.R.L. | E30: 30712305513 | F30: RI | G30: 0 | H30: 0 | I30: 1863000 | J30: 117800 | K30: 0 | L30: 0 | M30: 0 | N30: 220353 | O30: 0 | P30: 0 | Q30: 0 | R30: 0 | S30: 0 | T30: 0 | U30: =SUM(G30:T30) -> 2201153 | V30: Bienes | W30: Buenos Aires
A31: 03/11/2025 | B31: 03/11/2025 | C31: FCA 00004-00041612 | D31: EMILIANO RUBEN LEDESMA | E31: 20289111329 | F31: RI | G31: 0 | H31: 0 | I31: 0 | J31: 1704476.6 | K31: 0 | L31: 0 | M31: 0 | N31: 357940.09 | O31: 0 | P31: 0 | Q31: 0 | R31: 0 | S31: 0 | T31: 0 | U31: =SUM(G31:T31) -> 2062416.7 | V31: Bienes | W31: Buenos Aires
A32: 28/11/2025 | B32: 28/11/2025 | C32: FCA 00004-00041808 | D32: EMILIANO RUBEN LEDESMA | E32: 20289111329 | F32: RI | G32: 0 | H32: 0 | I32: 0 | J32: 60480 | K32: 0 | L32: 0 | M32: 0 | N32: 12700.8 | O32: 0 | P32: 0 | Q32: 0 | R32: 0 | S32: 0 | T32: 0 | U32: =SUM(G32:T32) -> 73180.8 | V32: Bienes | W32: Buenos Aires
A33: 18/11/2025 | B33: 18/11/2025 | C33: FCA 00005-00000068 | D33: JUN MA | E33: 20929183143 | F33: RI | G33: 0 | H33: 0 | I33: 0 | J33: 110000 | K33: 0 | L33: 0 | M33: 0 | N33: 23100 | O33: 0 | P33: 0 | Q33: 0 | R33: 0 | S33: 0 | T33: 0 | U33: =SUM(G33:T33) -> 133100 | V33: Servicios | W33: Ciudad de Buenos Aires
A34: 12/11/2025 | B34: 12/11/2025 | C34: FCA 00005-00001096 | D34: BM MEDICINE SRL | E34: 30712155945 | F34: RI | G34: 0 | H34: 0 | I34: 0 | J34: 783510 | K34: 0 | L34: 0 | M34: 0 | N34: 164537.1 | O34: 0 | P34: 0 | Q34: 0 | R34: 0 | S34: 0 | T34: 0 | U34: =SUM(G34:T34) -> 948047.1 | V34: Bienes | W34: Ciudad de Buenos Aires
A35: 19/11/2025 | B35: 19/11/2025 | C35: FCA 00005-00001105 | D35: BM MEDICINE SRL | E35: 30712155945 | F35: RI | G35: 0 | H35: 0 | I35: 0 | J35: 682110 | K35: 0 | L35: 0 | M35: 0 | N35: 143243.1 | O35: 0 | P35: 0 | Q35: 0 | R35: 0 | S35: 0 | T35: 0 | U35: =SUM(G35:T35) -> 825353.1 | V35: Bienes | W35: Ciudad de Buenos Aires
... A43: 25/11/2025 | B43: 25/11/2025 | C43: FCA 00006-00001684 | D43: HUGO GABRIEL VENTO | E43: 20247225243 | F43: RI | G43: 0 | H43: 0 | I43: 0 | J43: 140932 | K43: 0 | L43: 0 | M43: 0 | N43: 29595.72 | O43: 0 | P43: 0 | Q43: 0 | R43: 0 | S43: 0 | T43: 0 | U43: =SUM(G43:T43) -> 170527.72 | V43: Bienes | W43: Ciudad de Buenos Aires
A44: 11/11/2025 | B44: 11/11/2025 | C44: FCA 00006-00002160 | D44: PAPELERA GEOPEL SRL | E44: 30716815710 | F44: RI | G44: 0 | H44: 0 | I44: 0 | J44: 26200 | K44: 0 | L44: 0 | M44: 0 | N44: 5502 | O44: 0 | P44: 0 | Q44: 0 | R44: 0 | S44: 0 | T44: 0 | U44: =SUM(G44:T44) -> 31702 | V44: Bienes | W44: 81
A45: 14/11/2025 | B45: 14/11/2025 | C45: FCA 00006-00002163 | D45: PAPELERA GEOPEL SRL | E45: 30716815710 | F45: RI | G45: 0 | H45: 0 | I45: 0 | J45: 17000 | K45: 0 | L45: 0 | M45: 0 | N45: 3570 | O45: 0 | P45: 0 | Q45: 0 | R45: 0 | S45: 0 | T45: 0 | U45: =SUM(G45:T45) -> 20570 | V45: Bienes | W45: 81
A46: 28/11/2025 | B46: 28/11/2025 | C46: FCA 00006-00002177 | D46: PAPELERA GEOPEL SRL | E46: 30716815710 | F46: RI | G46: 0 | H46: 0 | I46: 0 | J46: 14000 | K46: 0 | L46: 0 | M46: 0 | N46: 2940 | O46: 0 | P46: 0 | Q46: 0 | R46: 0 | S46: 0 | T46: 0 | U46: =SUM(G46:T46) -> 16940 | V46: Bienes | W46: 81
A47: 01/11/2025 | B47: 01/11/2025 | C47: FCA 00006-00023963 | D47: SOMOS ENERGIA SA | E47: 33715594949 | F47: RI | G47: 0 | H47: 0 | I47: 0 | J47: 20749.09 | K47: 0 | L47: 0 | M47: 0 | N47: 4357.31 | O47: 3489.83 | P47: 0 | Q47: 0 | R47: 397.76 | S47: 0 | T47: 0 | U47: =SUM(G47:T47) -> 28993.99 | V47: Servicios | W47: 81
...

Sheet arcasss
B2: PEAJES | H2: FA-A | I2: 118
B3: ok contabil | H3: NC-A | I3: 8 | L3: 8
H4: FA-C | I4: 25 | L4: 25
H5: NC-C | I5: 2 | L5: 2
H6: TOTAL COMP | I6: =SUBTOTAL(9,I2:I5) -> 153
H7: total contabilium | I7: 149
A9: Fecha | B9: Tipo | C9: Punto de Venta | D9: Número Desde | E9: Número Hasta | F9: Cód. Autorización | G9: Tipo Doc. Emisor | H9: Nro. Doc. Emisor | I9: Denominación Emisor | J9: Tipo Doc. Receptor | K9: Nro. Doc. Receptor | L9: Tipo Cambio | M9: Moneda | N9: Neto Grav. IVA 0% | O9: IVA 2,5% | P9: Neto Grav. IVA 2,5% | Q9: IVA 5% | R9: Neto Grav. IVA 5% | S9: IVA 10,5% | T9: Neto Grav. IVA 10,5% | U9: IVA 21% | V9: Neto Grav. IVA 21% | W9: IVA 27% | X9: Neto Grav. IVA 27% | Y9: Neto Gravado Total | Z9: Neto No Gravado | AA9: Op. Exentas | AB9: Otros Tributos | AC9: Total IVA | AD9: Imp. Total | AE9: comp
A10: 01/10/2025 | B10: 1 - Factura A | C10: 500 | D10: 1791477 | E10: 1791477 | F10: 75397766663182 | G10: CUIT | H10: 30654118767 | I10: SOLUCIONES MULTIMEDIA S A | J10: CUIT | K10: 30710473168 | L10: 1 | M10: $ | U10: 34781 | V10: 165623.79 | Y10: 165623.79 | Z10: 0 | AA10: 0 | AB10: 6624.95 | AC10: 34781 | AD10: 207029.74
A11: 01/10/2025 | B11: 1 - Factura A | C11: 2059 | D11: 34131 | E11: 34131 | F11: 75406205517570 | G11: CUIT | H11: 30548083156 | I11: COTO CENTRO INTEGRAL DE COMERCIALIZACION SOCIEDAD ANONIMA | J11: CUIT | K11: 30710473168 | L11: 1 | M11: $ | U11: 1150.88 | V11: 5480.36 | Y11: 5480.36 | Z11: 0 | AA11: 0 | AB11: 383.62 | AC11: 1150.88 | AD11: 7014.86
A12: 01/10/2025 | B12: 1 - Factura A | C12: 5 | D12: 1679 | E12: 1679 | F12: 75405209208340 | G12: CUIT | H12: 27265302225 | I12: PRADO MARISOL | J12: CUIT | K12: 30710473168 | L12: 1 | M12: $ | U12: 26250 | V12: 125000 | Y12: 125000 | Z12: 0 | AA12: 0 | AB12: 0 | AC12: 26250 | AD12: 151250
A13: 01/10/2025 | B13: 1 - Factura A | C13: 1 | D13: 140551 | E13: 140551 | F13: 75409140621749 | G13: CUIT | H13: 30714864269 | I13: CONTABILIUM S.A. S. A. | J13: CUIT | K13: 30710473168 | L13: 1 | M13: $ | U13: 38808 | V13: 184800 | Y13: 184800 | Z13: 0 | AA13: 0 | AB13: 0 | AC13: 38808 | AD13: 223608
A14: 01/10/2025 | B14: 1 - Factura A | C14: 5 | D14: 1680 | E14: 1680 | F14: 75405214018996 | G14: CUIT | H14: 27265302225 | I14: PRADO MARISOL | J14: CUIT | K14: 30710473168 | L14: 1 | M14: $ | U14: 294000 | V14: 1400000 | Y14: 1400000 | Z14: 0 | AA14: 0 | AB14: 0 | AC14: 294000 | AD14: 1694000
A15: 01/10/2025 | B15: 1 - Factura A | C15: 5 | D15: 1676 | E15: 1676 | F15: 75405186336334 | G15: CUIT | H15: 27265302225 | I15: PRADO MARISOL | J15: CUIT | K15: 30710473168 | L15: 1 | M15: $ | U15: 525000 | V15: 2500000 | Y15: 2500000 | Z15: 0 | AA15: 0 | AB15: 0 | AC15: 525000 | AD15: 3025000
A16: 01/10/2025 | B16: 1 - Factura A | C16: 6 | D16: 96490 | E16: 96490 | F16: 75404218156994 | G16: CUIT | H16: 30711553564 | I16: SALUDTEX SA | J16: CUIT | K16: 30710473168 | L16: 1 | M16: $ | U16: 279778.59 | V16: 1332279 | Y16: 1332279 | Z16: 0 | AA16: 0 | AB16: 0 | AC16: 279778.59 | AD16: 1612057.6
A17: 01/10/2025 | B17: 1 - Factura A | C17: 6 | D17: 96491 | E17: 96491 | F17: 75404218271756 | G17: CUIT | H17: 30711553564 | I17: SALUDTEX SA | J17: CUIT | K17: 30710473168 | L17: 1 | M17: $ | U17: 147536.55 | V17: 702555 | Y17: 702555 | Z17: 0 | AA17: 0 | AB17: 0 | AC17: 147536.55 | AD17: 850091.55
A18: 01/10/2025 | B18: 1 - Factura A | C18: 6 | D18: 96492 | E18: 96492 | F18: 75404218424004 | G18: CUIT | H18: 30711553564 | I18: SALUDTEX SA | J18: CUIT | K18: 30710473168 | L18: 1 | M18: $ | U18: 6460.65 | V18: 30765 | Y18: 30765 | Z18: 0 | AA18: 0 | AB18: 0 | AC18: 6460.65 | AD18: 37225.65
A19: 15/10/2025 | B19: 1 - Factura A | C19: 50 | D19: 4670040 | E19: 4670040 | F19: 75426230181879 | G19: CUIT | H19: 30714112836 | I19: AUTOPISTAS DE BUENOS AIRES (AUBASA) SA S. A. | J19: CUIT | K19: 30710473168 | L19: 1 | M19: $ | U19: 1031.36 | V19: 4911.22 | Y19: 4911.22 | Z19: 0 | AA19: 0 | AB19: 147.34 | AC19: 1031.36 | AD19: 6089.92
A20: 31/10/2025 | B20: 1 - Factura A | C20: 50 | D20: 4706524 | E20: 4706524 | F20: 75446229190253 | G20: CUIT | H20: 30714112836 | I20: AUTOPISTAS DE BUENOS AIRES (AUBASA) SA S. A. | J20: CUIT | K20: 30710473168 | L20: 1 | M20: $ | U20: 343.78 | V20: 1637.07 | Y20: 1637.07 | Z20: 0 | AA20: 0 | AB20: 0 | AC20: 343.78 | AD20: 1980.85 | AE20: sin comp
A21: 01/10/2025 | B21: 1 - Factura A | C21: 2 | D21: 252 | E21: 252 | F21: 75402211250599 | G21: CUIT | H21: 30605344352 | I21: CONSORCIO BARTOLOME MITRE 2466 | J21: CUIT | K21: 30710473168 | L21: 1 | M21: $ | U21: 453722.01 | V21: 2160581 | Y21: 2160581 | Z21: 0 | AA21: 0 | AB21: 0 | AC21: 453722.01 | AD21: 2614303
A22: 01/10/2025 | B22: 3 - Nota de Crédito A | C22: 5 | D22: 131 | E22: 131 | F22: 75405208440708 | G22: CUIT | H22: 27265302225 | I22: PRADO MARISOL | J22: CUIT | K22: 30710473168 | L22: 1 | M22: $ | U22: 525000 | V22: 2500000 | Y22: 2500000 | Z22: 0 | AA22: 0 | AB22: 0 | AC22: 525000 | AD22: 3025000
A23: 01/10/2025 | B23: 3 - Nota de Crédito A | C23: 6 | D23: 13998 | E23: 13998 | F23: 75404232088366 | G23: CUIT | H23: 30711553564 | I23: SALUDTEX SA | J23: CUIT | K23: 30710473168 | L23: 1 | M23: $ | U23: 28978.11 | V23: 137991 | Y23: 137991 | Z23: 0 | AA23: 0 | AB23: 0 | AC23: 28978.11 | AD23: 166969.11
A24: 01/10/2025 | B24: 11 - Factura C | C24: 4 | D24: 67 | E24: 67 | F24: 75403183061118 | G24: CUIT | H24: 20086277523 | I24: GUASCH HECTOR RAUL | J24: CUIT | K24: 30710473168 | L24: 1 | M24: $ | AB24: 0 | AD24: 300000
A25: 01/10/2025 | B25: 11 - Factura C | C25: 4 | D25: 66 | E25: 66 | F25: 75403179949716 | G25: CUIT | H25: 20086277523 | I25: BOTINDARI JUAN CARLOS | J25: CUIT | K25: 30710473168 | L25: 1 | M25: $ | AB25: 0 | AD25: 300000
A26: 01/10/2025 | B26: 13 - Nota de Crédito C | C26: 4 | D26: 2 | E26: 2 | F26: 75403184483403 | G26: CUIT | H26: 20086277523 | I26: BOTINDARI JUAN CARLOS | J26: CUIT | K26: 30710473168 | L26: 1 | M26: $ | AB26: 0 | AD26: 300000
A27: 02/10/2025 | B27: 1 - Factura A | C27: 3051 | D27: 982461 | E27: 982461 | F27: 75407377852221 | G27: CUIT | H27: 30678814357 | I27: TELEFONICA MOVILES ARGENTINA SOCIEDAD ANONIMA | J27: CUIT | K27: 30710473168 | L27: 1 | M27: $ | W27: 15634.89 | X27: 57907 | Y27: 57907 | Z27: 0 | AA27: 0 | AB27: 7223.1 | AC27: 15634.89 | AD27: 80764.99
A28: 02/10/2025 | B28: 1 - Factura A | C28: 8 | D28: 476 | E28: 476 | F28: 75404371927575 | G28: CUIT | H28: 30643518364 | I28: FARMACIA DE MEDRANO 533 SOCIEDAD EN COMANDITA SIMPLE | J28: CUIT | K28: 30710473168 | L28: 1 | M28: $ | U28: 18637.5 | V28: 88750 | Y28: 88750 | Z28: 0 | AA28: 0 | AB28: 0 | AC28: 18637.5 | AD28: 107387.5
A29: 02/10/2025 | B29: 1 - Factura A | C29: 2 | D29: 1576 | E29: 1576 | F29: 75409356956133 | G29: CUIT | H29: 20272865869 | I29: DI FEO MARTIN EZEQUIEL | J29: CUIT | K29: 30710473168 | L29: 1 | M29: $ | U29: 14574 | V29: 69400 | Y29: 69400 | Z29: 0 | AA29: 0 | AB29: 0 | AC29: 14574 | AD29: 83974
A30: 02/10/2025 | B30: 1 - Factura A | C30: 17 | D30: 13744 | E30: 13744 | F30: 75400375536461 | G30: CUIT | H30: 30661143610 | I30: ORTOPEDIA BERNAT SRL | J30: CUIT | K30: 30710473168 | L30: 1 | M30: $ | U30: 21588 | V30: 102800 | Y30: 102800 | Z30: 0 | AA30: 0 | AB30: 4112 | AC30: 21588 | AD30: 128500
A31: 02/10/2025 | B31: 1 - Factura A | C31: 4 | D31: 19861 | E31: 19861 | F31: 75403288996009 | G31: CUIT | H31: 30714440183 | I31: INDUSTRIAS FERNANDEZ GARRIDO SA | J31: CUIT | K31: 30710473168 | L31: 1 | M31: $ | U31: 5684.76 | V31: 27070.3 | Y31: 27070.3 | Z31: 0 | AA31: 0 | AB31: 0 | AC31: 5684.76 | AD31: 32755.06
A32: 02/10/2025 | B32: 1 - Factura A | C32: 1 | D32: 1031096 | E32: 1031096 | F32: 75419072334708 | G32: CUIT | H32: 33716307749 | I32: VERISURE ARGENTINA MONITOREO DE ALARMAS SA | J32: CUIT | K32: 30710473168 | L32: 1 | M32: $ | U32: 13093.29 | V32: 62349.01 | Y32: 62349.01 | Z32: 0 | AA32: 0 | AB32: 2493.96 | AC32: 13093.29 | AD32: 77936.26
A33: 02/10/2025 | B33: 1 - Factura A | C33: 7 | D33: 55 | E33: 55 | F33: 75403337698338 | G33: CUIT | H33: 27325223273 | I33: SOUSA ALDERETE ALEJANDRA MABEL | J33: CUIT | K33: 30710473168 | L33: 1 | M33: $ | U33: 462000 | V33: 2200000 | Y33: 2200000 | Z33: 0 | AA33: 0 | AB33: 0 | AC33: 462000 | AD33: 2662000
A34: 02/10/2025 | B34: 11 - Factura C | C34: 1 | D34: 43 | E34: 43 | F34: 75401342703675 | G34: CUIT | H34: 20311855671 | I34: GUASCH HECTOR RAUL | J34: CUIT | K34: 30710473168 | L34: 1 | M34: $ | AB34: 0 | AD34: 290000
A35: 03/10/2025 | B35: 1 - Factura A | C35: 2 | D35: 1582 | E35: 1582 | F35: 75409440515122 | G35: CUIT | H35: 20272865869 | I35: DI FEO MARTIN EZEQUIEL | J35: CUIT | K35: 30710473168 | L35: 1 | M35: $ | U35: 64932 | V35: 309200 | Y35: 309200 | Z35: 0 | AA35: 0 | AB35: 0 | AC35: 64932 | AD35: 374132
A36: 03/10/2025 | B36: 1 - Factura A | C36: 26 | D36: 215680 | E36: 215680 | F36: 75407512016610 | G36: CUIT | H36: 30708847247 | I36: EXPRESO LANCIONI S.A. | J36: CUIT | K36: 30710473168 | L36: 1 | M36: $ | U36: 15703.62 | V36: 74779.14 | Y36: 74779.14 | Z36: 0 | AA36: 0 | AB36: 2991.17 | AC36: 15703.62 | AD36: 93473.93
A37: 03/10/2025 | B37: 1 - Factura A | C37: 5 | D37: 1682 | E37: 1682 | F37: 75405522210939 | G37: CUIT | H37: 27265302225 | I37: PRADO MARISOL | J37: CUIT | K37: 30710473168 | L37: 1 | M37: $ | U37: 262500 | V37: 1250000 | Y37: 1250000 | Z37: 0 | AA37: 0 | AB37: 0 | AC37: 262500 | AD37: 1512500
A38: 03/10/2025 | B38: 1 - Factura A | C38: 1054 | D38: 381 | E38: 381 | F38: 75401449551620 | G38: CUIT | H38: 30685849751 | I38: DIA ARGENTINA S A | J38: CUIT | K38: 30710473168 | L38: 1 | M38: $ | U38: 1133.31 | V38: 5396.69 | Y38: 5396.69 | Z38: 0 | AA38: 0 | AB38: 215.87 | AC38: 1133.31 | AD38: 6745.87
A39: 03/10/2025 | B39: 1 - Factura A | C39: 3 | D39: 930 | E39: 930 | F39: 75409454635742 | G39: CUIT | H39: 23076996989 | I39: GIULIETTI LUIS ALBERTO | J39: CUIT | K39: 30710473168 | L39: 1 | M39: $ | U39: 2776.86 | V39: 13223.14 | Y39: 13223.14 | Z39: 0 | AA39: 0 | AB39: 0 | AC39: 2776.86 | AD39: 16000
A40: 03/10/2025 | B40: 3 - Nota de Crédito A | C40: 5 | D40: 132 | E40: 132 | F40: 75405520316587 | G40: CUIT | H40: 27265302225 | I40: PRADO MARISOL | J40: CUIT | K40: 30710473168 | L40: 1 | M40: $ | U40: 26250 | V40: 125000 | Y40: 125000 | Z40: 0 | AA40: 0 | AB40: 0 | AC40: 26250 | AD40: 151250
A41: 03/10/2025 | B41: 11 - Factura C | C41: 2 | D41: 634 | E41: 634 | F41: 75407495074987 | G41: CUIT | H41: 20247881957 | I41: CAMPA DANIEL JORGE | J41: CUIT | K41: 30710473168 | L41: 1 | M41: $ | AB41: 0 | AD41: 13400
A42: 04/10/2025 | B42: 11 - Factura C | C42: 2 | D42: 138 | E42: 138 | F42: 75408636655570 | G42: CUIT | H42: 27315710508 | I42: RIVERO GABRIELA ROCIO | J42: CUIT | K42: 30710473168 | L42: 1 | M42: $ | AB42: 0 | AD42: 51030
...

Sheet Hoja7
A2: Fecha | B2: Tipo | C2: Punto de Venta | D2: Número Desde | E2: Denominación Emisor | F2: CUIT EMISOR | H2: Tipo Doc. Emisor | I2: Nro. Doc. Emisor | K2: Tipo Doc. Receptor | L2: Nro. Doc. Receptor | M2: Tipo Cambio | N2: IVA 10,5% | O2: Neto Grav. IVA 10,5% | P2: IVA 21% | Q2: Neto Grav. IVA 21% | R2: IVA 27% | S2: Neto Grav. IVA 27% | T2: Neto Gravado Total | U2: Neto No Gravado | V2: Op. Exentas | W2: Otros Tributos | X2: Total IVA | Y2: Imp. Total
A3: 03/11/2025 | B3: 11 - Factura C | C3: 4 | D3: 80 | E3: BOTINDARI JUAN CARLOS | F3: 20086277523 | H3: CUIT | I3: 20086277523 | K3: CUIT | L3: 30710473168 | M3: 1 | W3: 0 | Y3: 300000
A4: 03/11/2025 | B4: 03/11/2025 | C4: 03/11/2025 | D4: FCC 00004-00000080 | E4: JUAN CARLOS BOTINDARI | F4: 20086277523 | G4: MO | H4: 0 | I4: 0 | J4: 0 | K4: 0 | L4: 0 | M4: 0 | N4: 300000 | O4: 0 | P4: 0 | Q4: 0 | R4: 0 | S4: 0 | T4: 0 | U4: 0 | V4: 300000 | W4: Bienes | Y4: 300000
A5: 05/11/2025 | B5: 1 - Factura A | C5: 4 | D5: 138 | E5: NARDOMARINO EDUARDO FRANCISCO | F5: 20174004146 | H5: CUIT | I5: 20174004146 | K5: CUIT | L5: 30710473168 | M5: 1 | P5: 56700 | Q5: 270000 | T5: 270000 | U5: 0 | V5: 0 | W5: 0 | X5: 56700 | Y5: 326700
A6: 17/11/2025 | B6: 1 - Factura A | C6: 4 | D6: 141 | E6: NARDOMARINO EDUARDO FRANCISCO | F6: 20174004146 | H6: CUIT | I6: 20174004146 | K6: CUIT | L6: 30710473168 | M6: 1 | P6: 58800 | Q6: 280000 | T6: 280000 | U6: 0 | V6: 0 | W6: 0 | X6: 58800 | Y6: 338800
A7: 18/11/2025 | B7: 1 - Factura A | C7: 4 | D7: 142 | E7: NARDOMARINO EDUARDO FRANCISCO | F7: 20174004146 | H7: CUIT | I7: 20174004146 | K7: CUIT | L7: 30710473168 | M7: 1 | P7: 69825 | Q7: 332500 | T7: 332500 | U7: 0 | V7: 0 | W7: 0 | X7: 69825 | Y7: 402325
A8: 20/11/2025 | B8: 1 - Factura A | C8: 4 | D8: 143 | E8: NARDOMARINO EDUARDO FRANCISCO | F8: 20174004146 | H8: CUIT | I8: 20174004146 | K8: CUIT | L8: 30710473168 | M8: 1 | P8: 55125 | Q8: 262500 | T8: 262500 | U8: 0 | V8: 0 | W8: 0 | X8: 55125 | Y8: 317625
A9: 05/11/2025 | B9: 05/11/2025 | C9: 05/11/2025 | D9: FCA 00004-00000138 | E9: EDUARDO FRANCISCO NARDOMARINO | F9: 20174004146 | G9: RI | H9: 0 | I9: 0 | J9: 0 | K9: 270000 | L9: 0 | M9: 0 | N9: 0 | O9: 56700 | P9: 0 | Q9: 0 | R9: 0 | S9: 0 | T9: 0 | U9: 0 | V9: 326700 | W9: Servicios | Y9: 326700
A10: 27/11/2025 | B10: 11 - Factura C | C10: 9 | D10: 197 | E10: CORRAO HECTOR RUBEN | F10: 20233248283 | H10: CUIT | I10: 20233248283 | K10: CUIT | L10: 30710473168 | M10: 1 | W10: 0 | Y10: 525000
A11: 27/11/2025 | B11: 27/11/2025 | C11: 27/11/2025 | D11: FCC 00009-00000197 | E11: HECTOR RUBEN CORRAO | F11: 20233248283 | G11: MO | H11: 0 | I11: 0 | J11: 0 | K11: 0 | L11: 0 | M11: 0 | N11: 525000 | O11: 0 | P11: 0 | Q11: 0 | R11: 0 | S11: 0 | T11: 0 | U11: 0 | V11: 525000 | Y11: 525000
A12: 11/11/2025 | B12: 1 - Factura A | C12: 9 | D12: 1686 | E12: IALLONARDO SERGIO ALEJANDRO | F12: 20242126158 | H12: CUIT | I12: 20242126158 | K12: CUIT | L12: 30710473168 | M12: 1 | P12: 29400 | Q12: 140000 | T12: 140000 | U12: 0 | V12: 0 | W12: 0 | X12: 29400 | Y12: 169400
A13: 11/11/2025 | B13: 11/11/2025 | C13: 11/11/2025 | D13: FCA 00009-00001686 | E13: SERGIO ALEJANDRO IALLONARDO | F13: 20242126158 | G13: RI | H13: 0 | I13: 0 | J13: 0 | K13: 140000 | L13: 0 | M13: 0 | N13: 0 | O13: 29400 | P13: 0 | Q13: 0 | R13: 0 | S13: 0 | T13: 0 | U13: 0 | V13: 169400 | W13: Bienes | Y13: 169400
A14: 13/11/2025 | B14: 1 - Factura A | C14: 6 | D14: 1672 | E14: VENTO HUGO GABRIEL | F14: 20247225243 | H14: CUIT | I14: 20247225243 | K14: CUIT | L14: 30710473168 | M14: 1 | P14: 34216.14 | Q14: 162934 | T14: 162934 | U14: 0 | V14: 0 | W14: 0 | X14: 34216.14 | Y14: 197150.14
A15: 21/11/2025 | B15: 1 - Factura A | C15: 6 | D15: 1679 | E15: VENTO HUGO GABRIEL | F15: 20247225243 | H15: CUIT | I15: 20247225243 | K15: CUIT | L15: 30710473168 | M15: 1 | P15: 17507.28 | Q15: 83368 | T15: 83368 | U15: 0 | V15: 0 | W15: 0 | X15: 17507.28 | Y15: 100875.28
A16: 25/11/2025 | B16: 1 - Factura A | C16: 6 | D16: 1684 | E16: VENTO HUGO GABRIEL | F16: 20247225243 | H16: CUIT | I16: 20247225243 | K16: CUIT | L16: 30710473168 | M16: 1 | P16: 29595.72 | Q16: 140932 | T16: 140932 | U16: 0 | V16: 0 | W16: 0 | X16: 29595.72 | Y16: 170527.72
A17: 13/11/2025 | B17: 13/11/2025 | C17: 45974 | D17: FCA 00006-00001672 | E17: HUGO GABRIEL VENTO | F17: 20247225243 | G17: RI | H17: 0 | I17: 0 | J17: 0 | K17: 162934 | L17: 0 | M17: 0 | N17: 0 | O17: 34216.14 | P17: 0 | Q17: 0 | R17: 0 | S17: 0 | T17: 0 | U17: 0 | V17: 197150.14 | W17: Bienes | Y17: 197150.14
A18: 25/11/2025 | B18: 25/11/2025 | C18: 45986 | D18: FCA 00006-00001684 | E18: HUGO GABRIEL VENTO | F18: 20247225243 | G18: RI | H18: 0 | I18: 0 | J18: 0 | K18: 140932 | L18: 0 | M18: 0 | N18: 0 | O18: 29595.72 | P18: 0 | Q18: 0 | R18: 0 | S18: 0 | T18: 0 | U18: 0 | V18: 170527.72 | W18: Bienes | Y18: 170527.72
A19: 21/11/2025 | B19: 21/11/2025 | C19: 45982 | D19: FCA 00006-00001679 | E19: HUGO GABRIEL VENTO | F19: 20247225243 | G19: RI | H19: 0 | I19: 0 | J19: 0 | K19: 83368 | L19: 0 | M19: 0 | N19: 0 | O19: 17507.28 | P19: 0 | Q19: 0 | R19: 0 | S19: 0 | T19: 0 | U19: 0 | V19: 100875.28 | W19: Bienes | Y19: 100875.28
A20: 10/11/2025 | B20: 11 - Factura C | C20: 2 | D20: 706 | E20: CAMPA DANIEL JORGE | F20: 20247881957 | H20: CUIT | I20: 20247881957 | K20: CUIT | L20: 30710473168 | M20: 1 | W20: 0 | Y20: 9700
A21: 27/11/2025 | B21: 11 - Factura C | C21: 2 | D21: 751 | E21: CAMPA DANIEL JORGE | F21: 20247881957 | H21: CUIT | I21: 20247881957 | K21: CUIT | L21: 30710473168 | M21: 1 | W21: 0 | Y21: 8500
A22: 10/11/2025 | B22: 10/11/2025 | C22: 10/11/2025 | D22: FCC 00002-00000706 | E22: DANIEL JORGE CAMPA | F22: 20247881957 | G22: MO | H22: 0 | I22: 0 | J22: 0 | K22: 0 | L22: 0 | M22: 0 | N22: 9700 | O22: 0 | P22: 0 | Q22: 0 | R22: 0 | S22: 0 | T22: 0 | U22: 0 | V22: 9700 | W22: Bienes | Y22: 9700
A23: 27/11/2025 | B23: 27/11/2025 | C23: 27/11/2025 | D23: FCC 00002-00000751 | E23: DANIEL JORGE CAMPA | F23: 20247881957 | G23: MO | H23: 0 | I23: 0 | J23: 0 | K23: 0 | L23: 0 | M23: 0 | N23: 8500 | O23: 0 | P23: 0 | Q23: 0 | R23: 0 | S23: 0 | T23: 0 | U23: 0 | V23: 8500 | W23: Bienes | Y23: 8500
A24: 06/11/2025 | B24: 1 - Factura A | C24: 2 | D24: 1649 | E24: DI FEO MARTIN EZEQUIEL | F24: 20272865869 | H24: CUIT | I24: 20272865869 | K24: CUIT | L24: 30710473168 | M24: 1 | P24: 22953 | Q24: 109300 | T24: 109300 | U24: 0 | V24: 0 | W24: 0 | X24: 22953 | Y24: 132253
A25: 12/11/2025 | B25: 1 - Factura A | C25: 2 | D25: 1667 | E25: DI FEO MARTIN EZEQUIEL | F25: 20272865869 | H25: CUIT | I25: 20272865869 | K25: CUIT | L25: 30710473168 | M25: 1 | P25: 26544 | Q25: 126400 | T25: 126400 | U25: 0 | V25: 0 | W25: 0 | X25: 26544 | Y25: 152944
A26: 14/11/2025 | B26: 1 - Factura A | C26: 2 | D26: 1673 | E26: DI FEO MARTIN EZEQUIEL | F26: 20272865869 | H26: CUIT | I26: 20272865869 | K26: CUIT | L26: 30710473168 | M26: 1 | P26: 4095 | Q26: 19500 | T26: 19500 | U26: 0 | V26: 0 | W26: 0 | X26: 4095 | Y26: 23595
A27: 14/11/2025 | B27: 14/11/2025 | C27: FCA 00002-00001673 | E27: DI FEO MARTIN EZEQUIEL | F27: 20272865869 | G27: 0 | H27: 0 | I27: 0 | J27: 19500 | K27: 0 | L27: 0 | M27: 0 | N27: 4095 | O27: 0 | P27: 0 | Q27: 0 | R27: 0 | S27: 0 | T27: 0 | U27: 23595 | V27: Bienes | W27: Buenos Aires | X27: Sin comprobante | Y27: 23595 | Z27: Sin comprobante
A28: 19/11/2025 | B28: 1 - Factura A | C28: 2 | D28: 1686 | E28: DI FEO MARTIN EZEQUIEL | F28: 20272865869 | H28: CUIT | I28: 20272865869 | K28: CUIT | L28: 30710473168 | M28: 1 | P28: 31647 | Q28: 150700 | T28: 150700 | U28: 0 | V28: 0 | W28: 0 | X28: 31647 | Y28: 182347
A29: 20/11/2025 | B29: 1 - Factura A | C29: 2 | D29: 1687 | E29: DI FEO MARTIN EZEQUIEL | F29: 20272865869 | H29: CUIT | I29: 20272865869 | K29: CUIT | L29: 30710473168 | M29: 1 | P29: 3297 | Q29: 15700 | T29: 15700 | U29: 0 | V29: 0 | W29: 0 | X29: 3297 | Y29: 18997
A30: 28/11/2025 | B30: 1 - Factura A | C30: 2 | D30: 1697 | E30: DI FEO MARTIN EZEQUIEL | F30: 20272865869 | H30: CUIT | I30: 20272865869 | K30: CUIT | L30: 30710473168 | M30: 1 | P30: 27511.91 | Q30: 131009.09 | T30: 131009.09 | U30: 0 | V30: 0 | W30: 0 | X30: 27511.91 | Y30: 158521
A31: 06/11/2025 | B31: 06/11/2025 | C31: 06/11/2025 | D31: FCA 00002-00001649 | E31: MARTIN EZEQUIEL DI FEO | F31: 20272865869 | G31: RI | H31: 0 | I31: 0 | J31: 0 | K31: 109300 | L31: 0 | M31: 0 | N31: 0 | O31: 22953 | P31: 0 | Q31: 0 | R31: 0 | S31: 0 | T31: 0 | U31: 0 | V31: 132253 | W31: Bienes | Y31: 132253
A32: 12/11/2025 | B32: 12/11/2025 | C32: 12/11/2025 | D32: FCA 00002-00001667 | E32: MARTIN EZEQUIEL DI FEO | F32: 20272865869 | G32: RI | H32: 0 | I32: 0 | J32: 0 | K32: 126400 | L32: 0 | M32: 0 | N32: 0 | O32: 26544 | P32: 0 | Q32: 0 | R32: 0 | S32: 0 | T32: 0 | U32: 0 | V32: 152944 | W32: Bienes | Y32: 152944
A33: 20/11/2025 | B33: 20/11/2025 | C33: 45981 | D33: FCA 00002-00001687 | E33: MARTIN EZEQUIEL DI FEO | F33: 20272865869 | G33: RI | H33: 0 | I33: 0 | J33: 0 | K33: 15700 | L33: 0 | M33: 0 | N33: 0 | O33: 3297 | P33: 0 | Q33: 0 | R33: 0 | S33: 0 | T33: 0 | U33: 0 | V33: 18997 | W33: Bienes | Y33: 18997
A34: 19/11/2025 | B34: 19/11/2025 | C34: 45980 | D34: FCA 00002-00001686 | E34: MARTIN EZEQUIEL DI FEO | F34: 20272865869 | G34: RI | H34: 0 | I34: 0 | J34: 0 | K34: 150700 | L34: 0 | M34: 0 | N34: 0 | O34: 31647 | P34: 0 | Q34: 0 | R34: 0 | S34: 0 | T34: 0 | U34: 0 | V34: 182347 | W34: Bienes | Y34: 182347
A35: 28/11/2025 | B35: 28/11/2025 | C35: 28/11/2025 | D35: FCA 00002-00001697 | E35: MARTIN EZEQUIEL DI FEO | F35: 20272865869 | G35: RI | H35: 0 | I35: 0 | J35: 0 | K35: 131009.09 | L35: 0 | M35: 0 | N35: 0 | O35: 27511.91 | P35: 0 | Q35: 0 | R35: 0 | S35: 0 | T35: 0 | U35: 0 | V35: 158521 | W35: Bienes | Y35: 158521
A36: 03/11/2025 | B36: 1 - Factura A | C36: 4 | D36: 41612 | E36: LEDESMA EMILIANO RUBEN | F36: 20289111329 | H36: CUIT | I36: 20289111329 | K36: CUIT | L36: 30710473168 | M36: 1 | P36: 357940.09 | Q36: 1704476.6 | T36: 1704476.6 | U36: 0 | V36: 0 | W36: 0 | X36: 357940.09 | Y36: 2062416.7
A37: 28/11/2025 | B37: 1 - Factura A | C37: 4 | D37: 41808 | E37: LEDESMA EMILIANO RUBEN | F37: 20289111329 | H37: CUIT | I37: 20289111329 | K37: CUIT | L37: 30710473168 | M37: 1 | P37: 12700.8 | Q37: 60480 | T37: 60480 | U37: 0 | V37: 0 | W37: 0 | X37: 12700.8 | Y37: 73180.8
A38: 03/11/2025 | B38: 03/11/2025 | C38: 14/11/2025 | D38: FCA 00004-00041612 | E38: EMILIANO RUBEN LEDESMA | F38: 20289111329 | G38: RI | H38: 0 | I38: 0 | J38: 0 | K38: 1704476.6 | L38: 0 | M38: 0 | N38: 0 | O38: 357940.09 | P38: 0 | Q38: 0 | R38: 0 | S38: 0 | T38: 0 | U38: 0 | V38: 2062416.7 | W38: Bienes | Y38: 2062416.7
A39: 28/11/2025 | B39: 28/11/2025 | C39: 28/11/2025 | D39: FCA 00004-00041808 | E39: EMILIANO RUBEN LEDESMA | F39: 20289111329 | G39: RI | H39: 0 | I39: 0 | J39: 0 | K39: 60480 | L39: 0 | M39: 0 | N39: 0 | O39: 12700.8 | P39: 0 | Q39: 0 | R39: 0 | S39: 0 | T39: 0 | U39: 0 | V39: 73180.8 | W39: Bienes | Y39: 73180.8
A40: 13/11/2025 | B40: 11 - Factura C | C40: 3 | D40: 15 | E40: OVIEDO LUIS ALBERTO | F40: 20310489930 | H40: CUIT | I40: 20310489930 | K40: CUIT | L40: 30710473168 | M40: 1 | W40: 0 | Y40: 540580
A41: 28/11/2025 | B41: 11 - Factura C | C41: 3 | D41: 16 | E41: OVIEDO LUIS ALBERTO | F41: 20310489930 | H41: CUIT | I41: 20310489930 | K41: CUIT | L41: 30710473168 | M41: 1 | W41: 0 | Y41: 383580
...
