Workbook

Sheet Lista_CUIT
A1: CUIT | B1: RAZON SOCIAL | C1: Tipo de Gasto | D1: PROVINCIA
A2: 20174004146 | B2: EDUEARDO FRANCISCO NARDOMARINO | C2: FLETE | G2: Mercaderia
A3: 30708555548 | B3: AGH S.A | C3: Insumo | G3: Servicios Gas, Luz, etc.
A4: 20270821 | B4: AGOSTINO, ANA CAROLINA | G4: Gastos catering
A5: 30641659106 | B5: AGRISOL SA | C5: INSUMO | G5: Combustibe
A6: 30709565075 | B6: AGUA Y SANEAMIENTOS ARG SA | C6: SERVICIOS | G6: Gastos Varios
A7: 18149370 | B7: AGÜERO, PATRICIA ALEJANDRA | G7: Gastos seguridad
A8: 20273107526 | B8: AGUERRIDO NAZARENO ISMAEL | G8: Librería
A9: 4399520 | B9: Aguiar Elvira | G9: Gastos mantenimiento
A10: 18139117 | B10: Aguilar Omar Adolfo | G10: Gastos comercializacion
A11: 8208160 | B11: Aguirre Diego | G11: Alquiler
A12: 29803614 | B12: Aguirre Rodrigo | G12: Honorarios contables
A13: 33109633 | B13: AGUIRRE SERGIO SEBASTIAN | G13: Gastos administrativos
A14: 7419183 | B14: AISEMBERG FREDY | G14: Seguro
A15: 30500229973 | B15: AKIAN GRAFICA EDITORA SA | C15: Insumo | G15: Extracto
A16: 33709914109 | B16: ALAN COLLECTION SA | C16: MERCADERIA | G16: Flete
A17: 30710799241 | B17: ALANAR S.R.L. | G17: Honorarios Legales
A18: 20469052 | B18: ALARCON CAPRA, KARINA ANDREA | G18: Insumo
A19: 20267161616 | B19: ALBAJARI DIEGO MARCOS | C19: Gastos Varios | G19: Muebles y Utiles
A20: 30628205090 | B20: ALBAMIE SA | C20: CLIENTE | G20: Otros
A21: 30628205090 | B21: ALBAMIE SA | C21: CLIENTE | G21: Telefonia
A22: 7375725 | B22: ALBANESE, ARTURO ANTONIO | G22: Alojamiento-Varios
A23: 4049033 | B23: Aldazabal Martin Claudio
A24: 10121438 | B24: ALDO SODANO
A25: 5804480 | B25: ALEJANDRA SIFFREDI TORRES SANMARCO
A26: 35376990 | B26: ALEJANDRO DANIEL TORRES
A27: 20236101127 | B27: ALEJANDRO DARIO LOPEZ
A28: 20291929126 | B28: ALEJANDRO MIGUEL DAUBLER
A29: 26472781 | B29: ALEJANDRO, ULISES ISAAC
A30: 30645337979 | B30: ALEXANDER FLEMING SA
A31: 30709604887 | B31: ALFABIS SRL. | C31: Mantenimiento
A32: 4171382 | B32: Alfano Alberico Alejandro
A33: 30711573999 | B33: Alfar Construcciones SA
A34: 20083925680 | B34: ALFREDO DANIEL FERNANDEZ | C34: Gastos Varios
A35: 30656038752 | B35: ALFREDO OMAR POTENZA SRL | C35: INSUMO
A36: 30504563894 | B36: ALI HERMANOS SRL | C36: Insumo
A37: 3751602 | B37: Alicia Lemma
A38: 30602699826 | B38: ALKO SRL
A39: 30715190385 | B39: ALL FEDERAL SA.
A40: 28735023 | B40: ALLARIO, MARTIN EMANUEL
...

Sheet Ene-25
B1: LIBRO IVA COMPRAS | G1: ORTOPEDIA GEMINIS S.A. | N1: 45658
B3: TOTAL COMPRAS NETAS | G3: TOTAL CREDITO FISCAL | J3: TOTAL VENTAS NETAS | M3: TOTAL DEBITO FISCAL | P3: RESULTADO
B4: =SUM(compras_mes1[[#Totals],[NETO GRAVADO]])+extracto_banco_mes1[[#Totals],[NETO]] -> 38722844 | G4: =compras_mes1[[#Totals],[IVA 21 %]]+compras_mes1[[#Totals],[IVA 27%]]+compras_mes1[[#Totals],[IVA 10,5%]]+I133 -> 8069136 | J4: =venta_a_mes1[[#Totals],[IMPORTE NETO]]+ventas_b_mes1[[#Totals],[IMPORTE NETO]] -> 0 | M4: =venta_a_mes1[[#Totals],[IVA 21%]]+venta_a_mes1[[#Totals],[IVA 10,5%]]+ventas_b_mes1[[#Totals],[IVA 21%]]+ventas_b_mes1[[#Totals],[IVA 10,5%]] -> 0 | P4: =G4-M4 -> 8069136
B8: FECHA | C8: TIPO | D8: PTO VTA | E8: NRO. CPTE | F8: CUIT | G8: RAZON SOCIAL | H8: NETO GRAVADO | I8: IVA 21 % | J8: IVA 27% | K8: IVA 10,5% | L8: PERC. IVA | M8: PERC IIBB BS AS | N8: PERC. IIBB CABA | O8: Otros / No Grav. | P8: TOTAL | Q8: Tipo de Gasto | R8: Provincia
B9: 45658 | C9: 1 | D9: 711 | E9: 6577836 | F9: 30677237119 | G9: =IFERROR(IF(compras_mes1[[#This Row],[CUIT]]="","-",VLOOKUP(compras_mes1[[#This Row],[CUIT]],Lista_CUIT[#All],2,0)),"CUIT NO CARGADO") -> AUTOPISTAS DEL SOL SA | H9: 10053.15 | I9: =IF(compras_mes1[[#This Row],[NETO GRAVADO]]="","",compras_mes1[[#This Row],[NETO GRAVADO]]*0.21) -> 2111.1615 | O9: 301.59 | P9: =SUM(compras_mes1[[#This Row],[NETO GRAVADO]:[Otros / No Grav.]]) -> 12465.901 | Q9: =IFERROR(IF(compras_mes1[[#This Row],[CUIT]]="","-",VLOOKUP(compras_mes1[[#This Row],[CUIT]],Lista_CUIT[#All],3,0)),"CUIT NO CARGADO") -> Autopista | R9: =IFERROR(IF(compras_mes1[[#This Row],[CUIT]]="","-",VLOOKUP(compras_mes1[[#This Row],[CUIT]],Lista_CUIT[#All],4,0)),"CUIT NO CARGADO") -> 0
B10: 45658 | C10: 1 | D10: 629 | E10: 5740876 | F10: 30663498513 | G10: =IFERROR(IF(compras_mes1[[#This Row],[CUIT]]="","-",VLOOKUP(compras_mes1[[#This Row],[CUIT]],Lista_CUIT[#All],2,0)),"CUIT NO CARGADO") -> GRUPO CONCES. DEL OESTE SA | H10: 4968.79 | I10: =IF(compras_mes1[[#This Row],[NETO GRAVADO]]="","",compras_mes1[[#This Row],[NETO GRAVADO]]*0.21) -> 1043.4459 | P10: =SUM(compras_mes1[[#This Row],[NETO GRAVADO]:[Otros / No Grav.]]) -> 6012.2359 | Q10: =IFERROR(IF(compras_mes1[[#This Row],[CUIT]]="","-",VLOOKUP(compras_mes1[[#This Row],[CUIT]],Lista_CUIT[#All],3,0)),"CUIT NO CARGADO") -> Autopista | R10: =IFERROR(IF(compras_mes1[[#This Row],[CUIT]]="","-",VLOOKUP(compras_mes1[[#This Row],[CUIT]],Lista_CUIT[#All],4,0)),"CUIT NO CARGADO") -> 0
B11: 45659 | C11: 1 | D11: 500 | E11: 1671509 | F11: 30654118767 | G11: =IFERROR(IF(compras_mes1[[#This Row],[CUIT]]="","-",VLOOKUP(compras_mes1[[#This Row],[CUIT]],Lista_CUIT[#All],2,0)),"CUIT NO CARGADO") -> SOLUCIONES MULTIMEDIA SA | H11: 109168.92 | I11: =IF(compras_mes1[[#This Row],[NETO GRAVADO]]="","",compras_mes1[[#This Row],[NETO GRAVADO]]*0.21) -> 22925.473 | P11: =SUM(compras_mes1[[#This Row],[NETO GRAVADO]:[Otros / No Grav.]]) -> 132094.39 | Q11: =IFERROR(IF(compras_mes1[[#This Row],[CUIT]]="","-",VLOOKUP(compras_mes1[[#This Row],[CUIT]],Lista_CUIT[#All],3,0)),"CUIT NO CARGADO") -> gastos varios | R11: =IFERROR(IF(compras_mes1[[#This Row],[CUIT]]="","-",VLOOKUP(compras_mes1[[#This Row],[CUIT]],Lista_CUIT[#All],4,0)),"CUIT NO CARGADO") -> 0
B12: 45659 | C12: 1 | D12: 3 | E12: 4390 | F12: 20184052858 | G12: =IFERROR(IF(compras_mes1[[#This Row],[CUIT]]="","-",VLOOKUP(compras_mes1[[#This Row],[CUIT]],Lista_CUIT[#All],2,0)),"CUIT NO CARGADO") -> ABOUD PABLO DANIEL | H12: 54214.86 | I12: =IF(compras_mes1[[#This Row],[NETO GRAVADO]]="","",compras_mes1[[#This Row],[NETO GRAVADO]]*0.21) -> 11385.121 | P12: =SUM(compras_mes1[[#This Row],[NETO GRAVADO]:[Otros / No Grav.]]) -> 65599.981 | Q12: =IFERROR(IF(compras_mes1[[#This Row],[CUIT]]="","-",VLOOKUP(compras_mes1[[#This Row],[CUIT]],Lista_CUIT[#All],3,0)),"CUIT NO CARGADO") -> Gastos Varios | R12: =IFERROR(IF(compras_mes1[[#This Row],[CUIT]]="","-",VLOOKUP(compras_mes1[[#This Row],[CUIT]],Lista_CUIT[#All],4,0)),"CUIT NO CARGADO") -> 0
B13: 45659 | C13: 1 | D13: 2 | E13: 1026 | F13: 20272865869 | G13: =IFERROR(IF(compras_mes1[[#This Row],[CUIT]]="","-",VLOOKUP(compras_mes1[[#This Row],[CUIT]],Lista_CUIT[#All],2,0)),"CUIT NO CARGADO") -> DI FEO MARTIN EZEQUIEL | H13: 47550 | I13: =IF(compras_mes1[[#This Row],[NETO GRAVADO]]="","",compras_mes1[[#This Row],[NETO GRAVADO]]*0.21) -> 9985.5 | P13: =SUM(compras_mes1[[#This Row],[NETO GRAVADO]:[Otros / No Grav.]]) -> 57535.5 | Q13: =IFERROR(IF(compras_mes1[[#This Row],[CUIT]]="","-",VLOOKUP(compras_mes1[[#This Row],[CUIT]],Lista_CUIT[#All],3,0)),"CUIT NO CARGADO") -> INSUMOS | R13: =IFERROR(IF(compras_mes1[[#This Row],[CUIT]]="","-",VLOOKUP(compras_mes1[[#This Row],[CUIT]],Lista_CUIT[#All],4,0)),"CUIT NO CARGADO") -> 0
B14: 45659 | C14: 1 | D14: 13 | E14: 955 | F14: 30714201286 | G14: =IFERROR(IF(compras_mes1[[#This Row],[CUIT]]="","-",VLOOKUP(compras_mes1[[#This Row],[CUIT]],Lista_CUIT[#All],2,0)),"CUIT NO CARGADO") -> T.I.M. TIME IS MONEY S.R.L. | H14: 125000 | I14: =IF(compras_mes1[[#This Row],[NETO GRAVADO]]="","",compras_mes1[[#This Row],[NETO GRAVADO]]*0.21) -> 26250 | P14: =SUM(compras_mes1[[#This Row],[NETO GRAVADO]:[Otros / No Grav.]]) -> 151250 | Q14: =IFERROR(IF(compras_mes1[[#This Row],[CUIT]]="","-",VLOOKUP(compras_mes1[[#This Row],[CUIT]],Lista_CUIT[#All],3,0)),"CUIT NO CARGADO") -> textil | R14: =IFERROR(IF(compras_mes1[[#This Row],[CUIT]]="","-",VLOOKUP(compras_mes1[[#This Row],[CUIT]],Lista_CUIT[#All],4,0)),"CUIT NO CARGADO") -> 0
B15: 45659 | C15: 1 | D15: 3051 | E15: 856129 | F15: 30678814357 | G15: =IFERROR(IF(compras_mes1[[#This Row],[CUIT]]="","-",VLOOKUP(compras_mes1[[#This Row],[CUIT]],Lista_CUIT[#All],2,0)),"CUIT NO CARGADO") -> TELEFONICA MOVILES ARG SA | H15: 58294 | J15: =compras_mes1[[#This Row],[NETO GRAVADO]]*27/100 -> 15739.38 | P15: =SUM(compras_mes1[[#This Row],[NETO GRAVADO]:[Otros / No Grav.]]) -> 74033.38 | Q15: =IFERROR(IF(compras_mes1[[#This Row],[CUIT]]="","-",VLOOKUP(compras_mes1[[#This Row],[CUIT]],Lista_CUIT[#All],3,0)),"CUIT NO CARGADO") -> SERVICIO | R15: =IFERROR(IF(compras_mes1[[#This Row],[CUIT]]="","-",VLOOKUP(compras_mes1[[#This Row],[CUIT]],Lista_CUIT[#All],4,0)),"CUIT NO CARGADO") -> 0
B16: 45660 | C16: 1 | D16: 120 | E16: 5451 | F16: 30587197215 | G16: =IFERROR(IF(compras_mes1[[#This Row],[CUIT]]="","-",VLOOKUP(compras_mes1[[#This Row],[CUIT]],Lista_CUIT[#All],2,0)),"CUIT NO CARGADO") -> PANATEL SOCIEDAD ANONIMA | H16: 95041.32 | I16: =IF(compras_mes1[[#This Row],[NETO GRAVADO]]="","",compras_mes1[[#This Row],[NETO GRAVADO]]*0.21) -> 19958.677 | P16: =SUM(compras_mes1[[#This Row],[NETO GRAVADO]:[Otros / No Grav.]]) -> 115000 | Q16: =IFERROR(IF(compras_mes1[[#This Row],[CUIT]]="","-",VLOOKUP(compras_mes1[[#This Row],[CUIT]],Lista_CUIT[#All],3,0)),"CUIT NO CARGADO") -> SERVICIOS DE ALOJAMIENTO EN HOTELES | R16: =IFERROR(IF(compras_mes1[[#This Row],[CUIT]]="","-",VLOOKUP(compras_mes1[[#This Row],[CUIT]],Lista_CUIT[#All],4,0)),"CUIT NO CARGADO") -> 0
B17: 45660 | C17: 1 | D17: 1 | E17: 711934 | F17: 33716307749 | G17: =IFERROR(IF(compras_mes1[[#This Row],[CUIT]]="","-",VLOOKUP(compras_mes1[[#This Row],[CUIT]],Lista_CUIT[#All],2,0)),"CUIT NO CARGADO") -> VERISURE ARGENTINA MONITOREO DE ALARMAS SA | H17: 49498.9 | I17: =IF(compras_mes1[[#This Row],[NETO GRAVADO]]="","",compras_mes1[[#This Row],[NETO GRAVADO]]*0.21) -> 10394.769 | P17: =SUM(compras_mes1[[#This Row],[NETO GRAVADO]:[Otros / No Grav.]]) -> 59893.669 | Q17: =IFERROR(IF(compras_mes1[[#This Row],[CUIT]]="","-",VLOOKUP(compras_mes1[[#This Row],[CUIT]],Lista_CUIT[#All],3,0)),"CUIT NO CARGADO") -> Serv. Seguridad | R17: =IFERROR(IF(compras_mes1[[#This Row],[CUIT]]="","-",VLOOKUP(compras_mes1[[#This Row],[CUIT]],Lista_CUIT[#All],4,0)),"CUIT NO CARGADO") -> 0
B18: 45660 | C18: 1 | D18: 7 | E18: 3573 | F18: 20284183534 | G18: =IFERROR(IF(compras_mes1[[#This Row],[CUIT]]="","-",VLOOKUP(compras_mes1[[#This Row],[CUIT]],Lista_CUIT[#All],2,0)),"CUIT NO CARGADO") -> FURLANETTO MARTIN | H18: 9256.19 | I18: =IF(compras_mes1[[#This Row],[NETO GRAVADO]]="","",compras_mes1[[#This Row],[NETO GRAVADO]]*0.21) -> 1943.7999 | P18: =SUM(compras_mes1[[#This Row],[NETO GRAVADO]:[Otros / No Grav.]]) -> 11199.99 | Q18: =IFERROR(IF(compras_mes1[[#This Row],[CUIT]]="","-",VLOOKUP(compras_mes1[[#This Row],[CUIT]],Lista_CUIT[#All],3,0)),"CUIT NO CARGADO") -> gastos varios | R18: =IFERROR(IF(compras_mes1[[#This Row],[CUIT]]="","-",VLOOKUP(compras_mes1[[#This Row],[CUIT]],Lista_CUIT[#All],4,0)),"CUIT NO CARGADO") -> 0
B19: 45663 | C19: 1 | D19: 5 | E19: 1419 | F19: 27265302225 | G19: =IFERROR(IF(compras_mes1[[#This Row],[CUIT]]="","-",VLOOKUP(compras_mes1[[#This Row],[CUIT]],Lista_CUIT[#All],2,0)),"CUIT NO CARGADO") -> PRADO MARISOL | H19: 2100000 | I19: =IF(compras_mes1[[#This Row],[NETO GRAVADO]]="","",compras_mes1[[#This Row],[NETO GRAVADO]]*0.21) -> 441000 | P19: =SUM(compras_mes1[[#This Row],[NETO GRAVADO]:[Otros / No Grav.]]) -> 2541000 | Q19: =IFERROR(IF(compras_mes1[[#This Row],[CUIT]]="","-",VLOOKUP(compras_mes1[[#This Row],[CUIT]],Lista_CUIT[#All],3,0)),"CUIT NO CARGADO") -> INSUMO | R19: =IFERROR(IF(compras_mes1[[#This Row],[CUIT]]="","-",VLOOKUP(compras_mes1[[#This Row],[CUIT]],Lista_CUIT[#All],4,0)),"CUIT NO CARGADO") -> 0
B20: 45663 | C20: 1 | D20: 1 | E20: 112052 | F20: 30714864269 | G20: =IFERROR(IF(compras_mes1[[#This Row],[CUIT]]="","-",VLOOKUP(compras_mes1[[#This Row],[CUIT]],Lista_CUIT[#All],2,0)),"CUIT NO CARGADO") -> CONTABILIUM S.A. S. A. | H20: 139127 | I20: =IF(compras_mes1[[#This Row],[NETO GRAVADO]]="","",compras_mes1[[#This Row],[NETO GRAVADO]]*0.21) -> 29216.67 | P20: =SUM(compras_mes1[[#This Row],[NETO GRAVADO]:[Otros / No Grav.]]) -> 168343.67 | Q20: =IFERROR(IF(compras_mes1[[#This Row],[CUIT]]="","-",VLOOKUP(compras_mes1[[#This Row],[CUIT]],Lista_CUIT[#All],3,0)),"CUIT NO CARGADO") -> USUARIO CONTABLE | R20: =IFERROR(IF(compras_mes1[[#This Row],[CUIT]]="","-",VLOOKUP(compras_mes1[[#This Row],[CUIT]],Lista_CUIT[#All],4,0)),"CUIT NO CARGADO") -> 0
B21: 45663 | C21: 1 | D21: 1 | E21: 112096 | F21: 30714864269 | G21: =IFERROR(IF(compras_mes1[[#This Row],[CUIT]]="","-",VLOOKUP(compras_mes1[[#This Row],[CUIT]],Lista_CUIT[#All],2,0)),"CUIT NO CARGADO") -> CONTABILIUM S.A. S. A. | H21: 139127 | I21: =IF(compras_mes1[[#This Row],[NETO GRAVADO]]="","",compras_mes1[[#This Row],[NETO GRAVADO]]*0.21) -> 29216.67 | P21: =SUM(compras_mes1[[#This Row],[NETO GRAVADO]:[Otros / No Grav.]]) -> 168343.67 | Q21: =IFERROR(IF(compras_mes1[[#This Row],[CUIT]]="","-",VLOOKUP(compras_mes1[[#This Row],[CUIT]],Lista_CUIT[#All],3,0)),"CUIT NO CARGADO") -> USUARIO CONTABLE | R21: =IFERROR(IF(compras_mes1[[#This Row],[CUIT]]="","-",VLOOKUP(compras_mes1[[#This Row],[CUIT]],Lista_CUIT[#All],4,0)),"CUIT NO CARGADO") -> 0
B22: 45663 | C22: 1 | D22: 6 | E22: 87976 | F22: 30711553564 | G22: =IFERROR(IF(compras_mes1[[#This Row],[CUIT]]="","-",VLOOKUP(compras_mes1[[#This Row],[CUIT]],Lista_CUIT[#All],2,0)),"CUIT NO CARGADO") -> SALUD TEX S.A | H22: 72248 | I22: =IF(compras_mes1[[#This Row],[NETO GRAVADO]]="","",compras_mes1[[#This Row],[NETO GRAVADO]]*0.21) -> 15172.08 | P22: =SUM(compras_mes1[[#This Row],[NETO GRAVADO]:[Otros / No Grav.]]) -> 87420.08 | Q22: =IFERROR(IF(compras_mes1[[#This Row],[CUIT]]="","-",VLOOKUP(compras_mes1[[#This Row],[CUIT]],Lista_CUIT[#All],3,0)),"CUIT NO CARGADO") -> INSUMO | R22: =IFERROR(IF(compras_mes1[[#This Row],[CUIT]]="","-",VLOOKUP(compras_mes1[[#This Row],[CUIT]],Lista_CUIT[#All],4,0)),"CUIT NO CARGADO") -> 0
B23: 45663 | C23: 1 | D23: 5 | E23: 162444 | F23: 30598960093 | G23: =IFERROR(IF(compras_mes1[[#This Row],[CUIT]]="","-",VLOOKUP(compras_mes1[[#This Row],[CUIT]],Lista_CUIT[#All],2,0)),"CUIT NO CARGADO") -> SILVESTRIN FABRIS SRL | H23: 4386223.5 | I23: =IF(compras_mes1[[#This Row],[NETO GRAVADO]]="","",compras_mes1[[#This Row],[NETO GRAVADO]]*0.21) -> 921106.93 | P23: =SUM(compras_mes1[[#This Row],[NETO GRAVADO]:[Otros / No Grav.]]) -> 5307330.4 | Q23: =IFERROR(IF(compras_mes1[[#This Row],[CUIT]]="","-",VLOOKUP(compras_mes1[[#This Row],[CUIT]],Lista_CUIT[#All],3,0)),"CUIT NO CARGADO") -> INSUMO | R23: =IFERROR(IF(compras_mes1[[#This Row],[CUIT]]="","-",VLOOKUP(compras_mes1[[#This Row],[CUIT]],Lista_CUIT[#All],4,0)),"CUIT NO CARGADO") -> 0
B24: 45663 | C24: 1 | D24: 11 | E24: 69639 | F24: 30711091552 | G24: =IFERROR(IF(compras_mes1[[#This Row],[CUIT]]="","-",VLOOKUP(compras_mes1[[#This Row],[CUIT]],Lista_CUIT[#All],2,0)),"CUIT NO CARGADO") -> BIGBOX S.A. | H24: 30578.51 | I24: =IF(compras_mes1[[#This Row],[NETO GRAVADO]]="","",compras_mes1[[#This Row],[NETO GRAVADO]]*0.21) -> 6421.4871 | P24: =SUM(compras_mes1[[#This Row],[NETO GRAVADO]:[Otros / No Grav.]]) -> 36999.997 | Q24: =IFERROR(IF(compras_mes1[[#This Row],[CUIT]]="","-",VLOOKUP(compras_mes1[[#This Row],[CUIT]],Lista_CUIT[#All],3,0)),"CUIT NO CARGADO") -> INSUMO | R24: =IFERROR(IF(compras_mes1[[#This Row],[CUIT]]="","-",VLOOKUP(compras_mes1[[#This Row],[CUIT]],Lista_CUIT[#All],4,0)),"CUIT NO CARGADO") -> 0
B25: 45664 | C25: 1 | D25: 700 | E25: 2180405 | F25: 30715804812 | G25: =IFERROR(IF(compras_mes1[[#This Row],[CUIT]]="","-",VLOOKUP(compras_mes1[[#This Row],[CUIT]],Lista_CUIT[#All],2,0)),"CUIT NO CARGADO") -> CORREDORES VIALES SOCIEDAD ANONIMA | H25: 8735.85 | I25: =IF(compras_mes1[[#This Row],[NETO GRAVADO]]="","",compras_mes1[[#This Row],[NETO GRAVADO]]*0.21) -> 1834.5285 | P25: =SUM(compras_mes1[[#This Row],[NETO GRAVADO]:[Otros / No Grav.]]) -> 10570.379 | Q25: =IFERROR(IF(compras_mes1[[#This Row],[CUIT]]="","-",VLOOKUP(compras_mes1[[#This Row],[CUIT]],Lista_CUIT[#All],3,0)),"CUIT NO CARGADO") -> Autopista | R25: =IFERROR(IF(compras_mes1[[#This Row],[CUIT]]="","-",VLOOKUP(compras_mes1[[#This Row],[CUIT]],Lista_CUIT[#All],4,0)),"CUIT NO CARGADO") -> 0
B26: 45664 | C26: 1 | D26: 2 | E26: 25726 | F26: 23233422029 | G26: =IFERROR(IF(compras_mes1[[#This Row],[CUIT]]="","-",VLOOKUP(compras_mes1[[#This Row],[CUIT]],Lista_CUIT[#All],2,0)),"CUIT NO CARGADO") -> RODOLFO SCHULZE | H26: 272814.48 | I26: =IF(compras_mes1[[#This Row],[NETO GRAVADO]]="","",compras_mes1[[#This Row],[NETO GRAVADO]]*0.21) -> 57291.041 | P26: =SUM(compras_mes1[[#This Row],[NETO GRAVADO]:[Otros / No Grav.]]) -> 330105.52 | Q26: =IFERROR(IF(compras_mes1[[#This Row],[CUIT]]="","-",VLOOKUP(compras_mes1[[#This Row],[CUIT]],Lista_CUIT[#All],3,0)),"CUIT NO CARGADO") -> INSUMO | R26: =IFERROR(IF(compras_mes1[[#This Row],[CUIT]]="","-",VLOOKUP(compras_mes1[[#This Row],[CUIT]],Lista_CUIT[#All],4,0)),"CUIT NO CARGADO") -> 0
B27: 45664 | C27: 1 | D27: 4 | E27: 1280 | F27: 27148854764 | G27: =IFERROR(IF(compras_mes1[[#This Row],[CUIT]]="","-",VLOOKUP(compras_mes1[[#This Row],[CUIT]],Lista_CUIT[#All],2,0)),"CUIT NO CARGADO") -> PAZ CLAUDIA SILVIA | H27: 12452.89 | I27: =IF(compras_mes1[[#This Row],[NETO GRAVADO]]="","",compras_mes1[[#This Row],[NETO GRAVADO]]*0.21) -> 2615.1069 | P27: =SUM(compras_mes1[[#This Row],[NETO GRAVADO]:[Otros / No Grav.]]) -> 15067.997 | Q27: =IFERROR(IF(compras_mes1[[#This Row],[CUIT]]="","-",VLOOKUP(compras_mes1[[#This Row],[CUIT]],Lista_CUIT[#All],3,0)),"CUIT NO CARGADO") -> Gastos Varios | R27: =IFERROR(IF(compras_mes1[[#This Row],[CUIT]]="","-",VLOOKUP(compras_mes1[[#This Row],[CUIT]],Lista_CUIT[#All],4,0)),"CUIT NO CARGADO") -> 0
... B33: 45665 | C33: 1 | D33: 12 | E33: 1811132 | F33: 30709776564 | G33: =IFERROR(IF(compras_mes1[[#This Row],[CUIT]]="","-",VLOOKUP(compras_mes1[[#This Row],[CUIT]],Lista_CUIT[#All],2,0)),"CUIT NO CARGADO") -> PROSEGUR ACTIVA ARG SA | H33: 129241 | I33: =IF(compras_mes1[[#This Row],[NETO GRAVADO]]="","",compras_mes1[[#This Row],[NETO GRAVADO]]*0.21) -> 27140.61 | P33: =SUM(compras_mes1[[#This Row],[NETO GRAVADO]:[Otros / No Grav.]]) -> 156381.61 | Q33: =IFERROR(IF(compras_mes1[[#This Row],[CUIT]]="","-",VLOOKUP(compras_mes1[[#This Row],[CUIT]],Lista_CUIT[#All],3,0)),"CUIT NO CARGADO") -> ALARMA SEGURIDAD | R33: =IFERROR(IF(compras_mes1[[#This Row],[CUIT]]="","-",VLOOKUP(compras_mes1[[#This Row],[CUIT]],Lista_CUIT[#All],4,0)),"CUIT NO CARGADO") -> 0
B34: 45666 | C34: 1 | D34: 3101 | E34: 235363 | F34: 30678814357 | G34: =IFERROR(IF(compras_mes1[[#This Row],[CUIT]]="","-",VLOOKUP(compras_mes1[[#This Row],[CUIT]],Lista_CUIT[#All],2,0)),"CUIT NO CARGADO") -> TELEFONICA MOVILES ARG SA | H34: 73526.55 | J34: =compras_mes1[[#This Row],[NETO GRAVADO]]*27/100 -> 19852.168 | P34: =SUM(compras_mes1[[#This Row],[NETO GRAVADO]:[Otros / No Grav.]]) -> 93378.719 | Q34: =IFERROR(IF(compras_mes1[[#This Row],[CUIT]]="","-",VLOOKUP(compras_mes1[[#This Row],[CUIT]],Lista_CUIT[#All],3,0)),"CUIT NO CARGADO") -> SERVICIO | R34: =IFERROR(IF(compras_mes1[[#This Row],[CUIT]]="","-",VLOOKUP(compras_mes1[[#This Row],[CUIT]],Lista_CUIT[#All],4,0)),"CUIT NO CARGADO") -> 0
B35: 45666 | C35: 1 | D35: 2 | E35: 1041 | F35: 20272865869 | G35: =IFERROR(IF(compras_mes1[[#This Row],[CUIT]]="","-",VLOOKUP(compras_mes1[[#This Row],[CUIT]],Lista_CUIT[#All],2,0)),"CUIT NO CARGADO") -> DI FEO MARTIN EZEQUIEL | H35: 24220 | I35: =IF(compras_mes1[[#This Row],[NETO GRAVADO]]="","",compras_mes1[[#This Row],[NETO GRAVADO]]*0.21) -> 5086.2 | P35: =SUM(compras_mes1[[#This Row],[NETO GRAVADO]:[Otros / No Grav.]]) -> 29306.2 | Q35: =IFERROR(IF(compras_mes1[[#This Row],[CUIT]]="","-",VLOOKUP(compras_mes1[[#This Row],[CUIT]],Lista_CUIT[#All],3,0)),"CUIT NO CARGADO") -> INSUMOS | R35: =IFERROR(IF(compras_mes1[[#This Row],[CUIT]]="","-",VLOOKUP(compras_mes1[[#This Row],[CUIT]],Lista_CUIT[#All],4,0)),"CUIT NO CARGADO") -> 0
B36: 45666 | C36: 1 | D36: 7 | E36: 19904 | F36: 30709214078 | G36: =IFERROR(IF(compras_mes1[[#This Row],[CUIT]]="","-",VLOOKUP(compras_mes1[[#This Row],[CUIT]],Lista_CUIT[#All],2,0)),"CUIT NO CARGADO") -> REHAVITA S.A | H36: 96246 | I36: =IF(compras_mes1[[#This Row],[NETO GRAVADO]]="","",compras_mes1[[#This Row],[NETO GRAVADO]]*0.21) -> 20211.66 | P36: =SUM(compras_mes1[[#This Row],[NETO GRAVADO]:[Otros / No Grav.]]) -> 116457.66 | Q36: =IFERROR(IF(compras_mes1[[#This Row],[CUIT]]="","-",VLOOKUP(compras_mes1[[#This Row],[CUIT]],Lista_CUIT[#All],3,0)),"CUIT NO CARGADO") -> INSUMO | R36: =IFERROR(IF(compras_mes1[[#This Row],[CUIT]]="","-",VLOOKUP(compras_mes1[[#This Row],[CUIT]],Lista_CUIT[#All],4,0)),"CUIT NO CARGADO") -> 0
B37: 45667 | C37: 1 | D37: 2 | E37: 226 | F37: 30605344352 | G37: =IFERROR(IF(compras_mes1[[#This Row],[CUIT]]="","-",VLOOKUP(compras_mes1[[#This Row],[CUIT]],Lista_CUIT[#All],2,0)),"CUIT NO CARGADO") -> CONSORCIO BARTOLME MITRE 2466 | H37: 1200000 | I37: =IF(compras_mes1[[#This Row],[NETO GRAVADO]]="","",compras_mes1[[#This Row],[NETO GRAVADO]]*0.21) -> 252000 | P37: =SUM(compras_mes1[[#This Row],[NETO GRAVADO]:[Otros / No Grav.]]) -> 1452000 | Q37: =IFERROR(IF(compras_mes1[[#This Row],[CUIT]]="","-",VLOOKUP(compras_mes1[[#This Row],[CUIT]],Lista_CUIT[#All],3,0)),"CUIT NO CARGADO") -> ALQUILER LOCAL | R37: =IFERROR(IF(compras_mes1[[#This Row],[CUIT]]="","-",VLOOKUP(compras_mes1[[#This Row],[CUIT]],Lista_CUIT[#All],4,0)),"CUIT NO CARGADO") -> 0
B38: 45667 | C38: 1 | D38: 6 | E38: 55729 | F38: 30710177658 | G38: =IFERROR(IF(compras_mes1[[#This Row],[CUIT]]="","-",VLOOKUP(compras_mes1[[#This Row],[CUIT]],Lista_CUIT[#All],2,0)),"CUIT NO CARGADO") -> TARGET MEDICAL SA | H38: 904195.2 | I38: =IF(compras_mes1[[#This Row],[NETO GRAVADO]]="","",compras_mes1[[#This Row],[NETO GRAVADO]]*0.21) -> 189880.99 | P38: =SUM(compras_mes1[[#This Row],[NETO GRAVADO]:[Otros / No Grav.]]) -> 1094076.2 | Q38: =IFERROR(IF(compras_mes1[[#This Row],[CUIT]]="","-",VLOOKUP(compras_mes1[[#This Row],[CUIT]],Lista_CUIT[#All],3,0)),"CUIT NO CARGADO") -> INSUMO | R38: =IFERROR(IF(compras_mes1[[#This Row],[CUIT]]="","-",VLOOKUP(compras_mes1[[#This Row],[CUIT]],Lista_CUIT[#All],4,0)),"CUIT NO CARGADO") -> 0
B39: 45667 | C39: 1 | D39: 2 | E39: 2471 | F39: 33713192509 | G39: =IFERROR(IF(compras_mes1[[#This Row],[CUIT]]="","-",VLOOKUP(compras_mes1[[#This Row],[CUIT]],Lista_CUIT[#All],2,0)),"CUIT NO CARGADO") -> TAIKUE SA | H39: 104958.68 | I39: =IF(compras_mes1[[#This Row],[NETO GRAVADO]]="","",compras_mes1[[#This Row],[NETO GRAVADO]]*0.21) -> 22041.323 | P39: =SUM(compras_mes1[[#This Row],[NETO GRAVADO]:[Otros / No Grav.]]) -> 127000 | Q39: =IFERROR(IF(compras_mes1[[#This Row],[CUIT]]="","-",VLOOKUP(compras_mes1[[#This Row],[CUIT]],Lista_CUIT[#All],3,0)),"CUIT NO CARGADO") -> Mantenimiento | R39: =IFERROR(IF(compras_mes1[[#This Row],[CUIT]]="","-",VLOOKUP(compras_mes1[[#This Row],[CUIT]],Lista_CUIT[#All],4,0)),"CUIT NO CARGADO") -> 0
B40: 45667 | C40: 1 | D40: 4 | E40: 148 | F40: 20317488476 | G40: =IFERROR(IF(compras_mes1[[#This Row],[CUIT]]="","-",VLOOKUP(compras_mes1[[#This Row],[CUIT]],Lista_CUIT[#All],2,0)),"CUIT NO CARGADO") -> MIGUEL ANGEL VILLALBA | H40: 500000 | I40: =IF(compras_mes1[[#This Row],[NETO GRAVADO]]="","",compras_mes1[[#This Row],[NETO GRAVADO]]*0.21) -> 105000 | P40: =SUM(compras_mes1[[#This Row],[NETO GRAVADO]:[Otros / No Grav.]]) -> 605000 | Q40: BIEN DE USO | R40: =IFERROR(IF(compras_mes1[[#This Row],[CUIT]]="","-",VLOOKUP(compras_mes1[[#This Row],[CUIT]],Lista_CUIT[#All],4,0)),"CUIT NO CARGADO") -> 0
B41: 45667 | C41: 1 | D41: 4 | E41: 1291 | F41: 20202500138 | G41: =IFERROR(IF(compras_mes1[[#This Row],[CUIT]]="","-",VLOOKUP(compras_mes1[[#This Row],[CUIT]],Lista_CUIT[#All],2,0)),"CUIT NO CARGADO") -> RAMBAUD DIEGO GABRIEL | H41: 39457.01 | K41: =compras_mes1[[#This Row],[NETO GRAVADO]]*10.5/100 -> 4142.9861 | P41: =SUM(compras_mes1[[#This Row],[NETO GRAVADO]:[Otros / No Grav.]]) -> 43599.996 | Q41: =IFERROR(IF(compras_mes1[[#This Row],[CUIT]]="","-",VLOOKUP(compras_mes1[[#This Row],[CUIT]],Lista_CUIT[#All],3,0)),"CUIT NO CARGADO") -> GASTOS VARIOS | R41: =IFERROR(IF(compras_mes1[[#This Row],[CUIT]]="","-",VLOOKUP(compras_mes1[[#This Row],[CUIT]],Lista_CUIT[#All],4,0)),"CUIT NO CARGADO") -> 0
B42: 45667 | C42: 1 | D42: 16 | E42: 32 | F42: 27310367813 | G42: =IFERROR(IF(compras_mes1[[#This Row],[CUIT]]="","-",VLOOKUP(compras_mes1[[#This Row],[CUIT]],Lista_CUIT[#All],2,0)),"CUIT NO CARGADO") -> LA BRUNA MARIA VIRGINIA | H42: 133471.07 | I42: =IF(compras_mes1[[#This Row],[NETO GRAVADO]]="","",compras_mes1[[#This Row],[NETO GRAVADO]]*0.21) -> 28028.925 | P42: =SUM(compras_mes1[[#This Row],[NETO GRAVADO]:[Otros / No Grav.]]) -> 161499.99 | Q42: =IFERROR(IF(compras_mes1[[#This Row],[CUIT]]="","-",VLOOKUP(compras_mes1[[#This Row],[CUIT]],Lista_CUIT[#All],3,0)),"CUIT NO CARGADO") -> Hon. Juridicos | R42: =IFERROR(IF(compras_mes1[[#This Row],[CUIT]]="","-",VLOOKUP(compras_mes1[[#This Row],[CUIT]],Lista_CUIT[#All],4,0)),"CUIT NO CARGADO") -> 0
B43: 45668 | C43: 1 | D43: 2 | E43: 227 | F43: 30605344352 | G43: =IFERROR(IF(compras_mes1[[#This Row],[CUIT]]="","-",VLOOKUP(compras_mes1[[#This Row],[CUIT]],Lista_CUIT[#All],2,0)),"CUIT NO CARGADO") -> CONSORCIO BARTOLME MITRE 2466 | H43: 366000 | I43: =IF(compras_mes1[[#This Row],[NETO GRAVADO]]="","",compras_mes1[[#This Row],[NETO GRAVADO]]*0.21) -> 76860 | P43: =SUM(compras_mes1[[#This Row],[NETO GRAVADO]:[Otros / No Grav.]]) -> 442860 | Q43: =IFERROR(IF(compras_mes1[[#This Row],[CUIT]]="","-",VLOOKUP(compras_mes1[[#This Row],[CUIT]],Lista_CUIT[#All],3,0)),"CUIT NO CARGADO") -> ALQUILER LOCAL | R43: =IFERROR(IF(compras_mes1[[#This Row],[CUIT]]="","-",VLOOKUP(compras_mes1[[#This Row],[CUIT]],Lista_CUIT[#All],4,0)),"CUIT NO CARGADO") -> 0
B44: 45669 | C44: 1 | D44: 2189 | E44: 83402 | F44: 30548083156 | G44: =IFERROR(IF(compras_mes1[[#This Row],[CUIT]]="","-",VLOOKUP(compras_mes1[[#This Row],[CUIT]],Lista_CUIT[#All],2,0)),"CUIT NO CARGADO") -> COTO CICSA | H44: 9135.66 | I44: =IF(compras_mes1[[#This Row],[NETO GRAVADO]]="","",compras_mes1[[#This Row],[NETO GRAVADO]]*0.21) -> 1918.4886 | P44: =SUM(compras_mes1[[#This Row],[NETO GRAVADO]:[Otros / No Grav.]]) -> 11054.149 | Q44: =IFERROR(IF(compras_mes1[[#This Row],[CUIT]]="","-",VLOOKUP(compras_mes1[[#This Row],[CUIT]],Lista_CUIT[#All],3,0)),"CUIT NO CARGADO") -> Gastos Varios | R44: =IFERROR(IF(compras_mes1[[#This Row],[CUIT]]="","-",VLOOKUP(compras_mes1[[#This Row],[CUIT]],Lista_CUIT[#All],4,0)),"CUIT NO CARGADO") -> 0
B45: 45671 | C45: 1 | D45: 104 | E45: 7892105 | F45: 30715804812 | G45: =IFERROR(IF(compras_mes1[[#This Row],[CUIT]]="","-",VLOOKUP(compras_mes1[[#This Row],[CUIT]],Lista_CUIT[#All],2,0)),"CUIT NO CARGADO") -> CORREDORES VIALES SOCIEDAD ANONIMA | H45: 1039.98 | I45: =IF(compras_mes1[[#This Row],[NETO GRAVADO]]="","",compras_mes1[[#This Row],[NETO GRAVADO]]*0.21) -> 218.3958 | P45: =SUM(compras_mes1[[#This Row],[NETO GRAVADO]:[Otros / No Grav.]]) -> 1258.3758 | Q45: =IFERROR(IF(compras_mes1[[#This Row],[CUIT]]="","-",VLOOKUP(compras_mes1[[#This Row],[CUIT]],Lista_CUIT[#All],3,0)),"CUIT NO CARGADO") -> Autopista | R45: =IFERROR(IF(compras_mes1[[#This Row],[CUIT]]="","-",VLOOKUP(compras_mes1[[#This Row],[CUIT]],Lista_CUIT[#All],4,0)),"CUIT NO CARGADO") -> 0
B46: 45671 | C46: 1 | D46: 101 | E46: 8931 | F46: 33711430879 | G46: =IFERROR(IF(compras_mes1[[#This Row],[CUIT]]="","-",VLOOKUP(compras_mes1[[#This Row],[CUIT]],Lista_CUIT[#All],2,0)),"CUIT NO CARGADO") -> BALANZE S.A. | H46: 130000 | I46: =IF(compras_mes1[[#This Row],[NETO GRAVADO]]="","",compras_mes1[[#This Row],[NETO GRAVADO]]*0.21) -> 27300 | P46: =SUM(compras_mes1[[#This Row],[NETO GRAVADO]:[Otros / No Grav.]]) -> 157300 | Q46: =IFERROR(IF(compras_mes1[[#This Row],[CUIT]]="","-",VLOOKUP(compras_mes1[[#This Row],[CUIT]],Lista_CUIT[#All],3,0)),"CUIT NO CARGADO") -> INSUMO | R46: =IFERROR(IF(compras_mes1[[#This Row],[CUIT]]="","-",VLOOKUP(compras_mes1[[#This Row],[CUIT]],Lista_CUIT[#All],4,0)),"CUIT NO CARGADO") -> 0
B47: 45672 | C47: 1 | D47: 5015 | E47: 714288 | F47: 30574876474 | G47: =IFERROR(IF(compras_mes1[[#This Row],[CUIT]]="","-",VLOOKUP(compras_mes1[[#This Row],[CUIT]],Lista_CUIT[#All],2,0)),"CUIT NO CARGADO") -> AUTOP. URBANAS SA | H47: 11727.02 | I47: =IF(compras_mes1[[#This Row],[NETO GRAVADO]]="","",compras_mes1[[#This Row],[NETO GRAVADO]]*0.21) -> 2462.6742 | P47: =SUM(compras_mes1[[#This Row],[NETO GRAVADO]:[Otros / No Grav.]]) -> 14189.694 | Q47: =IFERROR(IF(compras_mes1[[#This Row],[CUIT]]="","-",VLOOKUP(compras_mes1[[#This Row],[CUIT]],Lista_CUIT[#All],3,0)),"CUIT NO CARGADO") -> PEAJE | R47: =IFERROR(IF(compras_mes1[[#This Row],[CUIT]]="","-",VLOOKUP(compras_mes1[[#This Row],[CUIT]],Lista_CUIT[#All],4,0)),"CUIT NO CARGADO") -> 0
B48: 45672 | C48: 1 | D48: 113 | E48: 4022341 | F48: 30577207190 | G48: =IFERROR(IF(compras_mes1[[#This Row],[CUIT]]="","-",VLOOKUP(compras_mes1[[#This Row],[CUIT]],Lista_CUIT[#All],2,0)),"CUIT NO CARGADO") -> COORDINACION ECOLOGICA AREA METROPOLITANA SOCIEDAD DEL ESTADO | H48: 5960.33 | I48: =IF(compras_mes1[[#This Row],[NETO GRAVADO]]="","",compras_mes1[[#This Row],[NETO GRAVADO]]*0.21) -> 1251.6693 | P48: =SUM(compras_mes1[[#This Row],[NETO GRAVADO]:[Otros / No Grav.]]) -> 7211.9993 | Q48: =IFERROR(IF(compras_mes1[[#This Row],[CUIT]]="","-",VLOOKUP(compras_mes1[[#This Row],[CUIT]],Lista_CUIT[#All],3,0)),"CUIT NO CARGADO") -> gastos varios | R48: =IFERROR(IF(compras_mes1[[#This Row],[CUIT]]="","-",VLOOKUP(compras_mes1[[#This Row],[CUIT]],Lista_CUIT[#All],4,0)),"CUIT NO CARGADO") -> 0
B49: 45672 | C49: 1 | D49: 5009 | E49: 1166794 | F49: 30574876474 | G49: =IFERROR(IF(compras_mes1[[#This Row],[CUIT]]="","-",VLOOKUP(compras_mes1[[#This Row],[CUIT]],Lista_CUIT[#All],2,0)),"CUIT NO CARGADO") -> AUTOP. URBANAS SA | H49: 1655.12 | I49: =IF(compras_mes1[[#This Row],[NETO GRAVADO]]="","",compras_mes1[[#This Row],[NETO GRAVADO]]*0.21) -> 347.5752 | P49: =SUM(compras_mes1[[#This Row],[NETO GRAVADO]:[Otros / No Grav.]]) -> 2002.6952 | Q49: =IFERROR(IF(compras_mes1[[#This Row],[CUIT]]="","-",VLOOKUP(compras_mes1[[#This Row],[CUIT]],Lista_CUIT[#All],3,0)),"CUIT NO CARGADO") -> PEAJE | R49: =IFERROR(IF(compras_mes1[[#This Row],[CUIT]]="","-",VLOOKUP(compras_mes1[[#This Row],[CUIT]],Lista_CUIT[#All],4,0)),"CUIT NO CARGADO") -> 0
...

Sheet Feb-25
B1: LIBRO IVA COMPRAS | G1: ='Ene-25'!G1:M1 -> ORTOPEDIA GEMINIS S.A. | N1: =EDATE('Ene-25'!N1,1) -> 45689
B3: TOTAL COMPRAS | G3: TOTAL CREDITO FISCAL | J3: TOTAL VENTAS NETAS | M3: TOTAL DEBITO FISCAL | P3: RESULTADO
B4: =SUM(compras_mes2[[#Totals],[NETO GRAVADO]])+extracto_banco_mes2[[#Totals],[NETO]] -> 26792809 | G4: =compras_mes2[[#Totals],[IVA 21 %]]+compras_mes2[[#Totals],[IVA 27%]]+compras_mes2[[#Totals],[IVA 10,5%]]+extracto_banco_mes2[[#Totals],[IVA 21%]]+extracto_banco_mes2[[#Totals],[IVA 10,5%]] -> 5467560.1 | J4: =venta_a_mes2[[#Totals],[IMPORTE NETO]]+ventas_b_mes2[[#Totals],[IMPORTE NETO]] -> 0 | M4: =venta_a_mes2[[#Totals],[IVA 21%]]+venta_a_mes2[[#Totals],[IVA 10,5%]]+ventas_b_mes2[[#Totals],[IVA 21%]]+ventas_b_mes2[[#Totals],[IVA 10,5%]] -> 0 | P4: =G4-M4 -> 5467560.1
B8: FECHA | C8: TIPO | D8: PTO VTA | E8: NRO. CPTE | F8: CUIT | G8: RAZON SOCIAL | H8: NETO GRAVADO | I8: IVA 21 % | J8: IVA 27% | K8: IVA 10,5% | L8: PERC. IVA | M8: PERC IIBB BS AS | N8: PERC. IIBB CABA | O8: Otros / No Grav. | P8: TOTAL | Q8: Tipo de Gasto | R8: Provincia
B9: 45689 | C9: 1 | D9: 629 | E9: 5821744 | F9: 30663498513 | G9: =IFERROR(IF(compras_mes2[[#This Row],[CUIT]]="","-",VLOOKUP(compras_mes2[[#This Row],[CUIT]],Lista_CUIT[#All],2,0)),"CUIT NO CARGADO") -> GRUPO CONCES. DEL OESTE SA | H9: 577.76 | I9: =IF(compras_mes2[[#This Row],[NETO GRAVADO]]="","",compras_mes2[[#This Row],[NETO GRAVADO]]*0.21) -> 121.3296 | P9: =SUM(compras_mes2[[#This Row],[NETO GRAVADO]:[Otros / No Grav.]]) -> 699.0896 | Q9: =IFERROR(IF(compras_mes2[[#This Row],[CUIT]]="","-",VLOOKUP(compras_mes2[[#This Row],[CUIT]],Lista_CUIT[#All],3,0)),"CUIT NO CARGADO") -> Autopista | R9: =IFERROR(IF(compras_mes2[[#This Row],[CUIT]]="","-",VLOOKUP(compras_mes2[[#This Row],[CUIT]],Lista_CUIT[#All],4,0)),"CUIT NO CARGADO") -> 0 | S9: 72378.33
B10: 45690 | C10: 1 | D10: 2031 | E10: 194172 | F10: 30516186670 | G10: =IFERROR(IF(compras_mes2[[#This Row],[CUIT]]="","-",VLOOKUP(compras_mes2[[#This Row],[CUIT]],Lista_CUIT[#All],2,0)),"CUIT NO CARGADO") -> DEHEZA SAICF E I | H10: 41633.14 | I10: =IF(compras_mes2[[#This Row],[NETO GRAVADO]]="","",compras_mes2[[#This Row],[NETO GRAVADO]]*0.21) -> 8742.9594 | P10: =SUM(compras_mes2[[#This Row],[NETO GRAVADO]:[Otros / No Grav.]]) -> 50376.099 | Q10: =IFERROR(IF(compras_mes2[[#This Row],[CUIT]]="","-",VLOOKUP(compras_mes2[[#This Row],[CUIT]],Lista_CUIT[#All],3,0)),"CUIT NO CARGADO") -> COMBUSTIBLE | R10: =IFERROR(IF(compras_mes2[[#This Row],[CUIT]]="","-",VLOOKUP(compras_mes2[[#This Row],[CUIT]],Lista_CUIT[#All],4,0)),"CUIT NO CARGADO") -> 0 | S10: 210479.5
B11: 45690 | C11: 1 | D11: 3051 | E11: 876626 | F11: 30678814357 | G11: =IFERROR(IF(compras_mes2[[#This Row],[CUIT]]="","-",VLOOKUP(compras_mes2[[#This Row],[CUIT]],Lista_CUIT[#All],2,0)),"CUIT NO CARGADO") -> TELEFONICA MOVILES ARG SA | H11: 76614.82 | J11: =compras_mes2[[#This Row],[NETO GRAVADO]]*27/100 -> 20686.001 | P11: =SUM(compras_mes2[[#This Row],[NETO GRAVADO]:[Otros / No Grav.]]) -> 97300.821 | Q11: =IFERROR(IF(compras_mes2[[#This Row],[CUIT]]="","-",VLOOKUP(compras_mes2[[#This Row],[CUIT]],Lista_CUIT[#All],3,0)),"CUIT NO CARGADO") -> SERVICIO | R11: =IFERROR(IF(compras_mes2[[#This Row],[CUIT]]="","-",VLOOKUP(compras_mes2[[#This Row],[CUIT]],Lista_CUIT[#All],4,0)),"CUIT NO CARGADO") -> 0 | S11: 23923.11
B12: 45691 | C12: 1 | D12: 7 | E12: 3876 | F12: 20347228002 | G12: =IFERROR(IF(compras_mes2[[#This Row],[CUIT]]="","-",VLOOKUP(compras_mes2[[#This Row],[CUIT]],Lista_CUIT[#All],2,0)),"CUIT NO CARGADO") -> MATIAS EZEQUIEL ROMANO | H12: 81817.36 | I12: =IF(compras_mes2[[#This Row],[NETO GRAVADO]]="","",compras_mes2[[#This Row],[NETO GRAVADO]]*0.21) -> 17181.646 | P12: =SUM(compras_mes2[[#This Row],[NETO GRAVADO]:[Otros / No Grav.]]) -> 98999.006 | Q12: =IFERROR(IF(compras_mes2[[#This Row],[CUIT]]="","-",VLOOKUP(compras_mes2[[#This Row],[CUIT]],Lista_CUIT[#All],3,0)),"CUIT NO CARGADO") -> INSUMO | R12: =IFERROR(IF(compras_mes2[[#This Row],[CUIT]]="","-",VLOOKUP(compras_mes2[[#This Row],[CUIT]],Lista_CUIT[#All],4,0)),"CUIT NO CARGADO") -> 0 | S12: 48658.91
B13: 45691 | C13: 1 | D13: 2 | E13: 229 | F13: 30605344352 | G13: =IFERROR(IF(compras_mes2[[#This Row],[CUIT]]="","-",VLOOKUP(compras_mes2[[#This Row],[CUIT]],Lista_CUIT[#All],2,0)),"CUIT NO CARGADO") -> CONSORCIO BARTOLME MITRE 2466 | H13: 1200000 | I13: =IF(compras_mes2[[#This Row],[NETO GRAVADO]]="","",compras_mes2[[#This Row],[NETO GRAVADO]]*0.21) -> 252000 | P13: =SUM(compras_mes2[[#This Row],[NETO GRAVADO]:[Otros / No Grav.]]) -> 1452000 | Q13: =IFERROR(IF(compras_mes2[[#This Row],[CUIT]]="","-",VLOOKUP(compras_mes2[[#This Row],[CUIT]],Lista_CUIT[#All],3,0)),"CUIT NO CARGADO") -> ALQUILER LOCAL | R13: =IFERROR(IF(compras_mes2[[#This Row],[CUIT]]="","-",VLOOKUP(compras_mes2[[#This Row],[CUIT]],Lista_CUIT[#All],4,0)),"CUIT NO CARGADO") -> 0 | S13: 182956.36
B14: 45691 | C14: 1 | D14: 5 | E14: 1438 | F14: 27265302225 | G14: =IFERROR(IF(compras_mes2[[#This Row],[CUIT]]="","-",VLOOKUP(compras_mes2[[#This Row],[CUIT]],Lista_CUIT[#All],2,0)),"CUIT NO CARGADO") -> PRADO MARISOL | H14: 1200000 | I14: =IF(compras_mes2[[#This Row],[NETO GRAVADO]]="","",compras_mes2[[#This Row],[NETO GRAVADO]]*0.21) -> 252000 | P14: =SUM(compras_mes2[[#This Row],[NETO GRAVADO]:[Otros / No Grav.]]) -> 1452000 | Q14: =IFERROR(IF(compras_mes2[[#This Row],[CUIT]]="","-",VLOOKUP(compras_mes2[[#This Row],[CUIT]],Lista_CUIT[#All],3,0)),"CUIT NO CARGADO") -> INSUMO | R14: =IFERROR(IF(compras_mes2[[#This Row],[CUIT]]="","-",VLOOKUP(compras_mes2[[#This Row],[CUIT]],Lista_CUIT[#All],4,0)),"CUIT NO CARGADO") -> 0 | S14: 695750
B15: 45691 | C15: 1 | D15: 23 | E15: 7614 | F15: 30711776040 | G15: =IFERROR(IF(compras_mes2[[#This Row],[CUIT]]="","-",VLOOKUP(compras_mes2[[#This Row],[CUIT]],Lista_CUIT[#All],2,0)),"CUIT NO CARGADO") -> EXPRESO BICENTENARIO S.R.L | H15: 19433 | I15: =IF(compras_mes2[[#This Row],[NETO GRAVADO]]="","",compras_mes2[[#This Row],[NETO GRAVADO]]*0.21) -> 4080.93 | P15: =SUM(compras_mes2[[#This Row],[NETO GRAVADO]:[Otros / No Grav.]]) -> 23513.93 | Q15: =IFERROR(IF(compras_mes2[[#This Row],[CUIT]]="","-",VLOOKUP(compras_mes2[[#This Row],[CUIT]],Lista_CUIT[#All],3,0)),"CUIT NO CARGADO") -> Servicio Transporte | R15: =IFERROR(IF(compras_mes2[[#This Row],[CUIT]]="","-",VLOOKUP(compras_mes2[[#This Row],[CUIT]],Lista_CUIT[#All],4,0)),"CUIT NO CARGADO") -> 0 | S15: 696359.88
B16: 45691 | C16: 1 | D16: 500 | E16: 1681453 | F16: 30654118767 | G16: =IFERROR(IF(compras_mes2[[#This Row],[CUIT]]="","-",VLOOKUP(compras_mes2[[#This Row],[CUIT]],Lista_CUIT[#All],2,0)),"CUIT NO CARGADO") -> SOLUCIONES MULTIMEDIA SA | H16: 113718.7 | I16: =IF(compras_mes2[[#This Row],[NETO GRAVADO]]="","",compras_mes2[[#This Row],[NETO GRAVADO]]*0.21) -> 23880.927 | P16: =SUM(compras_mes2[[#This Row],[NETO GRAVADO]:[Otros / No Grav.]]) -> 137599.63 | Q16: =IFERROR(IF(compras_mes2[[#This Row],[CUIT]]="","-",VLOOKUP(compras_mes2[[#This Row],[CUIT]],Lista_CUIT[#All],3,0)),"CUIT NO CARGADO") -> gastos varios | R16: =IFERROR(IF(compras_mes2[[#This Row],[CUIT]]="","-",VLOOKUP(compras_mes2[[#This Row],[CUIT]],Lista_CUIT[#All],4,0)),"CUIT NO CARGADO") -> 0 | S16: 357748.6
B17: 45691 | C17: 1 | D17: 1 | E17: 722566 | F17: 33716307749 | G17: =IFERROR(IF(compras_mes2[[#This Row],[CUIT]]="","-",VLOOKUP(compras_mes2[[#This Row],[CUIT]],Lista_CUIT[#All],2,0)),"CUIT NO CARGADO") -> VERISURE ARGENTINA MONITOREO DE ALARMAS SA | H17: 49498.9 | I17: =IF(compras_mes2[[#This Row],[NETO GRAVADO]]="","",compras_mes2[[#This Row],[NETO GRAVADO]]*0.21) -> 10394.769 | P17: =SUM(compras_mes2[[#This Row],[NETO GRAVADO]:[Otros / No Grav.]]) -> 59893.669 | Q17: =IFERROR(IF(compras_mes2[[#This Row],[CUIT]]="","-",VLOOKUP(compras_mes2[[#This Row],[CUIT]],Lista_CUIT[#All],3,0)),"CUIT NO CARGADO") -> Serv. Seguridad | R17: =IFERROR(IF(compras_mes2[[#This Row],[CUIT]]="","-",VLOOKUP(compras_mes2[[#This Row],[CUIT]],Lista_CUIT[#All],4,0)),"CUIT NO CARGADO") -> 0 | S17: 1200000
B18: 45692 | C18: 1 | D18: 7 | E18: 1465 | F18: 30712187316 | G18: =IFERROR(IF(compras_mes2[[#This Row],[CUIT]]="","-",VLOOKUP(compras_mes2[[#This Row],[CUIT]],Lista_CUIT[#All],2,0)),"CUIT NO CARGADO") -> ITALOMED PRODUCTOS SRL | H18: 355547.74 | I18: =IF(compras_mes2[[#This Row],[NETO GRAVADO]]="","",compras_mes2[[#This Row],[NETO GRAVADO]]*0.21) -> 74665.025 | P18: =SUM(compras_mes2[[#This Row],[NETO GRAVADO]:[Otros / No Grav.]]) -> 430212.77 | Q18: =IFERROR(IF(compras_mes2[[#This Row],[CUIT]]="","-",VLOOKUP(compras_mes2[[#This Row],[CUIT]],Lista_CUIT[#All],3,0)),"CUIT NO CARGADO") -> INSUMO | R18: =IFERROR(IF(compras_mes2[[#This Row],[CUIT]]="","-",VLOOKUP(compras_mes2[[#This Row],[CUIT]],Lista_CUIT[#All],4,0)),"CUIT NO CARGADO") -> 0 | S18: 23837
B19: 45692 | C19: 1 | D19: 17 | E19: 11625 | F19: 30661143610 | G19: =IFERROR(IF(compras_mes2[[#This Row],[CUIT]]="","-",VLOOKUP(compras_mes2[[#This Row],[CUIT]],Lista_CUIT[#All],2,0)),"CUIT NO CARGADO") -> ORTOPEDIA BERNAT SRL | H19: 643559.14 | I19: =IF(compras_mes2[[#This Row],[NETO GRAVADO]]="","",compras_mes2[[#This Row],[NETO GRAVADO]]*0.21) -> 135147.42 | P19: =SUM(compras_mes2[[#This Row],[NETO GRAVADO]:[Otros / No Grav.]]) -> 778706.56 | Q19: =IFERROR(IF(compras_mes2[[#This Row],[CUIT]]="","-",VLOOKUP(compras_mes2[[#This Row],[CUIT]],Lista_CUIT[#All],3,0)),"CUIT NO CARGADO") -> INSUMO | R19: =IFERROR(IF(compras_mes2[[#This Row],[CUIT]]="","-",VLOOKUP(compras_mes2[[#This Row],[CUIT]],Lista_CUIT[#All],4,0)),"CUIT NO CARGADO") -> 0 | S19: 1394.63
B20: 45692 | C20: 1 | D20: 5 | E20: 163325 | F20: 30598960093 | G20: =IFERROR(IF(compras_mes2[[#This Row],[CUIT]]="","-",VLOOKUP(compras_mes2[[#This Row],[CUIT]],Lista_CUIT[#All],2,0)),"CUIT NO CARGADO") -> SILVESTRIN FABRIS SRL | H20: 453720 | I20: =IF(compras_mes2[[#This Row],[NETO GRAVADO]]="","",compras_mes2[[#This Row],[NETO GRAVADO]]*0.21) -> 95281.2 | P20: =SUM(compras_mes2[[#This Row],[NETO GRAVADO]:[Otros / No Grav.]]) -> 549001.2 | Q20: =IFERROR(IF(compras_mes2[[#This Row],[CUIT]]="","-",VLOOKUP(compras_mes2[[#This Row],[CUIT]],Lista_CUIT[#All],3,0)),"CUIT NO CARGADO") -> INSUMO | R20: =IFERROR(IF(compras_mes2[[#This Row],[CUIT]]="","-",VLOOKUP(compras_mes2[[#This Row],[CUIT]],Lista_CUIT[#All],4,0)),"CUIT NO CARGADO") -> 0 | S20: 1394.63
B21: 45692 | C21: 1 | D21: 5 | E21: 2205 | F21: 30712187316 | G21: =IFERROR(IF(compras_mes2[[#This Row],[CUIT]]="","-",VLOOKUP(compras_mes2[[#This Row],[CUIT]],Lista_CUIT[#All],2,0)),"CUIT NO CARGADO") -> ITALOMED PRODUCTOS SRL | H21: 219513.44 | I21: =IF(compras_mes2[[#This Row],[NETO GRAVADO]]="","",compras_mes2[[#This Row],[NETO GRAVADO]]*0.21) -> 46097.822 | P21: =SUM(compras_mes2[[#This Row],[NETO GRAVADO]:[Otros / No Grav.]]) -> 265611.26 | Q21: =IFERROR(IF(compras_mes2[[#This Row],[CUIT]]="","-",VLOOKUP(compras_mes2[[#This Row],[CUIT]],Lista_CUIT[#All],3,0)),"CUIT NO CARGADO") -> INSUMO | R21: =IFERROR(IF(compras_mes2[[#This Row],[CUIT]]="","-",VLOOKUP(compras_mes2[[#This Row],[CUIT]],Lista_CUIT[#All],4,0)),"CUIT NO CARGADO") -> 0 | S21: 171435
B22: 45693 | C22: 1 | D22: 700 | E22: 2247740 | F22: 30715804812 | G22: =IFERROR(IF(compras_mes2[[#This Row],[CUIT]]="","-",VLOOKUP(compras_mes2[[#This Row],[CUIT]],Lista_CUIT[#All],2,0)),"CUIT NO CARGADO") -> CORREDORES VIALES SOCIEDAD ANONIMA | H22: 2079.97 | I22: =IF(compras_mes2[[#This Row],[NETO GRAVADO]]="","",compras_mes2[[#This Row],[NETO GRAVADO]]*0.21) -> 436.7937 | P22: =SUM(compras_mes2[[#This Row],[NETO GRAVADO]:[Otros / No Grav.]]) -> 2516.7637 | Q22: =IFERROR(IF(compras_mes2[[#This Row],[CUIT]]="","-",VLOOKUP(compras_mes2[[#This Row],[CUIT]],Lista_CUIT[#All],3,0)),"CUIT NO CARGADO") -> Autopista | R22: =IFERROR(IF(compras_mes2[[#This Row],[CUIT]]="","-",VLOOKUP(compras_mes2[[#This Row],[CUIT]],Lista_CUIT[#All],4,0)),"CUIT NO CARGADO") -> 0 | S22: 481999
B23: 45693 | C23: 1 | D23: 700 | E23: 2247741 | F23: 30715804812 | G23: =IFERROR(IF(compras_mes2[[#This Row],[CUIT]]="","-",VLOOKUP(compras_mes2[[#This Row],[CUIT]],Lista_CUIT[#All],2,0)),"CUIT NO CARGADO") -> CORREDORES VIALES SOCIEDAD ANONIMA | H23: 5407.9 | I23: =IF(compras_mes2[[#This Row],[NETO GRAVADO]]="","",compras_mes2[[#This Row],[NETO GRAVADO]]*0.21) -> 1135.659 | P23: =SUM(compras_mes2[[#This Row],[NETO GRAVADO]:[Otros / No Grav.]]) -> 6543.559 | Q23: =IFERROR(IF(compras_mes2[[#This Row],[CUIT]]="","-",VLOOKUP(compras_mes2[[#This Row],[CUIT]],Lista_CUIT[#All],3,0)),"CUIT NO CARGADO") -> Autopista | R23: =IFERROR(IF(compras_mes2[[#This Row],[CUIT]]="","-",VLOOKUP(compras_mes2[[#This Row],[CUIT]],Lista_CUIT[#All],4,0)),"CUIT NO CARGADO") -> 0 | S23: 116708
... B31: 45696 | C31: 1 | D31: 2019 | E31: 266598 | F31: 30516186670 | G31: =IFERROR(IF(compras_mes2[[#This Row],[CUIT]]="","-",VLOOKUP(compras_mes2[[#This Row],[CUIT]],Lista_CUIT[#All],2,0)),"CUIT NO CARGADO") -> DEHEZA SAICF E I | H31: 40217.66 | I31: =IF(compras_mes2[[#This Row],[NETO GRAVADO]]="","",compras_mes2[[#This Row],[NETO GRAVADO]]*0.21) -> 8445.7086 | P31: =SUM(compras_mes2[[#This Row],[NETO GRAVADO]:[Otros / No Grav.]]) -> 48663.369 | Q31: =IFERROR(IF(compras_mes2[[#This Row],[CUIT]]="","-",VLOOKUP(compras_mes2[[#This Row],[CUIT]],Lista_CUIT[#All],3,0)),"CUIT NO CARGADO") -> COMBUSTIBLE | R31: =IFERROR(IF(compras_mes2[[#This Row],[CUIT]]="","-",VLOOKUP(compras_mes2[[#This Row],[CUIT]],Lista_CUIT[#All],4,0)),"CUIT NO CARGADO") -> 0 | S31: 956080
B32: 45696 | C32: 1 | D32: 711 | E32: 6694090 | F32: 30677237119 | G32: =IFERROR(IF(compras_mes2[[#This Row],[CUIT]]="","-",VLOOKUP(compras_mes2[[#This Row],[CUIT]],Lista_CUIT[#All],2,0)),"CUIT NO CARGADO") -> AUTOPISTAS DEL SOL SA | H32: 5430.98 | I32: =IF(compras_mes2[[#This Row],[NETO GRAVADO]]="","",compras_mes2[[#This Row],[NETO GRAVADO]]*0.21) -> 1140.5058 | O32: 162.93 | P32: =SUM(compras_mes2[[#This Row],[NETO GRAVADO]:[Otros / No Grav.]]) -> 6734.4158 | Q32: =IFERROR(IF(compras_mes2[[#This Row],[CUIT]]="","-",VLOOKUP(compras_mes2[[#This Row],[CUIT]],Lista_CUIT[#All],3,0)),"CUIT NO CARGADO") -> Autopista | R32: =IFERROR(IF(compras_mes2[[#This Row],[CUIT]]="","-",VLOOKUP(compras_mes2[[#This Row],[CUIT]],Lista_CUIT[#All],4,0)),"CUIT NO CARGADO") -> 0 | S32: 413221.08
B33: 45696 | C33: 1 | D33: 5015 | E33: 745697 | F33: 30574876474 | G33: =IFERROR(IF(compras_mes2[[#This Row],[CUIT]]="","-",VLOOKUP(compras_mes2[[#This Row],[CUIT]],Lista_CUIT[#All],2,0)),"CUIT NO CARGADO") -> AUTOP. URBANAS SA | H33: 22267.28 | I33: =IF(compras_mes2[[#This Row],[NETO GRAVADO]]="","",compras_mes2[[#This Row],[NETO GRAVADO]]*0.21) -> 4676.1288 | P33: =SUM(compras_mes2[[#This Row],[NETO GRAVADO]:[Otros / No Grav.]]) -> 26943.409 | Q33: =IFERROR(IF(compras_mes2[[#This Row],[CUIT]]="","-",VLOOKUP(compras_mes2[[#This Row],[CUIT]],Lista_CUIT[#All],3,0)),"CUIT NO CARGADO") -> PEAJE | R33: =IFERROR(IF(compras_mes2[[#This Row],[CUIT]]="","-",VLOOKUP(compras_mes2[[#This Row],[CUIT]],Lista_CUIT[#All],4,0)),"CUIT NO CARGADO") -> 0 | S33: 87109.57
B34: 45697 | C34: 1 | D34: 3101 | E34: 263748 | F34: 30678814357 | G34: =IFERROR(IF(compras_mes2[[#This Row],[CUIT]]="","-",VLOOKUP(compras_mes2[[#This Row],[CUIT]],Lista_CUIT[#All],2,0)),"CUIT NO CARGADO") -> TELEFONICA MOVILES ARG SA | H34: 91600.07 | J34: =compras_mes2[[#This Row],[NETO GRAVADO]]*27/100 -> 24732.019 | P34: =SUM(compras_mes2[[#This Row],[NETO GRAVADO]:[Otros / No Grav.]]) -> 116332.09 | Q34: =IFERROR(IF(compras_mes2[[#This Row],[CUIT]]="","-",VLOOKUP(compras_mes2[[#This Row],[CUIT]],Lista_CUIT[#All],3,0)),"CUIT NO CARGADO") -> SERVICIO | R34: =IFERROR(IF(compras_mes2[[#This Row],[CUIT]]="","-",VLOOKUP(compras_mes2[[#This Row],[CUIT]],Lista_CUIT[#All],4,0)),"CUIT NO CARGADO") -> 0 | S34: 5371.9
B35: 45698 | C35: 1 | D35: 2 | E35: 11420 | F35: 30714331082 | G35: =IFERROR(IF(compras_mes2[[#This Row],[CUIT]]="","-",VLOOKUP(compras_mes2[[#This Row],[CUIT]],Lista_CUIT[#All],2,0)),"CUIT NO CARGADO") -> ORTOPEDIA CASA ESCALADA SRL | H35: 4007577.6 | I35: =IF(compras_mes2[[#This Row],[NETO GRAVADO]]="","",compras_mes2[[#This Row],[NETO GRAVADO]]*0.21) -> 841591.31 | P35: =SUM(compras_mes2[[#This Row],[NETO GRAVADO]:[Otros / No Grav.]]) -> 4849169 | Q35: =IFERROR(IF(compras_mes2[[#This Row],[CUIT]]="","-",VLOOKUP(compras_mes2[[#This Row],[CUIT]],Lista_CUIT[#All],3,0)),"CUIT NO CARGADO") -> INSUMO | R35: =IFERROR(IF(compras_mes2[[#This Row],[CUIT]]="","-",VLOOKUP(compras_mes2[[#This Row],[CUIT]],Lista_CUIT[#All],4,0)),"CUIT NO CARGADO") -> 0 | S35: 6596.25
B36: 45698 | C36: 1 | D36: 2 | E36: 11419 | F36: 30714331082 | G36: =IFERROR(IF(compras_mes2[[#This Row],[CUIT]]="","-",VLOOKUP(compras_mes2[[#This Row],[CUIT]],Lista_CUIT[#All],2,0)),"CUIT NO CARGADO") -> ORTOPEDIA CASA ESCALADA SRL | H36: 465345.68 | K36: =compras_mes2[[#This Row],[NETO GRAVADO]]*10.5/100 -> 48861.296 | P36: =SUM(compras_mes2[[#This Row],[NETO GRAVADO]:[Otros / No Grav.]]) -> 514206.98 | Q36: =IFERROR(IF(compras_mes2[[#This Row],[CUIT]]="","-",VLOOKUP(compras_mes2[[#This Row],[CUIT]],Lista_CUIT[#All],3,0)),"CUIT NO CARGADO") -> INSUMO | R36: =IFERROR(IF(compras_mes2[[#This Row],[CUIT]]="","-",VLOOKUP(compras_mes2[[#This Row],[CUIT]],Lista_CUIT[#All],4,0)),"CUIT NO CARGADO") -> 0 | S36: 22929.5
B37: 45698 | C37: 1 | D37: 6 | E37: 88871 | F37: 30711553564 | G37: =IFERROR(IF(compras_mes2[[#This Row],[CUIT]]="","-",VLOOKUP(compras_mes2[[#This Row],[CUIT]],Lista_CUIT[#All],2,0)),"CUIT NO CARGADO") -> SALUD TEX S.A | H37: 279138.5 | I37: =IF(compras_mes2[[#This Row],[NETO GRAVADO]]="","",compras_mes2[[#This Row],[NETO GRAVADO]]*0.21) -> 58619.085 | P37: =SUM(compras_mes2[[#This Row],[NETO GRAVADO]:[Otros / No Grav.]]) -> 337757.59 | Q37: =IFERROR(IF(compras_mes2[[#This Row],[CUIT]]="","-",VLOOKUP(compras_mes2[[#This Row],[CUIT]],Lista_CUIT[#All],3,0)),"CUIT NO CARGADO") -> INSUMO | R37: =IFERROR(IF(compras_mes2[[#This Row],[CUIT]]="","-",VLOOKUP(compras_mes2[[#This Row],[CUIT]],Lista_CUIT[#All],4,0)),"CUIT NO CARGADO") -> 0 | S37: 285000
B38: 45698 | C38: 1 | D38: 3 | E38: 47974 | F38: 30711454388 | G38: =IFERROR(IF(compras_mes2[[#This Row],[CUIT]]="","-",VLOOKUP(compras_mes2[[#This Row],[CUIT]],Lista_CUIT[#All],2,0)),"CUIT NO CARGADO") -> LIPROT S.R.L. | H38: 163900 | I38: =IF(compras_mes2[[#This Row],[NETO GRAVADO]]="","",compras_mes2[[#This Row],[NETO GRAVADO]]*0.21) -> 34419 | P38: =SUM(compras_mes2[[#This Row],[NETO GRAVADO]:[Otros / No Grav.]]) -> 198319 | Q38: =IFERROR(IF(compras_mes2[[#This Row],[CUIT]]="","-",VLOOKUP(compras_mes2[[#This Row],[CUIT]],Lista_CUIT[#All],3,0)),"CUIT NO CARGADO") -> textil | R38: =IFERROR(IF(compras_mes2[[#This Row],[CUIT]]="","-",VLOOKUP(compras_mes2[[#This Row],[CUIT]],Lista_CUIT[#All],4,0)),"CUIT NO CARGADO") -> 0 | S38: 40214.11
B39: 45699 | C39: 1 | D39: 26 | E39: 203264 | F39: 30708847247 | G39: =IFERROR(IF(compras_mes2[[#This Row],[CUIT]]="","-",VLOOKUP(compras_mes2[[#This Row],[CUIT]],Lista_CUIT[#All],2,0)),"CUIT NO CARGADO") -> TOAGRA SRL | H39: 12815.9 | I39: =IF(compras_mes2[[#This Row],[NETO GRAVADO]]="","",compras_mes2[[#This Row],[NETO GRAVADO]]*0.21) -> 2691.339 | P39: =SUM(compras_mes2[[#This Row],[NETO GRAVADO]:[Otros / No Grav.]]) -> 15507.239 | Q39: =IFERROR(IF(compras_mes2[[#This Row],[CUIT]]="","-",VLOOKUP(compras_mes2[[#This Row],[CUIT]],Lista_CUIT[#All],3,0)),"CUIT NO CARGADO") -> FLETE | R39: =IFERROR(IF(compras_mes2[[#This Row],[CUIT]]="","-",VLOOKUP(compras_mes2[[#This Row],[CUIT]],Lista_CUIT[#All],4,0)),"CUIT NO CARGADO") -> 0 | S39: 34999.98
B40: 45699 | C40: 1 | D40: 1 | E40: 6332 | F40: 30715141201 | G40: =IFERROR(IF(compras_mes2[[#This Row],[CUIT]]="","-",VLOOKUP(compras_mes2[[#This Row],[CUIT]],Lista_CUIT[#All],2,0)),"CUIT NO CARGADO") -> REHAB SRL | H40: 64545 | I40: =IF(compras_mes2[[#This Row],[NETO GRAVADO]]="","",compras_mes2[[#This Row],[NETO GRAVADO]]*0.21) -> 13554.45 | P40: =SUM(compras_mes2[[#This Row],[NETO GRAVADO]:[Otros / No Grav.]]) -> 78099.45 | Q40: =IFERROR(IF(compras_mes2[[#This Row],[CUIT]]="","-",VLOOKUP(compras_mes2[[#This Row],[CUIT]],Lista_CUIT[#All],3,0)),"CUIT NO CARGADO") -> INSUMO | R40: =IFERROR(IF(compras_mes2[[#This Row],[CUIT]]="","-",VLOOKUP(compras_mes2[[#This Row],[CUIT]],Lista_CUIT[#All],4,0)),"CUIT NO CARGADO") -> 0 | S40: 24000
B41: 45699 | C41: 1 | D41: 32 | E41: 156584 | F41: 30708847247 | G41: =IFERROR(IF(compras_mes2[[#This Row],[CUIT]]="","-",VLOOKUP(compras_mes2[[#This Row],[CUIT]],Lista_CUIT[#All],2,0)),"CUIT NO CARGADO") -> TOAGRA SRL | H41: 27257.62 | I41: =IF(compras_mes2[[#This Row],[NETO GRAVADO]]="","",compras_mes2[[#This Row],[NETO GRAVADO]]*0.21) -> 5724.1002 | P41: =SUM(compras_mes2[[#This Row],[NETO GRAVADO]:[Otros / No Grav.]]) -> 32981.72 | Q41: =IFERROR(IF(compras_mes2[[#This Row],[CUIT]]="","-",VLOOKUP(compras_mes2[[#This Row],[CUIT]],Lista_CUIT[#All],3,0)),"CUIT NO CARGADO") -> FLETE | R41: =IFERROR(IF(compras_mes2[[#This Row],[CUIT]]="","-",VLOOKUP(compras_mes2[[#This Row],[CUIT]],Lista_CUIT[#All],4,0)),"CUIT NO CARGADO") -> 0 | S41: 808361.07
B42: 45699 | C42: 1 | D42: 120 | E42: 5506 | F42: 30587197215 | G42: =IFERROR(IF(compras_mes2[[#This Row],[CUIT]]="","-",VLOOKUP(compras_mes2[[#This Row],[CUIT]],Lista_CUIT[#All],2,0)),"CUIT NO CARGADO") -> PANATEL SOCIEDAD ANONIMA | H42: 95041.32 | I42: =IF(compras_mes2[[#This Row],[NETO GRAVADO]]="","",compras_mes2[[#This Row],[NETO GRAVADO]]*0.21) -> 19958.677 | P42: =SUM(compras_mes2[[#This Row],[NETO GRAVADO]:[Otros / No Grav.]]) -> 115000 | Q42: =IFERROR(IF(compras_mes2[[#This Row],[CUIT]]="","-",VLOOKUP(compras_mes2[[#This Row],[CUIT]],Lista_CUIT[#All],3,0)),"CUIT NO CARGADO") -> SERVICIOS DE ALOJAMIENTO EN HOTELES | R42: =IFERROR(IF(compras_mes2[[#This Row],[CUIT]]="","-",VLOOKUP(compras_mes2[[#This Row],[CUIT]],Lista_CUIT[#All],4,0)),"CUIT NO CARGADO") -> 0 | S42: 2834920
B43: 45699 | C43: 1 | D43: 5 | E43: 1460 | F43: 27265302225 | G43: =IFERROR(IF(compras_mes2[[#This Row],[CUIT]]="","-",VLOOKUP(compras_mes2[[#This Row],[CUIT]],Lista_CUIT[#All],2,0)),"CUIT NO CARGADO") -> PRADO MARISOL | H43: 1 | I43: =IF(compras_mes2[[#This Row],[NETO GRAVADO]]="","",compras_mes2[[#This Row],[NETO GRAVADO]]*0.21) -> 0.21 | P43: =SUM(compras_mes2[[#This Row],[NETO GRAVADO]:[Otros / No Grav.]]) -> 1.21 | Q43: =IFERROR(IF(compras_mes2[[#This Row],[CUIT]]="","-",VLOOKUP(compras_mes2[[#This Row],[CUIT]],Lista_CUIT[#All],3,0)),"CUIT NO CARGADO") -> INSUMO | R43: =IFERROR(IF(compras_mes2[[#This Row],[CUIT]]="","-",VLOOKUP(compras_mes2[[#This Row],[CUIT]],Lista_CUIT[#All],4,0)),"CUIT NO CARGADO") -> 0 | S43: 5853.75
B44: 45700 | C44: 1 | D44: 2 | E44: 11442 | F44: 30714331082 | G44: =IFERROR(IF(compras_mes2[[#This Row],[CUIT]]="","-",VLOOKUP(compras_mes2[[#This Row],[CUIT]],Lista_CUIT[#All],2,0)),"CUIT NO CARGADO") -> ORTOPEDIA CASA ESCALADA SRL | H44: 1269066.3 | I44: =IF(compras_mes2[[#This Row],[NETO GRAVADO]]="","",compras_mes2[[#This Row],[NETO GRAVADO]]*0.21) -> 266503.91 | P44: =SUM(compras_mes2[[#This Row],[NETO GRAVADO]:[Otros / No Grav.]]) -> 1535570.2 | Q44: =IFERROR(IF(compras_mes2[[#This Row],[CUIT]]="","-",VLOOKUP(compras_mes2[[#This Row],[CUIT]],Lista_CUIT[#All],3,0)),"CUIT NO CARGADO") -> INSUMO | R44: =IFERROR(IF(compras_mes2[[#This Row],[CUIT]]="","-",VLOOKUP(compras_mes2[[#This Row],[CUIT]],Lista_CUIT[#All],4,0)),"CUIT NO CARGADO") -> 0 | S44: 7290406.4
B45: 45700 | C45: 1 | D45: 5 | E45: 163567 | F45: 30598960093 | G45: =IFERROR(IF(compras_mes2[[#This Row],[CUIT]]="","-",VLOOKUP(compras_mes2[[#This Row],[CUIT]],Lista_CUIT[#All],2,0)),"CUIT NO CARGADO") -> SILVESTRIN FABRIS SRL | H45: 1231762.2 | I45: 25389.88 | K45: 116640.09 | P45: =SUM(compras_mes2[[#This Row],[NETO GRAVADO]:[Otros / No Grav.]]) -> 1373792.2 | Q45: =IFERROR(IF(compras_mes2[[#This Row],[CUIT]]="","-",VLOOKUP(compras_mes2[[#This Row],[CUIT]],Lista_CUIT[#All],3,0)),"CUIT NO CARGADO") -> INSUMO | R45: =IFERROR(IF(compras_mes2[[#This Row],[CUIT]]="","-",VLOOKUP(compras_mes2[[#This Row],[CUIT]],Lista_CUIT[#All],4,0)),"CUIT NO CARGADO") -> 0 | S45: 39750.27
B46: 45700 | C46: 1 | D46: 2 | E46: 11443 | F46: 30714331082 | G46: =IFERROR(IF(compras_mes2[[#This Row],[CUIT]]="","-",VLOOKUP(compras_mes2[[#This Row],[CUIT]],Lista_CUIT[#All],2,0)),"CUIT NO CARGADO") -> ORTOPEDIA CASA ESCALADA SRL | H46: 341383.77 | I46: =IF(compras_mes2[[#This Row],[NETO GRAVADO]]="","",compras_mes2[[#This Row],[NETO GRAVADO]]*0.21) -> 71690.592 | P46: =SUM(compras_mes2[[#This Row],[NETO GRAVADO]:[Otros / No Grav.]]) -> 413074.36 | Q46: =IFERROR(IF(compras_mes2[[#This Row],[CUIT]]="","-",VLOOKUP(compras_mes2[[#This Row],[CUIT]],Lista_CUIT[#All],3,0)),"CUIT NO CARGADO") -> INSUMO | R46: =IFERROR(IF(compras_mes2[[#This Row],[CUIT]]="","-",VLOOKUP(compras_mes2[[#This Row],[CUIT]],Lista_CUIT[#All],4,0)),"CUIT NO CARGADO") -> 0 | S46: 210139.51
B47: 45701 | C47: 1 | D47: 5 | E47: 24333 | F47: 30656038752 | G47: =IFERROR(IF(compras_mes2[[#This Row],[CUIT]]="","-",VLOOKUP(compras_mes2[[#This Row],[CUIT]],Lista_CUIT[#All],2,0)),"CUIT NO CARGADO") -> ALFREDO OMAR POTENZA SRL | H47: 314389.25 | I47: =IF(compras_mes2[[#This Row],[NETO GRAVADO]]="","",compras_mes2[[#This Row],[NETO GRAVADO]]*0.21) -> 66021.742 | P47: =SUM(compras_mes2[[#This Row],[NETO GRAVADO]:[Otros / No Grav.]]) -> 380410.99 | Q47: =IFERROR(IF(compras_mes2[[#This Row],[CUIT]]="","-",VLOOKUP(compras_mes2[[#This Row],[CUIT]],Lista_CUIT[#All],3,0)),"CUIT NO CARGADO") -> INSUMO | R47: =IFERROR(IF(compras_mes2[[#This Row],[CUIT]]="","-",VLOOKUP(compras_mes2[[#This Row],[CUIT]],Lista_CUIT[#All],4,0)),"CUIT NO CARGADO") -> 0 | S47: 130482.28
B48: 45701 | C48: 1 | D48: 2 | E48: 1080 | F48: 20272865869 | G48: =IFERROR(IF(compras_mes2[[#This Row],[CUIT]]="","-",VLOOKUP(compras_mes2[[#This Row],[CUIT]],Lista_CUIT[#All],2,0)),"CUIT NO CARGADO") -> DI FEO MARTIN EZEQUIEL | H48: 397580 | I48: =IF(compras_mes2[[#This Row],[NETO GRAVADO]]="","",compras_mes2[[#This Row],[NETO GRAVADO]]*0.21) -> 83491.8 | P48: =SUM(compras_mes2[[#This Row],[NETO GRAVADO]:[Otros / No Grav.]]) -> 481071.8 | Q48: =IFERROR(IF(compras_mes2[[#This Row],[CUIT]]="","-",VLOOKUP(compras_mes2[[#This Row],[CUIT]],Lista_CUIT[#All],3,0)),"CUIT NO CARGADO") -> INSUMOS | R48: =IFERROR(IF(compras_mes2[[#This Row],[CUIT]]="","-",VLOOKUP(compras_mes2[[#This Row],[CUIT]],Lista_CUIT[#All],4,0)),"CUIT NO CARGADO") -> 0 | S48: 126445
B49: 45702 | C49: 1 | D49: 5 | E49: 2227 | F49: 30712187316 | G49: =IFERROR(IF(compras_mes2[[#This Row],[CUIT]]="","-",VLOOKUP(compras_mes2[[#This Row],[CUIT]],Lista_CUIT[#All],2,0)),"CUIT NO CARGADO") -> ITALOMED PRODUCTOS SRL | H49: 400088.92 | I49: =IF(compras_mes2[[#This Row],[NETO GRAVADO]]="","",compras_mes2[[#This Row],[NETO GRAVADO]]*0.21) -> 84018.673 | P49: =SUM(compras_mes2[[#This Row],[NETO GRAVADO]:[Otros / No Grav.]]) -> 484107.59 | Q49: =IFERROR(IF(compras_mes2[[#This Row],[CUIT]]="","-",VLOOKUP(compras_mes2[[#This Row],[CUIT]],Lista_CUIT[#All],3,0)),"CUIT NO CARGADO") -> INSUMO | R49: =IFERROR(IF(compras_mes2[[#This Row],[CUIT]]="","-",VLOOKUP(compras_mes2[[#This Row],[CUIT]],Lista_CUIT[#All],4,0)),"CUIT NO CARGADO") -> 0 | S49: 44000
B50: 45702 | C50: 1 | D50: 2 | E50: 1083 | F50: 20272865869 | G50: =IFERROR(IF(compras_mes2[[#This Row],[CUIT]]="","-",VLOOKUP(compras_mes2[[#This Row],[CUIT]],Lista_CUIT[#All],2,0)),"CUIT NO CARGADO") -> DI FEO MARTIN EZEQUIEL | H50: 12050 | I50: =IF(compras_mes2[[#This Row],[NETO GRAVADO]]="","",compras_mes2[[#This Row],[NETO GRAVADO]]*0.21) -> 2530.5 | P50: =SUM(compras_mes2[[#This Row],[NETO GRAVADO]:[Otros / No Grav.]]) -> 14580.5 | Q50: =IFERROR(IF(compras_mes2[[#This Row],[CUIT]]="","-",VLOOKUP(compras_mes2[[#This Row],[CUIT]],Lista_CUIT[#All],3,0)),"CUIT NO CARGADO") -> INSUMOS | R50: =IFERROR(IF(compras_mes2[[#This Row],[CUIT]]="","-",VLOOKUP(compras_mes2[[#This Row],[CUIT]],Lista_CUIT[#All],4,0)),"CUIT NO CARGADO") -> 0 | S50: 226834.59
B51: 45702 | C51: 1 | D51: 8 | E51: 369 | F51: 30643518364 | G51: =IFERROR(IF(compras_mes2[[#This Row],[CUIT]]="","-",VLOOKUP(compras_mes2[[#This Row],[CUIT]],Lista_CUIT[#All],2,0)),"CUIT NO CARGADO") -> FARMACIA DE MEDRANO SCS | H51: 390810 | I51: =IF(compras_mes2[[#This Row],[NETO GRAVADO]]="","",compras_mes2[[#This Row],[NETO GRAVADO]]*0.21) -> 82070.1 | P51: =SUM(compras_mes2[[#This Row],[NETO GRAVADO]:[Otros / No Grav.]]) -> 472880.1 | Q51: =IFERROR(IF(compras_mes2[[#This Row],[CUIT]]="","-",VLOOKUP(compras_mes2[[#This Row],[CUIT]],Lista_CUIT[#All],3,0)),"CUIT NO CARGADO") -> INSUMO | R51: =IFERROR(IF(compras_mes2[[#This Row],[CUIT]]="","-",VLOOKUP(compras_mes2[[#This Row],[CUIT]],Lista_CUIT[#All],4,0)),"CUIT NO CARGADO") -> 0 | S51: 115000
...

Sheet Mar-25
B1: LIBRO IVA COMPRAS | G1: ='Ene-25'!G1:M1 -> ORTOPEDIA GEMINIS S.A. | N1: =EDATE('Ene-25'!N1,2) -> 45717
B3: TOTAL COMPRAS | G3: TOTAL CREDITO FISCAL | J3: TOTAL VENTAS NETAS | M3: TOTAL DEBITO FISCAL | P3: RESULTADO
B4: =SUM(compras_mes3[[#Totals],[NETO GRAVADO]])+extracto_banco_mes3[[#Totals],[NETO]]+O72 -> 22713890 | G4: =compras_mes3[[#Totals],[IVA 21 %]]+compras_mes3[[#Totals],[IVA 27%]]+compras_mes3[[#Totals],[IVA 10,5%]]+extracto_banco_mes3[[#Totals],[IVA 21%]]+extracto_banco_mes3[[#Totals],[IVA 10,5%]] -> 4741924.9 | J4: =venta_a_mes3[[#Totals],[IMPORTE NETO]]+ventas_b_mes3[[#Totals],[IMPORTE NETO]] -> 0 | M4: =venta_a_mes3[[#Totals],[IVA 21%]]+venta_a_mes3[[#Totals],[IVA 10,5%]]+ventas_b_mes3[[#Totals],[IVA 21%]]+ventas_b_mes3[[#Totals],[IVA 10,5%]] -> 0 | P4: =G4-M4 -> 4741924.9
B8: FECHA | C8: TIPO | D8: PTO VTA | E8: NRO. CPTE | F8: CUIT | G8: RAZON SOCIAL | H8: NETO GRAVADO | I8: IVA 21 % | J8: IVA 27% | K8: IVA 10,5% | L8: PERC. IVA | M8: PERC IIBB BS AS | N8: PERC. IIBB CABA | O8: Otros / No Grav. | P8: TOTAL | Q8: Tipo de Gasto | R8: Provincia
