Workbook
Name partner_id: Configuracion!$B$332

Sheet Configuracion
F1: CUIT | G1: Cargar sin guiones
F2: RAZON SOCIAL | G2: Maximo 30 caracteres
A3: CUIT | B3: RAZON SOCIAL | C3: DETALLE | F3: DETALLE | G3: Cargar tipo de gasto
A4: 30628205090 | B4: ALBAMIE SA | C4: CLIENTE
A5: 30711678820 | B5: 2PSI INGENIERIA SRL | C5: PROVEEDOR
A6: 33716367539 | B6: 3PI S.A.S. | C6: PROVEEDOR
A7: 30660373108 | B7: ABC SA | C7: VARIOS
A8: 20300210881 | B8: ABOY DIEGO OSCAR | C8: PROVEEDOR
A9: 27229910782 | B9: ABUGAUCH MARIA DE LOS ANGELES | C9: PROVEEDOR
A10: 20242709897 | B10: ABUGAUCH VICTOR HUGO | C10: PROVEEDOR
A11: 20281669053 | B11: ACOSTA JAVIER GUSTAVO | C11: FLETE
A12: 20174240125 | B12: ACOSTA OSCAR ISIDRO | C12: VARIOS
A13: 30641659106 | B13: AGRISOL SA | C13: VARIOS
A14: 33709914109 | B14: ALAN COLLECTION SA | C14: VARIOS
A15: 20267161616 | B15: ALBAJARI DIEGO MARCOS | C15: VARIOS
... A155: 30537679855 | B155: ESTACION LIMA SA | C155: VARIOS
A156: 30-56864959-8 | B156: EXPRESO BISONTE SRL | C156: FLETE
A157: 30708542349 | B157: EXPRESO FORMOSA SRL | C157: FLETE
A158: 30526582884 | B158: EXPRESO MAR DEL PLATA SA | C158: FLETE
A159: 30577744579 | B159: EXPRESO TROLE SRL | C159: FLETE
A160: 30715949292 | B160: EYPAPEL SAS | C160: GASTOS VARIOS
A161: 30715980807 | B161: FABORT SRL | C161: PROVEEDOR
A162: 20359718765 | B162: FAIL ABRAHAM | C162: VARIOS
A163: 30643518364 | B163: FARMACIA DE MEDRANO SCS | C163: PROVEEDOR
A164: 30692138747 | B164: FARMACITY SA | C164: VARIOS
A165: 33712234429 | B165: FEDAGAS SA | C165: VARIOS
A166: 20353576012 | B166: FEDERICO PABLO FEOLA | C166: VARIOS
A167: 20343766441 | B167: FERNANDEZ MAURO | C167: TALLER
A168: 27062343449 | B168: FERREIRA LILIANA INES | C168: FLETE
... A570: 30661273093 | B570: OSETRA | C570: CLIENTE

Sheet Octubre 25
A1: ORTOPEDIA GEMINIS S.A. | J1: 45931
A4: LIBRO IVA COMPRAS
A6: FACTURAS A
A7: FECHA | B7: PTO VTA | C7: FAC A | D7: CUIT | E7: RAZON SOCIAL | F7: NETO | G7: IVA 21% | H7: IVA 27% | I7: IVA 10,5% | J7: P IVA | K7: IIBB CF | L7: IIBB BS | M7: NO GRAV | N7: OTROS | O7: TOTAL | P7: DETALLE
E8: =VLOOKUP(D8,Configuracion!$A$4:$C$590,2,FALSE()) -> #N/A | G8: =F8*21% -> 0 | O8: =SUM(F8:N8) -> 0 | P8: =VLOOKUP(D8,Configuracion!$A$4:$C$590,3,FALSE()) -> #N/A
E9: =VLOOKUP(D9,Configuracion!$A$4:$C$590,2,FALSE()) -> #N/A | G9: =F9*21% -> 0 | O9: =SUM(F9:N9) -> 0 | P9: =VLOOKUP(D9,Configuracion!$A$4:$C$590,3,FALSE()) -> #N/A
E10: =VLOOKUP(D10,Configuracion!$A$4:$C$590,2,FALSE()) -> #N/A | G10: =F10*21% -> 0 | O10: =SUM(F10:N10) -> 0 | P10: =VLOOKUP(D10,Configuracion!$A$4:$C$590,3,FALSE()) -> #N/A
E11: =VLOOKUP(D11,Configuracion!$A$4:$C$590,2,FALSE()) -> #N/A | G11: =F11*21% -> 0 | O11: =SUM(F11:N11) -> 0 | P11: =VLOOKUP(D11,Configuracion!$A$4:$C$590,3,FALSE()) -> #N/A
E12: =VLOOKUP(D12,Configuracion!$A$4:$C$590,2,FALSE()) -> #N/A | G12: =F12*21% -> 0 | O12: =SUM(F12:N12) -> 0 | P12: =VLOOKUP(D12,Configuracion!$A$4:$C$590,3,FALSE()) -> #N/A
E13: =VLOOKUP(D13,Configuracion!$A$4:$C$590,2,FALSE()) -> #N/A | G13: =F13*21% -> 0 | O13: =SUM(F13:N13) -> 0 | P13: =VLOOKUP(D13,Configuracion!$A$4:$C$590,3,FALSE()) -> #N/A
E14: =VLOOKUP(D14,Configuracion!$A$4:$C$590,2,FALSE()) -> #N/A | G14: =F14*21% -> 0 | O14: =SUM(F14:N14) -> 0 | P14: =VLOOKUP(D14,Configuracion!$A$4:$C$590,3,FALSE()) -> #N/A
E15: =VLOOKUP(D15,Configuracion!$A$4:$C$590,2,FALSE()) -> #N/A | G15: =F15*21% -> 0 | O15: =SUM(F15:N15) -> 0 | P15: =VLOOKUP(D15,Configuracion!$A$4:$C$590,3,FALSE()) -> #N/A
E16: =VLOOKUP(D16,Configuracion!$A$4:$C$590,2,FALSE()) -> #N/A | G16: =F16*21% -> 0 | O16: =SUM(F16:N16) -> 0 | P16: =VLOOKUP(D16,Configuracion!$A$4:$C$590,3,FALSE()) -> #N/A
E17: =VLOOKUP(D17,Configuracion!$A$4:$C$590,2,FALSE()) -> #N/A | G17: =F17*21% -> 0 | O17: =SUM(F17:N17) -> 0 | P17: =VLOOKUP(D17,Configuracion!$A$4:$C$590,3,FALSE()) -> #N/A
A18: TOTAL | F18: =SUM(F8:F17) -> 0 | G18: =SUM(G8:G17) -> 0 | H18: =SUM(H8:H17) -> 0 | I18: =SUM(I8:I17) -> 0 | J18: =SUM(J8:J17) -> 0 | K18: =SUM(K8:K17) -> 0 | L18: =SUM(L8:L17) -> 0 | M18: =SUM(M8:M17) -> 0 | ... O18: =SUM(O8:O17) -> 0
F19: IVA | G19: =G18+H18+I18 -> 0
A21: FACTURAS B/C
A22: FECHA | B22: PTO VTA | C22: FAC C | D22: CUIT | E22: RAZON SOCIAL | F22: TOTAL | G22: DETALLE
E23: =VLOOKUP(D23,Configuracion!$A$4:$C$590,2,FALSE()) -> #N/A | G23: =VLOOKUP(D23,Configuracion!$A$4:$C$590,3,FALSE()) -> #N/A
E24: =VLOOKUP(D24,Configuracion!$A$4:$C$590,2,FALSE()) -> #N/A | G24: =VLOOKUP(D24,Configuracion!$A$4:$C$590,3,FALSE()) -> #N/A
E25: =VLOOKUP(D25,Configuracion!$A$4:$C$590,2,FALSE()) -> #N/A | G25: =VLOOKUP(D25,Configuracion!$A$4:$C$590,3,FALSE()) -> #N/A
E26: =VLOOKUP(D26,Configuracion!$A$4:$C$590,2,FALSE()) -> #N/A | G26: =VLOOKUP(D26,Configuracion!$A$4:$C$590,3,FALSE()) -> #N/A
E27: =VLOOKUP(D27,Configuracion!$A$4:$C$590,2,FALSE()) -> #N/A | G27: =VLOOKUP(D27,Configuracion!$A$4:$C$590,3,FALSE()) -> #N/A
E28: =VLOOKUP(D28,Configuracion!$A$4:$C$590,2,FALSE()) -> #N/A | G28: =VLOOKUP(D28,Configuracion!$A$4:$C$590,3,FALSE()) -> #N/A
E29: =VLOOKUP(D29,Configuracion!$A$4:$C$590,2,FALSE()) -> #N/A | G29: =VLOOKUP(D29,Configuracion!$A$4:$C$590,3,FALSE()) -> #N/A
E30: =VLOOKUP(D30,Configuracion!$A$4:$C$590,2,FALSE()) -> #N/A | G30: =VLOOKUP(D30,Configuracion!$A$4:$C$590,3,FALSE()) -> #N/A
E31: =VLOOKUP(D31,Configuracion!$A$4:$C$590,2,FALSE()) -> #N/A | G31: =VLOOKUP(D31,Configuracion!$A$4:$C$590,3,FALSE()) -> #N/A
E32: =VLOOKUP(D32,Configuracion!$A$4:$C$590,2,FALSE()) -> #N/A | G32: =VLOOKUP(D32,Configuracion!$A$4:$C$590,3,FALSE()) -> #N/A
E33: =VLOOKUP(D33,Configuracion!$A$4:$C$590,2,FALSE()) -> #N/A | G33: =VLOOKUP(D33,Configuracion!$A$4:$C$590,3,FALSE()) -> #N/A
E34: =VLOOKUP(D34,Configuracion!$A$4:$C$590,2,FALSE()) -> #N/A | G34: =VLOOKUP(D34,Configuracion!$A$4:$C$590,3,FALSE()) -> #N/A
... E41: =VLOOKUP(D41,Configuracion!$A$4:$C$590,2,FALSE()) -> #N/A | G41: =VLOOKUP(D41,Configuracion!$A$4:$C$590,3,FALSE()) -> #N/A
A42: TOTAL | F42: =SUM(F23:F41) -> 0
A44: RETENCIONES
A45: FECHA | B45: COMPROBANTE NRO | D45: CUIT | E45: RAZON SOCIAL | F45: GANANCIAS | G45: IVA | H45: IIBB | I45: SUSS
A46: 45950 | B46: 92687 | D46: 30522428163 | E46: =VLOOKUP(D46,Configuracion!$A$4:$C$590,2,FALSE()) -> GALENO ARGENTINA SA | G46: 693084.55
E47: =VLOOKUP(D47,Configuracion!$A$4:$C$590,2,FALSE()) -> #N/A
E48: =VLOOKUP(D48,Configuracion!$A$4:$C$590,2,FALSE()) -> #N/A
E49: =VLOOKUP(D49,Configuracion!$A$4:$C$590,2,FALSE()) -> #N/A
E50: =VLOOKUP(D50,Configuracion!$A$4:$C$590,2,FALSE()) -> #N/A
E51: =VLOOKUP(D51,Configuracion!$A$4:$C$590,2,FALSE()) -> #N/A
...

Sheet Calculo IVA
B1: ORTOPEDIA GEMINIS
A2: Calculo Iva | D2: 45931
B4: VENTAS
B5: Neto | C5: Iva | D5: Total
A6: FAC. "A" | B6: =+'Ventas 10'!D4+'Ventas 10'!D5 -> 1.3344938e+08 | C6: =+B6*0.21 -> 28024369 | D6: =+B6+C6 -> 1.6147374e+08
A7: FAC. "B" | B7: =+'Ventas 10'!D6+'Ventas 10'!D7+'Ventas 10'!D8 -> 31019426 | C7: =+B7*0.21 -> 6514079.4 | D7: =+B7+C7 -> 37533505
B8: =SUM(B6:B7) -> 1.644688e+08 | C8: =SUM(C6:C7) -> 34538448 | D8: =SUM(D6:D7) -> 1.9900725e+08
B11: COMPRAS
B12: Neto | C12: IVA | D12: Total
A13: Comprobantes / Extractos | B13: =+'Compras 10'!I177+'Compras 10'!J177+'Compras 10'!K177 -> 51535702 | C13: =+'Compras 10'!N177 -> 10623453 | D13: =+'Compras 10'!U177 -> 79402288
B16: =SUM(B13:B15) -> 51535702 | C16: =SUM(C13:C15) -> 10623453 | D16: =SUM(D13:D15) -> 79402288
A19: RETENCIONES | B19: N° Cuit | C19: Importe | D19: Nro. Retencion | E19: Fecha
A20: AFIP - No están informadas las retenciones de IVA en el sistema de AFIP
C35: =+'Octubre 25'!G79 -> 693084.55
A37: PERCEPCIONES | B37: N° Cuit | C37: Importe | D37: Nro. Retencion | E37: Fecha
C41: =SUM(C38:C40) -> 0
A43: Total Deducciociones | C43: =+C41+C35 -> 693084.55
C46: (Montos en Positivo)
A47: 1er Saldo Tecnico del Período | C47: =+C8-C16 -> 23914995
A49: Saldo Tecnico de período Anterior (a favor) | D49: (resta en el total)
A51: Saldo Neto Técnico | C51: =+C47-C49 -> 23914995
A55: Saldo L.D. del Período | C55: =+C41+C35 -> 693084.55
A57: Saldo L.D. del Período Anterior
A59: Neto S.L.D | C59: =+C55+C57 -> 693084.55
A62: I V A | C62: =+C51-C59 -> 23221911
A63: NOTA: Sin Tomar posibles Retenciones que se hayan hecho

Sheet Ventas 10
C2: Totales por Tipo de Comprobante - ARCA
D3: Base | E3: IVA | F3: Otros Imp. | G3: Total Compr.
C4: FACTURAS A | D4: 1.3832638e+08 | E4: =+D4*0.21 -> 29048540 | G4: =SUBTOTAL(9,D4:F4) -> 1.6737492e+08
C5: NC A | D5: -4877007.9 | E5: =+D5*0.21 -> -1024171.7 | G5: =SUBTOTAL(9,D5:F5) -> -5901179.5
C6: FACTURAS B | D6: 35076825 | E6: =+D6*0.21 -> 7366133.2 | G6: =SUBTOTAL(9,D6:F6) -> 42442958
C7: NC B | D7: -4057398.8 | E7: =+D7*0.21 -> -852053.74 | G7: =SUBTOTAL(9,D7:F7) -> -4909452.5
C8: ND B | E8: =+D8*0.21 -> 0 | G8: =SUBTOTAL(9,D8:F8) -> 0
D9: =SUBTOTAL(9,D4:D8) -> 1.644688e+08 | E9: =SUBTOTAL(9,E4:E8) -> 34538448 | F9: 0 | G9: =+E9+D9 -> 1.9900725e+08 | H9: =+SUBTOTAL(109,H12:H466) -> 1.644688e+08
A11: Fecha | B11: Razon Social | C11: Cuit | D11: Provincia | E11: Ciudad | F11: Condicion IVA | G11: Nro Factura | H11: Importe Neto Gravado | I11: Importe No Grav | J11: IVA2 | K11: IVA5 | L11: IVA10 | M11: IVA21 | N11: IVA27 | O11: IIBB | P11: Percepcion IVA | Q11: Otros Impuestos | R11: Total IVA | S11: Total Facturado | T11: Observaciones
A12: 01/10/2025 | B12: Galeno A.R.T. S.A. | C12: 30685228501 | D12: Ciudad de Buenos Aires | E12: SIN IDENTIFICAR | F12: EX | G12: FCB 0007-00006469 | H12: 494958.68 | I12: 0 | J12: 0 | K12: 0 | L12: 0 | M12: 103941.32 | N12: 0 | O12: 0 | P12: 0 | Q12: 0 | R12: 103941.32 | S12: 598900
A13: 01/10/2025 | B13: GIGAGLIA, MARIA LUCILA | C13: 25315045 | D13: Buenos Aires | E13: BECCAR | F13: CF | G13: FCB 0007-00006470 | H13: 18181.82 | I13: 0 | J13: 0 | K13: 0 | L13: 0 | M13: 3818.18 | N13: 0 | O13: 0 | P13: 0 | Q13: 0 | R13: 3818.18 | S13: 22000
A14: 01/10/2025 | B14: MAIZTEGUI ANDRÉS | C14: 20002428 | D14: Ciudad de Buenos Aires | E14: RECOLETA | F14: CF | G14: FCB 0007-00006471 | H14: 23140.5 | I14: 0 | J14: 0 | K14: 0 | L14: 0 | M14: 4859.5 | N14: 0 | O14: 0 | P14: 0 | Q14: 0 | R14: 4859.5 | S14: 28000
A15: 01/10/2025 | B15: AYELEN LUCIA ROLDAN | C15: 27337476398 | D15: Ciudad de Buenos Aires | E15: SIN IDENTIFICAR | F15: CF | G15: FCB 0007-00006472 | H15: 21487.6 | I15: 0 | J15: 0 | K15: 0 | L15: 0 | M15: 4512.4 | N15: 0 | O15: 0 | P15: 0 | Q15: 0 | R15: 4512.4 | S15: 26000
A16: 01/10/2025 | B16: FEDERICO DANTE BARRANCO | C16: 20400911542 | D16: Ciudad de Buenos Aires | E16: SIN IDENTIFICAR | F16: CF | G16: FCB 0005-00014481 | H16: 27272.73 | I16: 0 | J16: 0 | K16: 0 | L16: 0 | M16: 5727.27 | N16: 0 | O16: 0 | P16: 0 | Q16: 0 | R16: 5727.27 | S16: 33000
A17: 01/10/2025 | B17: CISNERO CLARA PATRICIA | C17: 23271414544 | D17: Ciudad de Buenos Aires | E17: SIN IDENTIFICAR | F17: CF | G17: FCB 0007-00006473 | H17: 42148.76 | I17: 0 | J17: 0 | K17: 0 | L17: 0 | M17: 8851.24 | N17: 0 | O17: 0 | P17: 0 | Q17: 0 | R17: 8851.24 | S17: 51000
A18: 01/10/2025 | B18: LAILA IVANA NATUCCE | C18: 27355887206 | D18: Ciudad de Buenos Aires | E18: SIN IDENTIFICAR | F18: CF | G18: FCB 0007-00006474 | H18: 18181.82 | I18: 0 | J18: 0 | K18: 0 | L18: 0 | M18: 3818.18 | N18: 0 | O18: 0 | P18: 0 | Q18: 0 | R18: 3818.18 | S18: 22000
A19: 01/10/2025 | B19: CECILIA DEL PILAR TELLO MARTEL | C19: 27951120370 | D19: Ciudad de Buenos Aires | E19: SIN IDENTIFICAR | F19: CF | G19: FCB 0007-00006475 | H19: 28925.62 | I19: 0 | J19: 0 | K19: 0 | L19: 0 | M19: 6074.38 | N19: 0 | O19: 0 | P19: 0 | Q19: 0 | R19: 6074.38 | S19: 35000
A20: 01/10/2025 | B20: . CONSUMIDOR FINAL ANÓNIMO | C20: 111 | D20: Ciudad de Buenos Aires | E20: SIN IDENTIFICAR | F20: CF | G20: FCB 0005-00014482 | H20: 14214.88 | I20: 0 | J20: 0 | K20: 0 | L20: 0 | M20: 2985.12 | N20: 0 | O20: 0 | P20: 0 | Q20: 0 | R20: 2985.12 | S20: 17200
A21: 01/10/2025 | B21: HC HOMECARE INTERNACION DOMICILIARIA S.A. | C21: 30710538014 | D21: Buenos Aires | E21: VILLA MARTELLI | F21: RI | G21: FCA 0007-00002719 | H21: 434850.24 | I21: 0 | J21: 0 | K21: 0 | L21: 0 | M21: 91318.55 | N21: 0 | O21: 0 | P21: 0 | Q21: 0 | R21: 91318.55 | S21: 526168.79
A22: 01/10/2025 | B22: . CONSUMIDOR FINAL ANÓNIMO | C22: 111 | D22: Ciudad de Buenos Aires | E22: SIN IDENTIFICAR | F22: CF | G22: FCB 0005-00014483 | H22: 26942.15 | I22: 0 | J22: 0 | K22: 0 | L22: 0 | M22: 5657.85 | N22: 0 | O22: 0 | P22: 0 | Q22: 0 | R22: 5657.85 | S22: 32600
A23: 01/10/2025 | B23: . CONSUMIDOR FINAL ANÓNIMO | C23: 111 | D23: Ciudad de Buenos Aires | E23: SIN IDENTIFICAR | F23: CF | G23: FCB 0005-00014484 | H23: 18595.04 | I23: 0 | J23: 0 | K23: 0 | L23: 0 | M23: 3904.96 | N23: 0 | O23: 0 | P23: 0 | Q23: 0 | R23: 3904.96 | S23: 22500
... A123: 07/10/2025 | B123: PINO, ANA PAULA | C123: 20008996 | D123: Buenos Aires | E123: FLORIDA | F123: CF | G123: FCB 0007-00006484 | H123: 28099.17 | I123: 0 | J123: 0 | K123: 0 | L123: 0 | M123: 5900.83 | N123: 0 | O123: 0 | P123: 0 | Q123: 0 | R123: 5900.83 | S123: 34000
A124: 07/10/2025 | B124: SCHELGEL, LUIS ALBERTO | D124: Buenos Aires | E124: SIN IDENTIFICAR | F124: CF | G124: FCB 0007-00006485 | H124: 17355.37 | I124: 0 | J124: 0 | K124: 0 | L124: 0 | M124: 3644.63 | N124: 0 | O124: 0 | P124: 0 | Q124: 0 | R124: 3644.63 | S124: 21000
A125: 07/10/2025 | B125: ANA ESTELA CALVINO | C125: 27144066990 | D125: Ciudad de Buenos Aires | E125: SIN IDENTIFICAR | F125: CF | G125: FCB 0007-00006486 | H125: 28925.62 | I125: 0 | J125: 0 | K125: 0 | L125: 0 | M125: 6074.38 | N125: 0 | O125: 0 | P125: 0 | Q125: 0 | R125: 6074.38 | S125: 35000
A126: 07/10/2025 | B126: ALVAREZ MARTA OLGA | C126: 9955440 | D126: Buenos Aires | E126: RAMOS MEJIA | F126: CF | G126: FCB 0007-00006487 | H126: 8603.31 | I126: 0 | J126: 0 | K126: 0 | L126: 0 | M126: 1806.69 | N126: 0 | O126: 0 | P126: 0 | Q126: 0 | R126: 1806.69 | S126: 10410
A127: 07/10/2025 | B127: FREDA JOHANNA GISE | C127: 27337086301 | D127: Ciudad de Buenos Aires | E127: SIN IDENTIFICAR | F127: CF | G127: FCB 0007-00006488 | H127: 26033.06 | I127: 0 | J127: 0 | K127: 0 | L127: 0 | M127: 5466.94 | N127: 0 | O127: 0 | P127: 0 | Q127: 0 | R127: 5466.94 | S127: 31500
A128: 07/10/2025 | B128: JUAN ANTONIO PARRA | C128: 20149320025 | D128: Ciudad de Buenos Aires | E128: SIN IDENTIFICAR | F128: CF | G128: FCB 0007-00006489 | H128: 39669.42 | I128: 0 | J128: 0 | K128: 0 | L128: 0 | M128: 8330.58 | N128: 0 | O128: 0 | P128: 0 | Q128: 0 | R128: 8330.58 | S128: 48000
A129: 07/10/2025 | B129: BAUAB, CAROLINA | D129: Buenos Aires | E129: SIN IDENTIFICAR | F129: CF | G129: FCB 0007-00006490 | H129: 58677.69 | I129: 0 | J129: 0 | K129: 0 | L129: 0 | M129: 12322.31 | N129: 0 | O129: 0 | P129: 0 | Q129: 0 | R129: 12322.31 | S129: 71000
A130: 07/10/2025 | B130: SCHELGEL, LUIS ALBERTO | D130: Buenos Aires | E130: SIN IDENTIFICAR | F130: CF | G130: FCB 0007-00006491 | H130: 39669.42 | I130: 0 | J130: 0 | K130: 0 | L130: 0 | M130: 8330.58 | N130: 0 | O130: 0 | P130: 0 | Q130: 0 | R130: 8330.58 | S130: 48000
A131: 07/10/2025 | B131: SILVIA MONICA ROJAS | C131: 27141958807 | D131: Ciudad de Buenos Aires | E131: BALVANERA | F131: CF | G131: FCB 0007-00006492 | H131: 36363.64 | I131: 0 | J131: 0 | K131: 0 | L131: 0 | M131: 7636.36 | N131: 0 | O131: 0 | P131: 0 | Q131: 0 | R131: 7636.36 | S131: 44000
A132: 07/10/2025 | B132: AGOSTINO MIRIAM | C132: 17275405 | D132: Buenos Aires | E132: SIN IDENTIFICAR | F132: CF | G132: FCB 0007-00006493 | H132: 52066.12 | I132: 0 | J132: 0 | K132: 0 | L132: 0 | M132: 10933.88 | N132: 0 | O132: 0 | P132: 0 | Q132: 0 | R132: 10933.88 | S132: 63000
A133: 07/10/2025 | B133: CONEN SILVIA ADELA | C133: 334529 | D133: Ciudad de Buenos Aires | E133: SIN IDENTIFICAR | F133: CF | G133: FCB 0007-00006494 | H133: 37190.08 | I133: 0 | J133: 0 | K133: 0 | L133: 0 | M133: 7809.92 | N133: 0 | O133: 0 | P133: 0 | Q133: 0 | R133: 7809.92 | S133: 45000
A134: 07/10/2025 | B134: . CONSUMIDOR FINAL ANÓNIMO | C134: 111 | D134: Ciudad de Buenos Aires | E134: SIN IDENTIFICAR | F134: CF | G134: FCB 0005-00014544 | H134: 23966.94 | I134: 0 | J134: 0 | K134: 0 | L134: 0 | M134: 5033.06 | N134: 0 | O134: 0 | P134: 0 | Q134: 0 | R134: 5033.06 | S134: 29000
A135: 07/10/2025 | B135: . CONSUMIDOR FINAL ANÓNIMO | C135: 111 | D135: Ciudad de Buenos Aires | E135: SIN IDENTIFICAR | F135: CF | G135: FCB 0005-00014545 | H135: 13884.3 | I135: 0 | J135: 0 | K135: 0 | L135: 0 | M135: 2915.7 | N135: 0 | O135: 0 | P135: 0 | Q135: 0 | R135: 2915.7 | S135: 16800
A136: 07/10/2025 | B136: . CONSUMIDOR FINAL ANÓNIMO | C136: 111 | D136: Ciudad de Buenos Aires | E136: SIN IDENTIFICAR | F136: CF | G136: FCB 0005-00014546 | H136: 14380.17 | I136: 0 | J136: 0 | K136: 0 | L136: 0 | M136: 3019.83 | N136: 0 | O136: 0 | P136: 0 | Q136: 0 | R136: 3019.83 | S136: 17400
A137: 07/10/2025 | B137: MIRTA EVANGELINA OJEDA | C137: 27301702367 | D137: Ciudad de Buenos Aires | E137: SIN IDENTIFICAR | F137: CF | G137: FCB 0005-00014547 | H137: 57851.24 | I137: 0 | J137: 0 | K137: 0 | L137: 0 | M137: 12148.76 | N137: 0 | O137: 0 | P137: 0 | Q137: 0 | R137: 12148.76 | S137: 70000
A138: 07/10/2025 | B138: FERRAZIN, CAROLINA ELEONORA INES | C138: 17855620 | D138: Buenos Aires | E138: SIN IDENTIFICAR | F138: CF | G138: FCB 0007-00006495 | H138: 33057.85 | I138: 0 | J138: 0 | K138: 0 | L138: 0 | M138: 6942.15 | N138: 0 | O138: 0 | P138: 0 | Q138: 0 | R138: 6942.15 | S138: 40000
A139: 07/10/2025 | B139: VOLPI, ALBERTO JAVIER | D139: Ciudad de Buenos Aires | E139: SIN IDENTIFICAR | F139: CF | G139: FCB 0007-00006496 | H139: 66115.7 | I139: 0 | J139: 0 | K139: 0 | L139: 0 | M139: 13884.3 | N139: 0 | O139: 0 | P139: 0 | Q139: 0 | R139: 13884.3 | S139: 80000
A140: 07/10/2025 | B140: Herman Patricia | C140: 21645724 | D140: Buenos Aires | E140: PILAR | F140: CF | G140: FCB 0007-00006497 | H140: 45454.55 | I140: 0 | J140: 0 | K140: 0 | L140: 0 | M140: 9545.45 | N140: 0 | O140: 0 | P140: 0 | Q140: 0 | R140: 9545.45 | S140: 55000
A141: 07/10/2025 | B141: . CONSUMIDOR FINAL ANÓNIMO | C141: 111 | D141: Ciudad de Buenos Aires | E141: SIN IDENTIFICAR | F141: CF | G141: FCB 0005-00014548 | H141: 27851.24 | I141: 0 | J141: 0 | K141: 0 | L141: 0 | M141: 5848.76 | N141: 0 | O141: 0 | P141: 0 | Q141: 0 | R141: 5848.76 | S141: 33700
...

Sheet Compras 10
A1: Fecha Emision | B1: Fecha Contable | C1: Nro Factura | D1: Razon Social | E1: Cuit | F1: Condicion Iva | G1: Monto Gravado Iva 2 | H1: Monto Gravado Iva 5 | I1: Monto Gravado Iva 10,5 | J1: Monto Gravado Iva 21 | K1: Monto Gravado Iva 27 | L1: Monto No Gravado Y Exentos | M1: Monto Gravado Monotributistas | N1: Iva Facturado | O1: Imp Interno | P1: Imp Municipal | Q1: Imp Nacional | R1: Otros | S1: Percepcion IVA | T1: IIBB | U1: Total Facturado | V1: Rubro | W1: Cod Fa
A2: 22/10/2025 | B2: 22/10/2025 | C2: FCA 00001-00000142 | D2: GOU TURISMO EJECUTIVO S.R.L. | E2: 30716046091 | F2: RI | G2: 0 | H2: 0 | I2: 400000 | J2: 0 | K2: 0 | L2: 0 | M2: 0 | N2: 42000 | O2: 0 | P2: 0 | Q2: 0 | R2: 0 | S2: 0 | T2: 0 | U2: 442000 | V2: Servicios
A3: 24/10/2025 | B3: 24/10/2025 | C3: FCA 00001-00009186 | D3: REHAB SRL | E3: 30715141201 | F3: RI | G3: 0 | H3: 0 | I3: 0 | J3: 2411808.8 | K3: 0 | L3: 0 | M3: 0 | N3: 506479.84 | O3: 0 | P3: 0 | Q3: 0 | R3: 0 | S3: 0 | T3: 0 | U3: 2918288.6 | V3: Bienes
A4: 27/10/2025 | B4: 27/10/2025 | C4: FCA 00001-00009201 | D4: REHAB SRL | E4: 30715141201 | F4: RI | G4: 0 | H4: 0 | I4: 0 | J4: 14480734 | K4: 0 | L4: 0 | M4: 0 | N4: 3040954.1 | O4: 0 | P4: 0 | Q4: 0 | R4: 0 | S4: 0 | T4: 0 | U4: 17521688 | V4: Bienes
A5: 28/10/2025 | B5: 28/10/2025 | C5: FCA 00001-00009213 | D5: REHAB SRL | E5: 30715141201 | F5: RI | G5: 0 | H5: 0 | I5: 0 | J5: 1647975 | K5: 0 | L5: 0 | M5: 0 | N5: 346074.75 | O5: 0 | P5: 0 | Q5: 0 | R5: 0 | S5: 0 | T5: 0 | U5: 1994049.8 | V5: Bienes
A6: 28/10/2025 | B6: 28/10/2025 | C6: FCA 00001-00009214 | D6: REHAB SRL | E6: 30715141201 | F6: RI | G6: 0 | H6: 0 | I6: 0 | J6: 206561.25 | K6: 0 | L6: 0 | M6: 0 | N6: 43377.86 | O6: 0 | P6: 0 | Q6: 0 | R6: 0 | S6: 0 | T6: 0 | U6: 249939.11 | V6: Bienes
A7: 01/10/2025 | B7: 01/10/2025 | C7: FCA 00001-00140551 | D7: CONTABILIUM SA | E7: 30714864269 | F7: RI | G7: 0 | H7: 0 | I7: 0 | J7: 184800 | K7: 0 | L7: 0 | M7: 0 | N7: 38808 | O7: 0 | P7: 0 | Q7: 0 | R7: 0 | S7: 0 | T7: 0 | U7: 223608 | V7: Servicios
A8: 01/10/2025 | B8: 08/10/2025 | C8: FCA 00001-01031096 | D8: VERISURE ARGENTINA MONITOREO DE ALARMAS SA | E8: 33716307749 | F8: RI | G8: 0 | H8: 0 | I8: 0 | J8: 62349.01 | K8: 0 | L8: 0 | M8: 0 | N8: 13093.29 | O8: 0 | P8: 0 | Q8: 0 | R8: 2493.96 | S8: 0 | T8: 0 | U8: 77936.26 | V8: Servicios
A9: 29/10/2025 | B9: 29/10/2025 | C9: FCA 00002-00000049 | D9: BARD MARISA SILVIA | E9: 27243660535 | F9: RI | G9: 0 | H9: 0 | I9: 0 | J9: 474914.87 | K9: 0 | L9: 0 | M9: 0 | N9: 99732.12 | O9: 0 | P9: 0 | Q9: 0 | R9: 0 | S9: 0 | T9: 0 | U9: 574646.99 | V9: Locaciones
A10: 29/10/2025 | B10: 29/10/2025 | C10: FCA 00002-00000050 | D10: BARD MARISA SILVIA | E10: 27243660535 | F10: RI | G10: 0 | H10: 0 | I10: 0 | J10: 474914.87 | K10: 0 | L10: 0 | M10: 0 | N10: 99732.12 | O10: 0 | P10: 0 | Q10: 0 | R10: 0 | S10: 0 | T10: 0 | U10: 574646.99 | V10: Locaciones
A11: 28/10/2025 | B11: 28/10/2025 | C11: FCA 00002-00000141 | D11: WILSON GUSTAVO UBALDO AQUINO | E11: 20276761111 | F11: RI | G11: 0 | H11: 0 | I11: 0 | J11: 49950 | K11: 0 | L11: 0 | M11: 0 | N11: 10489.5 | O11: 0 | P11: 0 | Q11: 0 | R11: 0 | S11: 0 | T11: 0 | U11: 60439.5 | V11: Bienes
A12: 01/10/2025 | B12: 07/10/2025 | C12: FCA 00002-00000252 | D12: CONSORCIO BARTOLME MITRE 2466 | E12: 30605344352 | F12: RI | G12: 0 | H12: 0 | I12: 0 | J12: 2160581 | K12: 0 | L12: 0 | M12: 0 | N12: 453722.01 | O12: 0 | P12: 0 | Q12: 0 | R12: 0 | S12: 0 | T12: 0 | U12: 2614303 | V12: Servicios
A13: 02/10/2025 | B13: 02/10/2025 | C13: FCA 00002-00001576 | D13: MARTIN EZEQUIEL DI FEO | E13: 20272865869 | F13: RI | G13: 0 | H13: 0 | I13: 0 | J13: 69400 | K13: 0 | L13: 0 | M13: 0 | N13: 14574 | O13: 0 | P13: 0 | Q13: 0 | R13: 0 | S13: 0 | T13: 0 | U13: 83974 | V13: Bienes
... A42: 08/10/2025 | B42: 09/10/2025 | C42: FCA 00005-00001694 | D42: MARISOL PRADO | E42: 27265302225 | F42: RI | G42: 0 | H42: 0 | I42: 0 | J42: 1400000 | K42: 0 | L42: 0 | M42: 0 | N42: 294000 | O42: 0 | P42: 0 | Q42: 0 | R42: 0 | S42: 0 | T42: 0 | U42: 1694000 | V42: Bienes
A43: 21/09/2025 | B43: 20/10/2025 | C43: FCA 00005-00006144 | D43: MONTE DUAL S.R.L. | E43: 33714967989 | F43: RI | G43: 0 | H43: 0 | I43: 0 | J43: 47207.83 | K43: 0 | L43: 0 | M43: 0 | N43: 9913.64 | O43: 11223.05 | P43: 0 | Q43: 0 | R43: 687.49 | S43: 0 | T43: 0 | U43: 69032.01 | V43: Servicios | W43: 81
A44: 14/10/2025 | B44: 14/10/2025 | C44: FCA 00005-00006507 | D44: BIODINAMICA ASISTENCIA S.R.L. | E44: 30715833243 | F44: RI | G44: 0 | H44: 0 | I44: 0 | J44: 378025 | K44: 0 | L44: 0 | M44: 0 | N44: 79385.25 | O44: 0 | P44: 0 | Q44: 0 | R44: 0 | S44: 0 | T44: 0 | U44: 457410.25 | V44: Bienes
A45: 14/10/2025 | B45: 14/10/2025 | C45: FCA 00005-00006509 | D45: BIODINAMICA ASISTENCIA S.R.L. | E45: 30715833243 | F45: RI | G45: 0 | H45: 0 | I45: 0 | J45: 115215 | K45: 0 | L45: 0 | M45: 0 | N45: 24195.15 | O45: 0 | P45: 0 | Q45: 0 | R45: 0 | S45: 0 | T45: 0 | U45: 139410.15 | V45: Bienes
A46: 15/10/2025 | B46: 15/10/2025 | C46: FCA 00005-00006522 | D46: BIODINAMICA ASISTENCIA S.R.L. | E46: 30715833243 | F46: RI | G46: 0 | H46: 0 | I46: 0 | J46: 102960 | K46: 0 | L46: 0 | M46: 0 | N46: 21621.6 | O46: 0 | P46: 0 | Q46: 0 | R46: 0 | S46: 0 | T46: 0 | U46: 124581.6 | V46: Bienes
A47: 15/10/2025 | B47: 15/10/2025 | C47: FCA 00005-00006523 | D47: BIODINAMICA ASISTENCIA S.R.L. | E47: 30715833243 | F47: RI | G47: 0 | H47: 0 | I47: 0 | J47: 33660.78 | K47: 0 | L47: 0 | M47: 0 | N47: 7068.76 | O47: 0 | P47: 0 | Q47: 0 | R47: 0 | S47: 0 | T47: 0 | U47: 40729.54 | V47: Bienes
A48: 16/10/2025 | B48: 16/10/2025 | C48: FCA 00005-00006531 | D48: BIODINAMICA ASISTENCIA S.R.L. | E48: 30715833243 | F48: RI | G48: 0 | H48: 0 | I48: 0 | J48: 432231 | K48: 0 | L48: 0 | M48: 0 | N48: 90768.51 | O48: 0 | P48: 0 | Q48: 0 | R48: 0 | S48: 0 | T48: 0 | U48: 522999.51 | V48: Bienes
A49: 22/10/2025 | B49: 22/10/2025 | C49: FCA 00005-03410705 | D49: NSS SA - IPLAN | E49: 30702652975 | F49: RI | G49: 0 | H49: 0 | I49: 0 | J49: 39734.25 | K49: 0 | L49: 0 | M49: 0 | N49: 8344.19 | O49: 0 | P49: 0 | Q49: 0 | R49: 0 | S49: 0 | T49: 1589.37 | U49: 49667.81 | V49: Servicios
A50: 09/10/2025 | B50: 09/10/2025 | C50: FCA 00006-00000121 | D50: 46 SPEED S.A. | E50: 30711610096 | F50: RI | G50: 0 | H50: 0 | I50: 0 | J50: 865620 | K50: 0 | L50: 0 | M50: 0 | N50: 181780.2 | O50: 0 | P50: 0 | Q50: 0 | R50: 0 | S50: 0 | T50: 0 | U50: 1047400.2 | V50: Bienes
A51: 09/10/2025 | B51: 09/10/2025 | C51: FCA 00006-00000123 | D51: 46 SPEED S.A. | E51: 30711610096 | F51: RI | G51: 0 | H51: 0 | I51: 0 | J51: 865620 | K51: 0 | L51: 0 | M51: 0 | N51: 181780.2 | O51: 0 | P51: 0 | Q51: 0 | R51: 0 | S51: 0 | T51: 0 | U51: 1047400.2 | V51: Bienes
A52: 15/10/2025 | B52: 15/10/2025 | C52: FCA 00006-00000127 | D52: 46 SPEED S.A. | E52: 30711610096 | F52: RI | G52: 0 | H52: 0 | I52: 0 | J52: 720000 | K52: 0 | L52: 0 | M52: 0 | N52: 151200 | O52: 0 | P52: 0 | Q52: 0 | R52: 0 | S52: 0 | T52: 0 | U52: 871200 | V52: Bienes
A53: 08/10/2025 | B53: 08/10/2025 | C53: FCA 00006-00002120 | D53: PAPELERA GEOPEL SRL | E53: 30716815710 | F53: RI | G53: 0 | H53: 0 | I53: 0 | J53: 26800 | K53: 0 | L53: 0 | M53: 0 | N53: 5628 | O53: 0 | P53: 0 | Q53: 0 | R53: 0 | S53: 0 | T53: 0 | U53: 32428 | V53: Bienes
A54: 07/10/2025 | B54: 07/10/2025 | C54: FCA 00006-00003443 | D54: GRUPO MAXIMUS S.R.L. | E54: 30715775014 | F54: RI | G54: 0 | H54: 0 | I54: 38371.04 | J54: 0 | K54: 0 | L54: 0 | M54: 0 | N54: 4028.96 | O54: 0 | P54: 0 | Q54: 0 | R54: 0 | S54: 0 | T54: 1534.84 | U54: 43934.84 | V54: Bienes
A55: 14/10/2025 | B55: 14/10/2025 | C55: FCA 00006-00059344 | D55: TARGET MEDICAL SA | E55: 30710177658 | F55: RI | G55: 0 | H55: 0 | I55: 0 | J55: 831952 | K55: 0 | L55: 0 | M55: 0 | N55: 174709.92 | O55: 0 | P55: 0 | Q55: 0 | R55: 0 | S55: 0 | T55: 33278.08 | U55: 1039940 | V55: Bienes
A56: 31/10/2025 | B56: 31/10/2025 | C56: FCA 00006-00059569 | D56: TARGET MEDICAL SA | E56: 30710177658 | F56: RI | G56: 0 | H56: 0 | I56: 0 | J56: 575200 | K56: 0 | L56: 0 | M56: 0 | N56: =J56*0.21 -> 120792 | O56: 0 | P56: 0 | Q56: 0 | R56: 0 | S56: 0 | T56: 23008 | U56: =SUM(G56:T56) -> 719000 | V56: Bienes
A57: 01/10/2025 | B57: 01/10/2025 | C57: FCA 00006-00096490 | D57: SALUDTEX SA | E57: 30711553564 | F57: RI | G57: 0 | H57: 0 | I57: 0 | J57: 1332279 | K57: 0 | L57: 0 | M57: 0 | N57: 279778.59 | O57: 0 | P57: 0 | Q57: 0 | R57: 0 | S57: 0 | T57: 0 | U57: 1612057.6 | V57: Bienes
A58: 01/10/2025 | B58: 01/10/2025 | C58: FCA 00006-00096491 | D58: SALUDTEX SA | E58: 30711553564 | F58: RI | G58: 0 | H58: 0 | I58: 0 | J58: 702555 | K58: 0 | L58: 0 | M58: 0 | N58: 147536.55 | O58: 0 | P58: 0 | Q58: 0 | R58: 0 | S58: 0 | T58: 0 | U58: 850091.55 | V58: Bienes
A59: 01/10/2025 | B59: 01/10/2025 | C59: FCA 00006-00096492 | D59: SALUDTEX SA | E59: 30711553564 | F59: RI | G59: 0 | H59: 0 | I59: 0 | J59: 30765 | K59: 0 | L59: 0 | M59: 0 | N59: 6460.65 | O59: 0 | P59: 0 | Q59: 0 | R59: 0 | S59: 0 | T59: 0 | U59: 37225.65 | V59: Bienes
A60: 22/10/2025 | B60: 22/10/2025 | C60: FCA 00006-00097166 | D60: SALUDTEX SA | E60: 30711553564 | F60: RI | G60: 0 | H60: 0 | I60: 0 | J60: 355304 | K60: 0 | L60: 0 | M60: 0 | N60: 74613.84 | O60: 0 | P60: 0 | Q60: 0 | R60: 0 | S60: 0 | T60: 0 | U60: 429917.84 | V60: Bienes
A61: 30/10/2025 | B61: 30/10/2025 | C61: FCA 00006-21005478 | D61: POSNET SOCIEDAD DE RESPONSABILIDAD LIMITADA | E61: 30620177497 | F61: RI | G61: 0 | H61: 0 | I61: 0 | J61: 19593.02 | K61: 0 | L61: 0 | M61: 0 | N61: 4114.53 | O61: 0 | P61: 0 | Q61: 0 | R61: 1371.51 | S61: 0 | T61: 0 | U61: 25079.06 | V61: Servicios
A62: 02/10/2025 | B62: 07/10/2025 | C62: FCA 00007-00000055 | D62: ALEJANDRA MABEL SOUSA ALDERETE | E62: 27325223273 | F62: RI | G62: 0 | H62: 0 | I62: 0 | J62: 2200000 | K62: 0 | L62: 0 | M62: 0 | N62: 462000 | O62: 0 | P62: 0 | Q62: 0 | R62: 0 | S62: 0 | T62: 0 | U62: 2662000 | V62: Bienes
A63: 08/10/2025 | B63: 09/10/2025 | C63: FCA 00007-00000056 | D63: ALEJANDRA MABEL SOUSA ALDERETE | E63: 27325223273 | F63: RI | G63: 0 | H63: 0 | I63: 0 | J63: 1300000 | K63: 0 | L63: 0 | M63: 0 | N63: 273000 | O63: 0 | P63: 0 | Q63: 0 | R63: 0 | S63: 0 | T63: 0 | U63: 1573000 | V63: Bienes
A64: 28/10/2025 | B64: 28/10/2025 | C64: FCA 00007-00001773 | D64: ITALOMED PRODUCTOS SRL | E64: 30712187316 | F64: RI | G64: 0 | H64: 0 | I64: 0 | J64: 215832.05 | K64: 0 | L64: 0 | M64: 0 | N64: 45324.73 | O64: 0 | P64: 0 | Q64: 0 | R64: 0 | S64: 0 | T64: 0 | U64: 261156.78 | V64: Bienes
A65: 29/10/2025 | B65: 29/10/2025 | C65: FCA 00007-00001777 | D65: ITALOMED PRODUCTOS SRL | E65: 30712187316 | F65: RI | G65: 0 | H65: 0 | I65: 0 | J65: 199854.05 | K65: 0 | L65: 0 | M65: 0 | N65: 41969.35 | O65: 0 | P65: 0 | Q65: 0 | R65: 0 | S65: 0 | T65: 0 | U65: 241823.4 | V65: Bienes
A66: 23/10/2025 | B66: 23/10/2025 | C66: FCA 00007-00005934 | D66: MATIAS EZEQUIEL ROMANO | E66: 20347228002 | F66: RI | G66: 0 | H66: 0 | I66: 0 | J66: 80594.23 | K66: 0 | L66: 0 | M66: 0 | N66: 16924.79 | O66: 0 | P66: 0 | Q66: 0 | R66: 0 | S66: 0 | T66: 0 | U66: 97519.02 | V66: Bienes
A67: 10/10/2025 | B67: 13/10/2025 | C67: FCA 00007-00022484 | D67: FOURMAX S.R.L. | E67: 30711647135 | F67: RI | G67: 0 | H67: 0 | I67: 0 | J67: 96169.7 | K67: 0 | L67: 0 | M67: 0 | N67: 20195.64 | O67: 0 | P67: 0 | Q67: 0 | R67: 13634.67 | S67: 0 | T67: 0 | U67: 130000.01 | W67: 81
A68: 14/10/2025 | B68: 14/10/2025 | C68: FCA 00007-00022647 | D68: REHAVITA S.A. | E68: 30709214078 | F68: RI | G68: 0 | H68: 0 | I68: 315560 | J68: 0 | K68: 0 | L68: 0 | M68: 0 | N68: 33133.8 | O68: 0 | P68: 0 | Q68: 0 | R68: 0 | S68: 0 | T68: 0 | U68: 348693.8 | V68: Bienes
...

Sheet arcasss
B2: PEAJES | H2: FA-A | I2: 118
B3: ok contabil | H3: NC-A | I3: 8 | L3: 8
H4: FA-C | I4: 25 | L4: 25
H5: NC-C | I5: 2 | L5: 2
H6: TOTAL COMP | I6: =SUBTOTAL(9,I2:I5) -> 153
H7: total contabilium | I7: 149
A9: Fecha | B9: Tipo | C9: Punto de Venta | D9: Número Desde | E9: Número Hasta | F9: Cód. Autorización | G9: Tipo Doc. Emisor | H9: Nro. Doc. Emisor | I9: Denominación Emisor | J9: Tipo Doc. Receptor | K9: Nro. Doc. Receptor | L9: Tipo Cambio | M9: Moneda | N9: Neto Grav. IVA 0% | O9: IVA 2,5% | P9: Neto Grav. IVA 2,5% | Q9: IVA 5% | R9: Neto Grav. IVA 5% | S9: IVA 10,5% | T9: Neto Grav. IVA 10,5% | U9: IVA 21% | V9: Neto Grav. IVA 21% | W9: IVA 27% | X9: Neto Grav. IVA 27% | Y9: Neto Gravado Total | Z9: Neto No Gravado | AA9: Op. Exentas | AB9: Otros Tributos | AC9: Total IVA | AD9: Imp. Total | AE9: comp
A10: 01/10/2025 | B10: 1 - Factura A | C10: 500 | D10: 1791477 | E10: 1791477 | F10: 75397766663182 | G10: CUIT | H10: 30654118767 | I10: SOLUCIONES MULTIMEDIA S A | J10: CUIT | K10: 30710473168 | L10: 1 | M10: $ | U10: 34781 | V10: 165623.79 | Y10: 165623.79 | Z10: 0 | AA10: 0 | AB10: 6624.95 | AC10: 34781 | AD10: 207029.74
A11: 01/10/2025 | B11: 1 - Factura A | C11: 2059 | D11: 34131 | E11: 34131 | F11: 75406205517570 | G11: CUIT | H11: 30548083156 | I11: COTO CENTRO INTEGRAL DE COMERCIALIZACION SOCIEDAD ANONIMA | J11: CUIT | K11: 30710473168 | L11: 1 | M11: $ | U11: 1150.88 | V11: 5480.36 | Y11: 5480.36 | Z11: 0 | AA11: 0 | AB11: 383.62 | AC11: 1150.88 | AD11: 7014.86
A12: 01/10/2025 | B12: 1 - Factura A | C12: 5 | D12: 1679 | E12: 1679 | F12: 75405209208340 | G12: CUIT | H12: 27265302225 | I12: PRADO MARISOL | J12: CUIT | K12: 30710473168 | L12: 1 | M12: $ | U12: 26250 | V12: 125000 | Y12: 125000 | Z12: 0 | AA12: 0 | AB12: 0 | AC12: 26250 | AD12: 151250
A13: 01/10/2025 | B13: 1 - Factura A | C13: 1 | D13: 140551 | E13: 140551 | F13: 75409140621749 | G13: CUIT | H13: 30714864269 | I13: CONTABILIUM S.A. S. A. | J13: CUIT | K13: 30710473168 | L13: 1 | M13: $ | U13: 38808 | V13: 184800 | Y13: 184800 | Z13: 0 | AA13: 0 | AB13: 0 | AC13: 38808 | AD13: 223608
A14: 01/10/2025 | B14: 1 - Factura A | C14: 5 | D14: 1680 | E14: 1680 | F14: 75405214018996 | G14: CUIT | H14: 27265302225 | I14: PRADO MARISOL | J14: CUIT | K14: 30710473168 | L14: 1 | M14: $ | U14: 294000 | V14: 1400000 | Y14: 1400000 | Z14: 0 | AA14: 0 | AB14: 0 | AC14: 294000 | AD14: 1694000
A15: 01/10/2025 | B15: 1 - Factura A | C15: 5 | D15: 1676 | E15: 1676 | F15: 75405186336334 | G15: CUIT | H15: 27265302225 | I15: PRADO MARISOL | J15: CUIT | K15: 30710473168 | L15: 1 | M15: $ | U15: 525000 | V15: 2500000 | Y15: 2500000 | Z15: 0 | AA15: 0 | AB15: 0 | AC15: 525000 | AD15: 3025000
A16: 01/10/2025 | B16: 1 - Factura A | C16: 6 | D16: 96490 | E16: 96490 | F16: 75404218156994 | G16: CUIT | H16: 30711553564 | I16: SALUDTEX SA | J16: CUIT | K16: 30710473168 | L16: 1 | M16: $ | U16: 279778.59 | V16: 1332279 | Y16: 1332279 | Z16: 0 | AA16: 0 | AB16: 0 | AC16: 279778.59 | AD16: 1612057.6
A17: 01/10/2025 | B17: 1 - Factura A | C17: 6 | D17: 96491 | E17: 96491 | F17: 75404218271756 | G17: CUIT | H17: 30711553564 | I17: SALUDTEX SA | J17: CUIT | K17: 30710473168 | L17: 1 | M17: $ | U17: 147536.55 | V17: 702555 | Y17: 702555 | Z17: 0 | AA17: 0 | AB17: 0 | AC17: 147536.55 | AD17: 850091.55
A18: 01/10/2025 | B18: 1 - Factura A | C18: 6 | D18: 96492 | E18: 96492 | F18: 75404218424004 | G18: CUIT | H18: 30711553564 | I18: SALUDTEX SA | J18: CUIT | K18: 30710473168 | L18: 1 | M18: $ | U18: 6460.65 | V18: 30765 | Y18: 30765 | Z18: 0 | AA18: 0 | AB18: 0 | AC18: 6460.65 | AD18: 37225.65
A19: 15/10/2025 | B19: 1 - Factura A | C19: 50 | D19: 4670040 | E19: 4670040 | F19: 75426230181879 | G19: CUIT | H19: 30714112836 | I19: AUTOPISTAS DE BUENOS AIRES (AUBASA) SA S. A. | J19: CUIT | K19: 30710473168 | L19: 1 | M19: $ | U19: 1031.36 | V19: 4911.22 | Y19: 4911.22 | Z19: 0 | AA19: 0 | AB19: 147.34 | AC19: 1031.36 | AD19: 6089.92
A20: 31/10/2025 | B20: 1 - Factura A | C20: 50 | D20: 4706524 | E20: 4706524 | F20: 75446229190253 | G20: CUIT | H20: 30714112836 | I20: AUTOPISTAS DE BUENOS AIRES (AUBASA) SA S. A. | J20: CUIT | K20: 30710473168 | L20: 1 | M20: $ | U20: 343.78 | V20: 1637.07 | Y20: 1637.07 | Z20: 0 | AA20: 0 | AB20: 0 | AC20: 343.78 | AD20: 1980.85 | AE20: sin comp
A21: 01/10/2025 | B21: 1 - Factura A | C21: 2 | D21: 252 | E21: 252 | F21: 75402211250599 | G21: CUIT | H21: 30605344352 | I21: CONSORCIO BARTOLOME MITRE 2466 | J21: CUIT | K21: 30710473168 | L21: 1 | M21: $ | U21: 453722.01 | V21: 2160581 | Y21: 2160581 | Z21: 0 | AA21: 0 | AB21: 0 | AC21: 453722.01 | AD21: 2614303
A22: 01/10/2025 | B22: 3 - Nota de Crédito A | C22: 5 | D22: 131 | E22: 131 | F22: 75405208440708 | G22: CUIT | H22: 27265302225 | I22: PRADO MARISOL | J22: CUIT | K22: 30710473168 | L22: 1 | M22: $ | U22: 525000 | V22: 2500000 | Y22: 2500000 | Z22: 0 | AA22: 0 | AB22: 0 | AC22: 525000 | AD22: 3025000
A23: 01/10/2025 | B23: 3 - Nota de Crédito A | C23: 6 | D23: 13998 | E23: 13998 | F23: 75404232088366 | G23: CUIT | H23: 30711553564 | I23: SALUDTEX SA | J23: CUIT | K23: 30710473168 | L23: 1 | M23: $ | U23: 28978.11 | V23: 137991 | Y23: 137991 | Z23: 0 | AA23: 0 | AB23: 0 | AC23: 28978.11 | AD23: 166969.11
A24: 01/10/2025 | B24: 11 - Factura C | C24: 4 | D24: 67 | E24: 67 | F24: 75403183061118 | G24: CUIT | H24: 20086277523 | I24: GUASCH HECTOR RAUL | J24: CUIT | K24: 30710473168 | L24: 1 | M24: $ | AB24: 0 | AD24: 300000
A25: 01/10/2025 | B25: 11 - Factura C | C25: 4 | D25: 66 | E25: 66 | F25: 75403179949716 | G25: CUIT | H25: 20086277523 | I25: BOTINDARI JUAN CARLOS | J25: CUIT | K25: 30710473168 | L25: 1 | M25: $ | AB25: 0 | AD25: 300000
A26: 01/10/2025 | B26: 13 - Nota de Crédito C | C26: 4 | D26: 2 | E26: 2 | F26: 75403184483403 | G26: CUIT | H26: 20086277523 | I26: BOTINDARI JUAN CARLOS | J26: CUIT | K26: 30710473168 | L26: 1 | M26: $ | AB26: 0 | AD26: 300000
A27: 02/10/2025 | B27: 1 - Factura A | C27: 3051 | D27: 982461 | E27: 982461 | F27: 75407377852221 | G27: CUIT | H27: 30678814357 | I27: TELEFONICA MOVILES ARGENTINA SOCIEDAD ANONIMA | J27: CUIT | K27: 30710473168 | L27: 1 | M27: $ | W27: 15634.89 | X27: 57907 | Y27: 57907 | Z27: 0 | AA27: 0 | AB27: 7223.1 | AC27: 15634.89 | AD27: 80764.99
A28: 02/10/2025 | B28: 1 - Factura A | C28: 8 | D28: 476 | E28: 476 | F28: 75404371927575 | G28: CUIT | H28: 30643518364 | I28: FARMACIA DE MEDRANO 533 SOCIEDAD EN COMANDITA SIMPLE | J28: CUIT | K28: 30710473168 | L28: 1 | M28: $ | U28: 18637.5 | V28: 88750 | Y28: 88750 | Z28: 0 | AA28: 0 | AB28: 0 | AC28: 18637.5 | AD28: 107387.5
A29: 02/10/2025 | B29: 1 - Factura A | C29: 2 | D29: 1576 | E29: 1576 | F29: 75409356956133 | G29: CUIT | H29: 20272865869 | I29: DI FEO MARTIN EZEQUIEL | J29: CUIT | K29: 30710473168 | L29: 1 | M29: $ | U29: 14574 | V29: 69400 | Y29: 69400 | Z29: 0 | AA29: 0 | AB29: 0 | AC29: 14574 | AD29: 83974
A30: 02/10/2025 | B30: 1 - Factura A | C30: 17 | D30: 13744 | E30: 13744 | F30: 75400375536461 | G30: CUIT | H30: 30661143610 | I30: ORTOPEDIA BERNAT SRL | J30: CUIT | K30: 30710473168 | L30: 1 | M30: $ | U30: 21588 | V30: 102800 | Y30: 102800 | Z30: 0 | AA30: 0 | AB30: 4112 | AC30: 21588 | AD30: 128500
A31: 02/10/2025 | B31: 1 - Factura A | C31: 4 | D31: 19861 | E31: 19861 | F31: 75403288996009 | G31: CUIT | H31: 30714440183 | I31: INDUSTRIAS FERNANDEZ GARRIDO SA | J31: CUIT | K31: 30710473168 | L31: 1 | M31: $ | U31: 5684.76 | V31: 27070.3 | Y31: 27070.3 | Z31: 0 | AA31: 0 | AB31: 0 | AC31: 5684.76 | AD31: 32755.06
A32: 02/10/2025 | B32: 1 - Factura A | C32: 1 | D32: 1031096 | E32: 1031096 | F32: 75419072334708 | G32: CUIT | H32: 33716307749 | I32: VERISURE ARGENTINA MONITOREO DE ALARMAS SA | J32: CUIT | K32: 30710473168 | L32: 1 | M32: $ | U32: 13093.29 | V32: 62349.01 | Y32: 62349.01 | Z32: 0 | AA32: 0 | AB32: 2493.96 | AC32: 13093.29 | AD32: 77936.26
A33: 02/10/2025 | B33: 1 - Factura A | C33: 7 | D33: 55 | E33: 55 | F33: 75403337698338 | G33: CUIT | H33: 27325223273 | I33: SOUSA ALDERETE ALEJANDRA MABEL | J33: CUIT | K33: 30710473168 | L33: 1 | M33: $ | U33: 462000 | V33: 2200000 | Y33: 2200000 | Z33: 0 | AA33: 0 | AB33: 0 | AC33: 462000 | AD33: 2662000
A34: 02/10/2025 | B34: 11 - Factura C | C34: 1 | D34: 43 | E34: 43 | F34: 75401342703675 | G34: CUIT | H34: 20311855671 | I34: GUASCH HECTOR RAUL | J34: CUIT | K34: 30710473168 | L34: 1 | M34: $ | AB34: 0 | AD34: 290000
A35: 03/10/2025 | B35: 1 - Factura A | C35: 2 | D35: 1582 | E35: 1582 | F35: 75409440515122 | G35: CUIT | H35: 20272865869 | I35: DI FEO MARTIN EZEQUIEL | J35: CUIT | K35: 30710473168 | L35: 1 | M35: $ | U35: 64932 | V35: 309200 | Y35: 309200 | Z35: 0 | AA35: 0 | AB35: 0 | AC35: 64932 | AD35: 374132
A36: 03/10/2025 | B36: 1 - Factura A | C36: 26 | D36: 215680 | E36: 215680 | F36: 75407512016610 | G36: CUIT | H36: 30708847247 | I36: EXPRESO LANCIONI S.A. | J36: CUIT | K36: 30710473168 | L36: 1 | M36: $ | U36: 15703.62 | V36: 74779.14 | Y36: 74779.14 | Z36: 0 | AA36: 0 | AB36: 2991.17 | AC36: 15703.62 | AD36: 93473.93
A37: 03/10/2025 | B37: 1 - Factura A | C37: 5 | D37: 1682 | E37: 1682 | F37: 75405522210939 | G37: CUIT | H37: 27265302225 | I37: PRADO MARISOL | J37: CUIT | K37: 30710473168 | L37: 1 | M37: $ | U37: 262500 | V37: 1250000 | Y37: 1250000 | Z37: 0 | AA37: 0 | AB37: 0 | AC37: 262500 | AD37: 1512500
A38: 03/10/2025 | B38: 1 - Factura A | C38: 1054 | D38: 381 | E38: 381 | F38: 75401449551620 | G38: CUIT | H38: 30685849751 | I38: DIA ARGENTINA S A | J38: CUIT | K38: 30710473168 | L38: 1 | M38: $ | U38: 1133.31 | V38: 5396.69 | Y38: 5396.69 | Z38: 0 | AA38: 0 | AB38: 215.87 | AC38: 1133.31 | AD38: 6745.87
A39: 03/10/2025 | B39: 1 - Factura A | C39: 3 | D39: 930 | E39: 930 | F39: 75409454635742 | G39: CUIT | H39: 23076996989 | I39: GIULIETTI LUIS ALBERTO | J39: CUIT | K39: 30710473168 | L39: 1 | M39: $ | U39: 2776.86 | V39: 13223.14 | Y39: 13223.14 | Z39: 0 | AA39: 0 | AB39: 0 | AC39: 2776.86 | AD39: 16000
A40: 03/10/2025 | B40: 3 - Nota de Crédito A | C40: 5 | D40: 132 | E40: 132 | F40: 75405520316587 | G40: CUIT | H40: 27265302225 | I40: PRADO MARISOL | J40: CUIT | K40: 30710473168 | L40: 1 | M40: $ | U40: 26250 | V40: 125000 | Y40: 125000 | Z40: 0 | AA40: 0 | AB40: 0 | AC40: 26250 | AD40: 151250
A41: 03/10/2025 | B41: 11 - Factura C | C41: 2 | D41: 634 | E41: 634 | F41: 75407495074987 | G41: CUIT | H41: 20247881957 | I41: CAMPA DANIEL JORGE | J41: CUIT | K41: 30710473168 | L41: 1 | M41: $ | AB41: 0 | AD41: 13400
A42: 04/10/2025 | B42: 11 - Factura C | C42: 2 | D42: 138 | E42: 138 | F42: 75408636655570 | G42: CUIT | H42: 27315710508 | I42: RIVERO GABRIELA ROCIO | J42: CUIT | K42: 30710473168 | L42: 1 | M42: $ | AB42: 0 | AD42: 51030
...
