Workbook
Name partner_id: Configuracion!$B$332

Sheet Configuracion
F1: CUIT | G1: Cargar sin guiones
F2: RAZON SOCIAL | G2: Maximo 30 caracteres
A3: CUIT | B3: RAZON SOCIAL | C3: DETALLE | F3: DETALLE | G3: Cargar tipo de gasto
A4: 30628205090 | B4: ALBAMIE SA | C4: CLIENTE
A5: 30711678820 | B5: 2PSI INGENIERIA SRL | C5: PROVEEDOR
A6: 33716367539 | B6: 3PI S.A.S. | C6: PROVEEDOR
A7: 30660373108 | B7: ABC SA | C7: VARIOS
A8: 20300210881 | B8: ABOY DIEGO OSCAR | C8: PROVEEDOR
A9: 27229910782 | B9: ABUGAUCH MARIA DE LOS ANGELES | C9: PROVEEDOR
A10: 20242709897 | B10: ABUGAUCH VICTOR HUGO | C10: PROVEEDOR
A11: 20281669053 | B11: ACOSTA JAVIER GUSTAVO | C11: FLETE
A12: 20174240125 | B12: ACOSTA OSCAR ISIDRO | C12: VARIOS
A13: 30641659106 | B13: AGRISOL SA | C13: VARIOS
A14: 33709914109 | B14: ALAN COLLECTION SA | C14: VARIOS
A15: 20267161616 | B15: ALBAJARI DIEGO MARCOS | C15: VARIOS
... A155: 30537679855 | B155: ESTACION LIMA SA | C155: VARIOS
A156: 30-56864959-8 | B156: EXPRESO BISONTE SRL | C156: FLETE
A157: 30708542349 | B157: EXPRESO FORMOSA SRL | C157: FLETE
A158: 30526582884 | B158: EXPRESO MAR DEL PLATA SA | C158: FLETE
A159: 30577744579 | B159: EXPRESO TROLE SRL | C159: FLETE
A160: 30715949292 | B160: EYPAPEL SAS | C160: GASTOS VARIOS
A161: 30715980807 | B161: FABORT SRL | C161: PROVEEDOR
A162: 20359718765 | B162: FAIL ABRAHAM | C162: VARIOS
A163: 30643518364 | B163: FARMACIA DE MEDRANO SCS | C163: PROVEEDOR
A164: 30692138747 | B164: FARMACITY SA | C164: VARIOS
A165: 33712234429 | B165: FEDAGAS SA | C165: VARIOS
A166: 20353576012 | B166: FEDERICO PABLO FEOLA | C166: VARIOS
A167: 20343766441 | B167: FERNANDEZ MAURO | C167: TALLER
A168: 27062343449 | B168: FERREIRA LILIANA INES | C168: FLETE
... A547: 30604958640 | B547: Aca Salud Coop P.S. Medico A.L | C547: CLIENTE

Sheet Julio 2024
A1: ORTOPEDIA GEMINIS S.A. | J1: 45474
A4: LIBRO IVA COMPRAS
A6: FACTURAS A
A7: FECHA | B7: PTO VTA | C7: FAC A | D7: CUIT | E7: RAZON SOCIAL | F7: NETO | G7: IVA 21% | H7: IVA 27% | I7: IVA 10,5% | J7: P IVA | K7: IIBB CF | L7: IIBB BS | M7: NO GRAV | N7: OTROS | O7: TOTAL | P7: DETALLE
E8: =VLOOKUP(D8,Configuracion!$A$4:$C$591,2,FALSE) -> #N/A | G8: =F8*21% -> 0 | O8: =SUM(F8:N8) -> 0 | P8: =VLOOKUP(D8,Configuracion!$A$4:$C$591,3,FALSE) -> #N/A
E9: =VLOOKUP(D9,Configuracion!$A$4:$C$591,2,FALSE) -> #N/A | G9: =F9*21% -> 0 | O9: =SUM(F9:N9) -> 0 | P9: =VLOOKUP(D9,Configuracion!$A$4:$C$591,3,FALSE) -> #N/A
E10: =VLOOKUP(D10,Configuracion!$A$4:$C$591,2,FALSE) -> #N/A | G10: =F10*21% -> 0 | O10: =SUM(F10:N10) -> 0 | P10: =VLOOKUP(D10,Configuracion!$A$4:$C$591,3,FALSE) -> #N/A
E11: =VLOOKUP(D11,Configuracion!$A$4:$C$591,2,FALSE) -> #N/A | G11: =F11*21% -> 0 | O11: =SUM(F11:N11) -> 0 | P11: =VLOOKUP(D11,Configuracion!$A$4:$C$591,3,FALSE) -> #N/A
A12: TOTAL | F12: =SUM(F8:F11) -> 0 | G12: =SUM(G8:G11) -> 0 | H12: =SUM(H8:H11) -> 0 | I12: =SUM(I8:I11) -> 0 | J12: =SUM(J8:J11) -> 0 | K12: =SUM(K8:K11) -> 0 | L12: =SUM(L8:L11) -> 0 | M12: =SUM(M8:M11) -> 0 | ... O12: =SUM(O8:O11) -> 0
F13: IVA | G13: =G12+H12+I12 -> 0
A15: FACTURAS B/C
A16: FECHA | B16: PTO VTA | C16: FAC C | D16: CUIT | E16: RAZON SOCIAL | F16: TOTAL | G16: DETALLE
E17: =VLOOKUP(D17,Configuracion!$A$4:$C$591,2,FALSE) -> #N/A | G17: =VLOOKUP(D17,Configuracion!$A$4:$C$591,3,FALSE) -> #N/A
E18: =VLOOKUP(D18,Configuracion!$A$4:$C$591,2,FALSE) -> #N/A | G18: =VLOOKUP(D18,Configuracion!$A$4:$C$591,3,FALSE) -> #N/A
E19: =VLOOKUP(D19,Configuracion!$A$4:$C$591,2,FALSE) -> #N/A | G19: =VLOOKUP(D19,Configuracion!$A$4:$C$591,3,FALSE) -> #N/A
E20: =VLOOKUP(D20,Configuracion!$A$4:$C$591,2,FALSE) -> #N/A | G20: =VLOOKUP(D20,Configuracion!$A$4:$C$591,3,FALSE) -> #N/A
E21: =VLOOKUP(D21,Configuracion!$A$4:$C$591,2,FALSE) -> #N/A | G21: =VLOOKUP(D21,Configuracion!$A$4:$C$591,3,FALSE) -> #N/A
E22: =VLOOKUP(D22,Configuracion!$A$4:$C$591,2,FALSE) -> #N/A | G22: =VLOOKUP(D22,Configuracion!$A$4:$C$591,3,FALSE) -> #N/A
E23: =VLOOKUP(D23,Configuracion!$A$4:$C$591,2,FALSE) -> #N/A | G23: =VLOOKUP(D23,Configuracion!$A$4:$C$591,3,FALSE) -> #N/A
E24: =VLOOKUP(D24,Configuracion!$A$4:$C$591,2,FALSE) -> #N/A | G24: =VLOOKUP(D24,Configuracion!$A$4:$C$591,3,FALSE) -> #N/A
A25: TOTAL | F25: =SUM(F17:F24) -> 0
A27: RETENCIONES
A28: FECHA | B28: COMPROBANTE NRO | D28: CUIT | E28: RAZON SOCIAL | F28: GANANCIAS | G28: IVA | H28: IIBB | I28: SUSS
A29: 45485 | B29: 59644 | D29: 30522428163 | E29: =VLOOKUP(D29,Configuracion!$A$4:$C$591,2,FALSE) -> GALENO ARGENTINA SA | F29: 7473.09 | G29: 40200.09 | H29: 3736.76 | I29: 3828.58
A30: 45475 | B30: 55614 | D30: 30522428163 | E30: =VLOOKUP(D30,Configuracion!$A$4:$C$591,2,FALSE) -> GALENO ARGENTINA SA | F30: 0 | G30: 23887.32 | H30: 2016.31 | I30: 2274.98
A31: 45485 | B31: 59642 | D31: 30522428163 | E31: =VLOOKUP(D31,Configuracion!$A$4:$C$591,2,FALSE) -> GALENO ARGENTINA SA | F31: 18354.61 | G31: 102601.53 | H31: 9177.3 | I31: 9771.57
A32: 45481 | B32: 57001 | D32: 30522428163 | E32: =VLOOKUP(D32,Configuracion!$A$4:$C$591,2,FALSE) -> GALENO ARGENTINA SA | F32: 183170 | G32: 972505.93 | H32: 91585 | I32: 92619.61
A33: 45481 | B33: 56919 | D33: 30522428163 | E33: =VLOOKUP(D33,Configuracion!$A$4:$C$591,2,FALSE) -> GALENO ARGENTINA SA | F33: 26347.77 | G33: 138325.79 | H33: 13173.88 | I33: 13173.88
A34: 45481 | B34: 57034 | D34: 30522428163 | E34: =VLOOKUP(D34,Configuracion!$A$4:$C$591,2,FALSE) -> GALENO ARGENTINA SA | F34: 6749.88 | G34: 120681.51 | H34: 3371.67 | I34: 11493.48
A35: 45468 | B35: 53218 | D35: 30522428163 | E35: =VLOOKUP(D35,Configuracion!$A$4:$C$591,2,FALSE) -> GALENO ARGENTINA SA | F35: 738.13 | G35: 4747.73 | H35: 369.06 | I35: 452.16
A36: 45450 | B36: 47651 | D36: 30522428163 | E36: =VLOOKUP(D36,Configuracion!$A$4:$C$591,2,FALSE) -> GALENO ARGENTINA SA | F36: 225303.14 | G36: 1182841.5 | H36: 112651.57 | I36: 112651.57
A37: 45484 | B37: 59037 | D37: 30522428163 | E37: =VLOOKUP(D37,Configuracion!$A$4:$C$591,2,FALSE) -> GALENO ARGENTINA SA | F37: 165627.86 | G37: 871890.5 | H37: 83037.19 | I37: 83037.19
A38: 45484 | B38: 59039 | D38: 30522428163 | E38: =VLOOKUP(D38,Configuracion!$A$4:$C$591,2,FALSE) -> GALENO ARGENTINA SA | F38: 598347.1 | G38: 3141322.3 | H38: 299173.55 | I38: 299173.55
A39: 45481 | B39: 57177 | D39: 30522428163 | E39: =VLOOKUP(D39,Configuracion!$A$4:$C$591,2,FALSE) -> GALENO ARGENTINA SA | F39: 24231.4 | G39: 127214.88 | H39: 12115.7 | I39: 12115.7
A40: 45481 | B40: 57324 | D40: 30522428163 | E40: =VLOOKUP(D40,Configuracion!$A$4:$C$591,2,FALSE) -> GALENO ARGENTINA SA | F40: 38148.76 | G40: 214599.17 | H40: 19074.38 | I40: 20438.02
... A45: 45478 | B45: 56788 | D45: 30522428163 | E45: =VLOOKUP(D45,Configuracion!$A$4:$C$591,2,FALSE) -> GALENO ARGENTINA SA | F45: 544161.98 | G45: 2856850.4 | H45: 272080.99 | I45: 272080.99
A46: 45477 | B46: 124506 | D46: 30590354798 | E46: =VLOOKUP(D46,Configuracion!$A$4:$C$591,2,FALSE) -> ASOCIACION MUTUAL SANCOR SALUD | F46: 29992.07 | H46: 30163.06
A47: 45478 | B47: 124762 | D47: 30590354798 | E47: =VLOOKUP(D47,Configuracion!$A$4:$C$591,2,FALSE) -> ASOCIACION MUTUAL SANCOR SALUD | F47: 27390 | H47: 23966.25
A48: 45498 | B48: 127746 | D48: 30590354798 | E48: =VLOOKUP(D48,Configuracion!$A$4:$C$591,2,FALSE) -> ASOCIACION MUTUAL SANCOR SALUD | F48: 31550.15 | H48: 27606.38
A49: 45495 | B49: 127251 | D49: 30590354798 | E49: =VLOOKUP(D49,Configuracion!$A$4:$C$591,2,FALSE) -> ASOCIACION MUTUAL SANCOR SALUD | F49: 36831.47 | H49: 32227.54
...

Sheet Calculo IVA
B1: ORTOPEDIA GEMINIS
A2: Calculo Iva | D2: 45474
B4: VENTAS
B5: Neto | C5: Iva | D5: Total
A6: FAC. "A" | B6: =+'Julio 2024'!F96 -> 16391270 | C6: =(B6*0.21) -> 3442166.8 | D6: =(B6+C6) -> 19833437
A7: FAC. "B" | B7: =+'Julio 2024'!F106 -> 0 | C7: =(B7*0.21) -> 0 | D7: =(B7+C7) -> 0
A8: FAC. "A" - Odoo | B8: =+'Julio 2024'!B115+'Julio 2024'!B117+'Julio 2024'!B118+'Julio 2024'!B116 -> 18508060 | C8: =+B8*0.21 -> 3886692.6 | D8: =(B8+C8) -> 22394753
A9: FAC. "B" - Odoo | B9: =+'Julio 2024'!B119+'Julio 2024'!B120 -> 35948743 | C9: =+B9*0.21 -> 7549236 | D9: =(B9+C9) -> 43497979
B10: =SUM(B6:B9) -> 70848073 | C10: =SUM(C6:C9) -> 14878095 | D10: =SUM(D6:D9) -> 85726168
B13: COMPRAS
B14: Neto | C14: Iva | D14: Total
A16: Compras s/ODOO | B16: 59861425 | C16: 9105103.9 | D16: 85572968
A17: Comprobantes AFIP - Saldo | B17: 536556.15 | C17: 114087.09 | D17: 1561385.3
A18: IVA S/ EXTRACTOS BANCARIOS | C18: 10544.01
B19: =SUM(B15:B18) -> 60397981 | C19: =SUM(C15:C18) -> 9229735 | D19: =SUM(D15:D18) -> 87134353
A22: RETENCIONES | B22: N° Cuit | C22: Importe | D22: Nro. Retencion | E22: Fecha
A23: AFIP - No están informadas las retenciones de IVA en el sistema de AFIP
C38: =+'Julio 2024'!G70 -> 11861105
A40: PERCEPCIONES | B40: N° Cuit | C40: Importe | D40: Nro. Retencion | E40: Fecha
C44: =SUM(C41:C43) -> 0
A46: Total Deducciociones | C46: =+C44+C38 -> 11861105
C49: (Montos en Positivo)
A50: 1er Saldo Tecnico del Período | C50: =+C10-C19 -> 5648360.3
A52: Saldo Tecnico de período Anterior (a favor) | D52: (resta en el total)
A54: Saldo Neto Técnico | C54: =+C50-C52 -> 5648360.3
A58: Saldo L.D. del Período | C58: =+C44+C38 -> 11861105
A60: Saldo L.D. del Período Anterior
A62: Neto S.L.D | C62: =+C58+C60 -> 11861105
A65: I V A | C65: =+C54-C62 -> -6212744.9
A66: NOTA: Sin Tomar posibles Retenciones que se hayan hecho

Sheet Ventas 07
A1: Ventas Libro de IVA 01/07/2024 - 31/07/2024
A2: Ortopedia Geminis S.A.
A4: Fecha | B4: Comprobante | C4: Nombre | D4: Cond. IVA | E4: CUIT o Doc. | F4: Gravado | G4: No Gravado | H4: IVA 2,5% | I4: IVA 5% | J4: IVA 10.5% | K4: IVA 21% | L4: IVA 27% | M4: Otros Imp | N4: Total Compr.
A5: 12/07/2024 | B5: FA-A 0005-00000154 | C5: Muñoz, Marcelo Sebastian | D5: IVA Responsable Inscripto | E5: 20238528543 | F5: 10743.8 | G5: 0 | H5: 0 | I5: 0 | J5: 0 | K5: 2256.2 | L5: 0 | M5: 0 | N5: 13000
A6: 29/07/2024 | B6: FA-A 0005-00000155 | C6: Puertolas, Maximiliano | D6: IVA Responsable Inscripto | E6: 20249404870 | F6: 15123.97 | G6: 0 | H6: 0 | I6: 0 | J6: 0 | K6: 3176.03 | L6: 0 | M6: 0 | N6: 18300
A7: 04/07/2024 | B7: FA-A 0006-00000512 | C7: Galeno Argentina SA | D7: IVA Responsable Inscripto | E7: 30522428163 | F7: 1495867.8 | G7: 0 | H7: 0 | I7: 0 | J7: 0 | K7: 314132.24 | L7: 0 | M7: 0 | N7: 1810000
A8: 10/07/2024 | B8: FA-A 0006-00000513 | C8: Galeno Argentina SA | D8: IVA Responsable Inscripto | E8: 30522428163 | F8: 1267889.9 | G8: 0 | H8: 0 | I8: 0 | J8: 0 | K8: 266256.88 | L8: 0 | M8: 0 | N8: 1534146.8
A9: 10/07/2024 | B9: FA-A 0006-00000514 | C9: Galeno Argentina SA | D9: IVA Responsable Inscripto | E9: 30522428163 | F9: 8704563.9 | G9: 0 | H9: 0 | I9: 0 | J9: 0 | K9: 1827958.4 | L9: 0 | M9: 0 | N9: 10532522
A10: 31/07/2024 | B10: FA-A 0006-00000516 | C10: Galeno Argentina SA | D10: IVA Responsable Inscripto | E10: 30522428163 | F10: 1453471.1 | G10: 0 | H10: 0 | I10: 0 | J10: 0 | K10: 305228.93 | L10: 0 | M10: 0 | N10: 1758700
A11: 02/07/2024 | B11: FA-A 0007-00002024 | C11: Medincare Argentina S.A. | D11: IVA Responsable Inscripto | E11: 30713669004 | F11: 72231.4 | G11: 0 | H11: 0 | I11: 0 | J11: 0 | K11: 15168.59 | L11: 0 | M11: 0 | N11: 87399.99
A12: 02/07/2024 | B12: FA-A 0007-00002025 | C12: Hc Homecare Internacion Domiciliaria S.A. | D12: IVA Responsable Inscripto | E12: 30710538014 | F12: 369049.59 | G12: 0 | H12: 0 | I12: 0 | J12: 0 | K12: 77500.41 | L12: 0 | M12: 0 | N12: 446550
A13: 02/07/2024 | B13: FA-A 0007-00002026 | C13: Login Door S.A | D13: IVA Responsable Inscripto | E13: 30711244383 | F13: 48576.03 | G13: 0 | H13: 0 | I13: 0 | J13: 0 | K13: 10200.97 | L13: 0 | M13: 0 | N13: 58777
A14: 02/07/2024 | B14: FA-A 0007-00002027 | C14: Medicus Sociedad Anonima De Asistencia Medica Y Cientifica | D14: IVA Responsable Inscripto | E14: 30546771314 | F14: 16597.8 | G14: 0 | H14: 0 | I14: 0 | J14: 0 | K14: 3485.54 | L14: 0 | M14: 0 | N14: 20083.34
A15: 03/07/2024 | B15: FA-A 0007-00002028 | C15: MGR IMPLANTES SA | D15: IVA Responsable Inscripto | E15: 30709016012 | F15: 131716.53 | G15: 0 | H15: 0 | I15: 0 | J15: 0 | K15: 27660.47 | L15: 0 | M15: 0 | N15: 159377
A16: 03/07/2024 | B16: FA-A 0007-00002029 | C16: MGR IMPLANTES SA | D16: IVA Responsable Inscripto | E16: 30709016012 | F16: 487603.32 | G16: 0 | H16: 0 | I16: 0 | J16: 0 | K16: 102396.71 | L16: 0 | M16: 0 | N16: 590000.03
... A65: 30/07/2024 | B65: FA-A 0007-00002078 | C65: Aca Salud Cooperativa De Prestacion De Servicios Medico Asistenciales Limitada | D65: IVA Responsable Inscripto | E65: 30604958640 | F65: 400000 | G65: 0 | H65: 0 | I65: 0 | J65: 0 | K65: 84000 | L65: 0 | M65: 0 | N65: 484000
A66: 01/07/2024 | B66: FA-B 0005-00010943 | C66: .CONSUMIDOR FINAL | D66: Consumidor Final | F66: 10743.8 | G66: 0 | H66: 0 | I66: 0 | J66: 0 | K66: 2256.2 | L66: 0 | M66: 0 | N66: 13000
A67: 01/07/2024 | B67: FA-B 0005-00010944 | C67: .CONSUMIDOR FINAL | D67: Consumidor Final | F67: 10743.8 | G67: 0 | H67: 0 | I67: 0 | J67: 0 | K67: 2256.2 | L67: 0 | M67: 0 | N67: 13000
A68: 01/07/2024 | B68: FA-B 0005-00010945 | C68: .CONSUMIDOR FINAL | D68: Consumidor Final | F68: 14462.81 | G68: 0 | H68: 0 | I68: 0 | J68: 0 | K68: 3037.19 | L68: 0 | M68: 0 | N68: 17500
A69: 01/07/2024 | B69: FA-B 0005-00010946 | C69: DIAZ, HECTOR | D69: Consumidor Final | E69: 8286597 | F69: 14462.81 | G69: 0 | H69: 0 | I69: 0 | J69: 0 | K69: 3037.19 | L69: 0 | M69: 0 | N69: 17500
A70: 01/07/2024 | B70: FA-B 0005-00010947 | C70: .CONSUMIDOR FINAL | D70: Consumidor Final | F70: 21487.6 | G70: 0 | H70: 0 | I70: 0 | J70: 0 | K70: 4512.4 | L70: 0 | M70: 0 | N70: 26000
A71: 01/07/2024 | B71: FA-B 0005-00010948 | C71: .CONSUMIDOR FINAL | D71: Consumidor Final | F71: 4628.1 | G71: 0 | H71: 0 | I71: 0 | J71: 0 | K71: 971.9 | L71: 0 | M71: 0 | N71: 5600
A72: 01/07/2024 | B72: FA-B 0005-00010949 | C72: .CONSUMIDOR FINAL | D72: Consumidor Final | F72: 14876.03 | G72: 0 | H72: 0 | I72: 0 | J72: 0 | K72: 3123.97 | L72: 0 | M72: 0 | N72: 18000
A73: 01/07/2024 | B73: FA-B 0005-00010950 | C73: .CONSUMIDOR FINAL | D73: Consumidor Final | F73: 13636.36 | G73: 0 | H73: 0 | I73: 0 | J73: 0 | K73: 2863.64 | L73: 0 | M73: 0 | N73: 16500
A74: 01/07/2024 | B74: FA-B 0005-00010951 | C74: LOUGE BARBARA | D74: Consumidor Final | E74: 25966714 | F74: 29338.84 | G74: 0 | H74: 0 | I74: 0 | J74: 0 | K74: 6161.16 | L74: 0 | M74: 0 | N74: 35500
A75: 01/07/2024 | B75: FA-B 0005-00010952 | C75: .CONSUMIDOR FINAL | D75: Consumidor Final | F75: 14669.42 | G75: 0 | H75: 0 | I75: 0 | J75: 0 | K75: 3080.58 | L75: 0 | M75: 0 | N75: 17750
A76: 01/07/2024 | B76: FA-B 0005-00010953 | C76: .CONSUMIDOR FINAL | D76: Consumidor Final | F76: 10743.8 | G76: 0 | H76: 0 | I76: 0 | J76: 0 | K76: 2256.2 | L76: 0 | M76: 0 | N76: 13000
A77: 01/07/2024 | B77: FA-B 0005-00010954 | C77: .CONSUMIDOR FINAL | D77: Consumidor Final | F77: 19669.42 | G77: 0 | H77: 0 | I77: 0 | J77: 0 | K77: 4130.58 | L77: 0 | M77: 0 | N77: 23800
A78: 01/07/2024 | B78: FA-B 0005-00010955 | C78: .CONSUMIDOR FINAL | D78: Consumidor Final | F78: 14049.59 | G78: 0 | H78: 0 | I78: 0 | J78: 0 | K78: 2950.41 | L78: 0 | M78: 0 | N78: 17000
A79: 01/07/2024 | B79: FA-B 0005-00010956 | C79: .CONSUMIDOR FINAL | D79: Consumidor Final | F79: 38925.62 | G79: 0 | H79: 0 | I79: 0 | J79: 0 | K79: 8174.38 | L79: 0 | M79: 0 | N79: 47100
A80: 01/07/2024 | B80: FA-B 0005-00010957 | C80: .CONSUMIDOR FINAL | D80: Consumidor Final | F80: 13223.14 | G80: 0 | H80: 0 | I80: 0 | J80: 0 | K80: 2776.86 | L80: 0 | M80: 0 | N80: 16000
A81: 02/07/2024 | B81: FA-B 0005-00010958 | C81: .CONSUMIDOR FINAL | D81: Consumidor Final | F81: 19090.91 | G81: 0 | H81: 0 | I81: 0 | J81: 0 | K81: 4009.09 | L81: 0 | M81: 0 | N81: 23100
A82: 02/07/2024 | B82: FA-B 0005-00010959 | C82: .CONSUMIDOR FINAL | D82: Consumidor Final | F82: 24628.1 | G82: 0 | H82: 0 | I82: 0 | J82: 0 | K82: 5171.9 | L82: 0 | M82: 0 | N82: 29800
A83: 02/07/2024 | B83: FA-B 0005-00010960 | C83: .CONSUMIDOR FINAL | D83: Consumidor Final | F83: 21074.38 | G83: 0 | H83: 0 | I83: 0 | J83: 0 | K83: 4425.62 | L83: 0 | M83: 0 | N83: 25500
A84: 02/07/2024 | B84: FA-B 0005-00010961 | C84: .CONSUMIDOR FINAL | D84: Consumidor Final | F84: 21487.6 | G84: 0 | H84: 0 | I84: 0 | J84: 0 | K84: 4512.4 | L84: 0 | M84: 0 | N84: 26000
A85: 02/07/2024 | B85: FA-B 0005-00010962 | C85: .CONSUMIDOR FINAL | D85: Consumidor Final | F85: 68925.62 | G85: 0 | H85: 0 | I85: 0 | J85: 0 | K85: 14474.38 | L85: 0 | M85: 0 | N85: 83400
A86: 02/07/2024 | B86: FA-B 0005-00010963 | C86: .CONSUMIDOR FINAL | D86: Consumidor Final | F86: 16528.93 | G86: 0 | H86: 0 | I86: 0 | J86: 0 | K86: 3471.07 | L86: 0 | M86: 0 | N86: 20000
... A107: 04/07/2024 | B107: FA-B 0005-00010984 | C107: .CONSUMIDOR FINAL | D107: Consumidor Final | F107: 4462.81 | G107: 0 | H107: 0 | I107: 0 | J107: 0 | K107: 937.19 | L107: 0 | M107: 0 | N107: 5400
A108: 04/07/2024 | B108: FA-B 0005-00010985 | C108: LEAL LUIS | D108: Consumidor Final | E108: 30298513 | F108: 33884.3 | G108: 0 | H108: 0 | I108: 0 | J108: 0 | K108: 7115.7 | L108: 0 | M108: 0 | N108: 41000
A109: 04/07/2024 | B109: FA-B 0005-00010986 | C109: .CONSUMIDOR FINAL | D109: Consumidor Final | F109: 10743.8 | G109: 0 | H109: 0 | I109: 0 | J109: 0 | K109: 2256.2 | L109: 0 | M109: 0 | N109: 13000
...

Sheet Compras 07 
A2: Compras Libro de IVA 01/07/2024 - 31/07/2024
A3: Ortopedia Geminis S.A.
A5: Fecha | B5: Comprobante | C5: Nombre | D5: Cond. IVA | E5: CUIT o Doc. | F5: Gravado | G5: No Gravado | H5: IVA 2,5% | I5: IVA 5% | J5: IVA 10.5% | K5: IVA 21% | L5: IVA 27% | M5: Otros Imp | N5: Total Compr.
A6: 45483 | B6: FA-A 0001-00000831 | C6: Rolls Y Empanadas S.A. | D6: IVA Responsable Inscripto | E6: 30715048066 | F6: 807785 | G6: 0 | H6: 0 | I6: 0 | J6: 0 | K6: 169634.85 | L6: 0 | M6: 0 | N6: 977419.85
A7: 45475 | B7: FA-A 0001-00002313 | C7: Nicolas Tobias Sequeira Y Maria Gabriela Rattner Sociedad De La Seccion Iv Lgs | D7: IVA Responsable Inscripto | E7: 30717179389 | F7: 33884.3 | G7: 0 | H7: 0 | I7: 0 | J7: 0 | K7: 7115.7 | L7: 0 | M7: 0 | N7: 41000
A8: 45474 | B8: FA-A 0001-00003721 | C8: Rehab S.R.L. | D8: IVA Responsable Inscripto | E8: 30715141201 | F8: 196966.09 | G8: 0 | H8: 0 | I8: 0 | J8: 0 | K8: 41362.88 | L8: 0 | M8: 0 | N8: 238328.97
A9: 45490 | B9: FA-A 0001-00003886 | C9: Rehab S.R.L. | D9: IVA Responsable Inscripto | E9: 30715141201 | F9: 3092234.2 | G9: 0 | H9: 0 | I9: 0 | J9: 0 | K9: 649369.19 | L9: 0 | M9: 0 | N9: 3741603.4
A10: 45490 | B10: FA-A 0001-00003887 | C10: Rehab S.R.L. | D10: IVA Responsable Inscripto | E10: 30715141201 | F10: 1426289.1 | G10: 0 | H10: 0 | I10: 0 | J10: 0 | K10: 299520.7 | L10: 0 | M10: 0 | N10: 1725809.8
A11: 45490 | B11: FA-A 0001-00003889 | C11: Rehab S.R.L. | D11: IVA Responsable Inscripto | E11: 30715141201 | F11: 364413 | G11: 0 | H11: 0 | I11: 0 | J11: 0 | K11: 76526.73 | L11: 0 | M11: 0 | N11: 440939.73
A12: 45490 | B12: FA-A 0001-00003890 | C12: Rehab S.R.L. | D12: IVA Responsable Inscripto | E12: 30715141201 | F12: 818170.5 | G12: 0 | H12: 0 | I12: 0 | J12: 0 | K12: 171815.81 | L12: 0 | M12: 0 | N12: 989986.31
A13: 45495 | B13: FA-A 0001-00003956 | C13: Rehab S.R.L. | D13: IVA Responsable Inscripto | E13: 30715141201 | F13: 3832222.5 | G13: 0 | H13: 0 | I13: 0 | J13: 0 | K13: 804766.73 | L13: 0 | M13: 0 | N13: 4636989.2
A14: 45496 | B14: FA-A 0001-00003985 | C14: Rehab S.R.L. | D14: IVA Responsable Inscripto | E14: 30715141201 | F14: 1365747 | G14: 0 | H14: 0 | I14: 0 | J14: 0 | K14: 286806.87 | L14: 0 | M14: 0 | N14: 1652553.9
A15: 45502 | B15: FA-A 0001-00004054 | C15: Rehab S.R.L. | D15: IVA Responsable Inscripto | E15: 30715141201 | F15: 2047644.3 | G15: 0 | H15: 0 | I15: 0 | J15: 0 | K15: 430005.3 | L15: 0 | M15: 0 | N15: 2477649.6
A16: 45499 | B16: FA-A 0002-00000021 | C16: Bard, Marisa Silvia | D16: IVA Responsable Inscripto | E16: 27243660535 | F16: 360000 | G16: 0 | H16: 0 | I16: 0 | J16: 0 | K16: 75600 | L16: 0 | M16: 0 | N16: 435600
A17: 45474 | B17: FA-A 0002-00000212 | C17: CONSORCIO BTOME MITRE 2466 | D17: IVA Responsable Inscripto | E17: 30605344352 | F17: 834000 | G17: 0 | H17: 0 | I17: 0 | J17: 0 | K17: 175140 | L17: 0 | M17: 0 | N17: 1009140
... A115: 45478 | B115: FA-C 2019-00004305 | C115: Murua Pou, Pablo Roberto | D115: Responsable Monotributo | E115: 20277164192 | F115: 0 | G115: 5700 | H115: 0 | I115: 0 | J115: 0 | K115: 0 | L115: 0 | M115: 0 | N115: 5700
A116: 45484 | B116: R-C 0002-00000500 | C116: Sampedro Silivia Herminia | D116: Responsable Monotributo | E116: 27178792178 | G116: 680000 | H116: 0 | I116: 0 | J116: 0 | K116: 0 | L116: 0 | M116: 0 | N116: 680000
A117: 45456 | B117: TF-A 0002-00010354 | C117: LA CAMIONERA MENDOCINA SRL | D117: IVA Responsable Inscripto | E117: 33531122599 | F117: 80000 | G117: 0 | H117: 0 | I117: 0 | J117: 0 | K117: 16800 | L117: 0 | M117: 0 | N117: 96800
A118: 45455 | B118: TF-A0004-00000138 | C118: Gasco Conde, Silvia Monica | D118: IVA Responsable Inscripto | E118: 27942499154 | F118: 16528.93 | G118: 0 | H118: 0 | I118: 0 | J118: 0 | K118: 3471.08 | L118: 0 | M118: 0 | N118: 20000.01
A119: 45503 | B119: TF-A0006-00001564 | C119: Papelera Geopel S.R.L. | D119: IVA Responsable Inscripto | E119: 30716815710 | F119: 13400 | G119: 0 | H119: 0 | I119: 0 | J119: 0 | K119: 2814 | L119: 0 | M119: 0 | N119: 16214
A120: 45487 | B120: TF-A0008-00011937 | C120: Somos Energia S.A. | D120: IVA Responsable Inscripto | E120: 33715594949 | F120: 36231.57 | G120: 0 | H120: 0 | I120: 0 | J120: 0 | K120: 7608.63 | L120: 0 | M120: 3759.8 | N120: 47600
A121: 45493 | B121: TF-A0012-00010431 | C121: Mirvar Sa | D121: IVA Responsable Inscripto | E121: 30685116657 | F121: 36015.72 | G121: 0 | H121: 0 | I121: 0 | J121: 0 | K121: 7563.3 | L121: 0 | M121: 6424.79 | N121: 50003.81
A122: 45474 | B122: TF-A0012-00037786 | C122: Unens S R L | D122: IVA Responsable Inscripto | E122: 33688436279 | F122: 33236.31 | G122: 0 | H122: 0 | I122: 0 | J122: 0 | K122: 6979.63 | L122: 0 | M122: 6187.03 | N122: 46402.97
A123: 45484 | B123: TF-A0015-00035343 | C123: Mirvar Sa | D123: IVA Responsable Inscripto | E123: 30685116657 | F123: 35581.89 | G123: 0 | H123: 0 | I123: 0 | J123: 0 | K123: 7472.2 | L123: 0 | M123: 6347.4 | N123: 49401.49
A124: 45455 | B124: TF-A0020-00010392 | C124: Iacono, Juan | D124: IVA Responsable Inscripto | E124: 20139793170 | F124: 35450.39 | G124: 0 | H124: 0 | I124: 0 | J124: 0 | K124: 7444.58 | L124: 0 | M124: 6161.02 | N124: 49055.99
A125: 45482 | B125: TF-A0024-00018322 | C125: Iacono, Juan | D125: IVA Responsable Inscripto | E125: 20139793170 | F125: 94948.88 | G125: 0 | H125: 0 | I125: 0 | J125: 0 | K125: 19939.26 | L125: 0 | M125: 8618.91 | N125: 123507.05
A126: 45487 | B126: TF-A0024-00018434 | C126: Iacono, Juan | D126: IVA Responsable Inscripto | E126: 20139793170 | F126: 46675.67 | G126: 0 | H126: 0 | I126: 0 | J126: 0 | K126: 9801.89 | L126: 0 | M126: 4323.39 | N126: 60800.95
A127: 45492 | B127: TF-A0024-00018557 | C127: Iacono, Juan | D127: IVA Responsable Inscripto | E127: 20139793170 | F127: 38383.94 | G127: 0 | H127: 0 | I127: 0 | J127: 0 | K127: 8060.63 | L127: 0 | M127: 3555.36 | N127: 49999.93
A128: 45495 | B128: TF-A0024-00018621 | C128: Iacono, Juan | D128: IVA Responsable Inscripto | E128: 20139793170 | F128: 73087.75 | G128: 0 | H128: 0 | I128: 0 | J128: 0 | K128: 15348.43 | L128: 0 | M128: 6769.85 | N128: 95206.03
A129: 45501 | B129: TF-A0024-00018718 | C129: Iacono, Juan | D129: IVA Responsable Inscripto | E129: 20139793170 | F129: 90376.27 | G129: 0 | H129: 0 | I129: 0 | J129: 0 | K129: 18979.02 | L129: 0 | M129: 8272.69 | N129: 117627.98
F130: =SUM(F6:F129) -> 59861425 | G130: =SUM(G6:G129) -> 16517670 | H130: =SUM(H6:H129) -> 0 | I130: =SUM(I6:I129) -> 0 | J130: =SUM(J6:J129) -> 3470207.2 | K130: =SUM(K6:K129) -> 5615042.7 | L130: =SUM(L6:L129) -> 19853.97 | M130: =SUM(M6:M129) -> 88769.43 | N130: =SUM(N6:N129) -> 85572968
H131: =+SUM(H130:L130) -> 9105103.9
B135: Comprobantes AFIP no recepcionados
A138: Fecha | B138: Tipo | C138: Punto de Venta | D138: Número Desde | E138: Número Hasta | F138: Cód. Autorización | G138: Tipo Doc. Emisor | H138: Nro. Doc. Emisor | I138: Denominación Emisor | J138: Tipo Cambio | K138: Moneda | L138: Imp. Neto Gravado | M138: Imp. Neto No Gravado | N138: Imp. Op. Exentas | O138: Otros Tributos | P138: IVA | Q138: Imp. Total
A139: 16/07/2024 | B139: 11 - Factura C | C139: 1 | D139: 12 | F139: 74305085368219 | G139: CUIT | H139: 27443612705 | I139: MIGOYA MORIONDO MARIA INES | J139: 1 | K139: $ | O139: 0 | Q139: 600000
A140: 08/07/2024 | B140: 11 - Factura C | C140: 4 | D140: 35 | F140: 74283166033414 | G140: CUIT | H140: 20272417653 | I140: TACACHO ROLANDO GABRIEL | J140: 1 | K140: $ | O140: 0 | Q140: 260000
A141: 18/07/2024 | B141: 1 - Factura A | C141: 6 | D141: 64 | F141: 74292359557295 | G141: CUIT | H141: 20263640862 | I141: LURASCHI HUMBERTO JOSE | J141: 1 | K141: $ | L141: 75206.62 | M141: 0 | N141: 0 | O141: 0 | P141: 15793.39 | Q141: 91000
A142: 20/07/2024 | B142: 1 - Factura A | C142: 7 | D142: 395 | F142: 74297565435532 | G142: CUIT | H142: 30717409007 | I142: GUPARO S.R.L. | J142: 1 | K142: $ | L142: 46611.57 | M142: 0 | N142: 0 | O142: 0 | P142: 9788.43 | Q142: 56400
A143: 05/07/2024 | B143: 1 - Factura A | C143: 1057 | D143: 569 | F143: 74271882575824 | G143: CUIT | H143: 30685849751 | I143: DIA ARGENTINA S A | J143: 1 | K143: $ | L143: 15545.45 | M143: 0 | N143: 0 | O143: 0 | P143: 3264.55 | Q143: 19431.82
A144: 26/07/2024 | B144: 1 - Factura A | C144: 7 | D144: 1247 | F144: 74306210605040 | G144: CUIT | H144: 30712187316 | I144: ITALOMED PRODUCTOS SRL | J144: 1 | K144: $ | L144: 117224.59 | M144: 0 | N144: 0 | O144: 0 | P144: 24617.16 | Q144: 141841.75
...
