Workbook
Name partner_id: Configuracion!$B$332

Sheet Configuracion
F1: CUIT | G1: Cargar sin guiones
F2: RAZON SOCIAL | G2: Maximo 30 caracteres
A3: CUIT | B3: RAZON SOCIAL | C3: DETALLE | F3: DETALLE | G3: Cargar tipo de gasto
A4: 30628205090 | B4: ALBAMIE SA | C4: CLIENTE
A5: 30711678820 | B5: 2PSI INGENIERIA SRL | C5: PROVEEDOR
A6: 33716367539 | B6: 3PI S.A.S. | C6: PROVEEDOR
A7: 30660373108 | B7: ABC SA | C7: VARIOS
A8: 20300210881 | B8: ABOY DIEGO OSCAR | C8: PROVEEDOR
A9: 27229910782 | B9: ABUGAUCH MARIA DE LOS ANGELES | C9: PROVEEDOR
A10: 20242709897 | B10: ABUGAUCH VICTOR HUGO | C10: PROVEEDOR
A11: 20281669053 | B11: ACOSTA JAVIER GUSTAVO | C11: FLETE
A12: 20174240125 | B12: ACOSTA OSCAR ISIDRO | C12: VARIOS
A13: 30641659106 | B13: AGRISOL SA | C13: VARIOS
A14: 33709914109 | B14: ALAN COLLECTION SA | C14: VARIOS
A15: 20267161616 | B15: ALBAJARI DIEGO MARCOS | C15: VARIOS
... A155: 30537679855 | B155: ESTACION LIMA SA | C155: VARIOS
A156: 30-56864959-8 | B156: EXPRESO BISONTE SRL | C156: FLETE
A157: 30708542349 | B157: EXPRESO FORMOSA SRL | C157: FLETE
A158: 30526582884 | B158: EXPRESO MAR DEL PLATA SA | C158: FLETE
A159: 30577744579 | B159: EXPRESO TROLE SRL | C159: FLETE
A160: 30715949292 | B160: EYPAPEL SAS | C160: GASTOS VARIOS
A161: 30715980807 | B161: FABORT SRL | C161: PROVEEDOR
A162: 20359718765 | B162: FAIL ABRAHAM | C162: VARIOS
A163: 30643518364 | B163: FARMACIA DE MEDRANO SCS | C163: PROVEEDOR
A164: 30692138747 | B164: FARMACITY SA | C164: VARIOS
A165: 33712234429 | B165: FEDAGAS SA | C165: VARIOS
A166: 20353576012 | B166: FEDERICO PABLO FEOLA | C166: VARIOS
A167: 20343766441 | B167: FERNANDEZ MAURO | C167: TALLER
A168: 27062343449 | B168: FERREIRA LILIANA INES | C168: FLETE
... A516: 33717383139 | B516: BALINERO SRL | C516: VARIOS

Sheet Abril 2023
A1: ORTOPEDIA GEMINIS S.A. | J1: 45017
A4: LIBRO IVA COMPRAS
A6: FACTURAS A
A7: FECHA | B7: PTO VTA | C7: FAC A | D7: CUIT | E7: RAZON SOCIAL | F7: NETO | G7: IVA 21% | H7: IVA 27% | I7: IVA 10,5% | J7: P IVA | K7: IIBB CF | L7: IIBB BS | M7: NO GRAV | N7: OTROS | O7: TOTAL | P7: DETALLE
A8: 44998 | B8: 13 | C8: 1119 | D8: 33709914109 | E8: =VLOOKUP(D8,Configuracion!$A$4:$C$591,2,FALSE) -> ALAN COLLECTION SA | F8: 5289.26 | G8: =F8*21% -> 1110.7446 | O8: =SUM(F8:N8) -> 6400.0046 | P8: =VLOOKUP(D8,Configuracion!$A$4:$C$591,3,FALSE) -> VARIOS
A9: 44973 | B9: 13 | C9: 1095 | D9: 33709914109 | E9: =VLOOKUP(D9,Configuracion!$A$4:$C$591,2,FALSE) -> ALAN COLLECTION SA | F9: 1322.31 | G9: =F9*21% -> 277.6851 | O9: =SUM(F9:N9) -> 1599.9951 | P9: =VLOOKUP(D9,Configuracion!$A$4:$C$591,3,FALSE) -> VARIOS
A10: 45028 | B10: 13 | C10: 1140 | D10: 33709914109 | E10: =VLOOKUP(D10,Configuracion!$A$4:$C$591,2,FALSE) -> ALAN COLLECTION SA | F10: 2892.56 | G10: =F10*21% -> 607.4376 | O10: =SUM(F10:N10) -> 3499.9976 | P10: =VLOOKUP(D10,Configuracion!$A$4:$C$591,3,FALSE) -> VARIOS
A11: 45036 | B11: 13 | C11: 1150 | D11: 33709914109 | E11: =VLOOKUP(D11,Configuracion!$A$4:$C$591,2,FALSE) -> ALAN COLLECTION SA | F11: 2561.98 | G11: =F11*21% -> 538.0158 | O11: =SUM(F11:N11) -> 3099.9958 | P11: =VLOOKUP(D11,Configuracion!$A$4:$C$591,3,FALSE) -> VARIOS
A12: 11/04/2023 | B12: 8 | C12: 1430 | D12: 30708973501 | E12: =VLOOKUP(D12,Configuracion!$A$4:$C$591,2,FALSE) -> ASIAL SRL | F12: 239840 | G12: =F12*21% -> 50366.4 | O12: =SUM(F12:N12) -> 290206.4 | P12: =VLOOKUP(D12,Configuracion!$A$4:$C$591,3,FALSE) -> INSUMOS
A13: 11/04/2023 | B13: 8 | C13: 1431 | D13: 30708973501 | E13: =VLOOKUP(D13,Configuracion!$A$4:$C$591,2,FALSE) -> ASIAL SRL | F13: 221022 | G13: =F13*21% -> 46414.62 | O13: =SUM(F13:N13) -> 267436.62 | P13: =VLOOKUP(D13,Configuracion!$A$4:$C$591,3,FALSE) -> INSUMOS
A14: 10/04/2023 | B14: 4 | C14: 376 | D14: 20379223185 | E14: =VLOOKUP(D14,Configuracion!$A$4:$C$591,2,FALSE) -> AYALA MAURICIO JUAN JOSE | F14: 47380 | G14: =F14*21% -> 9949.8 | O14: =SUM(F14:N14) -> 57329.8 | P14: =VLOOKUP(D14,Configuracion!$A$4:$C$591,3,FALSE) -> PROVEEDOR
A15: 04/04/2023 | B15: 5 | C15: 2458 | D15: 33714662819 | E15: =VLOOKUP(D15,Configuracion!$A$4:$C$591,2,FALSE) -> AYUDAS TECNICAS SRL | F15: 510444 | G15: =F15*21% -> 107193.24 | O15: =SUM(F15:N15) -> 617637.24 | P15: =VLOOKUP(D15,Configuracion!$A$4:$C$591,3,FALSE) -> PROVEEDOR
A16: 04/04/2023 | B16: 6 | C16: 167 | D16: 33717383139 | E16: =VLOOKUP(D16,Configuracion!$A$4:$C$591,2,FALSE) -> BALINERO SRL | F16: 9330.58 | G16: =F16*21% -> 1959.4218 | O16: =SUM(F16:N16) -> 11290.002 | P16: =VLOOKUP(D16,Configuracion!$A$4:$C$591,3,FALSE) -> VARIOS
A17: 03/04/2023 | B17: 15 | C17: 4280 | D17: 33712276539 | E17: =VLOOKUP(D17,Configuracion!$A$4:$C$591,2,FALSE) -> CASTAÑO AUTOVOX SRL | F17: 10155.9 | G17: =F17*21% -> 2132.739 | K17: 355.46 | M17: 612.55 | O17: =SUM(F17:N17) -> 13256.649 | P17: =VLOOKUP(D17,Configuracion!$A$4:$C$591,3,FALSE) -> VARIOS
A18: 14/04/2023 | B18: 15 | C18: 4365 | D18: 33712276539 | E18: =VLOOKUP(D18,Configuracion!$A$4:$C$591,2,FALSE) -> CASTAÑO AUTOVOX SRL | F18: 12910.24 | G18: =F18*21% -> 2711.1504 | K18: 451.86 | M18: 778.67 | O18: =SUM(F18:N18) -> 16851.92 | P18: =VLOOKUP(D18,Configuracion!$A$4:$C$591,3,FALSE) -> VARIOS
A19: 22/04/2023 | B19: 27 | C19: 4512 | D19: 33712276539 | E19: =VLOOKUP(D19,Configuracion!$A$4:$C$591,2,FALSE) -> CASTAÑO AUTOVOX SRL | F19: 2662.46 | G19: =F19*21% -> 559.1166 | K19: 93.19 | N19: 155.28 | O19: =SUM(F19:N19) -> 3470.0466 | P19: =VLOOKUP(D19,Configuracion!$A$4:$C$591,3,FALSE) -> VARIOS
A20: 03/04/2023 | B20: 2 | C20: 182 | D20: 30605344352 | E20: =VLOOKUP(D20,Configuracion!$A$4:$C$591,2,FALSE) -> CONSORCIO BARTOLME MITRE 2466 | F20: 187880 | G20: =F20*21% -> 39454.8 | O20: =SUM(F20:N20) -> 227334.8 | P20: =VLOOKUP(D20,Configuracion!$A$4:$C$591,3,FALSE) -> CONSORCIO
A21: 14/04/2023 | B21: 2635 | C21: 964 | D21: 33699685459 | E21: =VLOOKUP(D21,Configuracion!$A$4:$C$591,2,FALSE) -> CORREO ANDREANI SA | F21: 1734.39 | G21: =F21*21% -> 364.2219 | O21: =SUM(F21:N21) -> 2098.6119 | P21: =VLOOKUP(D21,Configuracion!$A$4:$C$591,3,FALSE) -> VARIOS
A22: 30/04/2023 | B22: 20 | C22: 146748 | D22: 30696850972 | E22: =VLOOKUP(D22,Configuracion!$A$4:$C$591,2,FALSE) -> CPS COMUNICACIONES SA | F22: 3290.91 | H22: 888.55 | K22: 115.17 | O22: =SUM(F22:N22) -> 4294.63 | P22: =VLOOKUP(D22,Configuracion!$A$4:$C$591,3,FALSE) -> SERVICIO
A23: 03/04/2023 | B23: 3 | C23: 7688 | D23: 20045615473 | E23: =VLOOKUP(D23,Configuracion!$A$4:$C$591,2,FALSE) -> DI FEO HUGO PASCUAL GUILLERMO | F23: 28600 | G23: =F23*21% -> 6006 | O23: =SUM(F23:N23) -> 34606 | P23: =VLOOKUP(D23,Configuracion!$A$4:$C$591,3,FALSE) -> INSUMOS
A24: 13/04/2023 | B24: 3 | C24: 7710 | D24: 20045615473 | E24: =VLOOKUP(D24,Configuracion!$A$4:$C$591,2,FALSE) -> DI FEO HUGO PASCUAL GUILLERMO | F24: 15050 | G24: =F24*21% -> 3160.5 | O24: =SUM(F24:N24) -> 18210.5 | P24: =VLOOKUP(D24,Configuracion!$A$4:$C$591,3,FALSE) -> INSUMOS
A25: 13/04/2023 | B25: 3 | C25: 7713 | D25: 20045615473 | E25: =VLOOKUP(D25,Configuracion!$A$4:$C$591,2,FALSE) -> DI FEO HUGO PASCUAL GUILLERMO | F25: 2795 | G25: =F25*21% -> 586.95 | O25: =SUM(F25:N25) -> 3381.95 | P25: =VLOOKUP(D25,Configuracion!$A$4:$C$591,3,FALSE) -> INSUMOS
A26: 44987 | B26: 3 | C26: 7605 | D26: 20045615473 | E26: =VLOOKUP(D26,Configuracion!$A$4:$C$591,2,FALSE) -> DI FEO HUGO PASCUAL GUILLERMO | F26: 11415 | G26: =F26*21% -> 2397.15 | O26: =SUM(F26:N26) -> 13812.15 | P26: =VLOOKUP(D26,Configuracion!$A$4:$C$591,3,FALSE) -> INSUMOS
A27: 44980 | B27: 907 | C27: 206 | D27: 30685849751 | E27: =VLOOKUP(D27,Configuracion!$A$4:$C$591,2,FALSE) -> DIA ARGENTINA SA | F27: 415.37 | G27: =F27*21% -> 87.2277 | O27: =SUM(F27:N27) -> 502.5977 | P27: =VLOOKUP(D27,Configuracion!$A$4:$C$591,3,FALSE) -> VARIOS
A28: 44942 | B28: 10845 | C28: 63 | D28: 30685849751 | E28: =VLOOKUP(D28,Configuracion!$A$4:$C$591,2,FALSE) -> DIA ARGENTINA SA | F28: 1023.6 | G28: =F28*21% -> 214.956 | O28: =SUM(F28:N28) -> 1238.556 | P28: =VLOOKUP(D28,Configuracion!$A$4:$C$591,3,FALSE) -> VARIOS
A29: 11/04/2023 | B29: 7 | C29: 26677 | D29: 20271532483 | E29: =VLOOKUP(D29,Configuracion!$A$4:$C$591,2,FALSE) -> DIEGO MARTIN RIOS | F29: 1508857.9 | G29: =F29*21% -> 316860.15 | K29: 52810.03 | O29: =SUM(F29:N29) -> 1878528.1 | P29: =VLOOKUP(D29,Configuracion!$A$4:$C$591,3,FALSE) -> PROVEEDOR
A30: 14/04/2023 | B30: 7 | C30: 26710 | D30: 20271532483 | E30: =VLOOKUP(D30,Configuracion!$A$4:$C$591,2,FALSE) -> DIEGO MARTIN RIOS | F30: 1085101.3 | G30: =F30*21% -> 227871.28 | K30: 37978.55 | O30: =SUM(F30:N30) -> 1350951.1 | P30: =VLOOKUP(D30,Configuracion!$A$4:$C$591,3,FALSE) -> PROVEEDOR
A31: 19/04/2023 | B31: 7 | C31: 26744 | D31: 20271532483 | E31: =VLOOKUP(D31,Configuracion!$A$4:$C$591,2,FALSE) -> DIEGO MARTIN RIOS | F31: 561704.08 | G31: =F31*21% -> 117957.86 | K31: 19659.64 | O31: =SUM(F31:N31) -> 699321.58 | P31: =VLOOKUP(D31,Configuracion!$A$4:$C$591,3,FALSE) -> PROVEEDOR
A32: 24/04/2023 | B32: 7 | C32: 26800 | D32: 20271532483 | E32: =VLOOKUP(D32,Configuracion!$A$4:$C$591,2,FALSE) -> DIEGO MARTIN RIOS | F32: 1942261.4 | G32: =F32*21% -> 407874.89 | K32: 67979.15 | O32: =SUM(F32:N32) -> 2418115.4 | P32: =VLOOKUP(D32,Configuracion!$A$4:$C$591,3,FALSE) -> PROVEEDOR
A33: 25/04/2023 | B33: 2 | C33: 7247 | D33: 30694549817 | E33: =VLOOKUP(D33,Configuracion!$A$4:$C$591,2,FALSE) -> DISEÑOS JERY SRL | F33: 364800 | G33: =F33*21% -> 76608 | O33: =SUM(F33:N33) -> 441408 | P33: =VLOOKUP(D33,Configuracion!$A$4:$C$591,3,FALSE) -> PROVEEDOR
A34: 10/04/2023 | B34: 2 | C34: 671 | D34: 20140958213 | E34: =VLOOKUP(D34,Configuracion!$A$4:$C$591,2,FALSE) -> ESPAÑA ALEJANDRO JORGE | F34: 97107.44 | G34: =F34*21% -> 20392.562 | O34: =SUM(F34:N34) -> 117500 | P34: =VLOOKUP(D34,Configuracion!$A$4:$C$591,3,FALSE) -> PROVEEDOR
A35: 45026 | B35: 2 | C35: 671 | D35: 20140958213 | E35: =VLOOKUP(D35,Configuracion!$A$4:$C$591,2,FALSE) -> ESPAÑA ALEJANDRO JORGE | F35: 97107.44 | G35: =F35*21% -> 20392.562 | O35: =SUM(F35:N35) -> 117500 | P35: =VLOOKUP(D35,Configuracion!$A$4:$C$591,3,FALSE) -> PROVEEDOR
A36: 12/04/2023 | B36: 7 | C36: 381 | D36: 30711328498 | E36: =VLOOKUP(D36,Configuracion!$A$4:$C$591,2,FALSE) -> ESPOSITO FRANCISCO ANT Y OT SH | F36: 16363.64 | G36: =F36*21% -> 3436.3644 | O36: =SUM(F36:N36) -> 19800.004 | P36: =VLOOKUP(D36,Configuracion!$A$4:$C$591,3,FALSE) -> GASTOS MOVILIDAD
A37: 26/04/2023 | B37: 11 | C37: 81644 | D37: 30526582884 | E37: =VLOOKUP(D37,Configuracion!$A$4:$C$591,2,FALSE) -> EXPRESO MAR DEL PLATA SA | F37: 3826.45 | G37: =F37*21% -> 803.5545 | O37: =SUM(F37:N37) -> 4630.0045 | P37: =VLOOKUP(D37,Configuracion!$A$4:$C$591,3,FALSE) -> FLETE
A38: 03/04/2023 | B38: 44 | C38: 20505 | D38: 30626009618 | E38: =VLOOKUP(D38,Configuracion!$A$4:$C$591,2,FALSE) -> EXPRESO RIVADAVIA SRL | F38: 1499.07 | G38: =F38*21% -> 314.8047 | O38: =SUM(F38:N38) -> 1813.8747 | P38: =VLOOKUP(D38,Configuracion!$A$4:$C$591,3,FALSE) -> FLETE
A39: 03/04/2023 | B39: 48 | C39: 368332 | D39: 30626009618 | E39: =VLOOKUP(D39,Configuracion!$A$4:$C$591,2,FALSE) -> EXPRESO RIVADAVIA SRL | F39: 5646.21 | G39: =F39*21% -> 1185.7041 | O39: =SUM(F39:N39) -> 6831.9141 | P39: =VLOOKUP(D39,Configuracion!$A$4:$C$591,3,FALSE) -> FLETE
A40: 45035 | B40: 48 | C40: 371809 | D40: 30626009618 | E40: =VLOOKUP(D40,Configuracion!$A$4:$C$591,2,FALSE) -> EXPRESO RIVADAVIA SRL | F40: 5239.67 | G40: =F40*21% -> 1100.3307 | O40: =SUM(F40:N40) -> 6340.0007 | P40: =VLOOKUP(D40,Configuracion!$A$4:$C$591,3,FALSE) -> FLETE
A41: 44971 | B41: 2398 | C41: 669 | D41: 30692138747 | E41: =VLOOKUP(D41,Configuracion!$A$4:$C$591,2,FALSE) -> FARMACITY SA | F41: 2295.05 | G41: =F41*21% -> 481.9605 | K41: 68.85 | O41: =SUM(F41:N41) -> 2845.8605 | P41: =VLOOKUP(D41,Configuracion!$A$4:$C$591,3,FALSE) -> VARIOS
A42: 13/04/2023 | B42: 7 | C42: 1719 | D42: 20284183534 | E42: =VLOOKUP(D42,Configuracion!$A$4:$C$591,2,FALSE) -> FURLANETTO MARTIN | F42: 1735.54 | G42: =F42*21% -> 364.4634 | O42: =SUM(F42:N42) -> 2100.0034 | P42: =VLOOKUP(D42,Configuracion!$A$4:$C$591,3,FALSE) -> VARIOS
A43: 45033 | B43: 7 | C43: 1730 | D43: 20284183534 | E43: =VLOOKUP(D43,Configuracion!$A$4:$C$591,2,FALSE) -> FURLANETTO MARTIN | F43: 2743.84 | G43: =F43*21% -> 576.2064 | O43: =SUM(F43:N43) -> 3320.0464 | P43: =VLOOKUP(D43,Configuracion!$A$4:$C$591,3,FALSE) -> VARIOS
...

Sheet Calculo IVA
B1: ORTOPEDIA GEMINIS
A2: Calculo Iva | D2: 45017
B4: VENTAS
B5: Neto | C5: Iva | D5: Total
A6: FAC. "A" | B6: =+'Abril 2023'!F227 -> 0 | C6: =(B6*0.21) -> 0 | D6: =(B6+C6) -> 0
A7: FAC. "B" | B7: =+'Abril 2023'!F237 -> 0 | C7: =(B7*0.21) -> 0 | D7: =(B7+C7) -> 0
A8: FAC. "A" - Odoo | B8: =+'Abril 2023'!B246+'Abril 2023'!B248+'Abril 2023'!B249+'Abril 2023'!B247 -> 27597413 | C8: =+B8*0.21 -> 5795456.7 | D8: =(B8+C8) -> 33392869
A9: FAC. "B" - Odoo | B9: =+'Abril 2023'!B250+'Abril 2023'!B251 -> 2558641.9 | C9: =+B9*0.21 -> 537314.79 | D9: =(B9+C9) -> 3095956.7
B10: =SUM(B6:B9) -> 30156055 | C10: =SUM(C6:C9) -> 6332771.5 | D10: =SUM(D6:D9) -> 36488826
B13: COMPRAS
B14: Neto | C14: Iva | D14: Total
B15: =+'Abril 2023'!F120 -> 11859356 | C15: =+'Abril 2023'!G120+'Abril 2023'!H120+'Abril 2023'!I120 -> 2449003 | D15: =(B15+C15) -> 14308359
B17: =SUM(B15:B16) -> 11859356 | C17: =SUM(C15:C16) -> 2449003 | D17: =SUM(D15:D16) -> 14308359
A20: RETENCIONES | B20: N° Cuit | C20: Importe | D20: Nro. Retencion | E20: Fecha
A21: AFIP - No están informadas las retenciones de IVA en el sistema de AFIP
C36: =+'Abril 2023'!G213 -> 2641321.8
A38: PERCEPCIONES | B38: N° Cuit | C38: Importe | D38: Nro. Retencion | E38: Fecha
C42: =SUM(C39:C41) -> 0
A44: Total Deducciociones | C44: =+C42+C36 -> 2641321.8
C47: (Montos en Positivo)
A48: 1er Saldo Tecnico del Período | C48: =+C10-C17 -> 3883768.4
A50: Saldo Tecnico de período Anterior (a favor) | D50: (resta en el total)
A52: Saldo Neto Técnico | C52: =+C48-C50 -> 3883768.4
A56: Saldo L.D. del Período | C56: =+C42+C36 -> 2641321.8
A58: Saldo L.D. del Período Anterior
A60: Neto S.L.D | C60: =+C56+C58 -> 2641321.8
A63: I V A | C63: =+C52-C60 -> 1242446.7
A64: NOTA: Sin Tomar posibles Retenciones que se hayan hecho

Sheet Ventas 04 2023
A2: Ventas Libro de IVA 01/04/2023 - 30/04/2023
A3: Ortopedia Geminis S.A.
A5: Fecha | B5: Comprobante | C5: Nombre | D5: Cond. IVA | E5: CUIT o Doc. | F5: Gravado | G5: No Gravado | H5: IVA 2,5% | I5: IVA 5% | J5: IVA 10.5% | K5: IVA 21% | L5: IVA 27% | M5: Otros Imp | N5: Total Compr.
A6: 03/04/2023 | B6: FA-B 0005-00007644 | C6: .CONSUMIDOR FINAL | D6: Consumidor Final | F6: 3884.3 | G6: 0 | H6: 0 | I6: 0 | J6: 0 | K6: 815.7 | L6: 0 | M6: 0 | N6: 4700
A7: 03/04/2023 | B7: FA-B 0005-00007645 | C7: .CONSUMIDOR FINAL | D7: Consumidor Final | F7: 4958.68 | G7: 0 | H7: 0 | I7: 0 | J7: 0 | K7: 1041.32 | L7: 0 | M7: 0 | N7: 6000
A8: 03/04/2023 | B8: FA-B 0005-00007646 | C8: .CONSUMIDOR FINAL | D8: Consumidor Final | F8: 9710.75 | G8: 0 | H8: 0 | I8: 0 | J8: 0 | K8: 2039.25 | L8: 0 | M8: 0 | N8: 11750
A9: 03/04/2023 | B9: FA-B 0005-00007647 | C9: .CONSUMIDOR FINAL | D9: Consumidor Final | F9: 7272.73 | G9: 0 | H9: 0 | I9: 0 | J9: 0 | K9: 1527.27 | L9: 0 | M9: 0 | N9: 8800
A10: 03/04/2023 | B10: FA-B 0005-00007648 | C10: .CONSUMIDOR FINAL | D10: Consumidor Final | F10: 6446.28 | G10: 0 | H10: 0 | I10: 0 | J10: 0 | K10: 1353.72 | L10: 0 | M10: 0 | N10: 7800
A11: 03/04/2023 | B11: FA-B 0005-00007649 | C11: .CONSUMIDOR FINAL | D11: Consumidor Final | F11: 2314.05 | G11: 0 | H11: 0 | I11: 0 | J11: 0 | K11: 485.95 | L11: 0 | M11: 0 | N11: 2800
A12: 03/04/2023 | B12: FA-B 0005-00007650 | C12: .CONSUMIDOR FINAL | D12: Consumidor Final | F12: 8264.47 | G12: 0 | H12: 0 | I12: 0 | J12: 0 | K12: 1735.53 | L12: 0 | M12: 0 | N12: 10000
A13: 03/04/2023 | B13: FA-B 0005-00007651 | C13: .CONSUMIDOR FINAL | D13: Consumidor Final | F13: 2231.4 | G13: 0 | H13: 0 | I13: 0 | J13: 0 | K13: 468.6 | L13: 0 | M13: 0 | N13: 2700
A14: 03/04/2023 | B14: FA-B 0005-00007652 | C14: .CONSUMIDOR FINAL | D14: Consumidor Final | F14: 7768.6 | G14: 0 | H14: 0 | I14: 0 | J14: 0 | K14: 1631.4 | L14: 0 | M14: 0 | N14: 9400
A15: 03/04/2023 | B15: FA-B 0005-00007653 | C15: .CONSUMIDOR FINAL | D15: Consumidor Final | F15: 15694.21 | G15: 0 | H15: 0 | I15: 0 | J15: 0 | K15: 3295.79 | L15: 0 | M15: 0 | N15: 18990
A16: 03/04/2023 | B16: FA-B 0005-00007654 | C16: .CONSUMIDOR FINAL | D16: Consumidor Final | F16: 12892.56 | G16: 0 | H16: 0 | I16: 0 | J16: 0 | K16: 2707.44 | L16: 0 | M16: 0 | N16: 15600
A17: 03/04/2023 | B17: FA-B 0005-00007655 | C17: .CONSUMIDOR FINAL | D17: Consumidor Final | F17: 4504.13 | G17: 0 | H17: 0 | I17: 0 | J17: 0 | K17: 945.87 | L17: 0 | M17: 0 | N17: 5450
A18: 03/04/2023 | B18: FA-A 0006-00000332 | C18: Galeno Argentina Sociedad Anonima | D18: IVA Responsable Inscripto | E18: 30522428163 | F18: 2042975.2 | G18: 0 | H18: 0 | I18: 0 | J18: 0 | K18: 429024.8 | L18: 0 | M18: 0 | N18: 2472000
A19: 03/04/2023 | B19: FA-A 0007-00001398 | C19: Amparo Salud S.R.L. | D19: IVA Responsable Inscripto | E19: 30715186655 | F19: 58674.1 | G19: 0 | H19: 0 | I19: 0 | J19: 0 | K19: 12321.56 | L19: 0 | M19: 0 | N19: 70995.66
A20: 03/04/2023 | B20: FA-A 0007-00001399 | C20: Amparo Salud S.R.L. | D20: IVA Responsable Inscripto | E20: 30715186655 | F20: 3512.4 | G20: 0 | H20: 0 | I20: 0 | J20: 0 | K20: 737.6 | L20: 0 | M20: 0 | N20: 4250
A21: 03/04/2023 | B21: FA-A 0007-00001400 | C21: Centro Medico Amenabar Srl | D21: IVA Responsable Inscripto | E21: 30707612971 | F21: 8796.31 | G21: 0 | H21: 0 | I21: 0 | J21: 0 | K21: 1847.23 | L21: 0 | M21: 0 | N21: 10643.54
A22: 03/04/2023 | B22: FA-A 0007-00001401 | C22: Ensalud S.A | D22: IVA Responsable Inscripto | E22: 30707118454 | F22: 4003.3 | G22: 0 | H22: 0 | I22: 0 | J22: 0 | K22: 840.69 | L22: 0 | M22: 0 | N22: 4843.99
A23: 03/04/2023 | B23: FA-A 0007-00001402 | C23: Obra Social Del Personal De Las Telecomunicaciones De La Republica Argentina | D23: IVA Responsable Inscripto | E23: 30608716390 | F23: 1487.6 | G23: 0 | H23: 0 | I23: 0 | J23: 0 | K23: 312.4 | L23: 0 | M23: 0 | N23: 1800
A24: 03/04/2023 | B24: FA-A 0007-00001403 | C24: Obra Social Del Personal De Las Telecomunicaciones De La Republica Argentina | D24: IVA Responsable Inscripto | E24: 30608716390 | F24: 6033.06 | G24: 0 | H24: 0 | I24: 0 | J24: 0 | K24: 1266.94 | L24: 0 | M24: 0 | N24: 7300
A25: 03/04/2023 | B25: FA-B 0007-00004229 | C25: GABRIELA VANINA GALLO | D25: Consumidor Final | E25: 26542077 | F25: 8677.69 | G25: 0 | H25: 0 | I25: 0 | J25: 0 | K25: 1822.31 | L25: 0 | M25: 0 | N25: 10500
A26: 03/04/2023 | B26: FA-B 0007-00004230 | C26: LOCOCO, CARMEN | D26: Consumidor Final | E26: 17198648 | F26: 5950.41 | G26: 0 | H26: 0 | I26: 0 | J26: 0 | K26: 1249.59 | L26: 0 | M26: 0 | N26: 7200
A27: 04/04/2023 | B27: FA-B 0005-00007656 | C27: .CONSUMIDOR FINAL | D27: Consumidor Final | F27: 3884.3 | G27: 0 | H27: 0 | I27: 0 | J27: 0 | K27: 815.7 | L27: 0 | M27: 0 | N27: 4700
A28: 04/04/2023 | B28: FA-B 0005-00007657 | C28: .CONSUMIDOR FINAL | D28: Consumidor Final | F28: 5537.19 | G28: 0 | H28: 0 | I28: 0 | J28: 0 | K28: 1162.81 | L28: 0 | M28: 0 | N28: 6700
A29: 04/04/2023 | B29: FA-B 0005-00007658 | C29: .CONSUMIDOR FINAL | D29: Consumidor Final | F29: 6198.35 | G29: 0 | H29: 0 | I29: 0 | J29: 0 | K29: 1301.65 | L29: 0 | M29: 0 | N29: 7500
A30: 04/04/2023 | B30: FA-B 0005-00007659 | C30: .CONSUMIDOR FINAL | D30: Consumidor Final | F30: 3884.3 | G30: 0 | H30: 0 | I30: 0 | J30: 0 | K30: 815.7 | L30: 0 | M30: 0 | N30: 4700
A31: 04/04/2023 | B31: FA-B 0005-00007660 | C31: GALLO, ANDREA | D31: Consumidor Final | E31: 32315178 | F31: 21074.38 | G31: 0 | H31: 0 | I31: 0 | J31: 0 | K31: 4425.62 | L31: 0 | M31: 0 | N31: 25500
A32: 04/04/2023 | B32: FA-B 0005-00007661 | C32: .CONSUMIDOR FINAL | D32: Consumidor Final | F32: 7727.27 | G32: 0 | H32: 0 | I32: 0 | J32: 0 | K32: 1622.73 | L32: 0 | M32: 0 | N32: 9350
A33: 04/04/2023 | B33: FA-B 0005-00007662 | C33: .CONSUMIDOR FINAL | D33: Consumidor Final | F33: 2727.27 | G33: 0 | H33: 0 | I33: 0 | J33: 0 | K33: 572.73 | L33: 0 | M33: 0 | N33: 3300
A34: 04/04/2023 | B34: FA-B 0005-00007663 | C34: .CONSUMIDOR FINAL | D34: Consumidor Final | F34: 1735.54 | G34: 0 | H34: 0 | I34: 0 | J34: 0 | K34: 364.46 | L34: 0 | M34: 0 | N34: 2100
A35: 04/04/2023 | B35: FA-B 0005-00007664 | C35: .CONSUMIDOR FINAL | D35: Consumidor Final | F35: 4132.23 | G35: 0 | H35: 0 | I35: 0 | J35: 0 | K35: 867.77 | L35: 0 | M35: 0 | N35: 5000
A36: 04/04/2023 | B36: FA-B 0005-00007665 | C36: .CONSUMIDOR FINAL | D36: Consumidor Final | F36: 2727.27 | G36: 0 | H36: 0 | I36: 0 | J36: 0 | K36: 572.73 | L36: 0 | M36: 0 | N36: 3300
A37: 04/04/2023 | B37: FA-B 0005-00007666 | C37: .CONSUMIDOR FINAL | D37: Consumidor Final | F37: 4132.23 | G37: 0 | H37: 0 | I37: 0 | J37: 0 | K37: 867.77 | L37: 0 | M37: 0 | N37: 5000
A38: 04/04/2023 | B38: FA-A 0006-00000333 | C38: Galeno Argentina Sociedad Anonima | D38: IVA Responsable Inscripto | E38: 30522428163 | F38: 297527.82 | G38: 0 | H38: 0 | I38: 0 | J38: 0 | K38: 62480.84 | L38: 0 | M38: 0 | N38: 360008.66
A39: 04/04/2023 | B39: FA-A 0006-00000334 | C39: Galeno Argentina Sociedad Anonima | D39: IVA Responsable Inscripto | E39: 30522428163 | F39: 4398512.4 | G39: 0 | H39: 0 | I39: 0 | J39: 0 | K39: 923687.6 | L39: 0 | M39: 0 | N39: 5322200
A40: 04/04/2023 | B40: NC-B 0007-00000136 | C40: Asociacion Mutual Sancor Salud | D40: IVA Sujeto Exento | E40: 30590354798 | F40: -4087.13 | G40: 0 | H40: 0 | I40: 0 | J40: 0 | K40: -858.3 | L40: 0 | M40: 0 | N40: -4945.43
A41: 04/04/2023 | B41: FA-A 0007-00001404 | C41: Galeno Argentina Sociedad Anonima | D41: IVA Responsable Inscripto | E41: 30522428163 | F41: 3681.09 | G41: 0 | H41: 0 | I41: 0 | J41: 0 | K41: 773.03 | L41: 0 | M41: 0 | N41: 4454.12
A42: 04/04/2023 | B42: FA-B 0007-00004231 | C42: COSTA, MARTA CRISTINA | D42: Consumidor Final | E42: 10093884 | F42: 3471.07 | G42: 0 | H42: 0 | I42: 0 | J42: 0 | K42: 728.93 | L42: 0 | M42: 0 | N42: 4200
...
