Workbook

Sheet IVA COMPRAS
A1: FECHA_EMI | B1: COD_PROVE | C1: NOM_PROVE | D1: COND_IVA | E1: IDENTIFTRI | F1: N_INTERNO | G1: T_COMP | H1: N_COMP | I1: N | J1: _COMP | M1: PORC_IVA | N1: IMP_EXENTO | O1: IMP_NETO | P1: IMP_IVA | Q1: IMP_TOTAL | R1: N_ING_BRU | S1: OTROSIMP
A2: 45316 | B2: GALICI | C2: BANCO DE GALICIA Y BUENOS AIRES S A U | D2: RI | E2: 30500001735 | F2: 10731 | G2: FAC | H2: A0202418403984 | I2: A | J2: 2024 | K2: 18403984 | L2: =CONCATENATE(E2,J2,K2) -> 30500001735202418403984 | M2: 21 | N2: 221.78 | O2: 1500 | P2: 315 | Q2: 2036.78 | S2: 0 | T2: =VLOOKUP(L2,'MIS COMPROBANTES'!E:Q,13,0) -> #N/A
A3: 45316 | B3: GALICI | C3: BANCO DE GALICIA Y BUENOS AIRES S A U | D3: RI | E3: 30500001735 | F3: 10732 | G3: FAC | H3: A0202418404036 | I3: A | J3: 2024 | K3: 18404036 | L3: =CONCATENATE(E3,J3,K3) -> 30500001735202418404036 | M3: 21 | N3: 322.28 | O3: 6700 | P3: 1407 | Q3: 8764.28 | S3: 134 | T3: =VLOOKUP(L3,'MIS COMPROBANTES'!E:Q,13,0) -> #N/A
A4: 45316 | B4: GALICI | C4: BANCO DE GALICIA Y BUENOS AIRES S A U | D4: RI | E4: 30500001735 | F4: 10732 | G4: FAC | H4: A0202418404036 | I4: A | J4: 2024 | K4: 18404036 | L4: =CONCATENATE(E4,J4,K4) -> 30500001735202418404036 | M4: 3 | N4: 0 | O4: 0 | P4: 201 | Q4: 0 | S4: 0 | T4: =VLOOKUP(L4,'MIS COMPROBANTES'!E:Q,13,0) -> #N/A
A5: 45320 | B5: AXION | C5: PAN AMERICAN ENERGY, S.L., SUC ARG | D5: RI | E5: 30695542476 | F5: 10680 | G5: FAC | H5: A0522400013660 | I5: A | J5: 5224 | K5: 13660 | L5: =CONCATENATE(E5,J5,K5) -> 30695542476522413660 | M5: 21 | N5: 1051.47 | O5: 33867.35 | P5: 7112.14 | Q5: 43046.98 | S5: 0 | T5: =VLOOKUP(L5,'MIS COMPROBANTES'!E:Q,13,0) -> #N/A
A6: 45320 | B6: AXION | C6: PAN AMERICAN ENERGY, S.L., SUC ARG | D6: RI | E6: 30695542476 | F6: 10680 | G6: FAC | H6: A0522400013660 | I6: A | J6: 5224 | K6: 13660 | L6: =CONCATENATE(E6,J6,K6) -> 30695542476522413660 | M6: 3 | N6: 0 | O6: 0 | P6: 1016.02 | Q6: 0 | S6: 0 | T6: =VLOOKUP(L6,'MIS COMPROBANTES'!E:Q,13,0) -> #N/A
A7: 45359 | B7: FIN | C7: FINCA DE SANTIAGO S.A. | D7: RI | E7: 30709571717 | F7: 11981 | G7: N/C | H7: A0000500000235 | I7: A | J7: 5 | K7: 235 | L7: =CONCATENATE(E7,J7,K7) -> 307095717175235 | M7: 21 | N7: 0 | O7: -80136.67 | P7: -16828.7 | Q7: -96965.37 | S7: 0 | T7: =VLOOKUP(L7,'MIS COMPROBANTES'!E:Q,13,0) -> #N/A
A8: 45365 | B8: CURVON | C8: EL CURVON SRL | D8: RI | E8: 30551016117 | F8: 12387 | G8: FAC | H8: A0000900033207 | I8: A | J8: 9 | K8: 33207 | L8: =CONCATENATE(E8,J8,K8) -> 30551016117933207 | M8: 21 | N8: 2330.98 | O8: 80717.94 | P8: 16950.77 | Q8: 99999.69 | S8: 0 | T8: =VLOOKUP(L8,'MIS COMPROBANTES'!E:Q,13,0) -> #N/A
A9: 45379 | B9: LUCANE | C9: LUCANERA ALFREDO ADOLFO | D9: RI | E9: 20055036579 | F9: 12108 | G9: FAC | H9: A0000400004709 | I9: A | J9: 4 | K9: 4709 | L9: =CONCATENATE(E9,J9,K9) -> 2005503657944709 | M9: 21 | N9: 0 | O9: 564614.12 | P9: 118568.97 | Q9: 683183.09 | S9: 0 | T9: =VLOOKUP(L9,'MIS COMPROBANTES'!E:Q,13,0) -> #N/A
A10: 45398 | B10: SAN IS | C10: SAN ISIDRO 2000 SA | D10: RI | E10: 33707901409 | F10: 12388 | G10: FAC | H10: A0000800115262 | I10: A | J10: 8 | K10: 115262 | L10: =CONCATENATE(E10,J10,K10) -> 337079014098115262 | M10: 21 | N10: 5691.63 | O10: 61411.91 | P10: 12896.5 | Q10: 80000.04 | S10: 0 | T10: =VLOOKUP(L10,'MIS COMPROBANTES'!E:Q,13,0) -> #N/A
A11: 45404 | B11: IPLAN | C11: NSS SA | D11: RI | E11: 30702652975 | F11: 12163 | G11: FAC | H11: A0000503017938 | I11: A | J11: 5 | K11: 3017938 | L11: =CONCATENATE(E11,J11,K11) -> 3070265297553017938 | M11: 21 | N11: 0 | O11: 3895.04 | P11: 817.96 | Q11: 4829.85 | S11: 116.85 | T11: =VLOOKUP(L11,'MIS COMPROBANTES'!E:Q,13,0) -> #N/A
A12: 45408 | B12: MASTEL | C12: MASTELLONE HNOS S A | D12: RI | E12: 30547242331 | F12: 12149 | G12: N/C | H12: A0616200040408 | I12: A | J12: 6162 | K12: 40408 | L12: =CONCATENATE(E12,J12,K12) -> 30547242331616240408 | M12: 21 | N12: 0 | O12: -56649.39 | P12: -11896.37 | Q12: -68545.76 | S12: 0 | T12: =VLOOKUP(L12,'MIS COMPROBANTES'!E:Q,13,0) -> #N/A
A13: 45411 | B13: RIO | C13: BANCO SANTANDER RIO | D13: RI | E13: 30500008454 | F13: 11887 | G13: FAC | H13: 00202429042024 | I13: 0 | J13: 2024 | K13: 29042024 | L13: =CONCATENATE(E13,J13,K13) -> 30500008454202429042024 | M13: 3 | N13: 0 | O13: 0 | P13: 999 | Q13: 1840 | S13: 841 | T13: =VLOOKUP(L13,'MIS COMPROBANTES'!E:Q,13,0) -> #N/A
A14: 45412 | B14: COMAFI | C14: BANCO COMAFI SOCIEDAD ANONIMA | D14: RI | E14: 30604731018 | F14: 11945 | G14: FAC | H14: 00202400300424 | I14: 0 | J14: 2024 | K14: 300424 | L14: =CONCATENATE(E14,J14,K14) -> 306047310182024300424 | M14: 10.5 | N14: 301 | O14: 24832.4 | P14: 2607.4 | Q14: 28609.93 | S14: 496.65 | T14: =VLOOKUP(L14,'MIS COMPROBANTES'!E:Q,13,0) -> #N/A
A15: 45412 | B15: COMAFI | C15: BANCO COMAFI SOCIEDAD ANONIMA | D15: RI | E15: 30604731018 | F15: 11945 | G15: FAC | H15: 00202400300424 | I15: 0 | J15: 2024 | K15: 300424 | L15: =CONCATENATE(E15,J15,K15) -> 306047310182024300424 | M15: 1.5 | N15: 0 | O15: 0 | P15: 372.48 | Q15: 0 | S15: 0 | T15: =VLOOKUP(L15,'MIS COMPROBANTES'!E:Q,13,0) -> #N/A
A16: 45412 | B16: LUCANE | C16: LUCANERA ALFREDO ADOLFO | D16: RI | E16: 20055036579 | F16: 12114 | G16: FAC | H16: A0000400004758 | I16: A | J16: 4 | K16: 4758 | L16: =CONCATENATE(E16,J16,K16) -> 2005503657944758 | M16: 21 | N16: 0 | O16: 526798.01 | P16: 110627.58 | Q16: 637425.59 | S16: 0 | T16: =VLOOKUP(L16,'MIS COMPROBANTES'!E:Q,13,0) -> #N/A
A17: 45412 | B17: MARCOS | C17: MARCOS SCHMUKLER S A | D17: RI | E17: 30552910512 | F17: 12125 | G17: N/C | H17: A0001000007634 | I17: A | J17: 10 | K17: 7634 | L17: =CONCATENATE(E17,J17,K17) -> 30552910512107634 | M17: 21 | N17: 0 | O17: -29796 | P17: -6257.16 | Q17: -37542.96 | S17: -595.92 | T17: =VLOOKUP(L17,'MIS COMPROBANTES'!E:Q,13,0) -> #N/A
A18: 45412 | B18: MARCOS | C18: MARCOS SCHMUKLER S A | D18: RI | E18: 30552910512 | F18: 12125 | G18: N/C | H18: A0001000007634 | I18: A | J18: 10 | K18: 7634 | L18: =CONCATENATE(E18,J18,K18) -> 30552910512107634 | M18: 3 | N18: 0 | O18: 0 | P18: -893.88 | Q18: 0 | S18: 0 | T18: =VLOOKUP(L18,'MIS COMPROBANTES'!E:Q,13,0) -> #N/A
A19: 45413 | B19: ANURA | C19: CITILAN ARGENTINA S.A. | D19: RI | E19: 30707135596 | F19: 11931 | G19: FAC | H19: A0000300227267 | I19: A | J19: 3 | K19: 227267 | L19: =CONCATENATE(E19,J19,K19) -> 307071355963227267 | M19: 21 | N19: 0 | O19: 82021.65 | P19: 17224.55 | Q19: 100886.63 | R19: 901-543720-4 | S19: 1640.43 | T19: =VLOOKUP(L19,'MIS COMPROBANTES'!E:Q,13,0) -> 100886.63
A20: 45413 | B20: BERKLE | C20: BERKLEY INTERNATIONAL SEGUROS S.A. | D20: RI | E20: 30500035788 | F20: 11930 | G20: FAC | H20: A0000500579401 | I20: A | J20: 5 | K20: 579401 | L20: =CONCATENATE(E20,J20,K20) -> 305000357885579401 | M20: 21 | N20: 314.53 | O20: 11536.45 | P20: 2422.65 | Q20: 14850.45 | S20: 230.73 | T20: =VLOOKUP(L20,'MIS COMPROBANTES'!E:Q,13,0) -> 14850.45
A21: 45413 | B21: BERKLE | C21: BERKLEY INTERNATIONAL SEGUROS S.A. | D21: RI | E21: 30500035788 | F21: 11930 | G21: FAC | H21: A0000500579401 | I21: A | J21: 5 | K21: 579401 | L21: =CONCATENATE(E21,J21,K21) -> 305000357885579401 | M21: 3 | N21: 0 | O21: 0 | P21: 346.09 | Q21: 0 | S21: 0 | T21: =VLOOKUP(L21,'MIS COMPROBANTES'!E:Q,13,0) -> 14850.45
A22: 45413 | B22: CLARO | C22: AMX ARGENTINA SOCIEDAD ANONIMA | D22: RI | E22: 30663288497 | F22: 11920 | G22: FAC | H22: A0132600838787 | I22: A | J22: 1326 | K22: 838787 | L22: =CONCATENATE(E22,J22,K22) -> 306632884971326838787 | M22: 21 | N22: 0 | O22: 21260 | P22: 4422.6 | Q22: 26799.6 | S22: 425.2 | T22: =VLOOKUP(L22,'MIS COMPROBANTES'!E:Q,13,0) -> 26799.6
A23: 45413 | B23: CLARO | C23: AMX ARGENTINA SOCIEDAD ANONIMA | D23: RI | E23: 30663288497 | F23: 11920 | G23: FAC | H23: A0132600838787 | I23: A | J23: 1326 | K23: 838787 | L23: =CONCATENATE(E23,J23,K23) -> 306632884971326838787 | M23: 27 | N23: 0 | O23: 0 | P23: 54 | Q23: 0 | S23: 0 | T23: =VLOOKUP(L23,'MIS COMPROBANTES'!E:Q,13,0) -> 26799.6
A24: 45413 | B24: CLARO | C24: AMX ARGENTINA SOCIEDAD ANONIMA | D24: RI | E24: 30663288497 | F24: 11920 | G24: FAC | H24: A0132600838787 | I24: A | J24: 1326 | K24: 838787 | L24: =CONCATENATE(E24,J24,K24) -> 306632884971326838787 | M24: 3 | N24: 0 | O24: 0 | P24: 637.8 | Q24: 0 | S24: 0 | T24: =VLOOKUP(L24,'MIS COMPROBANTES'!E:Q,13,0) -> 26799.6
A25: 45413 | B25: SAP | C25: Molfino Hnos SA | D25: RI | E25: 30500768262 | F25: 11889 | G25: FAC | H25: A0200200285263 | I25: A | J25: 2002 | K25: 285263 | L25: =CONCATENATE(E25,J25,K25) -> 305007682622002285263 | M25: 21 | N25: 0 | O25: 1214533.2 | P25: 255051.97 | Q25: 1566747.8 | S25: 60726.65 | T25: =VLOOKUP(L25,'MIS COMPROBANTES'!E:Q,13,0) -> 1566747.8
A26: 45413 | B26: SAP | C26: Molfino Hnos SA | D26: RI | E26: 30500768262 | F26: 11889 | G26: FAC | H26: A0200200285263 | I26: A | J26: 2002 | K26: 285263 | L26: =CONCATENATE(E26,J26,K26) -> 305007682622002285263 | M26: 3 | N26: 0 | O26: 0 | P26: 36435.99 | Q26: 0 | S26: 0 | T26: =VLOOKUP(L26,'MIS COMPROBANTES'!E:Q,13,0) -> 1566747.8
A27: 45414 | B27: LITO | C27: SANTAMARIA MOSCHETTA PASCUAL | D27: RI | E27: 20084318362 | F27: 12239 | G27: FAC | H27: A0000200000810 | I27: A | J27: 2 | K27: 810 | L27: =CONCATENATE(E27,J27,K27) -> 200843183622810 | M27: 21 | N27: 0 | O27: 768785 | P27: 161444.85 | Q27: 930229.85 | S27: 0 | T27: =VLOOKUP(L27,'MIS COMPROBANTES'!E:Q,13,0) -> 930229.85
A28: 45414 | B28: T | C28: PRODUCTOS ALIMENTICIOS TARTAGAL S R L | D28: RI | E28: 30703957478 | F28: 11660 | G28: FAC | H28: A0000300100226 | I28: A | J28: 3 | K28: 100226 | L28: =CONCATENATE(E28,J28,K28) -> 307039574783100226 | M28: 21 | N28: 0 | O28: 1158379.4 | P28: 243259.66 | Q28: 1424806.6 | S28: 23167.59 | T28: =VLOOKUP(L28,'MIS COMPROBANTES'!E:Q,13,0) -> 1424806.6
A29: 45414 | B29: T | C29: PRODUCTOS ALIMENTICIOS TARTAGAL S R L | D29: RI | E29: 30703957478 | F29: 11659 | G29: FAC | H29: A0000300100229 | I29: A | J29: 3 | K29: 100229 | L29: =CONCATENATE(E29,J29,K29) -> 307039574783100229 | M29: 21 | N29: 0 | O29: 5596510.3 | P29: 1175267.2 | Q29: 6883707.7 | S29: 111930.21 | T29: =VLOOKUP(L29,'MIS COMPROBANTES'!E:Q,13,0) -> 6883707.7
A30: 45414 | B30: FIN | C30: FINCA DE SANTIAGO S.A. | D30: RI | E30: 30709571717 | F30: 11712 | G30: FAC | H30: A0000500000951 | I30: A | J30: 5 | K30: 951 | L30: =CONCATENATE(E30,J30,K30) -> 307095717175951 | M30: 21 | N30: 0 | O30: 19433554 | P30: 4081046.3 | Q30: 23514600 | S30: 0 | T30: =VLOOKUP(L30,'MIS COMPROBANTES'!E:Q,13,0) -> 23514600
A31: 45414 | B31: LOLAPA | C31: LOLAPALUZA S.A. | D31: RI | E31: 30712175148 | F31: 11656 | G31: FAC | H31: A0000700008376 | I31: A | J31: 7 | K31: 8376 | L31: =CONCATENATE(E31,J31,K31) -> 3071217514878376 | M31: 21 | N31: 8534.98 | O31: 87990.08 | P31: 18477.92 | Q31: 115002.98 | R31: 9016591224 | S31: 0 | T31: =VLOOKUP(L31,'MIS COMPROBANTES'!E:Q,13,0) -> #N/A
A32: 45414 | B32: LAQUES | C32: CASSINI Y CESARATTO S.A. | D32: RI | E32: 30646618521 | F32: 11838 | G32: FAC | H32: A0002000152753 | I32: A | J32: 20 | K32: 152753 | L32: =CONCATENATE(E32,J32,K32) -> 3064661852120152753 | M32: 21 | N32: 0 | O32: 7450417.2 | P32: 1564587.6 | Q32: 9238517.3 | S32: 0 | T32: =VLOOKUP(L32,'MIS COMPROBANTES'!E:Q,13,0) -> 9238517.3
A33: 45414 | B33: LAQUES | C33: CASSINI Y CESARATTO S.A. | D33: RI | E33: 30646618521 | F33: 11838 | G33: FAC | H33: A0002000152753 | I33: A | J33: 20 | K33: 152753 | L33: =CONCATENATE(E33,J33,K33) -> 3064661852120152753 | M33: 3 | N33: 0 | O33: 0 | P33: 223512.51 | Q33: 0 | S33: 0 | T33: =VLOOKUP(L33,'MIS COMPROBANTES'!E:Q,13,0) -> 9238517.3
A34: 45414 | B34: CALSA | C34: COMPAÑIA ARGENTINA DE LEVADURAS S A I C | D34: RI | E34: 30532149793 | F34: 11871 | G34: FAC | H34: A0004600400220 | I34: A | J34: 46 | K34: 400220 | L34: =CONCATENATE(E34,J34,K34) -> 3053214979346400220 | M34: 21 | N34: 0 | O34: 1531572 | P34: 321630.12 | Q34: 1929780.7 | S34: 30631.44 | T34: =VLOOKUP(L34,'MIS COMPROBANTES'!E:Q,13,0) -> 1929780.7
A35: 45414 | B35: CALSA | C35: COMPAÑIA ARGENTINA DE LEVADURAS S A I C | D35: RI | E35: 30532149793 | F35: 11871 | G35: FAC | H35: A0004600400220 | I35: A | J35: 46 | K35: 400220 | L35: =CONCATENATE(E35,J35,K35) -> 3053214979346400220 | M35: 3 | N35: 0 | O35: 0 | P35: 45947.16 | Q35: 0 | S35: 0 | T35: =VLOOKUP(L35,'MIS COMPROBANTES'!E:Q,13,0) -> 1929780.7
A36: 45414 | B36: DOS | C36: COMPAÑIA INTRODUCTORA DE BUENOS AIRES S A | D36: RI | E36: 30501290323 | F36: 11841 | G36: FAC | H36: A0021800160954 | I36: A | J36: 218 | K36: 160954 | L36: =CONCATENATE(E36,J36,K36) -> 30501290323218160954 | M36: 21 | N36: 0 | O36: 132196.75 | P36: 27761.32 | Q36: 170533.81 | S36: 6609.84 | T36: =VLOOKUP(L36,'MIS COMPROBANTES'!E:Q,13,0) -> 170533.81
A37: 45414 | B37: DOS | C37: COMPAÑIA INTRODUCTORA DE BUENOS AIRES S A | D37: RI | E37: 30501290323 | F37: 11841 | G37: FAC | H37: A0021800160954 | I37: A | J37: 218 | K37: 160954 | L37: =CONCATENATE(E37,J37,K37) -> 30501290323218160954 | M37: 3 | N37: 0 | O37: 0 | P37: 3965.9 | Q37: 0 | S37: 0 | T37: =VLOOKUP(L37,'MIS COMPROBANTES'!E:Q,13,0) -> 170533.81
A38: 45414 | B38: DOS | C38: COMPAÑIA INTRODUCTORA DE BUENOS AIRES S A | D38: RI | E38: 30501290323 | F38: 11840 | G38: FAC | H38: A0021800160955 | I38: A | J38: 218 | K38: 160955 | L38: =CONCATENATE(E38,J38,K38) -> 30501290323218160955 | M38: 21 | N38: 0 | O38: 132196.75 | P38: 27761.32 | Q38: 170533.81 | S38: 6609.84 | T38: =VLOOKUP(L38,'MIS COMPROBANTES'!E:Q,13,0) -> 170533.81
A39: 45414 | B39: DOS | C39: COMPAÑIA INTRODUCTORA DE BUENOS AIRES S A | D39: RI | E39: 30501290323 | F39: 11840 | G39: FAC | H39: A0021800160955 | I39: A | J39: 218 | K39: 160955 | L39: =CONCATENATE(E39,J39,K39) -> 30501290323218160955 | M39: 3 | N39: 0 | O39: 0 | P39: 3965.9 | Q39: 0 | S39: 0 | T39: =VLOOKUP(L39,'MIS COMPROBANTES'!E:Q,13,0) -> 170533.81
A40: 45414 | B40: DOS | C40: COMPAÑIA INTRODUCTORA DE BUENOS AIRES S A | D40: RI | E40: 30501290323 | F40: 11839 | G40: FAC | H40: A0021800160956 | I40: A | J40: 218 | K40: 160956 | L40: =CONCATENATE(E40,J40,K40) -> 30501290323218160956 | M40: 21 | N40: 0 | O40: 132196.75 | P40: 27761.32 | Q40: 170533.81 | S40: 6609.84 | T40: =VLOOKUP(L40,'MIS COMPROBANTES'!E:Q,13,0) -> 170533.81
...

Sheet MIS COMPROBANTES
A1: Fecha | B1: Tipo | C1: Punto de Venta | D1: Número Desde | E1: Número Hasta | F1: Cód. Autorización | G1: Tipo Doc. Emisor | H1: Nro. Doc. Emisor | I1: Denominación Emisor | J1: Tipo Cambio | K1: Moneda | L1: Imp. Neto Gravado | M1: Imp. Neto No Gravado | N1: Imp. Op. Exentas | O1: Otros Tributos | P1: IVA | Q1: Imp. Total
A2: 06/05/2024 | B2: 1 - Factura A | C2: 3 | D2: 1377 | E2: =CONCATENATE(H2,C2,D2) -> 3071474643631377 | F2: 74196131264727 | G2: CUIT | H2: 30714746436 | I2: 3PL SRL | J2: 1 | K2: $ | L2: 712500 | M2: 0 | N2: 0 | O2: 0 | P2: 149625 | Q2: 862125 | R2: =VLOOKUP(E2,'IVA COMPRAS'!L:Q,6,0) -> 862125
A3: 06/05/2024 | B3: 1 - Factura A | C3: 3 | D3: 1378 | E3: =CONCATENATE(H3,C3,D3) -> 3071474643631378 | F3: 74196131729709 | G3: CUIT | H3: 30714746436 | I3: 3PL SRL | J3: 1 | K3: $ | L3: 2164976.4 | M3: 0 | N3: 0 | O3: 0 | P3: 454645.05 | Q3: 2619621.5 | R3: =VLOOKUP(E3,'IVA COMPRAS'!L:Q,6,0) -> 2619621.5
A4: 15/05/2024 | B4: 1 - Factura A | C4: 3 | D4: 1393 | E4: =CONCATENATE(H4,C4,D4) -> 3071474643631393 | F4: 74216645832652 | G4: CUIT | H4: 30714746436 | I4: 3PL SRL | J4: 1 | K4: $ | L4: 22340591 | M4: 0 | N4: 0 | O4: 0 | P4: 4691524.2 | Q4: 27032115 | R4: =VLOOKUP(E4,'IVA COMPRAS'!L:Q,6,0) -> 27032115
A5: 06/05/2024 | B5: 1 - Factura A | C5: 1 | D5: 471 | E5: =CONCATENATE(H5,C5,D5) -> 337177102291471 | F5: 74199160741030 | G5: CUIT | H5: 33717710229 | I5: ACEITERA GERASOLES S.A. | J5: 1 | K5: $ | L5: 1420000 | M5: 0 | N5: 0 | O5: 0 | P5: 298200 | Q5: 1718200 | R5: =VLOOKUP(E5,'IVA COMPRAS'!L:Q,6,0) -> 1718200
A6: 13/05/2024 | B6: 1 - Factura A | C6: 1 | D6: 487 | E6: =CONCATENATE(H6,C6,D6) -> 337177102291487 | F6: 74209932372777 | G6: CUIT | H6: 33717710229 | I6: ACEITERA GERASOLES S.A. | J6: 1 | K6: $ | L6: 4500000 | M6: 0 | N6: 0 | O6: 0 | P6: 945000 | Q6: 5445000 | R6: =VLOOKUP(E6,'IVA COMPRAS'!L:Q,6,0) -> 5445000
A7: 31/05/2024 | B7: 1 - Factura A | C7: 1 | D7: 519 | E7: =CONCATENATE(H7,C7,D7) -> 337177102291519 | F7: 74229910571889 | G7: CUIT | H7: 33717710229 | I7: ACEITERA GERASOLES S.A. | J7: 1 | K7: $ | L7: 12090000 | M7: 0 | N7: 0 | O7: 0 | P7: 2538900 | Q7: 14628900 | R7: =VLOOKUP(E7,'IVA COMPRAS'!L:Q,6,0) -> 14628900
A8: 31/05/2024 | B8: 11 - Factura C | C8: 1 | D8: 10 | E8: =CONCATENATE(H8,C8,D8) -> 27321077299110 | F8: 74229868791859 | G8: CUIT | H8: 27321077299 | I8: ALVAREZ GABRIELA ANALIA | J8: 1 | K8: $ | O8: 0 | Q8: 580000 | R8: =VLOOKUP(E8,'IVA COMPRAS'!L:Q,6,0) -> 580000
A9: 01/05/2024 | B9: 1 - Factura A | C9: 1326 | D9: 838787 | E9: =CONCATENATE(H9,C9,D9) -> 306632884971326838787 | F9: 74187738343095 | G9: CUIT | H9: 30663288497 | I9: AMX ARGENTINA SOCIEDAD ANONIMA | J9: 1 | K9: $ | L9: 21260 | M9: 0 | N9: 0 | O9: 0 | P9: 4476.6 | Q9: 26799.6 | R9: =VLOOKUP(E9,'IVA COMPRAS'!L:Q,6,0) -> 26799.6
A10: 06/05/2024 | B10: 11 - Factura C | C10: 1 | D10: 30 | E10: =CONCATENATE(H10,C10,D10) -> 20345349600130 | F10: 74190167783128 | G10: CUIT | H10: 20345349600 | I10: ARGÜELLO LUIS MIGUEL | J10: 1 | K10: $ | O10: 0 | Q10: 750900 | R10: =VLOOKUP(E10,'IVA COMPRAS'!L:Q,6,0) -> 750900
A11: 06/05/2024 | B11: 1 - Factura A | C11: 14 | D11: 15688 | E11: =CONCATENATE(H11,C11,D11) -> 335405454191415688 | F11: 74199170390552 | G11: CUIT | H11: 33540545419 | I11: ARMANDO J RIOS S ACIF | J11: 1 | K11: $ | L11: 13500 | M11: 0 | N11: 0 | O11: 0 | P11: 2835 | Q11: 16740 | R11: =VLOOKUP(E11,'IVA COMPRAS'!L:Q,6,0) -> #N/A
A12: 06/05/2024 | B12: 3 - Nota de Crédito A | C12: 14 | D12: 1475 | E12: =CONCATENATE(H12,C12,D12) -> 33540545419141475 | F12: 74199170624991 | G12: CUIT | H12: 33540545419 | I12: ARMANDO J RIOS S ACIF | J12: 1 | K12: $ | L12: 13500 | M12: 0 | N12: 0 | O12: 0 | P12: 2835 | Q12: -16740 | R12: =VLOOKUP(E12,'IVA COMPRAS'!L:Q,6,0) -> #N/A
A13: 31/05/2024 | B13: 1 - Factura A | C13: 50 | D13: 3642257 | E13: =CONCATENATE(H13,C13,D13) -> 30714112836503642257 | F13: 74226025316646 | G13: CUIT | H13: 30714112836 | I13: AUTOPISTAS DE BUENOS AIRES (AUBASA) SA | J13: 1 | K13: $ | L13: 11417.35 | M13: 0 | N13: 0 | O13: 0 | P13: 2397.65 | Q13: 14728.39 | R13: =VLOOKUP(E13,'IVA COMPRAS'!L:Q,6,0) -> 14728.39
A14: 31/05/2024 | B14: 1 - Factura A | C14: 50 | D14: 3641532 | E14: =CONCATENATE(H14,C14,D14) -> 30714112836503641532 | F14: 74226025268654 | G14: CUIT | H14: 30714112836 | I14: AUTOPISTAS DE BUENOS AIRES (AUBASA) SA | J14: 1 | K14: $ | L14: 9351.24 | M14: 0 | N14: 0 | O14: 0 | P14: 1963.76 | Q14: 12063.11 | R14: =VLOOKUP(E14,'IVA COMPRAS'!L:Q,6,0) -> 12063.11
A15: 03/05/2024 | B15: 1 - Factura A | C15: 711 | D15: 5666700 | E15: =CONCATENATE(H15,C15,D15) -> 306772371197115666700 | F15: 34179735526070 | G15: CUIT | H15: 30677237119 | I15: AUTOPISTAS DEL SOL S A | J15: 1 | K15: $ | L15: 34008.05 | M15: 0 | N15: 1020.24 | O15: 0 | P15: 7141.95 | Q15: 43870.64 | R15: =VLOOKUP(E15,'IVA COMPRAS'!L:Q,6,0) -> 43870.64
A16: 03/05/2024 | B16: 1 - Factura A | C16: 711 | D16: 5662018 | E16: =CONCATENATE(H16,C16,D16) -> 306772371197115662018 | F16: 34179735526070 | G16: CUIT | H16: 30677237119 | I16: AUTOPISTAS DEL SOL S A | J16: 1 | K16: $ | L16: 7272.63 | M16: 0 | N16: 218.18 | O16: 0 | P16: 1527.37 | Q16: 9381.81 | R16: =VLOOKUP(E16,'IVA COMPRAS'!L:Q,6,0) -> 9381.81
A17: 03/05/2024 | B17: 1 - Factura A | C17: 711 | D17: 5664894 | E17: =CONCATENATE(H17,C17,D17) -> 306772371197115664894 | F17: 34179735526070 | G17: CUIT | H17: 30677237119 | I17: AUTOPISTAS DEL SOL S A | J17: 1 | K17: $ | L17: 21900.76 | M17: 0 | N17: 657.02 | O17: 0 | P17: 4599.24 | Q17: 28252.06 | R17: =VLOOKUP(E17,'IVA COMPRAS'!L:Q,6,0) -> 28252.06
A18: 17/05/2024 | B18: 1 - Factura A | C18: 711 | D18: 5722790 | E18: =CONCATENATE(H18,C18,D18) -> 306772371197115722790 | F18: 34209924038028 | G18: CUIT | H18: 30677237119 | I18: AUTOPISTAS DEL SOL S A | J18: 1 | K18: $ | L18: 24958.58 | M18: 0 | N18: 748.76 | O18: 0 | P18: 5241.42 | Q18: 32196.69 | R18: =VLOOKUP(E18,'IVA COMPRAS'!L:Q,6,0) -> 32196.69
A19: 17/05/2024 | B19: 1 - Factura A | C19: 711 | D19: 5720986 | E19: =CONCATENATE(H19,C19,D19) -> 306772371197115720986 | F19: 34209924038028 | G19: CUIT | H19: 30677237119 | I19: AUTOPISTAS DEL SOL S A | J19: 1 | K19: $ | L19: 21322.32 | M19: 0 | N19: 639.67 | O19: 0 | P19: 4477.68 | Q19: 27505.79 | R19: =VLOOKUP(E19,'IVA COMPRAS'!L:Q,6,0) -> 27505.79
A20: 17/05/2024 | B20: 1 - Factura A | C20: 711 | D20: 5718133 | E20: =CONCATENATE(H20,C20,D20) -> 306772371197115718133 | F20: 34209924038028 | G20: CUIT | H20: 30677237119 | I20: AUTOPISTAS DEL SOL S A | J20: 1 | K20: $ | L20: 5619.76 | M20: 0 | N20: 168.59 | O20: 0 | P20: 1180.24 | Q20: 7249.58 | R20: =VLOOKUP(E20,'IVA COMPRAS'!L:Q,6,0) -> 7249.58
A21: 02/05/2024 | B21: 1 - Factura A | C21: 5014 | D21: 610338 | E21: =CONCATENATE(H21,C21,D21) -> 305748764745014610338 | F21: 74184683189884 | G21: CUIT | H21: 30574876474 | I21: AUTOPISTAS URBANAS S A | J21: 1 | K21: $ | L21: 6742.88 | M21: 0 | N21: 0 | O21: 0 | P21: 1416 | Q21: 9035.46 | R21: =VLOOKUP(E21,'IVA COMPRAS'!L:Q,6,0) -> 9035.46
A22: 02/05/2024 | B22: 1 - Factura A | C22: 5011 | D22: 612383 | E22: =CONCATENATE(H22,C22,D22) -> 305748764745011612383 | F22: 74184670330200 | G22: CUIT | H22: 30574876474 | I22: AUTOPISTAS URBANAS S A | J22: 1 | K22: $ | L22: 23900.53 | M22: 0 | N22: 0 | O22: 0 | P22: 5019.08 | Q22: 32026.67 | R22: =VLOOKUP(E22,'IVA COMPRAS'!L:Q,6,0) -> 32026.68
... A52: 01/05/2024 | B52: 1 - Factura A | C52: 5 | D52: 579401 | E52: =CONCATENATE(H52,C52,D52) -> 305000357885579401 | F52: 74188605011421 | G52: CUIT | H52: 30500035788 | I52: BERKLEY INTERNATIONAL SEGUROS S.A. | J52: 1 | K52: $ | L52: 14850.45 | M52: 302.99 | N52: 0 | O52: 0 | P52: 3118.59 | Q52: 14850.45 | R52: =VLOOKUP(E52,'IVA COMPRAS'!L:Q,6,0) -> 14850.45
A53: 02/05/2024 | B53: 11 - Factura C | C53: 1 | D53: 32 | E53: =CONCATENATE(H53,C53,D53) -> 27444490204132 | F53: 74184715717287 | G53: CUIT | H53: 27444490204 | I53: BOTINDARI MARIA MERCEDES | J53: 1 | K53: $ | O53: 0 | Q53: 270000 | R53: =VLOOKUP(E53,'IVA COMPRAS'!L:Q,6,0) -> 270000
A54: 03/05/2024 | B54: 1 - Factura A | C54: 3 | D54: 2239 | E54: =CONCATENATE(H54,C54,D54) -> 3071519599932239 | F54: 74189838483963 | G54: CUIT | H54: 30715195999 | I54: BUCKINGHAM S.R.L. | J54: 1 | K54: $ | L54: 289179.7 | M54: 0 | N54: 0 | O54: 0 | P54: 60727.74 | Q54: 349907.44 | R54: =VLOOKUP(E54,'IVA COMPRAS'!L:Q,6,0) -> 349907.44
A55: 03/05/2024 | B55: 1 - Factura A | C55: 2009 | D55: 37406 | E55: =CONCATENATE(H55,C55,D55) -> 30700869918200937406 | F55: 74188907600135 | G55: CUIT | H55: 30700869918 | I55: BUNGE ARGENTINA S A | J55: 1 | K55: $ | L55: 4860000 | M55: 0 | N55: 0 | O55: 0 | P55: 1020600 | Q55: 6269400 | R55: =VLOOKUP(E55,'IVA COMPRAS'!L:Q,6,0) -> 6269400
A56: 03/05/2024 | B56: 1 - Factura A | C56: 2009 | D56: 37407 | E56: =CONCATENATE(H56,C56,D56) -> 30700869918200937407 | F56: 74188907607674 | G56: CUIT | H56: 30700869918 | I56: BUNGE ARGENTINA S A | J56: 1 | K56: $ | L56: 12636000 | M56: 0 | N56: 0 | O56: 0 | P56: 2653560 | Q56: 16300440 | R56: =VLOOKUP(E56,'IVA COMPRAS'!L:Q,6,0) -> 16300440
A57: 03/05/2024 | B57: 1 - Factura A | C57: 2009 | D57: 37405 | E57: =CONCATENATE(H57,C57,D57) -> 30700869918200937405 | F57: 74188907592467 | G57: CUIT | H57: 30700869918 | I57: BUNGE ARGENTINA S A | J57: 1 | K57: $ | L57: 1095600 | M57: 0 | N57: 0 | O57: 0 | P57: 230076 | Q57: 1413324 | R57: =VLOOKUP(E57,'IVA COMPRAS'!L:Q,6,0) -> 1413324
A58: 08/05/2024 | B58: 1 - Factura A | C58: 2009 | D58: 37599 | E58: =CONCATENATE(H58,C58,D58) -> 30700869918200937599 | F58: 74198445630957 | G58: CUIT | H58: 30700869918 | I58: BUNGE ARGENTINA S A | J58: 1 | K58: $ | L58: 5478000 | M58: 0 | N58: 0 | O58: 0 | P58: 1150380 | Q58: 7066620 | R58: =VLOOKUP(E58,'IVA COMPRAS'!L:Q,6,0) -> 7066620
A59: 08/05/2024 | B59: 1 - Factura A | C59: 2009 | D59: 37600 | E59: =CONCATENATE(H59,C59,D59) -> 30700869918200937600 | F59: 74198445639278 | G59: CUIT | H59: 30700869918 | I59: BUNGE ARGENTINA S A | J59: 1 | K59: $ | L59: 8800000 | M59: 0 | N59: 0 | O59: 0 | P59: 1848000 | Q59: 11352000 | R59: =VLOOKUP(E59,'IVA COMPRAS'!L:Q,6,0) -> 11352000
A60: 22/05/2024 | B60: 1 - Factura A | C60: 2009 | D60: 38027 | E60: =CONCATENATE(H60,C60,D60) -> 30700869918200938027 | F60: 74218948224045 | G60: CUIT | H60: 30700869918 | I60: BUNGE ARGENTINA S A | J60: 1 | K60: $ | L60: 10560000 | M60: 0 | N60: 0 | O60: 0 | P60: 2217600 | Q60: 13622400 | R60: =VLOOKUP(E60,'IVA COMPRAS'!L:Q,6,0) -> 13622400
A61: 22/05/2024 | B61: 1 - Factura A | C61: 2009 | D61: 38025 | E61: =CONCATENATE(H61,C61,D61) -> 30700869918200938025 | F61: 74218948207526 | G61: CUIT | H61: 30700869918 | I61: BUNGE ARGENTINA S A | J61: 1 | K61: $ | L61: 3286800 | M61: 0 | N61: 0 | O61: 0 | P61: 690228 | Q61: 4239972 | R61: =VLOOKUP(E61,'IVA COMPRAS'!L:Q,6,0) -> 4239972
A62: 22/05/2024 | B62: 1 - Factura A | C62: 2009 | D62: 38026 | E62: =CONCATENATE(H62,C62,D62) -> 30700869918200938026 | F62: 74218948217553 | G62: CUIT | H62: 30700869918 | I62: BUNGE ARGENTINA S A | J62: 1 | K62: $ | L62: 3286800 | M62: 0 | N62: 0 | O62: 0 | P62: 690228 | Q62: 4239972 | R62: =VLOOKUP(E62,'IVA COMPRAS'!L:Q,6,0) -> 4239972
A63: 24/05/2024 | B63: 1 - Factura A | C63: 2009 | D63: 38114 | E63: =CONCATENATE(H63,C63,D63) -> 30700869918200938114 | F63: 74218230154494 | G63: CUIT | H63: 30700869918 | I63: BUNGE ARGENTINA S A | J63: 1 | K63: $ | L63: 10824000 | M63: 0 | N63: 0 | O63: 0 | P63: 2273040 | Q63: 13962960 | R63: =VLOOKUP(E63,'IVA COMPRAS'!L:Q,6,0) -> 13962960
A64: 29/05/2024 | B64: 1 - Factura A | C64: 1411 | D64: 6735 | E64: =CONCATENATE(H64,C64,D64) -> 3053774574214116735 | F64: 74222631605390 | G64: CUIT | H64: 30537745742 | I64: CABRALES SA | J64: 1 | K64: $ | L64: 149747.62 | O64: 0 | P64: 31447 | Q64: 188681.99 | R64: =VLOOKUP(E64,'IVA COMPRAS'!L:Q,6,0) -> 188681.99
A65: 14/05/2024 | B65: 1 - Factura A | C65: 1 | D65: 863 | E65: =CONCATENATE(H65,C65,D65) -> 272808246451863 | F65: 74205011423268 | G65: CUIT | H65: 27280824645 | I65: CALDERON ELIZABET LAURA | J65: 1 | K65: $ | L65: 4416000 | M65: 0 | N65: 0 | O65: 0 | P65: 927360 | Q65: 5343360 | R65: =VLOOKUP(E65,'IVA COMPRAS'!L:Q,6,0) -> 5343360
A66: 03/05/2024 | B66: 1 - Factura A | C66: 539 | D66: 40432 | E66: =CONCATENATE(H66,C66,D66) -> 3066319759953940432 | F66: 74189830777640 | G66: CUIT | H66: 30663197599 | I66: CAMPO AUSTRAL SA | J66: 1 | K66: $ | L66: 549623.29 | O66: 0 | P66: 115420.89 | Q66: 676036.65 | R66: =VLOOKUP(E66,'IVA COMPRAS'!L:Q,6,0) -> 676036.66
A67: 10/05/2024 | B67: 1 - Factura A | C67: 539 | D67: 40564 | E67: =CONCATENATE(H67,C67,D67) -> 3066319759953940564 | F67: 74199626279533 | G67: CUIT | H67: 30663197599 | I67: CAMPO AUSTRAL SA | J67: 1 | K67: $ | L67: 757721.9 | O67: 0 | P67: 159121.6 | Q67: 931997.94 | R67: =VLOOKUP(E67,'IVA COMPRAS'!L:Q,6,0) -> 931997.93
A68: 17/05/2024 | B68: 1 - Factura A | C68: 539 | D68: 40730 | E68: =CONCATENATE(H68,C68,D68) -> 3066319759953940730 | F68: 74209432538039 | G68: CUIT | H68: 30663197599 | I68: CAMPO AUSTRAL SA | J68: 1 | K68: $ | L68: 951634.95 | O68: 0 | P68: 199843.34 | Q68: 1170511 | R68: =VLOOKUP(E68,'IVA COMPRAS'!L:Q,6,0) -> 1170511
A69: 27/05/2024 | B69: 1 - Factura A | C69: 539 | D69: 40950 | E69: =CONCATENATE(H69,C69,D69) -> 3066319759953940950 | F69: 74229420243823 | G69: CUIT | H69: 30663197599 | I69: CAMPO AUSTRAL SA | J69: 1 | K69: $ | L69: 759763.48 | O69: 0 | P69: 159550.33 | Q69: 934509.06 | R69: =VLOOKUP(E69,'IVA COMPRAS'!L:Q,6,0) -> 934509.08
...

Sheet Hoja3
