Workbook

Sheet IVA COMPRAS
A1: FECHA_EMI | B1: COD_PROVE | C1: NOM_PROVE | D1: COND_IVA | E1: IDENTIFTRI | F1: N_INTERNO | G1: T_COMP | H1: N_COMP | I1: =MID(H1,2,5) -> _COMP | J1: =RIGHT(H1,8) -> N_COMP | K1: GUIA | L1: PORC_IVA | M1: IMP_EXENTO | N1: IMP_NETO | O1: IMP_IVA | P1: IMP_TOTAL | Q1: N_ING_BRU | R1: OTROSIMP
A2: 45322 | B2: RIO | C2: BANCO SANTANDER RIO | D2: RI | E2: 30500008454 | F2: 12654 | G2: FAC | H2: 00202431012024 | I2: 2024 | J2: 31012024 | K2: =CONCATENATE(E2,I2,J2) -> 30500008454202431012024 | L2: 21 | M2: 259 | N2: 47077.28 | O2: 3586.17 | P2: 54672.48 | R2: 600.01 | S2: =VLOOKUP(K2,'MIS COMPROBANTES'!E:Q,13,FALSE) -> #N/A
A3: 45322 | B3: RIO | C3: BANCO SANTANDER RIO | D3: RI | E3: 30500008454 | F3: 12654 | G3: FAC | H3: 00202431012024 | I3: 2024 | J3: 31012024 | K3: =CONCATENATE(E3,I3,J3) -> 30500008454202431012024 | L3: 10.5 | M3: 0 | N3: 0 | O3: 3150.02 | P3: 0 | R3: 0 | S3: =VLOOKUP(K3,'MIS COMPROBANTES'!E:Q,13,FALSE) -> #N/A
A4: 45322 | B4: COMAFI | C4: BANCO COMAFI SOCIEDAD ANONIMA | D4: RI | E4: 30604731018 | F4: 12655 | G4: FAC | H4: 00202431012024 | I4: 2024 | J4: 31012024 | K4: =CONCATENATE(E4,I4,J4) -> 30604731018202431012024 | L4: 21 | M4: 259 | N4: 47077.28 | O4: 3586.17 | P4: 54672.48 | R4: 600.01 | S4: =VLOOKUP(K4,'MIS COMPROBANTES'!E:Q,13,FALSE) -> #N/A
A5: 45322 | B5: COMAFI | C5: BANCO COMAFI SOCIEDAD ANONIMA | D5: RI | E5: 30604731018 | F5: 12655 | G5: FAC | H5: 00202431012024 | I5: 2024 | J5: 31012024 | K5: =CONCATENATE(E5,I5,J5) -> 30604731018202431012024 | L5: 10.5 | M5: 0 | N5: 0 | O5: 3150.02 | P5: 0 | R5: 0 | S5: =VLOOKUP(K5,'MIS COMPROBANTES'!E:Q,13,FALSE) -> #N/A
A6: 45415 | B6: QUESER | C6: QUESERIA Y FIAMBRERIA DON ANGEL S.A. | D6: RI | E6: 30711758034 | F6: 12710 | G6: FAC | H6: A0001000022865 | I6: 10 | J6: 22865 | K6: =CONCATENATE(E6,I6,J6) -> 307117580341022865 | L6: 21 | M6: 0 | N6: 34736.88 | O6: 2463.61 | P6: 40310.79 | R6: 694.73 | S6: =VLOOKUP(K6,'MIS COMPROBANTES'!E:Q,13,FALSE) -> #N/A
A7: 45415 | B7: QUESER | C7: QUESERIA Y FIAMBRERIA DON ANGEL S.A. | D7: RI | E7: 30711758034 | F7: 12710 | G7: FAC | H7: A0001000022865 | I7: 10 | J7: 22865 | K7: =CONCATENATE(E7,I7,J7) -> 307117580341022865 | L7: 10.5 | M7: 0 | N7: 0 | O7: 2415.57 | P7: 0 | R7: 0 | S7: =VLOOKUP(K7,'MIS COMPROBANTES'!E:Q,13,FALSE) -> #N/A
A8: 45421 | B8: QUESER | C8: QUESERIA Y FIAMBRERIA DON ANGEL S.A. | D8: RI | E8: 30711758034 | F8: 12712 | G8: FAC | H8: A0001000023031 | I8: 10 | J8: 23031 | K8: =CONCATENATE(E8,I8,J8) -> 307117580341023031 | L8: 21 | M8: 0 | N8: 41724.12 | O8: 4731.97 | P8: 49305.62 | R8: 834.48 | S8: =VLOOKUP(K8,'MIS COMPROBANTES'!E:Q,13,FALSE) -> #N/A
A9: 45421 | B9: QUESER | C9: QUESERIA Y FIAMBRERIA DON ANGEL S.A. | D9: RI | E9: 30711758034 | F9: 12712 | G9: FAC | H9: A0001000023031 | I9: 10 | J9: 23031 | K9: =CONCATENATE(E9,I9,J9) -> 307117580341023031 | L9: 10.5 | M9: 0 | N9: 0 | O9: 2015.05 | P9: 0 | R9: 0 | S9: =VLOOKUP(K9,'MIS COMPROBANTES'!E:Q,13,FALSE) -> #N/A
A10: 45426 | B10: QUESER | C10: QUESERIA Y FIAMBRERIA DON ANGEL S.A. | D10: RI | E10: 30711758034 | F10: 12713 | G10: FAC | H10: A0001000023189 | I10: 10 | J10: 23189 | K10: =CONCATENATE(E10,I10,J10) -> 307117580341023189 | L10: 21 | M10: 0 | N10: 28160.06 | O10: 2465.17 | P10: 32912.65 | R10: 563.2 | S10: =VLOOKUP(K10,'MIS COMPROBANTES'!E:Q,13,FALSE) -> #N/A
A11: 45426 | B11: QUESER | C11: QUESERIA Y FIAMBRERIA DON ANGEL S.A. | D11: RI | E11: 30711758034 | F11: 12713 | G11: FAC | H11: A0001000023189 | I11: 10 | J11: 23189 | K11: =CONCATENATE(E11,I11,J11) -> 307117580341023189 | L11: 10.5 | M11: 0 | N11: 0 | O11: 1724.22 | P11: 0 | R11: 0 | S11: =VLOOKUP(K11,'MIS COMPROBANTES'!E:Q,13,FALSE) -> #N/A
A12: 45428 | B12: QUESER | C12: QUESERIA Y FIAMBRERIA DON ANGEL S.A. | D12: RI | E12: 30711758034 | F12: 12711 | G12: FAC | H12: A0001000023258 | I12: 10 | J12: 23258 | K12: =CONCATENATE(E12,I12,J12) -> 307117580341023258 | L12: 21 | M12: 0 | N12: 17269.15 | O12: 1166.01 | P12: 20010.8 | R12: 345.38 | S12: =VLOOKUP(K12,'MIS COMPROBANTES'!E:Q,13,FALSE) -> #N/A
A13: 45428 | B13: QUESER | C13: QUESERIA Y FIAMBRERIA DON ANGEL S.A. | D13: RI | E13: 30711758034 | F13: 12711 | G13: FAC | H13: A0001000023258 | I13: 10 | J13: 23258 | K13: =CONCATENATE(E13,I13,J13) -> 307117580341023258 | L13: 10.5 | M13: 0 | N13: 0 | O13: 1230.26 | P13: 0 | R13: 0 | S13: =VLOOKUP(K13,'MIS COMPROBANTES'!E:Q,13,FALSE) -> #N/A
... A15: 45442 | B15: TREGAR | C15: GARCIA HERMANOS AGROINDUSTRIAL SRL | D15: RI | E15: 30566108352 | F15: 12705 | G15: N/C | H15: A0013500224140 | I15: 135 | J15: 224140 | K15: =CONCATENATE(E15,I15,J15) -> 30566108352135224140 | L15: 21 | M15: 0 | N15: -143592.73 | O15: -30154.47 | P15: -173747.2 | R15: 0 | S15: =VLOOKUP(K15,'MIS COMPROBANTES'!E:Q,13,FALSE) -> #N/A
A16: 45444 | B16: ANURA | C16: CITILAN ARGENTINA S.A. | D16: RI | E16: 30707135596 | F16: 12671 | G16: FAC | H16: A0000300228947 | I16: 3 | J16: 228947 | K16: =CONCATENATE(E16,I16,J16) -> 307071355963228947 | L16: 21 | M16: 0 | N16: 82978.84 | O16: 17425.56 | P16: 102063.98 | Q16: 901-543720-4 | R16: 1659.58 | S16: =VLOOKUP(K16,'MIS COMPROBANTES'!E:Q,13,FALSE) -> 102063.98
A17: 45444 | B17: ZURICH | C17: ZURICH ASEGURADORA ARGENTINA S.A | D17: RI | E17: 30500036393 | F17: 12790 | G17: FAC | H17: A0000400285921 | I17: 4 | J17: 285921 | K17: =CONCATENATE(E17,I17,J17) -> 305000363934285921 | L17: 21 | M17: 70179.77 | N17: 1867931.5 | O17: 392265.61 | P17: 2423773.4 | R17: 37358.63 | S17: =VLOOKUP(K17,'MIS COMPROBANTES'!E:Q,13,FALSE) -> #N/A
A18: 45444 | B18: ZURICH | C18: ZURICH ASEGURADORA ARGENTINA S.A | D18: RI | E18: 30500036393 | F18: 12790 | G18: FAC | H18: A0000400285921 | I18: 4 | J18: 285921 | K18: =CONCATENATE(E18,I18,J18) -> 305000363934285921 | L18: 3 | M18: 0 | N18: 0 | O18: 56037.94 | P18: 0 | R18: 0 | S18: =VLOOKUP(K18,'MIS COMPROBANTES'!E:Q,13,FALSE) -> #N/A
A19: 45444 | B19: VERO | C19: VERONICA S.A.C.I.A.F.e.I. | D19: RI | E19: 30500979824 | F19: 12263 | G19: FAC | H19: A0004300297442 | I19: 43 | J19: 297442 | K19: =CONCATENATE(E19,I19,J19) -> 3050097982443297442 | L19: 21 | M19: 0 | N19: 1441217.3 | O19: 302655.64 | P19: 1851964.3 | Q19: 30-50097982-4 | R19: 64854.78 | S19: =VLOOKUP(K19,'MIS COMPROBANTES'!E:Q,13,FALSE) -> 1851964.3
A20: 45444 | B20: VERO | C20: VERONICA S.A.C.I.A.F.e.I. | D20: RI | E20: 30500979824 | F20: 12263 | G20: FAC | H20: A0004300297442 | I20: 43 | J20: 297442 | K20: =CONCATENATE(E20,I20,J20) -> 3050097982443297442 | L20: 3 | M20: 0 | N20: 0 | O20: 43236.52 | P20: 0 | Q20: 30-50097982-4 | R20: 0 | S20: =VLOOKUP(K20,'MIS COMPROBANTES'!E:Q,13,FALSE) -> 1851964.3
A21: 45444 | B21: MIL | C21: MILKAUT S.A. | D21: RI | E21: 30682032630 | F21: 12264 | G21: FAC | H21: A0062200283753 | I21: 622 | J21: 283753 | K21: =CONCATENATE(E21,I21,J21) -> 30682032630622283753 | L21: 21 | M21: 0 | N21: 1533727.1 | O21: 322082.7 | P21: 1970839.4 | R21: 69017.72 | S21: =VLOOKUP(K21,'MIS COMPROBANTES'!E:Q,13,FALSE) -> 1970839.4
A22: 45444 | B22: MIL | C22: MILKAUT S.A. | D22: RI | E22: 30682032630 | F22: 12264 | G22: FAC | H22: A0062200283753 | I22: 622 | J22: 283753 | K22: =CONCATENATE(E22,I22,J22) -> 30682032630622283753 | L22: 3 | M22: 0 | N22: 0 | O22: 46011.81 | P22: 0 | R22: 0 | S22: =VLOOKUP(K22,'MIS COMPROBANTES'!E:Q,13,FALSE) -> 1970839.4
A23: 45444 | B23: CLARO | C23: AMX ARGENTINA SOCIEDAD ANONIMA | D23: RI | E23: 30663288497 | F23: 12663 | G23: FAC | H23: A0132601005423 | I23: 1326 | J23: 1005423 | K23: =CONCATENATE(E23,I23,J23) -> 3066328849713261005423 | L23: 21 | M23: 0 | N23: 23510 | O23: 4895.1 | P23: 29634.6 | R23: 470.2 | S23: =VLOOKUP(K23,'MIS COMPROBANTES'!E:Q,13,FALSE) -> 29634.6
A24: 45444 | B24: CLARO | C24: AMX ARGENTINA SOCIEDAD ANONIMA | D24: RI | E24: 30663288497 | F24: 12663 | G24: FAC | H24: A0132601005423 | I24: 1326 | J24: 1005423 | K24: =CONCATENATE(E24,I24,J24) -> 3066328849713261005423 | L24: 27 | M24: 0 | N24: 0 | O24: 54 | P24: 0 | R24: 0 | S24: =VLOOKUP(K24,'MIS COMPROBANTES'!E:Q,13,FALSE) -> 29634.6
A25: 45444 | B25: CLARO | C25: AMX ARGENTINA SOCIEDAD ANONIMA | D25: RI | E25: 30663288497 | F25: 12663 | G25: FAC | H25: A0132601005423 | I25: 1326 | J25: 1005423 | K25: =CONCATENATE(E25,I25,J25) -> 3066328849713261005423 | L25: 3 | M25: 0 | N25: 0 | O25: 705.3 | P25: 0 | R25: 0 | S25: =VLOOKUP(K25,'MIS COMPROBANTES'!E:Q,13,FALSE) -> 29634.6
A26: 45444 | B26: BUN | C26: BUNGE ARGENTINA S.A. | D26: RI | E26: 30700869918 | F26: 12158 | G26: N/C | H26: A0200900006273 | I26: 2009 | J26: 6273 | K26: =CONCATENATE(E26,I26,J26) -> 3070086991820096273 | L26: 21 | M26: 0 | N26: -164000 | O26: -34440 | P26: -198440 | R26: 0 | S26: =VLOOKUP(K26,'MIS COMPROBANTES'!E:Q,13,FALSE) -> 198440
A27: 45444 | B27: MASTEL | C27: MASTELLONE HNOS S A | D27: RI | E27: 30547242331 | F27: 11279 | G27: N/C | H27: A0615602449724 | I27: 6156 | J27: 2449724 | K27: =CONCATENATE(E27,I27,J27) -> 3054724233161562449724 | L27: 21 | M27: 0 | N27: -1439.7 | O27: -302.34 | P27: -1742.04 | R27: 0 | S27: =VLOOKUP(K27,'MIS COMPROBANTES'!E:Q,13,FALSE) -> #N/A
A28: 45445 | B28: OMINT | C28: OMINT S.A. | D28: RI | E28: 30550245309 | F28: 12335 | G28: FAC | H28: A0002101125131 | I28: 21 | J28: 1125131 | K28: =CONCATENATE(E28,I28,J28) -> 30550245309211125131 | L28: 10.5 | M28: 0 | N28: 2226154.6 | O28: 233600.24 | P28: 2560223.8 | R28: 100176.96 | S28: =VLOOKUP(K28,'MIS COMPROBANTES'!E:Q,13,FALSE) -> 2560223.8
A29: 45445 | B29: OMINT | C29: OMINT S.A. | D29: RI | E29: 30550245309 | F29: 12335 | G29: FAC | H29: A0002101125131 | I29: 21 | J29: 1125131 | K29: =CONCATENATE(E29,I29,J29) -> 30550245309211125131 | L29: 21 | M29: 0 | N29: 0 | O29: 292 | P29: 0 | R29: 0 | S29: =VLOOKUP(K29,'MIS COMPROBANTES'!E:Q,13,FALSE) -> 2560223.8
A30: 45446 | B30: RIO | C30: BANCO SANTANDER RIO | D30: RI | E30: 30500008454 | F30: 12652 | G30: FAC | H30: 00202410102094 | I30: 2024 | J30: 10102094 | K30: =CONCATENATE(E30,I30,J30) -> 30500008454202410102094 | L30: 10.5 | M30: 21732102 | N30: 1249313.3 | O30: 131177.89 | P30: 23156319 | R30: 24986.27 | S30: =VLOOKUP(K30,'MIS COMPROBANTES'!E:Q,13,FALSE) -> #N/A
A31: 45446 | B31: RIO | C31: BANCO SANTANDER RIO | D31: RI | E31: 30500008454 | F31: 12652 | G31: FAC | H31: 00202410102094 | I31: 2024 | J31: 10102094 | K31: =CONCATENATE(E31,I31,J31) -> 30500008454202410102094 | L31: 1.5 | M31: 0 | N31: 0 | O31: 18739.7 | P31: 0 | R31: 0 | S31: =VLOOKUP(K31,'MIS COMPROBANTES'!E:Q,13,FALSE) -> #N/A
A32: 45446 | B32: COMAFI | C32: BANCO COMAFI SOCIEDAD ANONIMA | D32: RI | E32: 30604731018 | F32: 12384 | G32: FAC | H32: 00202433218951 | I32: 2024 | J32: 33218951 | K32: =CONCATENATE(E32,I32,J32) -> 30604731018202433218951 | L32: 10.5 | M32: 1630101.9 | N32: 1270547.9 | O32: 133407.53 | P32: 3078526.5 | R32: 25410.96 | S32: =VLOOKUP(K32,'MIS COMPROBANTES'!E:Q,13,FALSE) -> #N/A
... A64: 45447 | B64: GILBAR | C64: GILBAR COMBUSTIBLES S.A. | D64: RI | E64: 30712201467 | F64: 12331 | G64: FAC | H64: A0000600014199 | I64: 6 | J64: 14199 | K64: =CONCATENATE(E64,I64,J64) -> 30712201467614199 | L64: 21 | M64: 12624.2 | N64: 86267.61 | O64: 18116.2 | P64: 117008.01 | R64: 0 | S64: =VLOOKUP(K64,'MIS COMPROBANTES'!E:Q,13,FALSE) -> #N/A
A65: 45447 | B65: LODI | C65: LODISER S.A. | D65: RI | E65: 30707059806 | F65: 12265 | G65: FAC | H65: A0009100245410 | I65: 91 | J65: 245410 | K65: =CONCATENATE(E65,I65,J65) -> 3070705980691245410 | L65: 21 | M65: 0 | N65: 3750000 | O65: 787500 | P65: 4818750 | Q65: 901-039988-2 | R65: 168750 | S65: =VLOOKUP(K65,'MIS COMPROBANTES'!E:Q,13,FALSE) -> 4818750
A66: 45447 | B66: LODI | C66: LODISER S.A. | D66: RI | E66: 30707059806 | F66: 12265 | G66: FAC | H66: A0009100245410 | I66: 91 | J66: 245410 | K66: =CONCATENATE(E66,I66,J66) -> 3070705980691245410 | L66: 3 | M66: 0 | N66: 0 | O66: 112500 | P66: 0 | Q66: 901-039988-2 | R66: 0 | S66: =VLOOKUP(K66,'MIS COMPROBANTES'!E:Q,13,FALSE) -> 4818750
A67: 45447 | B67: AUSOL | C67: AUTOPISTAS DEL SOL SA | D67: RI | E67: 30677237119 | F67: 12794 | G67: FAC | H67: A0071105776565 | I67: 711 | J67: 5776565 | K67: =CONCATENATE(E67,I67,J67) -> 306772371197115776565 | L67: 21 | M67: 0 | N67: 12355.38 | O67: 2594.62 | P67: 15876.65 | R67: 555.99 | S67: =VLOOKUP(K67,'MIS COMPROBANTES'!E:Q,13,FALSE) -> 15876.65
A68: 45447 | B68: AUSOL | C68: AUTOPISTAS DEL SOL SA | D68: RI | E68: 30677237119 | F68: 12794 | G68: FAC | H68: A0071105776565 | I68: 711 | J68: 5776565 | K68: =CONCATENATE(E68,I68,J68) -> 306772371197115776565 | L68: 3 | M68: 0 | N68: 0 | O68: 370.66 | P68: 0 | R68: 0 | S68: =VLOOKUP(K68,'MIS COMPROBANTES'!E:Q,13,FALSE) -> 15876.65
A69: 45447 | B69: AUSOL | C69: AUTOPISTAS DEL SOL SA | D69: RI | E69: 30677237119 | F69: 12795 | G69: FAC | H69: A0071105779436 | I69: 711 | J69: 5779436 | K69: =CONCATENATE(E69,I69,J69) -> 306772371197115779436 | L69: 21 | M69: 0 | N69: 60000.23 | O69: 12599.77 | P69: 77100.02 | R69: 2700.01 | S69: =VLOOKUP(K69,'MIS COMPROBANTES'!E:Q,13,FALSE) -> 77100.02
A70: 45447 | B70: AUSOL | C70: AUTOPISTAS DEL SOL SA | D70: RI | E70: 30677237119 | F70: 12795 | G70: FAC | H70: A0071105779436 | I70: 711 | J70: 5779436 | K70: =CONCATENATE(E70,I70,J70) -> 306772371197115779436 | L70: 3 | M70: 0 | N70: 0 | O70: 1800.01 | P70: 0 | R70: 0 | S70: =VLOOKUP(K70,'MIS COMPROBANTES'!E:Q,13,FALSE) -> 77100.02
A71: 45447 | B71: AUSOL | C71: AUTOPISTAS DEL SOL SA | D71: RI | E71: 30677237119 | F71: 12796 | G71: FAC | H71: A0071105781253 | I71: 711 | J71: 5781253 | K71: =CONCATENATE(E71,I71,J71) -> 306772371197115781253 | L71: 21 | M71: 0 | N71: 66611.74 | O71: 13988.26 | P71: 85595.87 | R71: 2997.52 | S71: =VLOOKUP(K71,'MIS COMPROBANTES'!E:Q,13,FALSE) -> 85595.87
A72: 45447 | B72: AUSOL | C72: AUTOPISTAS DEL SOL SA | D72: RI | E72: 30677237119 | F72: 12796 | G72: FAC | H72: A0071105781253 | I72: 711 | J72: 5781253 | K72: =CONCATENATE(E72,I72,J72) -> 306772371197115781253 | L72: 3 | M72: 0 | N72: 0 | O72: 1998.35 | P72: 0 | R72: 0 | S72: =VLOOKUP(K72,'MIS COMPROBANTES'!E:Q,13,FALSE) -> 85595.87
...

Sheet MIS COMPROBANTES
A1: Fecha | B1: Tipo | C1: Punto de Venta | D1: Número Desde | E1: GUIA | F1: Cód. Autorización | G1: Tipo Doc. Emisor | H1: Nro. Doc. Emisor | I1: Denominación Emisor | J1: Tipo Cambio | K1: Moneda | L1: Imp. Neto Gravado | M1: Imp. Neto No Gravado | N1: Imp. Op. Exentas | O1: Otros Tributos | P1: IVA | Q1: Imp. Total
A2: 13/06/2024 | B2: 1 - Factura A | C2: 20 | D2: 1747 | E2: =CONCATENATE(H2,C2,D2) -> 30594465497201747 | F2: 74247383955164 | G2: CUIT | H2: 30594465497 | I2: 3 ARROYOS S A | J2: 1 | K2: $ | L2: 497578.08 | M2: 0 | N2: 0 | O2: 0 | P2: 104491.4 | Q2: 602069.48 | R2: =VLOOKUP(E2,'IVA COMPRAS'!K:P,6,FALSE) -> 602069.48
A3: 27/06/2024 | B3: 1 - Factura A | C3: 20 | D3: 1765 | E3: =CONCATENATE(H3,C3,D3) -> 30594465497201765 | F3: 74267863513493 | G3: CUIT | H3: 30594465497 | I3: 3 ARROYOS S A | J3: 1 | K3: $ | L3: 1042471.8 | M3: 0 | N3: 0 | O3: 0 | P3: 218919.07 | Q3: 1261390.8 | R3: =VLOOKUP(E3,'IVA COMPRAS'!K:P,6,FALSE) -> 1261390.8
A4: 04/06/2024 | B4: 1 - Factura A | C4: 3 | D4: 1398 | E4: =CONCATENATE(H4,C4,D4) -> 3071474643631398 | F4: 74236315053296 | G4: CUIT | H4: 30714746436 | I4: 3PL SRL | J4: 1 | K4: $ | L4: 247070.52 | M4: 0 | N4: 0 | O4: 0 | P4: 51884.81 | Q4: 298955.33 | R4: =VLOOKUP(E4,'IVA COMPRAS'!K:P,6,FALSE) -> 298955.33
A5: 04/06/2024 | B5: 3 - Nota de Crédito A | C5: 3 | D5: 110 | E5: =CONCATENATE(H5,C5,D5) -> 307147464363110 | F5: 74236314737611 | G5: CUIT | H5: 30714746436 | I5: 3PL SRL | J5: 1 | K5: $ | L5: 81378.96 | M5: 0 | N5: 0 | O5: 0 | P5: 17089.58 | Q5: 98468.54 | R5: =VLOOKUP(E5,'IVA COMPRAS'!K:P,6,FALSE) -> -98468.54
A6: 06/06/2024 | B6: 1 - Factura A | C6: 3 | D6: 1406 | E6: =CONCATENATE(H6,C6,D6) -> 3071474643631406 | F6: 74236598158189 | G6: CUIT | H6: 30714746436 | I6: 3PL SRL | J6: 1 | K6: $ | L6: 2055110.8 | M6: 0 | N6: 0 | O6: 0 | P6: 431573.27 | Q6: 2486684.1 | R6: =VLOOKUP(E6,'IVA COMPRAS'!K:P,6,FALSE) -> 2486684.1
A7: 06/06/2024 | B7: 1 - Factura A | C7: 3 | D7: 1407 | E7: =CONCATENATE(H7,C7,D7) -> 3071474643631407 | F7: 74236602128219 | G7: CUIT | H7: 30714746436 | I7: 3PL SRL | J7: 1 | K7: $ | L7: 23936204 | M7: 0 | N7: 0 | O7: 0 | P7: 5026602.9 | Q7: 28962807 | R7: =VLOOKUP(E7,'IVA COMPRAS'!K:P,6,FALSE) -> 28962807
A8: 19/06/2024 | B8: 1 - Factura A | C8: 3 | D8: 1416 | E8: =CONCATENATE(H8,C8,D8) -> 3071474643631416 | F8: 74256008538726 | G8: CUIT | H8: 30714746436 | I8: 3PL SRL | J8: 1 | K8: $ | L8: 297418.06 | M8: 0 | N8: 0 | O8: 0 | P8: 62457.79 | Q8: 359875.85 | R8: =VLOOKUP(E8,'IVA COMPRAS'!K:P,6,FALSE) -> 359875.85
A9: 19/06/2024 | B9: 1 - Factura A | C9: 3 | D9: 1417 | E9: =CONCATENATE(H9,C9,D9) -> 3071474643631417 | F9: 74256008948455 | G9: CUIT | H9: 30714746436 | I9: 3PL SRL | J9: 1 | K9: $ | L9: 978927.88 | M9: 0 | N9: 0 | O9: 0 | P9: 205574.85 | Q9: 1184502.7 | R9: =VLOOKUP(E9,'IVA COMPRAS'!K:P,6,FALSE) -> 1184502.7
A10: 28/06/2024 | B10: 3 - Nota de Crédito A | C10: 3 | D10: 114 | E10: =CONCATENATE(H10,C10,D10) -> 307147464363114 | F10: 74266978052704 | G10: CUIT | H10: 30714746436 | I10: 3PL SRL | J10: 1 | K10: $ | L10: 1691427.9 | M10: 0 | N10: 0 | O10: 0 | P10: 355199.85 | Q10: 2046627.7 | R10: =VLOOKUP(E10,'IVA COMPRAS'!K:P,6,FALSE) -> -2046627.7
A11: 14/06/2024 | B11: 1 - Factura A | C11: 12 | D11: 1795 | E11: =CONCATENATE(H11,C11,D11) -> 30709151041121795 | F11: 74241504243336 | G11: CUIT | H11: 30709151041 | I11: A.V.A. SOCIEDAD ANONIMA | J11: 1 | K11: $ | L11: 812296.8 | M11: 0 | N11: 0 | O11: 0 | P11: 170582.33 | Q11: 982879.13 | R11: =VLOOKUP(E11,'IVA COMPRAS'!K:P,6,FALSE) -> 982879.13
A12: 28/06/2024 | B12: 1 - Factura A | C12: 1 | D12: 569 | E12: =CONCATENATE(H12,C12,D12) -> 337177102291569 | F12: 74269943893605 | G12: CUIT | H12: 33717710229 | I12: ACEITERA GERASOLES S.A. | J12: 1 | K12: $ | L12: 9750000 | M12: 0 | N12: 0 | O12: 0 | P12: 2047500 | Q12: 11797500 | R12: =VLOOKUP(E12,'IVA COMPRAS'!K:P,6,FALSE) -> 11797500
A13: 01/06/2024 | B13: 1 - Factura A | C13: 1326 | D13: 1005423 | E13: =CONCATENATE(H13,C13,D13) -> 3066328849713261005423 | F13: 74227115981874 | G13: CUIT | H13: 30663288497 | I13: AMX ARGENTINA SOCIEDAD ANONIMA | J13: 1 | K13: $ | L13: 23510 | M13: 0 | N13: 0 | O13: 0 | P13: 4949.1 | Q13: 29634.6 | R13: =VLOOKUP(E13,'IVA COMPRAS'!K:P,6,FALSE) -> 29634.6
... A46: 19/06/2024 | B46: 1 - Factura A | C46: 1 | D46: 105 | E46: =CONCATENATE(H46,C46,D46) -> 203019714791105 | F46: 74259091875524 | G46: CUIT | H46: 20301971479 | I46: BELLOTO LUIS MIGUEL | J46: 1 | K46: $ | L46: 380000 | M46: 0 | N46: 0 | O46: 0 | P46: 79800 | Q46: 459800 | R46: =VLOOKUP(E46,'IVA COMPRAS'!K:P,6,FALSE) -> 459800
A47: 25/06/2024 | B47: 1 - Factura A | C47: 12 | D47: 1953 | E47: =CONCATENATE(H47,C47,D47) -> 30711969132121953 | F47: 74262575963797 | G47: CUIT | H47: 30711969132 | I47: BIGAR S.A. | J47: 1 | K47: $ | L47: 646019 | M47: 0 | N47: 0 | O47: 0 | P47: 135663.99 | Q47: 781682.99 | R47: SE ANULA E/SI
A48: 26/06/2024 | B48: 3 - Nota de Crédito A | C48: 12 | D48: 513 | E48: =CONCATENATE(H48,C48,D48) -> 3071196913212513 | F48: 74262702878565 | G48: CUIT | H48: 30711969132 | I48: BIGAR S.A. | J48: 1 | K48: $ | L48: 646019 | M48: 0 | N48: 0 | O48: 0 | P48: 135663.99 | Q48: 781682.99 | R48: SE ANULA E/SI
A49: 04/06/2024 | B49: 1 - Factura A | C49: 2 | D49: 1037 | E49: =CONCATENATE(H49,C49,D49) -> 2314856169921037 | F49: 74239303170183 | G49: CUIT | H49: 23148561699 | I49: BONINI HORACIO ALBERTO | J49: 1 | K49: $ | L49: 396000 | M49: 0 | N49: 0 | O49: 0 | P49: 83160 | Q49: 479160 | R49: =VLOOKUP(E49,'IVA COMPRAS'!K:P,6,FALSE) -> 479160
A50: 03/06/2024 | B50: 11 - Factura C | C50: 1 | D50: 35 | E50: =CONCATENATE(H50,C50,D50) -> 27444490204135 | F50: 74234234739919 | G50: CUIT | H50: 27444490204 | I50: BOTINDARI MARIA MERCEDES | J50: 1 | K50: $ | O50: 0 | Q50: 350000 | R50: =VLOOKUP(E50,'IVA COMPRAS'!K:P,6,FALSE) -> 350000
A51: 01/06/2024 | B51: 3 - Nota de Crédito A | C51: 2009 | D51: 6273 | E51: =CONCATENATE(H51,C51,D51) -> 3070086991820096273 | F51: 74238210429374 | G51: CUIT | H51: 30700869918 | I51: BUNGE ARGENTINA S A | J51: 1 | K51: $ | L51: 164000 | M51: 0 | N51: 0 | O51: 0 | P51: 34440 | Q51: 198440 | R51: =VLOOKUP(E51,'IVA COMPRAS'!K:P,6,FALSE) -> -198440
A52: 10/06/2024 | B52: 1 - Factura A | C52: 2009 | D52: 38502 | E52: =CONCATENATE(H52,C52,D52) -> 30700869918200938502 | F52: 74248029583152 | G52: CUIT | H52: 30700869918 | I52: BUNGE ARGENTINA S A | J52: 1 | K52: $ | L52: 6156000 | M52: 0 | N52: 0 | O52: 0 | P52: 1292760 | Q52: 7910460 | R52: =VLOOKUP(E52,'IVA COMPRAS'!K:P,6,FALSE) -> 7910460
A53: 10/06/2024 | B53: 1 - Factura A | C53: 2009 | D53: 38503 | E53: =CONCATENATE(H53,C53,D53) -> 30700869918200938503 | F53: 74248029650518 | G53: CUIT | H53: 30700869918 | I53: BUNGE ARGENTINA S A | J53: 1 | K53: $ | L53: 6156000 | M53: 0 | N53: 0 | O53: 0 | P53: 1292760 | Q53: 7910460 | R53: =VLOOKUP(E53,'IVA COMPRAS'!K:P,6,FALSE) -> 7910460
A54: 10/06/2024 | B54: 1 - Factura A | C54: 2009 | D54: 38504 | E54: =CONCATENATE(H54,C54,D54) -> 30700869918200938504 | F54: 74248029659711 | G54: CUIT | H54: 30700869918 | I54: BUNGE ARGENTINA S A | J54: 1 | K54: $ | L54: 4532000 | M54: 0 | N54: 0 | O54: 0 | P54: 951720 | Q54: 5823620 | R54: =VLOOKUP(E54,'IVA COMPRAS'!K:P,6,FALSE) -> 5823620
A55: 10/06/2024 | B55: 1 - Factura A | C55: 2009 | D55: 38505 | E55: =CONCATENATE(H55,C55,D55) -> 30700869918200938505 | F55: 74248029754637 | G55: CUIT | H55: 30700869918 | I55: BUNGE ARGENTINA S A | J55: 1 | K55: $ | L55: 5665000 | M55: 0 | N55: 0 | O55: 0 | P55: 1189650 | Q55: 7477800 | R55: =VLOOKUP(E55,'IVA COMPRAS'!K:P,6,FALSE) -> 7477800
A56: 13/06/2024 | B56: 1 - Factura A | C56: 2009 | D56: 38575 | E56: =CONCATENATE(H56,C56,D56) -> 30700869918200938575 | F56: 74248438815243 | G56: CUIT | H56: 30700869918 | I56: BUNGE ARGENTINA S A | J56: 1 | K56: $ | L56: 10560000 | M56: 0 | N56: 0 | O56: 0 | P56: 2217600 | Q56: 13949760 | R56: =VLOOKUP(E56,'IVA COMPRAS'!K:P,6,FALSE) -> 13949760
A57: 13/06/2024 | B57: 1 - Factura A | C57: 2009 | D57: 38576 | E57: =CONCATENATE(H57,C57,D57) -> 30700869918200938576 | F57: 74248438826873 | G57: CUIT | H57: 30700869918 | I57: BUNGE ARGENTINA S A | J57: 1 | K57: $ | L57: 5665000 | M57: 0 | N57: 0 | O57: 0 | P57: 1189650 | Q57: 7483465 | R57: =VLOOKUP(E57,'IVA COMPRAS'!K:P,6,FALSE) -> 7483465
A58: 19/06/2024 | B58: 1 - Factura A | C58: 2009 | D58: 38673 | E58: =CONCATENATE(H58,C58,D58) -> 30700869918200938673 | F58: 74258025377789 | G58: CUIT | H58: 30700869918 | I58: BUNGE ARGENTINA S A | J58: 1 | K58: $ | L58: 5665000 | M58: 0 | N58: 0 | O58: 0 | P58: 1189650 | Q58: 7279525 | R58: =VLOOKUP(E58,'IVA COMPRAS'!K:P,6,FALSE) -> 7279525
A59: 19/06/2024 | B59: 1 - Factura A | C59: 2009 | D59: 38674 | E59: =CONCATENATE(H59,C59,D59) -> 30700869918200938674 | F59: 74258025390097 | G59: CUIT | H59: 30700869918 | I59: BUNGE ARGENTINA S A | J59: 1 | K59: $ | L59: 963600 | M59: 0 | N59: 0 | O59: 0 | P59: 202356 | Q59: 1238226 | R59: =VLOOKUP(E59,'IVA COMPRAS'!K:P,6,FALSE) -> 1238226
A60: 19/06/2024 | B60: 1 - Factura A | C60: 2009 | D60: 38675 | E60: =CONCATENATE(H60,C60,D60) -> 30700869918200938675 | F60: 74258025400652 | G60: CUIT | H60: 30700869918 | I60: BUNGE ARGENTINA S A | J60: 1 | K60: $ | L60: 2630880 | M60: 0 | N60: 0 | O60: 0 | P60: 552484.8 | Q60: 3472761.6 | R60: =VLOOKUP(E60,'IVA COMPRAS'!K:P,6,FALSE) -> 3472761.6
A61: 19/06/2024 | B61: 3 - Nota de Crédito A | C61: 2009 | D61: 6304 | E61: =CONCATENATE(H61,C61,D61) -> 3070086991820096304 | F61: 74258058573795 | G61: CUIT | H61: 30700869918 | I61: BUNGE ARGENTINA S A | J61: 1 | K61: $ | L61: 1095600 | M61: 0 | N61: 0 | O61: 0 | P61: 230076 | Q61: 1446192 | R61: =VLOOKUP(E61,'IVA COMPRAS'!K:P,6,FALSE) -> -1446192
A62: 12/06/2024 | B62: 11 - Factura C | C62: 11 | D62: 13465 | E62: =CONCATENATE(H62,C62,D62) -> 306631787641113465 | F62: 74244269891639 | G62: CUIT | H62: 30663178764 | I62: CAMARA ARGENTINA DE TRANSPORTE AUTOMOTOR DE MERCANCIAS Y RESIDUOS PELIGROSOS | J62: 1 | K62: $ | O62: 0 | Q62: 3200 | R62: PEDIR A LOGISTICA
A63: 05/06/2024 | B63: 1 - Factura A | C63: 539 | D63: 41126 | E63: =CONCATENATE(H63,C63,D63) -> 3066319759953941126 | F63: 74239476727663 | G63: CUIT | H63: 30663197599 | I63: CAMPO AUSTRAL SA | J63: 1 | K63: $ | L63: 1296608.9 | O63: 0 | P63: 272287.87 | Q63: 1594828.9 | R63: =VLOOKUP(E63,'IVA COMPRAS'!K:P,6,FALSE) -> 1594828.9
A64: 11/06/2024 | B64: 3 - Nota de Crédito A | C64: 539 | D64: 11958 | E64: =CONCATENATE(H64,C64,D64) -> 3066319759953911958 | F64: 74249142985380 | G64: CUIT | H64: 30663197599 | I64: CAMPO AUSTRAL SA | J64: 1 | K64: $ | L64: 103713.43 | O64: 0 | P64: 21779.82 | Q64: 125493.25 | R64: =VLOOKUP(E64,'IVA COMPRAS'!K:P,6,FALSE) -> -125493.26
A65: 12/06/2024 | B65: 1 - Factura A | C65: 539 | D65: 41282 | E65: =CONCATENATE(H65,C65,D65) -> 3066319759953941282 | F65: 74249319317745 | G65: CUIT | H65: 30663197599 | I65: CAMPO AUSTRAL SA | J65: 1 | K65: $ | L65: 833129.57 | O65: 0 | P65: 174957.21 | Q65: 1024749.4 | R65: =VLOOKUP(E65,'IVA COMPRAS'!K:P,6,FALSE) -> 1024749.4
A66: 26/06/2024 | B66: 1 - Factura A | C66: 539 | D66: 41530 | E66: =CONCATENATE(H66,C66,D66) -> 3066319759953941530 | F66: 74269719506857 | G66: CUIT | H66: 30663197599 | I66: CAMPO AUSTRAL SA | J66: 1 | K66: $ | L66: 736755.71 | O66: 0 | P66: 154718.7 | Q66: 906209.52 | R66: =VLOOKUP(E66,'IVA COMPRAS'!K:P,6,FALSE) -> 906209.54
A67: 25/06/2024 | B67: 11 - Factura C | C67: 2 | D67: 1767 | E67: =CONCATENATE(H67,C67,D67) -> 2017701852021767 | F67: 74260618252164 | G67: CUIT | H67: 20177018520 | I67: CASELLA ROBERTO CARLOS | J67: 1 | K67: $ | O67: 0 | Q67: 25500 | R67: =VLOOKUP(E67,'IVA COMPRAS'!K:P,6,FALSE) -> #N/A
A68: 11/06/2024 | B68: 1 - Factura A | C68: 29 | D68: 37 | E68: =CONCATENATE(H68,C68,D68) -> 307110225932937 | F68: 74243124746449 | G68: CUIT | H68: 30711022593 | I68: CEREALES SAN VICENTE SRL | J68: 1 | K68: $ | L68: 12054640 | M68: 0 | N68: 0 | O68: 0 | P68: 2531474.4 | Q68: 14586114 | R68: =VLOOKUP(E68,'IVA COMPRAS'!K:P,6,FALSE) -> 14586114
A69: 01/06/2024 | B69: 1 - Factura A | C69: 3 | D69: 228947 | E69: =CONCATENATE(H69,C69,D69) -> 307071355963228947 | F69: 74226996479387 | G69: CUIT | H69: 30707135596 | I69: CITILAN ARGENTINA S.A. | J69: 1 | K69: $ | L69: 82978.84 | M69: 0 | N69: 0 | O69: 0 | P69: 17425.56 | Q69: 102063.98 | R69: =VLOOKUP(E69,'IVA COMPRAS'!K:P,6,FALSE) -> 102063.98
A70: 05/06/2024 | B70: 1 - Factura A | C70: 601 | D70: 264433 | E70: =CONCATENATE(H70,C70,D70) -> 30525390086601264433 | F70: 34226022380740 | G70: CUIT | H70: 30525390086 | I70: COCA COLA FEMSA DE BUENOS AIRES S A | J70: 1 | K70: $ | L70: 7019387.9 | M70: 0 | N70: 0 | O70: 0 | P70: 1474071.4 | Q70: 9356377.7 | R70: =VLOOKUP(E70,'IVA COMPRAS'!K:P,6,FALSE) -> 9356377.7
A71: 05/06/2024 | B71: 1 - Factura A | C71: 601 | D71: 264434 | E71: =CONCATENATE(H71,C71,D71) -> 30525390086601264434 | F71: 34226022380740 | G71: CUIT | H71: 30525390086 | I71: COCA COLA FEMSA DE BUENOS AIRES S A | J71: 1 | K71: $ | L71: 2804032 | M71: 0 | N71: 0 | O71: 0 | P71: 588846.73 | Q71: 3692545.9 | R71: =VLOOKUP(E71,'IVA COMPRAS'!K:P,6,FALSE) -> 3692545.9
A72: 05/06/2024 | B72: 3 - Nota de Crédito A | C72: 603 | D72: 57049 | E72: =CONCATENATE(H72,C72,D72) -> 3052539008660357049 | F72: 34226022380740 | G72: CUIT | H72: 30525390086 | I72: COCA COLA FEMSA DE BUENOS AIRES S A | J72: 1 | K72: $ | L72: 155446.19 | M72: 0 | N72: 0 | O72: 0 | P72: 32643.7 | Q72: 206270.88 | R72: =VLOOKUP(E72,'IVA COMPRAS'!K:P,6,FALSE) -> -206270.88
...

Sheet Hoja3
