Workbook
Name partner_id: Configuracion!$B$332

Sheet Configuracion
F1: CUIT | G1: Cargar sin guiones
F2: RAZON SOCIAL | G2: Maximo 30 caracteres
A3: CUIT | B3: RAZON SOCIAL | C3: DETALLE | F3: DETALLE | G3: Cargar tipo de gasto
A4: 30628205090 | B4: ALBAMIE SA | C4: CLIENTE
A5: 30711678820 | B5: 2PSI INGENIERIA SRL | C5: PROVEEDOR
A6: 33716367539 | B6: 3PI S.A.S. | C6: PROVEEDOR
A7: 30660373108 | B7: ABC SA | C7: VARIOS
A8: 20300210881 | B8: ABOY DIEGO OSCAR | C8: PROVEEDOR
A9: 27229910782 | B9: ABUGAUCH MARIA DE LOS ANGELES | C9: PROVEEDOR
A10: 20242709897 | B10: ABUGAUCH VICTOR HUGO | C10: PROVEEDOR
A11: 20281669053 | B11: ACOSTA JAVIER GUSTAVO | C11: FLETE
A12: 20174240125 | B12: ACOSTA OSCAR ISIDRO | C12: VARIOS
A13: 30641659106 | B13: AGRISOL SA | C13: VARIOS
A14: 33709914109 | B14: ALAN COLLECTION SA | C14: VARIOS
A15: 20267161616 | B15: ALBAJARI DIEGO MARCOS | C15: VARIOS
... A155: 30537679855 | B155: ESTACION LIMA SA | C155: VARIOS
A156: 30-56864959-8 | B156: EXPRESO BISONTE SRL | C156: FLETE
A157: 30708542349 | B157: EXPRESO FORMOSA SRL | C157: FLETE
A158: 30526582884 | B158: EXPRESO MAR DEL PLATA SA | C158: FLETE
A159: 30577744579 | B159: EXPRESO TROLE SRL | C159: FLETE
A160: 30715949292 | B160: EYPAPEL SAS | C160: GASTOS VARIOS
A161: 30715980807 | B161: FABORT SRL | C161: PROVEEDOR
A162: 20359718765 | B162: FAIL ABRAHAM | C162: VARIOS
A163: 30643518364 | B163: FARMACIA DE MEDRANO SCS | C163: PROVEEDOR
A164: 30692138747 | B164: FARMACITY SA | C164: VARIOS
A165: 33712234429 | B165: FEDAGAS SA | C165: VARIOS
A166: 20353576012 | B166: FEDERICO PABLO FEOLA | C166: VARIOS
A167: 20343766441 | B167: FERNANDEZ MAURO | C167: TALLER
A168: 27062343449 | B168: FERREIRA LILIANA INES | C168: FLETE
... A567: 27179026967 | B567: ARABIA FABIANA | C567: GASTOS ADMIN

Sheet Oct 24
A1: ORTOPEDIA GEMINIS S.A. | J1: 45566
A4: LIBRO IVA COMPRAS
A6: FACTURAS A
A7: FECHA | B7: PTO VTA | C7: FAC A | D7: CUIT | E7: RAZON SOCIAL | F7: NETO | G7: IVA 21% | H7: IVA 27% | I7: IVA 10,5% | J7: P IVA | K7: IIBB CF | L7: IIBB BS | M7: NO GRAV | N7: OTROS | O7: TOTAL | P7: DETALLE
A8: 45574 | B8: 6 | C8: 1658 | D8: 30716815710 | E8: =VLOOKUP(D8,Configuracion!$A$4:$C$590,2,FALSE) -> PAPELERA GEOPEL SRL | F8: 15700 | G8: =F8*21% -> 3297 | O8: =SUM(F8:N8) -> 18997 | P8: =VLOOKUP(D8,Configuracion!$A$4:$C$590,3,FALSE) -> LIBRERÍA
A9: 45568 | B9: 6 | C9: 19623 | D9: 33715594949 | E9: =VLOOKUP(D9,Configuracion!$A$4:$C$590,2,FALSE) -> SOMOS ENERGIA SA | F9: 90860.71 | G9: =F9*21% -> 19080.749 | N9: 7268.6 | O9: =SUM(F9:N9) -> 117210.06 | P9: =VLOOKUP(D9,Configuracion!$A$4:$C$590,3,FALSE) -> GASTOS VARIOS
A10: 45596 | B10: 1002 | C10: 20230 | D10: 30712289046 | E10: =VLOOKUP(D10,Configuracion!$A$4:$C$590,2,FALSE) -> IMPIERI, PIÑEIRO, RIZZO Y A SA | F10: 45017.3 | G10: =F10*21% -> 9453.633 | M10: 5529.01 | O10: =SUM(F10:N10) -> 59999.943 | P10: =VLOOKUP(D10,Configuracion!$A$4:$C$590,3,FALSE) -> VARIOS
A11: 45593 | B11: 591 | C11: 3828 | D11: 30590360763 | E11: =VLOOKUP(D11,Configuracion!$A$4:$C$590,2,FALSE) -> CENCOSUD S.A. | F11: 51727.69 | G11: =F11*21% -> 10862.815 | J11: 1551.83 | K11: 2586.38 | O11: =SUM(F11:N11) -> 66728.715 | P11: =VLOOKUP(D11,Configuracion!$A$4:$C$590,3,FALSE) -> VARIOS
A12: 45595 | B12: 13 | C12: 1869 | D12: 33709914109 | E12: =VLOOKUP(D12,Configuracion!$A$4:$C$590,2,FALSE) -> ALAN COLLECTION SA | F12: 19008.26 | G12: =F12*21% -> 3991.7346 | O12: =SUM(F12:N12) -> 22999.995 | P12: =VLOOKUP(D12,Configuracion!$A$4:$C$590,3,FALSE) -> VARIOS
A13: 45574 | B13: 6 | C13: 19699 | D13: 33715594949 | E13: =VLOOKUP(D13,Configuracion!$A$4:$C$590,2,FALSE) -> SOMOS ENERGIA SA | F13: 77387.46 | G13: =F13*21% -> 16251.367 | N13: 6354.13 | O13: =SUM(F13:N13) -> 99992.957 | P13: =VLOOKUP(D13,Configuracion!$A$4:$C$590,3,FALSE) -> GASTOS VARIOS
A14: 45578 | B14: 8 | C14: 12982 | D14: 33715594949 | E14: =VLOOKUP(D14,Configuracion!$A$4:$C$590,2,FALSE) -> SOMOS ENERGIA SA | F14: 23224.02 | G14: =F14*21% -> 4877.0442 | N14: 1906.88 | O14: =SUM(F14:N14) -> 30007.944 | P14: =VLOOKUP(D14,Configuracion!$A$4:$C$590,3,FALSE) -> GASTOS VARIOS
A15: 45594 | B15: 8 | C15: 13145 | D15: 33715594949 | E15: =VLOOKUP(D15,Configuracion!$A$4:$C$590,2,FALSE) -> SOMOS ENERGIA SA | F15: 59005.12 | G15: =F15*21% -> 12391.075 | N15: 4844.8 | O15: =SUM(F15:N15) -> 76240.995 | P15: =VLOOKUP(D15,Configuracion!$A$4:$C$590,3,FALSE) -> GASTOS VARIOS
A16: 45588 | B16: 11 | C16: 12631 | D16: 30705740670 | E16: =VLOOKUP(D16,Configuracion!$A$4:$C$590,2,FALSE) -> MAVISUR SA | F16: 51347.06 | G16: =F16*21% -> 10782.883 | N16: 6872.06 | O16: =SUM(F16:N16) -> 69002.003 | P16: =VLOOKUP(D16,Configuracion!$A$4:$C$590,3,FALSE) -> VARIOS
A17: 45581 | B17: 15 | C17: 38379 | D17: 30685116657 | E17: =VLOOKUP(D17,Configuracion!$A$4:$C$590,2,FALSE) -> MIRVAR SA | F17: 48501.78 | G17: =F17*21% -> 10185.374 | N17: 5318.06 | O17: =SUM(F17:N17) -> 64005.214 | P17: =VLOOKUP(D17,Configuracion!$A$4:$C$590,3,FALSE) -> VARIOS
A18: 45586 | B18: 6 | C18: 19833 | D18: 33715594949 | E18: =VLOOKUP(D18,Configuracion!$A$4:$C$590,2,FALSE) -> SOMOS ENERGIA SA | F18: 46435.8 | G18: =F18*21% -> 9751.518 | N18: 3812.75 | O18: =SUM(F18:N18) -> 60000.068 | P18: =VLOOKUP(D18,Configuracion!$A$4:$C$590,3,FALSE) -> GASTOS VARIOS
A19: 45595 | B19: 1002 | C19: 20187 | D19: 30712289046 | E19: =VLOOKUP(D19,Configuracion!$A$4:$C$590,2,FALSE) -> IMPIERI, PIÑEIRO, RIZZO Y A SA | F19: 30011.57 | G19: =F19*21% -> 6302.4297 | K19: 3686.01 | O19: =SUM(F19:N19) -> 40000.01 | P19: =VLOOKUP(D19,Configuracion!$A$4:$C$590,3,FALSE) -> VARIOS
A20: 45589 | B20: 2 | C20: 876 | D20: 20272865869 | E20: =VLOOKUP(D20,Configuracion!$A$4:$C$590,2,FALSE) -> DI FEO MARTIN EZEQUIEL | F20: 133850 | G20: =F20*21% -> 28108.5 | O20: =SUM(F20:N20) -> 161958.5 | P20: =VLOOKUP(D20,Configuracion!$A$4:$C$590,3,FALSE) -> PROVEEDOR
A21: 45582 | B21: 2 | C21: 850 | D21: 20272865869 | E21: =VLOOKUP(D21,Configuracion!$A$4:$C$590,2,FALSE) -> DI FEO MARTIN EZEQUIEL | F21: 106750 | G21: =F21*21% -> 22417.5 | O21: =SUM(F21:N21) -> 129167.5 | P21: =VLOOKUP(D21,Configuracion!$A$4:$C$590,3,FALSE) -> PROVEEDOR
A22: 45582 | B22: 2 | C22: 845 | D22: 20272865869 | E22: =VLOOKUP(D22,Configuracion!$A$4:$C$590,2,FALSE) -> DI FEO MARTIN EZEQUIEL | F22: 109000 | G22: =F22*21% -> 22890 | O22: =SUM(F22:N22) -> 131890 | P22: =VLOOKUP(D22,Configuracion!$A$4:$C$590,3,FALSE) -> PROVEEDOR
A23: 45568 | B23: 2 | C23: 833 | D23: 20272865869 | E23: =VLOOKUP(D23,Configuracion!$A$4:$C$590,2,FALSE) -> DI FEO MARTIN EZEQUIEL | F23: 145500 | G23: =F23*21% -> 30555 | O23: =SUM(F23:N23) -> 176055 | P23: =VLOOKUP(D23,Configuracion!$A$4:$C$590,3,FALSE) -> PROVEEDOR
A24: 45575 | B24: 1 | C24: 5011 | D24: 30715141201 | E24: =VLOOKUP(D24,Configuracion!$A$4:$C$590,2,FALSE) -> REHAB SRL | F24: 43450 | G24: =F24*21% -> 9124.5 | O24: =SUM(F24:N24) -> 52574.5 | P24: =VLOOKUP(D24,Configuracion!$A$4:$C$590,3,FALSE) -> PROVEEDOR
A25: 45579 | B25: 1 | C25: 5027 | D25: 30715141201 | E25: =VLOOKUP(D25,Configuracion!$A$4:$C$590,2,FALSE) -> REHAB SRL | F25: 642844.12 | G25: =F25*21% -> 134997.27 | O25: =SUM(F25:N25) -> 777841.39 | P25: =VLOOKUP(D25,Configuracion!$A$4:$C$590,3,FALSE) -> PROVEEDOR
A26: 45573 | B26: 1 | C26: 4966 | D26: 30715141201 | E26: =VLOOKUP(D26,Configuracion!$A$4:$C$590,2,FALSE) -> REHAB SRL | F26: 267975 | G26: =F26*21% -> 56274.75 | O26: =SUM(F26:N26) -> 324249.75 | P26: =VLOOKUP(D26,Configuracion!$A$4:$C$590,3,FALSE) -> PROVEEDOR
A27: 45573 | B27: 1 | C27: 4972 | D27: 30715141201 | E27: =VLOOKUP(D27,Configuracion!$A$4:$C$590,2,FALSE) -> REHAB SRL | F27: 601618.51 | G27: =F27*21% -> 126339.89 | O27: =SUM(F27:N27) -> 727958.4 | P27: =VLOOKUP(D27,Configuracion!$A$4:$C$590,3,FALSE) -> PROVEEDOR
A28: 45569 | B28: 1 | C28: 4929 | D28: 30715141201 | E28: =VLOOKUP(D28,Configuracion!$A$4:$C$590,2,FALSE) -> REHAB SRL | F28: 99050 | G28: =F28*21% -> 20800.5 | O28: =SUM(F28:N28) -> 119850.5 | P28: =VLOOKUP(D28,Configuracion!$A$4:$C$590,3,FALSE) -> PROVEEDOR
A29: 45569 | B29: 1 | C29: 4933 | D29: 30715141201 | E29: =VLOOKUP(D29,Configuracion!$A$4:$C$590,2,FALSE) -> REHAB SRL | F29: 639938.25 | G29: =F29*21% -> 134387.03 | O29: =SUM(F29:N29) -> 774325.28 | P29: =VLOOKUP(D29,Configuracion!$A$4:$C$590,3,FALSE) -> PROVEEDOR
A30: 45589 | B30: 5 | C30: 160326 | D30: 30598960093 | E30: =VLOOKUP(D30,Configuracion!$A$4:$C$590,2,FALSE) -> SILVESTRIN FABRIS SRL | F30: 1977843 | G30: =F30*21% -> 415347.03 | K30: 98892.15 | O30: =SUM(F30:N30) -> 2492082.2 | P30: =VLOOKUP(D30,Configuracion!$A$4:$C$590,3,FALSE) -> PROVEEDOR
A31: 45575 | B31: 5 | C31: 159946 | D31: 30598960093 | E31: =VLOOKUP(D31,Configuracion!$A$4:$C$590,2,FALSE) -> SILVESTRIN FABRIS SRL | F31: 946021.5 | G31: =F31*21% -> 198664.51 | K31: 47301.08 | O31: =SUM(F31:N31) -> 1191987.1 | P31: =VLOOKUP(D31,Configuracion!$A$4:$C$590,3,FALSE) -> PROVEEDOR
A32: 45573 | B32: 5 | C32: 159832 | D32: 30598960093 | E32: =VLOOKUP(D32,Configuracion!$A$4:$C$590,2,FALSE) -> SILVESTRIN FABRIS SRL | F32: 1586940 | I32: =+F32*0.105 -> 166628.7 | K32: 79347 | O32: =SUM(F32:N32) -> 1832915.7 | P32: =VLOOKUP(D32,Configuracion!$A$4:$C$590,3,FALSE) -> PROVEEDOR
A33: 45566 | B33: 5 | C33: 159587 | D33: 30598960093 | E33: =VLOOKUP(D33,Configuracion!$A$4:$C$590,2,FALSE) -> SILVESTRIN FABRIS SRL | F33: 1464782.4 | G33: =F33*21% -> 307604.3 | K33: 73239.12 | O33: =SUM(F33:N33) -> 1845625.8 | P33: =VLOOKUP(D33,Configuracion!$A$4:$C$590,3,FALSE) -> PROVEEDOR
A34: 45568 | B34: 4 | C34: 38516 | D34: 20289111329 | E34: =VLOOKUP(D34,Configuracion!$A$4:$C$590,2,FALSE) -> R. N. LEDESMA | F34: 1170696.2 | G34: =F34*21% -> 245846.2 | O34: =SUM(F34:N34) -> 1416542.4 | P34: =VLOOKUP(D34,Configuracion!$A$4:$C$590,3,FALSE) -> PROVEEDOR
A35: 45580 | B35: 5 | C35: 32 | D35: 30707370552 | E35: =VLOOKUP(D35,Configuracion!$A$4:$C$590,2,FALSE) -> RAKE SA | F35: 895000 | G35: =F35*21% -> 187950 | O35: =SUM(F35:N35) -> 1082950 | P35: =VLOOKUP(D35,Configuracion!$A$4:$C$590,3,FALSE) -> PROVEEDOR
A36: 45569 | B36: 5 | C36: 27 | D36: 30707370552 | E36: =VLOOKUP(D36,Configuracion!$A$4:$C$590,2,FALSE) -> RAKE SA | F36: 1380000 | G36: =F36*21% -> 289800 | O36: =SUM(F36:N36) -> 1669800 | P36: =VLOOKUP(D36,Configuracion!$A$4:$C$590,3,FALSE) -> PROVEEDOR
A37: 45568 | B37: 4 | C37: 138 | D37: 20317488476 | E37: =VLOOKUP(D37,Configuracion!$A$4:$C$590,2,FALSE) -> VILLALBA MIGUEL ANGEL | F37: 150000 | G37: =F37*21% -> 31500 | O37: =SUM(F37:N37) -> 181500 | P37: =VLOOKUP(D37,Configuracion!$A$4:$C$590,3,FALSE) -> PROVEEDOR
A38: 45569 | B38: 7 | C38: 19168 | D38: 30709214078 | E38: =VLOOKUP(D38,Configuracion!$A$4:$C$590,2,FALSE) -> REHAVITA SA | F38: 59820 | G38: =F38*21% -> 12562.2 | O38: =SUM(F38:N38) -> 72382.2 | P38: =VLOOKUP(D38,Configuracion!$A$4:$C$590,3,FALSE) -> PROVEEDOR
A39: 45569 | B39: 401 | C39: 80 | D39: 30716234114 | E39: =VLOOKUP(D39,Configuracion!$A$4:$C$590,2,FALSE) -> UZUMAKI SAS | F39: 160978.5 | G39: =F39*21% -> 33805.485 | O39: =SUM(F39:N39) -> 194783.98 | P39: =VLOOKUP(D39,Configuracion!$A$4:$C$590,3,FALSE) -> PROVEEDOR
A40: 45569 | B40: 5 | C40: 2859 | D40: 30707267077 | E40: =VLOOKUP(D40,Configuracion!$A$4:$C$590,2,FALSE) -> BARBARO SC | F40: 1388000 | G40: =F40*21% -> 291480 | O40: =SUM(F40:N40) -> 1679480 | P40: =VLOOKUP(D40,Configuracion!$A$4:$C$590,3,FALSE) -> PROVEEDOR
A41: 45567 | B41: 1 | C41: 615464 | D41: 33716307749 | E41: =VLOOKUP(D41,Configuracion!$A$4:$C$590,2,FALSE) -> VERISURE ARG MONITOREO A SA | F41: 40398.88 | G41: =F41*21% -> 8483.7648 | N41: 2019.94 | O41: =SUM(F41:N41) -> 50902.585 | P41: =VLOOKUP(D41,Configuracion!$A$4:$C$590,3,FALSE) -> PROVEEDOR
A42: 45573 | B42: 120 | C42: 5161 | D42: 30587197215 | E42: =VLOOKUP(D42,Configuracion!$A$4:$C$590,2,FALSE) -> PANATEL SOCIEDAD ANONIMA | F42: 68595.04 | G42: =F42*21% -> 14404.958 | K42: 3429.75 | O42: =SUM(F42:N42) -> 86429.748 | P42: =VLOOKUP(D42,Configuracion!$A$4:$C$590,3,FALSE) -> VARIOS
A43: 45572 | B43: 8 | C43: 1698 | D43: 30708973501 | E43: =VLOOKUP(D43,Configuracion!$A$4:$C$590,2,FALSE) -> ASIAL SRL | F43: 767170 | G43: =F43*21% -> 161105.7 | O43: =SUM(F43:N43) -> 928275.7 | P43: =VLOOKUP(D43,Configuracion!$A$4:$C$590,3,FALSE) -> INSUMOS
...

Sheet Calculo IVA
B1: ORTOPEDIA GEMINIS
A2: Calculo Iva | D2: 45566
B4: VENTAS
B5: Neto | C5: Iva | D5: Total
A6: FAC. "A" | B6: =+'Oct 24'!F200 -> 0 | C6: =(B6*0.21) -> 0 | D6: =(B6+C6) -> 0
A7: FAC. "B" | B7: =+'Oct 24'!F210 -> 0 | C7: =(B7*0.21) -> 0 | D7: =(B7+C7) -> 0
A8: FAC. "A" - | B8: =+'Resumen Ventas 10'!B3+'Resumen Ventas 10'!B5+'Resumen Ventas 10'!B6+'Resumen Ventas 10'!B4 -> 33476168 | C8: =+B8*0.21 -> 7029995.2 | D8: =(B8+C8) -> 40506163
A9: FAC. "B" | B9: =+'Resumen Ventas 10'!B7+'Resumen Ventas 10'!B8 -> 24030351 | C9: =+'Resumen Ventas 10'!C7+'Resumen Ventas 10'!C8 -> 5046373.7 | D9: =(B9+C9) -> 29076724
B10: =SUM(B6:B9) -> 57506519 | C10: =SUM(C6:C9) -> 12076369 | D10: =SUM(D6:D9) -> 69582887
B13: COMPRAS
B14: Neto | C14: Iva | D14: Total
B15: =+'Oct 24'!F115 -> 29685781 | C15: =+('Oct 24'!G115+'Oct 24'!H115+'Oct 24'!I115) -> 5990180.8 | D15: =+'Oct 24'!O115 -> 36250262
A16: Compras s/ODOO
A17: Comprobantes AFIP - Saldo | B17: 433365.78 | C17: 91006.8 | D17: 2741329.5
A18: IVA S/ EXTRACTOS BANCARIOS | C18: =+'Compras 10'!D57 -> 12622.1
B19: =SUM(B15:B18) -> 30119147 | C19: =SUM(C15:C18) -> 6093809.7 | D19: =SUM(D15:D18) -> 38991591
A22: RETENCIONES | B22: N° Cuit | C22: Importe | D22: Nro. Retencion | E22: Fecha
A23: AFIP - No están informadas las retenciones de IVA en el sistema de AFIP
C38: =+'Oct 24'!G183 -> 1213578.6
A40: PERCEPCIONES | B40: N° Cuit | C40: Importe | D40: Nro. Retencion | E40: Fecha
C44: =SUM(C41:C43) -> 0
A46: Total Deducciociones | C46: =+C44+C38 -> 1213578.6
C49: (Montos en Positivo)
A50: 1er Saldo Tecnico del Período | C50: =+C10-C19 -> 5982559.2
A52: Saldo Tecnico de período Anterior (a favor) | D52: (resta en el total)
A54: Saldo Neto Técnico | C54: =+C50-C52 -> 5982559.2
A58: Saldo L.D. del Período | C58: =+C44+C38 -> 1213578.6
A60: Saldo L.D. del Período Anterior
A62: Neto S.L.D | C62: =+C58+C60 -> 1213578.6
A65: I V A | C65: =+C54-C62 -> 4768980.6
A66: NOTA: Sin Tomar posibles Retenciones que se hayan hecho

Sheet Compras 10
A2: Ortopedia Geminis S.A.
A4: Fecha | B4: Comprobante | C4: Nombre | D4: Cond. IVA | E4: CUIT o Doc. | F4: Gravado | G4: No Gravado | H4: IVA 2,5% | I4: IVA 5% | J4: IVA 10.5% | K4: IVA 21% | L4: IVA 27% | M4: Otros Imp | N4: Total Compr.
F6: =SUM(F5:F5) -> 0 | G6: =SUM(G5:G5) -> 0 | H6: =SUM(H5:H5) -> 0 | I6: =SUM(I5:I5) -> 0 | J6: =SUM(J5:J5) -> 0 | K6: =SUM(K5:K5) -> 0 | L6: =SUM(L5:L5) -> 0 | M6: =SUM(M5:M5) -> 0 | N6: =SUM(N5:N5) -> 0
H7: =+SUM(H6:L6) -> 0
B10: Comprobantes AFIP no recepcionados
A13: Fecha | B13: Tipo | C13: Punto de Venta | D13: Número Desde | E13: Número Hasta | F13: Cód. Autorización | G13: Tipo Doc. Emisor | H13: Nro. Doc. Emisor | I13: Denominación Emisor | J13: Tipo Cambio | K13: Moneda | L13: Imp. Neto Gravado | M13: Imp. Neto No Gravado | N13: Imp. Op. Exentas | O13: Otros Tributos | P13: IVA | Q13: Imp. Total
A14: 28/10/2024 | B14: 6 - Factura B | C14: 469 | D14: 272223 | F14: 74440058567706 | G14: CUIT | H14: 30696170580 | I14: AEROPUERTOS ARGENTINA 2000 S A | J14: 1 | K14: $ | L14: 0 | M14: 0 | N14: 0 | O14: 0 | P14: 0 | Q14: -5206.61
A15: 31/10/2024 | B15: 1 - Factura A | C15: 5009 | D15: 1056394 | F15: 74444676246493 | G15: CUIT | H15: 30574876474 | I15: AUTOPISTAS URBANAS S A | J15: 1 | K15: $ | L15: 5655.83 | M15: 0 | N15: 0 | O15: 0 | P15: 1187.72 | Q15: 7578.8
A16: 31/10/2024 | B16: 1 - Factura A | C16: 5015 | D16: 660519 | F16: 74444670715235 | G16: CUIT | H16: 30574876474 | I16: AUTOPISTAS URBANAS S A | J16: 1 | K16: $ | L16: 18764.68 | M16: 0 | N16: 0 | O16: 0 | P16: 3940.57 | Q16: 25144.66
A17: 29/10/2024 | B17: 1 - Factura A | C17: 101 | D17: 8782 | F17: 74449116152602 | G17: CUIT | H17: 33711430879 | I17: BALANZE S.A. | J17: 1 | K17: $ | L17: 125800 | M17: 0 | N17: 0 | O17: 0 | P17: 26418 | Q17: 152218
A18: 15/10/2024 | B18: 1 - Factura A | C18: 113 | D18: 3855807 | F18: 74420895911146 | G18: CUIT | H18: 30577207190 | I18: COORDINACION ECOLOGICA AREA METROPOLITANA SOCIEDAD DEL ESTADO | J18: 1 | K18: $ | L18: 991.73 | M18: 0 | N18: 0 | O18: 0 | P18: 208.27 | Q18: 1200
A19: 31/10/2024 | B19: 1 - Factura A | C19: 113 | D19: 3883633 | F19: 74440822775090 | G19: CUIT | H19: 30577207190 | I19: COORDINACION ECOLOGICA AREA METROPOLITANA SOCIEDAD DEL ESTADO | J19: 1 | K19: $ | L19: 2975.21 | M19: 0 | N19: 0 | O19: 0 | P19: 624.79 | Q19: 3689.26
A20: 15/10/2024 | B20: 1 - Factura A | C20: 104 | D20: 6923432 | F20: 74422530905691 | G20: CUIT | H20: 30715804812 | I20: CORREDORES VIALES SOCIEDAD ANONIMA | J20: 1 | K20: $ | L20: 910.78 | M20: 0 | N20: 0 | O20: 0 | P20: 191.26 | Q20: 1147.58
A21: 11/10/2024 | B21: 1 - Factura A | C21: 3 | D21: 4181 | F21: 74414181067117 | G21: CUIT | H21: 30501077824 | I21: DADAGLIO HNOS S A I C F I A | J21: 1 | K21: $ | L21: 104462.81 | M21: 0 | N21: 0 | O21: 0 | P21: 21937.19 | Q21: 126400.01
A22: 18/10/2024 | B22: 1 - Factura A | C22: 102 | D22: 49564 | F22: 74425010766802 | G22: CUIT | H22: 30701307115 | I22: DESPEGAR COM AR SA | J22: 1 | K22: $ | L22: 4218.89 | M22: 0 | N22: 0 | O22: 0 | P22: 885.97 | Q22: 5315.8
A23: 18/10/2024 | B23: 11 - Factura C | C23: 1 | D23: 15 | G23: CUIT | H23: 27443612705 | I23: MIGOYA MORIONDO MARIA INES | J23: 1 | K23: $ | O23: 0 | Q23: 800000
A24: 02/10/2024 | B24: 11 - Factura C | C24: 1 | D24: 8 | G24: CUIT | H24: 27443612713 | I24: MIGOYA MORIONDO SOFIA | J24: 1 | K24: $ | O24: 0 | Q24: 750000
A25: 24/10/2024 | B25: 1 - Factura A | C25: 2 | D25: 10822 | F25: 74432609825455 | G25: CUIT | H25: 30714331082 | I25: ORTOPEDIA CASA ESCALADA S.R.L. | J25: 1 | K25: $ | L25: 13081.82 | M25: 0 | N25: 0 | O25: 0 | P25: 2747.18 | Q25: 15829
A26: 31/10/2024 | B26: 1 - Factura A | C26: 6 | D26: 17717989 | F26: 74447345508330 | G26: CUIT | H26: 30620177497 | I26: POSNET SOCIEDAD DE RESPONSABILIDAD LIMITADA | J26: 1 | K26: $ | L26: 0 | M26: 0 | N26: 0 | O26: 0 | P26: 0 | Q26: 0
A27: 31/10/2024 | B27: 1 - Factura A | C27: 6 | D27: 17862335 | F27: 74447384891474 | G27: CUIT | H27: 30620177497 | I27: POSNET SOCIEDAD DE RESPONSABILIDAD LIMITADA | J27: 1 | K27: $ | L27: 27263.03 | M27: 0 | N27: 0 | O27: 0 | P27: 5725.24 | Q27: 35169.31
A28: 21/10/2024 | B28: 1 - Factura A | C28: 8 | D28: 100796 | F28: 74434281839124 | G28: CUIT | H28: 30709776564 | I28: PROSEGUR ACTIVA ARGENTINA SA | J28: 1 | K28: $ | L28: 129241 | M28: 0 | N28: 0 | O28: 0 | P28: 27140.61 | Q28: 162843.68
A29: 18/10/2024 | B29: 11 - Factura C | C29: 1 | D29: 254 | G29: CUIT | H29: 27217606255 | I29: SAPUNA MIRIAN KARINA | J29: 1 | K29: $ | O29: 0 | Q29: 163808.35
A30: 19/10/2024 | B30: 11 - Factura C | C30: 1 | D30: 255 | G30: CUIT | H30: 27217606255 | I30: SAPUNA MIRIAN KARINA | J30: 1 | K30: $ | O30: 0 | Q30: 105993.64
A31: 21/10/2024 | B31: 11 - Factura C | C31: 1 | D31: 256 | G31: CUIT | H31: 27217606255 | I31: SAPUNA MIRIAN KARINA | J31: 1 | K31: $ | O31: 0 | Q31: 115629.42
A32: 21/10/2024 | B32: 11 - Factura C | C32: 1 | D32: 257 | G32: CUIT | H32: 27217606255 | I32: SAPUNA MIRIAN KARINA | J32: 1 | K32: $ | O32: 0 | Q32: 96357.85
A33: 28/10/2024 | B33: 11 - Factura C | C33: 1 | D33: 258 | G33: CUIT | H33: 27217606255 | I33: SAPUNA MIRIAN KARINA | J33: 1 | K33: $ | O33: 0 | Q33: 62373.76
A34: 28/10/2024 | B34: 11 - Factura C | C34: 1 | D34: 259 | G34: CUIT | H34: 27217606255 | I34: SAPUNA MIRIAN KARINA | J34: 1 | K34: $ | O34: 0 | Q34: 55245.33
A35: 28/10/2024 | B35: 11 - Factura C | C35: 1 | D35: 260 | G35: CUIT | H35: 27217606255 | I35: SAPUNA MIRIAN KARINA | J35: 1 | K35: $ | O35: 0 | Q35: 60591.65
L40: =SUM(L14:L39) -> 433365.78 | M40: =SUM(M14:M39) -> 0 | N40: =SUM(N14:N39) -> 0 | O40: =SUM(O14:O39) -> 0 | P40: =SUM(P14:P39) -> 91006.8 | Q40: =SUM(Q14:Q39) -> 2741329.5
A44: IVA Extractos Bancarios
B47: Banco Credicoop
B48: IVA-ALIC ADIC RG 2408 S/COMIS-REC GASTOS | D48: 600
B49: IVA - ALICUOTA INSCRIPTO | D49: 4937.1
B52: Banco Patagonia
B53: IVA Alicuota General | D53: 6245
B54: IVA Percepcion | D54: 840
C57: TOTAL IVA S/ EXTRACTOS | D57: =+SUM(D48,D49,D53,D54) -> 12622.1

Sheet afip
A1: Fecha | B1: Tipo | C1: Punto de Venta | D1: Número Desde | E1: Número Hasta | F1: Cód. Autorización | G1: Tipo Doc. Emisor | H1: Nro. Doc. Emisor | I1: Denominación Emisor | J1: Tipo Cambio | K1: Moneda | L1: Imp. Neto Gravado | M1: Imp. Neto No Gravado | N1: Imp. Op. Exentas | O1: Otros Tributos | P1: IVA | Q1: Imp. Total
A2: 01/09/2024 | B2: 1 - Factura A | C2: 2189 | D2: 75919 | F2: 74356447170423 | G2: CUIT | H2: 30548083156 | I2: COTO CENTRO INTEGRAL DE COMERCIALIZACION SOCIEDAD ANONIMA | J2: 1 | K2: $ | L2: 6462.61 | M2: 0 | N2: 0 | O2: 452.38 | P2: 1357.15 | Q2: 8272.14
A3: 02/09/2024 | B3: 1 - Factura A | C3: 500 | D3: 1611886 | F3: 74357098226128 | G3: CUIT | H3: 30654118767 | I3: SOLUCIONES MULTIMEDIA S A | J3: 1 | K3: $ | L3: 89554.36 | M3: 0 | N3: 0 | O3: 0 | P3: 18806.42 | Q3: 112850.92
A4: 02/09/2024 | B4: 1 - Factura A | C4: 1 | D4: 4517 | F4: 74361573927319 | G4: CUIT | H4: 30715141201 | I4: REHAB S.R.L. | J4: 1 | K4: $ | L4: 1216380 | M4: 0 | N4: 0 | O4: 0 | P4: 255439.8 | Q4: 1471819.8
A5: 02/09/2024 | B5: 1 - Factura A | C5: 5 | D5: 158399 | F5: 74363528156508 | G5: CUIT | H5: 30598960093 | I5: SILVESTRIN FABRIS SOC RESP LTDA | J5: 1 | K5: $ | L5: 2376294.2 | M5: 0 | N5: 0 | O5: 0 | P5: 337808.56 | Q5: 2832917.5
A6: 02/09/2024 | B6: 1 - Factura A | C6: 17 | D6: 2245 | F6: 74361547632750 | G6: CUIT | H6: 30711764921 | I6: RELIEF CENTER S.R.L. | J6: 1 | K6: $ | L6: 93973 | M6: 0 | N6: 0 | O6: 0 | P6: 19734.33 | Q6: 113707.33
A7: 02/09/2024 | B7: 1 - Factura A | C7: 3051 | D7: 801967 | F7: 74367703518446 | G7: CUIT | H7: 30678814357 | I7: TELEFONICA MOVILES ARGENTINA SOCIEDAD ANONIMA | J7: 1 | K7: $ | L7: 14407 | M7: 0 | N7: 0 | O7: 0 | P7: 3889.89 | Q7: 20245.61
A8: 02/09/2024 | B8: 1 - Factura A | C8: 2 | D8: 248 | F8: 74363494027429 | G8: CUIT | H8: 27144282383 | I8: SCHEJTER LILA ELISA | J8: 1 | K8: $ | L8: 160000 | M8: 0 | N8: 0 | O8: 0 | P8: 33600 | Q8: 193600
A9: 02/09/2024 | B9: 1 - Factura A | C9: 5 | D9: 102 | F9: 74367559790009 | G9: CUIT | H9: 27329449357 | I9: ANDREANI AGUSTINA SUSANA | J9: 1 | K9: $ | L9: 64100 | M9: 16400 | N9: 0 | O9: 0 | P9: 13461 | Q9: 93961
A10: 02/09/2024 | B10: 11 - Factura C | C10: 3 | D10: 874 | F10: 74363563144286 | G10: CUIT | H10: 20086277523 | I10: BOTINDARI JUAN CARLOS | J10: 1 | K10: $ | O10: 0 | Q10: 275500
A11: 02/09/2024 | B11: 11 - Factura C | C11: 2 | D11: 302 | F11: 74368278674869 | G11: CUIT | H11: 27265832178 | I11: BLASCO MARIA GUADALUPE | J11: 1 | K11: $ | O11: 0 | Q11: 250000
A12: 03/09/2024 | B12: 1 - Factura A | C12: 629 | D12: 5407463 | F12: 34353802937243 | G12: CUIT | H12: 30663498513 | I12: GRUPO CONCESIONARIO DEL OESTE SA | J12: 1 | K12: $ | L12: 2121.64 | M12: 0 | N12: 0 | O12: 0 | P12: 445.54 | Q12: 2673.26
A13: 03/09/2024 | B13: 1 - Factura A | C13: 711 | D13: 6097149 | F13: 34359489663246 | G13: CUIT | H13: 30677237119 | I13: AUTOPISTAS DEL SOL S A | J13: 1 | K13: $ | L13: 7715.05 | M13: 0 | N13: 231.45 | O13: 0 | P13: 1620.16 | Q13: 9952.41
A14: 03/09/2024 | B14: 1 - Factura A | C14: 2635 | D14: 1369 | F14: 34359844249451 | G14: CUIT | H14: 33699685459 | I14: CORREO ANDREANI SA | J14: 1 | K14: $ | L14: 12449.6 | M14: 0 | N14: 0 | O14: 0 | P14: 2614.42 | Q14: 15064.02
A15: 03/09/2024 | B15: 1 - Factura A | C15: 2 | D15: 216 | F15: 74362687536018 | G15: CUIT | H15: 30605344352 | I15: CONSORCIO BARTOLOME MITRE 2466 | J15: 1 | K15: $ | L15: 834000 | M15: 0 | N15: 0 | O15: 0 | P15: 175140 | Q15: 1009140
A16: 04/09/2024 | B16: 1 - Factura A | C16: 17 | D16: 2255 | F16: 74361803741207 | G16: CUIT | H16: 30711764921 | I16: RELIEF CENTER S.R.L. | J16: 1 | K16: $ | L16: 527580 | M16: 0 | N16: 0 | O16: 0 | P16: 110791.8 | Q16: 638371.8
A17: 04/09/2024 | B17: 1 - Factura A | C17: 2 | D17: 50685 | F17: 74365825946417 | G17: CUIT | H17: 30595553535 | I17: RUBRICOM SOCIEDAD ANONIMA | J17: 1 | K17: $ | L17: 4793.39 | M17: 0 | N17: 0 | O17: 0 | P17: 1006.61 | Q17: 5800
A18: 04/09/2024 | B18: 1 - Factura A | C18: 120 | D18: 4949 | F18: 74365804898856 | G18: CUIT | H18: 30587197215 | I18: PANATEL SOCIEDAD ANONIMA | J18: 1 | K18: $ | L18: 68595.04 | M18: 0 | N18: 0 | O18: 0 | P18: 14404.96 | Q18: 86429.75
A19: 04/09/2024 | B19: 1 - Factura A | C19: 7 | D19: 3241 | F19: 74364799883128 | G19: CUIT | H19: 20284183534 | I19: FURLANETTO MARTIN | J19: 1 | K19: $ | L19: 4545.5 | M19: 0 | N19: 0 | O19: 0 | P19: 954.56 | Q19: 5500.06
A20: 04/09/2024 | B20: 1 - Factura A | C20: 120 | D20: 4948 | F20: 74365800262038 | G20: CUIT | H20: 30587197215 | I20: PANATEL SOCIEDAD ANONIMA | J20: 1 | K20: $ | L20: 68595.04 | M20: 0 | N20: 0 | O20: 0 | P20: 14404.96 | Q20: 86429.75
A21: 04/09/2024 | B21: 1 - Factura A | C21: 401 | D21: 66 | F21: 74364797895464 | G21: CUIT | H21: 30716234114 | I21: UZUMAKI S.A.S. | J21: 1305 | K21: USD | L21: 129.3 | M21: 0 | N21: 0 | O21: 0 | P21: 27.15 | Q21: 156.45
A22: 05/09/2024 | B22: 1 - Factura A | C22: 2 | D22: 760 | F22: 74369961703669 | G22: CUIT | H22: 20272865869 | I22: DI FEO MARTIN EZEQUIEL | J22: 1 | K22: $ | L22: 84450 | M22: 0 | N22: 0 | O22: 0 | P22: 17734.5 | Q22: 102184.5
A23: 05/09/2024 | B23: 1 - Factura A | C23: 5 | D23: 5331 | F23: 74363959099503 | G23: CUIT | H23: 30715833243 | I23: BIODINAMICA ASISTENCIA S.R.L. | J23: 1 | K23: $ | L23: 22238.59 | M23: 0 | N23: 0 | O23: 0 | P23: 4670.1 | Q23: 26908.69
... A35: 09/09/2024 | B35: 3 - Nota de Crédito A | C35: 5 | D35: 192 | F35: 74376416376753 | G35: CUIT | H35: 30712187316 | I35: ITALOMED PRODUCTOS SRL | J35: 1 | K35: $ | L35: 293619.94 | M35: 0 | N35: 0 | O35: 0 | P35: 61660.19 | Q35: 355280.13
A36: 09/09/2024 | B36: 11 - Factura C | C36: 1 | D36: 148 | F36: 74370408397319 | G36: CUIT | H36: 27338342840 | I36: CANCINO PAMELA RITA | J36: 1 | K36: $ | O36: 0 | Q36: 276800
A37: 10/09/2024 | B37: 1 - Factura A | C37: 2 | D37: 8403 | F37: 74372567359059 | G37: CUIT | H37: 27363810182 | I37: HECKER LAURA NOEMI | J37: 1 | K37: $ | L37: 3635.54 | M37: 0 | N37: 0 | O37: 0 | P37: 763.46 | Q37: 4399
A38: 10/09/2024 | B38: 1 - Factura A | C38: 5 | D38: 31858 | F38: 74370525870493 | G38: CUIT | H38: 30710804830 | I38: ZG MULTITEC SRL | J38: 1 | K38: $ | L38: 29410.86 | M38: 0 | N38: 0 | O38: 0 | P38: 3088.14 | Q38: 32499
A39: 10/09/2024 | B39: 1 - Factura A | C39: 8 | D39: 1684 | F39: 74371529941038 | G39: CUIT | H39: 30708973501 | I39: ASIAL S.R.L. | J39: 1 | K39: $ | L39: 740255 | M39: 0 | N39: 0 | O39: 0 | P39: 155453.55 | Q39: 895708.55
A40: 10/09/2024 | B40: 1 - Factura A | C40: 3 | D40: 4250 | F40: 74378552751950 | G40: CUIT | H40: 20184052858 | I40: ABOUD PABLO DANIEL | J40: 1 | K40: $ | L40: 16859.48 | M40: 0 | N40: 0 | O40: 0 | P40: 3540.49 | Q40: 20399.95
A41: 10/09/2024 | B41: 11 - Factura C | C41: 3 | D41: 986 | F41: 74379527477577 | G41: CUIT | H41: 20216451679 | I41: VAZQUEZ RICARDO OSCAR | J41: 1 | K41: $ | O41: 0 | Q41: 86000
A42: 11/09/2024 | B42: 1 - Factura A | C42: 1 | D42: 2468 | F42: 74379681409704 | G42: CUIT | H42: 30717179389 | I42: NICOLAS TOBIAS SEQUEIRA Y MARIA GABRIELA RATTNER SOCIEDAD DE LA SECCION IV LGS | J42: 1 | K42: $ | L42: 82644.62 | M42: 0 | N42: 0 | O42: 0 | P42: 17355.37 | Q42: 99999.99
A43: 11/09/2024 | B43: 1 - Factura A | C43: 5 | D43: 3378 | F43: 74379704726153 | G43: CUIT | H43: 30717179389 | I43: NICOLAS TOBIAS SEQUEIRA Y MARIA GABRIELA RATTNER SOCIEDAD DE LA SECCION IV LGS | J43: 1 | K43: $ | L43: 82644.63 | M43: 0 | N43: 0 | O43: 0 | P43: 17355.37 | Q43: 100000
A44: 11/09/2024 | B44: 1 - Factura A | C44: 3 | D44: 7676 | F44: 74379686794320 | G44: CUIT | H44: 33708218699 | I44: MANGGINI PABLO Y MANGGINI ULISES SOC. DE HECHO. | J44: 1 | K44: $ | L44: 15000 | M44: 0 | N44: 0 | O44: 0 | P44: 3150 | Q44: 18150
A45: 11/09/2024 | B45: 11 - Factura C | C45: 1 | D45: 9 | F45: 74373677716509 | G45: CUIT | H45: 20464199633 | I45: OVIEDO JIMENEZ TIZIANO LIONEL | J45: 1 | K45: $ | O45: 0 | Q45: 499950
A46: 12/09/2024 | B46: 1 - Factura A | C46: 2 | D46: 778 | F46: 74379814460759 | G46: CUIT | H46: 20272865869 | I46: DI FEO MARTIN EZEQUIEL | J46: 1 | K46: $ | L46: 128100 | M46: 0 | N46: 0 | O46: 0 | P46: 26901 | Q46: 155001
A47: 12/09/2024 | B47: 1 - Factura A | C47: 4 | D47: 38394 | F47: 74379814609856 | G47: CUIT | H47: 20289111329 | I47: LEDESMA EMILIANO RUBEN | J47: 1 | K47: $ | L47: 585730.8 | M47: 0 | N47: 0 | O47: 0 | P47: 123003.47 | Q47: 708734.27
A48: 12/09/2024 | B48: 1 - Factura A | C48: 5 | D48: 1915 | F48: 74376761404173 | G48: CUIT | H48: 30712187316 | I48: ITALOMED PRODUCTOS SRL | J48: 1 | K48: $ | L48: 254033.05 | M48: 0 | N48: 0 | O48: 0 | P48: 53346.94 | Q48: 307379.99
A49: 12/09/2024 | B49: 1 - Factura A | C49: 5 | D49: 1916 | F49: 74376766353942 | G49: CUIT | H49: 30712187316 | I49: ITALOMED PRODUCTOS SRL | J49: 1 | K49: $ | L49: 472751.65 | M49: 0 | N49: 0 | O49: 0 | P49: 99277.85 | Q49: 572029.5
A50: 13/09/2024 | B50: 1 - Factura A | C50: 1 | D50: 4620 | F50: 74371942773283 | G50: CUIT | H50: 30715141201 | I50: REHAB S.R.L. | J50: 1 | K50: $ | L50: 29295 | M50: 0 | N50: 0 | O50: 0 | P50: 6151.95 | Q50: 35446.95
A51: 13/09/2024 | B51: 1 - Factura A | C51: 5 | D51: 1920 | F51: 74376932362480 | G51: CUIT | H51: 30712187316 | I51: ITALOMED PRODUCTOS SRL | J51: 1 | K51: $ | L51: 34718.6 | M51: 0 | N51: 0 | O51: 0 | P51: 7290.91 | Q51: 42009.51
...

Sheet Hoja3
A1: Comprobante no recibido
A4: Fecha | B4: Comprobante | C4: Nombre | D4: Cond. IVA | E4: CUIT o Doc. | F4: Gravado | G4: No Gravado
A5: 02/09/2024 | B5: FA-C 0003-00000874 | C5: BOTINDARI JUAN CARLOS | D5: Responsable Monotributo | E5: 20086277523 | F5: 0 | G5: 275500
A6: 02/09/2024 | B6: 874 | C6: BOTINDARI JUAN CARLOS | E6: 20086277523
A7: 19/09/2024 | B7: FA-A 0007-00006066 | C7: Triveño Roma, Ramon | D7: IVA Responsable Inscripto | E7: 20131067446 | F7: 278865.6 | G7: 0
A8: 19/09/2024 | B8: 6066 | C8: TRIVEÑO ROMA RAMON | E8: 20131067446 | F8: 278865.6 | G8: 0
A9: 10/09/2024 | B9: FA-A 0003-00004250 | C9: Aboud, Pablo Daniel | D9: IVA Responsable Inscripto | E9: 20184052858 | F9: 16859.46 | G9: 0
A10: 30/09/2024 | B10: FA-A 0003-00004276 | C10: Aboud, Pablo Daniel | D10: IVA Responsable Inscripto | E10: 20184052858 | F10: 71074.3 | G10: 0
A11: 10/09/2024 | B11: 4250 | C11: ABOUD PABLO DANIEL | E11: 20184052858 | F11: 16859.48 | G11: 0
A12: 30/09/2024 | B12: 4276 | C12: ABOUD PABLO DANIEL | E12: 20184052858 | F12: 71074.33 | G12: 0
A13: 30/09/2024 | B13: 804 | C13: PAIS HECTOR GUILLERMO | E13: 20214946867 | F13: 37189.24 | G13: 0
A14: 10/09/2024 | B14: FA-C 0003-00000986 | C14: Vazquez, Ricardo Oscar | D14: Responsable Monotributo | E14: 20216451679 | F14: 0 | G14: 86000
A15: 27/09/2024 | B15: FA-C 0003-00000995 | C15: Vazquez, Ricardo Oscar | D15: Responsable Monotributo | E15: 20216451679 | F15: 0 | G15: 160000
A16: 10/09/2024 | B16: 986 | C16: VAZQUEZ RICARDO OSCAR | E16: 20216451679
A17: 19/09/2024 | B17: 991 | C17: VAZQUEZ RICARDO OSCAR | E17: 20216451679
A18: 27/09/2024 | B18: 995 | C18: VAZQUEZ RICARDO OSCAR | E18: 20216451679
A19: 12/09/2024 | B19: FA-A 0002-00000778 | C19: Di Feo, Martin Ezequiel | D19: IVA Responsable Inscripto | E19: 20272865869 | F19: 128100 | G19: 0
A20: 13/09/2024 | B20: FA-A 0002-00000783 | C20: Di Feo, Martin Ezequiel | D20: IVA Responsable Inscripto | E20: 20272865869 | F20: 9950 | G20: 0
A21: 19/09/2024 | B21: FA-A 0002-00000796 | C21: Di Feo, Martin Ezequiel | D21: IVA Responsable Inscripto | E21: 20272865869 | F21: 253100 | G21: 0
A22: 27/09/2024 | B22: FA-A 0002-00000816 | C22: Di Feo, Martin Ezequiel | D22: IVA Responsable Inscripto | E22: 20272865869 | F22: 9800 | G22: 0
A23: 27/09/2024 | B23: FA-A 0002-00000819 | C23: Di Feo, Martin Ezequiel | D23: IVA Responsable Inscripto | E23: 20272865869 | F23: 105000 | G23: 0
A24: 30/09/2024 | B24: FA-A 0002-00000814 | C24: Di Feo, Martin Ezequiel | D24: IVA Responsable Inscripto | E24: 20272865869 | F24: 149150 | G24: 0
A25: 05/09/2024 | B25: 760 | C25: DI FEO MARTIN EZEQUIEL | E25: 20272865869 | F25: 84450 | G25: 0
A26: 12/09/2024 | B26: 778 | C26: DI FEO MARTIN EZEQUIEL | E26: 20272865869 | F26: 128100 | G26: 0
A27: 13/09/2024 | B27: 783 | C27: DI FEO MARTIN EZEQUIEL | E27: 20272865869 | F27: 9950 | G27: 0
A28: 19/09/2024 | B28: 796 | C28: DI FEO MARTIN EZEQUIEL | E28: 20272865869 | F28: 253100 | G28: 0
A29: 26/09/2024 | B29: 814 | C29: DI FEO MARTIN EZEQUIEL | E29: 20272865869 | F29: 149150 | G29: 0
A30: 27/09/2024 | B30: 816 | C30: DI FEO MARTIN EZEQUIEL | E30: 20272865869 | F30: 9800 | G30: 0
A31: 27/09/2024 | B31: 819 | C31: DI FEO MARTIN EZEQUIEL | E31: 20272865869 | F31: 105000 | G31: 0
A32: 04/09/2024 | B32: FA-A 0007-00003241 | C32: Furlanetto, Martin | D32: IVA Responsable Inscripto | E32: 20284183534 | F32: 4545.5 | G32: 0
A33: 26/09/2024 | B33: TF-A0007-00003292 | C33: Furlanetto, Martin | D33: IVA Responsable Inscripto | E33: 20284183534 | F33: 9504.13 | G33: 0
A34: 04/09/2024 | B34: 3241 | C34: FURLANETTO MARTIN | E34: 20284183534 | F34: 4545.5 | G34: 0
A35: 26/09/2024 | B35: 3292 | C35: FURLANETTO MARTIN | E35: 20284183534 | F35: 9504.13 | G35: 0
A36: 12/09/2024 | B36: FA-A 0004-00038394 | C36: Ledesma, Emiliano Ruben | D36: IVA Responsable Inscripto | E36: 20289111329 | F36: 585730.8 | G36: 0
A37: 12/09/2024 | B37: 38394 | C37: LEDESMA EMILIANO RUBEN | E37: 20289111329 | F37: 585730.8 | G37: 0
A38: 20/09/2024 | B38: FA-A 0004-00000136 | C38: Villalba, Miguel Angel | D38: IVA Responsable Inscripto | E38: 20317488476 | F38: 1870000 | G38: 0
A39: 25/09/2024 | B39: FA-A 0004-00000137 | C39: Villalba, Miguel Angel | D39: IVA Responsable Inscripto | E39: 20317488476 | F39: 105000 | G39: 0
A40: 20/09/2024 | B40: 136 | C40: VILLALBA MIGUEL ANGEL | E40: 20317488476 | F40: 1870000 | G40: 0
A41: 25/09/2024 | B41: 137 | C41: VILLALBA MIGUEL ANGEL | E41: 20317488476 | F41: 105000 | G41: 0
A42: 13/09/2024 | B42: NC-A 0003-00000017 | C42: Nardomarino, Ezequiel Eduardo | D42: IVA Responsable Inscripto | E42: 20334976433 | F42: -188330 | G42: 0
...

Sheet Ventas 10
L2: =+SUBTOTAL(109,L7:L507) -> 57506519
A5: Mis Comprobantes Emitidos - CUIT 30710473168
A6: Fecha | B6: Tipo | C6: Punto de Venta | D6: Número Desde | E6: Número Hasta | F6: Cód. Autorización | G6: Tipo Doc. Receptor | H6: Nro. Doc. Receptor | I6: Denominación Receptor | J6: Tipo Cambio | K6: Moneda | L6: Imp. Neto Gravado | M6: Imp. Neto No Gravado | N6: Imp. Op. Exentas | O6: Otros Tributos | P6: IVA | Q6: Imp. Total
A7: 01/10/2024 | B7: 1 - Factura A | C7: 3 | D7: 2122 | F7: 74408937567460 | G7: CUIT | H7: 30522428163 | I7: GALENO ARGENTINA SOCIEDAD ANONIMA | J7: 1 | K7: $ | L7: 166023.57 | M7: 0 | N7: 0 | O7: 0 | P7: 34864.95 | Q7: 200888.54
A8: 01/10/2024 | B8: 1 - Factura A | C8: 3 | D8: 2123 | F8: 74408946814467 | G8: CUIT | H8: 30522428163 | I8: GALENO ARGENTINA SOCIEDAD ANONIMA | J8: 1 | K8: $ | L8: 122793.38 | M8: 0 | N8: 0 | O8: 0 | P8: 25786.61 | Q8: 148580
A9: 01/10/2024 | B9: 201 - Factura de Crédito electrónica MiPyMEs (FCE) A | C9: 3 | D9: 20 | F9: 74408946246916 | G9: CUIT | H9: 30522428163 | I9: GALENO ARGENTINA SOCIEDAD ANONIMA | J9: 1 | K9: $ | L9: 1159994.8 | M9: 0 | N9: 0 | O9: 0 | P9: 243598.9 | Q9: 1403593.6
A10: 01/10/2024 | B10: 201 - Factura de Crédito electrónica MiPyMEs (FCE) A | C10: 3 | D10: 17 | F10: 74408933316107 | G10: CUIT | H10: 30522428163 | I10: GALENO ARGENTINA SOCIEDAD ANONIMA | J10: 1 | K10: $ | L10: 9940284.7 | M10: 0 | N10: 0 | O10: 0 | P10: 2087459.8 | Q10: 12027744
A11: 01/10/2024 | B11: 201 - Factura de Crédito electrónica MiPyMEs (FCE) A | C11: 3 | D11: 18 | F11: 74408933881734 | G11: CUIT | H11: 30522428163 | I11: GALENO ARGENTINA SOCIEDAD ANONIMA | J11: 1 | K11: $ | L11: 1605012.1 | M11: 0 | N11: 0 | O11: 0 | P11: 337052.55 | Q11: 1942064.7
A12: 01/10/2024 | B12: 201 - Factura de Crédito electrónica MiPyMEs (FCE) A | C12: 3 | D12: 19 | F12: 74408938388545 | G12: CUIT | H12: 30522428163 | I12: GALENO ARGENTINA SOCIEDAD ANONIMA | J12: 1 | K12: $ | L12: 1420287.4 | M12: 0 | N12: 0 | O12: 0 | P12: 298260.35 | Q12: 1718547.7
A13: 01/10/2024 | B13: 6 - Factura B | C13: 9 | D13: 1 | F13: 74408943763770 | G13: 99 | H13: 0 | J13: 1 | K13: $ | L13: 1 | M13: 0 | N13: 0 | O13: 0 | P13: 0.21 | Q13: 1.21
A14: 03/10/2024 | B14: 6 - Factura B | C14: 8 | D14: 1 | F14: 74408170661661 | G14: 99 | H14: 0 | J14: 1 | K14: $ | L14: 8264.46 | M14: 0 | N14: 0 | O14: 0 | P14: 1735.54 | Q14: 10000
A15: 01/10/2024 | B15: 6 - Factura B | C15: 9 | D15: 2 | F15: 74408957430844 | G15: 99 | H15: 0 | J15: 1 | K15: $ | L15: 20661.16 | M15: 0 | N15: 0 | O15: 0 | P15: 4338.84 | Q15: 25000
A16: 03/10/2024 | B16: 6 - Factura B | C16: 8 | D16: 2 | F16: 74408171180167 | G16: 99 | H16: 0 | J16: 1 | K16: $ | L16: 6198.35 | M16: 0 | N16: 0 | O16: 0 | P16: 1301.65 | Q16: 7500
A17: 02/10/2024 | B17: 6 - Factura B | C17: 9 | D17: 3 | F17: 74408038377697 | G17: 99 | H17: 0 | J17: 1 | K17: $ | L17: 11487.6 | M17: 0 | N17: 0 | O17: 0 | P17: 2412.4 | Q17: 13900
A18: 03/10/2024 | B18: 6 - Factura B | C18: 8 | D18: 3 | F18: 74408175059410 | G18: 99 | H18: 0 | J18: 1 | K18: $ | L18: 21487.6 | M18: 0 | N18: 0 | O18: 0 | P18: 4512.4 | Q18: 26000
A19: 02/10/2024 | B19: 6 - Factura B | C19: 9 | D19: 4 | F19: 74408040307745 | G19: 99 | H19: 0 | J19: 1 | K19: $ | L19: 23471.07 | M19: 0 | N19: 0 | O19: 0 | P19: 4928.93 | Q19: 28400
A20: 03/10/2024 | B20: 6 - Factura B | C20: 8 | D20: 4 | F20: 74408178473241 | G20: 99 | H20: 0 | J20: 1 | K20: $ | L20: 20661.16 | M20: 0 | N20: 0 | O20: 0 | P20: 4338.84 | Q20: 25000
A21: 02/10/2024 | B21: 6 - Factura B | C21: 9 | D21: 5 | F21: 74408041595038 | G21: 99 | H21: 0 | J21: 1 | K21: $ | L21: 23966.94 | M21: 0 | N21: 0 | O21: 0 | P21: 5033.06 | Q21: 29000
A22: 03/10/2024 | B22: 6 - Factura B | C22: 8 | D22: 5 | F22: 74408179334943 | G22: 99 | H22: 0 | J22: 1 | K22: $ | L22: 4462.81 | M22: 0 | N22: 0 | O22: 0 | P22: 937.19 | Q22: 5400
A23: 02/10/2024 | B23: 6 - Factura B | C23: 9 | D23: 6 | F23: 74408042545709 | G23: 99 | H23: 0 | J23: 1 | K23: $ | L23: 26446.28 | M23: 0 | N23: 0 | O23: 0 | P23: 5553.72 | Q23: 32000
A24: 03/10/2024 | B24: 6 - Factura B | C24: 8 | D24: 6 | F24: 74408181398159 | G24: 99 | H24: 0 | J24: 1 | K24: $ | L24: 21487.6 | M24: 0 | N24: 0 | O24: 0 | P24: 4512.4 | Q24: 26000
... A50: 24/10/2024 | B50: 6 - Factura B | C50: 8 | D50: 19 | F50: 74438605807968 | G50: 99 | H50: 0 | J50: 1 | K50: $ | L50: 21487.6 | M50: 0 | N50: 0 | O50: 0 | P50: 4512.4 | Q50: 26000
A51: 01/10/2024 | B51: 8 - Nota de Crédito B | C51: 7 | D51: 160 | F51: 74408958958205 | G51: 99 | H51: 0 | J51: 1 | K51: $ | L51: -1 | M51: 0 | N51: 0 | O51: 0 | P51: =+L51*0.21 -> -0.21 | Q51: =+SUM(L51+P51) -> -1.21
A52: 02/10/2024 | B52: 1 - Factura A | C52: 7 | D52: 2167 | F52: 74408103654758 | G52: CUIT | H52: 30522428163 | I52: GALENO ARGENTINA SOCIEDAD ANONIMA | J52: 1 | K52: $ | L52: 94164.44 | M52: 0 | N52: 0 | O52: 0 | P52: 19774.53 | Q52: 113938.97
A53: 07/10/2024 | B53: 6 - Factura B | C53: 9 | D53: 20 | F53: 74418695581613 | G53: 99 | H53: 0 | J53: 1 | K53: $ | L53: 7024.79 | M53: 0 | N53: 0 | O53: 0 | P53: 1475.21 | Q53: 8500
A54: 24/10/2024 | B54: 6 - Factura B | C54: 8 | D54: 20 | F54: 74438607760579 | G54: 99 | H54: 0 | J54: 1 | K54: $ | L54: 29338.84 | M54: 0 | N54: 0 | O54: 0 | P54: 6161.16 | Q54: 35500
A55: 07/10/2024 | B55: 6 - Factura B | C55: 9 | D55: 21 | F55: 74418696494142 | G55: 99 | H55: 0 | J55: 1 | K55: $ | L55: 28099.17 | M55: 0 | N55: 0 | O55: 0 | P55: 5900.83 | Q55: 34000
A56: 24/10/2024 | B56: 6 - Factura B | C56: 8 | D56: 21 | F56: 74438612802737 | G56: 99 | H56: 0 | J56: 1 | K56: $ | L56: 10743.8 | M56: 0 | N56: 0 | O56: 0 | P56: 2256.2 | Q56: 13000
A57: 08/10/2024 | B57: 6 - Factura B | C57: 9 | D57: 22 | F57: 74418764489879 | G57: 99 | H57: 0 | J57: 1 | K57: $ | L57: 8595.04 | M57: 0 | N57: 0 | O57: 0 | P57: 1804.96 | Q57: 10400
A58: 24/10/2024 | B58: 6 - Factura B | C58: 8 | D58: 22 | F58: 74438617156130 | G58: 99 | H58: 0 | J58: 1 | K58: $ | L58: 11487.6 | M58: 0 | N58: 0 | O58: 0 | P58: 2412.4 | Q58: 13900
A59: 08/10/2024 | B59: 6 - Factura B | C59: 9 | D59: 23 | F59: 74418769740159 | G59: 99 | H59: 0 | J59: 1 | K59: $ | L59: 10743.8 | M59: 0 | N59: 0 | O59: 0 | P59: 2256.2 | Q59: 13000
A60: 24/10/2024 | B60: 6 - Factura B | C60: 8 | D60: 23 | F60: 74438639281565 | G60: 99 | H60: 0 | J60: 1 | K60: $ | L60: 4958.68 | M60: 0 | N60: 0 | O60: 0 | P60: 1041.32 | Q60: 6000
A61: 08/10/2024 | B61: 6 - Factura B | C61: 9 | D61: 24 | F61: 74418771754336 | G61: 99 | H61: 0 | J61: 1 | K61: $ | L61: 44628.1 | M61: 0 | N61: 0 | O61: 0 | P61: 9371.9 | Q61: 54000
A62: 24/10/2024 | B62: 6 - Factura B | C62: 8 | D62: 24 | F62: 74438643080056 | G62: 99 | H62: 0 | J62: 1 | K62: $ | L62: 8264.46 | M62: 0 | N62: 0 | O62: 0 | P62: 1735.54 | Q62: 10000
A63: 08/10/2024 | B63: 6 - Factura B | C63: 9 | D63: 25 | F63: 74418773946085 | G63: 99 | H63: 0 | J63: 1 | K63: $ | L63: 8595.04 | M63: 0 | N63: 0 | O63: 0 | P63: 1804.96 | Q63: 10400
A64: 24/10/2024 | B64: 6 - Factura B | C64: 8 | D64: 25 | F64: 74438648684078 | G64: 99 | H64: 0 | J64: 1 | K64: $ | L64: 21487.6 | M64: 0 | N64: 0 | O64: 0 | P64: 4512.4 | Q64: 26000
... A88: 10/10/2024 | B88: 6 - Factura B | C88: 9 | D88: 48 | F88: 74418040577125 | G88: 99 | H88: 0 | J88: 1 | K88: $ | L88: 10743.8 | M88: 0 | N88: 0 | O88: 0 | P88: 2256.2 | Q88: 13000
A89: 04/10/2024 | B89: 1 - Factura A | C89: 7 | D89: 2168 | F89: 74408316978690 | G89: CUIT | H89: 30715186655 | I89: AMPARO SALUD S.R.L. | J89: 1 | K89: $ | L89: 474097.79 | M89: 0 | N89: 0 | O89: 0 | P89: 99560.54 | Q89: 573658.33
A90: 04/10/2024 | B90: 1 - Factura A | C90: 7 | D90: 2169 | F90: 74408319440955 | G90: CUIT | H90: 30590412631 | I90: OBRA SOCIAL DEL SINDICATO DE MECANICOS Y AFINES DEL TRANSPORTE AUTOMOTOR | J90: 1 | K90: $ | L90: 411570.25 | M90: 0 | N90: 0 | O90: 0 | P90: 86429.75 | Q90: 498000
A91: 04/10/2024 | B91: 1 - Factura A | C91: 7 | D91: 2170 | F91: 74408321803168 | G91: CUIT | H91: 30500053522 | I91: OBRA SOCIAL DE LA ACTIVIDAD DE SEGUROS, REASEGUROS, CAPITALIZACION Y AHORRO Y PRESTAMO PARA LA VIVI | J91: 1 | K91: $ | L91: 65950.41 | M91: 0 | N91: 0 | O91: 0 | P91: 13849.59 | Q91: 79800
...

Sheet Resumen Ventas 10
A1: Totales por Tipo de Comprobante - AFIP
B2: Base | C2: IVA | D2: Otros Imp. | E2: Total Compr.
A3: (FCE) A | B3: 24190611 | C3: =+B3*0.21 -> 5080028.4 | E3: =SUM(B3:D3) -> 29270640
A4: NC FCE A | B4: 0 | C4: =+B4*0.21 -> 0 | E4: =SUM(B4:D4) -> 0
A5: FACTURAS A | B5: 9798831 | C5: =+B5*0.21 -> 2057754.5 | E5: =SUM(B5:D5) -> 11856586
A6: NC A | B6: -513274.69 | C6: =+B6*0.21 -> -107787.68 | E6: =SUM(B6:D6) -> -621062.37
A7: FACTURAS B | B7: 24269479 | C7: =+B7*0.21 -> 5096590.6 | E7: =SUM(B7:D7) -> 29366070
A8: NC B | B8: -239128.26 | C8: =+B8*0.21 -> -50216.935 | E8: =SUM(B8:D8) -> -289345.19
B9: =SUM(B3:B8) -> 57506519 | C9: =SUM(C3:C8) -> 12076369 | D9: 0 | E9: =SUM(E3:E8) -> 69582887
