Workbook

Sheet Lista_CUIT
A1: CUIT | B1: RAZON SOCIAL | C1: Tipo de Gasto | D1: PROVINCIA
A2: 30575019524 | B2: 100000 LAMPARAS SRL | G2: Mercaderia
A3: 30709829730 | B3: 4KRC SA | C3: Mantenimiento | G3: Servicios Gas, Luz, etc.
A4: 30715223704 | B4: 5 CEPAS S.R.L. | C4: MERCADERIA | G4: Gastos catering
A5: 30714869937 | B5: 60 LIBRAS SRL | G5: Combustibe
A6: 30692212130 | B6: A R C CONSTRUCCIONES S.A. | G6: Gastos Varios
A7: 30687722007 | B7: A. RUSSONIELLO SA | C7: SERVICIOS | G7: Gastos seguridad
A8: 30503874497 | B8: A.M. PESCIO S.C.A | C8: Mercaderia | G8: Librería
A9: 30702017498 | B9: ABBS POINT DESING S.A. | G9: Gastos mantenimiento
A10: 20182999661 | B10: ABEL JAVIER KLAINER | C10: Mercaderia | G10: Gastos comercializacion
A11: 30652000076 | B11: ABELSON SA | C11: Mercaderia | G11: Alquiler
A12: 30690536079 | B12: ACCESOR SRL | C12: Gastos Varios | G12: Honorarios contables
A13: 30515585415 | B13: ACEROSALFA SA | C13: Mercaderia | G13: Gastos administrativos
A14: 33711942659 | B14: ACLOS ASOC. CIVIL PARA LA LONG | C14: Mercaderia | G14: Seguro
A15: 30715243349 | B15: ADSE S.A | G15: Extracto
A16: 20174004146 | B16: ADUEARDO FRANCISCO NARDOMARINO | C16: Mercaderia | G16: Flete
A17: 30708555548 | B17: AGH S.A | C17: Mercaderia | G17: Honorarios Legales
A18: 30708263342 | B18: AGRACO S.A | C18: MERCADERIA | G18: Insumo
A19: 30709565075 | B19: AGUA Y SANEAMIENTOS ARG SA | C19: SERVICIOS | G19: Muebles y Utiles
A20: 30500229973 | B20: AKIAN GRAFICA EDITORA SA | C20: Mercaderia | G20: Otros
A21: 30710799241 | B21: ALANAR S.R.L. | G21: Telefonia
A22: 20236101127 | B22: ALEJANDRO DARIO LOPEZ | G22: Alojamiento-Varios
A23: 20291929126 | B23: ALEJANDRO MIGUEL DAUBLER
A24: 30709604887 | B24: ALFABIS SRL. | C24: Mantenimiento
A25: 20083925680 | B25: ALFREDO DANIEL FERNANDEZ | C25: Gastos Varios
A26: 30656038752 | B26: ALFREDO OMAR POTENZA SRL | C26: Mercaderia
A27: 30504563894 | B27: ALI HERMANOS SRL | C27: Mercaderia
A28: 30602699826 | B28: ALKO SRL
A29: 30715190385 | B29: ALL FEDERAL SA.
A30: 23945042079 | B30: ALVARENGA VILLAR LUIS F | C30: Gastos Varios
A31: 20040616498 | B31: ALVAREZ MARCELINO
A32: 30710587147 | B32: AMAKOR SA | C32: SERVICIOS
A33: 30663288497 | B33: AMX ARG SA
A34: 27108310559 | B34: ANA MARIA VALDEZ
A35: 30502375535 | B35: ANAVI S.C.A.
A36: 30709251739 | B36: ANDES LINEAS AEREAS SA
A37: 30709948667 | B37: ANTAGGER SRL | C37: Mercaderia
A38: 30683702060 | B38: ANTARES INDUST. ORTOP SA | C38: Mercaderia
A39: 30715985124 | B39: ANTOLFO S.R.L.
A40: 30714344656 | B40: AQUALAF S.A. | C40: Mercaderia
...

Sheet Abr-24
B1: LIBRO IVA COMPRAS | G1: CORITEC S. R. L. | N1: 45017
B3: TOTAL COMPRAS NETAS | G3: TOTAL CREDITO FISCAL | J3: TOTAL VENTAS NETAS | M3: TOTAL DEBITO FISCAL | P3: RESULTADO
B4: =SUM('Abr-24'!$H$37)+'Abr-24'!$G$54 -> 5732005.1 | G4: ='Abr-24'!$I$37+'Abr-24'!$J$37+'Abr-24'!$K$37+I55 -> 1194453.8 | J4: ='Abr-24'!$H$88+'Abr-24'!$H$98 -> 49918615 | M4: ='Abr-24'!$I$88+'Abr-24'!$J$88+'Abr-24'!$I$98+'Abr-24'!$J$98 -> 5303236.8 | P4: =G4-M4 -> -4108783
B8: FECHA | C8: TIPO | D8: PTO VTA | E8: NRO. CPTE | F8: CUIT | G8: RAZON SOCIAL | H8: NETO GRAVADO | I8: IVA 21 % | J8: IVA 27% | K8: IVA 10,5% | L8: PERC. IVA | M8: PERC IIBB BS AS | N8: PERC. IIBB CABA | O8: Otros / No Grav. | P8: TOTAL | Q8: Tipo de Gasto | R8: Provincia
B9: 45412 | C9: 1 | D9: 6 | E9: 14602 | F9: 30707756434 | G9: =IFERROR(IF('Abr-24'!$F9="","-",VLOOKUP('Abr-24'!$F9,Lista_CUIT!$A$1:$D$2241,2,0)),"CUIT NO CARGADO") -> SERVICIO INTEGRAL DE LIMPIEZA SRL | H9: 204000 | I9: ='Abr-24'!$H9*0.21 -> 42840 | P9: =SUM('Abr-24'!$H9:$O9) -> 246840 | Q9: =IFERROR(IF('Abr-24'!$F9="","-",VLOOKUP('Abr-24'!$F9,Lista_CUIT!$A$1:$D$2241,3,0)),"CUIT NO CARGADO") -> Mantenimiento | R9: =IFERROR(IF('Abr-24'!$F9="","-",VLOOKUP('Abr-24'!$F9,Lista_CUIT!$A$1:$D$2241,4,0)),"CUIT NO CARGADO") -> 0
B10: 45400 | C10: 1 | D10: 2 | E10: 197 | F10: 20125142851 | G10: =IFERROR(IF('Abr-24'!$F10="","-",VLOOKUP('Abr-24'!$F10,Lista_CUIT!$A$1:$D$2241,2,0)),"CUIT NO CARGADO") -> FEDERICI NICOLAS JOSE | H10: 319464.15 | I10: ='Abr-24'!$H10*0.21 -> 67087.471 | P10: =SUM('Abr-24'!$H10:$O10) -> 386551.62 | Q10: =IFERROR(IF('Abr-24'!$F10="","-",VLOOKUP('Abr-24'!$F10,Lista_CUIT!$A$1:$D$2241,3,0)),"CUIT NO CARGADO") -> INSUMO | R10: =IFERROR(IF('Abr-24'!$F10="","-",VLOOKUP('Abr-24'!$F10,Lista_CUIT!$A$1:$D$2241,4,0)),"CUIT NO CARGADO") -> 0
B11: 45400 | C11: 1 | D11: 2 | E11: 196 | F11: 20125142851 | G11: =IFERROR(IF('Abr-24'!$F11="","-",VLOOKUP('Abr-24'!$F11,Lista_CUIT!$A$1:$D$2241,2,0)),"CUIT NO CARGADO") -> FEDERICI NICOLAS JOSE | H11: 1234920.6 | I11: ='Abr-24'!$H11*0.21 -> 259333.33 | P11: =SUM('Abr-24'!$H11:$O11) -> 1494253.9 | Q11: =IFERROR(IF('Abr-24'!$F11="","-",VLOOKUP('Abr-24'!$F11,Lista_CUIT!$A$1:$D$2241,3,0)),"CUIT NO CARGADO") -> INSUMO | R11: =IFERROR(IF('Abr-24'!$F11="","-",VLOOKUP('Abr-24'!$F11,Lista_CUIT!$A$1:$D$2241,4,0)),"CUIT NO CARGADO") -> 0
B12: 45393 | C12: 1 | D12: 2 | E12: 2710 | F12: 30709131733 | G12: =IFERROR(IF('Abr-24'!$F12="","-",VLOOKUP('Abr-24'!$F12,Lista_CUIT!$A$1:$D$2241,2,0)),"CUIT NO CARGADO") -> DIGAS SRL | H12: 2758040 | I12: ='Abr-24'!$H12*0.21 -> 579188.4 | P12: =SUM('Abr-24'!$H12:$O12) -> 3337228.4 | Q12: =IFERROR(IF('Abr-24'!$F12="","-",VLOOKUP('Abr-24'!$F12,Lista_CUIT!$A$1:$D$2241,3,0)),"CUIT NO CARGADO") -> INSUMO | R12: =IFERROR(IF('Abr-24'!$F12="","-",VLOOKUP('Abr-24'!$F12,Lista_CUIT!$A$1:$D$2241,4,0)),"CUIT NO CARGADO") -> 0
B13: 45394 | C13: 1 | D13: 2 | E13: 686 | F13: 30718019814 | G13: =IFERROR(IF('Abr-24'!$F13="","-",VLOOKUP('Abr-24'!$F13,Lista_CUIT!$A$1:$D$2241,2,0)),"CUIT NO CARGADO") -> ALDO MOVILE S. CAP I SECC IV | H13: 28224.78 | I13: ='Abr-24'!$H13*0.21 -> 5927.2038 | P13: =SUM('Abr-24'!$H13:$O13) -> 34151.984 | Q13: =IFERROR(IF('Abr-24'!$F13="","-",VLOOKUP('Abr-24'!$F13,Lista_CUIT!$A$1:$D$2241,3,0)),"CUIT NO CARGADO") -> INSUMO | R13: =IFERROR(IF('Abr-24'!$F13="","-",VLOOKUP('Abr-24'!$F13,Lista_CUIT!$A$1:$D$2241,4,0)),"CUIT NO CARGADO") -> 0
B14: 45383 | C14: 1 | D14: 3 | E14: 223848 | F14: 30707135596 | G14: =IFERROR(IF('Abr-24'!$F14="","-",VLOOKUP('Abr-24'!$F14,Lista_CUIT!$A$1:$D$2241,2,0)),"CUIT NO CARGADO") -> CITILAN ARGENTINA S.A. | H14: 15510 | I14: ='Abr-24'!$H14*0.21 -> 3257.1 | P14: =SUM('Abr-24'!$H14:$O14) -> 18767.1 | Q14: =IFERROR(IF('Abr-24'!$F14="","-",VLOOKUP('Abr-24'!$F14,Lista_CUIT!$A$1:$D$2241,3,0)),"CUIT NO CARGADO") -> Telefonia | R14: =IFERROR(IF('Abr-24'!$F14="","-",VLOOKUP('Abr-24'!$F14,Lista_CUIT!$A$1:$D$2241,4,0)),"CUIT NO CARGADO") -> 0
B15: 45383 | C15: 1 | D15: 3 | E15: 744 | F15: 30715402765 | G15: =IFERROR(IF('Abr-24'!$F15="","-",VLOOKUP('Abr-24'!$F15,Lista_CUIT!$A$1:$D$2241,2,0)),"CUIT NO CARGADO") -> RIO 265 S.R.L. | H15: 43801.66 | I15: ='Abr-24'!$H15*0.21 -> 9198.3486 | P15: =SUM('Abr-24'!$H15:$O15) -> 53000.009 | Q15: =IFERROR(IF('Abr-24'!$F15="","-",VLOOKUP('Abr-24'!$F15,Lista_CUIT!$A$1:$D$2241,3,0)),"CUIT NO CARGADO") -> GASTOS VARIOS | R15: =IFERROR(IF('Abr-24'!$F15="","-",VLOOKUP('Abr-24'!$F15,Lista_CUIT!$A$1:$D$2241,4,0)),"CUIT NO CARGADO") -> 0
B16: 45391 | C16: 1 | D16: 1 | E16: 1126 | F16: 30717763692 | G16: =IFERROR(IF('Abr-24'!$F16="","-",VLOOKUP('Abr-24'!$F16,Lista_CUIT!$A$1:$D$2241,2,0)),"CUIT NO CARGADO") -> IGNISMOTORREDUCTORES S. A. | H16: 38016.53 | I16: ='Abr-24'!$H16*0.21 -> 7983.4713 | P16: =SUM('Abr-24'!$H16:$O16) -> 46000.001 | Q16: =IFERROR(IF('Abr-24'!$F16="","-",VLOOKUP('Abr-24'!$F16,Lista_CUIT!$A$1:$D$2241,3,0)),"CUIT NO CARGADO") -> INSUMO | R16: =IFERROR(IF('Abr-24'!$F16="","-",VLOOKUP('Abr-24'!$F16,Lista_CUIT!$A$1:$D$2241,4,0)),"CUIT NO CARGADO") -> 0
B17: 45390 | C17: 1 | D17: 3 | E17: 308 | F17: 20921575743 | G17: =IFERROR(IF('Abr-24'!$F17="","-",VLOOKUP('Abr-24'!$F17,Lista_CUIT!$A$1:$D$2241,2,0)),"CUIT NO CARGADO") -> RIOS GOMEZ JOSE ANTONIO | H17: 447500 | I17: ='Abr-24'!$H17*0.21 -> 93975 | P17: =SUM('Abr-24'!$H17:$O17) -> 541475 | Q17: =IFERROR(IF('Abr-24'!$F17="","-",VLOOKUP('Abr-24'!$F17,Lista_CUIT!$A$1:$D$2241,3,0)),"CUIT NO CARGADO") -> Papeleria | R17: =IFERROR(IF('Abr-24'!$F17="","-",VLOOKUP('Abr-24'!$F17,Lista_CUIT!$A$1:$D$2241,4,0)),"CUIT NO CARGADO") -> 0
B18: 45409 | C18: 1 | D18: 31 | E18: 41586 | F18: 30715209833 | G18: =IFERROR(IF('Abr-24'!$F18="","-",VLOOKUP('Abr-24'!$F18,Lista_CUIT!$A$1:$D$2241,2,0)),"CUIT NO CARGADO") -> GIFEL SRL | H18: 52429.75 | I18: ='Abr-24'!$H18*0.21 -> 11010.247 | P18: =SUM('Abr-24'!$H18:$O18) -> 63439.997 | Q18: =IFERROR(IF('Abr-24'!$F18="","-",VLOOKUP('Abr-24'!$F18,Lista_CUIT!$A$1:$D$2241,3,0)),"CUIT NO CARGADO") -> Gastos Oficina | R18: =IFERROR(IF('Abr-24'!$F18="","-",VLOOKUP('Abr-24'!$F18,Lista_CUIT!$A$1:$D$2241,4,0)),"CUIT NO CARGADO") -> 0
B19: 45406 | C19: 1 | D19: 31 | E19: 41286 | F19: 30715209833 | G19: =IFERROR(IF('Abr-24'!$F19="","-",VLOOKUP('Abr-24'!$F19,Lista_CUIT!$A$1:$D$2241,2,0)),"CUIT NO CARGADO") -> GIFEL SRL | H19: 43561.98 | I19: ='Abr-24'!$H19*0.21 -> 9148.0158 | P19: =SUM('Abr-24'!$H19:$O19) -> 52709.996 | Q19: =IFERROR(IF('Abr-24'!$F19="","-",VLOOKUP('Abr-24'!$F19,Lista_CUIT!$A$1:$D$2241,3,0)),"CUIT NO CARGADO") -> Gastos Oficina | R19: =IFERROR(IF('Abr-24'!$F19="","-",VLOOKUP('Abr-24'!$F19,Lista_CUIT!$A$1:$D$2241,4,0)),"CUIT NO CARGADO") -> 0
B20: 45404 | C20: 1 | D20: 4 | E20: 164 | F20: 30715863916 | G20: =IFERROR(IF('Abr-24'!$F20="","-",VLOOKUP('Abr-24'!$F20,Lista_CUIT!$A$1:$D$2241,2,0)),"CUIT NO CARGADO") -> BULONERA SUR SA | H20: 5173.55 | I20: ='Abr-24'!$H20*0.21 -> 1086.4455 | P20: =SUM('Abr-24'!$H20:$O20) -> 6259.9955 | Q20: =IFERROR(IF('Abr-24'!$F20="","-",VLOOKUP('Abr-24'!$F20,Lista_CUIT!$A$1:$D$2241,3,0)),"CUIT NO CARGADO") -> Ferreteria | R20: =IFERROR(IF('Abr-24'!$F20="","-",VLOOKUP('Abr-24'!$F20,Lista_CUIT!$A$1:$D$2241,4,0)),"CUIT NO CARGADO") -> 0
... B26: 45408 | C26: 1 | D26: 5 | E26: 47 | F26: 27224574679 | G26: =IFERROR(IF('Abr-24'!$F26="","-",VLOOKUP('Abr-24'!$F26,Lista_CUIT!$A$1:$D$2241,2,0)),"CUIT NO CARGADO") -> FERNANDEZ MARCELA ELIZABETH | H26: 18081.6 | I26: ='Abr-24'!$H26*0.21 -> 3797.136 | P26: =SUM('Abr-24'!$H26:$O26) -> 21878.736 | Q26: =IFERROR(IF('Abr-24'!$F26="","-",VLOOKUP('Abr-24'!$F26,Lista_CUIT!$A$1:$D$2241,3,0)),"CUIT NO CARGADO") -> GASTOS VARIOS | R26: =IFERROR(IF('Abr-24'!$F26="","-",VLOOKUP('Abr-24'!$F26,Lista_CUIT!$A$1:$D$2241,4,0)),"CUIT NO CARGADO") -> 0
B27: 02/04/2024 | C27: 1 | D27: 30 | E27: 128138 | F27: 30695056342 | G27: =IFERROR(IF('Abr-24'!$F27="","-",VLOOKUP('Abr-24'!$F27,Lista_CUIT!$A$1:$D$2241,2,0)),"CUIT NO CARGADO") -> AVENIDA MAIPU 4199 S C S | H27: 18238.84 | I27: ='Abr-24'!$H27*0.21 -> 3830.1564 | P27: =SUM('Abr-24'!$H27:$O27) -> 22068.996 | Q27: =IFERROR(IF('Abr-24'!$F27="","-",VLOOKUP('Abr-24'!$F27,Lista_CUIT!$A$1:$D$2241,3,0)),"CUIT NO CARGADO") -> Seg e Higiene | R27: =IFERROR(IF('Abr-24'!$F27="","-",VLOOKUP('Abr-24'!$F27,Lista_CUIT!$A$1:$D$2241,4,0)),"CUIT NO CARGADO") -> 0
B28: 07/04/2024 | C28: 1 | D28: 6 | E28: 2292 | F28: 27236006250 | G28: =IFERROR(IF('Abr-24'!$F28="","-",VLOOKUP('Abr-24'!$F28,Lista_CUIT!$A$1:$D$2241,2,0)),"CUIT NO CARGADO") -> LOKER MARISA TERESITA | H28: 8047.52 | I28: ='Abr-24'!$H28*0.21 -> 1689.9792 | P28: =SUM('Abr-24'!$H28:$O28) -> 9737.4992 | Q28: =IFERROR(IF('Abr-24'!$F28="","-",VLOOKUP('Abr-24'!$F28,Lista_CUIT!$A$1:$D$2241,3,0)),"CUIT NO CARGADO") -> GASTOS VARIOS | R28: =IFERROR(IF('Abr-24'!$F28="","-",VLOOKUP('Abr-24'!$F28,Lista_CUIT!$A$1:$D$2241,4,0)),"CUIT NO CARGADO") -> 0
B29: 08/04/2024 | C29: 1 | D29: 700 | E29: 643864 | F29: 30580111315 | G29: =IFERROR(IF('Abr-24'!$F29="","-",VLOOKUP('Abr-24'!$F29,Lista_CUIT!$A$1:$D$2241,2,0)),"CUIT NO CARGADO") -> DHL EXPRESS (ARGENTINA) S.A. | H29: 13222.5 | I29: ='Abr-24'!$H29*0.21 -> 2776.725 | O29: 545154.86 | P29: =SUM('Abr-24'!$H29:$O29) -> 561154.08 | Q29: =IFERROR(IF('Abr-24'!$F29="","-",VLOOKUP('Abr-24'!$F29,Lista_CUIT!$A$1:$D$2241,3,0)),"CUIT NO CARGADO") -> Gastos Importacion | R29: =IFERROR(IF('Abr-24'!$F29="","-",VLOOKUP('Abr-24'!$F29,Lista_CUIT!$A$1:$D$2241,4,0)),"CUIT NO CARGADO") -> 0
B30: 11/04/2024 | C30: 1 | D30: 2466 | E30: 636157 | F30: 30678814357 | G30: =IFERROR(IF('Abr-24'!$F30="","-",VLOOKUP('Abr-24'!$F30,Lista_CUIT!$A$1:$D$2241,2,0)),"CUIT NO CARGADO") -> TELEFONICA MOVILES ARG | H30: 17540 | J30: ='Abr-24'!$H30*0.27 -> 4735.8 | L30: 526.2 | O30: 923.15 | P30: =SUM('Abr-24'!$H30:$O30) -> 23725.15 | Q30: =IFERROR(IF('Abr-24'!$F30="","-",VLOOKUP('Abr-24'!$F30,Lista_CUIT!$A$1:$D$2241,3,0)),"CUIT NO CARGADO") -> Telefonia | R30: =IFERROR(IF('Abr-24'!$F30="","-",VLOOKUP('Abr-24'!$F30,Lista_CUIT!$A$1:$D$2241,4,0)),"CUIT NO CARGADO") -> 0
B31: 22/04/2024 | C31: 1 | D31: 3 | E31: 334487 | F31: 33643358749 | G31: =IFERROR(IF('Abr-24'!$F31="","-",VLOOKUP('Abr-24'!$F31,Lista_CUIT!$A$1:$D$2241,2,0)),"CUIT NO CARGADO") -> POLYTECH S A | H31: 52487.78 | K31: ='Abr-24'!$H31*0.105 -> 5511.2169 | P31: =SUM('Abr-24'!$H31:$O31) -> 57998.997 | Q31: =IFERROR(IF('Abr-24'!$F31="","-",VLOOKUP('Abr-24'!$F31,Lista_CUIT!$A$1:$D$2241,3,0)),"CUIT NO CARGADO") -> Servicios Informaticos | R31: =IFERROR(IF('Abr-24'!$F31="","-",VLOOKUP('Abr-24'!$F31,Lista_CUIT!$A$1:$D$2241,4,0)),"CUIT NO CARGADO") -> 0
B32: 24/04/2024 | C32: 1 | D32: 3 | E32: 334743 | F32: 33643358749 | G32: =IFERROR(IF('Abr-24'!$F32="","-",VLOOKUP('Abr-24'!$F32,Lista_CUIT!$A$1:$D$2241,2,0)),"CUIT NO CARGADO") -> POLYTECH S A | H32: 45794.57 | K32: ='Abr-24'!$H32*0.105 -> 4808.4298 | P32: =SUM('Abr-24'!$H32:$O32) -> 50603 | Q32: =IFERROR(IF('Abr-24'!$F32="","-",VLOOKUP('Abr-24'!$F32,Lista_CUIT!$A$1:$D$2241,3,0)),"CUIT NO CARGADO") -> Servicios Informaticos | R32: =IFERROR(IF('Abr-24'!$F32="","-",VLOOKUP('Abr-24'!$F32,Lista_CUIT!$A$1:$D$2241,4,0)),"CUIT NO CARGADO") -> 0
B33: 29/04/2024 | C33: 1 | D33: 106 | E33: 729129 | F33: 30594494187 | G33: =IFERROR(IF('Abr-24'!$F33="","-",VLOOKUP('Abr-24'!$F33,Lista_CUIT!$A$1:$D$2241,2,0)),"CUIT NO CARGADO") -> FEDERAL EXPRESS CORPORATION | H33: 0 | I33: ='Abr-24'!$H33*0.21 -> 0 | P33: =SUM('Abr-24'!$H33:$O33) -> 0 | Q33: =IFERROR(IF('Abr-24'!$F33="","-",VLOOKUP('Abr-24'!$F33,Lista_CUIT!$A$1:$D$2241,3,0)),"CUIT NO CARGADO") -> Gastos Importacion | R33: =IFERROR(IF('Abr-24'!$F33="","-",VLOOKUP('Abr-24'!$F33,Lista_CUIT!$A$1:$D$2241,4,0)),"CUIT NO CARGADO") -> 0
B34: 29/04/2024 | C34: 1 | D34: 3 | E34: 2022 | F34: 20401319930 | G34: =IFERROR(IF('Abr-24'!$F34="","-",VLOOKUP('Abr-24'!$F34,Lista_CUIT!$A$1:$D$2241,2,0)),"CUIT NO CARGADO") -> SANTORO FRANCO TOMAS | H34: 23243.8 | I34: ='Abr-24'!$H34*0.21 -> 4881.198 | P34: =SUM('Abr-24'!$H34:$O34) -> 28124.998 | Q34: =IFERROR(IF('Abr-24'!$F34="","-",VLOOKUP('Abr-24'!$F34,Lista_CUIT!$A$1:$D$2241,3,0)),"CUIT NO CARGADO") -> Catering | R34: =IFERROR(IF('Abr-24'!$F34="","-",VLOOKUP('Abr-24'!$F34,Lista_CUIT!$A$1:$D$2241,4,0)),"CUIT NO CARGADO") -> 0
B35: 45411 | C35: 1 | D35: 700 | E35: 651894 | F35: 30580111315 | G35: =IFERROR(IF('Abr-24'!$F35="","-",VLOOKUP('Abr-24'!$F35,Lista_CUIT!$A$1:$D$2241,2,0)),"CUIT NO CARGADO") -> DHL EXPRESS (ARGENTINA) S.A. | I35: ='Abr-24'!$H35*0.21 -> 0 | O35: 274547.4 | P35: =SUM('Abr-24'!$H35:$O35) -> 274547.4 | Q35: =IFERROR(IF('Abr-24'!$F35="","-",VLOOKUP('Abr-24'!$F35,Lista_CUIT!$A$1:$D$2241,3,0)),"CUIT NO CARGADO") -> Gastos Importacion | R35: =IFERROR(IF('Abr-24'!$F35="","-",VLOOKUP('Abr-24'!$F35,Lista_CUIT!$A$1:$D$2241,4,0)),"CUIT NO CARGADO") -> 0
G36: =IFERROR(IF('Abr-24'!$F36="","-",VLOOKUP('Abr-24'!$F36,Lista_CUIT!$A$1:$D$2241,2,0)),"CUIT NO CARGADO") -> - | I36: ='Abr-24'!$H36*0.21 -> 0 | P36: =SUM('Abr-24'!$H36:$O36) -> 0 | Q36: =IFERROR(IF('Abr-24'!$F36="","-",VLOOKUP('Abr-24'!$F36,Lista_CUIT!$A$1:$D$2241,3,0)),"CUIT NO CARGADO") -> - | R36: =IFERROR(IF('Abr-24'!$F36="","-",VLOOKUP('Abr-24'!$F36,Lista_CUIT!$A$1:$D$2241,4,0)),"CUIT NO CARGADO") -> -
B37: Total | H37: =SUBTOTAL(109,'Abr-24'!$H$9:$H$36) -> 5488346.6 | I37: =SUBTOTAL(109,'Abr-24'!$I$9:$I$36) -> 1128230.1 | J37: =SUBTOTAL(109,'Abr-24'!$J$9:$J$36) -> 4735.8 | K37: =SUBTOTAL(109,'Abr-24'!$K$9:$K$36) -> 10319.647 | L37: =SUBTOTAL(109,'Abr-24'!$L$9:$L$36) -> 526.2 | M37: =SUBTOTAL(109,'Abr-24'!$M$9:$M$36) -> 0 | N37: =SUBTOTAL(109,'Abr-24'!$N$9:$N$36) -> 0 | O37: =SUBTOTAL(109,'Abr-24'!$O$9:$O$36) -> 820625.41 | P37: =SUBTOTAL(109,'Abr-24'!$P$9:$P$36) -> 7452783.7
D42: LIQUIDACION EXTRACTOS BANCARIOS-TARJETAS
D43: FECHA | E43: NRO CPTE | F43: BANCO | G43: NETO | H43: IVA 21% | I43: IVA 10,5% | J43: RET IIBB CABA | K43: PERC IVA | L43: PERC IIBB | M43: total
D44: 45386 | E44: 1070357000 | G44: 8615 | H44: ='Abr-24'!$G44*0.21 -> 1809.15 | J44: 258.45 | M44: ='Abr-24'!$G44+'Abr-24'!$H44+'Abr-24'!$I44+'Abr-24'!$J44+'Abr-24'!$K44 -> 10682.6
D45: 45405 | E45: 825-879664 | F45: BIENES EXPORTADOS | G45: 65400 | H45: ='Abr-24'!$G45*0.21 -> 13734 | J45: 1962 | M45: ='Abr-24'!$G45+'Abr-24'!$H45+'Abr-24'!$I45+'Abr-24'!$J45+'Abr-24'!$K45 -> 81096
D46: 45399 | E46: 825-880947 | F46: BIENES EXPORTADOS | G46: 65137.5 | H46: ='Abr-24'!$G46*0.21 -> 13678.875 | J46: 1954.13 | M46: ='Abr-24'!$G46+'Abr-24'!$H46+'Abr-24'!$I46+'Abr-24'!$J46+'Abr-24'!$K46 -> 80770.505
D47: 45393 | E47: 980902000 | F47: COMISION POR AFECTACION SAOFE | G47: 21637.5 | H47: ='Abr-24'!$G47*0.21 -> 4543.875 | J47: 649.13 | M47: ='Abr-24'!$G47+'Abr-24'!$H47+'Abr-24'!$I47+'Abr-24'!$J47+'Abr-24'!$K47 -> 26830.505
D48: 45394 | E48: 980927000 | F48: COMISION POR AFECTACION SAOFE | G48: 21662.5 | H48: ='Abr-24'!$G48*0.21 -> 4549.125 | J48: 649.88 | M48: ='Abr-24'!$G48+'Abr-24'!$H48+'Abr-24'!$I48+'Abr-24'!$J48+'Abr-24'!$K48 -> 26861.505
D49: 45406 | E49: 1073108000 | F49: SEGUIMIENTO PERMISOS DE EMBARQUE | G49: 21825 | H49: ='Abr-24'!$G49*0.21 -> 4583.25 | J49: 654.75 | M49: ='Abr-24'!$G49+'Abr-24'!$H49+'Abr-24'!$I49+'Abr-24'!$J49+'Abr-24'!$K49 -> 27063
F50: BANCO CREDICOOP | G50: 38981 | H50: ='Abr-24'!$G50*0.21 -> 8186.01 | K50: 1036.13 | M50: ='Abr-24'!$G50+'Abr-24'!$H50+'Abr-24'!$I50+'Abr-24'!$J50+'Abr-24'!$K50 -> 48203.14
F51: BANCO CREDICOOP | G51: 400 | H51: ='Abr-24'!$G51*0.21 -> 84 | J51: 53.74 | M51: ='Abr-24'!$G51+'Abr-24'!$H51+'Abr-24'!$I51+'Abr-24'!$J51+'Abr-24'!$K51 -> 537.74
H52: ='Abr-24'!$G52*0.21 -> 0 | M52: ='Abr-24'!$G52+'Abr-24'!$H52+'Abr-24'!$I52+'Abr-24'!$J52+'Abr-24'!$K52 -> 0
H53: ='Abr-24'!$G53*0.21 -> 0 | M53: ='Abr-24'!$G53+'Abr-24'!$H53+'Abr-24'!$I53+'Abr-24'!$J53+'Abr-24'!$K53 -> 0
...

Sheet May-24
B1: LIBRO IVA COMPRAS | G1: ='Abr-24'!G1:M1 -> CORITEC S. R. L. | N1: 45413
B3: TOTAL COMPRAS | G3: TOTAL CREDITO FISCAL | J3: TOTAL VENTAS NETAS | M3: TOTAL DEBITO FISCAL | P3: RESULTADO
B4: =SUM('May-24'!$H$42)+'May-24'!$G$55 -> 10136411 | G4: ='May-24'!$I$42+'May-24'!$J$42+'May-24'!$K$42+'May-24'!$H$55+'May-24'!$I$55 -> 2130006.9 | J4: =SUM('May-24'!$H$104+'May-24'!$H$116) -> 85616903 | M4: =SUM('May-24'!$I$104+'May-24'!$J$104+'May-24'!$I$116+'May-24'!$J$116) -> 10862134 | P4: =G4-M4 -> -8732126.9
B8: FECHA | C8: TIPO | D8: PTO VTA | E8: NRO. CPTE | F8: CUIT | G8: RAZON SOCIAL | H8: NETO GRAVADO | I8: IVA 21 % | J8: IVA 27% | K8: IVA 10,5% | L8: PERC. IVA | M8: PERC IIBB BS AS | N8: PERC. IIBB CABA | O8: Otros / No Grav. | P8: TOTAL | Q8: Tipo de Gasto | R8: Provincia
B9: 45413 | C9: 1 | D9: 3 | E9: 227312 | F9: 30707135596 | G9: =IFERROR(IF('May-24'!$F9="","-",VLOOKUP('May-24'!$F9,Lista_CUIT!$A$1:$D$2241,2,0)),"CUIT NO CARGADO") -> CITILAN ARGENTINA S.A. | H9: 18742.75 | I9: =IF('May-24'!$H9="","",'May-24'!$H9*0.21) -> 3935.9775 | P9: =SUM('May-24'!$H9:$O9) -> 22678.728 | Q9: =IFERROR(IF('May-24'!$F9="","-",VLOOKUP('May-24'!$F9,Lista_CUIT!$A$1:$D$2241,3,0)),"CUIT NO CARGADO") -> Telefonia | R9: =IFERROR(IF('May-24'!$F9="","-",VLOOKUP('May-24'!$F9,Lista_CUIT!$A$1:$D$2241,4,0)),"CUIT NO CARGADO") -> 0
B10: 45413 | C10: 1 | D10: 3 | E10: 753 | F10: 30715402765 | G10: =IFERROR(IF('May-24'!$F10="","-",VLOOKUP('May-24'!$F10,Lista_CUIT!$A$1:$D$2241,2,0)),"CUIT NO CARGADO") -> RIO 265 S.R.L. | H10: 49586.76 | I10: =IF('May-24'!$H10="","",'May-24'!$H10*0.21) -> 10413.22 | P10: =SUM('May-24'!$H10:$O10) -> 59999.98 | Q10: =IFERROR(IF('May-24'!$F10="","-",VLOOKUP('May-24'!$F10,Lista_CUIT!$A$1:$D$2241,3,0)),"CUIT NO CARGADO") -> GASTOS VARIOS | R10: =IFERROR(IF('May-24'!$F10="","-",VLOOKUP('May-24'!$F10,Lista_CUIT!$A$1:$D$2241,4,0)),"CUIT NO CARGADO") -> 0
B11: 45414 | C11: 1 | D11: 4 | E11: 101074 | F11: 30559932236 | G11: =IFERROR(IF('May-24'!$F11="","-",VLOOKUP('May-24'!$F11,Lista_CUIT!$A$1:$D$2241,2,0)),"CUIT NO CARGADO") -> ELECTRONICA ELEMON S A | H11: 44562.34 | I11: =IF('May-24'!$H11="","",'May-24'!$H11*0.21) -> 9358.0914 | P11: =SUM('May-24'!$H11:$O11) -> 53920.431 | Q11: =IFERROR(IF('May-24'!$F11="","-",VLOOKUP('May-24'!$F11,Lista_CUIT!$A$1:$D$2241,3,0)),"CUIT NO CARGADO") -> Mat. Prima | R11: =IFERROR(IF('May-24'!$F11="","-",VLOOKUP('May-24'!$F11,Lista_CUIT!$A$1:$D$2241,4,0)),"CUIT NO CARGADO") -> 0
B12: 45414 | C12: 1 | D12: 1 | E12: 786 | F12: 30715048066 | G12: =IFERROR(IF('May-24'!$F12="","-",VLOOKUP('May-24'!$F12,Lista_CUIT!$A$1:$D$2241,2,0)),"CUIT NO CARGADO") -> ROLLS Y EMPANADAS SA | H12: 600510 | I12: =IF('May-24'!$H12="","",'May-24'!$H12*0.21) -> 126107.1 | P12: =SUM('May-24'!$H12:$O12) -> 726617.1 | Q12: =IFERROR(IF('May-24'!$F12="","-",VLOOKUP('May-24'!$F12,Lista_CUIT!$A$1:$D$2241,3,0)),"CUIT NO CARGADO") -> CATERING | R12: =IFERROR(IF('May-24'!$F12="","-",VLOOKUP('May-24'!$F12,Lista_CUIT!$A$1:$D$2241,4,0)),"CUIT NO CARGADO") -> 0
B13: 45414 | C13: 1 | D13: 3 | E13: 124 | F13: 20297899830 | G13: =IFERROR(IF('May-24'!$F13="","-",VLOOKUP('May-24'!$F13,Lista_CUIT!$A$1:$D$2241,2,0)),"CUIT NO CARGADO") -> FUNK MATIAS NICOLAS | H13: 5188880 | I13: =IF('May-24'!$H13="","",'May-24'!$H13*0.21) -> 1089664.8 | P13: =SUM('May-24'!$H13:$O13) -> 6278544.8 | Q13: =IFERROR(IF('May-24'!$F13="","-",VLOOKUP('May-24'!$F13,Lista_CUIT!$A$1:$D$2241,3,0)),"CUIT NO CARGADO") -> INSUMO | R13: =IFERROR(IF('May-24'!$F13="","-",VLOOKUP('May-24'!$F13,Lista_CUIT!$A$1:$D$2241,4,0)),"CUIT NO CARGADO") -> 0
B14: 45416 | C14: 1 | D14: 11 | E14: 1508 | F14: 27249663870 | G14: =IFERROR(IF('May-24'!$F14="","-",VLOOKUP('May-24'!$F14,Lista_CUIT!$A$1:$D$2241,2,0)),"CUIT NO CARGADO") -> GRAZIANO TAMARA NATALIA | H14: 19981.49 | I14: =IF('May-24'!$H14="","",'May-24'!$H14*0.21) -> 4196.1129 | P14: =SUM('May-24'!$H14:$O14) -> 24177.603 | Q14: =IFERROR(IF('May-24'!$F14="","-",VLOOKUP('May-24'!$F14,Lista_CUIT!$A$1:$D$2241,3,0)),"CUIT NO CARGADO") -> Servicios Informaticos | R14: =IFERROR(IF('May-24'!$F14="","-",VLOOKUP('May-24'!$F14,Lista_CUIT!$A$1:$D$2241,4,0)),"CUIT NO CARGADO") -> 0
B15: 45416 | C15: 1 | D15: 8 | E15: 3167 | F15: 30715247077 | G15: =IFERROR(IF('May-24'!$F15="","-",VLOOKUP('May-24'!$F15,Lista_CUIT!$A$1:$D$2241,2,0)),"CUIT NO CARGADO") -> MALATEX S.R.L. | H15: 27263.64 | I15: =IF('May-24'!$H15="","",'May-24'!$H15*0.21) -> 5725.3644 | P15: =SUM('May-24'!$H15:$O15) -> 32989.004 | Q15: =IFERROR(IF('May-24'!$F15="","-",VLOOKUP('May-24'!$F15,Lista_CUIT!$A$1:$D$2241,3,0)),"CUIT NO CARGADO") -> Ropa de Trabajo | R15: =IFERROR(IF('May-24'!$F15="","-",VLOOKUP('May-24'!$F15,Lista_CUIT!$A$1:$D$2241,4,0)),"CUIT NO CARGADO") -> 0
B16: 45418 | C16: 1 | D16: 2 | E16: 545 | F16: 30716952408 | G16: =IFERROR(IF('May-24'!$F16="","-",VLOOKUP('May-24'!$F16,Lista_CUIT!$A$1:$D$2241,2,0)),"CUIT NO CARGADO") -> MATECH IMPORT ARGENTINA SAS | H16: 5784.3 | I16: =IF('May-24'!$H16="","",'May-24'!$H16*0.21) -> 1214.703 | P16: =SUM('May-24'!$H16:$O16) -> 6999.003 | Q16: =IFERROR(IF('May-24'!$F16="","-",VLOOKUP('May-24'!$F16,Lista_CUIT!$A$1:$D$2241,3,0)),"CUIT NO CARGADO") -> software | R16: =IFERROR(IF('May-24'!$F16="","-",VLOOKUP('May-24'!$F16,Lista_CUIT!$A$1:$D$2241,4,0)),"CUIT NO CARGADO") -> 0
B17: 45418 | C17: 1 | D17: 100 | E17: 4344 | F17: 30562265844 | G17: =IFERROR(IF('May-24'!$F17="","-",VLOOKUP('May-24'!$F17,Lista_CUIT!$A$1:$D$2241,2,0)),"CUIT NO CARGADO") -> LA MADRILEÑA SOCIEDAD ANONIMA COMERCIAL INDUSTRIAL AGROPECUARIA FINANCIERA E INMOBILIARIA | H17: 69421.49 | I17: =IF('May-24'!$H17="","",'May-24'!$H17*0.21) -> 14578.513 | P17: =SUM('May-24'!$H17:$O17) -> 84000.003 | Q17: =IFERROR(IF('May-24'!$F17="","-",VLOOKUP('May-24'!$F17,Lista_CUIT!$A$1:$D$2241,3,0)),"CUIT NO CARGADO") -> Ropa de Trabajo | R17: =IFERROR(IF('May-24'!$F17="","-",VLOOKUP('May-24'!$F17,Lista_CUIT!$A$1:$D$2241,4,0)),"CUIT NO CARGADO") -> 0
B18: 45418 | C18: 1 | D18: 4 | E18: 15738 | F18: 33717112119 | G18: =IFERROR(IF('May-24'!$F18="","-",VLOOKUP('May-24'!$F18,Lista_CUIT!$A$1:$D$2241,2,0)),"CUIT NO CARGADO") -> PREVENSIS S.R.L. | H18: 16252.06 | I18: =IF('May-24'!$H18="","",'May-24'!$H18*0.21) -> 3412.9326 | P18: =SUM('May-24'!$H18:$O18) -> 19664.993 | Q18: =IFERROR(IF('May-24'!$F18="","-",VLOOKUP('May-24'!$F18,Lista_CUIT!$A$1:$D$2241,3,0)),"CUIT NO CARGADO") -> GASTOS VARIOS | R18: =IFERROR(IF('May-24'!$F18="","-",VLOOKUP('May-24'!$F18,Lista_CUIT!$A$1:$D$2241,4,0)),"CUIT NO CARGADO") -> 0
B19: 45419 | C19: 1 | D19: 3 | E19: 42639 | F19: 30715235419 | G19: =IFERROR(IF('May-24'!$F19="","-",VLOOKUP('May-24'!$F19,Lista_CUIT!$A$1:$D$2241,2,0)),"CUIT NO CARGADO") -> SIFEGA COMPANY | H19: 27825.62 | I19: =IF('May-24'!$H19="","",'May-24'!$H19*0.21) -> 5843.3802 | P19: =SUM('May-24'!$H19:$O19) -> 33669 | Q19: =IFERROR(IF('May-24'!$F19="","-",VLOOKUP('May-24'!$F19,Lista_CUIT!$A$1:$D$2241,3,0)),"CUIT NO CARGADO") -> INSUMO | R19: =IFERROR(IF('May-24'!$F19="","-",VLOOKUP('May-24'!$F19,Lista_CUIT!$A$1:$D$2241,4,0)),"CUIT NO CARGADO") -> 0
B20: 45420 | C20: 1 | D20: 16 | E20: 21955 | F20: 30708508221 | G20: =IFERROR(IF('May-24'!$F20="","-",VLOOKUP('May-24'!$F20,Lista_CUIT!$A$1:$D$2241,2,0)),"CUIT NO CARGADO") -> HERRAJES VEIGA | H20: 6701.02 | I20: =IF('May-24'!$H20="","",'May-24'!$H20*0.21) -> 1407.2142 | P20: =SUM('May-24'!$H20:$O20) -> 8108.2342 | Q20: =IFERROR(IF('May-24'!$F20="","-",VLOOKUP('May-24'!$F20,Lista_CUIT!$A$1:$D$2241,3,0)),"CUIT NO CARGADO") -> mercaderia | R20: =IFERROR(IF('May-24'!$F20="","-",VLOOKUP('May-24'!$F20,Lista_CUIT!$A$1:$D$2241,4,0)),"CUIT NO CARGADO") -> 0
... B22: 45420 | C22: 1 | D22: 2 | E22: 3462 | F22: 30710878974 | G22: =IFERROR(IF('May-24'!$F22="","-",VLOOKUP('May-24'!$F22,Lista_CUIT!$A$1:$D$2241,2,0)),"CUIT NO CARGADO") -> TEBY SRL | H22: 515446 | I22: =IF('May-24'!$H22="","",'May-24'!$H22*0.21) -> 108243.66 | P22: =SUM('May-24'!$H22:$O22) -> 623689.66 | Q22: =IFERROR(IF('May-24'!$F22="","-",VLOOKUP('May-24'!$F22,Lista_CUIT!$A$1:$D$2241,3,0)),"CUIT NO CARGADO") -> Papeleria | R22: =IFERROR(IF('May-24'!$F22="","-",VLOOKUP('May-24'!$F22,Lista_CUIT!$A$1:$D$2241,4,0)),"CUIT NO CARGADO") -> 0
B23: 45423 | C23: 1 | D23: 2466 | E23: 650742 | F23: 30678814357 | G23: =IFERROR(IF('May-24'!$F23="","-",VLOOKUP('May-24'!$F23,Lista_CUIT!$A$1:$D$2241,2,0)),"CUIT NO CARGADO") -> TELEFONICA MOVILES ARG | H23: 22677.35 | J23: ='May-24'!$H23*0.27 -> 6122.8845 | L23: 680.32 | O23: 1138.18 | P23: =SUM('May-24'!$H23:$O23) -> 30618.734 | Q23: =IFERROR(IF('May-24'!$F23="","-",VLOOKUP('May-24'!$F23,Lista_CUIT!$A$1:$D$2241,3,0)),"CUIT NO CARGADO") -> Telefonia | R23: =IFERROR(IF('May-24'!$F23="","-",VLOOKUP('May-24'!$F23,Lista_CUIT!$A$1:$D$2241,4,0)),"CUIT NO CARGADO") -> 0
B24: 45425 | C24: 1 | D24: 9 | E24: 1882 | F24: 30631047145 | G24: =IFERROR(IF('May-24'!$F24="","-",VLOOKUP('May-24'!$F24,Lista_CUIT!$A$1:$D$2241,2,0)),"CUIT NO CARGADO") -> SEMICONDUC. Y COMPON. SRL | H24: 343140 | I24: =IF('May-24'!$H24="","",'May-24'!$H24*0.21) -> 72059.4 | P24: =SUM('May-24'!$H24:$O24) -> 415199.4 | Q24: =IFERROR(IF('May-24'!$F24="","-",VLOOKUP('May-24'!$F24,Lista_CUIT!$A$1:$D$2241,3,0)),"CUIT NO CARGADO") -> Mercaderia | R24: =IFERROR(IF('May-24'!$F24="","-",VLOOKUP('May-24'!$F24,Lista_CUIT!$A$1:$D$2241,4,0)),"CUIT NO CARGADO") -> 0
B25: 45426 | C25: 1 | D25: 8 | E25: 23912 | F25: 30709953482 | G25: =IFERROR(IF('May-24'!$F25="","-",VLOOKUP('May-24'!$F25,Lista_CUIT!$A$1:$D$2241,2,0)),"CUIT NO CARGADO") -> HONRE S.A | H25: 12298.61 | I25: =IF('May-24'!$H25="","",'May-24'!$H25*0.21) -> 2582.7081 | P25: =SUM('May-24'!$H25:$O25) -> 14881.318 | Q25: =IFERROR(IF('May-24'!$F25="","-",VLOOKUP('May-24'!$F25,Lista_CUIT!$A$1:$D$2241,3,0)),"CUIT NO CARGADO") -> GASTOS VARIOS | R25: =IFERROR(IF('May-24'!$F25="","-",VLOOKUP('May-24'!$F25,Lista_CUIT!$A$1:$D$2241,4,0)),"CUIT NO CARGADO") -> 0
B26: 45426 | C26: 1 | D26: 6 | E26: 6245 | F26: 30714743402 | G26: =IFERROR(IF('May-24'!$F26="","-",VLOOKUP('May-24'!$F26,Lista_CUIT!$A$1:$D$2241,2,0)),"CUIT NO CARGADO") -> HERRAMIENTAS DALI SRL | H26: 22512.4 | I26: =IF('May-24'!$H26="","",'May-24'!$H26*0.21) -> 4727.604 | P26: =SUM('May-24'!$H26:$O26) -> 27240.004 | Q26: =IFERROR(IF('May-24'!$F26="","-",VLOOKUP('May-24'!$F26,Lista_CUIT!$A$1:$D$2241,3,0)),"CUIT NO CARGADO") -> REPUESTOS | R26: =IFERROR(IF('May-24'!$F26="","-",VLOOKUP('May-24'!$F26,Lista_CUIT!$A$1:$D$2241,4,0)),"CUIT NO CARGADO") -> 0
B27: 45426 | C27: 1 | D27: 3 | E27: 5725 | F27: 30710585411 | G27: =IFERROR(IF('May-24'!$F27="","-",VLOOKUP('May-24'!$F27,Lista_CUIT!$A$1:$D$2241,2,0)),"CUIT NO CARGADO") -> POSITIF PLANIFIER S.A. | H27: 49725.62 | I27: =IF('May-24'!$H27="","",'May-24'!$H27*0.21) -> 10442.38 | P27: =SUM('May-24'!$H27:$O27) -> 60168 | Q27: =IFERROR(IF('May-24'!$F27="","-",VLOOKUP('May-24'!$F27,Lista_CUIT!$A$1:$D$2241,3,0)),"CUIT NO CARGADO") -> Gastos de Comercializacion | R27: =IFERROR(IF('May-24'!$F27="","-",VLOOKUP('May-24'!$F27,Lista_CUIT!$A$1:$D$2241,4,0)),"CUIT NO CARGADO") -> 0
B28: 45427 | C28: 1 | D28: 8 | E28: 24019 | F28: 30709953482 | G28: =IFERROR(IF('May-24'!$F28="","-",VLOOKUP('May-24'!$F28,Lista_CUIT!$A$1:$D$2241,2,0)),"CUIT NO CARGADO") -> HONRE S.A | H28: 12298.61 | I28: =IF('May-24'!$H28="","",'May-24'!$H28*0.21) -> 2582.7081 | P28: =SUM('May-24'!$H28:$O28) -> 14881.318 | Q28: =IFERROR(IF('May-24'!$F28="","-",VLOOKUP('May-24'!$F28,Lista_CUIT!$A$1:$D$2241,3,0)),"CUIT NO CARGADO") -> GASTOS VARIOS | R28: =IFERROR(IF('May-24'!$F28="","-",VLOOKUP('May-24'!$F28,Lista_CUIT!$A$1:$D$2241,4,0)),"CUIT NO CARGADO") -> 0
B29: 45427 | C29: 1 | D29: 9 | E29: 14039 | F29: 30708600187 | G29: =IFERROR(IF('May-24'!$F29="","-",VLOOKUP('May-24'!$F29,Lista_CUIT!$A$1:$D$2241,2,0)),"CUIT NO CARGADO") -> MAQUINAS Y CONSUMIBLES S.A. | H29: 601160 | I29: =IF('May-24'!$H29="","",'May-24'!$H29*0.21) -> 126243.6 | P29: =SUM('May-24'!$H29:$O29) -> 727403.6 | Q29: =IFERROR(IF('May-24'!$F29="","-",VLOOKUP('May-24'!$F29,Lista_CUIT!$A$1:$D$2241,3,0)),"CUIT NO CARGADO") -> INSUMO | R29: =IFERROR(IF('May-24'!$F29="","-",VLOOKUP('May-24'!$F29,Lista_CUIT!$A$1:$D$2241,4,0)),"CUIT NO CARGADO") -> 0
B30: 45427 | C30: 3 | D30: 8 | E30: 2150 | F30: 30709953482 | G30: =IFERROR(IF('May-24'!$F30="","-",VLOOKUP('May-24'!$F30,Lista_CUIT!$A$1:$D$2241,2,0)),"CUIT NO CARGADO") -> HONRE S.A | H30: -12298.61 | I30: =IF('May-24'!$H30="","",'May-24'!$H30*0.21) -> -2582.7081 | P30: =SUM('May-24'!$H30:$O30) -> -14881.318 | Q30: =IFERROR(IF('May-24'!$F30="","-",VLOOKUP('May-24'!$F30,Lista_CUIT!$A$1:$D$2241,3,0)),"CUIT NO CARGADO") -> GASTOS VARIOS | R30: =IFERROR(IF('May-24'!$F30="","-",VLOOKUP('May-24'!$F30,Lista_CUIT!$A$1:$D$2241,4,0)),"CUIT NO CARGADO") -> 0
B31: 45428 | C31: 1 | D31: 106 | E31: 733821 | F31: 30594494187 | G31: =IFERROR(IF('May-24'!$F31="","-",VLOOKUP('May-24'!$F31,Lista_CUIT!$A$1:$D$2241,2,0)),"CUIT NO CARGADO") -> FEDERAL EXPRESS CORPORATION | H31: 0 | I31: =IF('May-24'!$H31="","",'May-24'!$H31*0.21) -> 0 | O31: 407884.8 | P31: =SUM('May-24'!$H31:$O31) -> 407884.8 | Q31: =IFERROR(IF('May-24'!$F31="","-",VLOOKUP('May-24'!$F31,Lista_CUIT!$A$1:$D$2241,3,0)),"CUIT NO CARGADO") -> Gastos Importacion | R31: =IFERROR(IF('May-24'!$F31="","-",VLOOKUP('May-24'!$F31,Lista_CUIT!$A$1:$D$2241,4,0)),"CUIT NO CARGADO") -> 0
B32: 45432 | C32: 1 | D32: 6 | E32: 782 | F32: 20283509924 | G32: =IFERROR(IF('May-24'!$F32="","-",VLOOKUP('May-24'!$F32,Lista_CUIT!$A$1:$D$2241,2,0)),"CUIT NO CARGADO") -> HEREDIA LEONARDO ADRIAN | H32: 24518.19 | I32: =IF('May-24'!$H32="","",'May-24'!$H32*0.21) -> 5148.8199 | P32: =SUM('May-24'!$H32:$O32) -> 29667.01 | Q32: =IFERROR(IF('May-24'!$F32="","-",VLOOKUP('May-24'!$F32,Lista_CUIT!$A$1:$D$2241,3,0)),"CUIT NO CARGADO") -> INSUMO | R32: =IFERROR(IF('May-24'!$F32="","-",VLOOKUP('May-24'!$F32,Lista_CUIT!$A$1:$D$2241,4,0)),"CUIT NO CARGADO") -> 0
B33: 45434 | C33: 1 | D33: 2 | E33: 8760 | F33: 30711726019 | G33: =IFERROR(IF('May-24'!$F33="","-",VLOOKUP('May-24'!$F33,Lista_CUIT!$A$1:$D$2241,2,0)),"CUIT NO CARGADO") -> MAV GROUP S.A. | H33: 351200 | I33: =IF('May-24'!$H33="","",'May-24'!$H33*0.21) -> 73752 | P33: =SUM('May-24'!$H33:$O33) -> 424952 | Q33: =IFERROR(IF('May-24'!$F33="","-",VLOOKUP('May-24'!$F33,Lista_CUIT!$A$1:$D$2241,3,0)),"CUIT NO CARGADO") -> Gastos Importacion | R33: =IFERROR(IF('May-24'!$F33="","-",VLOOKUP('May-24'!$F33,Lista_CUIT!$A$1:$D$2241,4,0)),"CUIT NO CARGADO") -> 0
B34: 45436 | C34: 1 | D34: 6 | E34: 791 | F34: 20283509924 | G34: =IFERROR(IF('May-24'!$F34="","-",VLOOKUP('May-24'!$F34,Lista_CUIT!$A$1:$D$2241,2,0)),"CUIT NO CARGADO") -> HEREDIA LEONARDO ADRIAN | H34: 49036.38 | I34: =IF('May-24'!$H34="","",'May-24'!$H34*0.21) -> 10297.64 | P34: =SUM('May-24'!$H34:$O34) -> 59334.02 | Q34: =IFERROR(IF('May-24'!$F34="","-",VLOOKUP('May-24'!$F34,Lista_CUIT!$A$1:$D$2241,3,0)),"CUIT NO CARGADO") -> INSUMO | R34: =IFERROR(IF('May-24'!$F34="","-",VLOOKUP('May-24'!$F34,Lista_CUIT!$A$1:$D$2241,4,0)),"CUIT NO CARGADO") -> 0
B35: 45439 | C35: 1 | D35: 3 | E35: 311 | F35: 20921575743 | G35: =IFERROR(IF('May-24'!$F35="","-",VLOOKUP('May-24'!$F35,Lista_CUIT!$A$1:$D$2241,2,0)),"CUIT NO CARGADO") -> RIOS GOMEZ JOSE ANTONIO | H35: 554900 | I35: =IF('May-24'!$H35="","",'May-24'!$H35*0.21) -> 116529 | P35: =SUM('May-24'!$H35:$O35) -> 671429 | Q35: =IFERROR(IF('May-24'!$F35="","-",VLOOKUP('May-24'!$F35,Lista_CUIT!$A$1:$D$2241,3,0)),"CUIT NO CARGADO") -> Papeleria | R35: =IFERROR(IF('May-24'!$F35="","-",VLOOKUP('May-24'!$F35,Lista_CUIT!$A$1:$D$2241,4,0)),"CUIT NO CARGADO") -> 0
B36: 45440 | C36: 1 | D36: 2 | E36: 198 | F36: 20125142851 | G36: =IFERROR(IF('May-24'!$F36="","-",VLOOKUP('May-24'!$F36,Lista_CUIT!$A$1:$D$2241,2,0)),"CUIT NO CARGADO") -> FEDERICI NICOLAS JOSE | H36: 63792.76 | I36: =IF('May-24'!$H36="","",'May-24'!$H36*0.21) -> 13396.48 | P36: =SUM('May-24'!$H36:$O36) -> 77189.24 | Q36: =IFERROR(IF('May-24'!$F36="","-",VLOOKUP('May-24'!$F36,Lista_CUIT!$A$1:$D$2241,3,0)),"CUIT NO CARGADO") -> INSUMO | R36: =IFERROR(IF('May-24'!$F36="","-",VLOOKUP('May-24'!$F36,Lista_CUIT!$A$1:$D$2241,4,0)),"CUIT NO CARGADO") -> 0
B37: 45442 | C37: 1 | D37: 5 | E37: 73679 | F37: 30692857611 | G37: =IFERROR(IF('May-24'!$F37="","-",VLOOKUP('May-24'!$F37,Lista_CUIT!$A$1:$D$2241,2,0)),"CUIT NO CARGADO") -> BAGUI S A | H37: 122817.35 | I37: =IF('May-24'!$H37="","",'May-24'!$H37*0.21) -> 25791.644 | P37: =SUM('May-24'!$H37:$O37) -> 148608.99 | Q37: =IFERROR(IF('May-24'!$F37="","-",VLOOKUP('May-24'!$F37,Lista_CUIT!$A$1:$D$2241,3,0)),"CUIT NO CARGADO") -> INSUMO | R37: =IFERROR(IF('May-24'!$F37="","-",VLOOKUP('May-24'!$F37,Lista_CUIT!$A$1:$D$2241,4,0)),"CUIT NO CARGADO") -> 0
B38: 45443 | C38: 1 | D38: 6 | E38: 14846 | F38: 30707756434 | G38: =IFERROR(IF('May-24'!$F38="","-",VLOOKUP('May-24'!$F38,Lista_CUIT!$A$1:$D$2241,2,0)),"CUIT NO CARGADO") -> SERVICIO INTEGRAL DE LIMPIEZA SRL | H38: 290000 | I38: =IF('May-24'!$H38="","",'May-24'!$H38*0.21) -> 60900 | P38: =SUM('May-24'!$H38:$O38) -> 350900 | Q38: =IFERROR(IF('May-24'!$F38="","-",VLOOKUP('May-24'!$F38,Lista_CUIT!$A$1:$D$2241,3,0)),"CUIT NO CARGADO") -> Mantenimiento | R38: =IFERROR(IF('May-24'!$F38="","-",VLOOKUP('May-24'!$F38,Lista_CUIT!$A$1:$D$2241,4,0)),"CUIT NO CARGADO") -> 0
G39: =IFERROR(IF('May-24'!$F39="","-",VLOOKUP('May-24'!$F39,Lista_CUIT!$A$1:$D$2241,2,0)),"CUIT NO CARGADO") -> - | I39: =IF('May-24'!$H39="","",'May-24'!$H39*0.21) | P39: =SUM('May-24'!$H39:$O39) -> 0 | Q39: =IFERROR(IF('May-24'!$F39="","-",VLOOKUP('May-24'!$F39,Lista_CUIT!$A$1:$D$2241,3,0)),"CUIT NO CARGADO") -> - | R39: =IFERROR(IF('May-24'!$F39="","-",VLOOKUP('May-24'!$F39,Lista_CUIT!$A$1:$D$2241,4,0)),"CUIT NO CARGADO") -> -
G40: =IFERROR(IF('May-24'!$F40="","-",VLOOKUP('May-24'!$F40,Lista_CUIT!$A$1:$D$2241,2,0)),"CUIT NO CARGADO") -> - | I40: =IF('May-24'!$H40="","",'May-24'!$H40*0.21) | P40: =SUM('May-24'!$H40:$O40) -> 0 | Q40: =IFERROR(IF('May-24'!$F40="","-",VLOOKUP('May-24'!$F40,Lista_CUIT!$A$1:$D$2241,3,0)),"CUIT NO CARGADO") -> - | R40: =IFERROR(IF('May-24'!$F40="","-",VLOOKUP('May-24'!$F40,Lista_CUIT!$A$1:$D$2241,4,0)),"CUIT NO CARGADO") -> -
G41: =IFERROR(IF('May-24'!$F41="","-",VLOOKUP('May-24'!$F41,Lista_CUIT!$A$1:$D$2241,2,0)),"CUIT NO CARGADO") -> - | I41: =IF('May-24'!$H41="","",'May-24'!$H41*0.21) | P41: =SUM('May-24'!$H41:$O41) -> 0 | Q41: =IFERROR(IF('May-24'!$F41="","-",VLOOKUP('May-24'!$F41,Lista_CUIT!$A$1:$D$2241,3,0)),"CUIT NO CARGADO") -> - | R41: =IFERROR(IF('May-24'!$F41="","-",VLOOKUP('May-24'!$F41,Lista_CUIT!$A$1:$D$2241,4,0)),"CUIT NO CARGADO") -> -
B42: Total | H42: =SUBTOTAL(109,'May-24'!$H$9:$H$41) -> 10048736 | I42: =SUBTOTAL(109,'May-24'!$I$9:$I$41) -> 2105472.3 | J42: =SUBTOTAL(109,'May-24'!$J$9:$J$41) -> 6122.8845 | K42: =SUBTOTAL(109,'May-24'!$K$9:$K$41) -> 0 | L42: =SUBTOTAL(109,'May-24'!$L$9:$L$41) -> 680.32 | M42: =SUBTOTAL(109,'May-24'!$M$9:$M$41) -> 0 | N42: =SUBTOTAL(109,'May-24'!$N$9:$N$41) -> 0 | O42: =SUBTOTAL(109,'May-24'!$O$9:$O$41) -> 409022.98 | P42: =SUBTOTAL(109,'May-24'!$P$9:$P$41) -> 12570035
D47: LIQUIDACION EXTRACTOS BANCARIOS-TARJETAS
D48: FECHA | E48: NRO CPTE | F48: BANCO | G48: NETO | H48: IVA 21% | I48: IVA 10,5% | J48: RET IIBB CABA | K48: PERC IVA | L48: PERC IIBB
D49: 45432 | F49: CREDICOOP | G49: 22212.5 | H49: ='May-24'!$G49*0.21 -> 4664.625 | K49: 666.38
...

Sheet Jun-24
B1: LIBRO IVA COMPRAS | G1: ='Abr-24'!G1:M1 -> CORITEC S. R. L. | N1: =EDATE('Abr-24'!N1,2) -> 45078
B3: TOTAL COMPRAS | G3: TOTAL CREDITO FISCAL | J3: TOTAL VENTAS NETAS | M3: TOTAL DEBITO FISCAL | P3: RESULTADO
B4: =SUM('Jun-24'!$H$44)+'Jun-24'!$G$54 -> 6085853.2 | G4: ='Jun-24'!$I$44+'Jun-24'!$J$44+'Jun-24'!$K$44+'Jun-24'!$H$54+'Jun-24'!$I$54 -> 1259020 | J4: ='Jun-24'!$H$91+'Jun-24'!$H$102 -> 40888667 | M4: ='Jun-24'!$I$91+'Jun-24'!$J$91+'Jun-24'!$I$102+'Jun-24'!$J$102 -> 4689871.8 | P4: =G4-M4 -> -3430851.9
B8: FECHA | C8: TIPO | D8: PTO VTA | E8: NRO. CPTE | F8: CUIT | G8: RAZON SOCIAL | H8: NETO GRAVADO | I8: IVA 21 % | J8: IVA 27% | K8: IVA 10,5% | L8: PERC. IVA | M8: PERC IIBB BS AS | N8: PERC. IIBB CABA | O8: Otros / No Grav. | P8: TOTAL | Q8: Tipo de Gasto | R8: Provincia
B9: 45444 | C9: 1 | D9: 3 | E9: 228991 | F9: 30707135596 | G9: =IFERROR(IF('Jun-24'!$F9="","-",VLOOKUP('Jun-24'!$F9,Lista_CUIT!$A$1:$D$2241,2,0)),"CUIT NO CARGADO") -> CITILAN ARGENTINA S.A. | H9: 18640 | I9: =IF('Jun-24'!$H9="","",'Jun-24'!$H9*0.21) -> 3914.4 | P9: =SUM('Jun-24'!$H9:$O9) -> 22554.4 | Q9: =IFERROR(IF('Jun-24'!$F9="","-",VLOOKUP('Jun-24'!$F9,Lista_CUIT!$A$1:$D$2241,3,0)),"CUIT NO CARGADO") -> Telefonia | R9: =IFERROR(IF('Jun-24'!$F9="","-",VLOOKUP('Jun-24'!$F9,Lista_CUIT!$A$1:$D$2241,4,0)),"CUIT NO CARGADO") -> 0
B10: 45444 | C10: 1 | D10: 7 | E10: 16187 | F10: 30604413482 | G10: =IFERROR(IF('Jun-24'!$F10="","-",VLOOKUP('Jun-24'!$F10,Lista_CUIT!$A$1:$D$2241,2,0)),"CUIT NO CARGADO") -> BULONERA VIETRI SOCIEDAD DE RESPONSABILIDAD LIMITADA | H10: 96750 | I10: =IF('Jun-24'!$H10="","",'Jun-24'!$H10*0.21) -> 20317.5 | P10: =SUM('Jun-24'!$H10:$O10) -> 117067.5 | Q10: =IFERROR(IF('Jun-24'!$F10="","-",VLOOKUP('Jun-24'!$F10,Lista_CUIT!$A$1:$D$2241,3,0)),"CUIT NO CARGADO") -> INSUMO | R10: =IFERROR(IF('Jun-24'!$F10="","-",VLOOKUP('Jun-24'!$F10,Lista_CUIT!$A$1:$D$2241,4,0)),"CUIT NO CARGADO") -> 0
B11: 45444 | C11: 1 | D11: 3 | E11: 761 | F11: 30715402765 | G11: =IFERROR(IF('Jun-24'!$F11="","-",VLOOKUP('Jun-24'!$F11,Lista_CUIT!$A$1:$D$2241,2,0)),"CUIT NO CARGADO") -> RIO 265 S.R.L. | H11: 54545.48 | I11: =IF('Jun-24'!$H11="","",'Jun-24'!$H11*0.21) -> 11454.551 | P11: =SUM('Jun-24'!$H11:$O11) -> 66000.031 | Q11: =IFERROR(IF('Jun-24'!$F11="","-",VLOOKUP('Jun-24'!$F11,Lista_CUIT!$A$1:$D$2241,3,0)),"CUIT NO CARGADO") -> GASTOS VARIOS | R11: =IFERROR(IF('Jun-24'!$F11="","-",VLOOKUP('Jun-24'!$F11,Lista_CUIT!$A$1:$D$2241,4,0)),"CUIT NO CARGADO") -> 0
B12: 45446 | C12: 1 | D12: 106 | E12: 738981 | F12: 30594494187 | G12: =IFERROR(IF('Jun-24'!$F12="","-",VLOOKUP('Jun-24'!$F12,Lista_CUIT!$A$1:$D$2241,2,0)),"CUIT NO CARGADO") -> FEDERAL EXPRESS CORPORATION | H12: 0 | I12: =IF('Jun-24'!$H12="","",'Jun-24'!$H12*0.21) -> 0 | O12: 294669.05 | P12: =SUM('Jun-24'!$H12:$O12) -> 294669.05 | Q12: =IFERROR(IF('Jun-24'!$F12="","-",VLOOKUP('Jun-24'!$F12,Lista_CUIT!$A$1:$D$2241,3,0)),"CUIT NO CARGADO") -> Gastos Importacion | R12: =IFERROR(IF('Jun-24'!$F12="","-",VLOOKUP('Jun-24'!$F12,Lista_CUIT!$A$1:$D$2241,4,0)),"CUIT NO CARGADO") -> 0
B13: 45446 | C13: 1 | D13: 106 | E13: 738982 | F13: 30594494187 | G13: =IFERROR(IF('Jun-24'!$F13="","-",VLOOKUP('Jun-24'!$F13,Lista_CUIT!$A$1:$D$2241,2,0)),"CUIT NO CARGADO") -> FEDERAL EXPRESS CORPORATION | H13: 0 | I13: =IF('Jun-24'!$H13="","",'Jun-24'!$H13*0.21) -> 0 | O13: 407229.16 | P13: =SUM('Jun-24'!$H13:$O13) -> 407229.16 | Q13: =IFERROR(IF('Jun-24'!$F13="","-",VLOOKUP('Jun-24'!$F13,Lista_CUIT!$A$1:$D$2241,3,0)),"CUIT NO CARGADO") -> Gastos Importacion | R13: =IFERROR(IF('Jun-24'!$F13="","-",VLOOKUP('Jun-24'!$F13,Lista_CUIT!$A$1:$D$2241,4,0)),"CUIT NO CARGADO") -> 0
B14: 45446 | C14: 1 | D14: 7 | E14: 16197 | F14: 30604413482 | G14: =IFERROR(IF('Jun-24'!$F14="","-",VLOOKUP('Jun-24'!$F14,Lista_CUIT!$A$1:$D$2241,2,0)),"CUIT NO CARGADO") -> BULONERA VIETRI SOCIEDAD DE RESPONSABILIDAD LIMITADA | H14: 34800 | I14: =IF('Jun-24'!$H14="","",'Jun-24'!$H14*0.21) -> 7308 | P14: =SUM('Jun-24'!$H14:$O14) -> 42108 | Q14: =IFERROR(IF('Jun-24'!$F14="","-",VLOOKUP('Jun-24'!$F14,Lista_CUIT!$A$1:$D$2241,3,0)),"CUIT NO CARGADO") -> INSUMO | R14: =IFERROR(IF('Jun-24'!$F14="","-",VLOOKUP('Jun-24'!$F14,Lista_CUIT!$A$1:$D$2241,4,0)),"CUIT NO CARGADO") -> 0
B15: 45446 | C15: 1 | D15: 2 | E15: 752 | F15: 20296550184 | G15: =IFERROR(IF('Jun-24'!$F15="","-",VLOOKUP('Jun-24'!$F15,Lista_CUIT!$A$1:$D$2241,2,0)),"CUIT NO CARGADO") -> COSTA DIEGO ALEJANDRO | H15: 575800 | I15: =IF('Jun-24'!$H15="","",'Jun-24'!$H15*0.21) -> 120918 | P15: =SUM('Jun-24'!$H15:$O15) -> 696718 | Q15: =IFERROR(IF('Jun-24'!$F15="","-",VLOOKUP('Jun-24'!$F15,Lista_CUIT!$A$1:$D$2241,3,0)),"CUIT NO CARGADO") -> Mat. Prima | R15: =IFERROR(IF('Jun-24'!$F15="","-",VLOOKUP('Jun-24'!$F15,Lista_CUIT!$A$1:$D$2241,4,0)),"CUIT NO CARGADO") -> 0
B16: 45447 | C16: 1 | D16: 12 | E16: 13219 | F16: 30694497701 | G16: =IFERROR(IF('Jun-24'!$F16="","-",VLOOKUP('Jun-24'!$F16,Lista_CUIT!$A$1:$D$2241,2,0)),"CUIT NO CARGADO") -> DECOR ALUM SRL | H16: 58134.44 | I16: =IF('Jun-24'!$H16="","",'Jun-24'!$H16*0.21) -> 12208.232 | P16: =SUM('Jun-24'!$H16:$O16) -> 70342.672 | Q16: =IFERROR(IF('Jun-24'!$F16="","-",VLOOKUP('Jun-24'!$F16,Lista_CUIT!$A$1:$D$2241,3,0)),"CUIT NO CARGADO") -> INSUMO | R16: =IFERROR(IF('Jun-24'!$F16="","-",VLOOKUP('Jun-24'!$F16,Lista_CUIT!$A$1:$D$2241,4,0)),"CUIT NO CARGADO") -> 0
B17: 45447 | C17: 1 | D17: 4 | E17: 101620 | F17: 30559932236 | G17: =IFERROR(IF('Jun-24'!$F17="","-",VLOOKUP('Jun-24'!$F17,Lista_CUIT!$A$1:$D$2241,2,0)),"CUIT NO CARGADO") -> ELECTRONICA ELEMON S A | H17: 1047897.6 | I17: =857376*0.21 -> 180048.96 | K17: =190521.59*0.105 -> 20004.767 | P17: =SUM('Jun-24'!$H17:$O17) -> 1247951.3 | Q17: =IFERROR(IF('Jun-24'!$F17="","-",VLOOKUP('Jun-24'!$F17,Lista_CUIT!$A$1:$D$2241,3,0)),"CUIT NO CARGADO") -> Mat. Prima | R17: =IFERROR(IF('Jun-24'!$F17="","-",VLOOKUP('Jun-24'!$F17,Lista_CUIT!$A$1:$D$2241,4,0)),"CUIT NO CARGADO") -> 0
B18: 45448 | C18: 1 | D18: 7 | E18: 16226 | F18: 30604413482 | G18: =IFERROR(IF('Jun-24'!$F18="","-",VLOOKUP('Jun-24'!$F18,Lista_CUIT!$A$1:$D$2241,2,0)),"CUIT NO CARGADO") -> BULONERA VIETRI SOCIEDAD DE RESPONSABILIDAD LIMITADA | H18: 368972.81 | I18: =IF('Jun-24'!$H18="","",'Jun-24'!$H18*0.21) -> 77484.29 | P18: =SUM('Jun-24'!$H18:$O18) -> 446457.1 | Q18: =IFERROR(IF('Jun-24'!$F18="","-",VLOOKUP('Jun-24'!$F18,Lista_CUIT!$A$1:$D$2241,3,0)),"CUIT NO CARGADO") -> INSUMO | R18: =IFERROR(IF('Jun-24'!$F18="","-",VLOOKUP('Jun-24'!$F18,Lista_CUIT!$A$1:$D$2241,4,0)),"CUIT NO CARGADO") -> 0
B19: 45449 | C19: 1 | D19: 1 | E19: 812 | F19: 30715048066 | G19: =IFERROR(IF('Jun-24'!$F19="","-",VLOOKUP('Jun-24'!$F19,Lista_CUIT!$A$1:$D$2241,2,0)),"CUIT NO CARGADO") -> ROLLS Y EMPANADAS SA | H19: 685860 | I19: =IF('Jun-24'!$H19="","",'Jun-24'!$H19*0.21) -> 144030.6 | P19: =SUM('Jun-24'!$H19:$O19) -> 829890.6 | Q19: =IFERROR(IF('Jun-24'!$F19="","-",VLOOKUP('Jun-24'!$F19,Lista_CUIT!$A$1:$D$2241,3,0)),"CUIT NO CARGADO") -> CATERING | R19: =IFERROR(IF('Jun-24'!$F19="","-",VLOOKUP('Jun-24'!$F19,Lista_CUIT!$A$1:$D$2241,4,0)),"CUIT NO CARGADO") -> 0
B20: 45449 | C20: 1 | D20: 1 | E20: 800 | F20: 30715048066 | G20: =IFERROR(IF('Jun-24'!$F20="","-",VLOOKUP('Jun-24'!$F20,Lista_CUIT!$A$1:$D$2241,2,0)),"CUIT NO CARGADO") -> ROLLS Y EMPANADAS SA | H20: 621040 | I20: =IF('Jun-24'!$H20="","",'Jun-24'!$H20*0.21) -> 130418.4 | P20: =SUM('Jun-24'!$H20:$O20) -> 751458.4 | Q20: =IFERROR(IF('Jun-24'!$F20="","-",VLOOKUP('Jun-24'!$F20,Lista_CUIT!$A$1:$D$2241,3,0)),"CUIT NO CARGADO") -> CATERING | R20: =IFERROR(IF('Jun-24'!$F20="","-",VLOOKUP('Jun-24'!$F20,Lista_CUIT!$A$1:$D$2241,4,0)),"CUIT NO CARGADO") -> 0
B21: 45450 | C21: 1 | D21: 327 | E21: 367 | F21: 30556565798 | G21: =IFERROR(IF('Jun-24'!$F21="","-",VLOOKUP('Jun-24'!$F21,Lista_CUIT!$A$1:$D$2241,2,0)),"CUIT NO CARGADO") -> VICTOR MASSON TRANSPORTES CRUZ DEL SUR S A | H21: 18042 | I21: =IF('Jun-24'!$H21="","",'Jun-24'!$H21*0.21) -> 3788.82 | P21: =SUM('Jun-24'!$H21:$O21) -> 21830.82 | Q21: =IFERROR(IF('Jun-24'!$F21="","-",VLOOKUP('Jun-24'!$F21,Lista_CUIT!$A$1:$D$2241,3,0)),"CUIT NO CARGADO") -> FLETE-LOGISTICA | R21: =IFERROR(IF('Jun-24'!$F21="","-",VLOOKUP('Jun-24'!$F21,Lista_CUIT!$A$1:$D$2241,4,0)),"CUIT NO CARGADO") -> 0
B22: 45454 | C22: 1 | D22: 2466 | E22: 656251 | F22: 30678814357 | G22: =IFERROR(IF('Jun-24'!$F22="","-",VLOOKUP('Jun-24'!$F22,Lista_CUIT!$A$1:$D$2241,2,0)),"CUIT NO CARGADO") -> TELEFONICA MOVILES ARG | H22: 21524.65 | J22: ='Jun-24'!$H22*0.27 -> 5811.6555 | L22: 645.74 | O22: 1124.2 | P22: =SUM('Jun-24'!$H22:$O22) -> 29106.246 | Q22: =IFERROR(IF('Jun-24'!$F22="","-",VLOOKUP('Jun-24'!$F22,Lista_CUIT!$A$1:$D$2241,3,0)),"CUIT NO CARGADO") -> Telefonia | R22: =IFERROR(IF('Jun-24'!$F22="","-",VLOOKUP('Jun-24'!$F22,Lista_CUIT!$A$1:$D$2241,4,0)),"CUIT NO CARGADO") -> 0
B23: 45456 | C23: 1 | D23: 3 | E23: 238092 | F23: 33658043779 | G23: =IFERROR(IF('Jun-24'!$F23="","-",VLOOKUP('Jun-24'!$F23,Lista_CUIT!$A$1:$D$2241,2,0)),"CUIT NO CARGADO") -> BUREAU VERITAS ARGENTINA SA | H23: 440000 | I23: =IF('Jun-24'!$H23="","",'Jun-24'!$H23*0.21) -> 92400 | P23: =SUM('Jun-24'!$H23:$O23) -> 532400 | Q23: =IFERROR(IF('Jun-24'!$F23="","-",VLOOKUP('Jun-24'!$F23,Lista_CUIT!$A$1:$D$2241,3,0)),"CUIT NO CARGADO") -> Servicios Informaticos | R23: =IFERROR(IF('Jun-24'!$F23="","-",VLOOKUP('Jun-24'!$F23,Lista_CUIT!$A$1:$D$2241,4,0)),"CUIT NO CARGADO") -> 0
B24: 45461 | C24: 1 | D24: 106 | E24: 743680 | F24: 30594494187 | G24: =IFERROR(IF('Jun-24'!$F24="","-",VLOOKUP('Jun-24'!$F24,Lista_CUIT!$A$1:$D$2241,2,0)),"CUIT NO CARGADO") -> FEDERAL EXPRESS CORPORATION | H24: 0 | I24: =IF('Jun-24'!$H24="","",'Jun-24'!$H24*0.21) -> 0 | O24: 398826.94 | P24: =SUM('Jun-24'!$H24:$O24) -> 398826.94 | Q24: =IFERROR(IF('Jun-24'!$F24="","-",VLOOKUP('Jun-24'!$F24,Lista_CUIT!$A$1:$D$2241,3,0)),"CUIT NO CARGADO") -> Gastos Importacion | R24: =IFERROR(IF('Jun-24'!$F24="","-",VLOOKUP('Jun-24'!$F24,Lista_CUIT!$A$1:$D$2241,4,0)),"CUIT NO CARGADO") -> 0
B25: 45468 | C25: 1 | D25: 5 | E25: 11670 | F25: 30716006391 | G25: =IFERROR(IF('Jun-24'!$F25="","-",VLOOKUP('Jun-24'!$F25,Lista_CUIT!$A$1:$D$2241,2,0)),"CUIT NO CARGADO") -> ALLISING | H25: 31885.95 | I25: =IF('Jun-24'!$H25="","",'Jun-24'!$H25*0.21) -> 6696.0495 | P25: =SUM('Jun-24'!$H25:$O25) -> 38581.999 | Q25: =IFERROR(IF('Jun-24'!$F25="","-",VLOOKUP('Jun-24'!$F25,Lista_CUIT!$A$1:$D$2241,3,0)),"CUIT NO CARGADO") -> GASTOS VARIOS | R25: =IFERROR(IF('Jun-24'!$F25="","-",VLOOKUP('Jun-24'!$F25,Lista_CUIT!$A$1:$D$2241,4,0)),"CUIT NO CARGADO") -> 0
B26: 45469 | C26: 1 | D26: 5 | E26: 818 | F26: 20309706197 | G26: =IFERROR(IF('Jun-24'!$F26="","-",VLOOKUP('Jun-24'!$F26,Lista_CUIT!$A$1:$D$2241,2,0)),"CUIT NO CARGADO") -> QUIROGA ARIEL ALEJANDRO | H26: 49585.95 | I26: =IF('Jun-24'!$H26="","",'Jun-24'!$H26*0.21) -> 10413.049 | P26: =SUM('Jun-24'!$H26:$O26) -> 59998.999 | Q26: =IFERROR(IF('Jun-24'!$F26="","-",VLOOKUP('Jun-24'!$F26,Lista_CUIT!$A$1:$D$2241,3,0)),"CUIT NO CARGADO") -> Ropa de Trabajo | R26: =IFERROR(IF('Jun-24'!$F26="","-",VLOOKUP('Jun-24'!$F26,Lista_CUIT!$A$1:$D$2241,4,0)),"CUIT NO CARGADO") -> 0
B27: 45469 | C27: 1 | D27: 2 | E27: 9126 | F27: 33717240249 | G27: =IFERROR(IF('Jun-24'!$F27="","-",VLOOKUP('Jun-24'!$F27,Lista_CUIT!$A$1:$D$2241,2,0)),"CUIT NO CARGADO") -> PERFU FAN S.R.L | H27: 14238 | I27: =IF('Jun-24'!$H27="","",'Jun-24'!$H27*0.21) -> 2989.98 | P27: =SUM('Jun-24'!$H27:$O27) -> 17227.98 | Q27: =IFERROR(IF('Jun-24'!$F27="","-",VLOOKUP('Jun-24'!$F27,Lista_CUIT!$A$1:$D$2241,3,0)),"CUIT NO CARGADO") -> Gastos Oficina | R27: =IFERROR(IF('Jun-24'!$F27="","-",VLOOKUP('Jun-24'!$F27,Lista_CUIT!$A$1:$D$2241,4,0)),"CUIT NO CARGADO") -> 0
B28: 45469 | C28: 1 | D28: 3 | E28: 912 | F28: 27424730608 | G28: =IFERROR(IF('Jun-24'!$F28="","-",VLOOKUP('Jun-24'!$F28,Lista_CUIT!$A$1:$D$2241,2,0)),"CUIT NO CARGADO") -> VAZQUEZ CABRAL WANDA MILENA | H28: 28132.23 | I28: =IF('Jun-24'!$H28="","",'Jun-24'!$H28*0.21) -> 5907.7683 | P28: =SUM('Jun-24'!$H28:$O28) -> 34039.998 | Q28: =IFERROR(IF('Jun-24'!$F28="","-",VLOOKUP('Jun-24'!$F28,Lista_CUIT!$A$1:$D$2241,3,0)),"CUIT NO CARGADO") -> GASTOS VARIOS | R28: =IFERROR(IF('Jun-24'!$F28="","-",VLOOKUP('Jun-24'!$F28,Lista_CUIT!$A$1:$D$2241,4,0)),"CUIT NO CARGADO") -> 0
B29: 45469 | C29: 1 | D29: 7 | E29: 132873 | F29: 20181426846 | G29: =IFERROR(IF('Jun-24'!$F29="","-",VLOOKUP('Jun-24'!$F29,Lista_CUIT!$A$1:$D$2241,2,0)),"CUIT NO CARGADO") -> GRIDEL WALTER DIEGO | H29: 20080.17 | I29: =IF('Jun-24'!$H29="","",'Jun-24'!$H29*0.21) -> 4216.8357 | P29: =SUM('Jun-24'!$H29:$O29) -> 24297.006 | Q29: =IFERROR(IF('Jun-24'!$F29="","-",VLOOKUP('Jun-24'!$F29,Lista_CUIT!$A$1:$D$2241,3,0)),"CUIT NO CARGADO") -> INSUMO | R29: =IFERROR(IF('Jun-24'!$F29="","-",VLOOKUP('Jun-24'!$F29,Lista_CUIT!$A$1:$D$2241,4,0)),"CUIT NO CARGADO") -> 0
B30: 45469 | C30: 1 | D30: 2 | E30: 199 | F30: 20125142851 | G30: =IFERROR(IF('Jun-24'!$F30="","-",VLOOKUP('Jun-24'!$F30,Lista_CUIT!$A$1:$D$2241,2,0)),"CUIT NO CARGADO") -> FEDERICI NICOLAS JOSE | H30: 1269918 | I30: =IF('Jun-24'!$H30="","",'Jun-24'!$H30*0.21) -> 266682.78 | P30: =SUM('Jun-24'!$H30:$O30) -> 1536600.8 | Q30: =IFERROR(IF('Jun-24'!$F30="","-",VLOOKUP('Jun-24'!$F30,Lista_CUIT!$A$1:$D$2241,3,0)),"CUIT NO CARGADO") -> INSUMO | R30: =IFERROR(IF('Jun-24'!$F30="","-",VLOOKUP('Jun-24'!$F30,Lista_CUIT!$A$1:$D$2241,4,0)),"CUIT NO CARGADO") -> 0
B31: 45469 | C31: 1 | D31: 2 | E31: 200 | F31: 20125142851 | G31: =IFERROR(IF('Jun-24'!$F31="","-",VLOOKUP('Jun-24'!$F31,Lista_CUIT!$A$1:$D$2241,2,0)),"CUIT NO CARGADO") -> FEDERICI NICOLAS JOSE | H31: 285937.76 | I31: =IF('Jun-24'!$H31="","",'Jun-24'!$H31*0.21) -> 60046.93 | P31: =SUM('Jun-24'!$H31:$O31) -> 345984.69 | Q31: =IFERROR(IF('Jun-24'!$F31="","-",VLOOKUP('Jun-24'!$F31,Lista_CUIT!$A$1:$D$2241,3,0)),"CUIT NO CARGADO") -> INSUMO | R31: =IFERROR(IF('Jun-24'!$F31="","-",VLOOKUP('Jun-24'!$F31,Lista_CUIT!$A$1:$D$2241,4,0)),"CUIT NO CARGADO") -> 0
B32: 45470 | C32: 1 | D32: 3 | E32: 29970 | F32: 30715002848 | G32: =IFERROR(IF('Jun-24'!$F32="","-",VLOOKUP('Jun-24'!$F32,Lista_CUIT!$A$1:$D$2241,2,0)),"CUIT NO CARGADO") -> MASTER LEADER MUNDIAL S.A. | H32: 11730.57 | I32: =IF('Jun-24'!$H32="","",'Jun-24'!$H32*0.21) -> 2463.4197 | P32: =SUM('Jun-24'!$H32:$O32) -> 14193.99 | Q32: =IFERROR(IF('Jun-24'!$F32="","-",VLOOKUP('Jun-24'!$F32,Lista_CUIT!$A$1:$D$2241,3,0)),"CUIT NO CARGADO") -> INSUMO | R32: =IFERROR(IF('Jun-24'!$F32="","-",VLOOKUP('Jun-24'!$F32,Lista_CUIT!$A$1:$D$2241,4,0)),"CUIT NO CARGADO") -> BUENOS AIRES
B33: 45470 | C33: 1 | D33: 6 | E33: 15075 | F33: 30707756434 | G33: =IFERROR(IF('Jun-24'!$F33="","-",VLOOKUP('Jun-24'!$F33,Lista_CUIT!$A$1:$D$2241,2,0)),"CUIT NO CARGADO") -> SERVICIO INTEGRAL DE LIMPIEZA SRL | H33: 232000 | I33: =IF('Jun-24'!$H33="","",'Jun-24'!$H33*0.21) -> 48720 | P33: =SUM('Jun-24'!$H33:$O33) -> 280720 | Q33: =IFERROR(IF('Jun-24'!$F33="","-",VLOOKUP('Jun-24'!$F33,Lista_CUIT!$A$1:$D$2241,3,0)),"CUIT NO CARGADO") -> Mantenimiento | R33: =IFERROR(IF('Jun-24'!$F33="","-",VLOOKUP('Jun-24'!$F33,Lista_CUIT!$A$1:$D$2241,4,0)),"CUIT NO CARGADO") -> 0
B34: 45470 | C34: 1 | D34: 4 | E34: 12711 | F34: 33710719549 | G34: =IFERROR(IF('Jun-24'!$F34="","-",VLOOKUP('Jun-24'!$F34,Lista_CUIT!$A$1:$D$2241,2,0)),"CUIT NO CARGADO") -> FIVELEC S.R.L. | H34: 34181 | I34: =IF('Jun-24'!$H34="","",'Jun-24'!$H34*0.21) -> 7178.01 | P34: =SUM('Jun-24'!$H34:$O34) -> 41359.01 | Q34: =IFERROR(IF('Jun-24'!$F34="","-",VLOOKUP('Jun-24'!$F34,Lista_CUIT!$A$1:$D$2241,3,0)),"CUIT NO CARGADO") -> INSUMO | R34: =IFERROR(IF('Jun-24'!$F34="","-",VLOOKUP('Jun-24'!$F34,Lista_CUIT!$A$1:$D$2241,4,0)),"CUIT NO CARGADO") -> 0
B35: 45473 | C35: 1 | D35: 700 | E35: 675604 | F35: 30580111315 | G35: =IFERROR(IF('Jun-24'!$F35="","-",VLOOKUP('Jun-24'!$F35,Lista_CUIT!$A$1:$D$2241,2,0)),"CUIT NO CARGADO") -> DHL EXPRESS (ARGENTINA) S.A. | H35: 13957.5 | I35: =IF('Jun-24'!$H35="","",'Jun-24'!$H35*0.21) -> 2931.075 | O35: 654067.06 | P35: =SUM('Jun-24'!$H35:$O35) -> 670955.63 | Q35: =IFERROR(IF('Jun-24'!$F35="","-",VLOOKUP('Jun-24'!$F35,Lista_CUIT!$A$1:$D$2241,3,0)),"CUIT NO CARGADO") -> Gastos Importacion | R35: =IFERROR(IF('Jun-24'!$F35="","-",VLOOKUP('Jun-24'!$F35,Lista_CUIT!$A$1:$D$2241,4,0)),"CUIT NO CARGADO") -> 0
G36: =IFERROR(IF('Jun-24'!$F36="","-",VLOOKUP('Jun-24'!$F36,Lista_CUIT!$A$1:$D$2241,2,0)),"CUIT NO CARGADO") -> - | I36: =IF('Jun-24'!$H36="","",'Jun-24'!$H36*0.21) | P36: =SUM('Jun-24'!$H36:$O36) -> 0 | Q36: =IFERROR(IF('Jun-24'!$F36="","-",VLOOKUP('Jun-24'!$F36,Lista_CUIT!$A$1:$D$2241,3,0)),"CUIT NO CARGADO") -> - | R36: =IFERROR(IF('Jun-24'!$F36="","-",VLOOKUP('Jun-24'!$F36,Lista_CUIT!$A$1:$D$2241,4,0)),"CUIT NO CARGADO") -> -
G37: =IFERROR(IF('Jun-24'!$F37="","-",VLOOKUP('Jun-24'!$F37,Lista_CUIT!$A$1:$D$2241,2,0)),"CUIT NO CARGADO") -> - | I37: =IF('Jun-24'!$H37="","",'Jun-24'!$H37*0.21) | P37: =SUM('Jun-24'!$H37:$O37) -> 0 | Q37: =IFERROR(IF('Jun-24'!$F37="","-",VLOOKUP('Jun-24'!$F37,Lista_CUIT!$A$1:$D$2241,3,0)),"CUIT NO CARGADO") -> - | R37: =IFERROR(IF('Jun-24'!$F37="","-",VLOOKUP('Jun-24'!$F37,Lista_CUIT!$A$1:$D$2241,4,0)),"CUIT NO CARGADO") -> -
G38: =IFERROR(IF('Jun-24'!$F38="","-",VLOOKUP('Jun-24'!$F38,Lista_CUIT!$A$1:$D$2241,2,0)),"CUIT NO CARGADO") -> - | I38: =IF('Jun-24'!$H38="","",'Jun-24'!$H38*0.21) | P38: =SUM('Jun-24'!$H38:$O38) -> 0 | Q38: =IFERROR(IF('Jun-24'!$F38="","-",VLOOKUP('Jun-24'!$F38,Lista_CUIT!$A$1:$D$2241,3,0)),"CUIT NO CARGADO") -> - | R38: =IFERROR(IF('Jun-24'!$F38="","-",VLOOKUP('Jun-24'!$F38,Lista_CUIT!$A$1:$D$2241,4,0)),"CUIT NO CARGADO") -> -
G39: =IFERROR(IF('Jun-24'!$F39="","-",VLOOKUP('Jun-24'!$F39,Lista_CUIT!$A$1:$D$2241,2,0)),"CUIT NO CARGADO") -> - | I39: =IF('Jun-24'!$H39="","",'Jun-24'!$H39*0.21) | P39: =SUM('Jun-24'!$H39:$O39) -> 0 | Q39: =IFERROR(IF('Jun-24'!$F39="","-",VLOOKUP('Jun-24'!$F39,Lista_CUIT!$A$1:$D$2241,3,0)),"CUIT NO CARGADO") -> - | R39: =IFERROR(IF('Jun-24'!$F39="","-",VLOOKUP('Jun-24'!$F39,Lista_CUIT!$A$1:$D$2241,4,0)),"CUIT NO CARGADO") -> -
G40: =IFERROR(IF('Jun-24'!$F40="","-",VLOOKUP('Jun-24'!$F40,Lista_CUIT!$A$1:$D$2241,2,0)),"CUIT NO CARGADO") -> - | I40: =IF('Jun-24'!$H40="","",'Jun-24'!$H40*0.21) | P40: =SUM('Jun-24'!$H40:$O40) -> 0 | Q40: =IFERROR(IF('Jun-24'!$F40="","-",VLOOKUP('Jun-24'!$F40,Lista_CUIT!$A$1:$D$2241,3,0)),"CUIT NO CARGADO") -> - | R40: =IFERROR(IF('Jun-24'!$F40="","-",VLOOKUP('Jun-24'!$F40,Lista_CUIT!$A$1:$D$2241,4,0)),"CUIT NO CARGADO") -> -
G41: =IFERROR(IF('Jun-24'!$F41="","-",VLOOKUP('Jun-24'!$F41,Lista_CUIT!$A$1:$D$2241,2,0)),"CUIT NO CARGADO") -> - | I41: =IF('Jun-24'!$H41="","",'Jun-24'!$H41*0.21) | P41: =SUM('Jun-24'!$H41:$O41) -> 0 | Q41: =IFERROR(IF('Jun-24'!$F41="","-",VLOOKUP('Jun-24'!$F41,Lista_CUIT!$A$1:$D$2241,3,0)),"CUIT NO CARGADO") -> - | R41: =IFERROR(IF('Jun-24'!$F41="","-",VLOOKUP('Jun-24'!$F41,Lista_CUIT!$A$1:$D$2241,4,0)),"CUIT NO CARGADO") -> - | S41: COD 5
G42: =IFERROR(IF('Jun-24'!$F42="","-",VLOOKUP('Jun-24'!$F42,Lista_CUIT!$A$1:$D$2241,2,0)),"CUIT NO CARGADO") -> - | I42: =IF('Jun-24'!$H42="","",'Jun-24'!$H42*0.21) | P42: =SUM('Jun-24'!$H42:$O42) -> 0 | Q42: =IFERROR(IF('Jun-24'!$F42="","-",VLOOKUP('Jun-24'!$F42,Lista_CUIT!$A$1:$D$2241,3,0)),"CUIT NO CARGADO") -> - | R42: =IFERROR(IF('Jun-24'!$F42="","-",VLOOKUP('Jun-24'!$F42,Lista_CUIT!$A$1:$D$2241,4,0)),"CUIT NO CARGADO") -> - | S42: COD 5
G43: =IFERROR(IF('Jun-24'!$F43="","-",VLOOKUP('Jun-24'!$F43,Lista_CUIT!$A$1:$D$2241,2,0)),"CUIT NO CARGADO") -> - | I43: =IF('Jun-24'!$H43="","",'Jun-24'!$H43*0.21) | P43: =SUM('Jun-24'!$H43:$O43) -> 0 | Q43: =IFERROR(IF('Jun-24'!$F43="","-",VLOOKUP('Jun-24'!$F43,Lista_CUIT!$A$1:$D$2241,3,0)),"CUIT NO CARGADO") -> - | R43: =IFERROR(IF('Jun-24'!$F43="","-",VLOOKUP('Jun-24'!$F43,Lista_CUIT!$A$1:$D$2241,4,0)),"CUIT NO CARGADO") -> -
B44: Total | H44: =SUBTOTAL(109,'Jun-24'!$H$9:$H$43) -> 6033654.1 | I44: =SUBTOTAL(109,'Jun-24'!$I$9:$I$43) -> 1222537.7 | J44: =SUBTOTAL(109,'Jun-24'!$J$9:$J$43) -> 5811.6555 | K44: =SUBTOTAL(109,'Jun-24'!$K$9:$K$43) -> 20004.767 | L44: =SUBTOTAL(109,'Jun-24'!$L$9:$L$43) -> 645.74 | M44: =SUBTOTAL(109,'Jun-24'!$M$9:$M$43) -> 0 | N44: =SUBTOTAL(109,'Jun-24'!$N$9:$N$43) -> 0 | O44: =SUBTOTAL(109,'Jun-24'!$O$9:$O$43) -> 1755916.4 | P44: =SUBTOTAL(109,'Jun-24'!$P$9:$P$43) -> 9038570.3
...

Sheet Jul-24
B1: LIBRO IVA COMPRAS | G1: ='Abr-24'!G1:M1 -> CORITEC S. R. L. | N1: =EDATE('Abr-24'!N1,3) -> 45108
B3: TOTAL COMPRAS | G3: TOTAL CREDITO FISCAL | J3: TOTAL VENTAS NETAS | M3: TOTAL DEBITO FISCAL | P3: RESULTADO
B4: =SUM('Jul-24'!$H$35)+'Jul-24'!$G$47 -> 19384475 | G4: ='Jul-24'!$I$35+'Jul-24'!$J$35+'Jul-24'!$K$35+'Jul-24'!$H$47+'Jul-24'!$I$47 -> 4072459.2 | J4: ='Jul-24'!$H$86+'Jul-24'!$H$96 -> 60193539 | M4: ='Jul-24'!$I$86+'Jul-24'!$J$86+'Jul-24'!$I$96+'Jul-24'!$J$96 -> 6988420.2 | P4: =G4-M4 -> -2915961
B8: FECHA | C8: TIPO | D8: PTO VTA | E8: NRO. CPTE | F8: CUIT | G8: RAZON SOCIAL | H8: NETO GRAVADO | I8: IVA 21 % | J8: IVA 27% | K8: IVA 10,5% | L8: PERC. IVA | M8: PERC IIBB BS AS | N8: PERC. IIBB CABA | O8: Otros / No Grav. | P8: TOTAL | Q8: Tipo de Gasto | R8: Provincia
B9: 01/07/2024 | C9: 1 | D9: 3 | E9: 233013 | F9: 30707135596 | G9: =IFERROR(IF('Jul-24'!$F9="","-",VLOOKUP('Jul-24'!$F9,Lista_CUIT!$A$1:$D$2241,2,0)),"CUIT NO CARGADO") -> CITILAN ARGENTINA S.A. | H9: 18640 | I9: =IF('Jul-24'!$H9="","",'Jul-24'!$H9*0.21) -> 3914.4 | P9: =SUM('Jul-24'!$H9:$O9) -> 22554.4 | Q9: =IFERROR(IF('Jul-24'!$F9="","-",VLOOKUP('Jul-24'!$F9,Lista_CUIT!$A$1:$D$2241,3,0)),"CUIT NO CARGADO") -> Telefonia | R9: =IFERROR(IF('Jul-24'!$F9="","-",VLOOKUP('Jul-24'!$F9,Lista_CUIT!$A$1:$D$2241,4,0)),"CUIT NO CARGADO") -> 0
B10: 01/07/2024 | C10: 1 | D10: 3 | E10: 769 | F10: 30715402765 | G10: =IFERROR(IF('Jul-24'!$F10="","-",VLOOKUP('Jul-24'!$F10,Lista_CUIT!$A$1:$D$2241,2,0)),"CUIT NO CARGADO") -> RIO 265 S.R.L. | H10: 58677.67 | I10: =IF('Jul-24'!$H10="","",'Jul-24'!$H10*0.21) -> 12322.311 | P10: =SUM('Jul-24'!$H10:$O10) -> 70999.981 | Q10: =IFERROR(IF('Jul-24'!$F10="","-",VLOOKUP('Jul-24'!$F10,Lista_CUIT!$A$1:$D$2241,3,0)),"CUIT NO CARGADO") -> GASTOS VARIOS | R10: =IFERROR(IF('Jul-24'!$F10="","-",VLOOKUP('Jul-24'!$F10,Lista_CUIT!$A$1:$D$2241,4,0)),"CUIT NO CARGADO") -> 0
B11: 03/07/2024 | C11: 1 | D11: 5 | E11: 29626 | F11: 30707555404 | G11: =IFERROR(IF('Jul-24'!$F11="","-",VLOOKUP('Jul-24'!$F11,Lista_CUIT!$A$1:$D$2241,2,0)),"CUIT NO CARGADO") -> MAQUINAS E INSUMOS S.R.L. | H11: 70413.12 | I11: =IF('Jul-24'!$H11="","",'Jul-24'!$H11*0.21) -> 14786.755 | P11: =SUM('Jul-24'!$H11:$O11) -> 85199.875 | Q11: =IFERROR(IF('Jul-24'!$F11="","-",VLOOKUP('Jul-24'!$F11,Lista_CUIT!$A$1:$D$2241,3,0)),"CUIT NO CARGADO") -> INSUMO | R11: =IFERROR(IF('Jul-24'!$F11="","-",VLOOKUP('Jul-24'!$F11,Lista_CUIT!$A$1:$D$2241,4,0)),"CUIT NO CARGADO") -> 0
