Workbook
Name partner_id: Configuracion!$B$332

Sheet Configuracion
F1: CUIT | G1: Cargar sin guiones
F2: RAZON SOCIAL | G2: Maximo 30 caracteres
A3: CUIT | B3: RAZON SOCIAL | C3: DETALLE | F3: DETALLE | G3: Cargar tipo de gasto
A4: 30628205090 | B4: ALBAMIE SA | C4: CLIENTE
A5: 30711678820 | B5: 2PSI INGENIERIA SRL | C5: PROVEEDOR
A6: 33716367539 | B6: 3PI S.A.S. | C6: PROVEEDOR
A7: 30660373108 | B7: ABC SA | C7: VARIOS
A8: 20300210881 | B8: ABOY DIEGO OSCAR | C8: PROVEEDOR
A9: 27229910782 | B9: ABUGAUCH MARIA DE LOS ANGELES | C9: PROVEEDOR
A10: 20242709897 | B10: ABUGAUCH VICTOR HUGO | C10: PROVEEDOR
A11: 20281669053 | B11: ACOSTA JAVIER GUSTAVO | C11: FLETE
A12: 20174240125 | B12: ACOSTA OSCAR ISIDRO | C12: VARIOS
A13: 30641659106 | B13: AGRISOL SA | C13: VARIOS
A14: 33709914109 | B14: ALAN COLLECTION SA | C14: VARIOS
A15: 20267161616 | B15: ALBAJARI DIEGO MARCOS | C15: VARIOS
... A155: 30537679855 | B155: ESTACION LIMA SA | C155: VARIOS
A156: 30-56864959-8 | B156: EXPRESO BISONTE SRL | C156: FLETE
A157: 30708542349 | B157: EXPRESO FORMOSA SRL | C157: FLETE
A158: 30526582884 | B158: EXPRESO MAR DEL PLATA SA | C158: FLETE
A159: 30577744579 | B159: EXPRESO TROLE SRL | C159: FLETE
A160: 30715949292 | B160: EYPAPEL SAS | C160: GASTOS VARIOS
A161: 30715980807 | B161: FABORT SRL | C161: PROVEEDOR
A162: 20359718765 | B162: FAIL ABRAHAM | C162: VARIOS
A163: 30643518364 | B163: FARMACIA DE MEDRANO SCS | C163: PROVEEDOR
A164: 30692138747 | B164: FARMACITY SA | C164: VARIOS
A165: 33712234429 | B165: FEDAGAS SA | C165: VARIOS
A166: 20353576012 | B166: FEDERICO PABLO FEOLA | C166: VARIOS
A167: 20343766441 | B167: FERNANDEZ MAURO | C167: TALLER
A168: 27062343449 | B168: FERREIRA LILIANA INES | C168: FLETE
... A568: 30587842358 | B568: CLINICA BASILEA SA | C568: CLIENTE

Sheet Nov 24
A1: ORTOPEDIA GEMINIS S.A. | J1: 45597
A4: LIBRO IVA COMPRAS
A6: FACTURAS A
A7: FECHA | B7: PTO VTA | C7: FAC A | D7: CUIT | E7: RAZON SOCIAL | F7: NETO | G7: IVA 21% | H7: IVA 27% | I7: IVA 10,5% | J7: P IVA | K7: IIBB CF | L7: IIBB BS | M7: NO GRAV | N7: OTROS | O7: TOTAL | P7: DETALLE
A8: 45607 | B8: 8 | C8: 13270 | D8: 33715594949 | E8: =VLOOKUP(D8,Configuracion!$A$4:$C$590,2,FALSE) -> SOMOS ENERGIA SA | F8: 80639.13 | G8: =F8*21% -> 16934.217 | K8: 5769.09 | N8: 657.51 | O8: =SUM(F8:N8) -> 103999.95 | P8: =VLOOKUP(D8,Configuracion!$A$4:$C$590,3,FALSE) -> GASTOS VARIOS
A9: 45584 | B9: 12 | C9: 12765 | D9: 30685116657 | E9: =VLOOKUP(D9,Configuracion!$A$4:$C$590,2,FALSE) -> MIRVAR SA | F9: 37736.11 | G9: =F9*21% -> 7924.5831 | N9: 7345.16 | O9: =SUM(F9:N9) -> 53005.853 | P9: =VLOOKUP(D9,Configuracion!$A$4:$C$590,3,FALSE) -> VARIOS
A10: 45623 | B10: 6 | C10: 20262 | D10: 33715594949 | E10: =VLOOKUP(D10,Configuracion!$A$4:$C$590,2,FALSE) -> SOMOS ENERGIA SA | F10: 99460.83 | G10: =F10*21% -> 20886.774 | N10: 12651.36 | O10: =SUM(F10:N10) -> 132998.96 | P10: =VLOOKUP(D10,Configuracion!$A$4:$C$590,3,FALSE) -> GASTOS VARIOS
A11: 45594 | B11: 6 | C11: 19925 | D11: 33715594949 | E11: =VLOOKUP(D11,Configuracion!$A$4:$C$590,2,FALSE) -> SOMOS ENERGIA SA | F11: 34466.21 | G11: =F11*21% -> 7237.9041 | N11: 2639.95 | O11: =SUM(F11:N11) -> 44344.064 | P11: =VLOOKUP(D11,Configuracion!$A$4:$C$590,3,FALSE) -> GASTOS VARIOS
A12: 45598 | B12: 6 | C12: 199958 | D12: 33715594949 | E12: =VLOOKUP(D12,Configuracion!$A$4:$C$590,2,FALSE) -> SOMOS ENERGIA SA | F12: 50154.49 | G12: =F12*21% -> 10532.443 | N12: 3997.11 | O12: =SUM(F12:N12) -> 64684.043 | P12: =VLOOKUP(D12,Configuracion!$A$4:$C$590,3,FALSE) -> GASTOS VARIOS
A13: 45603 | B13: 6 | C13: 20024 | D13: 33715594949 | E13: =VLOOKUP(D13,Configuracion!$A$4:$C$590,2,FALSE) -> SOMOS ENERGIA SA | F13: 67728.33 | G13: =F13*21% -> 14222.949 | N13: 5397.67 | O13: =SUM(F13:N13) -> 87348.949 | P13: =VLOOKUP(D13,Configuracion!$A$4:$C$590,3,FALSE) -> GASTOS VARIOS
A14: 45617 | B14: 8 | C14: 13359 | D14: 33715594949 | E14: =VLOOKUP(D14,Configuracion!$A$4:$C$590,2,FALSE) -> SOMOS ENERGIA SA | F14: 89743.55 | G14: =F14*21% -> 18846.145 | N14: 11415.32 | O14: =SUM(F14:N14) -> 120005.02 | P14: =VLOOKUP(D14,Configuracion!$A$4:$C$590,3,FALSE) -> GASTOS VARIOS
A15: 45616 | B15: 6 | C15: 1710 | D15: 30716815710 | E15: =VLOOKUP(D15,Configuracion!$A$4:$C$590,2,FALSE) -> PAPELERA GEOPEL SRL | F15: 14800 | G15: =F15*21% -> 3108 | O15: =SUM(F15:N15) -> 17908 | P15: =VLOOKUP(D15,Configuracion!$A$4:$C$590,3,FALSE) -> LIBRERÍA
A16: 45615 | B16: 326 | C16: 79605 | D16: 30556565798 | E16: =VLOOKUP(D16,Configuracion!$A$4:$C$590,2,FALSE) -> V M TRASP CRUZ DEL SUR SA | F16: 21901.87 | G16: =F16*21% -> 4599.3927 | O16: =SUM(F16:N16) -> 26501.263 | P16: =VLOOKUP(D16,Configuracion!$A$4:$C$590,3,FALSE) -> FLETE
E17: =VLOOKUP(D17,Configuracion!$A$4:$C$590,2,FALSE) -> #N/A | G17: =F17*21% -> 0 | O17: =SUM(F17:N17) -> 0 | P17: =VLOOKUP(D17,Configuracion!$A$4:$C$590,3,FALSE) -> #N/A
A18: TOTAL | F18: =SUM(F8:F17) -> 496630.52 | G18: =SUM(G8:G17) -> 104292.41 | H18: =SUM(H8:H17) -> 0 | I18: =SUM(I8:I17) -> 0 | J18: =SUM(J8:J17) -> 0 | K18: =SUM(K8:K17) -> 5769.09 | L18: =SUM(L8:L17) -> 0 | M18: =SUM(M8:M17) -> 0 | ... O18: =SUM(O8:O17) -> 650796.1
F19: IVA | G19: =G18+H18+I18 -> 104292.41
A21: FACTURAS B/C
A22: FECHA | B22: PTO VTA | C22: FAC C | D22: CUIT | E22: RAZON SOCIAL | F22: TOTAL | G22: DETALLE
E23: =VLOOKUP(D23,Configuracion!$A$4:$C$590,2,FALSE) -> #N/A | G23: =VLOOKUP(D23,Configuracion!$A$4:$C$590,3,FALSE) -> #N/A
E24: =VLOOKUP(D24,Configuracion!$A$4:$C$590,2,FALSE) -> #N/A | G24: =VLOOKUP(D24,Configuracion!$A$4:$C$590,3,FALSE) -> #N/A
E25: =VLOOKUP(D25,Configuracion!$A$4:$C$590,2,FALSE) -> #N/A | G25: =VLOOKUP(D25,Configuracion!$A$4:$C$590,3,FALSE) -> #N/A
E26: =VLOOKUP(D26,Configuracion!$A$4:$C$590,2,FALSE) -> #N/A | G26: =VLOOKUP(D26,Configuracion!$A$4:$C$590,3,FALSE) -> #N/A
E27: =VLOOKUP(D27,Configuracion!$A$4:$C$590,2,FALSE) -> #N/A | G27: =VLOOKUP(D27,Configuracion!$A$4:$C$590,3,FALSE) -> #N/A
E28: =VLOOKUP(D28,Configuracion!$A$4:$C$590,2,FALSE) -> #N/A | G28: =VLOOKUP(D28,Configuracion!$A$4:$C$590,3,FALSE) -> #N/A
E29: =VLOOKUP(D29,Configuracion!$A$4:$C$590,2,FALSE) -> #N/A | G29: =VLOOKUP(D29,Configuracion!$A$4:$C$590,3,FALSE) -> #N/A
E30: =VLOOKUP(D30,Configuracion!$A$4:$C$590,2,FALSE) -> #N/A | G30: =VLOOKUP(D30,Configuracion!$A$4:$C$590,3,FALSE) -> #N/A
E31: =VLOOKUP(D31,Configuracion!$A$4:$C$590,2,FALSE) -> #N/A | G31: =VLOOKUP(D31,Configuracion!$A$4:$C$590,3,FALSE) -> #N/A
E32: =VLOOKUP(D32,Configuracion!$A$4:$C$590,2,FALSE) -> #N/A | G32: =VLOOKUP(D32,Configuracion!$A$4:$C$590,3,FALSE) -> #N/A
E33: =VLOOKUP(D33,Configuracion!$A$4:$C$590,2,FALSE) -> #N/A | G33: =VLOOKUP(D33,Configuracion!$A$4:$C$590,3,FALSE) -> #N/A
E34: =VLOOKUP(D34,Configuracion!$A$4:$C$590,2,FALSE) -> #N/A | G34: =VLOOKUP(D34,Configuracion!$A$4:$C$590,3,FALSE) -> #N/A
... E41: =VLOOKUP(D41,Configuracion!$A$4:$C$590,2,FALSE) -> #N/A | G41: =VLOOKUP(D41,Configuracion!$A$4:$C$590,3,FALSE) -> #N/A
A42: TOTAL | F42: =SUM(F23:F41) -> 0
A44: RETENCIONES
A45: FECHA | B45: COMPROBANTE NRO | D45: CUIT | E45: RAZON SOCIAL | F45: GANANCIAS | G45: IVA | H45: IIBB | I45: SUSS
A46: 45565 | B46: 86205 | D46: 30522428163 | E46: =VLOOKUP(D46,Configuracion!$A$4:$C$590,2,FALSE) -> GALENO ARGENTINA SA | F46: 36314.96 | G46: 190648.76 | H46: 18157.02 | I46: 18157.02
A47: 45603 | B47: 97789 | D47: 30522428163 | E47: =VLOOKUP(D47,Configuracion!$A$4:$C$590,2,FALSE) -> GALENO ARGENTINA SA | F47: 20231.24 | G47: 106214.87 | H47: 10115.7 | I47: 10115.7
A48: 45566 | B48: 86767 | D48: 30522428163 | E48: =VLOOKUP(D48,Configuracion!$A$4:$C$590,2,FALSE) -> GALENO ARGENTINA SA | F48: 66222.86 | G48: 347671.49 | H48: 33111.57 | I48: 33111.57
A49: 45581 | B49: 92605 | D49: 30522428163 | E49: =VLOOKUP(D49,Configuracion!$A$4:$C$590,2,FALSE) -> GALENO ARGENTINA SA | F49: 127811.57 | G49: 682118.18 | H49: 63905.79 | I49: 64963.64
A50: 45595 | B50: 95940 | D50: 30522428163 | E50: =VLOOKUP(D50,Configuracion!$A$4:$C$590,2,FALSE) -> GALENO ARGENTINA SA | F50: 27865.66 | G50: 187958.68 | H50: 13933.88 | I50: 17900.83
A51: 45603 | B51: 97785 | D51: 30522428163 | E51: =VLOOKUP(D51,Configuracion!$A$4:$C$590,2,FALSE) -> GALENO ARGENTINA SA | F51: 20326.16 | G51: 115380.64 | H51: 10160.7 | I51: 10988.63
...

Sheet Calculo IVA
B1: ORTOPEDIA GEMINIS
A2: Calculo Iva | D2: 45597
B4: VENTAS
B5: Neto | C5: Iva | D5: Total
A6: FAC. "A" | B6: =+'Nov 24'!F103 -> 0 | C6: =(B6*0.21) -> 0 | D6: =(B6+C6) -> 0
A7: FAC. "B" | B7: =+'Nov 24'!F113 -> 0 | C7: =(B7*0.21) -> 0 | D7: =(B7+C7) -> 0
A8: FAC. "A" - | B8: =+'Resumen Ventas 11'!B3+'Resumen Ventas 11'!B5+'Resumen Ventas 11'!B6+'Resumen Ventas 11'!B4 -> 53169173 | C8: =+B8*0.21 -> 11165526 | D8: =(B8+C8) -> 64334699
A9: FAC. "B" | B9: =+'Resumen Ventas 11'!B7+'Resumen Ventas 11'!B8 -> 12086889 | C9: =+'Resumen Ventas 11'!C7+'Resumen Ventas 11'!C8 -> 2538246.6 | D9: =(B9+C9) -> 14625135
B10: =SUM(B6:B9) -> 65256062 | C10: =SUM(C6:C9) -> 13703773 | D10: =SUM(D6:D9) -> 78959835
B13: COMPRAS
B14: Neto | C14: Iva | D14: Total
A15: Comprobantes Ticket FA-A | B15: =+'Nov 24'!F18 -> 496630.52 | C15: =+('Nov 24'!G18+'Nov 24'!H18+'Nov 24'!I18) -> 104292.41 | D15: =+'Nov 24'!O18 -> 650796.1
A16: Comprobantes AFIP - Recibidos | B16: 33676874 | C16: 7031917.2 | D16: 50481960
A17: Comprobantes AFIP - No Recibidos | B17: 180184.52 | C17: 36671.52 | D17: 1130925.2
A18: IVA S/ EXTRACTOS BANCARIOS | C18: 15379.32
B19: =SUM(B15:B18) -> 34353689 | C19: =SUM(C15:C18) -> 7188260.4 | D19: =SUM(D15:D18) -> 52263681
A22: RETENCIONES | B22: N° Cuit | C22: Importe | D22: Nro. Retencion | E22: Fecha
A23: AFIP - No están informadas las retenciones de IVA en el sistema de AFIP
C38: =+'Nov 24'!G86 -> 3073311.7
A40: PERCEPCIONES | B40: N° Cuit | C40: Importe | D40: Nro. Retencion | E40: Fecha
C44: =SUM(C41:C43) -> 0
A46: Total Deducciociones | C46: =+C44+C38 -> 3073311.7
C49: (Montos en Positivo)
A50: 1er Saldo Tecnico del Período | C50: =+C10-C19 -> 6515512.6
A52: Saldo Tecnico de período Anterior (a favor) | D52: (resta en el total)
A54: Saldo Neto Técnico | C54: =+C50-C52 -> 6515512.6
A58: Saldo L.D. del Período | C58: =+C44+C38 -> 3073311.7
A60: Saldo L.D. del Período Anterior
A62: Neto S.L.D | C62: =+C58+C60 -> 3073311.7
A65: I V A | C65: =+C54-C62 -> 3442200.9
A66: NOTA: Sin Tomar posibles Retenciones que se hayan hecho

Sheet afip
A1: Fecha | B1: Tipo | C1: Punto de Venta | D1: Número Desde | E1: Número Hasta | F1: Cód. Autorización | G1: Tipo Doc. Emisor | H1: Nro. Doc. Emisor | I1: Denominación Emisor | J1: Tipo Cambio | K1: Moneda | L1: Imp. Neto Gravado | M1: Imp. Neto No Gravado | N1: Imp. Op. Exentas | O1: Otros Tributos | P1: IVA | Q1: Imp. Total
A2: 01/09/2024 | B2: 1 - Factura A | C2: 2189 | D2: 75919 | F2: 74356447170423 | G2: CUIT | H2: 30548083156 | I2: COTO CENTRO INTEGRAL DE COMERCIALIZACION SOCIEDAD ANONIMA | J2: 1 | K2: $ | L2: 6462.61 | M2: 0 | N2: 0 | O2: 452.38 | P2: 1357.15 | Q2: 8272.14
A3: 02/09/2024 | B3: 1 - Factura A | C3: 500 | D3: 1611886 | F3: 74357098226128 | G3: CUIT | H3: 30654118767 | I3: SOLUCIONES MULTIMEDIA S A | J3: 1 | K3: $ | L3: 89554.36 | M3: 0 | N3: 0 | O3: 0 | P3: 18806.42 | Q3: 112850.92
A4: 02/09/2024 | B4: 1 - Factura A | C4: 1 | D4: 4517 | F4: 74361573927319 | G4: CUIT | H4: 30715141201 | I4: REHAB S.R.L. | J4: 1 | K4: $ | L4: 1216380 | M4: 0 | N4: 0 | O4: 0 | P4: 255439.8 | Q4: 1471819.8
A5: 02/09/2024 | B5: 1 - Factura A | C5: 5 | D5: 158399 | F5: 74363528156508 | G5: CUIT | H5: 30598960093 | I5: SILVESTRIN FABRIS SOC RESP LTDA | J5: 1 | K5: $ | L5: 2376294.2 | M5: 0 | N5: 0 | O5: 0 | P5: 337808.56 | Q5: 2832917.5
A6: 02/09/2024 | B6: 1 - Factura A | C6: 17 | D6: 2245 | F6: 74361547632750 | G6: CUIT | H6: 30711764921 | I6: RELIEF CENTER S.R.L. | J6: 1 | K6: $ | L6: 93973 | M6: 0 | N6: 0 | O6: 0 | P6: 19734.33 | Q6: 113707.33
A7: 02/09/2024 | B7: 1 - Factura A | C7: 3051 | D7: 801967 | F7: 74367703518446 | G7: CUIT | H7: 30678814357 | I7: TELEFONICA MOVILES ARGENTINA SOCIEDAD ANONIMA | J7: 1 | K7: $ | L7: 14407 | M7: 0 | N7: 0 | O7: 0 | P7: 3889.89 | Q7: 20245.61
A8: 02/09/2024 | B8: 1 - Factura A | C8: 2 | D8: 248 | F8: 74363494027429 | G8: CUIT | H8: 27144282383 | I8: SCHEJTER LILA ELISA | J8: 1 | K8: $ | L8: 160000 | M8: 0 | N8: 0 | O8: 0 | P8: 33600 | Q8: 193600
A9: 02/09/2024 | B9: 1 - Factura A | C9: 5 | D9: 102 | F9: 74367559790009 | G9: CUIT | H9: 27329449357 | I9: ANDREANI AGUSTINA SUSANA | J9: 1 | K9: $ | L9: 64100 | M9: 16400 | N9: 0 | O9: 0 | P9: 13461 | Q9: 93961
A10: 02/09/2024 | B10: 11 - Factura C | C10: 3 | D10: 874 | F10: 74363563144286 | G10: CUIT | H10: 20086277523 | I10: BOTINDARI JUAN CARLOS | J10: 1 | K10: $ | O10: 0 | Q10: 275500
A11: 02/09/2024 | B11: 11 - Factura C | C11: 2 | D11: 302 | F11: 74368278674869 | G11: CUIT | H11: 27265832178 | I11: BLASCO MARIA GUADALUPE | J11: 1 | K11: $ | O11: 0 | Q11: 250000
A12: 03/09/2024 | B12: 1 - Factura A | C12: 629 | D12: 5407463 | F12: 34353802937243 | G12: CUIT | H12: 30663498513 | I12: GRUPO CONCESIONARIO DEL OESTE SA | J12: 1 | K12: $ | L12: 2121.64 | M12: 0 | N12: 0 | O12: 0 | P12: 445.54 | Q12: 2673.26
A13: 03/09/2024 | B13: 1 - Factura A | C13: 711 | D13: 6097149 | F13: 34359489663246 | G13: CUIT | H13: 30677237119 | I13: AUTOPISTAS DEL SOL S A | J13: 1 | K13: $ | L13: 7715.05 | M13: 0 | N13: 231.45 | O13: 0 | P13: 1620.16 | Q13: 9952.41
A14: 03/09/2024 | B14: 1 - Factura A | C14: 2635 | D14: 1369 | F14: 34359844249451 | G14: CUIT | H14: 33699685459 | I14: CORREO ANDREANI SA | J14: 1 | K14: $ | L14: 12449.6 | M14: 0 | N14: 0 | O14: 0 | P14: 2614.42 | Q14: 15064.02
A15: 03/09/2024 | B15: 1 - Factura A | C15: 2 | D15: 216 | F15: 74362687536018 | G15: CUIT | H15: 30605344352 | I15: CONSORCIO BARTOLOME MITRE 2466 | J15: 1 | K15: $ | L15: 834000 | M15: 0 | N15: 0 | O15: 0 | P15: 175140 | Q15: 1009140
A16: 04/09/2024 | B16: 1 - Factura A | C16: 17 | D16: 2255 | F16: 74361803741207 | G16: CUIT | H16: 30711764921 | I16: RELIEF CENTER S.R.L. | J16: 1 | K16: $ | L16: 527580 | M16: 0 | N16: 0 | O16: 0 | P16: 110791.8 | Q16: 638371.8
A17: 04/09/2024 | B17: 1 - Factura A | C17: 2 | D17: 50685 | F17: 74365825946417 | G17: CUIT | H17: 30595553535 | I17: RUBRICOM SOCIEDAD ANONIMA | J17: 1 | K17: $ | L17: 4793.39 | M17: 0 | N17: 0 | O17: 0 | P17: 1006.61 | Q17: 5800
A18: 04/09/2024 | B18: 1 - Factura A | C18: 120 | D18: 4949 | F18: 74365804898856 | G18: CUIT | H18: 30587197215 | I18: PANATEL SOCIEDAD ANONIMA | J18: 1 | K18: $ | L18: 68595.04 | M18: 0 | N18: 0 | O18: 0 | P18: 14404.96 | Q18: 86429.75
A19: 04/09/2024 | B19: 1 - Factura A | C19: 7 | D19: 3241 | F19: 74364799883128 | G19: CUIT | H19: 20284183534 | I19: FURLANETTO MARTIN | J19: 1 | K19: $ | L19: 4545.5 | M19: 0 | N19: 0 | O19: 0 | P19: 954.56 | Q19: 5500.06
A20: 04/09/2024 | B20: 1 - Factura A | C20: 120 | D20: 4948 | F20: 74365800262038 | G20: CUIT | H20: 30587197215 | I20: PANATEL SOCIEDAD ANONIMA | J20: 1 | K20: $ | L20: 68595.04 | M20: 0 | N20: 0 | O20: 0 | P20: 14404.96 | Q20: 86429.75
A21: 04/09/2024 | B21: 1 - Factura A | C21: 401 | D21: 66 | F21: 74364797895464 | G21: CUIT | H21: 30716234114 | I21: UZUMAKI S.A.S. | J21: 1305 | K21: USD | L21: 129.3 | M21: 0 | N21: 0 | O21: 0 | P21: 27.15 | Q21: 156.45
A22: 05/09/2024 | B22: 1 - Factura A | C22: 2 | D22: 760 | F22: 74369961703669 | G22: CUIT | H22: 20272865869 | I22: DI FEO MARTIN EZEQUIEL | J22: 1 | K22: $ | L22: 84450 | M22: 0 | N22: 0 | O22: 0 | P22: 17734.5 | Q22: 102184.5
A23: 05/09/2024 | B23: 1 - Factura A | C23: 5 | D23: 5331 | F23: 74363959099503 | G23: CUIT | H23: 30715833243 | I23: BIODINAMICA ASISTENCIA S.R.L. | J23: 1 | K23: $ | L23: 22238.59 | M23: 0 | N23: 0 | O23: 0 | P23: 4670.1 | Q23: 26908.69
... A35: 09/09/2024 | B35: 3 - Nota de Crédito A | C35: 5 | D35: 192 | F35: 74376416376753 | G35: CUIT | H35: 30712187316 | I35: ITALOMED PRODUCTOS SRL | J35: 1 | K35: $ | L35: 293619.94 | M35: 0 | N35: 0 | O35: 0 | P35: 61660.19 | Q35: 355280.13
A36: 09/09/2024 | B36: 11 - Factura C | C36: 1 | D36: 148 | F36: 74370408397319 | G36: CUIT | H36: 27338342840 | I36: CANCINO PAMELA RITA | J36: 1 | K36: $ | O36: 0 | Q36: 276800
A37: 10/09/2024 | B37: 1 - Factura A | C37: 2 | D37: 8403 | F37: 74372567359059 | G37: CUIT | H37: 27363810182 | I37: HECKER LAURA NOEMI | J37: 1 | K37: $ | L37: 3635.54 | M37: 0 | N37: 0 | O37: 0 | P37: 763.46 | Q37: 4399
A38: 10/09/2024 | B38: 1 - Factura A | C38: 5 | D38: 31858 | F38: 74370525870493 | G38: CUIT | H38: 30710804830 | I38: ZG MULTITEC SRL | J38: 1 | K38: $ | L38: 29410.86 | M38: 0 | N38: 0 | O38: 0 | P38: 3088.14 | Q38: 32499
A39: 10/09/2024 | B39: 1 - Factura A | C39: 8 | D39: 1684 | F39: 74371529941038 | G39: CUIT | H39: 30708973501 | I39: ASIAL S.R.L. | J39: 1 | K39: $ | L39: 740255 | M39: 0 | N39: 0 | O39: 0 | P39: 155453.55 | Q39: 895708.55
A40: 10/09/2024 | B40: 1 - Factura A | C40: 3 | D40: 4250 | F40: 74378552751950 | G40: CUIT | H40: 20184052858 | I40: ABOUD PABLO DANIEL | J40: 1 | K40: $ | L40: 16859.48 | M40: 0 | N40: 0 | O40: 0 | P40: 3540.49 | Q40: 20399.95
A41: 10/09/2024 | B41: 11 - Factura C | C41: 3 | D41: 986 | F41: 74379527477577 | G41: CUIT | H41: 20216451679 | I41: VAZQUEZ RICARDO OSCAR | J41: 1 | K41: $ | O41: 0 | Q41: 86000
A42: 11/09/2024 | B42: 1 - Factura A | C42: 1 | D42: 2468 | F42: 74379681409704 | G42: CUIT | H42: 30717179389 | I42: NICOLAS TOBIAS SEQUEIRA Y MARIA GABRIELA RATTNER SOCIEDAD DE LA SECCION IV LGS | J42: 1 | K42: $ | L42: 82644.62 | M42: 0 | N42: 0 | O42: 0 | P42: 17355.37 | Q42: 99999.99
A43: 11/09/2024 | B43: 1 - Factura A | C43: 5 | D43: 3378 | F43: 74379704726153 | G43: CUIT | H43: 30717179389 | I43: NICOLAS TOBIAS SEQUEIRA Y MARIA GABRIELA RATTNER SOCIEDAD DE LA SECCION IV LGS | J43: 1 | K43: $ | L43: 82644.63 | M43: 0 | N43: 0 | O43: 0 | P43: 17355.37 | Q43: 100000
A44: 11/09/2024 | B44: 1 - Factura A | C44: 3 | D44: 7676 | F44: 74379686794320 | G44: CUIT | H44: 33708218699 | I44: MANGGINI PABLO Y MANGGINI ULISES SOC. DE HECHO. | J44: 1 | K44: $ | L44: 15000 | M44: 0 | N44: 0 | O44: 0 | P44: 3150 | Q44: 18150
A45: 11/09/2024 | B45: 11 - Factura C | C45: 1 | D45: 9 | F45: 74373677716509 | G45: CUIT | H45: 20464199633 | I45: OVIEDO JIMENEZ TIZIANO LIONEL | J45: 1 | K45: $ | O45: 0 | Q45: 499950
A46: 12/09/2024 | B46: 1 - Factura A | C46: 2 | D46: 778 | F46: 74379814460759 | G46: CUIT | H46: 20272865869 | I46: DI FEO MARTIN EZEQUIEL | J46: 1 | K46: $ | L46: 128100 | M46: 0 | N46: 0 | O46: 0 | P46: 26901 | Q46: 155001
A47: 12/09/2024 | B47: 1 - Factura A | C47: 4 | D47: 38394 | F47: 74379814609856 | G47: CUIT | H47: 20289111329 | I47: LEDESMA EMILIANO RUBEN | J47: 1 | K47: $ | L47: 585730.8 | M47: 0 | N47: 0 | O47: 0 | P47: 123003.47 | Q47: 708734.27
A48: 12/09/2024 | B48: 1 - Factura A | C48: 5 | D48: 1915 | F48: 74376761404173 | G48: CUIT | H48: 30712187316 | I48: ITALOMED PRODUCTOS SRL | J48: 1 | K48: $ | L48: 254033.05 | M48: 0 | N48: 0 | O48: 0 | P48: 53346.94 | Q48: 307379.99
A49: 12/09/2024 | B49: 1 - Factura A | C49: 5 | D49: 1916 | F49: 74376766353942 | G49: CUIT | H49: 30712187316 | I49: ITALOMED PRODUCTOS SRL | J49: 1 | K49: $ | L49: 472751.65 | M49: 0 | N49: 0 | O49: 0 | P49: 99277.85 | Q49: 572029.5
A50: 13/09/2024 | B50: 1 - Factura A | C50: 1 | D50: 4620 | F50: 74371942773283 | G50: CUIT | H50: 30715141201 | I50: REHAB S.R.L. | J50: 1 | K50: $ | L50: 29295 | M50: 0 | N50: 0 | O50: 0 | P50: 6151.95 | Q50: 35446.95
A51: 13/09/2024 | B51: 1 - Factura A | C51: 5 | D51: 1920 | F51: 74376932362480 | G51: CUIT | H51: 30712187316 | I51: ITALOMED PRODUCTOS SRL | J51: 1 | K51: $ | L51: 34718.6 | M51: 0 | N51: 0 | O51: 0 | P51: 7290.91 | Q51: 42009.51
...

Sheet Hoja3
A1: Comprobante no recibido
A4: Fecha | B4: Comprobante | C4: Nombre | D4: Cond. IVA | E4: CUIT o Doc. | F4: Gravado | G4: No Gravado
A5: 02/09/2024 | B5: FA-C 0003-00000874 | C5: BOTINDARI JUAN CARLOS | D5: Responsable Monotributo | E5: 20086277523 | F5: 0 | G5: 275500
A6: 02/09/2024 | B6: 874 | C6: BOTINDARI JUAN CARLOS | E6: 20086277523
A7: 19/09/2024 | B7: FA-A 0007-00006066 | C7: Triveño Roma, Ramon | D7: IVA Responsable Inscripto | E7: 20131067446 | F7: 278865.6 | G7: 0
A8: 19/09/2024 | B8: 6066 | C8: TRIVEÑO ROMA RAMON | E8: 20131067446 | F8: 278865.6 | G8: 0
A9: 10/09/2024 | B9: FA-A 0003-00004250 | C9: Aboud, Pablo Daniel | D9: IVA Responsable Inscripto | E9: 20184052858 | F9: 16859.46 | G9: 0
A10: 30/09/2024 | B10: FA-A 0003-00004276 | C10: Aboud, Pablo Daniel | D10: IVA Responsable Inscripto | E10: 20184052858 | F10: 71074.3 | G10: 0
A11: 10/09/2024 | B11: 4250 | C11: ABOUD PABLO DANIEL | E11: 20184052858 | F11: 16859.48 | G11: 0
A12: 30/09/2024 | B12: 4276 | C12: ABOUD PABLO DANIEL | E12: 20184052858 | F12: 71074.33 | G12: 0
A13: 30/09/2024 | B13: 804 | C13: PAIS HECTOR GUILLERMO | E13: 20214946867 | F13: 37189.24 | G13: 0
A14: 10/09/2024 | B14: FA-C 0003-00000986 | C14: Vazquez, Ricardo Oscar | D14: Responsable Monotributo | E14: 20216451679 | F14: 0 | G14: 86000
A15: 27/09/2024 | B15: FA-C 0003-00000995 | C15: Vazquez, Ricardo Oscar | D15: Responsable Monotributo | E15: 20216451679 | F15: 0 | G15: 160000
A16: 10/09/2024 | B16: 986 | C16: VAZQUEZ RICARDO OSCAR | E16: 20216451679
A17: 19/09/2024 | B17: 991 | C17: VAZQUEZ RICARDO OSCAR | E17: 20216451679
A18: 27/09/2024 | B18: 995 | C18: VAZQUEZ RICARDO OSCAR | E18: 20216451679
A19: 12/09/2024 | B19: FA-A 0002-00000778 | C19: Di Feo, Martin Ezequiel | D19: IVA Responsable Inscripto | E19: 20272865869 | F19: 128100 | G19: 0
A20: 13/09/2024 | B20: FA-A 0002-00000783 | C20: Di Feo, Martin Ezequiel | D20: IVA Responsable Inscripto | E20: 20272865869 | F20: 9950 | G20: 0
A21: 19/09/2024 | B21: FA-A 0002-00000796 | C21: Di Feo, Martin Ezequiel | D21: IVA Responsable Inscripto | E21: 20272865869 | F21: 253100 | G21: 0
A22: 27/09/2024 | B22: FA-A 0002-00000816 | C22: Di Feo, Martin Ezequiel | D22: IVA Responsable Inscripto | E22: 20272865869 | F22: 9800 | G22: 0
A23: 27/09/2024 | B23: FA-A 0002-00000819 | C23: Di Feo, Martin Ezequiel | D23: IVA Responsable Inscripto | E23: 20272865869 | F23: 105000 | G23: 0
A24: 30/09/2024 | B24: FA-A 0002-00000814 | C24: Di Feo, Martin Ezequiel | D24: IVA Responsable Inscripto | E24: 20272865869 | F24: 149150 | G24: 0
A25: 05/09/2024 | B25: 760 | C25: DI FEO MARTIN EZEQUIEL | E25: 20272865869 | F25: 84450 | G25: 0
A26: 12/09/2024 | B26: 778 | C26: DI FEO MARTIN EZEQUIEL | E26: 20272865869 | F26: 128100 | G26: 0
A27: 13/09/2024 | B27: 783 | C27: DI FEO MARTIN EZEQUIEL | E27: 20272865869 | F27: 9950 | G27: 0
A28: 19/09/2024 | B28: 796 | C28: DI FEO MARTIN EZEQUIEL | E28: 20272865869 | F28: 253100 | G28: 0
A29: 26/09/2024 | B29: 814 | C29: DI FEO MARTIN EZEQUIEL | E29: 20272865869 | F29: 149150 | G29: 0
A30: 27/09/2024 | B30: 816 | C30: DI FEO MARTIN EZEQUIEL | E30: 20272865869 | F30: 9800 | G30: 0
A31: 27/09/2024 | B31: 819 | C31: DI FEO MARTIN EZEQUIEL | E31: 20272865869 | F31: 105000 | G31: 0
A32: 04/09/2024 | B32: FA-A 0007-00003241 | C32: Furlanetto, Martin | D32: IVA Responsable Inscripto | E32: 20284183534 | F32: 4545.5 | G32: 0
A33: 26/09/2024 | B33: TF-A0007-00003292 | C33: Furlanetto, Martin | D33: IVA Responsable Inscripto | E33: 20284183534 | F33: 9504.13 | G33: 0
A34: 04/09/2024 | B34: 3241 | C34: FURLANETTO MARTIN | E34: 20284183534 | F34: 4545.5 | G34: 0
A35: 26/09/2024 | B35: 3292 | C35: FURLANETTO MARTIN | E35: 20284183534 | F35: 9504.13 | G35: 0
A36: 12/09/2024 | B36: FA-A 0004-00038394 | C36: Ledesma, Emiliano Ruben | D36: IVA Responsable Inscripto | E36: 20289111329 | F36: 585730.8 | G36: 0
A37: 12/09/2024 | B37: 38394 | C37: LEDESMA EMILIANO RUBEN | E37: 20289111329 | F37: 585730.8 | G37: 0
A38: 20/09/2024 | B38: FA-A 0004-00000136 | C38: Villalba, Miguel Angel | D38: IVA Responsable Inscripto | E38: 20317488476 | F38: 1870000 | G38: 0
A39: 25/09/2024 | B39: FA-A 0004-00000137 | C39: Villalba, Miguel Angel | D39: IVA Responsable Inscripto | E39: 20317488476 | F39: 105000 | G39: 0
A40: 20/09/2024 | B40: 136 | C40: VILLALBA MIGUEL ANGEL | E40: 20317488476 | F40: 1870000 | G40: 0
A41: 25/09/2024 | B41: 137 | C41: VILLALBA MIGUEL ANGEL | E41: 20317488476 | F41: 105000 | G41: 0
A42: 13/09/2024 | B42: NC-A 0003-00000017 | C42: Nardomarino, Ezequiel Eduardo | D42: IVA Responsable Inscripto | E42: 20334976433 | F42: -188330 | G42: 0
...

Sheet Resumen Ventas 11
A1: Totales por Tipo de Comprobante - AFIP
B2: Base | C2: IVA | D2: Otros Imp. | E2: Total Compr.
A3: (FCE) A | B3: 47800480 | C3: =+B3*0.21 -> 10038101 | E3: =SUM(B3:D3) -> 57838581
A4: NC FCE A | B4: -3293388.4 | C4: =+B4*0.21 -> -691611.57 | E4: =SUM(B4:D4) -> -3985000
A5: FACTURAS A | B5: 10002680 | C5: =+B5*0.21 -> 2100562.9 | E5: =SUM(B5:D5) -> 12103243
A6: NC A | B6: -1340599.2 | C6: =+B6*0.21 -> -281525.82 | E6: =SUM(B6:D6) -> -1622125
A7: FACTURAS B | B7: 13423197 | C7: =+B7*0.21 -> 2818871.3 | E7: =SUM(B7:D7) -> 16242068
A8: NC B | B8: -1336307.9 | C8: =+B8*0.21 -> -280624.67 | E8: =SUM(B8:D8) -> -1616932.6
B9: =SUM(B3:B8) -> 65256062 | C9: =SUM(C3:C8) -> 13703773 | D9: 0 | E9: =SUM(E3:E8) -> 78959835

Sheet Ventas 11
L3: =+SUBTOTAL(109,L10:L801) -> 13423197
A8: Mis Comprobantes Emitidos - CUIT 30710473168
A9: Fecha | B9: Tipo | C9: Punto de Venta | D9: Número Desde | E9: Número Hasta | F9: Cód. Autorización | G9: Tipo Doc. Receptor | H9: Nro. Doc. Receptor | I9: Denominación Receptor | J9: Tipo Cambio | K9: Moneda | L9: Imp. Neto Gravado | M9: Imp. Neto No Gravado | N9: Imp. Op. Exentas | O9: Otros Tributos | P9: IVA | Q9: Imp. Total
A10: 01/11/2024 | B10: 1 - Factura A | C10: 7 | D10: 2227 | F10: 74448602428030 | G10: CUIT | H10: 30546771314 | I10: MEDICUS SOCIEDAD ANONIMA DE ASISTENCIA MEDICA Y CIENTIFICA | J10: 1 | K10: $ | L10: 104132.23 | M10: 0 | N10: 0 | O10: 0 | P10: 21867.77 | Q10: 126000
A11: 01/11/2024 | B11: 1 - Factura A | C11: 7 | D11: 2226 | F11: 74448600824252 | G11: CUIT | H11: 30546771314 | I11: MEDICUS SOCIEDAD ANONIMA DE ASISTENCIA MEDICA Y CIENTIFICA | J11: 1 | K11: $ | L11: 153884.3 | M11: 0 | N11: 0 | O11: 0 | P11: 32315.7 | Q11: 186200
A12: 01/11/2024 | B12: 6 - Factura B | C12: 9 | D12: 234 | F12: 74448561909174 | G12: 99 | H12: 0 | J12: 1 | K12: $ | L12: 11487.6 | M12: 0 | N12: 0 | O12: 0 | P12: 2412.4 | Q12: 13900
A13: 01/11/2024 | B13: 6 - Factura B | C13: 9 | D13: 240 | F13: 74448598039318 | G13: 99 | H13: 0 | J13: 1 | K13: $ | L13: 20661.16 | M13: 0 | N13: 0 | O13: 0 | P13: 4338.84 | Q13: 25000
A14: 01/11/2024 | B14: 6 - Factura B | C14: 9 | D14: 237 | F14: 74448569238896 | G14: 99 | H14: 0 | J14: 1 | K14: $ | L14: 23471.07 | M14: 0 | N14: 0 | O14: 0 | P14: 4928.93 | Q14: 28400
A15: 01/11/2024 | B15: 6 - Factura B | C15: 9 | D15: 241 | F15: 74448601705798 | G15: 99 | H15: 0 | J15: 1 | K15: $ | L15: 16528.93 | M15: 0 | N15: 0 | O15: 0 | P15: 3471.07 | Q15: 20000
A16: 01/11/2024 | B16: 6 - Factura B | C16: 9 | D16: 239 | F16: 74448589059048 | G16: 99 | H16: 0 | J16: 1 | K16: $ | L16: 9256.19 | M16: 0 | N16: 0 | O16: 0 | P16: 1943.81 | Q16: 11200
A17: 01/11/2024 | B17: 6 - Factura B | C17: 9 | D17: 232 | F17: 74448544837619 | G17: 99 | H17: 0 | J17: 1 | K17: $ | L17: 14669.42 | M17: 0 | N17: 0 | O17: 0 | P17: 3080.58 | Q17: 17750
A18: 01/11/2024 | B18: 6 - Factura B | C18: 9 | D18: 236 | F18: 74448567380131 | G18: 99 | H18: 0 | J18: 1 | K18: $ | L18: 11487.6 | M18: 0 | N18: 0 | O18: 0 | P18: 2412.4 | Q18: 13900
A19: 01/11/2024 | B19: 6 - Factura B | C19: 9 | D19: 235 | F19: 74448564292856 | G19: 99 | H19: 0 | J19: 1 | K19: $ | L19: 85537.18 | M19: 0 | N19: 0 | O19: 0 | P19: 17962.82 | Q19: 103500
A20: 01/11/2024 | B20: 6 - Factura B | C20: 9 | D20: 233 | F20: 74448555084195 | G20: 99 | H20: 0 | J20: 1 | K20: $ | L20: 30495.87 | M20: 0 | N20: 0 | O20: 0 | P20: 6404.13 | Q20: 36900
A21: 01/11/2024 | B21: 6 - Factura B | C21: 9 | D21: 242 | F21: 74448616564521 | G21: 99 | H21: 0 | J21: 1 | K21: $ | L21: 14669.42 | M21: 0 | N21: 0 | O21: 0 | P21: 3080.58 | Q21: 17750
A22: 01/11/2024 | B22: 6 - Factura B | C22: 9 | D22: 238 | F22: 74448577672628 | G22: 99 | H22: 0 | J22: 1 | K22: $ | L22: 14669.42 | M22: 0 | N22: 0 | O22: 0 | P22: 3080.58 | Q22: 17750
A23: 01/11/2024 | B23: 6 - Factura B | C23: 3 | D23: 2862 | F23: 74448548497786 | G23: CUIL | H23: 20078376105 | I23: SCHERNETZKI ANSELMO | J23: 1 | K23: $ | L23: 314049.57 | M23: 0 | N23: 0 | O23: 0 | P23: 65950.41 | Q23: 380000
A24: 01/11/2024 | B24: 6 - Factura B | C24: 3 | D24: 2863 | F24: 74448603364668 | G24: DNI | H24: 35940091 | I24: ROMERO LEONARDO ARIEL | J24: 1 | K24: $ | L24: 12727.29 | M24: 0 | N24: 0 | O24: 0 | P24: 2672.73 | Q24: 15400
A25: 01/11/2024 | B25: 6 - Factura B | C25: 3 | D25: 2864 | F25: 74448610147202 | G25: DNI | H25: 18066137 | I25: RAIDEN RICARDO | J25: 1 | K25: $ | L25: 17355.38 | M25: 0 | N25: 0 | O25: 0 | P25: 3644.63 | Q25: 21000
A26: 04/11/2024 | B26: 1 - Factura A | C26: 7 | D26: 2228 | F26: 74458947045077 | G26: CUIT | H26: 30715186655 | I26: AMPARO SALUD S.R.L. | J26: 1 | K26: $ | L26: 420498.35 | M26: 0 | N26: 0 | O26: 0 | P26: 88304.65 | Q26: 508803
A27: 04/11/2024 | B27: 1 - Factura A | C27: 7 | D27: 2229 | F27: 74458947251680 | G27: CUIT | H27: 30715186655 | I27: AMPARO SALUD S.R.L. | J27: 1 | K27: $ | L27: 56198.35 | M27: 0 | N27: 0 | O27: 0 | P27: 11801.65 | Q27: 68000
A28: 04/11/2024 | B28: 1 - Factura A | C28: 7 | D28: 2231 | F28: 74458951113373 | G28: CUIT | H28: 30711244383 | I28: LOGIN DOOR S.A | J28: 1 | K28: $ | L28: 60331.43 | M28: 0 | N28: 0 | O28: 0 | P28: 12669.6 | Q28: 73001.03
A29: 04/11/2024 | B29: 1 - Factura A | C29: 7 | D29: 2230 | F29: 74458948601244 | G29: CUIT | H29: 30710538014 | I29: HC HOMECARE INTERNACION DOMICILIARIA S.A. | J29: 1 | K29: $ | L29: 436033.06 | M29: 0 | N29: 0 | O29: 0 | P29: 91566.94 | Q29: 527600
A30: 04/11/2024 | B30: 6 - Factura B | C30: 9 | D30: 243 | F30: 74458877910909 | G30: 99 | H30: 0 | J30: 1 | K30: $ | L30: 16942.15 | M30: 0 | N30: 0 | O30: 0 | P30: 3557.85 | Q30: 20500
A31: 04/11/2024 | B31: 6 - Factura B | C31: 9 | D31: 247 | F31: 74458927986748 | G31: 99 | H31: 0 | J31: 1 | K31: $ | L31: 29338.84 | M31: 0 | N31: 0 | O31: 0 | P31: 6161.16 | Q31: 35500
A32: 04/11/2024 | B32: 6 - Factura B | C32: 9 | D32: 245 | F32: 74458922661220 | G32: 99 | H32: 0 | J32: 1 | K32: $ | L32: 10743.8 | M32: 0 | N32: 0 | O32: 0 | P32: 2256.2 | Q32: 13000
A33: 04/11/2024 | B33: 6 - Factura B | C33: 9 | D33: 244 | F33: 74458879179224 | G33: 99 | H33: 0 | J33: 1 | K33: $ | L33: 4132.23 | M33: 0 | N33: 0 | O33: 0 | P33: 867.77 | Q33: 5000
A34: 04/11/2024 | B34: 6 - Factura B | C34: 7 | D34: 5426 | F34: 74458912363535 | G34: DNI | H34: 17198648 | I34: LOCOCO CARMEN CLAUDIA | J34: 1 | K34: $ | L34: 19834.71 | M34: 0 | N34: 0 | O34: 0 | P34: 4165.29 | Q34: 24000
A35: 04/11/2024 | B35: 6 - Factura B | C35: 7 | D35: 5427 | F35: 74458952323313 | G35: CUIT | H35: 30571766287 | I35: OBRA SOCIAL DEL PERSONAL DE LA INDUSTRIA DEL PLASTICO | J35: 1 | K35: $ | L35: 167570.25 | M35: 0 | N35: 0 | O35: 0 | P35: 35189.75 | Q35: 202760
A36: 04/11/2024 | B36: 6 - Factura B | C36: 9 | D36: 246 | F36: 74458924110077 | G36: 99 | H36: 0 | J36: 1 | K36: $ | L36: 8264.46 | M36: 0 | N36: 0 | O36: 0 | P36: 1735.54 | Q36: 10000
A37: 04/11/2024 | B37: 6 - Factura B | C37: 3 | D37: 2865 | F37: 74458902778395 | J37: 1 | K37: $ | L37: 12396.71 | M37: 0 | N37: 0 | O37: 0 | P37: 2603.31 | Q37: 15000
A38: 04/11/2024 | B38: 6 - Factura B | C38: 3 | D38: 2869 | F38: 74458939112061 | J38: 1 | K38: $ | L38: 17355.38 | M38: 0 | N38: 0 | O38: 0 | P38: 3644.63 | Q38: 21000
A39: 04/11/2024 | B39: 6 - Factura B | C39: 3 | D39: 2872 | F39: 74458942253899 | G39: DNI | H39: 18057302 | I39: CARABALLO LUIS FERNANDO | J39: 1 | K39: $ | L39: 18677.67 | M39: 0 | N39: 0 | O39: 0 | P39: 3922.31 | Q39: 22600
A40: 04/11/2024 | B40: 6 - Factura B | C40: 3 | D40: 2867 | F40: 74458937256075 | G40: DNI | H40: 28369491 | I40: BELLIA MARIANA CRISTINA | J40: 1 | K40: $ | L40: 21900.81 | M40: 0 | N40: 0 | O40: 0 | P40: 4599.17 | Q40: 26500
A41: 04/11/2024 | B41: 6 - Factura B | C41: 3 | D41: 2866 | F41: 74458912240084 | G41: DNI | H41: 11987513 | I41: MORGAN SANTIAGO | J41: 1 | K41: $ | L41: 34297.52 | M41: 0 | N41: 0 | O41: 0 | P41: 7202.48 | Q41: 41500
A42: 04/11/2024 | B42: 6 - Factura B | C42: 3 | D42: 2870 | F42: 74458940452154 | G42: DNI | H42: 17795042 | I42: ZUMBO MARIA LAURA | J42: 1 | K42: $ | L42: 35041.33 | M42: 0 | N42: 0 | O42: 0 | P42: 7358.68 | Q42: 42400
A43: 04/11/2024 | B43: 6 - Factura B | C43: 3 | D43: 2868 | F43: 74458937935802 | G43: DNI | H43: 17467464 | I43: ROMERO JUAN CARLOS | J43: 1 | K43: $ | L43: 12727.29 | M43: 0 | N43: 0 | O43: 0 | P43: 2672.73 | Q43: 15400
A44: 04/11/2024 | B44: 6 - Factura B | C44: 3 | D44: 2871 | F44: 74458941173907 | G44: DNI | H44: 18811819 | I44: CLIMENT BORZANI ANA GABRIELA | J44: 1 | K44: $ | L44: 12396.71 | M44: 0 | N44: 0 | O44: 0 | P44: 2603.31 | Q44: 15000
A45: 05/11/2024 | B45: 1 - Factura A | C45: 7 | D45: 2232 | F45: 74458049339978 | G45: CUIT | H45: 30522428163 | I45: GALENO ARGENTINA SOCIEDAD ANONIMA | J45: 1 | K45: $ | L45: 37190.08 | M45: 0 | N45: 0 | O45: 0 | P45: 7809.92 | Q45: 45000
A46: 05/11/2024 | B46: 1 - Factura A | C46: 7 | D46: 2233 | F46: 74458065861742 | G46: CUIT | H46: 30522428163 | I46: GALENO ARGENTINA SOCIEDAD ANONIMA | J46: 1 | K46: $ | L46: 280783.17 | M46: 0 | N46: 0 | O46: 0 | P46: 58964.47 | Q46: 339747.64
...

Sheet Compras 11
A1: Mis Comprobantes Recibidos - CUIT 30710473168
A2: Fecha | B2: Tipo | C2: Punto de Venta | D2: Número Desde | E2: Número Hasta | F2: Cód. Autorización | G2: Tipo Doc. Emisor | H2: Nro. Doc. Emisor | I2: Denominación Emisor | J2: Tipo Cambio | K2: Moneda | L2: Imp. Neto Gravado | M2: Imp. Neto No Gravado | N2: Imp. Op. Exentas | O2: Otros Tributos | P2: IVA | Q2: Imp. Total
A3: 01/11/2024 | B3: 1 - Factura A | C3: 500 | D3: 1641624 | F3: 74447326861618 | G3: CUIT | H3: 30654118767 | I3: SOLUCIONES MULTIMEDIA S A | J3: 1 | K3: $ | L3: 102077.93 | M3: 0 | N3: 0 | O3: 6359.83 | P3: 21436.37 | Q3: 129874.13
A4: 01/11/2024 | B4: 1 - Factura A | C4: 17 | D4: 10855 | F4: 74440611010248 | G4: CUIT | H4: 30661143610 | I4: ORTOPEDIA BERNAT SRL | J4: 1 | K4: $ | L4: 3950700 | M4: 0 | N4: 0 | O4: 197535 | P4: 829647 | Q4: 4977882
A5: 01/11/2024 | B5: 1 - Factura A | C5: 629 | D5: 5571683 | F5: 34433634355672 | G5: CUIT | H5: 30663498513 | I5: GRUPO CONCESIONARIO DEL OESTE SA | J5: 1 | K5: $ | L5: 6731.58 | M5: 0 | N5: 0 | O5: 336.58 | P5: 1413.6 | Q5: 8481.76
A6: 01/11/2024 | B6: 1 - Factura A | C6: 711 | D6: 6334596 | F6: 34439311727749 | G6: CUIT | H6: 30677237119 | I6: AUTOPISTAS DEL SOL S A | J6: 1 | K6: $ | L6: 3312.36 | M6: 0 | N6: 99.37 | O6: 165.62 | P6: 695.58 | Q6: 4272.93
A7: 01/11/2024 | B7: 1 - Factura A | C7: 2 | D7: 6 | F7: 74440602724999 | G7: CUIT | H7: 20233007820 | I7: MUSSO LUIS ADRIAN | J7: 1 | K7: $ | L7: 23600 | M7: 0 | N7: 0 | O7: 0 | P7: 4956 | Q7: 28556
A8: 01/11/2024 | B8: 11 - Factura C | C8: 3 | D8: 1010 | F8: 74449587504125 | G8: CUIT | H8: 20216451679 | I8: VAZQUEZ RICARDO OSCAR | J8: 1 | K8: $ | O8: 0 | Q8: 400000
A9: 02/11/2024 | B9: 1 - Factura A | C9: 3051 | D9: 831166 | F9: 74447821819310 | G9: CUIT | H9: 30678814357 | I9: TELEFONICA MOVILES ARGENTINA SOCIEDAD ANONIMA | J9: 1 | K9: $ | L9: 28282.81 | M9: 0 | N9: 0 | O9: 3787.98 | P9: 7636.36 | Q9: 39707.15
A10: 04/11/2024 | B10: 1 - Factura A | C10: 5 | D10: 160678 | F10: 74453921324614 | G10: CUIT | H10: 30598960093 | I10: SILVESTRIN FABRIS SOC RESP LTDA | J10: 1 | K10: $ | L10: 393556.5 | M10: 0 | N10: 0 | O10: 19677.83 | P10: 82646.86 | Q10: 495881.19
A11: 04/11/2024 | B11: 1 - Factura A | C11: 6 | D11: 86462 | F11: 74454883728913 | G11: CUIT | H11: 30711553564 | I11: SALUDTEX SA | J11: 1 | K11: $ | L11: 249584 | M11: 0 | N11: 0 | O11: 0 | P11: 52412.64 | Q11: 301996.64
A12: 04/11/2024 | B12: 1 - Factura A | C12: 5 | D12: 160663 | F12: 74453883837723 | G12: CUIT | H12: 30598960093 | I12: SILVESTRIN FABRIS SOC RESP LTDA | J12: 1 | K12: $ | L12: 642151.5 | M12: 0 | N12: 0 | O12: 32107.58 | P12: 134851.81 | Q12: 809110.89
A13: 04/11/2024 | B13: 1 - Factura A | C13: 6 | D13: 86458 | F13: 74454881337054 | G13: CUIT | H13: 30711553564 | I13: SALUDTEX SA | J13: 1 | K13: $ | L13: 1182131.9 | M13: 0 | N13: 0 | O13: 0 | P13: 248247.71 | Q13: 1430379.6
A14: 04/11/2024 | B14: 1 - Factura A | C14: 6 | D14: 86459 | F14: 74454881511572 | G14: CUIT | H14: 30711553564 | I14: SALUDTEX SA | J14: 1 | K14: $ | L14: 831346.9 | M14: 0 | N14: 0 | O14: 0 | P14: 174582.85 | Q14: 1005929.8
A15: 04/11/2024 | B15: 1 - Factura A | C15: 6 | D15: 86460 | F15: 74454881999129 | G15: CUIT | H15: 30711553564 | I15: SALUDTEX SA | J15: 1 | K15: $ | L15: 224853.6 | M15: 0 | N15: 0 | O15: 0 | P15: 47219.26 | Q15: 272072.86
A16: 04/11/2024 | B16: 1 - Factura A | C16: 401 | D16: 100 | F16: 74454890527415 | G16: CUIT | H16: 30716234114 | I16: UZUMAKI S.A.S. | J16: 1220 | K16: USD | L16: =129.3*1220 -> 157746 | M16: 0 | N16: 0 | O16: 0 | P16: =+L16*0.21 -> 33126.66 | Q16: =+P16+L16 -> 190872.66
A17: 04/11/2024 | B17: 1 - Factura A | C17: 1 | D17: 649205 | F17: 74469903137915 | G17: CUIT | H17: 33716307749 | I17: VERISURE ARGENTINA MONITOREO DE ALARMAS SA | J17: 1 | K17: $ | L17: 34999 | M17: 0 | N17: 0 | O17: 1749.95 | P17: 7349.79 | Q17: 44098.74
A18: 04/11/2024 | B18: 1 - Factura A | C18: 2 | D18: 221 | F18: 74452914341353 | G18: CUIT | H18: 30605344352 | I18: CONSORCIO BARTOLOME MITRE 2466 | J18: 1 | K18: $ | L18: 834000 | M18: 0 | N18: 0 | O18: 0 | P18: 175140 | Q18: 1009140
A19: 04/11/2024 | B19: 3 - Nota de Crédito A | C19: 6 | D19: 12145 | F19: 74454883499642 | G19: CUIT | H19: 30711553564 | I19: SALUDTEX SA | J19: 1 | K19: $ | L19: -145916.26 | M19: 0 | N19: 0 | O19: 0 | P19: =+L19*0.21 -> -30642.415 | Q19: =+P19+L19 -> -176558.67
A20: 04/11/2024 | B20: 11 - Factura C | C20: 3 | D20: 9725 | F20: 74456937615061 | G20: CUIT | H20: 20167634436 | I20: DEMARIA AUGUSTO CARLOS | J20: 1 | K20: $ | O20: 0 | Q20: 4570
A21: 04/11/2024 | B21: 11 - Factura C | C21: 2 | D21: 313 | F21: 74448830666315 | G21: CUIT | H21: 27265832178 | I21: BLASCO MARIA GUADALUPE | J21: 1 | K21: $ | O21: 0 | Q21: 3200000
A22: 04/11/2024 | B22: 11 - Factura C | C22: 3 | D22: 893 | F22: 74453925401501 | G22: CUIT | H22: 20086277523 | I22: BOTINDARI JUAN CARLOS | J22: 1 | K22: $ | O22: 0 | Q22: 275500
A23: 06/11/2024 | B23: 1 - Factura A | C23: 1 | D23: 106971 | F23: 74459220885612 | G23: CUIT | H23: 30714864269 | I23: CONTABILIUM S.A. | J23: 1 | K23: $ | L23: 115939.17 | M23: 0 | N23: 0 | O23: 0 | P23: 24347.23 | Q23: 140286.4
A24: 06/11/2024 | B24: 1 - Factura A | C24: 17 | D24: 10884 | F24: 74450210166030 | G24: CUIT | H24: 30661143610 | I24: ORTOPEDIA BERNAT SRL | J24: 1 | K24: $ | L24: 565493.55 | M24: 0 | N24: 0 | O24: 28274.68 | P24: 118753.65 | Q24: 712521.88
A25: 06/11/2024 | B25: 1 - Factura A | C25: 8 | D25: 1712 | F25: 74451209572827 | G25: CUIT | H25: 30708973501 | I25: ASIAL S.R.L. | J25: 1 | K25: $ | L25: 831850 | M25: 0 | N25: 0 | O25: 0 | P25: 174688.5 | Q25: 1006538.5
A26: 06/11/2024 | B26: 11 - Factura C | C26: 1 | D26: 9 | F26: 74453269307006 | G26: CUIT | H26: 27443612713 | I26: MIGOYA MORIONDO SOFIA | J26: 1 | K26: $ | O26: 0 | Q26: 850000
A27: 07/11/2024 | B27: 1 - Factura A | C27: 5015 | D27: 663243 | F27: 74454290535475 | G27: CUIT | H27: 30574876474 | I27: AUTOPISTAS URBANAS S A | J27: 1 | K27: $ | L27: 5655.84 | M27: 0 | N27: 0 | O27: 735.25 | P27: 1187.72 | Q27: 7578.81
A28: 07/11/2024 | B28: 1 - Factura A | C28: 2 | D28: 908 | F28: 74459364672319 | G28: CUIT | H28: 20272865869 | I28: DI FEO MARTIN EZEQUIEL | J28: 1 | K28: $ | L28: 126700 | M28: 0 | N28: 0 | O28: 0 | P28: 26607 | Q28: 153307
A29: 07/11/2024 | B29: 11 - Factura C | C29: 2 | D29: 514 | F29: 74451358198277 | G29: CUIT | H29: 27299725761 | I29: TURSARKISIAN MISISIAN VERONICA GEMA | J29: 1 | K29: $ | O29: 0 | Q29: 460000
A30: 08/11/2024 | B30: 1 - Factura A | C30: 2 | D30: 909 | F30: 74459437726799 | G30: CUIT | H30: 20272865869 | I30: DI FEO MARTIN EZEQUIEL | J30: 1 | K30: $ | L30: 10050 | M30: 0 | N30: 0 | O30: 0 | P30: 2110.5 | Q30: 12160.5
A31: 08/11/2024 | B31: 1 - Factura A | C31: 4 | D31: 38780 | F31: 74459471135405 | G31: CUIT | H31: 20289111329 | I31: LEDESMA EMILIANO RUBEN | J31: 1 | K31: $ | L31: 585348.09 | M31: 0 | N31: 0 | O31: 0 | P31: 122923.1 | Q31: 708271.19
A32: 08/11/2024 | B32: 1 - Factura A | C32: 5 | D32: 2014 | F32: 74456481045397 | G32: CUIT | H32: 30712187316 | I32: ITALOMED PRODUCTOS SRL | J32: 1 | K32: $ | L32: 263903.45 | M32: 0 | N32: 0 | O32: 0 | P32: 55419.72 | Q32: 319323.17
A33: 08/11/2024 | B33: 1 - Factura A | C33: 120 | D33: 5322 | F33: 74455493316593 | G33: CUIT | H33: 30587197215 | I33: PANATEL SOCIEDAD ANONIMA | J33: 1 | K33: $ | L33: 68595.04 | M33: 0 | N33: 0 | O33: 3429.75 | P33: 14404.96 | Q33: 86429.75
A34: 09/11/2024 | B34: 1 - Factura A | C34: 3101 | D34: 197858 | F34: 74457706084453 | G34: CUIT | H34: 30678814357 | I34: TELEFONICA MOVILES ARGENTINA SOCIEDAD ANONIMA | J34: 1 | K34: $ | L34: 68662.57 | M34: 0 | N34: 0 | O34: 5493.01 | P34: 18538.89 | Q34: 92694.47
A35: 11/11/2024 | B35: 1 - Factura A | C35: 2 | D35: 255 | F35: 74463794655257 | G35: CUIT | H35: 27144282383 | I35: SCHEJTER LILA ELISA | J35: 1 | K35: $ | L35: 50000 | M35: 0 | N35: 0 | O35: 0 | P35: 10500 | Q35: 60500
A36: 11/11/2024 | B36: 1 - Factura A | C36: 7 | D36: 6 | F36: 74463805989277 | G36: CUIT | H36: 27325223273 | I36: SOUSA ALDERETE ALEJANDRA MABEL | J36: 1 | K36: $ | L36: 850000 | M36: 0 | N36: 0 | O36: 0 | P36: 178500 | Q36: 1028500
A37: 12/11/2024 | B37: 1 - Factura A | C37: 1 | D37: 5318 | F37: 74461943651694 | G37: CUIT | H37: 30715141201 | I37: REHAB S.R.L. | J37: 1 | K37: $ | L37: 273915 | M37: 0 | N37: 0 | O37: 0 | P37: 57522.15 | Q37: 331437.15
A38: 12/11/2024 | B38: 1 - Factura A | C38: 17 | D38: 2449 | F38: 74461967994767 | G38: CUIT | H38: 30711764921 | I38: RELIEF CENTER S.R.L. | J38: 1 | K38: $ | L38: 305928 | M38: 0 | N38: 0 | O38: 0 | P38: 64244.88 | Q38: 370172.88
A39: 12/11/2024 | B39: 1 - Factura A | C39: 1 | D39: 5319 | F39: 74461944646171 | G39: CUIT | H39: 30715141201 | I39: REHAB S.R.L. | J39: 1 | K39: $ | L39: 665437.5 | M39: 0 | N39: 0 | O39: 0 | P39: 139741.88 | Q39: 805179.38
A40: 12/11/2024 | B40: 1 - Factura A | C40: 5 | D40: 38 | F40: 74462965211526 | G40: CUIT | H40: 30707370552 | I40: RAKE S.A. | J40: 1 | K40: $ | L40: 950000 | M40: 0 | N40: 0 | O40: 0 | P40: 199500 | Q40: 1149500
...
