Workbook
Name partner_id: Configuracion!$B$332

Sheet Configuracion
F1: CUIT | G1: Cargar sin guiones
F2: RAZON SOCIAL | G2: Maximo 30 caracteres
A3: CUIT | B3: RAZON SOCIAL | C3: DETALLE | F3: DETALLE | G3: Cargar tipo de gasto
A4: 30628205090 | B4: ALBAMIE SA | C4: CLIENTE
A5: 30711678820 | B5: 2PSI INGENIERIA SRL | C5: PROVEEDOR
A6: 33716367539 | B6: 3PI S.A.S. | C6: PROVEEDOR
A7: 30660373108 | B7: ABC SA | C7: VARIOS
A8: 20300210881 | B8: ABOY DIEGO OSCAR | C8: PROVEEDOR
A9: 27229910782 | B9: ABUGAUCH MARIA DE LOS ANGELES | C9: PROVEEDOR
A10: 20242709897 | B10: ABUGAUCH VICTOR HUGO | C10: PROVEEDOR
A11: 20281669053 | B11: ACOSTA JAVIER GUSTAVO | C11: FLETE
A12: 20174240125 | B12: ACOSTA OSCAR ISIDRO | C12: VARIOS
A13: 30641659106 | B13: AGRISOL SA | C13: VARIOS
A14: 33709914109 | B14: ALAN COLLECTION SA | C14: VARIOS
A15: 20267161616 | B15: ALBAJARI DIEGO MARCOS | C15: VARIOS
... A155: 30537679855 | B155: ESTACION LIMA SA | C155: VARIOS
A156: 30-56864959-8 | B156: EXPRESO BISONTE SRL | C156: FLETE
A157: 30708542349 | B157: EXPRESO FORMOSA SRL | C157: FLETE
A158: 30526582884 | B158: EXPRESO MAR DEL PLATA SA | C158: FLETE
A159: 30577744579 | B159: EXPRESO TROLE SRL | C159: FLETE
A160: 30715949292 | B160: EYPAPEL SAS | C160: GASTOS VARIOS
A161: 30715980807 | B161: FABORT SRL | C161: PROVEEDOR
A162: 20359718765 | B162: FAIL ABRAHAM | C162: VARIOS
A163: 30643518364 | B163: FARMACIA DE MEDRANO SCS | C163: PROVEEDOR
A164: 30692138747 | B164: FARMACITY SA | C164: VARIOS
A165: 33712234429 | B165: FEDAGAS SA | C165: VARIOS
A166: 20353576012 | B166: FEDERICO PABLO FEOLA | C166: VARIOS
A167: 20343766441 | B167: FERNANDEZ MAURO | C167: TALLER
A168: 27062343449 | B168: FERREIRA LILIANA INES | C168: FLETE
... A538: 30693066022 | B538: Mg Farmaceutica Sociedad En CS | C538: VARIOS

Sheet AGOSTO
A1: ORTOPEDIA GEMINIS S.A. | J1: 45139
A4: LIBRO IVA COMPRAS
A6: FACTURAS A
A7: FECHA | B7: PTO VTA | C7: FAC A | D7: CUIT | E7: RAZON SOCIAL | F7: NETO | G7: IVA 21% | H7: IVA 27% | I7: IVA 10,5% | J7: P IVA | K7: IIBB CF | L7: IIBB BS | M7: NO GRAV | N7: OTROS | O7: TOTAL | P7: DETALLE
A8: 09/04/2023 | B8: 11 | C8: 1535829 | D8: 30709776564 | E8: =VLOOKUP(D8,Configuracion!$A$4:$C$591,2,FALSE) -> PROSEGUR ACTIVA ARG SA | F8: 14992.91 | G8: =F8*21% -> 3148.5111 | K8: =+F8*0.035 -> 524.75185 | O8: =SUM(F8:N8) -> 18666.173 | P8: =VLOOKUP(D8,Configuracion!$A$4:$C$591,3,FALSE) -> SEGUROS
A9: 45111 | B9: 1055 | C9: 546 | D9: 30685849751 | E9: =VLOOKUP(D9,Configuracion!$A$4:$C$591,2,FALSE) -> DIA ARGENTINA SA | F9: 914.88 | G9: =F9*21% -> 192.1248 | O9: =SUM(F9:N9) -> 1107.0048 | P9: =VLOOKUP(D9,Configuracion!$A$4:$C$591,3,FALSE) -> VARIOS
A10: 45124 | B10: 17 | C10: 1153 | D10: 30711764921 | E10: =VLOOKUP(D10,Configuracion!$A$4:$C$591,2,FALSE) -> RELIEF CENTER SRL | F10: 14834 | G10: =F10*21% -> 3115.14 | O10: =SUM(F10:N10) -> 17949.14 | P10: =VLOOKUP(D10,Configuracion!$A$4:$C$591,3,FALSE) -> PROVEEDOR
A11: 45124 | B11: 4264 | C11: 2395412 | D11: 30639453738 | E11: =VLOOKUP(D11,Configuracion!$A$4:$C$591,2,FALSE) -> TELECOM ARGENTINA SA | F11: =10586.78+3851.24 -> 14438.02 | G11: =F11*21% -> 3031.9842 | J11: 433.14 | K11: 505.33 | O11: =SUM(F11:N11) -> 18408.474 | P11: =VLOOKUP(D11,Configuracion!$A$4:$C$591,3,FALSE) -> SERVICIO
A12: 45124 | B12: 13 | C12: 1208 | D12: 33709914109 | E12: =VLOOKUP(D12,Configuracion!$A$4:$C$591,2,FALSE) -> ALAN COLLECTION SA | F12: 4628.1 | G12: =F12*21% -> 971.901 | O12: =SUM(F12:N12) -> 5600.001 | P12: =VLOOKUP(D12,Configuracion!$A$4:$C$591,3,FALSE) -> VARIOS
A13: 45126 | B13: 17 | C13: 1161 | D13: 30711764921 | E13: =VLOOKUP(D13,Configuracion!$A$4:$C$591,2,FALSE) -> RELIEF CENTER SRL | F13: 39660 | G13: =F13*21% -> 8328.6 | O13: =SUM(F13:N13) -> 47988.6 | P13: =VLOOKUP(D13,Configuracion!$A$4:$C$591,3,FALSE) -> PROVEEDOR
A14: 45127 | B14: 7 | C14: 2010 | D14: 20284183534 | E14: =VLOOKUP(D14,Configuracion!$A$4:$C$591,2,FALSE) -> FURLANETTO MARTIN | F14: 2479.34 | G14: =F14*21% -> 520.6614 | O14: =SUM(F14:N14) -> 3000.0014 | P14: =VLOOKUP(D14,Configuracion!$A$4:$C$591,3,FALSE) -> VARIOS
A15: 45128 | B15: 7 | C15: 2019 | D15: 20284183534 | E15: =VLOOKUP(D15,Configuracion!$A$4:$C$591,2,FALSE) -> FURLANETTO MARTIN | F15: 1818.18 | G15: =F15*21% -> 381.8178 | O15: =SUM(F15:N15) -> 2199.9978 | P15: =VLOOKUP(D15,Configuracion!$A$4:$C$591,3,FALSE) -> VARIOS
A16: 45128 | B16: 7 | C16: 2020 | D16: 20284183534 | E16: =VLOOKUP(D16,Configuracion!$A$4:$C$591,2,FALSE) -> FURLANETTO MARTIN | F16: 851.25 | G16: =F16*21% -> 178.7625 | O16: =SUM(F16:N16) -> 1030.0125 | P16: =VLOOKUP(D16,Configuracion!$A$4:$C$591,3,FALSE) -> VARIOS
A17: 45128 | B17: 7 | C17: 2017 | D17: 20284183534 | E17: =VLOOKUP(D17,Configuracion!$A$4:$C$591,2,FALSE) -> FURLANETTO MARTIN | F17: 404.96 | G17: =F17*21% -> 85.0416 | O17: =SUM(F17:N17) -> 490.0016 | P17: =VLOOKUP(D17,Configuracion!$A$4:$C$591,3,FALSE) -> VARIOS
A18: 45128 | B18: 15 | C18: 23029 | D18: 30685116657 | E18: =VLOOKUP(D18,Configuracion!$A$4:$C$591,2,FALSE) -> MIRVAR SA | F18: 9890.73 | G18: =F18*21% -> 2077.0533 | N18: 1038.34 | O18: =SUM(F18:N18) -> 13006.123 | P18: =VLOOKUP(D18,Configuracion!$A$4:$C$591,3,FALSE) -> VARIOS
A19: 45131 | B19: 7 | C19: 2024 | D19: 20284183534 | E19: =VLOOKUP(D19,Configuracion!$A$4:$C$591,2,FALSE) -> FURLANETTO MARTIN | F19: 1603.31 | G19: =F19*21% -> 336.6951 | O19: =SUM(F19:N19) -> 1940.0051 | P19: =VLOOKUP(D19,Configuracion!$A$4:$C$591,3,FALSE) -> VARIOS
A20: 31/07/2023 | B20: 20 | C20: 156206 | D20: 30696850972 | E20: =VLOOKUP(D20,Configuracion!$A$4:$C$591,2,FALSE) -> CPS COMUNICACIONES SA | F20: 4302.05 | H20: =+F20*0.27 -> 1161.5535 | K20: =+F20*0.035 -> 150.57175 | O20: =SUM(F20:N20) -> 5614.1753 | P20: =VLOOKUP(D20,Configuracion!$A$4:$C$591,3,FALSE) -> SERVICIO
A21: 31/07/2023 | B21: 9044 | C21: 17802 | D21: 30678774495 | E21: =VLOOKUP(D21,Configuracion!$A$4:$C$591,2,FALSE) -> OPERADORA DE ESTAC. DE SERV SA | F21: 11747.47 | G21: =F21*21% -> 2466.9687 | M21: 785.56 | O21: =SUM(F21:N21) -> 14999.999 | P21: =VLOOKUP(D21,Configuracion!$A$4:$C$591,3,FALSE) -> VARIOS
A22: 31/07/2023 | B22: 9044 | C22: 17803 | D22: 30678774495 | E22: =VLOOKUP(D22,Configuracion!$A$4:$C$591,2,FALSE) -> OPERADORA DE ESTAC. DE SERV SA | F22: 2358.12 | G22: =F22*21% -> 495.2052 | M22: 157.69 | O22: =SUM(F22:N22) -> 3011.0152 | P22: =VLOOKUP(D22,Configuracion!$A$4:$C$591,3,FALSE) -> VARIOS
A23: 01/08/2023 | B23: 2 | C23: 190 | D23: 30605344352 | E23: =VLOOKUP(D23,Configuracion!$A$4:$C$591,2,FALSE) -> CONSORCIO BARTOLME MITRE 2466 | F23: 230000 | G23: =F23*21% -> 48300 | O23: =SUM(F23:N23) -> 278300 | P23: =VLOOKUP(D23,Configuracion!$A$4:$C$591,3,FALSE) -> CONSORCIO
A24: 01/08/2023 | B24: 10 | C24: 646 | D24: 23324039759 | E24: =VLOOKUP(D24,Configuracion!$A$4:$C$591,2,FALSE) -> RAGO DIEGO ORLANDO | F24: 17834.72 | G24: =F24*21% -> 3745.2912 | O24: =SUM(F24:N24) -> 21580.011 | P24: =VLOOKUP(D24,Configuracion!$A$4:$C$591,3,FALSE) -> VARIOS
A25: 01/08/2023 | B25: 7 | C25: 16138 | D25: 30709214078 | E25: =VLOOKUP(D25,Configuracion!$A$4:$C$591,2,FALSE) -> REHAVITA SA | F25: 1529952.5 | G25: 302414.59 | I25: 9437.72 | O25: =SUM(F25:N25) -> 1841804.8 | P25: =VLOOKUP(D25,Configuracion!$A$4:$C$591,3,FALSE) -> PROVEEDOR
A26: 01/08/2023 | B26: 7 | C26: 16142 | D26: 30709214078 | E26: =VLOOKUP(D26,Configuracion!$A$4:$C$591,2,FALSE) -> REHAVITA SA | F26: 37740 | I26: 3962.7 | O26: =SUM(F26:N26) -> 41702.7 | P26: =VLOOKUP(D26,Configuracion!$A$4:$C$591,3,FALSE) -> PROVEEDOR
A27: 01/08/2023 | B27: 4 | C27: 56 | D27: 20317488476 | E27: =VLOOKUP(D27,Configuracion!$A$4:$C$591,2,FALSE) -> VILLALBA MIGUEL ANGEL | F27: 170912 | G27: =F27*21% -> 35891.52 | O27: =SUM(F27:N27) -> 206803.52 | P27: =VLOOKUP(D27,Configuracion!$A$4:$C$591,3,FALSE) -> PROVEEDOR
A28: 02/08/2023 | B28: 2 | C28: 7361 | D28: 30694549817 | E28: =VLOOKUP(D28,Configuracion!$A$4:$C$591,2,FALSE) -> DISEÑOS JERY SRL | F28: 477494.37 | G28: =F28*21% -> 100273.82 | O28: =SUM(F28:N28) -> 577768.19 | P28: =VLOOKUP(D28,Configuracion!$A$4:$C$591,3,FALSE) -> PROVEEDOR
A29: 02/08/2023 | B29: 7 | C29: 16163 | D29: 30709214078 | E29: =VLOOKUP(D29,Configuracion!$A$4:$C$591,2,FALSE) -> REHAVITA SA | F29: 90596 | G29: =F29*21% -> 19025.16 | O29: =SUM(F29:N29) -> 109621.16 | P29: =VLOOKUP(D29,Configuracion!$A$4:$C$591,3,FALSE) -> PROVEEDOR
A30: 02/08/2023 | B30: 7 | C30: 16164 | D30: 30709214078 | E30: =VLOOKUP(D30,Configuracion!$A$4:$C$591,2,FALSE) -> REHAVITA SA | F30: 136437.5 | I30: 14325.94 | O30: =SUM(F30:N30) -> 150763.44 | P30: =VLOOKUP(D30,Configuracion!$A$4:$C$591,3,FALSE) -> PROVEEDOR
A31: 45141 | B31: 2 | C31: 6 | D31: 20272865869 | E31: =VLOOKUP(D31,Configuracion!$A$4:$C$591,2,FALSE) -> DI FEO MARTIN EZEQUIEL | F31: 43522.24 | G31: =F31*21% -> 9139.6704 | O31: =SUM(F31:N31) -> 52661.91 | P31: =VLOOKUP(D31,Configuracion!$A$4:$C$591,3,FALSE) -> PROVEEDOR
A32: 45141 | B32: 2 | C32: 1 | D32: 20272865869 | E32: =VLOOKUP(D32,Configuracion!$A$4:$C$591,2,FALSE) -> DI FEO MARTIN EZEQUIEL | F32: -3655.36 | G32: =F32*21% -> -767.6256 | O32: =SUM(F32:N32) -> -4422.9856 | P32: =VLOOKUP(D32,Configuracion!$A$4:$C$591,3,FALSE) -> PROVEEDOR
A33: 03/08/2023 | B33: 7 | C33: 27748 | D33: 20271532483 | E33: =VLOOKUP(D33,Configuracion!$A$4:$C$591,2,FALSE) -> DIEGO MARTIN RIOS | F33: 1362250.2 | G33: =F33*21% -> 286072.54 | K33: 47678.76 | O33: =SUM(F33:N33) -> 1696001.5 | P33: =VLOOKUP(D33,Configuracion!$A$4:$C$591,3,FALSE) -> PROVEEDOR
A34: 03/08/2023 | B34: 7 | C34: 27749 | D34: 20271532483 | E34: =VLOOKUP(D34,Configuracion!$A$4:$C$591,2,FALSE) -> DIEGO MARTIN RIOS | F34: 1702175.8 | G34: =F34*21% -> 357456.92 | K34: 59576.15 | O34: =SUM(F34:N34) -> 2119208.9 | P34: =VLOOKUP(D34,Configuracion!$A$4:$C$591,3,FALSE) -> PROVEEDOR
A35: 03/08/2023 | B35: 7 | C35: 27750 | D35: 20271532483 | E35: =VLOOKUP(D35,Configuracion!$A$4:$C$591,2,FALSE) -> DIEGO MARTIN RIOS | F35: 79172.1 | G35: =F35*21% -> 16626.141 | K35: 2771.02 | O35: =SUM(F35:N35) -> 98569.261 | P35: =VLOOKUP(D35,Configuracion!$A$4:$C$591,3,FALSE) -> PROVEEDOR
A36: 03/08/2023 | B36: 6 | C36: 469 | D36: 20289111329 | E36: =VLOOKUP(D36,Configuracion!$A$4:$C$591,2,FALSE) -> R. N. LEDESMA | F36: 9936277.7 | G36: =F36*21% -> 2086618.3 | O36: =SUM(F36:N36) -> 12022896 | P36: =VLOOKUP(D36,Configuracion!$A$4:$C$591,3,FALSE) -> PROVEEDOR
A37: 03/08/2023 | B37: 6 | C37: 49420 | D37: 30710177658 | E37: =VLOOKUP(D37,Configuracion!$A$4:$C$591,2,FALSE) -> TARGET MEDICAL SA | F37: 196280 | G37: =F37*21% -> 41218.8 | O37: =SUM(F37:N37) -> 237498.8 | P37: =VLOOKUP(D37,Configuracion!$A$4:$C$591,3,FALSE) -> PROVEEDOR
A38: 45141 | B38: 7 | C38: 2070 | D38: 20284183534 | E38: =VLOOKUP(D38,Configuracion!$A$4:$C$591,2,FALSE) -> FURLANETTO MARTIN | F38: 330.58 | G38: =F38*21% -> 69.4218 | O38: =SUM(F38:N38) -> 400.0018 | P38: =VLOOKUP(D38,Configuracion!$A$4:$C$591,3,FALSE) -> VARIOS
A39: 04/08/2023 | B39: 7 | C39: 27775 | D39: 20271532483 | E39: =VLOOKUP(D39,Configuracion!$A$4:$C$591,2,FALSE) -> DIEGO MARTIN RIOS | F39: 51189.36 | G39: =F39*21% -> 10749.766 | K39: 1791.63 | O39: =SUM(F39:N39) -> 63730.756 | P39: =VLOOKUP(D39,Configuracion!$A$4:$C$591,3,FALSE) -> PROVEEDOR
A40: 04/08/2023 | B40: 5054 | C40: 22102 | D40: 30695542476 | E40: =VLOOKUP(D40,Configuracion!$A$4:$C$591,2,FALSE) -> PAN AMERICAN ENERGY SL | F40: 5098.24 | G40: =F40*21% -> 1070.6304 | J40: 152.95 | N40: 331.12 | O40: =SUM(F40:N40) -> 6652.9404 | P40: =VLOOKUP(D40,Configuracion!$A$4:$C$591,3,FALSE) -> INSUMOS
A41: 04/08/2023 | B41: 1 | C41: 650 | D41: 30715048066 | E41: =VLOOKUP(D41,Configuracion!$A$4:$C$591,2,FALSE) -> ROLLS Y EMPANADAS SA | F41: 274910 | G41: =F41*21% -> 57731.1 | O41: =SUM(F41:N41) -> 332641.1 | P41: =VLOOKUP(D41,Configuracion!$A$4:$C$591,3,FALSE) -> VARIOS
A42: 06/08/2023 | B42: 2080 | C42: 86349 | D42: 30548083156 | E42: =VLOOKUP(D42,Configuracion!$A$4:$C$591,2,FALSE) -> COTO CICSA | F42: =52014.39+12239.59 -> 64253.98 | G42: 10923.02 | I42: 1285.16 | J42: =1529.7+183.59 -> 1713.29 | K42: 1920.97 | O42: =SUM(F42:N42) -> 80096.42 | P42: =VLOOKUP(D42,Configuracion!$A$4:$C$591,3,FALSE) -> GASTOS VARIOS
A43: 07/08/2023 | B43: 3 | C43: 90 | D43: 20334976433 | E43: =VLOOKUP(D43,Configuracion!$A$4:$C$591,2,FALSE) -> NARDOMARINO EZEQUIEL EDUARDO | F43: 98482.64 | G43: =F43*21% -> 20681.354 | O43: =SUM(F43:N43) -> 119163.99 | P43: =VLOOKUP(D43,Configuracion!$A$4:$C$591,3,FALSE) -> FLETE
...

Sheet Calculo IVA
B1: ORTOPEDIA GEMINIS
A2: Calculo Iva | D2: 45139
B4: VENTAS
B5: Neto | C5: Iva | D5: Total
A6: FAC. "A" | B6: =+AGOSTO!F210 -> 3414710.7 | C6: =(B6*0.21) -> 717089.26 | D6: =(B6+C6) -> 4131800
A7: FAC. "B" | B7: =+AGOSTO!F220 -> 0 | C7: =(B7*0.21) -> 0 | D7: =(B7+C7) -> 0
A8: FAC. "A" - Odoo | B8: =+AGOSTO!B229+AGOSTO!B231+AGOSTO!B232+AGOSTO!B230 -> 44881359 | C8: =+B8*0.21 -> 9425085.4 | D8: =(B8+C8) -> 54306445
A9: FAC. "B" - Odoo | B9: =+AGOSTO!B233+AGOSTO!B234 -> 3383620.5 | C9: =+B9*0.21 -> 710560.3 | D9: =(B9+C9) -> 4094180.8
B10: =SUM(B6:B9) -> 51679690 | C10: =SUM(C6:C9) -> 10852735 | D10: =SUM(D6:D9) -> 62532425
B13: COMPRAS
B14: Neto | C14: Iva | D14: Total
B15: =+AGOSTO!F116 -> 24295961 | C15: =+AGOSTO!G116+AGOSTO!H116+AGOSTO!I116 -> 4936749.7 | D15: =(B15+C15) -> 29232711
B17: =SUM(B15:B16) -> 24295961 | C17: =SUM(C15:C16) -> 4936749.7 | D17: =SUM(D15:D16) -> 29232711
A20: RETENCIONES | B20: N° Cuit | C20: Importe | D20: Nro. Retencion | E20: Fecha
A21: AFIP - No están informadas las retenciones de IVA en el sistema de AFIP
C36: =+AGOSTO!G197 -> 957038.24
A38: PERCEPCIONES | B38: N° Cuit | C38: Importe | D38: Nro. Retencion | E38: Fecha
C42: =SUM(C39:C41) -> 0
A44: Total Deducciociones | C44: =+C42+C36 -> 957038.24
C47: (Montos en Positivo)
A48: 1er Saldo Tecnico del Período | C48: =+C10-C17 -> 5915985.3
A50: Saldo Tecnico de período Anterior (a favor) | D50: (resta en el total)
A52: Saldo Neto Técnico | C52: =+C48-C50 -> 5915985.3
A56: Saldo L.D. del Período | C56: =+C42+C36 -> 957038.24
A58: Saldo L.D. del Período Anterior
A60: Neto S.L.D | C60: =+C56+C58 -> 957038.24
A63: I V A | C63: =+C52-C60 -> 4958947
A64: NOTA: Sin Tomar posibles Retenciones que se hayan hecho

Sheet Iva Ventas 08 2023
A2: Ventas Libro de IVA 01/08/2023 - 31/08/2023
A3: Ortopedia Geminis S.A.
A5: Fecha | B5: Comprobante | C5: Nombre | D5: Cond. IVA | E5: CUIT o Doc. | F5: Gravado | G5: No Gravado | H5: IVA 2,5% | I5: IVA 5% | J5: IVA 10.5% | K5: IVA 21% | L5: IVA 27% | M5: Otros Imp | N5: Total Compr.
A6: 01/08/2023 | B6: FA-B 0005-00008505 | C6: .CONSUMIDOR FINAL | D6: Consumidor Final | F6: 3388.43 | G6: 0 | H6: 0 | I6: 0 | J6: 0 | K6: 711.57 | L6: 0 | M6: 0 | N6: 4100
A7: 01/08/2023 | B7: FA-B 0005-00008506 | C7: .CONSUMIDOR FINAL | D7: Consumidor Final | F7: 6694.21 | G7: 0 | H7: 0 | I7: 0 | J7: 0 | K7: 1405.79 | L7: 0 | M7: 0 | N7: 8100
A8: 01/08/2023 | B8: FA-B 0005-00008507 | C8: .CONSUMIDOR FINAL | D8: Consumidor Final | F8: 8760.33 | G8: 0 | H8: 0 | I8: 0 | J8: 0 | K8: 1839.67 | L8: 0 | M8: 0 | N8: 10600
A9: 01/08/2023 | B9: FA-B 0005-00008508 | C9: .CONSUMIDOR FINAL | D9: Consumidor Final | F9: 2520.66 | G9: 0 | H9: 0 | I9: 0 | J9: 0 | K9: 529.34 | L9: 0 | M9: 0 | N9: 3050
A10: 01/08/2023 | B10: FA-B 0005-00008509 | C10: .CONSUMIDOR FINAL | D10: Consumidor Final | F10: 6776.86 | G10: 0 | H10: 0 | I10: 0 | J10: 0 | K10: 1423.14 | L10: 0 | M10: 0 | N10: 8200
A11: 01/08/2023 | B11: FA-B 0005-00008510 | C11: GALIOSTRO MARCELO FABIO | D11: Consumidor Final | E11: 18142775 | F11: 4752.07 | G11: 0 | H11: 0 | I11: 0 | J11: 0 | K11: 997.93 | L11: 0 | M11: 0 | N11: 5750
A12: 01/08/2023 | B12: FA-B 0005-00008511 | C12: .CONSUMIDOR FINAL | D12: Consumidor Final | F12: 7851.24 | G12: 0 | H12: 0 | I12: 0 | J12: 0 | K12: 1648.76 | L12: 0 | M12: 0 | N12: 9500
A13: 01/08/2023 | B13: FA-B 0005-00008512 | C13: .CONSUMIDOR FINAL | D13: Consumidor Final | F13: 1157.02 | G13: 0 | H13: 0 | I13: 0 | J13: 0 | K13: 242.98 | L13: 0 | M13: 0 | N13: 1400
A14: 01/08/2023 | B14: FA-B 0005-00008513 | C14: .CONSUMIDOR FINAL | D14: Consumidor Final | F14: 6776.86 | G14: 0 | H14: 0 | I14: 0 | J14: 0 | K14: 1423.14 | L14: 0 | M14: 0 | N14: 8200
A15: 01/08/2023 | B15: FA-B 0005-00008514 | C15: .CONSUMIDOR FINAL | D15: Consumidor Final | F15: 10743.8 | G15: 0 | H15: 0 | I15: 0 | J15: 0 | K15: 2256.2 | L15: 0 | M15: 0 | N15: 13000
A16: 01/08/2023 | B16: FA-B 0007-00004531 | C16: GIMENEZ, SONIA GLADYS | D16: Consumidor Final | E16: 16124424 | F16: 11157.02 | G16: 0 | H16: 0 | I16: 0 | J16: 0 | K16: 2342.98 | L16: 0 | M16: 0 | N16: 13500
A17: 01/08/2023 | B17: FA-B 0007-00004532 | C17: HIGA MARCELA SANDRA | D17: Consumidor Final | E17: 17968654 | F17: 46115.7 | G17: 0 | H17: 0 | I17: 0 | J17: 0 | K17: 9684.3 | L17: 0 | M17: 0 | N17: 55800
A18: 02/08/2023 | B18: FA-B 0005-00008515 | C18: .CONSUMIDOR FINAL | D18: Consumidor Final | F18: 6776.86 | G18: 0 | H18: 0 | I18: 0 | J18: 0 | K18: 1423.14 | L18: 0 | M18: 0 | N18: 8200
A19: 02/08/2023 | B19: FA-B 0005-00008516 | C19: .CONSUMIDOR FINAL | D19: Consumidor Final | F19: 6280.99 | G19: 0 | H19: 0 | I19: 0 | J19: 0 | K19: 1319.01 | L19: 0 | M19: 0 | N19: 7600
A20: 02/08/2023 | B20: FA-B 0005-00008517 | C20: .CONSUMIDOR FINAL | D20: Consumidor Final | F20: 3388.43 | G20: 0 | H20: 0 | I20: 0 | J20: 0 | K20: 711.57 | L20: 0 | M20: 0 | N20: 4100
A21: 02/08/2023 | B21: FA-B 0005-00008518 | C21: .CONSUMIDOR FINAL | D21: Consumidor Final | F21: 3388.43 | G21: 0 | H21: 0 | I21: 0 | J21: 0 | K21: 711.57 | L21: 0 | M21: 0 | N21: 4100
A22: 02/08/2023 | B22: FA-B 0005-00008519 | C22: .CONSUMIDOR FINAL | D22: Consumidor Final | F22: 10743.8 | G22: 0 | H22: 0 | I22: 0 | J22: 0 | K22: 2256.2 | L22: 0 | M22: 0 | N22: 13000
A23: 02/08/2023 | B23: FA-B 0005-00008520 | C23: .CONSUMIDOR FINAL | D23: Consumidor Final | F23: 6776.86 | G23: 0 | H23: 0 | I23: 0 | J23: 0 | K23: 1423.14 | L23: 0 | M23: 0 | N23: 8200
A24: 02/08/2023 | B24: FA-B 0005-00008521 | C24: .CONSUMIDOR FINAL | D24: Consumidor Final | F24: 4132.23 | G24: 0 | H24: 0 | I24: 0 | J24: 0 | K24: 867.77 | L24: 0 | M24: 0 | N24: 5000
A25: 02/08/2023 | B25: FA-B 0005-00008522 | C25: .CONSUMIDOR FINAL | D25: Consumidor Final | F25: 9090.91 | G25: 0 | H25: 0 | I25: 0 | J25: 0 | K25: 1909.09 | L25: 0 | M25: 0 | N25: 11000
A26: 02/08/2023 | B26: FA-B 0005-00008523 | C26: .CONSUMIDOR FINAL | D26: Consumidor Final | F26: 6033.06 | G26: 0 | H26: 0 | I26: 0 | J26: 0 | K26: 1266.94 | L26: 0 | M26: 0 | N26: 7300
A27: 02/08/2023 | B27: FA-A 0006-00000372 | C27: Galeno Argentina Sociedad Anonima | D27: IVA Responsable Inscripto | E27: 30522428163 | F27: 2706554.2 | G27: 0 | H27: 0 | I27: 0 | J27: 0 | K27: 568376.39 | L27: 0 | M27: 0 | N27: 3274930.6
A28: 02/08/2023 | B28: FA-A 0007-00001546 | C28: Obra Social Del Personal De Las Telecomunicaciones De La Republica Argentina | D28: IVA Responsable Inscripto | E28: 30608716390 | F28: 1072.73 | G28: 0 | H28: 0 | I28: 0 | J28: 0 | K28: 225.27 | L28: 0 | M28: 0 | N28: 1298
A29: 02/08/2023 | B29: FA-A 0007-00001547 | C29: Galeno Argentina Sociedad Anonima | D29: IVA Responsable Inscripto | E29: 30522428163 | F29: 255019.16 | G29: 0 | H29: 0 | I29: 0 | J29: 0 | K29: 53554.02 | L29: 0 | M29: 0 | N29: 308573.18
A30: 02/08/2023 | B30: FA-A 0007-00001548 | C30: Galeno Argentina Sociedad Anonima | D30: IVA Responsable Inscripto | E30: 30522428163 | F30: 16280.99 | G30: 0 | H30: 0 | I30: 0 | J30: 0 | K30: 3419.01 | L30: 0 | M30: 0 | N30: 19700
A31: 02/08/2023 | B31: FA-A 0007-00001549 | C31: Galeno Argentina Sociedad Anonima | D31: IVA Responsable Inscripto | E31: 30522428163 | F31: 10749.24 | G31: 0 | H31: 0 | I31: 0 | J31: 0 | K31: 2257.34 | L31: 0 | M31: 0 | N31: 13006.58
A32: 02/08/2023 | B32: FA-A 0007-00001550 | C32: Galeno Argentina Sociedad Anonima | D32: IVA Responsable Inscripto | E32: 30522428163 | F32: 380473.58 | G32: 0 | H32: 0 | I32: 0 | J32: 0 | K32: 79899.45 | L32: 0 | M32: 0 | N32: 460373.03
A33: 02/08/2023 | B33: FA-A 0007-00001551 | C33: Galeno Argentina Sociedad Anonima | D33: IVA Responsable Inscripto | E33: 30522428163 | F33: 245643.54 | G33: 0 | H33: 0 | I33: 0 | J33: 0 | K33: 51585.14 | L33: 0 | M33: 0 | N33: 297228.68
A34: 02/08/2023 | B34: FA-B 0007-00004533 | C34: ALBARO BRESCIANO | D34: Consumidor Final | F34: 15619.83 | G34: 0 | H34: 0 | I34: 0 | J34: 0 | K34: 3280.17 | L34: 0 | M34: 0 | N34: 18900
A35: 02/08/2023 | B35: FA-B 0007-00004534 | C35: ALEJANDRA SIFFREDI TORRES SANMARCO | D35: Consumidor Final | E35: 5804480 | F35: 5785.12 | G35: 0 | H35: 0 | I35: 0 | J35: 0 | K35: 1214.88 | L35: 0 | M35: 0 | N35: 7000
A36: 02/08/2023 | B36: FA-B 0007-00004535 | C36: GABRIELA VANINA GALLO | D36: Consumidor Final | E36: 26542077 | F36: 12644.62 | G36: 0 | H36: 0 | I36: 0 | J36: 0 | K36: 2655.38 | L36: 0 | M36: 0 | N36: 15300
A37: 02/08/2023 | B37: FA-B 0007-00004536 | C37: MARIA ELENA RODRIGUEZ | D37: Consumidor Final | E37: 382591 | F37: 6611.57 | G37: 0 | H37: 0 | I37: 0 | J37: 0 | K37: 1388.43 | L37: 0 | M37: 0 | N37: 8000
A38: 02/08/2023 | B38: FA-B 0007-00004537 | C38: ENRIQUETA MARIA DEL SOCORRO MAJO | D38: Consumidor Final | E38: 3192296 | F38: 4958.68 | G38: 0 | H38: 0 | I38: 0 | J38: 0 | K38: 1041.32 | L38: 0 | M38: 0 | N38: 6000
A39: 03/08/2023 | B39: FA-B 0005-00008524 | C39: .CONSUMIDOR FINAL | D39: Consumidor Final | F39: 3925.62 | G39: 0 | H39: 0 | I39: 0 | J39: 0 | K39: 824.38 | L39: 0 | M39: 0 | N39: 4750
A40: 03/08/2023 | B40: FA-B 0005-00008525 | C40: .CONSUMIDOR FINAL | D40: Consumidor Final | F40: 10743.8 | G40: 0 | H40: 0 | I40: 0 | J40: 0 | K40: 2256.2 | L40: 0 | M40: 0 | N40: 13000
A41: 03/08/2023 | B41: FA-B 0005-00008526 | C41: .CONSUMIDOR FINAL | D41: Consumidor Final | F41: 10826.45 | G41: 0 | H41: 0 | I41: 0 | J41: 0 | K41: 2273.55 | L41: 0 | M41: 0 | N41: 13100
A42: 03/08/2023 | B42: FA-B 0005-00008527 | C42: .CONSUMIDOR FINAL | D42: Consumidor Final | F42: 6446.28 | G42: 0 | H42: 0 | I42: 0 | J42: 0 | K42: 1353.72 | L42: 0 | M42: 0 | N42: 7800
...
