Workbook

Sheet Lista_CUIT
A1: CUIT | B1: RAZON SOCIAL | C1: Tipo de Gasto | D1: PROVINCIA
A2: 30605344352 | B2: CONSORCIO BTOME MITRE 2466 | C2: ALQUILER | G2: Mercaderia
A3: 30717029336 | B3: ECOMOVE SRL | C3: BIENES DE USO | G3: Servicios Gas, Luz, etc.
A4: 30650600238 | B4: PECTAGAR S R L | C4: BIENES DE USO | G4: Gastos catering
A5: 30709317101 | B5: CDTEK SRL | C5: BIENES DE USO | G5: Combustibe
A6: 30716701820 | B6: MENTA GRANIZADA | C6: BIENES DE USO | G6: Gastos Varios
A7: 33708543409 | B7: DAMARFU SA | C7: BIENES DE USO | G7: Gastos seguridad
A8: 30715053744 | B8: FEMEN SA | C8: CARRO PORTA HERRAMIENTAS | G8: Librería
A9: 30715048066 | B9: ROLLS Y EMPANADAS SA | C9: CATERING | G9: Gastos mantenimiento
A10: 20214752868 | B10: RUIZ FERNANDO JAVIER | C10: COCHERA | G10: Gastos comercializacion
A11: 30678774495 | B11: OPER. DE EST. DE SERV. SA | C11: COMBUSTIBLE | G11: Alquiler
A12: 30695542476 | B12: PAN AMERICAN ENERGY LLC | C12: COMBUSTIBLE | G12: Honorarios contables
A13: 30574300858 | B13: SHELL SA | C13: COMBUSTIBLE | G13: Gastos administrativos
... A22: 30615530065 | B22: KINKA SA | C22: COMBUSTIBLE | G22: Alojamiento-Varios
A23: 20217165114 | B23: MARTINO CARLOS ALBERTO | C23: COMBUSTIBLE
A24: 30685116657 | B24: MIRVAR SA | C24: COMBUSTIBLE
A25: 33608724279 | B25: NAFPUR SA | C25: COMBUSTIBLE
A26: 30707983732 | B26: NAFPUR XXI SA | C26: COMBUSTIBLE
A27: 30678774495 | B27: OPER. DE EST. DE SERV. SA | C27: COMBUSTIBLE
A28: 30678774495 | B28: OPER. DE EST. SERV. S.A. | C28: COMBUSTIBLE
A29: 30678774495 | B29: OPER. DE EST. SERV. S.A. | C29: COMBUSTIBLE
A30: 30695542476 | B30: PAN AMERICAN ENERGY LLC. SUC. | C30: COMBUSTIBLE
A31: 30692317951 | B31: POSTA PILAR SA | C31: COMBUSTIBLE
A32: 30677909001 | B32: RERIFE SA | C32: COMBUSTIBLE
A33: 30538456876 | B33: RIO DE JANEIRO SA | C33: COMBUSTIBLE
A34: 30574300858 | B34: SHELL SA | C34: COMBUSTIBLE
... A106: 30662533072 | B106: ULTRALIGHT SRL | C106: Gastos Oficina
A107: 20247521764 | B107: SOBRINO LEANDRO HUGO | C107: Gastos Varios | D107: SOBRINO LEANDRO HUGO
A108: 30-67877449-5 | B108: OPERADORA DE ESTACIONES DE SERVICIOS SA | C108: Gastos Varios
A109: 30690536079 | B109: ACCESOR SRL | C109: Gastos Varios
A110: 27184156658 | B110: NUDELMAN GRACIELA MONICA | C110: Gastos Varios
A111: 20083925680 | B111: ALFREDO DANIEL FERNANDEZ | C111: Gastos Varios
A112: 23945042079 | B112: ALVARENGA VILLAR LUIS F | C112: Gastos Varios
A113: 20927832136 | B113: ARANCIBIA IBACETA CIPRIANO | C113: Gastos Varios
A114: 20045180620 | B114: ARUGUETE ENRIQUE JORGE | C114: Gastos Varios
A115: 30712458468 | B115: BEEL SUL S.A. | C115: Gastos Varios
A116: 30712387315 | B116: BIALA SRL | C116: Gastos Varios
A117: 30590360763 | B117: CENCOSUD S.A. | C117: Gastos Varios
A118: 30702286987 | B118: CINTAS OUTLET SA | C118: Gastos Varios
A119: 30548345525 | B119: Copy Max | C119: Gastos Varios
...

Sheet Abr-22
B1: LIBRO IVA COMPRAS | G1: CORITEC S.R.L. | N1: 44652
B3: TOTAL COMPRAS | G3: TOTAL CREDITO FISCAL | J3: TOTAL VENTAS NETAS | M3: TOTAL DEBITO FISCAL | P3: RESULTADO
B4: =SUM('Abr-22'!$H$51)+'Abr-22'!$G$64 -> 2080834.5 | G4: ='Abr-22'!$I$51+'Abr-22'!$J$51+'Abr-22'!$K$51+'Abr-22'!$H$64+'Abr-22'!$I$64 -> 388881.49 | J4: ='Abr-22'!$H$93+'Abr-22'!$H$100 -> 12289541 | M4: ='Abr-22'!$I$93+'Abr-22'!$J$93+'Abr-22'!$I$100+'Abr-22'!$J$100 -> 1572095.3 | P4: =G4-M4 -> -1183213.8
O7: no esta configurado para q esten en negativo
B8: FECHA | C8: TIPO | D8: PTO VTA | E8: NRO. CPTE | F8: CUIT | G8: RAZON SOCIAL | H8: NETO GRAVADO | I8: IVA 21 % | J8: IVA 27% | K8: IVA 10,5% | L8: PERC. IVA | M8: PERC IIBB BS AS | N8: PERC. IIBB CABA | O8: Otros / No Grav. | P8: TOTAL | Q8: Tipo de Gasto | R8: Provincia
B9: 44652 | C9: 1 | D9: 3 | E9: 153109 | F9: 30707135596 | G9: =IFERROR(IF('Abr-22'!$F9="","-",VLOOKUP('Abr-22'!$F9,Lista_CUIT!$A$1:$D$1871,2,0)),"CUIT NO CARGADO") -> CITILAN ARGENTINA SA | H9: 2725.92 | I9: =IF('Abr-22'!$H9="","",'Abr-22'!$H9*0.21) -> 572.4432 | P9: =SUM('Abr-22'!$H9:$O9) -> 3298.3632 | Q9: =IFERROR(IF('Abr-22'!$F9="","-",VLOOKUP('Abr-22'!$F9,Lista_CUIT!$A$1:$D$1871,3,0)),"CUIT NO CARGADO") -> SERVICIOS GAS, LUZ, ETC | R9: =IFERROR(IF('Abr-22'!$F9="","-",VLOOKUP('Abr-22'!$F9,Lista_CUIT!$A$1:$D$1871,4,0)),"CUIT NO CARGADO") -> 0
B10: 44652 | C10: 1 | D10: 3 | E10: 518 | F10: 30715402765 | G10: =IFERROR(IF('Abr-22'!$F10="","-",VLOOKUP('Abr-22'!$F10,Lista_CUIT!$A$1:$D$1871,2,0)),"CUIT NO CARGADO") -> RIO 265 SRL | H10: 7190.08 | I10: =IF('Abr-22'!$H10="","",'Abr-22'!$H10*0.21) -> 1509.9168 | P10: =SUM('Abr-22'!$H10:$O10) -> 8699.9968 | Q10: =IFERROR(IF('Abr-22'!$F10="","-",VLOOKUP('Abr-22'!$F10,Lista_CUIT!$A$1:$D$1871,3,0)),"CUIT NO CARGADO") -> GTOS VARIOS-ESTACIONAMIENTO HORACIO | R10: =IFERROR(IF('Abr-22'!$F10="","-",VLOOKUP('Abr-22'!$F10,Lista_CUIT!$A$1:$D$1871,4,0)),"CUIT NO CARGADO") -> 0
B11: 44652 | C11: 1 | D11: 3 | E11: 254 | F11: 20921575743 | G11: =IFERROR(IF('Abr-22'!$F11="","-",VLOOKUP('Abr-22'!$F11,Lista_CUIT!$A$1:$D$1871,2,0)),"CUIT NO CARGADO") -> RIOS GOMEZ JOSE ANTONIO | H11: 54000 | I11: =IF('Abr-22'!$H11="","",'Abr-22'!$H11*0.21) -> 11340 | P11: =SUM('Abr-22'!$H11:$O11) -> 65340 | Q11: =IFERROR(IF('Abr-22'!$F11="","-",VLOOKUP('Abr-22'!$F11,Lista_CUIT!$A$1:$D$1871,3,0)),"CUIT NO CARGADO") -> Papeleria e Impresos | R11: =IFERROR(IF('Abr-22'!$F11="","-",VLOOKUP('Abr-22'!$F11,Lista_CUIT!$A$1:$D$1871,4,0)),"CUIT NO CARGADO") -> 0
B12: 44652 | C12: 1 | D12: 2 | E12: 2022 | F12: 30709131733 | G12: =IFERROR(IF('Abr-22'!$F12="","-",VLOOKUP('Abr-22'!$F12,Lista_CUIT!$A$1:$D$1871,2,0)),"CUIT NO CARGADO") -> DIGAS SRL | H12: 193720 | I12: =IF('Abr-22'!$H12="","",'Abr-22'!$H12*0.21) -> 40681.2 | P12: =SUM('Abr-22'!$H12:$O12) -> 234401.2 | Q12: =IFERROR(IF('Abr-22'!$F12="","-",VLOOKUP('Abr-22'!$F12,Lista_CUIT!$A$1:$D$1871,3,0)),"CUIT NO CARGADO") -> INSUMO | R12: =IFERROR(IF('Abr-22'!$F12="","-",VLOOKUP('Abr-22'!$F12,Lista_CUIT!$A$1:$D$1871,4,0)),"CUIT NO CARGADO") -> 0
B13: 44652 | C13: 1 | D13: 7 | E13: 52774 | F13: 30626629942 | G13: =IFERROR(IF('Abr-22'!$F13="","-",VLOOKUP('Abr-22'!$F13,Lista_CUIT!$A$1:$D$1871,2,0)),"CUIT NO CARGADO") -> INSTRUMENTAL PASTEUR S R L | H13: 5619 | K13: 589.995 | P13: =SUM('Abr-22'!$H13:$O13) -> 6208.995 | Q13: =IFERROR(IF('Abr-22'!$F13="","-",VLOOKUP('Abr-22'!$F13,Lista_CUIT!$A$1:$D$1871,3,0)),"CUIT NO CARGADO") -> Gastos Varios | R13: =IFERROR(IF('Abr-22'!$F13="","-",VLOOKUP('Abr-22'!$F13,Lista_CUIT!$A$1:$D$1871,4,0)),"CUIT NO CARGADO") -> 0
B14: 44656 | C14: 1 | D14: 26 | E14: 2356 | F14: 30677470123 | G14: =IFERROR(IF('Abr-22'!$F14="","-",VLOOKUP('Abr-22'!$F14,Lista_CUIT!$A$1:$D$1871,2,0)),"CUIT NO CARGADO") -> NEUMATICOS VERONA SA | H14: 86942.16 | I14: =IF('Abr-22'!$H14="","",'Abr-22'!$H14*0.21) -> 18257.854 | P14: =SUM('Abr-22'!$H14:$O14) -> 105200.01 | Q14: =IFERROR(IF('Abr-22'!$F14="","-",VLOOKUP('Abr-22'!$F14,Lista_CUIT!$A$1:$D$1871,3,0)),"CUIT NO CARGADO") -> Mantenimiento Rodados | R14: =IFERROR(IF('Abr-22'!$F14="","-",VLOOKUP('Abr-22'!$F14,Lista_CUIT!$A$1:$D$1871,4,0)),"CUIT NO CARGADO") -> 0
B15: 44657 | C15: 1 | D15: 60 | E15: 6863 | F15: 30547188760 | G15: =IFERROR(IF('Abr-22'!$F15="","-",VLOOKUP('Abr-22'!$F15,Lista_CUIT!$A$1:$D$1871,2,0)),"CUIT NO CARGADO") -> LONCO HUE SA | H15: 1369.86 | I15: =IF('Abr-22'!$H15="","",'Abr-22'!$H15*0.21) -> 287.6706 | P15: =SUM('Abr-22'!$H15:$O15) -> 1657.5306 | Q15: =IFERROR(IF('Abr-22'!$F15="","-",VLOOKUP('Abr-22'!$F15,Lista_CUIT!$A$1:$D$1871,3,0)),"CUIT NO CARGADO") -> INSUMO | R15: =IFERROR(IF('Abr-22'!$F15="","-",VLOOKUP('Abr-22'!$F15,Lista_CUIT!$A$1:$D$1871,4,0)),"CUIT NO CARGADO") -> 0
B16: 44657 | C16: 1 | D16: 280 | E16: 1358550 | F16: 30580111315 | G16: =IFERROR(IF('Abr-22'!$F16="","-",VLOOKUP('Abr-22'!$F16,Lista_CUIT!$A$1:$D$1871,2,0)),"CUIT NO CARGADO") -> DHL EXPRESS ARG SA | H16: 348336.45 | I16: 703.71 | K16: 36223.193 | O16: -313623.44 | P16: =SUM('Abr-22'!$H16:$O16) -> 71639.912 | Q16: =IFERROR(IF('Abr-22'!$F16="","-",VLOOKUP('Abr-22'!$F16,Lista_CUIT!$A$1:$D$1871,3,0)),"CUIT NO CARGADO") -> GTOS IMP. | R16: =IFERROR(IF('Abr-22'!$F16="","-",VLOOKUP('Abr-22'!$F16,Lista_CUIT!$A$1:$D$1871,4,0)),"CUIT NO CARGADO") -> 0
B17: 44657 | C17: 1 | D17: 60 | E17: 6857 | F17: 30547188760 | G17: =IFERROR(IF('Abr-22'!$F17="","-",VLOOKUP('Abr-22'!$F17,Lista_CUIT!$A$1:$D$1871,2,0)),"CUIT NO CARGADO") -> LONCO HUE SA | H17: 13634.24 | I17: =IF('Abr-22'!$H17="","",'Abr-22'!$H17*0.21) -> 2863.1904 | P17: =SUM('Abr-22'!$H17:$O17) -> 16497.43 | Q17: =IFERROR(IF('Abr-22'!$F17="","-",VLOOKUP('Abr-22'!$F17,Lista_CUIT!$A$1:$D$1871,3,0)),"CUIT NO CARGADO") -> INSUMO | R17: =IFERROR(IF('Abr-22'!$F17="","-",VLOOKUP('Abr-22'!$F17,Lista_CUIT!$A$1:$D$1871,4,0)),"CUIT NO CARGADO") -> 0
B18: 44657 | C18: 1 | D18: 60 | E18: 6862 | F18: 30547188760 | G18: =IFERROR(IF('Abr-22'!$F18="","-",VLOOKUP('Abr-22'!$F18,Lista_CUIT!$A$1:$D$1871,2,0)),"CUIT NO CARGADO") -> LONCO HUE SA | H18: 334224.48 | I18: =IF('Abr-22'!$H18="","",'Abr-22'!$H18*0.21) -> 70187.141 | P18: =SUM('Abr-22'!$H18:$O18) -> 404411.62 | Q18: =IFERROR(IF('Abr-22'!$F18="","-",VLOOKUP('Abr-22'!$F18,Lista_CUIT!$A$1:$D$1871,3,0)),"CUIT NO CARGADO") -> INSUMO | R18: =IFERROR(IF('Abr-22'!$F18="","-",VLOOKUP('Abr-22'!$F18,Lista_CUIT!$A$1:$D$1871,4,0)),"CUIT NO CARGADO") -> 0
B19: 44662 | C19: 1 | D19: 700 | E19: 360195 | F19: 30580111315 | G19: =IFERROR(IF('Abr-22'!$F19="","-",VLOOKUP('Abr-22'!$F19,Lista_CUIT!$A$1:$D$1871,2,0)),"CUIT NO CARGADO") -> DHL EXPRESS ARG SA | I19: =IF('Abr-22'!$H19="","",'Abr-22'!$H19*0.21) | O19: 8033.97 | P19: =SUM('Abr-22'!$H19:$O19) -> 8033.97 | Q19: =IFERROR(IF('Abr-22'!$F19="","-",VLOOKUP('Abr-22'!$F19,Lista_CUIT!$A$1:$D$1871,3,0)),"CUIT NO CARGADO") -> GTOS IMP. | R19: =IFERROR(IF('Abr-22'!$F19="","-",VLOOKUP('Abr-22'!$F19,Lista_CUIT!$A$1:$D$1871,4,0)),"CUIT NO CARGADO") -> 0
B20: 44662 | C20: 1 | D20: 700 | E20: 361293 | F20: 30580111315 | G20: =IFERROR(IF('Abr-22'!$F20="","-",VLOOKUP('Abr-22'!$F20,Lista_CUIT!$A$1:$D$1871,2,0)),"CUIT NO CARGADO") -> DHL EXPRESS ARG SA | I20: =IF('Abr-22'!$H20="","",'Abr-22'!$H20*0.21) | O20: 44108.28 | P20: =SUM('Abr-22'!$H20:$O20) -> 44108.28 | Q20: =IFERROR(IF('Abr-22'!$F20="","-",VLOOKUP('Abr-22'!$F20,Lista_CUIT!$A$1:$D$1871,3,0)),"CUIT NO CARGADO") -> GTOS IMP. | R20: =IFERROR(IF('Abr-22'!$F20="","-",VLOOKUP('Abr-22'!$F20,Lista_CUIT!$A$1:$D$1871,4,0)),"CUIT NO CARGADO") -> 0
B21: 44662 | C21: 1 | D21: 7 | E21: 6293 | F21: 30604413482 | G21: =IFERROR(IF('Abr-22'!$F21="","-",VLOOKUP('Abr-22'!$F21,Lista_CUIT!$A$1:$D$1871,2,0)),"CUIT NO CARGADO") -> BULONERA VIETRI SRL | H21: 98274 | I21: =IF('Abr-22'!$H21="","",'Abr-22'!$H21*0.21) -> 20637.54 | P21: =SUM('Abr-22'!$H21:$O21) -> 118911.54 | Q21: =IFERROR(IF('Abr-22'!$F21="","-",VLOOKUP('Abr-22'!$F21,Lista_CUIT!$A$1:$D$1871,3,0)),"CUIT NO CARGADO") -> INSUMO | R21: =IFERROR(IF('Abr-22'!$F21="","-",VLOOKUP('Abr-22'!$F21,Lista_CUIT!$A$1:$D$1871,4,0)),"CUIT NO CARGADO") -> 0
B22: 44662 | C22: 1 | D22: 2466 | E22: 345117 | F22: 30678814357 | G22: =IFERROR(IF('Abr-22'!$F22="","-",VLOOKUP('Abr-22'!$F22,Lista_CUIT!$A$1:$D$1871,2,0)),"CUIT NO CARGADO") -> Telefonica Moviles Argentina SA | H22: 1765 | J22: 476.55 | O22: 92.89 | P22: =SUM('Abr-22'!$H22:$O22) -> 2334.44 | Q22: =IFERROR(IF('Abr-22'!$F22="","-",VLOOKUP('Abr-22'!$F22,Lista_CUIT!$A$1:$D$1871,3,0)),"CUIT NO CARGADO") -> SERVICIOS GAS, LUZ, ETC | R22: =IFERROR(IF('Abr-22'!$F22="","-",VLOOKUP('Abr-22'!$F22,Lista_CUIT!$A$1:$D$1871,4,0)),"CUIT NO CARGADO") -> 0
B23: 44666 | C23: 1 | D23: 5199 | E23: 12079 | F23: 30695542476 | G23: =IFERROR(IF('Abr-22'!$F23="","-",VLOOKUP('Abr-22'!$F23,Lista_CUIT!$A$1:$D$1871,2,0)),"CUIT NO CARGADO") -> PAN AMERICAN ENERGY LLC | H23: 3603.39 | I23: =IF('Abr-22'!$H23="","",'Abr-22'!$H23*0.21) -> 756.7119 | L23: 108.1 | O23: 779.8 | P23: =SUM('Abr-22'!$H23:$O23) -> 5248.0019 | Q23: =IFERROR(IF('Abr-22'!$F23="","-",VLOOKUP('Abr-22'!$F23,Lista_CUIT!$A$1:$D$1871,3,0)),"CUIT NO CARGADO") -> COMBUSTIBLE | R23: =IFERROR(IF('Abr-22'!$F23="","-",VLOOKUP('Abr-22'!$F23,Lista_CUIT!$A$1:$D$1871,4,0)),"CUIT NO CARGADO") -> 0
B24: 44669 | C24: 1 | D24: 700 | E24: 364547 | F24: 30580111315 | G24: =IFERROR(IF('Abr-22'!$F24="","-",VLOOKUP('Abr-22'!$F24,Lista_CUIT!$A$1:$D$1871,2,0)),"CUIT NO CARGADO") -> DHL EXPRESS ARG SA | I24: =IF('Abr-22'!$H24="","",'Abr-22'!$H24*0.21) | O24: 12877.34 | P24: =SUM('Abr-22'!$H24:$O24) -> 12877.34 | Q24: =IFERROR(IF('Abr-22'!$F24="","-",VLOOKUP('Abr-22'!$F24,Lista_CUIT!$A$1:$D$1871,3,0)),"CUIT NO CARGADO") -> GTOS IMP. | R24: =IFERROR(IF('Abr-22'!$F24="","-",VLOOKUP('Abr-22'!$F24,Lista_CUIT!$A$1:$D$1871,4,0)),"CUIT NO CARGADO") -> 0
B25: 44669 | C25: 1 | D25: 4 | E25: 1886 | F25: 20068864934 | G25: =IFERROR(IF('Abr-22'!$F25="","-",VLOOKUP('Abr-22'!$F25,Lista_CUIT!$A$1:$D$1871,2,0)),"CUIT NO CARGADO") -> DISTRIBUIDORA SANITARIA JACOBO | H25: 1289.26 | I25: =IF('Abr-22'!$H25="","",'Abr-22'!$H25*0.21) -> 270.7446 | P25: =SUM('Abr-22'!$H25:$O25) -> 1560.0046 | Q25: =IFERROR(IF('Abr-22'!$F25="","-",VLOOKUP('Abr-22'!$F25,Lista_CUIT!$A$1:$D$1871,3,0)),"CUIT NO CARGADO") -> INSUMO | R25: =IFERROR(IF('Abr-22'!$F25="","-",VLOOKUP('Abr-22'!$F25,Lista_CUIT!$A$1:$D$1871,4,0)),"CUIT NO CARGADO") -> 0
B26: 44669 | C26: 1 | D26: 2 | E26: 128 | F26: 20125142851 | G26: =IFERROR(IF('Abr-22'!$F26="","-",VLOOKUP('Abr-22'!$F26,Lista_CUIT!$A$1:$D$1871,2,0)),"CUIT NO CARGADO") -> FEDERICI NICOLAS JOSE | H26: 54222.3 | I26: =IF('Abr-22'!$H26="","",'Abr-22'!$H26*0.21) -> 11386.683 | P26: =SUM('Abr-22'!$H26:$O26) -> 65608.983 | Q26: =IFERROR(IF('Abr-22'!$F26="","-",VLOOKUP('Abr-22'!$F26,Lista_CUIT!$A$1:$D$1871,3,0)),"CUIT NO CARGADO") -> INSUMO | R26: =IFERROR(IF('Abr-22'!$F26="","-",VLOOKUP('Abr-22'!$F26,Lista_CUIT!$A$1:$D$1871,4,0)),"CUIT NO CARGADO") -> 0
B27: 44669 | C27: 1 | D27: 2 | E27: 129 | F27: 20125142851 | G27: =IFERROR(IF('Abr-22'!$F27="","-",VLOOKUP('Abr-22'!$F27,Lista_CUIT!$A$1:$D$1871,2,0)),"CUIT NO CARGADO") -> FEDERICI NICOLAS JOSE | H27: 59539.92 | I27: =IF('Abr-22'!$H27="","",'Abr-22'!$H27*0.21) -> 12503.383 | P27: =SUM('Abr-22'!$H27:$O27) -> 72043.303 | Q27: =IFERROR(IF('Abr-22'!$F27="","-",VLOOKUP('Abr-22'!$F27,Lista_CUIT!$A$1:$D$1871,3,0)),"CUIT NO CARGADO") -> INSUMO | R27: =IFERROR(IF('Abr-22'!$F27="","-",VLOOKUP('Abr-22'!$F27,Lista_CUIT!$A$1:$D$1871,4,0)),"CUIT NO CARGADO") -> 0
B28: 44670 | C28: 1 | D28: 4 | E28: 9754 | F28: 33710719549 | G28: =IFERROR(IF('Abr-22'!$F28="","-",VLOOKUP('Abr-22'!$F28,Lista_CUIT!$A$1:$D$1871,2,0)),"CUIT NO CARGADO") -> FIVELEV S.R.L. | H28: 3722.32 | I28: =IF('Abr-22'!$H28="","",'Abr-22'!$H28*0.21) -> 781.6872 | P28: =SUM('Abr-22'!$H28:$O28) -> 4504.0072 | Q28: =IFERROR(IF('Abr-22'!$F28="","-",VLOOKUP('Abr-22'!$F28,Lista_CUIT!$A$1:$D$1871,3,0)),"CUIT NO CARGADO") -> Gastos Varios | R28: =IFERROR(IF('Abr-22'!$F28="","-",VLOOKUP('Abr-22'!$F28,Lista_CUIT!$A$1:$D$1871,4,0)),"CUIT NO CARGADO") -> 0
B29: 44671 | C29: 1 | D29: 1 | E29: 110 | F29: 30715713272 | G29: =IFERROR(IF('Abr-22'!$F29="","-",VLOOKUP('Abr-22'!$F29,Lista_CUIT!$A$1:$D$1871,2,0)),"CUIT NO CARGADO") -> MALAGA GROUP SRL | H29: 191825.21 | I29: =IF('Abr-22'!$H29="","",'Abr-22'!$H29*0.21) -> 40283.294 | P29: =SUM('Abr-22'!$H29:$O29) -> 232108.5 | Q29: =IFERROR(IF('Abr-22'!$F29="","-",VLOOKUP('Abr-22'!$F29,Lista_CUIT!$A$1:$D$1871,3,0)),"CUIT NO CARGADO") -> Gastos Varios | R29: =IFERROR(IF('Abr-22'!$F29="","-",VLOOKUP('Abr-22'!$F29,Lista_CUIT!$A$1:$D$1871,4,0)),"CUIT NO CARGADO") -> 0
B30: 44672 | C30: 3 | D30: 2 | E30: 138 | F30: 30709131733 | G30: =IFERROR(IF('Abr-22'!$F30="","-",VLOOKUP('Abr-22'!$F30,Lista_CUIT!$A$1:$D$1871,2,0)),"CUIT NO CARGADO") -> DIGAS SRL | H30: -193720 | I30: =IF('Abr-22'!$H30="","",'Abr-22'!$H30*0.21) -> -40681.2 | P30: =SUM('Abr-22'!$H30:$O30) -> -234401.2 | Q30: =IFERROR(IF('Abr-22'!$F30="","-",VLOOKUP('Abr-22'!$F30,Lista_CUIT!$A$1:$D$1871,3,0)),"CUIT NO CARGADO") -> INSUMO | R30: =IFERROR(IF('Abr-22'!$F30="","-",VLOOKUP('Abr-22'!$F30,Lista_CUIT!$A$1:$D$1871,4,0)),"CUIT NO CARGADO") -> 0
B31: 44672 | C31: 1 | D31: 5 | E31: 415 | F31: 30716006391 | G31: =IFERROR(IF('Abr-22'!$F31="","-",VLOOKUP('Abr-22'!$F31,Lista_CUIT!$A$1:$D$1871,2,0)),"CUIT NO CARGADO") -> ALISSING | H31: 3077.69 | I31: =IF('Abr-22'!$H31="","",'Abr-22'!$H31*0.21) -> 646.3149 | P31: =SUM('Abr-22'!$H31:$O31) -> 3724.0049 | Q31: =IFERROR(IF('Abr-22'!$F31="","-",VLOOKUP('Abr-22'!$F31,Lista_CUIT!$A$1:$D$1871,3,0)),"CUIT NO CARGADO") -> Gastos Varios | R31: =IFERROR(IF('Abr-22'!$F31="","-",VLOOKUP('Abr-22'!$F31,Lista_CUIT!$A$1:$D$1871,4,0)),"CUIT NO CARGADO") -> 0
B32: 44672 | C32: 1 | D32: 7002 | E32: 3975 | F32: 30678774495 | G32: =IFERROR(IF('Abr-22'!$F32="","-",VLOOKUP('Abr-22'!$F32,Lista_CUIT!$A$1:$D$1871,2,0)),"CUIT NO CARGADO") -> OPER. DE EST. DE SERV. SA | H32: 3230.2 | I32: =IF('Abr-22'!$H32="","",'Abr-22'!$H32*0.21) -> 678.342 | O32: 982.25 | P32: =SUM('Abr-22'!$H32:$O32) -> 4890.792 | Q32: =IFERROR(IF('Abr-22'!$F32="","-",VLOOKUP('Abr-22'!$F32,Lista_CUIT!$A$1:$D$1871,3,0)),"CUIT NO CARGADO") -> COMBUSTIBLE | R32: =IFERROR(IF('Abr-22'!$F32="","-",VLOOKUP('Abr-22'!$F32,Lista_CUIT!$A$1:$D$1871,4,0)),"CUIT NO CARGADO") -> 0
B33: 44672 | C33: 1 | D33: 3 | E33: 16645 | F33: 30707468161 | G33: =IFERROR(IF('Abr-22'!$F33="","-",VLOOKUP('Abr-22'!$F33,Lista_CUIT!$A$1:$D$1871,2,0)),"CUIT NO CARGADO") -> LASERTEC INGENIERIA S.R.L. | H33: 25585 | I33: =IF('Abr-22'!$H33="","",'Abr-22'!$H33*0.21) -> 5372.85 | P33: =SUM('Abr-22'!$H33:$O33) -> 30957.85 | Q33: =IFERROR(IF('Abr-22'!$F33="","-",VLOOKUP('Abr-22'!$F33,Lista_CUIT!$A$1:$D$1871,3,0)),"CUIT NO CARGADO") -> INSUMO | R33: =IFERROR(IF('Abr-22'!$F33="","-",VLOOKUP('Abr-22'!$F33,Lista_CUIT!$A$1:$D$1871,4,0)),"CUIT NO CARGADO") -> 0
B34: 44672 | C34: 1 | D34: 2 | E34: 2055 | F34: 30709131733 | G34: =IFERROR(IF('Abr-22'!$F34="","-",VLOOKUP('Abr-22'!$F34,Lista_CUIT!$A$1:$D$1871,2,0)),"CUIT NO CARGADO") -> DIGAS SRL | H34: 267952.3 | I34: =IF('Abr-22'!$H34="","",'Abr-22'!$H34*0.21) -> 56269.983 | P34: =SUM('Abr-22'!$H34:$O34) -> 324222.28 | Q34: =IFERROR(IF('Abr-22'!$F34="","-",VLOOKUP('Abr-22'!$F34,Lista_CUIT!$A$1:$D$1871,3,0)),"CUIT NO CARGADO") -> INSUMO | R34: =IFERROR(IF('Abr-22'!$F34="","-",VLOOKUP('Abr-22'!$F34,Lista_CUIT!$A$1:$D$1871,4,0)),"CUIT NO CARGADO") -> 0
B35: 44673 | C35: 1 | D35: 106 | E35: 519106 | F35: 30594494187 | G35: =IFERROR(IF('Abr-22'!$F35="","-",VLOOKUP('Abr-22'!$F35,Lista_CUIT!$A$1:$D$1871,2,0)),"CUIT NO CARGADO") -> FEDERAL EXPRESS CORPORATION | H35: 11875 | I35: =IF('Abr-22'!$H35="","",'Abr-22'!$H35*0.21) -> 2493.75 | O35: 130744.03 | P35: =SUM('Abr-22'!$H35:$O35) -> 145112.78 | Q35: =IFERROR(IF('Abr-22'!$F35="","-",VLOOKUP('Abr-22'!$F35,Lista_CUIT!$A$1:$D$1871,3,0)),"CUIT NO CARGADO") -> GTOS IMP. | R35: =IFERROR(IF('Abr-22'!$F35="","-",VLOOKUP('Abr-22'!$F35,Lista_CUIT!$A$1:$D$1871,4,0)),"CUIT NO CARGADO") -> 0
B36: 44673 | C36: 1 | D36: 9 | E36: 1134 | F36: 30631047145 | G36: =IFERROR(IF('Abr-22'!$F36="","-",VLOOKUP('Abr-22'!$F36,Lista_CUIT!$A$1:$D$1871,2,0)),"CUIT NO CARGADO") -> SEMICONDUC. Y COMPON. SRL | H36: 38694 | I36: 3087 | K36: 2519.37 | P36: =SUM('Abr-22'!$H36:$O36) -> 44300.37 | Q36: =IFERROR(IF('Abr-22'!$F36="","-",VLOOKUP('Abr-22'!$F36,Lista_CUIT!$A$1:$D$1871,3,0)),"CUIT NO CARGADO") -> INSUMO | R36: =IFERROR(IF('Abr-22'!$F36="","-",VLOOKUP('Abr-22'!$F36,Lista_CUIT!$A$1:$D$1871,4,0)),"CUIT NO CARGADO") -> 0
B37: 44673 | C37: 1 | D37: 1 | E37: 305 | F37: 20190828205 | G37: =IFERROR(IF('Abr-22'!$F37="","-",VLOOKUP('Abr-22'!$F37,Lista_CUIT!$A$1:$D$1871,2,0)),"CUIT NO CARGADO") -> CARDENAS TORRES CARLOS DAVID | H37: 12669.68 | K37: 1330.3164 | P37: =SUM('Abr-22'!$H37:$O37) -> 13999.996 | Q37: =IFERROR(IF('Abr-22'!$F37="","-",VLOOKUP('Abr-22'!$F37,Lista_CUIT!$A$1:$D$1871,3,0)),"CUIT NO CARGADO") -> INSUMO | R37: =IFERROR(IF('Abr-22'!$F37="","-",VLOOKUP('Abr-22'!$F37,Lista_CUIT!$A$1:$D$1871,4,0)),"CUIT NO CARGADO") -> 0
B38: 44675 | C38: 1 | D38: 30 | E38: 3550 | F38: 20217293791 | G38: =IFERROR(IF('Abr-22'!$F38="","-",VLOOKUP('Abr-22'!$F38,Lista_CUIT!$A$1:$D$1871,2,0)),"CUIT NO CARGADO") -> VELASCO LEIVA DEMIAN | H38: 7462.81 | I38: =IF('Abr-22'!$H38="","",'Abr-22'!$H38*0.21) -> 1567.1901 | P38: =SUM('Abr-22'!$H38:$O38) -> 9030.0001 | Q38: =IFERROR(IF('Abr-22'!$F38="","-",VLOOKUP('Abr-22'!$F38,Lista_CUIT!$A$1:$D$1871,3,0)),"CUIT NO CARGADO") -> Gastos Varios | R38: =IFERROR(IF('Abr-22'!$F38="","-",VLOOKUP('Abr-22'!$F38,Lista_CUIT!$A$1:$D$1871,4,0)),"CUIT NO CARGADO") -> 0
B39: 44677 | C39: 1 | D39: 40 | E39: 1978547 | F39: 30710964277 | G39: =IFERROR(IF('Abr-22'!$F39="","-",VLOOKUP('Abr-22'!$F39,Lista_CUIT!$A$1:$D$1871,2,0)),"CUIT NO CARGADO") -> LAKAUT SA | H39: 2615.26 | I39: =IF('Abr-22'!$H39="","",'Abr-22'!$H39*0.21) -> 549.2046 | P39: =SUM('Abr-22'!$H39:$O39) -> 3164.4646 | Q39: =IFERROR(IF('Abr-22'!$F39="","-",VLOOKUP('Abr-22'!$F39,Lista_CUIT!$A$1:$D$1871,3,0)),"CUIT NO CARGADO") -> GTOS IMP. | R39: =IFERROR(IF('Abr-22'!$F39="","-",VLOOKUP('Abr-22'!$F39,Lista_CUIT!$A$1:$D$1871,4,0)),"CUIT NO CARGADO") -> 0
B40: 44677 | C40: 1 | D40: 3 | E40: 16677 | F40: 30707468161 | G40: =IFERROR(IF('Abr-22'!$F40="","-",VLOOKUP('Abr-22'!$F40,Lista_CUIT!$A$1:$D$1871,2,0)),"CUIT NO CARGADO") -> LASERTEC INGENIERIA S.R.L. | H40: 33460 | I40: =IF('Abr-22'!$H40="","",'Abr-22'!$H40*0.21) -> 7026.6 | P40: =SUM('Abr-22'!$H40:$O40) -> 40486.6 | Q40: =IFERROR(IF('Abr-22'!$F40="","-",VLOOKUP('Abr-22'!$F40,Lista_CUIT!$A$1:$D$1871,3,0)),"CUIT NO CARGADO") -> INSUMO | R40: =IFERROR(IF('Abr-22'!$F40="","-",VLOOKUP('Abr-22'!$F40,Lista_CUIT!$A$1:$D$1871,4,0)),"CUIT NO CARGADO") -> 0
B41: 44678 | C41: 3 | D41: 60 | E41: 462 | F41: 30547188760 | G41: =IFERROR(IF('Abr-22'!$F41="","-",VLOOKUP('Abr-22'!$F41,Lista_CUIT!$A$1:$D$1871,2,0)),"CUIT NO CARGADO") -> LONCO HUE SA | H41: -13634.24 | I41: =IF('Abr-22'!$H41="","",'Abr-22'!$H41*0.21) -> -2863.1904 | P41: =SUM('Abr-22'!$H41:$O41) -> -16497.43 | Q41: =IFERROR(IF('Abr-22'!$F41="","-",VLOOKUP('Abr-22'!$F41,Lista_CUIT!$A$1:$D$1871,3,0)),"CUIT NO CARGADO") -> INSUMO | R41: =IFERROR(IF('Abr-22'!$F41="","-",VLOOKUP('Abr-22'!$F41,Lista_CUIT!$A$1:$D$1871,4,0)),"CUIT NO CARGADO") -> 0
B42: 44678 | C42: 1 | D42: 3 | E42: 845863 | F42: 30712019359 | G42: =IFERROR(IF('Abr-22'!$F42="","-",VLOOKUP('Abr-22'!$F42,Lista_CUIT!$A$1:$D$1871,2,0)),"CUIT NO CARGADO") -> LINKEDSTORE ARGENTINA S.R.L. | H42: 2478.51 | I42: =IF('Abr-22'!$H42="","",'Abr-22'!$H42*0.21) -> 520.4871 | P42: =SUM('Abr-22'!$H42:$O42) -> 2998.9971 | Q42: =IFERROR(IF('Abr-22'!$F42="","-",VLOOKUP('Abr-22'!$F42,Lista_CUIT!$A$1:$D$1871,3,0)),"CUIT NO CARGADO") -> Gastos Varios | R42: =IFERROR(IF('Abr-22'!$F42="","-",VLOOKUP('Abr-22'!$F42,Lista_CUIT!$A$1:$D$1871,4,0)),"CUIT NO CARGADO") -> 0
B43: 44678 | C43: 1 | D43: 12 | E43: 12026 | F43: 30604942051 | G43: =IFERROR(IF('Abr-22'!$F43="","-",VLOOKUP('Abr-22'!$F43,Lista_CUIT!$A$1:$D$1871,2,0)),"CUIT NO CARGADO") -> IMPORTADORA FOTOGRAFICA SA | H43: 25288.62 | I43: =IF('Abr-22'!$H43="","",'Abr-22'!$H43*0.21) -> 5310.6102 | P43: =SUM('Abr-22'!$H43:$O43) -> 30599.23 | Q43: =IFERROR(IF('Abr-22'!$F43="","-",VLOOKUP('Abr-22'!$F43,Lista_CUIT!$A$1:$D$1871,3,0)),"CUIT NO CARGADO") -> Gastos Oficina | R43: =IFERROR(IF('Abr-22'!$F43="","-",VLOOKUP('Abr-22'!$F43,Lista_CUIT!$A$1:$D$1871,4,0)),"CUIT NO CARGADO") -> 0
...

Sheet May-22
B1: LIBRO IVA COMPRAS | G1: ='Abr-22'!G1:M1 -> CORITEC S.R.L. | N1: =EDATE('Abr-22'!N1,1) -> 44682
B3: TOTAL COMPRAS | G3: TOTAL CREDITO FISCAL | J3: TOTAL VENTAS NETAS | M3: TOTAL DEBITO FISCAL | P3: RESULTADO
B4: =SUM('May-22'!$H$51)+'May-22'!$G$63 -> 1100107 | G4: ='May-22'!$I$51+'May-22'!$J$51+'May-22'!$K$51+'May-22'!$H$63+'May-22'!$I$63 -> 223910.74 | J4: ='May-22'!$H$100+'May-22'!$H$112 -> 7471351.4 | M4: ='May-22'!$I$100+'May-22'!$J$100+'May-22'!$I$112+'May-22'!$J$112 -> 850836.36 | P4: =G4-M4 -> -626925.62
O7: no esta configurado para que este en negativo
B8: FECHA | C8: TIPO | D8: PTO VTA | E8: NRO. CPTE | F8: CUIT | G8: RAZON SOCIAL | H8: NETO GRAVADO | I8: IVA 21 % | J8: IVA 27% | K8: IVA 10,5% | L8: PERC. IVA | M8: PERC IIBB BS AS | N8: PERC. IIBB CABA | O8: Otros / No Grav. | P8: TOTAL | Q8: Tipo de Gasto | R8: Provincia
B9: 44682 | C9: 1 | D9: 3 | E9: 529 | F9: 30715402765 | G9: =IFERROR(IF('May-22'!$F9="","-",VLOOKUP('May-22'!$F9,Lista_CUIT!$A$1:$D$1871,2,0)),"CUIT NO CARGADO") -> RIO 265 SRL | H9: 7190.08 | I9: ='May-22'!$H9*0.21 -> 1509.9168 | P9: =SUM('May-22'!$H9:$O9) -> 8699.9968 | Q9: =IFERROR(IF('May-22'!$F9="","-",VLOOKUP('May-22'!$F9,Lista_CUIT!$A$1:$D$1871,3,0)),"CUIT NO CARGADO") -> GTOS VARIOS-ESTACIONAMIENTO HORACIO | R9: =IFERROR(IF('May-22'!$F9="","-",VLOOKUP('May-22'!$F9,Lista_CUIT!$A$1:$D$1871,4,0)),"CUIT NO CARGADO") -> 0
B10: 44682 | C10: 1 | D10: 3 | E10: 155932 | F10: 30707135596 | G10: =IFERROR(IF('May-22'!$F10="","-",VLOOKUP('May-22'!$F10,Lista_CUIT!$A$1:$D$1871,2,0)),"CUIT NO CARGADO") -> CITILAN ARGENTINA SA | H10: 2735.95 | I10: ='May-22'!$H10*0.21 -> 574.5495 | P10: =SUM('May-22'!$H10:$O10) -> 3310.4995 | Q10: =IFERROR(IF('May-22'!$F10="","-",VLOOKUP('May-22'!$F10,Lista_CUIT!$A$1:$D$1871,3,0)),"CUIT NO CARGADO") -> SERVICIOS GAS, LUZ, ETC | R10: =IFERROR(IF('May-22'!$F10="","-",VLOOKUP('May-22'!$F10,Lista_CUIT!$A$1:$D$1871,4,0)),"CUIT NO CARGADO") -> 0
B11: 44683 | C11: 1 | D11: 2 | E11: 131 | F11: 20125142851 | G11: =IFERROR(IF('May-22'!$F11="","-",VLOOKUP('May-22'!$F11,Lista_CUIT!$A$1:$D$1871,2,0)),"CUIT NO CARGADO") -> FEDERICI NICOLAS JOSE | H11: 15805 | I11: ='May-22'!$H11*0.21 -> 3319.05 | P11: =SUM('May-22'!$H11:$O11) -> 19124.05 | Q11: =IFERROR(IF('May-22'!$F11="","-",VLOOKUP('May-22'!$F11,Lista_CUIT!$A$1:$D$1871,3,0)),"CUIT NO CARGADO") -> INSUMO | R11: =IFERROR(IF('May-22'!$F11="","-",VLOOKUP('May-22'!$F11,Lista_CUIT!$A$1:$D$1871,4,0)),"CUIT NO CARGADO") -> 0
B12: 44683 | C12: 1 | D12: 4 | E12: 960 | F12: 27208929416 | G12: =IFERROR(IF('May-22'!$F12="","-",VLOOKUP('May-22'!$F12,Lista_CUIT!$A$1:$D$1871,2,0)),"CUIT NO CARGADO") -> FIGARO CARLA SILVINA | H12: 10160.29 | I12: ='May-22'!$H12*0.21 -> 2133.6609 | P12: =SUM('May-22'!$H12:$O12) -> 12293.951 | Q12: =IFERROR(IF('May-22'!$F12="","-",VLOOKUP('May-22'!$F12,Lista_CUIT!$A$1:$D$1871,3,0)),"CUIT NO CARGADO") -> INSUMO | R12: =IFERROR(IF('May-22'!$F12="","-",VLOOKUP('May-22'!$F12,Lista_CUIT!$A$1:$D$1871,4,0)),"CUIT NO CARGADO") -> 0
B13: 44683 | C13: 1 | D13: 9 | E13: 1143 | F13: 30631047145 | G13: =IFERROR(IF('May-22'!$F13="","-",VLOOKUP('May-22'!$F13,Lista_CUIT!$A$1:$D$1871,2,0)),"CUIT NO CARGADO") -> SEMICONDUC. Y COMPON. SRL | H13: 26317.5 | I13: 4827.9 | K13: 349.39 | P13: =SUM('May-22'!$H13:$O13) -> 31494.79 | Q13: =IFERROR(IF('May-22'!$F13="","-",VLOOKUP('May-22'!$F13,Lista_CUIT!$A$1:$D$1871,3,0)),"CUIT NO CARGADO") -> INSUMO | R13: =IFERROR(IF('May-22'!$F13="","-",VLOOKUP('May-22'!$F13,Lista_CUIT!$A$1:$D$1871,4,0)),"CUIT NO CARGADO") -> 0
B14: 44683 | C14: 1 | D14: 11 | E14: 1811 | F14: 30711809429 | G14: =IFERROR(IF('May-22'!$F14="","-",VLOOKUP('May-22'!$F14,Lista_CUIT!$A$1:$D$1871,2,0)),"CUIT NO CARGADO") -> DERPLO SA | H14: 3113.4 | I14: ='May-22'!$H14*0.21 -> 653.814 | P14: =SUM('May-22'!$H14:$O14) -> 3767.214 | Q14: =IFERROR(IF('May-22'!$F14="","-",VLOOKUP('May-22'!$F14,Lista_CUIT!$A$1:$D$1871,3,0)),"CUIT NO CARGADO") -> INSUMO | R14: =IFERROR(IF('May-22'!$F14="","-",VLOOKUP('May-22'!$F14,Lista_CUIT!$A$1:$D$1871,4,0)),"CUIT NO CARGADO") -> 0
B15: 44683 | C15: 1 | D15: 106 | E15: 521748 | F15: 30594494187 | G15: =IFERROR(IF('May-22'!$F15="","-",VLOOKUP('May-22'!$F15,Lista_CUIT!$A$1:$D$1871,2,0)),"CUIT NO CARGADO") -> FEDERAL EXPRESS CORPORATION | I15: ='May-22'!$H15*0.21 -> 0 | O15: 31189.2 | P15: =SUM('May-22'!$H15:$O15) -> 31189.2 | Q15: =IFERROR(IF('May-22'!$F15="","-",VLOOKUP('May-22'!$F15,Lista_CUIT!$A$1:$D$1871,3,0)),"CUIT NO CARGADO") -> GTOS IMP. | R15: =IFERROR(IF('May-22'!$F15="","-",VLOOKUP('May-22'!$F15,Lista_CUIT!$A$1:$D$1871,4,0)),"CUIT NO CARGADO") -> 0
B16: 44683 | C16: 1 | D16: 13 | E16: 763325 | F16: 30700940957 | G16: =IFERROR(IF('May-22'!$F16="","-",VLOOKUP('May-22'!$F16,Lista_CUIT!$A$1:$D$1871,2,0)),"CUIT NO CARGADO") -> UPS de ARGENTINA SA | H16: 63402.51 | K16: 6657.26 | M16: 7289.04 | O16: -63402.51 | P16: =SUM('May-22'!$H16:$O16) -> 13946.3 | Q16: =IFERROR(IF('May-22'!$F16="","-",VLOOKUP('May-22'!$F16,Lista_CUIT!$A$1:$D$1871,3,0)),"CUIT NO CARGADO") -> GTOS IMP. | R16: =IFERROR(IF('May-22'!$F16="","-",VLOOKUP('May-22'!$F16,Lista_CUIT!$A$1:$D$1871,4,0)),"CUIT NO CARGADO") -> 0
B17: 44684 | C17: 1 | D17: 3 | E17: 256 | F17: 20921575743 | G17: =IFERROR(IF('May-22'!$F17="","-",VLOOKUP('May-22'!$F17,Lista_CUIT!$A$1:$D$1871,2,0)),"CUIT NO CARGADO") -> RIOS GOMEZ JOSE ANTONIO | H17: 90720 | I17: ='May-22'!$H17*0.21 -> 19051.2 | P17: =SUM('May-22'!$H17:$O17) -> 109771.2 | Q17: =IFERROR(IF('May-22'!$F17="","-",VLOOKUP('May-22'!$F17,Lista_CUIT!$A$1:$D$1871,3,0)),"CUIT NO CARGADO") -> Papeleria e Impresos | R17: =IFERROR(IF('May-22'!$F17="","-",VLOOKUP('May-22'!$F17,Lista_CUIT!$A$1:$D$1871,4,0)),"CUIT NO CARGADO") -> 0
B18: 44684 | C18: 1 | D18: 3 | E18: 16737 | F18: 30707468161 | G18: =IFERROR(IF('May-22'!$F18="","-",VLOOKUP('May-22'!$F18,Lista_CUIT!$A$1:$D$1871,2,0)),"CUIT NO CARGADO") -> LASERTEC INGENIERIA S.R.L. | H18: 33740 | I18: ='May-22'!$H18*0.21 -> 7085.4 | P18: =SUM('May-22'!$H18:$O18) -> 40825.4 | Q18: =IFERROR(IF('May-22'!$F18="","-",VLOOKUP('May-22'!$F18,Lista_CUIT!$A$1:$D$1871,3,0)),"CUIT NO CARGADO") -> INSUMO | R18: =IFERROR(IF('May-22'!$F18="","-",VLOOKUP('May-22'!$F18,Lista_CUIT!$A$1:$D$1871,4,0)),"CUIT NO CARGADO") -> 0
B19: 44690 | C19: 1 | D19: 2 | E19: 132 | F19: 20125142851 | G19: =IFERROR(IF('May-22'!$F19="","-",VLOOKUP('May-22'!$F19,Lista_CUIT!$A$1:$D$1871,2,0)),"CUIT NO CARGADO") -> FEDERICI NICOLAS JOSE | H19: 21037 | I19: ='May-22'!$H19*0.21 -> 4417.77 | P19: =SUM('May-22'!$H19:$O19) -> 25454.77 | Q19: =IFERROR(IF('May-22'!$F19="","-",VLOOKUP('May-22'!$F19,Lista_CUIT!$A$1:$D$1871,3,0)),"CUIT NO CARGADO") -> INSUMO | R19: =IFERROR(IF('May-22'!$F19="","-",VLOOKUP('May-22'!$F19,Lista_CUIT!$A$1:$D$1871,4,0)),"CUIT NO CARGADO") -> 0
B20: 44690 | C20: 1 | D20: 2 | E20: 765 | F20: 30500805222 | G20: =IFERROR(IF('May-22'!$F20="","-",VLOOKUP('May-22'!$F20,Lista_CUIT!$A$1:$D$1871,2,0)),"CUIT NO CARGADO") -> KAVCIC SRL | H20: 69690 | I20: ='May-22'!$H20*0.21 -> 14634.9 | P20: =SUM('May-22'!$H20:$O20) -> 84324.9 | Q20: =IFERROR(IF('May-22'!$F20="","-",VLOOKUP('May-22'!$F20,Lista_CUIT!$A$1:$D$1871,3,0)),"CUIT NO CARGADO") -> INSUMO | R20: =IFERROR(IF('May-22'!$F20="","-",VLOOKUP('May-22'!$F20,Lista_CUIT!$A$1:$D$1871,4,0)),"CUIT NO CARGADO") -> 0
B21: 44691 | C21: 1 | D21: 31 | E21: 161345 | F21: 30710114176 | G21: =IFERROR(IF('May-22'!$F21="","-",VLOOKUP('May-22'!$F21,Lista_CUIT!$A$1:$D$1871,2,0)),"CUIT NO CARGADO") -> SYMONDS SA. | H21: 31404.13 | I21: ='May-22'!$H21*0.21 -> 6594.8673 | P21: =SUM('May-22'!$H21:$O21) -> 37998.997 | Q21: =IFERROR(IF('May-22'!$F21="","-",VLOOKUP('May-22'!$F21,Lista_CUIT!$A$1:$D$1871,3,0)),"CUIT NO CARGADO") -> Mantenimiento | R21: =IFERROR(IF('May-22'!$F21="","-",VLOOKUP('May-22'!$F21,Lista_CUIT!$A$1:$D$1871,4,0)),"CUIT NO CARGADO") -> 0
B22: 44691 | C22: 1 | D22: 3 | E22: 1743 | F22: 30715461540 | G22: =IFERROR(IF('May-22'!$F22="","-",VLOOKUP('May-22'!$F22,Lista_CUIT!$A$1:$D$1871,2,0)),"CUIT NO CARGADO") -> CAISEN S.R.L. | H22: 875.2 | I22: ='May-22'!$H22*0.21 -> 183.792 | P22: =SUM('May-22'!$H22:$O22) -> 1058.992 | Q22: =IFERROR(IF('May-22'!$F22="","-",VLOOKUP('May-22'!$F22,Lista_CUIT!$A$1:$D$1871,3,0)),"CUIT NO CARGADO") -> Gastos Varios | R22: =IFERROR(IF('May-22'!$F22="","-",VLOOKUP('May-22'!$F22,Lista_CUIT!$A$1:$D$1871,4,0)),"CUIT NO CARGADO") -> 0
B23: 44692 | C23: 1 | D23: 2466 | E23: 357998 | F23: 30678814357 | G23: =IFERROR(IF('May-22'!$F23="","-",VLOOKUP('May-22'!$F23,Lista_CUIT!$A$1:$D$1871,2,0)),"CUIT NO CARGADO") -> Telefonica Moviles Argentina SA | H23: 6911.5 | J23: 1866.11 | N23: 207.34 | O23: 92.89 | P23: =SUM('May-22'!$H23:$O23) -> 9077.84 | Q23: =IFERROR(IF('May-22'!$F23="","-",VLOOKUP('May-22'!$F23,Lista_CUIT!$A$1:$D$1871,3,0)),"CUIT NO CARGADO") -> SERVICIOS GAS, LUZ, ETC | R23: =IFERROR(IF('May-22'!$F23="","-",VLOOKUP('May-22'!$F23,Lista_CUIT!$A$1:$D$1871,4,0)),"CUIT NO CARGADO") -> 0
B24: 44693 | C24: 1 | D24: 2 | E24: 20370 | F24: 30715257099 | G24: =IFERROR(IF('May-22'!$F24="","-",VLOOKUP('May-22'!$F24,Lista_CUIT!$A$1:$D$1871,2,0)),"CUIT NO CARGADO") -> FAS MOTOS | H24: 18834.71 | I24: ='May-22'!$H24*0.21 -> 3955.2891 | P24: =SUM('May-22'!$H24:$O24) -> 22789.999 | Q24: =IFERROR(IF('May-22'!$F24="","-",VLOOKUP('May-22'!$F24,Lista_CUIT!$A$1:$D$1871,3,0)),"CUIT NO CARGADO") -> INSUMO | R24: =IFERROR(IF('May-22'!$F24="","-",VLOOKUP('May-22'!$F24,Lista_CUIT!$A$1:$D$1871,4,0)),"CUIT NO CARGADO") -> 0
B25: 44693 | C25: 1 | D25: 106 | E25: 524430 | F25: 30594494187 | G25: =IFERROR(IF('May-22'!$F25="","-",VLOOKUP('May-22'!$F25,Lista_CUIT!$A$1:$D$1871,2,0)),"CUIT NO CARGADO") -> FEDERAL EXPRESS CORPORATION | H25: 5844 | I25: ='May-22'!$H25*0.21 -> 1227.24 | O25: 4843.83 | P25: =SUM('May-22'!$H25:$O25) -> 11915.07 | Q25: =IFERROR(IF('May-22'!$F25="","-",VLOOKUP('May-22'!$F25,Lista_CUIT!$A$1:$D$1871,3,0)),"CUIT NO CARGADO") -> GTOS IMP. | R25: =IFERROR(IF('May-22'!$F25="","-",VLOOKUP('May-22'!$F25,Lista_CUIT!$A$1:$D$1871,4,0)),"CUIT NO CARGADO") -> 0
B26: 44693 | C26: 1 | D26: 7 | E26: 29271 | F26: 20181426846 | G26: =IFERROR(IF('May-22'!$F26="","-",VLOOKUP('May-22'!$F26,Lista_CUIT!$A$1:$D$1871,2,0)),"CUIT NO CARGADO") -> GRIDEL WALTER DIEGO | H26: 1849.17 | I26: ='May-22'!$H26*0.21 -> 388.3257 | P26: =SUM('May-22'!$H26:$O26) -> 2237.4957 | Q26: =IFERROR(IF('May-22'!$F26="","-",VLOOKUP('May-22'!$F26,Lista_CUIT!$A$1:$D$1871,3,0)),"CUIT NO CARGADO") -> Gastos Oficina | R26: =IFERROR(IF('May-22'!$F26="","-",VLOOKUP('May-22'!$F26,Lista_CUIT!$A$1:$D$1871,4,0)),"CUIT NO CARGADO") -> 0
B27: 44694 | C27: 1 | D27: 5 | E27: 542 | F27: 30707397256 | G27: =IFERROR(IF('May-22'!$F27="","-",VLOOKUP('May-22'!$F27,Lista_CUIT!$A$1:$D$1871,2,0)),"CUIT NO CARGADO") -> GRAFICA Y FOTOGRABADOS LA PLAZA SRL | H27: 315388.2 | I27: ='May-22'!$H27*0.21 -> 66231.522 | P27: =SUM('May-22'!$H27:$O27) -> 381619.72 | Q27: =IFERROR(IF('May-22'!$F27="","-",VLOOKUP('May-22'!$F27,Lista_CUIT!$A$1:$D$1871,3,0)),"CUIT NO CARGADO") -> Fotograbados | R27: =IFERROR(IF('May-22'!$F27="","-",VLOOKUP('May-22'!$F27,Lista_CUIT!$A$1:$D$1871,4,0)),"CUIT NO CARGADO") -> 0
B28: 44694 | C28: 1 | D28: 3 | E28: 170 | F28: 23319824979 | G28: =IFERROR(IF('May-22'!$F28="","-",VLOOKUP('May-22'!$F28,Lista_CUIT!$A$1:$D$1871,2,0)),"CUIT NO CARGADO") -> PEREZ SEBASTIAN LUCAS | H28: 4950.23 | K28: 519.77415 | P28: =SUM('May-22'!$H28:$O28) -> 5470.0041 | Q28: =IFERROR(IF('May-22'!$F28="","-",VLOOKUP('May-22'!$F28,Lista_CUIT!$A$1:$D$1871,3,0)),"CUIT NO CARGADO") -> Gastos Varios | R28: =IFERROR(IF('May-22'!$F28="","-",VLOOKUP('May-22'!$F28,Lista_CUIT!$A$1:$D$1871,4,0)),"CUIT NO CARGADO") -> 0
B29: 44695 | C29: 1 | D29: 6 | E29: 9566 | F29: 30715819461 | G29: =IFERROR(IF('May-22'!$F29="","-",VLOOKUP('May-22'!$F29,Lista_CUIT!$A$1:$D$1871,2,0)),"CUIT NO CARGADO") -> DISTRI AIRES SRL | H29: 4968.6 | I29: ='May-22'!$H29*0.21 -> 1043.406 | P29: =SUM('May-22'!$H29:$O29) -> 6012.006 | Q29: =IFERROR(IF('May-22'!$F29="","-",VLOOKUP('May-22'!$F29,Lista_CUIT!$A$1:$D$1871,3,0)),"CUIT NO CARGADO") -> Papeleria e Impresos | R29: =IFERROR(IF('May-22'!$F29="","-",VLOOKUP('May-22'!$F29,Lista_CUIT!$A$1:$D$1871,4,0)),"CUIT NO CARGADO") -> 0
B30: 44697 | C30: 1 | D30: 9 | E30: 25058 | F30: 30595378695 | G30: =IFERROR(IF('May-22'!$F30="","-",VLOOKUP('May-22'!$F30,Lista_CUIT!$A$1:$D$1871,2,0)),"CUIT NO CARGADO") -> QUIWI SRL | H30: 3372.38 | I30: ='May-22'!$H30*0.21 -> 708.1998 | P30: =SUM('May-22'!$H30:$O30) -> 4080.5798 | Q30: =IFERROR(IF('May-22'!$F30="","-",VLOOKUP('May-22'!$F30,Lista_CUIT!$A$1:$D$1871,3,0)),"CUIT NO CARGADO") -> Mantenimiento | R30: =IFERROR(IF('May-22'!$F30="","-",VLOOKUP('May-22'!$F30,Lista_CUIT!$A$1:$D$1871,4,0)),"CUIT NO CARGADO") -> 0
B31: 44697 | C31: 1 | D31: 3 | E31: 503 | F31: 30716331349 | G31: =IFERROR(IF('May-22'!$F31="","-",VLOOKUP('May-22'!$F31,Lista_CUIT!$A$1:$D$1871,2,0)),"CUIT NO CARGADO") -> STERLING TRADE S.R.L. | I31: ='May-22'!$H31*0.21 -> 0 | O31: 65190 | P31: =SUM('May-22'!$H31:$O31) -> 65190 | Q31: =IFERROR(IF('May-22'!$F31="","-",VLOOKUP('May-22'!$F31,Lista_CUIT!$A$1:$D$1871,3,0)),"CUIT NO CARGADO") -> FLETE | R31: =IFERROR(IF('May-22'!$F31="","-",VLOOKUP('May-22'!$F31,Lista_CUIT!$A$1:$D$1871,4,0)),"CUIT NO CARGADO") -> 0
B32: 44700 | C32: 1 | D32: 1 | E32: 7155 | F32: 33716043989 | G32: =IFERROR(IF('May-22'!$F32="","-",VLOOKUP('May-22'!$F32,Lista_CUIT!$A$1:$D$1871,2,0)),"CUIT NO CARGADO") -> DANIEL Y LUCIO RIAL SOCIEDAD SIMPLE | H32: 15033.1 | I32: ='May-22'!$H32*0.21 -> 3156.951 | P32: =SUM('May-22'!$H32:$O32) -> 18190.051 | Q32: =IFERROR(IF('May-22'!$F32="","-",VLOOKUP('May-22'!$F32,Lista_CUIT!$A$1:$D$1871,3,0)),"CUIT NO CARGADO") -> INSUMO | R32: =IFERROR(IF('May-22'!$F32="","-",VLOOKUP('May-22'!$F32,Lista_CUIT!$A$1:$D$1871,4,0)),"CUIT NO CARGADO") -> 0
B33: 44700 | C33: 1 | D33: 5 | E33: 52946 | F33: 30692857611 | G33: =IFERROR(IF('May-22'!$F33="","-",VLOOKUP('May-22'!$F33,Lista_CUIT!$A$1:$D$1871,2,0)),"CUIT NO CARGADO") -> BAGUI S.A. | H33: 6620.63 | I33: ='May-22'!$H33*0.21 -> 1390.3323 | P33: =SUM('May-22'!$H33:$O33) -> 8010.9623 | Q33: =IFERROR(IF('May-22'!$F33="","-",VLOOKUP('May-22'!$F33,Lista_CUIT!$A$1:$D$1871,3,0)),"CUIT NO CARGADO") -> MAT. PRIM. | R33: =IFERROR(IF('May-22'!$F33="","-",VLOOKUP('May-22'!$F33,Lista_CUIT!$A$1:$D$1871,4,0)),"CUIT NO CARGADO") -> 0
B34: 44700 | C34: 1 | D34: 5 | E34: 52913 | F34: 30692857611 | G34: =IFERROR(IF('May-22'!$F34="","-",VLOOKUP('May-22'!$F34,Lista_CUIT!$A$1:$D$1871,2,0)),"CUIT NO CARGADO") -> BAGUI S.A. | H34: 6373.13 | I34: ='May-22'!$H34*0.21 -> 1338.3573 | P34: =SUM('May-22'!$H34:$O34) -> 7711.4873 | Q34: =IFERROR(IF('May-22'!$F34="","-",VLOOKUP('May-22'!$F34,Lista_CUIT!$A$1:$D$1871,3,0)),"CUIT NO CARGADO") -> MAT. PRIM. | R34: =IFERROR(IF('May-22'!$F34="","-",VLOOKUP('May-22'!$F34,Lista_CUIT!$A$1:$D$1871,4,0)),"CUIT NO CARGADO") -> 0
B35: 44700 | C35: 3 | D35: 5 | E35: 6389 | F35: 30692857611 | G35: =IFERROR(IF('May-22'!$F35="","-",VLOOKUP('May-22'!$F35,Lista_CUIT!$A$1:$D$1871,2,0)),"CUIT NO CARGADO") -> BAGUI S.A. | H35: -6373.13 | I35: ='May-22'!$H35*0.21 -> -1338.3573 | P35: =SUM('May-22'!$H35:$O35) -> -7711.4873 | Q35: =IFERROR(IF('May-22'!$F35="","-",VLOOKUP('May-22'!$F35,Lista_CUIT!$A$1:$D$1871,3,0)),"CUIT NO CARGADO") -> MAT. PRIM. | R35: =IFERROR(IF('May-22'!$F35="","-",VLOOKUP('May-22'!$F35,Lista_CUIT!$A$1:$D$1871,4,0)),"CUIT NO CARGADO") -> 0
B36: 44701 | C36: 1 | D36: 3 | E36: 257 | F36: 20921575743 | G36: =IFERROR(IF('May-22'!$F36="","-",VLOOKUP('May-22'!$F36,Lista_CUIT!$A$1:$D$1871,2,0)),"CUIT NO CARGADO") -> RIOS GOMEZ JOSE ANTONIO | H36: 10350 | I36: ='May-22'!$H36*0.21 -> 2173.5 | P36: =SUM('May-22'!$H36:$O36) -> 12523.5 | Q36: =IFERROR(IF('May-22'!$F36="","-",VLOOKUP('May-22'!$F36,Lista_CUIT!$A$1:$D$1871,3,0)),"CUIT NO CARGADO") -> Papeleria e Impresos | R36: =IFERROR(IF('May-22'!$F36="","-",VLOOKUP('May-22'!$F36,Lista_CUIT!$A$1:$D$1871,4,0)),"CUIT NO CARGADO") -> 0
B37: 44701 | C37: 1 | D37: 6 | E37: 9713 | F37: 30715819461 | G37: =IFERROR(IF('May-22'!$F37="","-",VLOOKUP('May-22'!$F37,Lista_CUIT!$A$1:$D$1871,2,0)),"CUIT NO CARGADO") -> DISTRI AIRES SRL | H37: 4505.79 | I37: ='May-22'!$H37*0.21 -> 946.2159 | P37: =SUM('May-22'!$H37:$O37) -> 5452.0059 | Q37: =IFERROR(IF('May-22'!$F37="","-",VLOOKUP('May-22'!$F37,Lista_CUIT!$A$1:$D$1871,3,0)),"CUIT NO CARGADO") -> Papeleria e Impresos | R37: =IFERROR(IF('May-22'!$F37="","-",VLOOKUP('May-22'!$F37,Lista_CUIT!$A$1:$D$1871,4,0)),"CUIT NO CARGADO") -> 0
B38: 44702 | C38: 1 | D38: 6992 | E38: 7175 | F38: 30678774495 | G38: =IFERROR(IF('May-22'!$F38="","-",VLOOKUP('May-22'!$F38,Lista_CUIT!$A$1:$D$1871,2,0)),"CUIT NO CARGADO") -> OPER. DE EST. DE SERV. SA | H38: 5683.31 | I38: ='May-22'!$H38*0.21 -> 1193.4951 | O38: 1324.09 | P38: =SUM('May-22'!$H38:$O38) -> 8200.8951 | Q38: =IFERROR(IF('May-22'!$F38="","-",VLOOKUP('May-22'!$F38,Lista_CUIT!$A$1:$D$1871,3,0)),"CUIT NO CARGADO") -> COMBUSTIBLE | R38: =IFERROR(IF('May-22'!$F38="","-",VLOOKUP('May-22'!$F38,Lista_CUIT!$A$1:$D$1871,4,0)),"CUIT NO CARGADO") -> 0
B39: 44704 | C39: 1 | D39: 60 | E39: 7117 | F39: 30547188760 | G39: =IFERROR(IF('May-22'!$F39="","-",VLOOKUP('May-22'!$F39,Lista_CUIT!$A$1:$D$1871,2,0)),"CUIT NO CARGADO") -> LONCO HUE SA | H39: 20314.04 | I39: ='May-22'!$H39*0.21 -> 4265.9484 | P39: =SUM('May-22'!$H39:$O39) -> 24579.988 | Q39: =IFERROR(IF('May-22'!$F39="","-",VLOOKUP('May-22'!$F39,Lista_CUIT!$A$1:$D$1871,3,0)),"CUIT NO CARGADO") -> INSUMO | R39: =IFERROR(IF('May-22'!$F39="","-",VLOOKUP('May-22'!$F39,Lista_CUIT!$A$1:$D$1871,4,0)),"CUIT NO CARGADO") -> 0
B40: 44705 | C40: 1 | D40: 5 | E40: 53108 | F40: 30692857611 | G40: =IFERROR(IF('May-22'!$F40="","-",VLOOKUP('May-22'!$F40,Lista_CUIT!$A$1:$D$1871,2,0)),"CUIT NO CARGADO") -> BAGUI S.A. | H40: 12338 | I40: ='May-22'!$H40*0.21 -> 2590.98 | P40: =SUM('May-22'!$H40:$O40) -> 14928.98 | Q40: =IFERROR(IF('May-22'!$F40="","-",VLOOKUP('May-22'!$F40,Lista_CUIT!$A$1:$D$1871,3,0)),"CUIT NO CARGADO") -> MAT. PRIM. | R40: =IFERROR(IF('May-22'!$F40="","-",VLOOKUP('May-22'!$F40,Lista_CUIT!$A$1:$D$1871,4,0)),"CUIT NO CARGADO") -> 0
B41: 44705 | C41: 1 | D41: 5 | E41: 53109 | F41: 30692857611 | G41: =IFERROR(IF('May-22'!$F41="","-",VLOOKUP('May-22'!$F41,Lista_CUIT!$A$1:$D$1871,2,0)),"CUIT NO CARGADO") -> BAGUI S.A. | H41: 125388.8 | I41: ='May-22'!$H41*0.21 -> 26331.648 | P41: =SUM('May-22'!$H41:$O41) -> 151720.45 | Q41: =IFERROR(IF('May-22'!$F41="","-",VLOOKUP('May-22'!$F41,Lista_CUIT!$A$1:$D$1871,3,0)),"CUIT NO CARGADO") -> MAT. PRIM. | R41: =IFERROR(IF('May-22'!$F41="","-",VLOOKUP('May-22'!$F41,Lista_CUIT!$A$1:$D$1871,4,0)),"CUIT NO CARGADO") -> 0
B42: 44706 | C42: 1 | D42: 5199 | E42: 13676 | F42: 30695542476 | G42: =IFERROR(IF('May-22'!$F42="","-",VLOOKUP('May-22'!$F42,Lista_CUIT!$A$1:$D$1871,2,0)),"CUIT NO CARGADO") -> PAN AMERICAN ENERGY LLC | H42: 5252.89 | I42: ='May-22'!$H42*0.21 -> 1103.1069 | O42: 1101.59 | P42: =SUM('May-22'!$H42:$O42) -> 7457.5869 | Q42: =IFERROR(IF('May-22'!$F42="","-",VLOOKUP('May-22'!$F42,Lista_CUIT!$A$1:$D$1871,3,0)),"CUIT NO CARGADO") -> COMBUSTIBLE | R42: =IFERROR(IF('May-22'!$F42="","-",VLOOKUP('May-22'!$F42,Lista_CUIT!$A$1:$D$1871,4,0)),"CUIT NO CARGADO") -> 0
B43: 44707 | C43: 3 | D43: 5 | E43: 6400 | F43: 30692857611 | G43: =IFERROR(IF('May-22'!$F43="","-",VLOOKUP('May-22'!$F43,Lista_CUIT!$A$1:$D$1871,2,0)),"CUIT NO CARGADO") -> BAGUI S.A. | H43: -10185.83 | I43: ='May-22'!$H43*0.21 -> -2139.0243 | P43: =SUM('May-22'!$H43:$O43) -> -12324.854 | Q43: =IFERROR(IF('May-22'!$F43="","-",VLOOKUP('May-22'!$F43,Lista_CUIT!$A$1:$D$1871,3,0)),"CUIT NO CARGADO") -> MAT. PRIM. | R43: =IFERROR(IF('May-22'!$F43="","-",VLOOKUP('May-22'!$F43,Lista_CUIT!$A$1:$D$1871,4,0)),"CUIT NO CARGADO") -> 0
...

Sheet Jun-22
B1: LIBRO IVA COMPRAS | G1: ='Abr-22'!G1:M1 -> CORITEC S.R.L. | N1: =EDATE('Abr-22'!N1,2) -> 44713
B3: TOTAL COMPRAS | G3: TOTAL CREDITO FISCAL | J3: TOTAL VENTAS NETAS | M3: TOTAL DEBITO FISCAL | P3: RESULTADO
B4: =SUM('Jun-22'!$H$39)+'Jun-22'!$G$52 -> 2946484.8 | G4: ='Jun-22'!$I$39+'Jun-22'!$J$39+'Jun-22'!$K$39+'Jun-22'!$H$52+'Jun-22'!$I$52 -> 574986.36 | J4: ='Jun-22'!$H$93+'Jun-22'!$H$104 -> 2789657.3 | M4: ='Jun-22'!$I$93+'Jun-22'!$J$93+'Jun-22'!$I$104+'Jun-22'!$J$104 -> 340735.04 | P4: =G4-M4 -> 234251.32
B8: FECHA | C8: TIPO | D8: PTO VTA | E8: NRO. CPTE | F8: CUIT | G8: RAZON SOCIAL | H8: NETO GRAVADO | I8: IVA 21 % | J8: IVA 27% | K8: IVA 10,5% | L8: PERC. IVA | M8: PERC IIBB BS AS | N8: PERC. IIBB CABA | O8: Otros / No Grav. | P8: TOTAL | Q8: Tipo de Gasto | R8: Provincia
B9: 44741 | C9: 1 | D9: 2 | E9: 139 | F9: 20125142851 | G9: =IFERROR(IF('Jun-22'!$F9="","-",VLOOKUP('Jun-22'!$F9,Lista_CUIT!$A$1:$D$1871,2,0)),"CUIT NO CARGADO") -> FEDERICI NICOLAS JOSE | H9: 13908 | I9: =IF('Jun-22'!$H9="","",'Jun-22'!$H9*0.21) -> 2920.68 | P9: =SUM('Jun-22'!$H9:$O9) -> 16828.68 | Q9: =IFERROR(IF('Jun-22'!$F9="","-",VLOOKUP('Jun-22'!$F9,Lista_CUIT!$A$1:$D$1871,3,0)),"CUIT NO CARGADO") -> INSUMO | R9: =IFERROR(IF('Jun-22'!$F9="","-",VLOOKUP('Jun-22'!$F9,Lista_CUIT!$A$1:$D$1871,4,0)),"CUIT NO CARGADO") -> 0
B10: 44736 | C10: 1 | D10: 2 | E10: 138 | F10: 20125142851 | G10: =IFERROR(IF('Jun-22'!$F10="","-",VLOOKUP('Jun-22'!$F10,Lista_CUIT!$A$1:$D$1871,2,0)),"CUIT NO CARGADO") -> FEDERICI NICOLAS JOSE | H10: 15048 | I10: =IF('Jun-22'!$H10="","",'Jun-22'!$H10*0.21) -> 3160.08 | P10: =SUM('Jun-22'!$H10:$O10) -> 18208.08 | Q10: =IFERROR(IF('Jun-22'!$F10="","-",VLOOKUP('Jun-22'!$F10,Lista_CUIT!$A$1:$D$1871,3,0)),"CUIT NO CARGADO") -> INSUMO | R10: =IFERROR(IF('Jun-22'!$F10="","-",VLOOKUP('Jun-22'!$F10,Lista_CUIT!$A$1:$D$1871,4,0)),"CUIT NO CARGADO") -> 0
B11: 44739 | C11: 1 | D11: 1 | E11: 178227 | F11: 30716620634 | G11: =IFERROR(IF('Jun-22'!$F11="","-",VLOOKUP('Jun-22'!$F11,Lista_CUIT!$A$1:$D$1871,2,0)),"CUIT NO CARGADO") -> FIRST LABEL SRL | H11: 7106.61 | I11: =IF('Jun-22'!$H11="","",'Jun-22'!$H11*0.21) -> 1492.3881 | P11: =SUM('Jun-22'!$H11:$O11) -> 8598.9981 | Q11: =IFERROR(IF('Jun-22'!$F11="","-",VLOOKUP('Jun-22'!$F11,Lista_CUIT!$A$1:$D$1871,3,0)),"CUIT NO CARGADO") -> Gastos Varios | R11: =IFERROR(IF('Jun-22'!$F11="","-",VLOOKUP('Jun-22'!$F11,Lista_CUIT!$A$1:$D$1871,4,0)),"CUIT NO CARGADO") -> 0
B12: 44727 | C12: 1 | D12: 5 | E12: 71 | F12: 20235490251 | G12: =IFERROR(IF('Jun-22'!$F12="","-",VLOOKUP('Jun-22'!$F12,Lista_CUIT!$A$1:$D$1871,2,0)),"CUIT NO CARGADO") -> SALAS ARIEL ALFREDO | H12: 1444.21 | I12: =IF('Jun-22'!$H12="","",'Jun-22'!$H12*0.21) -> 303.2841 | P12: =SUM('Jun-22'!$H12:$O12) -> 1747.4941 | Q12: =IFERROR(IF('Jun-22'!$F12="","-",VLOOKUP('Jun-22'!$F12,Lista_CUIT!$A$1:$D$1871,3,0)),"CUIT NO CARGADO") -> Gastos Varios | R12: =IFERROR(IF('Jun-22'!$F12="","-",VLOOKUP('Jun-22'!$F12,Lista_CUIT!$A$1:$D$1871,4,0)),"CUIT NO CARGADO") -> 0
B13: 44718 | C13: 1 | D13: 3 | E13: 2090 | F13: 30716966530 | G13: =IFERROR(IF('Jun-22'!$F13="","-",VLOOKUP('Jun-22'!$F13,Lista_CUIT!$A$1:$D$1871,2,0)),"CUIT NO CARGADO") -> UDACHI SRL | H13: 3872.47 | I13: =IF('Jun-22'!$H13="","",'Jun-22'!$H13*0.21) -> 813.2187 | P13: =SUM('Jun-22'!$H13:$O13) -> 4685.6887 | Q13: =IFERROR(IF('Jun-22'!$F13="","-",VLOOKUP('Jun-22'!$F13,Lista_CUIT!$A$1:$D$1871,3,0)),"CUIT NO CARGADO") -> INSUMO | R13: =IFERROR(IF('Jun-22'!$F13="","-",VLOOKUP('Jun-22'!$F13,Lista_CUIT!$A$1:$D$1871,4,0)),"CUIT NO CARGADO") -> 0
B14: 44736 | C14: 1 | D14: 1 | E14: 467 | F14: 30715048066 | G14: =IFERROR(IF('Jun-22'!$F14="","-",VLOOKUP('Jun-22'!$F14,Lista_CUIT!$A$1:$D$1871,2,0)),"CUIT NO CARGADO") -> ROLLS Y EMPANADAS SA | H14: 119985 | I14: =IF('Jun-22'!$H14="","",'Jun-22'!$H14*0.21) -> 25196.85 | P14: =SUM('Jun-22'!$H14:$O14) -> 145181.85 | Q14: =IFERROR(IF('Jun-22'!$F14="","-",VLOOKUP('Jun-22'!$F14,Lista_CUIT!$A$1:$D$1871,3,0)),"CUIT NO CARGADO") -> CATERING | R14: =IFERROR(IF('Jun-22'!$F14="","-",VLOOKUP('Jun-22'!$F14,Lista_CUIT!$A$1:$D$1871,4,0)),"CUIT NO CARGADO") -> 0
B15: 44735 | C15: 1 | D15: 4 | E15: 87001 | F15: 30559932236 | G15: =IFERROR(IF('Jun-22'!$F15="","-",VLOOKUP('Jun-22'!$F15,Lista_CUIT!$A$1:$D$1871,2,0)),"CUIT NO CARGADO") -> ELECTRONICA ELEMON SA | H15: 22954.1 | K15: 2410.1805 | P15: =SUM('Jun-22'!$H15:$O15) -> 25364.28 | Q15: =IFERROR(IF('Jun-22'!$F15="","-",VLOOKUP('Jun-22'!$F15,Lista_CUIT!$A$1:$D$1871,3,0)),"CUIT NO CARGADO") -> MAT. PRIM. | R15: =IFERROR(IF('Jun-22'!$F15="","-",VLOOKUP('Jun-22'!$F15,Lista_CUIT!$A$1:$D$1871,4,0)),"CUIT NO CARGADO") -> 0
B16: 44735 | C16: 1 | D16: 7 | E16: 1293 | F16: 30709775762 | G16: =IFERROR(IF('Jun-22'!$F16="","-",VLOOKUP('Jun-22'!$F16,Lista_CUIT!$A$1:$D$1871,2,0)),"CUIT NO CARGADO") -> INDUSTRIA BAHIA S.A. | H16: 763743.32 | I16: =IF('Jun-22'!$H16="","",'Jun-22'!$H16*0.21) -> 160386.1 | P16: =SUM('Jun-22'!$H16:$O16) -> 924129.41 | Q16: =IFERROR(IF('Jun-22'!$F16="","-",VLOOKUP('Jun-22'!$F16,Lista_CUIT!$A$1:$D$1871,3,0)),"CUIT NO CARGADO") -> MAT. PRIM. | R16: =IFERROR(IF('Jun-22'!$F16="","-",VLOOKUP('Jun-22'!$F16,Lista_CUIT!$A$1:$D$1871,4,0)),"CUIT NO CARGADO") -> 0
B17: 44713 | C17: 1 | D17: 3 | E17: 540 | F17: 30715402765 | G17: =IFERROR(IF('Jun-22'!$F17="","-",VLOOKUP('Jun-22'!$F17,Lista_CUIT!$A$1:$D$1871,2,0)),"CUIT NO CARGADO") -> RIO 265 SRL | H17: 7190.08 | I17: =IF('Jun-22'!$H17="","",'Jun-22'!$H17*0.21) -> 1509.9168 | P17: =SUM('Jun-22'!$H17:$O17) -> 8699.9968 | Q17: =IFERROR(IF('Jun-22'!$F17="","-",VLOOKUP('Jun-22'!$F17,Lista_CUIT!$A$1:$D$1871,3,0)),"CUIT NO CARGADO") -> GTOS VARIOS-ESTACIONAMIENTO HORACIO | R17: =IFERROR(IF('Jun-22'!$F17="","-",VLOOKUP('Jun-22'!$F17,Lista_CUIT!$A$1:$D$1871,4,0)),"CUIT NO CARGADO") -> 0
B18: 44728 | C18: 1 | D18: 3 | E18: 259 | F18: 20921575743 | G18: =IFERROR(IF('Jun-22'!$F18="","-",VLOOKUP('Jun-22'!$F18,Lista_CUIT!$A$1:$D$1871,2,0)),"CUIT NO CARGADO") -> RIOS GOMEZ JOSE ANTONIO | H18: 13800 | I18: =IF('Jun-22'!$H18="","",'Jun-22'!$H18*0.21) -> 2898 | P18: =SUM('Jun-22'!$H18:$O18) -> 16698 | Q18: =IFERROR(IF('Jun-22'!$F18="","-",VLOOKUP('Jun-22'!$F18,Lista_CUIT!$A$1:$D$1871,3,0)),"CUIT NO CARGADO") -> Papeleria e Impresos | R18: =IFERROR(IF('Jun-22'!$F18="","-",VLOOKUP('Jun-22'!$F18,Lista_CUIT!$A$1:$D$1871,4,0)),"CUIT NO CARGADO") -> 0
B19: 44724 | C19: 1 | D19: 2 | E19: 137 | F19: 20125142851 | G19: =IFERROR(IF('Jun-22'!$F19="","-",VLOOKUP('Jun-22'!$F19,Lista_CUIT!$A$1:$D$1871,2,0)),"CUIT NO CARGADO") -> FEDERICI NICOLAS JOSE | H19: 25878 | I19: =IF('Jun-22'!$H19="","",'Jun-22'!$H19*0.21) -> 5434.38 | P19: =SUM('Jun-22'!$H19:$O19) -> 31312.38 | Q19: =IFERROR(IF('Jun-22'!$F19="","-",VLOOKUP('Jun-22'!$F19,Lista_CUIT!$A$1:$D$1871,3,0)),"CUIT NO CARGADO") -> INSUMO | R19: =IFERROR(IF('Jun-22'!$F19="","-",VLOOKUP('Jun-22'!$F19,Lista_CUIT!$A$1:$D$1871,4,0)),"CUIT NO CARGADO") -> 0
B20: 44720 | C20: 1 | D20: 2 | E20: 136 | F20: 20125142851 | G20: =IFERROR(IF('Jun-22'!$F20="","-",VLOOKUP('Jun-22'!$F20,Lista_CUIT!$A$1:$D$1871,2,0)),"CUIT NO CARGADO") -> FEDERICI NICOLAS JOSE | H20: 23073 | I20: =IF('Jun-22'!$H20="","",'Jun-22'!$H20*0.21) -> 4845.33 | P20: =SUM('Jun-22'!$H20:$O20) -> 27918.33 | Q20: =IFERROR(IF('Jun-22'!$F20="","-",VLOOKUP('Jun-22'!$F20,Lista_CUIT!$A$1:$D$1871,3,0)),"CUIT NO CARGADO") -> INSUMO | R20: =IFERROR(IF('Jun-22'!$F20="","-",VLOOKUP('Jun-22'!$F20,Lista_CUIT!$A$1:$D$1871,4,0)),"CUIT NO CARGADO") -> 0
B21: 44720 | C21: 1 | D21: 2 | E21: 135 | F21: 20125142851 | G21: =IFERROR(IF('Jun-22'!$F21="","-",VLOOKUP('Jun-22'!$F21,Lista_CUIT!$A$1:$D$1871,2,0)),"CUIT NO CARGADO") -> FEDERICI NICOLAS JOSE | H21: 19717.2 | I21: =IF('Jun-22'!$H21="","",'Jun-22'!$H21*0.21) -> 4140.612 | P21: =SUM('Jun-22'!$H21:$O21) -> 23857.812 | Q21: =IFERROR(IF('Jun-22'!$F21="","-",VLOOKUP('Jun-22'!$F21,Lista_CUIT!$A$1:$D$1871,3,0)),"CUIT NO CARGADO") -> INSUMO | R21: =IFERROR(IF('Jun-22'!$F21="","-",VLOOKUP('Jun-22'!$F21,Lista_CUIT!$A$1:$D$1871,4,0)),"CUIT NO CARGADO") -> 0
B22: 44726 | C22: 1 | D22: 10 | E22: 7137 | F22: 20168925582 | G22: =IFERROR(IF('Jun-22'!$F22="","-",VLOOKUP('Jun-22'!$F22,Lista_CUIT!$A$1:$D$1871,2,0)),"CUIT NO CARGADO") -> OXIGENO DORREGO | H22: 12600 | I22: =IF('Jun-22'!$H22="","",'Jun-22'!$H22*0.21) -> 2646 | P22: =SUM('Jun-22'!$H22:$O22) -> 15246 | Q22: =IFERROR(IF('Jun-22'!$F22="","-",VLOOKUP('Jun-22'!$F22,Lista_CUIT!$A$1:$D$1871,3,0)),"CUIT NO CARGADO") -> Gastos Varios | R22: =IFERROR(IF('Jun-22'!$F22="","-",VLOOKUP('Jun-22'!$F22,Lista_CUIT!$A$1:$D$1871,4,0)),"CUIT NO CARGADO") -> 0
B23: 44718 | C23: 1 | D23: 4 | E23: 86493 | F23: 30559932236 | G23: =IFERROR(IF('Jun-22'!$F23="","-",VLOOKUP('Jun-22'!$F23,Lista_CUIT!$A$1:$D$1871,2,0)),"CUIT NO CARGADO") -> ELECTRONICA ELEMON SA | H23: 61271.52 | I23: =IF('Jun-22'!$H23="","",'Jun-22'!$H23*0.21) -> 12867.019 | P23: =SUM('Jun-22'!$H23:$O23) -> 74138.539 | Q23: =IFERROR(IF('Jun-22'!$F23="","-",VLOOKUP('Jun-22'!$F23,Lista_CUIT!$A$1:$D$1871,3,0)),"CUIT NO CARGADO") -> MAT. PRIM. | R23: =IFERROR(IF('Jun-22'!$F23="","-",VLOOKUP('Jun-22'!$F23,Lista_CUIT!$A$1:$D$1871,4,0)),"CUIT NO CARGADO") -> 0
B24: 44719 | C24: 1 | D24: 8 | E24: 33893 | F24: 30655921644 | G24: =IFERROR(IF('Jun-22'!$F24="","-",VLOOKUP('Jun-22'!$F24,Lista_CUIT!$A$1:$D$1871,2,0)),"CUIT NO CARGADO") -> ELECTROCITY | H24: 3932.23 | I24: =IF('Jun-22'!$H24="","",'Jun-22'!$H24*0.21) -> 825.7683 | P24: =SUM('Jun-22'!$H24:$O24) -> 4757.9983 | Q24: =IFERROR(IF('Jun-22'!$F24="","-",VLOOKUP('Jun-22'!$F24,Lista_CUIT!$A$1:$D$1871,3,0)),"CUIT NO CARGADO") -> MAT. PRIM. | R24: =IFERROR(IF('Jun-22'!$F24="","-",VLOOKUP('Jun-22'!$F24,Lista_CUIT!$A$1:$D$1871,4,0)),"CUIT NO CARGADO") -> 0
B25: 44720 | C25: 1 | D25: 2 | E25: 768 | F25: 30500805222 | G25: =IFERROR(IF('Jun-22'!$F25="","-",VLOOKUP('Jun-22'!$F25,Lista_CUIT!$A$1:$D$1871,2,0)),"CUIT NO CARGADO") -> KAVCIC SRL | H25: 40260 | I25: =IF('Jun-22'!$H25="","",'Jun-22'!$H25*0.21) -> 8454.6 | P25: =SUM('Jun-22'!$H25:$O25) -> 48714.6 | Q25: =IFERROR(IF('Jun-22'!$F25="","-",VLOOKUP('Jun-22'!$F25,Lista_CUIT!$A$1:$D$1871,3,0)),"CUIT NO CARGADO") -> INSUMO | R25: =IFERROR(IF('Jun-22'!$F25="","-",VLOOKUP('Jun-22'!$F25,Lista_CUIT!$A$1:$D$1871,4,0)),"CUIT NO CARGADO") -> 0
B26: 44722 | C26: 1 | D26: 3 | E26: 6710 | F26: 30710212127 | G26: =IFERROR(IF('Jun-22'!$F26="","-",VLOOKUP('Jun-22'!$F26,Lista_CUIT!$A$1:$D$1871,2,0)),"CUIT NO CARGADO") -> COMPONENTES ELECTRICOS SA | H26: 827068.98 | I26: =IF('Jun-22'!$H26="","",'Jun-22'!$H26*0.21) -> 173684.49 | P26: =SUM('Jun-22'!$H26:$O26) -> 1000753.5 | Q26: =IFERROR(IF('Jun-22'!$F26="","-",VLOOKUP('Jun-22'!$F26,Lista_CUIT!$A$1:$D$1871,3,0)),"CUIT NO CARGADO") -> INSUMO | R26: =IFERROR(IF('Jun-22'!$F26="","-",VLOOKUP('Jun-22'!$F26,Lista_CUIT!$A$1:$D$1871,4,0)),"CUIT NO CARGADO") -> 0
B27: 44715 | C27: 1 | D27: 3 | E27: 7457 | F27: 30715864262 | G27: =IFERROR(IF('Jun-22'!$F27="","-",VLOOKUP('Jun-22'!$F27,Lista_CUIT!$A$1:$D$1871,2,0)),"CUIT NO CARGADO") -> ACPLIND - FELDMAN SH | H27: 18414 | I27: =IF('Jun-22'!$H27="","",'Jun-22'!$H27*0.21) -> 3866.94 | P27: =SUM('Jun-22'!$H27:$O27) -> 22280.94 | Q27: =IFERROR(IF('Jun-22'!$F27="","-",VLOOKUP('Jun-22'!$F27,Lista_CUIT!$A$1:$D$1871,3,0)),"CUIT NO CARGADO") -> MAT. PRIM. | R27: =IFERROR(IF('Jun-22'!$F27="","-",VLOOKUP('Jun-22'!$F27,Lista_CUIT!$A$1:$D$1871,4,0)),"CUIT NO CARGADO") -> 0
... B31: 44742 | C31: 1 | D31: 4 | E31: 12591 | F31: 23113854499 | G31: =IFERROR(IF('Jun-22'!$F31="","-",VLOOKUP('Jun-22'!$F31,Lista_CUIT!$A$1:$D$1871,2,0)),"CUIT NO CARGADO") -> VAZQUEZ DANIEL OSCAR | H31: 3801.65 | I31: =IF('Jun-22'!$H31="","",'Jun-22'!$H31*0.21) -> 798.3465 | P31: =SUM('Jun-22'!$H31:$O31) -> 4599.9965 | Q31: =IFERROR(IF('Jun-22'!$F31="","-",VLOOKUP('Jun-22'!$F31,Lista_CUIT!$A$1:$D$1871,3,0)),"CUIT NO CARGADO") -> INSUMO | R31: =IFERROR(IF('Jun-22'!$F31="","-",VLOOKUP('Jun-22'!$F31,Lista_CUIT!$A$1:$D$1871,4,0)),"CUIT NO CARGADO") -> 0
B32: 44741 | C32: 1 | D32: 280 | E32: 1375108 | F32: 30580111315 | G32: =IFERROR(IF('Jun-22'!$F32="","-",VLOOKUP('Jun-22'!$F32,Lista_CUIT!$A$1:$D$1871,2,0)),"CUIT NO CARGADO") -> DHL EXPRESS ARG SA | H32: 398923.43 | I32: 786.68 | K32: 41493.05 | O32: -359252.24 | P32: =SUM('Jun-22'!$H32:$O32) -> 81950.92 | Q32: =IFERROR(IF('Jun-22'!$F32="","-",VLOOKUP('Jun-22'!$F32,Lista_CUIT!$A$1:$D$1871,3,0)),"CUIT NO CARGADO") -> GTOS IMP. | R32: =IFERROR(IF('Jun-22'!$F32="","-",VLOOKUP('Jun-22'!$F32,Lista_CUIT!$A$1:$D$1871,4,0)),"CUIT NO CARGADO") -> 0
B33: 44723 | C33: 1 | D33: 2466 | E33: 370888 | F33: 30678814357 | G33: =IFERROR(IF('Jun-22'!$F33="","-",VLOOKUP('Jun-22'!$F33,Lista_CUIT!$A$1:$D$1871,2,0)),"CUIT NO CARGADO") -> Telefonica Moviles Argentina SA | H33: 2148.61 | J33: 580.1247 | M33: 64.46 | O33: 104.58 | P33: =SUM('Jun-22'!$H33:$O33) -> 2897.7747 | Q33: =IFERROR(IF('Jun-22'!$F33="","-",VLOOKUP('Jun-22'!$F33,Lista_CUIT!$A$1:$D$1871,3,0)),"CUIT NO CARGADO") -> SERVICIOS GAS, LUZ, ETC | R33: =IFERROR(IF('Jun-22'!$F33="","-",VLOOKUP('Jun-22'!$F33,Lista_CUIT!$A$1:$D$1871,4,0)),"CUIT NO CARGADO") -> 0
B34: 44729 | C34: 1 | D34: 30 | E34: 4666 | F34: 20217293791 | G34: =IFERROR(IF('Jun-22'!$F34="","-",VLOOKUP('Jun-22'!$F34,Lista_CUIT!$A$1:$D$1871,2,0)),"CUIT NO CARGADO") -> VELASCO LEIVA DEMIAN | H34: 8719.01 | I34: =IF('Jun-22'!$H34="","",'Jun-22'!$H34*0.21) -> 1830.9921 | P34: =SUM('Jun-22'!$H34:$O34) -> 10550.002 | Q34: =IFERROR(IF('Jun-22'!$F34="","-",VLOOKUP('Jun-22'!$F34,Lista_CUIT!$A$1:$D$1871,3,0)),"CUIT NO CARGADO") -> Gastos Varios | R34: =IFERROR(IF('Jun-22'!$F34="","-",VLOOKUP('Jun-22'!$F34,Lista_CUIT!$A$1:$D$1871,4,0)),"CUIT NO CARGADO") -> 0
B35: 44736 | C35: 1 | D35: 1 | E35: 466 | F35: 30715048066 | G35: =IFERROR(IF('Jun-22'!$F35="","-",VLOOKUP('Jun-22'!$F35,Lista_CUIT!$A$1:$D$1871,2,0)),"CUIT NO CARGADO") -> ROLLS Y EMPANADAS SA | H35: 81105 | I35: =IF('Jun-22'!$H35="","",'Jun-22'!$H35*0.21) -> 17032.05 | P35: =SUM('Jun-22'!$H35:$O35) -> 98137.05 | Q35: =IFERROR(IF('Jun-22'!$F35="","-",VLOOKUP('Jun-22'!$F35,Lista_CUIT!$A$1:$D$1871,3,0)),"CUIT NO CARGADO") -> CATERING | R35: =IFERROR(IF('Jun-22'!$F35="","-",VLOOKUP('Jun-22'!$F35,Lista_CUIT!$A$1:$D$1871,4,0)),"CUIT NO CARGADO") -> 0
B36: 44738 | C36: 1 | D36: 3 | E36: 939183 | F36: 30712019359 | G36: =IFERROR(IF('Jun-22'!$F36="","-",VLOOKUP('Jun-22'!$F36,Lista_CUIT!$A$1:$D$1871,2,0)),"CUIT NO CARGADO") -> LINKEDSTORE ARGENTINA S.R.L. | H36: 2478.51 | I36: =IF('Jun-22'!$H36="","",'Jun-22'!$H36*0.21) -> 520.4871 | P36: =SUM('Jun-22'!$H36:$O36) -> 2998.9971 | Q36: =IFERROR(IF('Jun-22'!$F36="","-",VLOOKUP('Jun-22'!$F36,Lista_CUIT!$A$1:$D$1871,3,0)),"CUIT NO CARGADO") -> Gastos Varios | R36: =IFERROR(IF('Jun-22'!$F36="","-",VLOOKUP('Jun-22'!$F36,Lista_CUIT!$A$1:$D$1871,4,0)),"CUIT NO CARGADO") -> 0
B37: 44741 | C37: 1 | D37: 5 | E37: 630 | F37: 30707397256 | G37: =IFERROR(IF('Jun-22'!$F37="","-",VLOOKUP('Jun-22'!$F37,Lista_CUIT!$A$1:$D$1871,2,0)),"CUIT NO CARGADO") -> GRAFICA Y FOTOGRABADOS LA PLAZA SRL | H37: 377201.4 | I37: =IF('Jun-22'!$H37="","",'Jun-22'!$H37*0.21) -> 79212.294 | P37: =SUM('Jun-22'!$H37:$O37) -> 456413.69 | Q37: =IFERROR(IF('Jun-22'!$F37="","-",VLOOKUP('Jun-22'!$F37,Lista_CUIT!$A$1:$D$1871,3,0)),"CUIT NO CARGADO") -> Fotograbados | R37: =IFERROR(IF('Jun-22'!$F37="","-",VLOOKUP('Jun-22'!$F37,Lista_CUIT!$A$1:$D$1871,4,0)),"CUIT NO CARGADO") -> 0
B38: 44741 | C38: 1 | D38: 1 | E38: 28187 | F38: 27332519633 | G38: =IFERROR(IF('Jun-22'!$F38="","-",VLOOKUP('Jun-22'!$F38,Lista_CUIT!$A$1:$D$1871,2,0)),"CUIT NO CARGADO") -> BOJORGE ROMINA VALERIA | H38: 2209.92 | I38: =IF('Jun-22'!$H38="","",'Jun-22'!$H38*0.21) -> 464.0832 | P38: =SUM('Jun-22'!$H38:$O38) -> 2674.0032 | Q38: =IFERROR(IF('Jun-22'!$F38="","-",VLOOKUP('Jun-22'!$F38,Lista_CUIT!$A$1:$D$1871,3,0)),"CUIT NO CARGADO") -> Gastos Oficina | R38: =IFERROR(IF('Jun-22'!$F38="","-",VLOOKUP('Jun-22'!$F38,Lista_CUIT!$A$1:$D$1871,4,0)),"CUIT NO CARGADO") -> 0
B39: Total | H39: =SUBTOTAL(109,'Jun-22'!$H$9:$H$38) -> 2944492.8 | I39: =SUBTOTAL(109,'Jun-22'!$I$9:$I$38) -> 530084.68 | J39: =SUBTOTAL(109,'Jun-22'!$J$9:$J$38) -> 580.1247 | K39: =SUBTOTAL(109,'Jun-22'!$K$9:$K$38) -> 43903.231 | L39: =SUBTOTAL(109,'Jun-22'!$L$9:$L$38) -> 0 | M39: =SUBTOTAL(109,'Jun-22'!$M$9:$M$38) -> 64.46 | N39: =SUBTOTAL(109,'Jun-22'!$N$9:$N$38) -> 0 | O39: =SUBTOTAL(109,'Jun-22'!$O$9:$O$38) -> -359147.66 | P39: =SUBTOTAL(109,'Jun-22'!$P$9:$P$38) -> 3159977.6
D44: LIQUIDACION EXTRACTOS BANCARIOS-TARJETAS
D45: FECHA | E45: NRO CPTE | F45: BANCO | G45: NETO | H45: IVA 21% | I45: IVA 10,5% | J45: RET IIBB CABA | K45: PERC IVA | L45: PERC IIBB
F46: BANCO CREDICOOP | G46: 1912 | H46: 401.52
F47: Liq. Importacion | H47: 0
F48: Cobro Exportacion | H48: 0
F49: VISA CREDITO | G49: 80 | H49: 16.8
F50: AMEX
D52: Total | G52: =SUBTOTAL(109,'Jun-22'!$G$46:$G$51) -> 1992 | H52: =SUBTOTAL(109,'Jun-22'!$H$46:$H$51) -> 418.32 | I52: =SUBTOTAL(109,'Jun-22'!$I$46:$I$51) -> 0 | J52: =SUBTOTAL(109,'Jun-22'!$J$46:$J$51) -> 0 | K52: =SUBTOTAL(109,'Jun-22'!$K$46:$K$51) -> 0 | L52: =SUBTOTAL(109,'Jun-22'!$L$46:$L$51) -> 0
...

Sheet Jul-22
B1: LIBRO IVA COMPRAS | G1: ='Abr-22'!G1:M1 -> CORITEC S.R.L. | N1: =EDATE('Abr-22'!N1,3) -> 44743
B3: TOTAL COMPRAS | G3: TOTAL CREDITO FISCAL | J3: TOTAL VENTAS NETAS | M3: TOTAL DEBITO FISCAL | P3: RESULTADO
