Workbook

Sheet Lista_CUIT
A1: CUIT | B1: RAZON SOCIAL | C1: Tipo de Gasto | D1: PROVINCIA
A2: =21779325 -> 21779325 | B2: BERAN Claudia Beatriz | C2: Gastos mantenimiento | G2: Mercaderia
A3: =12999779 -> 12999779 | B3: CORBALAN, MAFALDA ISABEL | G3: Servicios Gas, Luz, etc.
A4: =475785 -> 475785 | B4: GARCIA Ricardo Enrique | G4: Gastos catering
A5: =32052462 -> 32052462 | B5: Graells Luis Miguel | G5: Combustibe
A6: 33709585229 | B6: GOOGLE ARGENTINA S.R.L. | C6: Gastos Publicidad y Propaganda | G6: Gastos Varios
A7: 30526874249 | B7: FRAVEGA S A C I E I | C7: Gastos comercializacion | G7: Gastos seguridad
A8: 30716711621 | B8: TC TIENDAS AR S.R.L. | C8: insumos | D8: BUENOS AIRES | G8: Librería
A9: 30713550201 | B9: WAIKI S.A. | G9: Gastos mantenimiento
A10: 20357182914 | B10: GAIGA RENZO MIGUEL | G10: Gastos comercializacion
A11: 30715380567 | B11: SENS GROUP SRL | G11: Alquiler
A12: 33716435909 | B12: F&R S.A.S. | G12: Honorarios contables
A13: 30715313967 | B13: JD SOURCING S.R.L | G13: Gastos administrativos
A14: 27240934499 | B14: VITTOR LORENA MARCELA | G14: Seguro
A15: 20367341808 | B15: FEIDAS FERNANDO EMILIANO | G15: Extracto
A16: 30717477681 | B16: GRUPO FAM SA | G16: Flete
A17: 30717973166 | B17: STM ESTILO S.R.L | G17: Honorarios Legales
A18: 30717170594 | B18: INDUSTRIA4 S.R.L. | G18: Insumo
A19: 30716778041 | B19: PERROS Y GATOS FOOD S.A.S. | G19: Muebles y Utiles
A20: 20284212488 | B20: BARLETTA MAXIMILIANO SEBASTIAN | G20: Otros
... A23: 20252582704 | B23: GARCIA VAUTRIN ANDRES ALBERTO | G23: Gastos Publicidad y Propaganda
A24: 20391525227 | B24: BARISCI MATIAS NICOLAS
A25: 30715380567 | B25: SENS GROUP SRL
A26: 20367341808 | B26: FEIDAS FERNANDO EMILIANO
A27: 33716435909 | B27: F&R S.A.S.
A28: 30708026200 | B28: BORGES BUENOS AIRES SRL
A29: 30707040900 | B29: TODOVISION S.A
A30: 23380288079 | B30: CASTROMAN AGUSTIN | C30: Diseño Grafico
A31: 27341104845 | B31: BOSSI MARIA PAULA | C31: HON. ADMINISTRATIVOS
A32: 20300985158 | B32: GONZALEZ NESTOR RICARDO | C32: Diseño Grafico
A33: 33712058019 | B33: FLEET KYAN SRL
A34: 20369492528 | B34: GRIMALDI NICOLAS
A35: 20202853391 | B35: MATTEO DANIEL ERNESTO
A36: 27165844748 | B36: DENATALE MARCELA BEATRIZ
A37: 30716797437 | B37: PEISER
A38: 20287305460 | B38: LANDI GERONIMO
A39: 30710008635 | B39: CENTRO DE ENTRENAMIENTO DE MANEJO S.A.
A40: 30716914077 | B40: BACANES
A41: 20279415656 | B41: CECCO ALVARO GONZALO
A42: 30681452423 | B42: E S B A LUGANO S A
...

Sheet Ene-24
B1: LIBRO IVA COMPRAS | G1: RABLEB SRL | N1: 45292
B3: TOTAL COMPRAS | G3: TOTAL CREDITO FISCAL | J3: TOTAL VENTAS NETAS | M3: TOTAL DEBITO FISCAL | P3: RESULTADO
B4: =SUM(compras_mes1[[#Totals],[NETO GRAVADO]])+extracto_banco_mes1[[#Totals],[NETO]] -> 723376.81 | G4: =compras_mes1[[#Totals],[IVA 21 %]]+compras_mes1[[#Totals],[IVA 27%]]+compras_mes1[[#Totals],[IVA 10,5%]]+extracto_banco_mes1[[#Totals],[IVA 21%]]+extracto_banco_mes1[[#Totals],[IVA 10,5%]] -> 151909.13 | J4: =venta_a_mes1[[#Totals],[IMPORTE NETO]]+ventas_b_mes1[[#Totals],[IMPORTE NETO]] -> 1382498.1 | M4: =venta_a_mes1[[#Totals],[IVA 21%]]+venta_a_mes1[[#Totals],[IVA 10,5%]]+ventas_b_mes1[[#Totals],[IVA 21%]]+ventas_b_mes1[[#Totals],[IVA 10,5%]] -> 290324.6 | P4: =G4-M4 -> -138415.47
B8: FECHA | C8: TIPO | D8: PTO VTA | E8: NRO. CPTE | F8: CUIT | G8: RAZON SOCIAL | H8: NETO GRAVADO | I8: IVA 21 % | J8: IVA 27% | K8: IVA 10,5% | L8: PERC. IVA | M8: PERC IIBB BS AS | N8: PERC. IIBB CABA | O8: Otros / No Grav. | P8: TOTAL | Q8: Tipo de Gasto | R8: Provincia
B9: 45322 | C9: 1 | D9: 11 | E9: 941540 | F9: 33709585229 | G9: =IFERROR(IF(compras_mes1[[#This Row],[CUIT]]="","-",VLOOKUP(compras_mes1[[#This Row],[CUIT]],Lista_CUIT[#All],2,0)),"CUIT NO CARGADO") -> GOOGLE ARGENTINA S.R.L. | H9: 73116.08 | I9: =IF(compras_mes1[[#This Row],[NETO GRAVADO]]="","",compras_mes1[[#This Row],[NETO GRAVADO]]*0.21) -> 15354.377 | L9: 2193.48 | N9: 1096.74 | P9: =SUM(compras_mes1[[#This Row],[NETO GRAVADO]:[Otros / No Grav.]]) -> 91760.677 | Q9: =IFERROR(IF(compras_mes1[[#This Row],[CUIT]]="","-",VLOOKUP(compras_mes1[[#This Row],[CUIT]],Lista_CUIT[#All],3,0)),"CUIT NO CARGADO") -> Gastos Publicidad y Propaganda | R9: =IFERROR(IF(compras_mes1[[#This Row],[CUIT]]="","-",VLOOKUP(compras_mes1[[#This Row],[CUIT]],Lista_CUIT[#All],4,0)),"CUIT NO CARGADO") -> 0
B10: 45322 | C10: 1 | D10: 11 | E10: 937071 | F10: 33709585229 | G10: =IFERROR(IF(compras_mes1[[#This Row],[CUIT]]="","-",VLOOKUP(compras_mes1[[#This Row],[CUIT]],Lista_CUIT[#All],2,0)),"CUIT NO CARGADO") -> GOOGLE ARGENTINA S.R.L. | H10: 31817.43 | I10: =IF(compras_mes1[[#This Row],[NETO GRAVADO]]="","",compras_mes1[[#This Row],[NETO GRAVADO]]*0.21) -> 6681.6603 | L10: 954.52 | N10: 477.26 | P10: =SUM(compras_mes1[[#This Row],[NETO GRAVADO]:[Otros / No Grav.]]) -> 39930.87 | Q10: =IFERROR(IF(compras_mes1[[#This Row],[CUIT]]="","-",VLOOKUP(compras_mes1[[#This Row],[CUIT]],Lista_CUIT[#All],3,0)),"CUIT NO CARGADO") -> Gastos Publicidad y Propaganda | R10: =IFERROR(IF(compras_mes1[[#This Row],[CUIT]]="","-",VLOOKUP(compras_mes1[[#This Row],[CUIT]],Lista_CUIT[#All],4,0)),"CUIT NO CARGADO") -> 0
B11: 45322 | C11: 1 | D11: 11 | E11: 935773 | F11: 33709585229 | G11: =IFERROR(IF(compras_mes1[[#This Row],[CUIT]]="","-",VLOOKUP(compras_mes1[[#This Row],[CUIT]],Lista_CUIT[#All],2,0)),"CUIT NO CARGADO") -> GOOGLE ARGENTINA S.R.L. | H11: 41418.76 | I11: =IF(compras_mes1[[#This Row],[NETO GRAVADO]]="","",compras_mes1[[#This Row],[NETO GRAVADO]]*0.21) -> 8697.9396 | L11: 1242.56 | N11: 621.28 | P11: =SUM(compras_mes1[[#This Row],[NETO GRAVADO]:[Otros / No Grav.]]) -> 51980.54 | Q11: =IFERROR(IF(compras_mes1[[#This Row],[CUIT]]="","-",VLOOKUP(compras_mes1[[#This Row],[CUIT]],Lista_CUIT[#All],3,0)),"CUIT NO CARGADO") -> Gastos Publicidad y Propaganda | R11: =IFERROR(IF(compras_mes1[[#This Row],[CUIT]]="","-",VLOOKUP(compras_mes1[[#This Row],[CUIT]],Lista_CUIT[#All],4,0)),"CUIT NO CARGADO") -> 0
B12: 45322 | C12: 1 | D12: 11 | E12: 936068 | F12: 33709585229 | G12: =IFERROR(IF(compras_mes1[[#This Row],[CUIT]]="","-",VLOOKUP(compras_mes1[[#This Row],[CUIT]],Lista_CUIT[#All],2,0)),"CUIT NO CARGADO") -> GOOGLE ARGENTINA S.R.L. | H12: 477557.3 | I12: =IF(compras_mes1[[#This Row],[NETO GRAVADO]]="","",compras_mes1[[#This Row],[NETO GRAVADO]]*0.21) -> 100287.03 | L12: 14326.72 | N12: 7163.36 | P12: =SUM(compras_mes1[[#This Row],[NETO GRAVADO]:[Otros / No Grav.]]) -> 599334.41 | Q12: =IFERROR(IF(compras_mes1[[#This Row],[CUIT]]="","-",VLOOKUP(compras_mes1[[#This Row],[CUIT]],Lista_CUIT[#All],3,0)),"CUIT NO CARGADO") -> Gastos Publicidad y Propaganda | R12: =IFERROR(IF(compras_mes1[[#This Row],[CUIT]]="","-",VLOOKUP(compras_mes1[[#This Row],[CUIT]],Lista_CUIT[#All],4,0)),"CUIT NO CARGADO") -> 0
B13: 45322 | C13: 1 | D13: 11 | E13: 932631 | F13: 33709585229 | G13: =IFERROR(IF(compras_mes1[[#This Row],[CUIT]]="","-",VLOOKUP(compras_mes1[[#This Row],[CUIT]],Lista_CUIT[#All],2,0)),"CUIT NO CARGADO") -> GOOGLE ARGENTINA S.R.L. | H13: 30522.81 | I13: =IF(compras_mes1[[#This Row],[NETO GRAVADO]]="","",compras_mes1[[#This Row],[NETO GRAVADO]]*0.21) -> 6409.7901 | L13: 915.68 | N13: 457.84 | P13: =SUM(compras_mes1[[#This Row],[NETO GRAVADO]:[Otros / No Grav.]]) -> 38306.12 | Q13: =IFERROR(IF(compras_mes1[[#This Row],[CUIT]]="","-",VLOOKUP(compras_mes1[[#This Row],[CUIT]],Lista_CUIT[#All],3,0)),"CUIT NO CARGADO") -> Gastos Publicidad y Propaganda | R13: =IFERROR(IF(compras_mes1[[#This Row],[CUIT]]="","-",VLOOKUP(compras_mes1[[#This Row],[CUIT]],Lista_CUIT[#All],4,0)),"CUIT NO CARGADO") -> 0
B14: 45322 | C14: 1 | D14: 11 | E14: 931692 | F14: 33709585229 | G14: =IFERROR(IF(compras_mes1[[#This Row],[CUIT]]="","-",VLOOKUP(compras_mes1[[#This Row],[CUIT]],Lista_CUIT[#All],2,0)),"CUIT NO CARGADO") -> GOOGLE ARGENTINA S.R.L. | H14: 68993.02 | I14: =IF(compras_mes1[[#This Row],[NETO GRAVADO]]="","",compras_mes1[[#This Row],[NETO GRAVADO]]*0.21) -> 14488.534 | L14: 2069.79 | N14: 1034.9 | P14: =SUM(compras_mes1[[#This Row],[NETO GRAVADO]:[Otros / No Grav.]]) -> 86586.244 | Q14: =IFERROR(IF(compras_mes1[[#This Row],[CUIT]]="","-",VLOOKUP(compras_mes1[[#This Row],[CUIT]],Lista_CUIT[#All],3,0)),"CUIT NO CARGADO") -> Gastos Publicidad y Propaganda | R14: =IFERROR(IF(compras_mes1[[#This Row],[CUIT]]="","-",VLOOKUP(compras_mes1[[#This Row],[CUIT]],Lista_CUIT[#All],4,0)),"CUIT NO CARGADO") -> 0
B15: 45322 | C15: 3 | D15: 11 | E15: 691643 | F15: 33709585229 | G15: =IFERROR(IF(compras_mes1[[#This Row],[CUIT]]="","-",VLOOKUP(compras_mes1[[#This Row],[CUIT]],Lista_CUIT[#All],2,0)),"CUIT NO CARGADO") -> GOOGLE ARGENTINA S.R.L. | H15: -48.59 | I15: =IF(compras_mes1[[#This Row],[NETO GRAVADO]]="","",compras_mes1[[#This Row],[NETO GRAVADO]]*0.21) -> -10.2039 | P15: =SUM(compras_mes1[[#This Row],[NETO GRAVADO]:[Otros / No Grav.]]) -> -58.7939 | Q15: =IFERROR(IF(compras_mes1[[#This Row],[CUIT]]="","-",VLOOKUP(compras_mes1[[#This Row],[CUIT]],Lista_CUIT[#All],3,0)),"CUIT NO CARGADO") -> Gastos Publicidad y Propaganda | R15: =IFERROR(IF(compras_mes1[[#This Row],[CUIT]]="","-",VLOOKUP(compras_mes1[[#This Row],[CUIT]],Lista_CUIT[#All],4,0)),"CUIT NO CARGADO") -> 0
B16: 45322 | C16: 3 | D16: 11 | E16: 689632 | F16: 33709585229 | G16: =IFERROR(IF(compras_mes1[[#This Row],[CUIT]]="","-",VLOOKUP(compras_mes1[[#This Row],[CUIT]],Lista_CUIT[#All],2,0)),"CUIT NO CARGADO") -> GOOGLE ARGENTINA S.R.L. | H16: 0 | I16: =IF(compras_mes1[[#This Row],[NETO GRAVADO]]="","",compras_mes1[[#This Row],[NETO GRAVADO]]*0.21) -> 0 | P16: =SUM(compras_mes1[[#This Row],[NETO GRAVADO]:[Otros / No Grav.]]) -> 0 | Q16: =IFERROR(IF(compras_mes1[[#This Row],[CUIT]]="","-",VLOOKUP(compras_mes1[[#This Row],[CUIT]],Lista_CUIT[#All],3,0)),"CUIT NO CARGADO") -> Gastos Publicidad y Propaganda | R16: =IFERROR(IF(compras_mes1[[#This Row],[CUIT]]="","-",VLOOKUP(compras_mes1[[#This Row],[CUIT]],Lista_CUIT[#All],4,0)),"CUIT NO CARGADO") -> 0
G17: =IFERROR(IF(compras_mes1[[#This Row],[CUIT]]="","-",VLOOKUP(compras_mes1[[#This Row],[CUIT]],Lista_CUIT[#All],2,0)),"CUIT NO CARGADO") -> - | I17: =IF(compras_mes1[[#This Row],[NETO GRAVADO]]="","",compras_mes1[[#This Row],[NETO GRAVADO]]*0.21) | P17: =SUM(compras_mes1[[#This Row],[NETO GRAVADO]:[Otros / No Grav.]]) -> 0 | Q17: =IFERROR(IF(compras_mes1[[#This Row],[CUIT]]="","-",VLOOKUP(compras_mes1[[#This Row],[CUIT]],Lista_CUIT[#All],3,0)),"CUIT NO CARGADO") -> - | R17: =IFERROR(IF(compras_mes1[[#This Row],[CUIT]]="","-",VLOOKUP(compras_mes1[[#This Row],[CUIT]],Lista_CUIT[#All],4,0)),"CUIT NO CARGADO") -> -
G18: =IFERROR(IF(compras_mes1[[#This Row],[CUIT]]="","-",VLOOKUP(compras_mes1[[#This Row],[CUIT]],Lista_CUIT[#All],2,0)),"CUIT NO CARGADO") -> - | I18: =IF(compras_mes1[[#This Row],[NETO GRAVADO]]="","",compras_mes1[[#This Row],[NETO GRAVADO]]*0.21) | P18: =SUM(compras_mes1[[#This Row],[NETO GRAVADO]:[Otros / No Grav.]]) -> 0 | Q18: =IFERROR(IF(compras_mes1[[#This Row],[CUIT]]="","-",VLOOKUP(compras_mes1[[#This Row],[CUIT]],Lista_CUIT[#All],3,0)),"CUIT NO CARGADO") -> - | R18: =IFERROR(IF(compras_mes1[[#This Row],[CUIT]]="","-",VLOOKUP(compras_mes1[[#This Row],[CUIT]],Lista_CUIT[#All],4,0)),"CUIT NO CARGADO") -> -
B19: Total | H19: =SUBTOTAL(109,compras_mes1[NETO GRAVADO]) -> 723376.81 | I19: =SUBTOTAL(109,compras_mes1[IVA 21 %]) -> 151909.13 | J19: =SUBTOTAL(109,compras_mes1[IVA 27%]) -> 0 | K19: =SUBTOTAL(109,compras_mes1[IVA 10,5%]) -> 0 | L19: =SUBTOTAL(109,compras_mes1[PERC. IVA]) -> 21702.75 | M19: =SUBTOTAL(109,compras_mes1[PERC IIBB BS AS]) -> 0 | N19: =SUBTOTAL(109,compras_mes1[PERC. IIBB CABA]) -> 10851.38 | O19: =SUBTOTAL(109,compras_mes1[Otros / No Grav.]) -> 0 | P19: =SUBTOTAL(109,compras_mes1[TOTAL]) -> 907840.07
D24: LIQUIDACION EXTRACTOS BANCARIOS-TARJETAS
D25: FECHA | E25: NRO CPTE | F25: BANCO | G25: NETO | H25: IVA 21% | I25: IVA 10,5% | J25: RET IIBB CABA | K25: PERC IVA | L25: PERC IIBB
D29: Total | G29: =SUBTOTAL(109,extracto_banco_mes1[NETO]) -> 0 | H29: =SUBTOTAL(109,extracto_banco_mes1[IVA 21%]) -> 0 | I29: =SUBTOTAL(109,extracto_banco_mes1[IVA 10,5%]) -> 0 | J29: =SUBTOTAL(109,extracto_banco_mes1[RET IIBB CABA]) -> 0 | K29: =SUBTOTAL(109,extracto_banco_mes1[PERC IVA]) -> 0 | L29: =SUBTOTAL(109,extracto_banco_mes1[PERC IIBB]) -> 0
D33: FACTURAS C
D34: FECHA | E34: PTO VTA | F34: FC Nº | G34: CUIT | H34: RAZON SOCIAL | I34: TOTAL | J34: TIPO DE GASTO | K34: Provincia
D35: 45293 | E35: 2 | F35: 698 | G35: 20400104094 | H35: =IFERROR(IF(factura_c_mes1[[#This Row],[CUIT]]="","-",VLOOKUP(factura_c_mes1[[#This Row],[CUIT]],Lista_CUIT[#All],2,0)),"CUIT NO CARGADO") -> BOTINDARI FEDERICO DANIEL | I35: 46500 | J35: =IFERROR(IF(factura_c_mes1[[#This Row],[CUIT]]="","-",VLOOKUP(factura_c_mes1[[#This Row],[CUIT]],Lista_CUIT[#All],3,0)),"CUIT NO CARGADO") -> HONORARIOS CONTABLE | K35: =IFERROR(IF(factura_c_mes1[[#This Row],[CUIT]]="","-",VLOOKUP(factura_c_mes1[[#This Row],[CUIT]],Lista_CUIT[#All],4,0)),"CUIT NO CARGADO") -> 0
D36: 45294 | E36: 1 | F36: 299 | G36: 27386311000 | H36: =IFERROR(IF(factura_c_mes1[[#This Row],[CUIT]]="","-",VLOOKUP(factura_c_mes1[[#This Row],[CUIT]],Lista_CUIT[#All],2,0)),"CUIT NO CARGADO") -> OPANASIUK MACARENA ANTONELLA | I36: 500000 | J36: =IFERROR(IF(factura_c_mes1[[#This Row],[CUIT]]="","-",VLOOKUP(factura_c_mes1[[#This Row],[CUIT]],Lista_CUIT[#All],3,0)),"CUIT NO CARGADO") -> Honorarios Profesionales | K36: =IFERROR(IF(factura_c_mes1[[#This Row],[CUIT]]="","-",VLOOKUP(factura_c_mes1[[#This Row],[CUIT]],Lista_CUIT[#All],4,0)),"CUIT NO CARGADO") -> 0
H37: =IFERROR(IF(factura_c_mes1[[#This Row],[CUIT]]="","-",VLOOKUP(factura_c_mes1[[#This Row],[CUIT]],Lista_CUIT[#All],2,0)),"CUIT NO CARGADO") -> - | J37: =IFERROR(IF(factura_c_mes1[[#This Row],[CUIT]]="","-",VLOOKUP(factura_c_mes1[[#This Row],[CUIT]],Lista_CUIT[#All],3,0)),"CUIT NO CARGADO") -> - | K37: =IFERROR(IF(factura_c_mes1[[#This Row],[CUIT]]="","-",VLOOKUP(factura_c_mes1[[#This Row],[CUIT]],Lista_CUIT[#All],4,0)),"CUIT NO CARGADO") -> -
D38: Total | I38: =SUBTOTAL(109,factura_c_mes1[TOTAL]) -> 546500
B44: LIBRO IVA VENTAS | K44: =N1 -> 45292
B46: VENTAS "A"
B47: FECHA | C47: TIPO | D47: PTO VENTA | E47: Nº FACTURA | F47: CUIT | G47: RAZON SOCIAL | H47: IMPORTE NETO | I47: IVA 21% | J47: IVA 10,5% | K47: EXENTO | L47: TOTAL | M47: Provincia
B48: 45293 | C48: 1 | D48: 2 | E48: 6 | F48: 30715380567 | G48: =IFERROR(IF(venta_a_mes1[[#This Row],[CUIT]]="","-",VLOOKUP(venta_a_mes1[[#This Row],[CUIT]],Lista_CUIT[#All],2,0)),"CUIT NO CARGADO") -> SENS GROUP SRL | H48: 184981.05 | I48: =venta_a_mes1[[#This Row],[IMPORTE NETO]]*0.21 -> 38846.02 | L48: =SUM(venta_a_mes1[[#This Row],[IMPORTE NETO]:[EXENTO]]) -> 223827.07
B49: 45293 | C49: 1 | D49: 1 | E49: 107 | F49: 30717973166 | G49: =IFERROR(IF(venta_a_mes1[[#This Row],[CUIT]]="","-",VLOOKUP(venta_a_mes1[[#This Row],[CUIT]],Lista_CUIT[#All],2,0)),"CUIT NO CARGADO") -> STM ESTILO S.R.L | H49: 37685.95 | I49: =venta_a_mes1[[#This Row],[IMPORTE NETO]]*0.21 -> 7914.0495 | L49: =SUM(venta_a_mes1[[#This Row],[IMPORTE NETO]:[EXENTO]]) -> 45599.999
B50: 45293 | C50: 1 | D50: 1 | E50: 105 | F50: 30717170594 | G50: =IFERROR(IF(venta_a_mes1[[#This Row],[CUIT]]="","-",VLOOKUP(venta_a_mes1[[#This Row],[CUIT]],Lista_CUIT[#All],2,0)),"CUIT NO CARGADO") -> INDUSTRIA4 S.R.L. | H50: 75371.9 | I50: =venta_a_mes1[[#This Row],[IMPORTE NETO]]*0.21 -> 15828.099 | L50: =SUM(venta_a_mes1[[#This Row],[IMPORTE NETO]:[EXENTO]]) -> 91199.999
B51: 45293 | C51: 1 | D51: 1 | E51: 111 | F51: 20279415656 | G51: =IFERROR(IF(venta_a_mes1[[#This Row],[CUIT]]="","-",VLOOKUP(venta_a_mes1[[#This Row],[CUIT]],Lista_CUIT[#All],2,0)),"CUIT NO CARGADO") -> CECCO ALVARO GONZALO | H51: 75371.9 | I51: =venta_a_mes1[[#This Row],[IMPORTE NETO]]*0.21 -> 15828.099 | L51: =SUM(venta_a_mes1[[#This Row],[IMPORTE NETO]:[EXENTO]]) -> 91199.999
B52: 45293 | C52: 1 | D52: 1 | E52: 110 | F52: 20287305460 | G52: =IFERROR(IF(venta_a_mes1[[#This Row],[CUIT]]="","-",VLOOKUP(venta_a_mes1[[#This Row],[CUIT]],Lista_CUIT[#All],2,0)),"CUIT NO CARGADO") -> LANDI GERONIMO | H52: 37685.95 | I52: =venta_a_mes1[[#This Row],[IMPORTE NETO]]*0.21 -> 7914.0495 | L52: =SUM(venta_a_mes1[[#This Row],[IMPORTE NETO]:[EXENTO]]) -> 45599.999
B53: 45293 | C53: 1 | D53: 1 | E53: 104 | F53: 20284212488 | G53: =IFERROR(IF(venta_a_mes1[[#This Row],[CUIT]]="","-",VLOOKUP(venta_a_mes1[[#This Row],[CUIT]],Lista_CUIT[#All],2,0)),"CUIT NO CARGADO") -> BARLETTA MAXIMILIANO SEBASTIAN | H53: 37685.95 | I53: =venta_a_mes1[[#This Row],[IMPORTE NETO]]*0.21 -> 7914.0495 | L53: =SUM(venta_a_mes1[[#This Row],[IMPORTE NETO]:[EXENTO]]) -> 45599.999
B54: 45293 | C54: 1 | D54: 1 | E54: 115 | F54: 30717465101 | G54: =IFERROR(IF(venta_a_mes1[[#This Row],[CUIT]]="","-",VLOOKUP(venta_a_mes1[[#This Row],[CUIT]],Lista_CUIT[#All],2,0)),"CUIT NO CARGADO") -> EMPRENDIMIENTOS SHOPGLASS S. R. L. | H54: 37685.95 | I54: =venta_a_mes1[[#This Row],[IMPORTE NETO]]*0.21 -> 7914.0495 | L54: =SUM(venta_a_mes1[[#This Row],[IMPORTE NETO]:[EXENTO]]) -> 45599.999
B55: 45293 | C55: 1 | D55: 1 | E55: 106 | F55: 30717170594 | G55: =IFERROR(IF(venta_a_mes1[[#This Row],[CUIT]]="","-",VLOOKUP(venta_a_mes1[[#This Row],[CUIT]],Lista_CUIT[#All],2,0)),"CUIT NO CARGADO") -> INDUSTRIA4 S.R.L. | H55: 37685.95 | I55: =venta_a_mes1[[#This Row],[IMPORTE NETO]]*0.21 -> 7914.0495 | L55: =SUM(venta_a_mes1[[#This Row],[IMPORTE NETO]:[EXENTO]]) -> 45599.999
B56: 45293 | C56: 1 | D56: 1 | E56: 114 | F56: 30717969061 | G56: =IFERROR(IF(venta_a_mes1[[#This Row],[CUIT]]="","-",VLOOKUP(venta_a_mes1[[#This Row],[CUIT]],Lista_CUIT[#All],2,0)),"CUIT NO CARGADO") -> FABIO Y RAUL ROSSO S.A.S. | H56: 37685.95 | I56: =venta_a_mes1[[#This Row],[IMPORTE NETO]]*0.21 -> 7914.0495 | L56: =SUM(venta_a_mes1[[#This Row],[IMPORTE NETO]:[EXENTO]]) -> 45599.999
B57: 45293 | C57: 1 | D57: 1 | E57: 103 | F57: 30717477681 | G57: =IFERROR(IF(venta_a_mes1[[#This Row],[CUIT]]="","-",VLOOKUP(venta_a_mes1[[#This Row],[CUIT]],Lista_CUIT[#All],2,0)),"CUIT NO CARGADO") -> GRUPO FAM SA | H57: 52479.33 | I57: =venta_a_mes1[[#This Row],[IMPORTE NETO]]*0.21 -> 11020.659 | L57: =SUM(venta_a_mes1[[#This Row],[IMPORTE NETO]:[EXENTO]]) -> 63499.989
B58: 45293 | C58: 1 | D58: 1 | E58: 113 | F58: 30715941763 | G58: =IFERROR(IF(venta_a_mes1[[#This Row],[CUIT]]="","-",VLOOKUP(venta_a_mes1[[#This Row],[CUIT]],Lista_CUIT[#All],2,0)),"CUIT NO CARGADO") -> TOURMALHYN S.R.L. | H58: 20661.14 | I58: =venta_a_mes1[[#This Row],[IMPORTE NETO]]*0.21 -> 4338.8394 | L58: =SUM(venta_a_mes1[[#This Row],[IMPORTE NETO]:[EXENTO]]) -> 24999.979
B59: 45293 | C59: 1 | D59: 1 | E59: 109 | F59: 20252582704 | G59: =IFERROR(IF(venta_a_mes1[[#This Row],[CUIT]]="","-",VLOOKUP(venta_a_mes1[[#This Row],[CUIT]],Lista_CUIT[#All],2,0)),"CUIT NO CARGADO") -> GARCIA VAUTRIN ANDRES ALBERTO | H59: 75371.9 | I59: =venta_a_mes1[[#This Row],[IMPORTE NETO]]*0.21 -> 15828.099 | L59: =SUM(venta_a_mes1[[#This Row],[IMPORTE NETO]:[EXENTO]]) -> 91199.999
... B68: 45302 | C68: 3 | D68: 2 | E68: 1 | F68: 30715380567 | G68: =IFERROR(IF(venta_a_mes1[[#This Row],[CUIT]]="","-",VLOOKUP(venta_a_mes1[[#This Row],[CUIT]],Lista_CUIT[#All],2,0)),"CUIT NO CARGADO") -> SENS GROUP SRL | H68: -184981.05 | I68: =venta_a_mes1[[#This Row],[IMPORTE NETO]]*0.21 -> -38846.02 | L68: =SUM(venta_a_mes1[[#This Row],[IMPORTE NETO]:[EXENTO]]) -> -223827.07
...

Sheet Feb-24
B1: LIBRO IVA COMPRAS | G1: ='Ene-24'!G1:M1 -> RABLEB SRL | N1: =EDATE('Ene-24'!N1,1) -> 45323
B3: TOTAL COMPRAS | G3: TOTAL CREDITO FISCAL | J3: TOTAL VENTAS NETAS | M3: TOTAL DEBITO FISCAL | P3: RESULTADO
B4: =SUM(compras_mes2[[#Totals],[NETO GRAVADO]])+extracto_banco_mes2[[#Totals],[NETO]] -> 908825.01 | G4: =compras_mes2[[#Totals],[IVA 21 %]]+compras_mes2[[#Totals],[IVA 27%]]+compras_mes2[[#Totals],[IVA 10,5%]]+extracto_banco_mes2[[#Totals],[IVA 21%]]+extracto_banco_mes2[[#Totals],[IVA 10,5%]] -> 190853.25 | J4: =venta_a_mes2[[#Totals],[IMPORTE NETO]]+ventas_b_mes2[[#Totals],[IMPORTE NETO]] -> 1292484.6 | M4: =venta_a_mes2[[#Totals],[IVA 21%]]+venta_a_mes2[[#Totals],[IVA 10,5%]]+ventas_b_mes2[[#Totals],[IVA 21%]]+ventas_b_mes2[[#Totals],[IVA 10,5%]] -> 271421.77 | P4: =G4-M4 -> -80568.517
B8: FECHA | C8: TIPO | D8: PTO VTA | E8: NRO. CPTE | F8: CUIT | G8: RAZON SOCIAL | H8: NETO GRAVADO | I8: IVA 21 % | J8: IVA 27% | K8: IVA 10,5% | L8: PERC. IVA | M8: PERC IIBB BS AS | N8: PERC. IIBB CABA | O8: Otros / No Grav. | P8: TOTAL | Q8: Tipo de Gasto | R8: Provincia
B9: 29/02/2024 | C9: 1 | D9: 11 | E9: 945335 | F9: 33709585229 | G9: =IFERROR(IF(compras_mes2[[#This Row],[CUIT]]="","-",VLOOKUP(compras_mes2[[#This Row],[CUIT]],Lista_CUIT[#All],2,0)),"CUIT NO CARGADO") -> GOOGLE ARGENTINA S.R.L. | H9: 30120.52 | I9: =compras_mes2[[#This Row],[NETO GRAVADO]]*0.21 -> 6325.3092 | N9: 451.81 | O9: 903.62 | P9: =SUM(compras_mes2[[#This Row],[NETO GRAVADO]:[Otros / No Grav.]]) -> 37801.259 | Q9: =IFERROR(IF(compras_mes2[[#This Row],[CUIT]]="","-",VLOOKUP(compras_mes2[[#This Row],[CUIT]],Lista_CUIT[#All],3,0)),"CUIT NO CARGADO") -> Gastos Publicidad y Propaganda | R9: =IFERROR(IF(compras_mes2[[#This Row],[CUIT]]="","-",VLOOKUP(compras_mes2[[#This Row],[CUIT]],Lista_CUIT[#All],4,0)),"CUIT NO CARGADO") -> 0
B10: 29/02/2024 | C10: 1 | D10: 11 | E10: 945919 | F10: 33709585229 | G10: =IFERROR(IF(compras_mes2[[#This Row],[CUIT]]="","-",VLOOKUP(compras_mes2[[#This Row],[CUIT]],Lista_CUIT[#All],2,0)),"CUIT NO CARGADO") -> GOOGLE ARGENTINA S.R.L. | H10: 428219.51 | I10: =compras_mes2[[#This Row],[NETO GRAVADO]]*0.21 -> 89926.097 | N10: 6423.29 | O10: 12846.59 | P10: =SUM(compras_mes2[[#This Row],[NETO GRAVADO]:[Otros / No Grav.]]) -> 537415.49 | Q10: =IFERROR(IF(compras_mes2[[#This Row],[CUIT]]="","-",VLOOKUP(compras_mes2[[#This Row],[CUIT]],Lista_CUIT[#All],3,0)),"CUIT NO CARGADO") -> Gastos Publicidad y Propaganda | R10: =IFERROR(IF(compras_mes2[[#This Row],[CUIT]]="","-",VLOOKUP(compras_mes2[[#This Row],[CUIT]],Lista_CUIT[#All],4,0)),"CUIT NO CARGADO") -> 0
B11: 29/02/2024 | C11: 1 | D11: 11 | E11: 950110 | F11: 33709585229 | G11: =IFERROR(IF(compras_mes2[[#This Row],[CUIT]]="","-",VLOOKUP(compras_mes2[[#This Row],[CUIT]],Lista_CUIT[#All],2,0)),"CUIT NO CARGADO") -> GOOGLE ARGENTINA S.R.L. | H11: 34780.14 | I11: =compras_mes2[[#This Row],[NETO GRAVADO]]*0.21 -> 7303.8294 | N11: 521.7 | O11: 1043.4 | P11: =SUM(compras_mes2[[#This Row],[NETO GRAVADO]:[Otros / No Grav.]]) -> 43649.069 | Q11: =IFERROR(IF(compras_mes2[[#This Row],[CUIT]]="","-",VLOOKUP(compras_mes2[[#This Row],[CUIT]],Lista_CUIT[#All],3,0)),"CUIT NO CARGADO") -> Gastos Publicidad y Propaganda | R11: =IFERROR(IF(compras_mes2[[#This Row],[CUIT]]="","-",VLOOKUP(compras_mes2[[#This Row],[CUIT]],Lista_CUIT[#All],4,0)),"CUIT NO CARGADO") -> 0
B12: 29/02/2024 | C12: 1 | D12: 11 | E12: 950338 | F12: 33709585229 | G12: =IFERROR(IF(compras_mes2[[#This Row],[CUIT]]="","-",VLOOKUP(compras_mes2[[#This Row],[CUIT]],Lista_CUIT[#All],2,0)),"CUIT NO CARGADO") -> GOOGLE ARGENTINA S.R.L. | H12: 58023.31 | I12: =compras_mes2[[#This Row],[NETO GRAVADO]]*0.21 -> 12184.895 | N12: 870.35 | O12: 1740.7 | P12: =SUM(compras_mes2[[#This Row],[NETO GRAVADO]:[Otros / No Grav.]]) -> 72819.255 | Q12: =IFERROR(IF(compras_mes2[[#This Row],[CUIT]]="","-",VLOOKUP(compras_mes2[[#This Row],[CUIT]],Lista_CUIT[#All],3,0)),"CUIT NO CARGADO") -> Gastos Publicidad y Propaganda | R12: =IFERROR(IF(compras_mes2[[#This Row],[CUIT]]="","-",VLOOKUP(compras_mes2[[#This Row],[CUIT]],Lista_CUIT[#All],4,0)),"CUIT NO CARGADO") -> 0
B13: 29/02/2024 | C13: 1 | D13: 11 | E13: 951705 | F13: 33709585229 | G13: =IFERROR(IF(compras_mes2[[#This Row],[CUIT]]="","-",VLOOKUP(compras_mes2[[#This Row],[CUIT]],Lista_CUIT[#All],2,0)),"CUIT NO CARGADO") -> GOOGLE ARGENTINA S.R.L. | H13: 246532.43 | I13: =compras_mes2[[#This Row],[NETO GRAVADO]]*0.21 -> 51771.81 | N13: 3697.99 | O13: 7395.97 | P13: =SUM(compras_mes2[[#This Row],[NETO GRAVADO]:[Otros / No Grav.]]) -> 309398.2 | Q13: =IFERROR(IF(compras_mes2[[#This Row],[CUIT]]="","-",VLOOKUP(compras_mes2[[#This Row],[CUIT]],Lista_CUIT[#All],3,0)),"CUIT NO CARGADO") -> Gastos Publicidad y Propaganda | R13: =IFERROR(IF(compras_mes2[[#This Row],[CUIT]]="","-",VLOOKUP(compras_mes2[[#This Row],[CUIT]],Lista_CUIT[#All],4,0)),"CUIT NO CARGADO") -> 0
B14: 29/02/2024 | C14: 1 | D14: 11 | E14: 948578 | F14: 33709585229 | G14: =IFERROR(IF(compras_mes2[[#This Row],[CUIT]]="","-",VLOOKUP(compras_mes2[[#This Row],[CUIT]],Lista_CUIT[#All],2,0)),"CUIT NO CARGADO") -> GOOGLE ARGENTINA S.R.L. | H14: 61234.13 | I14: =compras_mes2[[#This Row],[NETO GRAVADO]]*0.21 -> 12859.167 | N14: 918.51 | O14: 1837.02 | P14: =SUM(compras_mes2[[#This Row],[NETO GRAVADO]:[Otros / No Grav.]]) -> 76848.827 | Q14: =IFERROR(IF(compras_mes2[[#This Row],[CUIT]]="","-",VLOOKUP(compras_mes2[[#This Row],[CUIT]],Lista_CUIT[#All],3,0)),"CUIT NO CARGADO") -> Gastos Publicidad y Propaganda | R14: =IFERROR(IF(compras_mes2[[#This Row],[CUIT]]="","-",VLOOKUP(compras_mes2[[#This Row],[CUIT]],Lista_CUIT[#All],4,0)),"CUIT NO CARGADO") -> 0
B15: 29/02/2024 | C15: 1 | D15: 11 | E15: 943854 | F15: 33709585229 | G15: =IFERROR(IF(compras_mes2[[#This Row],[CUIT]]="","-",VLOOKUP(compras_mes2[[#This Row],[CUIT]],Lista_CUIT[#All],2,0)),"CUIT NO CARGADO") -> GOOGLE ARGENTINA S.R.L. | H15: 18570.74 | I15: =compras_mes2[[#This Row],[NETO GRAVADO]]*0.21 -> 3899.8554 | N15: 557.12 | O15: 278.56 | P15: =SUM(compras_mes2[[#This Row],[NETO GRAVADO]:[Otros / No Grav.]]) -> 23306.275 | Q15: =IFERROR(IF(compras_mes2[[#This Row],[CUIT]]="","-",VLOOKUP(compras_mes2[[#This Row],[CUIT]],Lista_CUIT[#All],3,0)),"CUIT NO CARGADO") -> Gastos Publicidad y Propaganda | R15: =IFERROR(IF(compras_mes2[[#This Row],[CUIT]]="","-",VLOOKUP(compras_mes2[[#This Row],[CUIT]],Lista_CUIT[#All],4,0)),"CUIT NO CARGADO") -> 0
B16: 29/02/2024 | C16: 1 | D16: 11 | E16: 943049 | F16: 33709585229 | G16: =IFERROR(IF(compras_mes2[[#This Row],[CUIT]]="","-",VLOOKUP(compras_mes2[[#This Row],[CUIT]],Lista_CUIT[#All],2,0)),"CUIT NO CARGADO") -> GOOGLE ARGENTINA S.R.L. | H16: 31927.67 | I16: =compras_mes2[[#This Row],[NETO GRAVADO]]*0.21 -> 6704.8107 | N16: 478.92 | O16: 957.83 | P16: =SUM(compras_mes2[[#This Row],[NETO GRAVADO]:[Otros / No Grav.]]) -> 40069.231 | Q16: =IFERROR(IF(compras_mes2[[#This Row],[CUIT]]="","-",VLOOKUP(compras_mes2[[#This Row],[CUIT]],Lista_CUIT[#All],3,0)),"CUIT NO CARGADO") -> Gastos Publicidad y Propaganda | R16: =IFERROR(IF(compras_mes2[[#This Row],[CUIT]]="","-",VLOOKUP(compras_mes2[[#This Row],[CUIT]],Lista_CUIT[#All],4,0)),"CUIT NO CARGADO") -> 0
B17: 29/02/2024 | C17: 3 | D17: 11 | E17: 698844 | F17: 33709585229 | G17: =IFERROR(IF(compras_mes2[[#This Row],[CUIT]]="","-",VLOOKUP(compras_mes2[[#This Row],[CUIT]],Lista_CUIT[#All],2,0)),"CUIT NO CARGADO") -> GOOGLE ARGENTINA S.R.L. | H17: -583.44 | I17: =compras_mes2[[#This Row],[NETO GRAVADO]]*0.21 -> -122.5224 | N17: -8.75 | P17: =SUM(compras_mes2[[#This Row],[NETO GRAVADO]:[Otros / No Grav.]]) -> -714.7124 | Q17: =IFERROR(IF(compras_mes2[[#This Row],[CUIT]]="","-",VLOOKUP(compras_mes2[[#This Row],[CUIT]],Lista_CUIT[#All],3,0)),"CUIT NO CARGADO") -> Gastos Publicidad y Propaganda | R17: =IFERROR(IF(compras_mes2[[#This Row],[CUIT]]="","-",VLOOKUP(compras_mes2[[#This Row],[CUIT]],Lista_CUIT[#All],4,0)),"CUIT NO CARGADO") -> 0
B18: Total | H18: =SUBTOTAL(109,compras_mes2[NETO GRAVADO]) -> 908825.01 | I18: =SUBTOTAL(109,compras_mes2[IVA 21 %]) -> 190853.25 | J18: =SUBTOTAL(109,compras_mes2[IVA 27%]) -> 0 | K18: =SUBTOTAL(109,compras_mes2[IVA 10,5%]) -> 0 | L18: =SUBTOTAL(109,compras_mes2[PERC. IVA]) -> 0 | M18: =SUBTOTAL(109,compras_mes2[PERC IIBB BS AS]) -> 0 | N18: =SUBTOTAL(109,compras_mes2[PERC. IIBB CABA]) -> 13910.94 | O18: =SUBTOTAL(109,compras_mes2[Otros / No Grav.]) -> 27003.69 | P18: =SUBTOTAL(109,compras_mes2[TOTAL]) -> 1140592.9
D23: LIQUIDACION EXTRACTOS BANCARIOS-TARJETAS
D24: FECHA | E24: NRO CPTE | F24: BANCO | G24: NETO | H24: IVA 21% | I24: IVA 10,5% | J24: RET IIBB CABA | K24: PERC IVA | L24: PERC IIBB
D28: Total | G28: =SUBTOTAL(109,extracto_banco_mes2[NETO]) -> 0 | H28: =SUBTOTAL(109,extracto_banco_mes2[IVA 21%]) -> 0 | I28: =SUBTOTAL(109,extracto_banco_mes2[IVA 10,5%]) -> 0 | J28: =SUBTOTAL(109,extracto_banco_mes2[RET IIBB CABA]) -> 0 | K28: =SUBTOTAL(109,extracto_banco_mes2[PERC IVA]) -> 0 | L28: =SUBTOTAL(109,extracto_banco_mes2[PERC IIBB]) -> 0
D32: FACTURAS C
D33: FECHA | E33: PTO VTA | F33: FC Nº | G33: CUIT | H33: RAZON SOCIAL | I33: TOTAL | J33: TIPO DE GASTO | K33: Provincia
D34: 05/02/2024 | E34: 2 | F34: 716 | G34: 20400104094 | H34: =IFERROR(IF(factura_c_mes2[[#This Row],[CUIT]]="","-",VLOOKUP(factura_c_mes2[[#This Row],[CUIT]],Lista_CUIT[#All],2,0)),"CUIT NO CARGADO") -> BOTINDARI FEDERICO DANIEL | I34: 46500 | J34: =IFERROR(IF(factura_c_mes2[[#This Row],[CUIT]]="","-",VLOOKUP(factura_c_mes2[[#This Row],[CUIT]],Lista_CUIT[#All],3,0)),"CUIT NO CARGADO") -> HONORARIOS CONTABLE | K34: =IFERROR(IF(factura_c_mes2[[#This Row],[CUIT]]="","-",VLOOKUP(factura_c_mes2[[#This Row],[CUIT]],Lista_CUIT[#All],4,0)),"CUIT NO CARGADO") -> 0
D35: 11/02/2024 | E35: 3 | F35: 401 | G35: 20178248201 | H35: =IFERROR(IF(factura_c_mes2[[#This Row],[CUIT]]="","-",VLOOKUP(factura_c_mes2[[#This Row],[CUIT]],Lista_CUIT[#All],2,0)),"CUIT NO CARGADO") -> FRANCISCO ADRIAN MARCELO | I35: 47500 | J35: =IFERROR(IF(factura_c_mes2[[#This Row],[CUIT]]="","-",VLOOKUP(factura_c_mes2[[#This Row],[CUIT]],Lista_CUIT[#All],3,0)),"CUIT NO CARGADO") -> 0 | K35: =IFERROR(IF(factura_c_mes2[[#This Row],[CUIT]]="","-",VLOOKUP(factura_c_mes2[[#This Row],[CUIT]],Lista_CUIT[#All],4,0)),"CUIT NO CARGADO") -> 0
H36: =IFERROR(IF(factura_c_mes2[[#This Row],[CUIT]]="","-",VLOOKUP(factura_c_mes2[[#This Row],[CUIT]],Lista_CUIT[#All],2,0)),"CUIT NO CARGADO") -> - | J36: =IFERROR(IF(factura_c_mes2[[#This Row],[CUIT]]="","-",VLOOKUP(factura_c_mes2[[#This Row],[CUIT]],Lista_CUIT[#All],3,0)),"CUIT NO CARGADO") -> - | K36: =IFERROR(IF(factura_c_mes2[[#This Row],[CUIT]]="","-",VLOOKUP(factura_c_mes2[[#This Row],[CUIT]],Lista_CUIT[#All],4,0)),"CUIT NO CARGADO") -> -
H37: =IFERROR(IF(factura_c_mes2[[#This Row],[CUIT]]="","-",VLOOKUP(factura_c_mes2[[#This Row],[CUIT]],Lista_CUIT[#All],2,0)),"CUIT NO CARGADO") -> - | J37: =IFERROR(IF(factura_c_mes2[[#This Row],[CUIT]]="","-",VLOOKUP(factura_c_mes2[[#This Row],[CUIT]],Lista_CUIT[#All],3,0)),"CUIT NO CARGADO") -> - | K37: =IFERROR(IF(factura_c_mes2[[#This Row],[CUIT]]="","-",VLOOKUP(factura_c_mes2[[#This Row],[CUIT]],Lista_CUIT[#All],4,0)),"CUIT NO CARGADO") -> -
D38: Total | I38: =SUBTOTAL(109,factura_c_mes2[TOTAL]) -> 94000
B44: LIBRO IVA VENTAS | K44: =N1 -> 45323
B46: VENTAS "A"
B47: FECHA | C47: TIPO | D47: PTO VENTA | E47: Nº FACTURA | F47: CUIT | G47: RAZON SOCIAL | H47: IMPORTE NETO | I47: IVA 21% | J47: IVA 10,5% | K47: EXENTO | L47: TOTAL | M47: Provincia
B48: 01/02/2024 | C48: 1 | D48: 1 | E48: 125 | F48: 20284212488 | G48: =IFERROR(IF(venta_a_mes2[[#This Row],[CUIT]]="","-",VLOOKUP(venta_a_mes2[[#This Row],[CUIT]],Lista_CUIT[#All],2,0)),"CUIT NO CARGADO") -> BARLETTA MAXIMILIANO SEBASTIAN | H48: 37685.95 | I48: =venta_a_mes2[[#This Row],[IMPORTE NETO]]*0.21 -> 7914.0495 | L48: =SUM(venta_a_mes2[[#This Row],[IMPORTE NETO]:[EXENTO]]) -> 45599.999
B49: 01/02/2024 | C49: 1 | D49: 1 | E49: 132 | F49: 20287305460 | G49: =IFERROR(IF(venta_a_mes2[[#This Row],[CUIT]]="","-",VLOOKUP(venta_a_mes2[[#This Row],[CUIT]],Lista_CUIT[#All],2,0)),"CUIT NO CARGADO") -> LANDI GERONIMO | H49: 37685.95 | I49: =venta_a_mes2[[#This Row],[IMPORTE NETO]]*0.21 -> 7914.0495 | L49: =SUM(venta_a_mes2[[#This Row],[IMPORTE NETO]:[EXENTO]]) -> 45599.999
B50: 01/02/2024 | C50: 1 | D50: 1 | E50: 138 | F50: 20132082198 | G50: =IFERROR(IF(venta_a_mes2[[#This Row],[CUIT]]="","-",VLOOKUP(venta_a_mes2[[#This Row],[CUIT]],Lista_CUIT[#All],2,0)),"CUIT NO CARGADO") -> FADIGA OSCAR ALBERTO | H50: 37685.95 | I50: =venta_a_mes2[[#This Row],[IMPORTE NETO]]*0.21 -> 7914.0495 | L50: =SUM(venta_a_mes2[[#This Row],[IMPORTE NETO]:[EXENTO]]) -> 45599.999
B51: 01/02/2024 | C51: 1 | D51: 1 | E51: 136 | F51: 30717969061 | G51: =IFERROR(IF(venta_a_mes2[[#This Row],[CUIT]]="","-",VLOOKUP(venta_a_mes2[[#This Row],[CUIT]],Lista_CUIT[#All],2,0)),"CUIT NO CARGADO") -> FABIO Y RAUL ROSSO S.A.S. | H51: 37685.95 | I51: =venta_a_mes2[[#This Row],[IMPORTE NETO]]*0.21 -> 7914.0495 | L51: =SUM(venta_a_mes2[[#This Row],[IMPORTE NETO]:[EXENTO]]) -> 45599.999
B52: 01/02/2024 | C52: 1 | D52: 1 | E52: 137 | F52: 30717465101 | G52: =IFERROR(IF(venta_a_mes2[[#This Row],[CUIT]]="","-",VLOOKUP(venta_a_mes2[[#This Row],[CUIT]],Lista_CUIT[#All],2,0)),"CUIT NO CARGADO") -> EMPRENDIMIENTOS SHOPGLASS S. R. L. | H52: 37685.95 | I52: =venta_a_mes2[[#This Row],[IMPORTE NETO]]*0.21 -> 7914.0495 | L52: =SUM(venta_a_mes2[[#This Row],[IMPORTE NETO]:[EXENTO]]) -> 45599.999
B53: 01/02/2024 | C53: 1 | D53: 1 | E53: 131 | F53: 20252582704 | G53: =IFERROR(IF(venta_a_mes2[[#This Row],[CUIT]]="","-",VLOOKUP(venta_a_mes2[[#This Row],[CUIT]],Lista_CUIT[#All],2,0)),"CUIT NO CARGADO") -> GARCIA VAUTRIN ANDRES ALBERTO | H53: 75371.9 | I53: =venta_a_mes2[[#This Row],[IMPORTE NETO]]*0.21 -> 15828.099 | L53: =SUM(venta_a_mes2[[#This Row],[IMPORTE NETO]:[EXENTO]]) -> 91199.999
B54: 01/02/2024 | C54: 1 | D54: 1 | E54: 124 | F54: 30717477681 | G54: =IFERROR(IF(venta_a_mes2[[#This Row],[CUIT]]="","-",VLOOKUP(venta_a_mes2[[#This Row],[CUIT]],Lista_CUIT[#All],2,0)),"CUIT NO CARGADO") -> GRUPO FAM SA | H54: 52479.33 | I54: =venta_a_mes2[[#This Row],[IMPORTE NETO]]*0.21 -> 11020.659 | L54: =SUM(venta_a_mes2[[#This Row],[IMPORTE NETO]:[EXENTO]]) -> 63499.989
B55: 01/02/2024 | C55: 1 | D55: 1 | E55: 123 | F55: 30716914077 | G55: =IFERROR(IF(venta_a_mes2[[#This Row],[CUIT]]="","-",VLOOKUP(venta_a_mes2[[#This Row],[CUIT]],Lista_CUIT[#All],2,0)),"CUIT NO CARGADO") -> BACANES | H55: 96694.24 | I55: =venta_a_mes2[[#This Row],[IMPORTE NETO]]*0.21 -> 20305.79 | L55: =SUM(venta_a_mes2[[#This Row],[IMPORTE NETO]:[EXENTO]]) -> 117000.03
B56: 01/02/2024 | C56: 1 | D56: 1 | E56: 127 | F56: 30717170594 | G56: =IFERROR(IF(venta_a_mes2[[#This Row],[CUIT]]="","-",VLOOKUP(venta_a_mes2[[#This Row],[CUIT]],Lista_CUIT[#All],2,0)),"CUIT NO CARGADO") -> INDUSTRIA4 S.R.L. | H56: 37685.95 | I56: =venta_a_mes2[[#This Row],[IMPORTE NETO]]*0.21 -> 7914.0495 | L56: =SUM(venta_a_mes2[[#This Row],[IMPORTE NETO]:[EXENTO]]) -> 45599.999
B57: 01/02/2024 | C57: 1 | D57: 1 | E57: 122 | F57: 20369499956 | G57: =IFERROR(IF(venta_a_mes2[[#This Row],[CUIT]]="","-",VLOOKUP(venta_a_mes2[[#This Row],[CUIT]],Lista_CUIT[#All],2,0)),"CUIT NO CARGADO") -> LAMARI FRANCO AGUSTIN | H57: 96694.24 | I57: =venta_a_mes2[[#This Row],[IMPORTE NETO]]*0.21 -> 20305.79 | L57: =SUM(venta_a_mes2[[#This Row],[IMPORTE NETO]:[EXENTO]]) -> 117000.03
B58: 01/02/2024 | C58: 1 | D58: 1 | E58: 135 | F58: 30715941763 | G58: =IFERROR(IF(venta_a_mes2[[#This Row],[CUIT]]="","-",VLOOKUP(venta_a_mes2[[#This Row],[CUIT]],Lista_CUIT[#All],2,0)),"CUIT NO CARGADO") -> TOURMALHYN S.R.L. | H58: 20661.14 | I58: =venta_a_mes2[[#This Row],[IMPORTE NETO]]*0.21 -> 4338.8394 | L58: =SUM(venta_a_mes2[[#This Row],[IMPORTE NETO]:[EXENTO]]) -> 24999.979
B59: 01/02/2024 | C59: 1 | D59: 1 | E59: 130 | F59: 27165844748 | G59: =IFERROR(IF(venta_a_mes2[[#This Row],[CUIT]]="","-",VLOOKUP(venta_a_mes2[[#This Row],[CUIT]],Lista_CUIT[#All],2,0)),"CUIT NO CARGADO") -> DENATALE MARCELA BEATRIZ | H59: 96694.24 | I59: =venta_a_mes2[[#This Row],[IMPORTE NETO]]*0.21 -> 20305.79 | L59: =SUM(venta_a_mes2[[#This Row],[IMPORTE NETO]:[EXENTO]]) -> 117000.03
... B66: 09/02/2024 | C66: 3 | D66: 1 | E66: 8 | F66: 30717170594 | G66: =IFERROR(IF(venta_a_mes2[[#This Row],[CUIT]]="","-",VLOOKUP(venta_a_mes2[[#This Row],[CUIT]],Lista_CUIT[#All],2,0)),"CUIT NO CARGADO") -> INDUSTRIA4 S.R.L. | H66: -37685.95 | I66: =venta_a_mes2[[#This Row],[IMPORTE NETO]]*0.21 -> -7914.0495 | L66: =SUM(venta_a_mes2[[#This Row],[IMPORTE NETO]:[EXENTO]]) -> -45599.999
...

Sheet Mar-24
B1: LIBRO IVA COMPRAS | G1: ='Ene-24'!G1:M1 -> RABLEB SRL | N1: =EDATE('Ene-24'!N1,2) -> 45352
B3: TOTAL COMPRAS | G3: TOTAL CREDITO FISCAL | J3: TOTAL VENTAS NETAS | M3: TOTAL DEBITO FISCAL | P3: RESULTADO
B4: =SUM(compras_mes3[[#Totals],[NETO GRAVADO]])+extracto_banco_mes3[[#Totals],[NETO]] -> 1081034.2 | G4: =compras_mes3[[#Totals],[IVA 21 %]]+compras_mes3[[#Totals],[IVA 27%]]+compras_mes3[[#Totals],[IVA 10,5%]]+extracto_banco_mes3[[#Totals],[IVA 21%]]+extracto_banco_mes3[[#Totals],[IVA 10,5%]] -> 227017.17 | J4: =venta_a_mes3[[#Totals],[IMPORTE NETO]]+ventas_b_mes3[[#Totals],[IMPORTE NETO]] -> 1876164.1 | M4: =venta_a_mes3[[#Totals],[IVA 21%]]+venta_a_mes3[[#Totals],[IVA 10,5%]]+ventas_b_mes3[[#Totals],[IVA 21%]]+ventas_b_mes3[[#Totals],[IVA 10,5%]] -> 393994.46 | P4: =G4-M4 -> -166977.29
B8: FECHA | C8: TIPO | D8: PTO VTA | E8: NRO. CPTE | F8: CUIT | G8: RAZON SOCIAL | H8: NETO GRAVADO | I8: IVA 21 % | J8: IVA 27% | K8: IVA 10,5% | L8: PERC. IVA | M8: PERC IIBB BS AS | N8: PERC. IIBB CABA | O8: Otros / No Grav. | P8: TOTAL | Q8: Tipo de Gasto | R8: Provincia
B9: 31/03/2024 | C9: 1 | D9: 11 | E9: 964700 | F9: 33709585229 | G9: =IFERROR(IF(compras_mes3[[#This Row],[CUIT]]="","-",VLOOKUP(compras_mes3[[#This Row],[CUIT]],Lista_CUIT[#All],2,0)),"CUIT NO CARGADO") -> GOOGLE ARGENTINA S.R.L. | H9: 28962.51 | I9: =IF(compras_mes3[[#This Row],[NETO GRAVADO]]="","",compras_mes3[[#This Row],[NETO GRAVADO]]*0.21) -> 6082.1271 | N9: 434.44 | O9: 868.88 | P9: =SUM(compras_mes3[[#This Row],[NETO GRAVADO]:[Otros / No Grav.]]) -> 36347.957 | Q9: =IFERROR(IF(compras_mes3[[#This Row],[CUIT]]="","-",VLOOKUP(compras_mes3[[#This Row],[CUIT]],Lista_CUIT[#All],3,0)),"CUIT NO CARGADO") -> Gastos Publicidad y Propaganda | R9: =IFERROR(IF(compras_mes3[[#This Row],[CUIT]]="","-",VLOOKUP(compras_mes3[[#This Row],[CUIT]],Lista_CUIT[#All],4,0)),"CUIT NO CARGADO") -> 0
B10: 31/03/2024 | C10: 1 | D10: 11 | E10: 957922 | F10: 33709585229 | G10: =IFERROR(IF(compras_mes3[[#This Row],[CUIT]]="","-",VLOOKUP(compras_mes3[[#This Row],[CUIT]],Lista_CUIT[#All],2,0)),"CUIT NO CARGADO") -> GOOGLE ARGENTINA S.R.L. | H10: 5316.32 | I10: =IF(compras_mes3[[#This Row],[NETO GRAVADO]]="","",compras_mes3[[#This Row],[NETO GRAVADO]]*0.21) -> 1116.4272 | N10: 79.74 | O10: 159.49 | P10: =SUM(compras_mes3[[#This Row],[NETO GRAVADO]:[Otros / No Grav.]]) -> 6671.9772 | Q10: =IFERROR(IF(compras_mes3[[#This Row],[CUIT]]="","-",VLOOKUP(compras_mes3[[#This Row],[CUIT]],Lista_CUIT[#All],3,0)),"CUIT NO CARGADO") -> Gastos Publicidad y Propaganda | R10: =IFERROR(IF(compras_mes3[[#This Row],[CUIT]]="","-",VLOOKUP(compras_mes3[[#This Row],[CUIT]],Lista_CUIT[#All],4,0)),"CUIT NO CARGADO") -> 0
B11: 31/03/2024 | C11: 1 | D11: 11 | E11: 959718 | F11: 33709585229 | G11: =IFERROR(IF(compras_mes3[[#This Row],[CUIT]]="","-",VLOOKUP(compras_mes3[[#This Row],[CUIT]],Lista_CUIT[#All],2,0)),"CUIT NO CARGADO") -> GOOGLE ARGENTINA S.R.L. | H11: 9324.4 | I11: =IF(compras_mes3[[#This Row],[NETO GRAVADO]]="","",compras_mes3[[#This Row],[NETO GRAVADO]]*0.21) -> 1958.124 | N11: 139.87 | O11: 279.73 | P11: =SUM(compras_mes3[[#This Row],[NETO GRAVADO]:[Otros / No Grav.]]) -> 11702.124 | Q11: =IFERROR(IF(compras_mes3[[#This Row],[CUIT]]="","-",VLOOKUP(compras_mes3[[#This Row],[CUIT]],Lista_CUIT[#All],3,0)),"CUIT NO CARGADO") -> Gastos Publicidad y Propaganda | R11: =IFERROR(IF(compras_mes3[[#This Row],[CUIT]]="","-",VLOOKUP(compras_mes3[[#This Row],[CUIT]],Lista_CUIT[#All],4,0)),"CUIT NO CARGADO") -> 0
B12: 31/03/2024 | C12: 1 | D12: 11 | E12: 960009 | F12: 33709585229 | G12: =IFERROR(IF(compras_mes3[[#This Row],[CUIT]]="","-",VLOOKUP(compras_mes3[[#This Row],[CUIT]],Lista_CUIT[#All],2,0)),"CUIT NO CARGADO") -> GOOGLE ARGENTINA S.R.L. | H12: 291853.48 | I12: =IF(compras_mes3[[#This Row],[NETO GRAVADO]]="","",compras_mes3[[#This Row],[NETO GRAVADO]]*0.21) -> 61289.231 | N12: 4377.8 | O12: 8755.6 | P12: =SUM(compras_mes3[[#This Row],[NETO GRAVADO]:[Otros / No Grav.]]) -> 366276.11 | Q12: =IFERROR(IF(compras_mes3[[#This Row],[CUIT]]="","-",VLOOKUP(compras_mes3[[#This Row],[CUIT]],Lista_CUIT[#All],3,0)),"CUIT NO CARGADO") -> Gastos Publicidad y Propaganda | R12: =IFERROR(IF(compras_mes3[[#This Row],[CUIT]]="","-",VLOOKUP(compras_mes3[[#This Row],[CUIT]],Lista_CUIT[#All],4,0)),"CUIT NO CARGADO") -> 0
B13: 31/03/2024 | C13: 1 | D13: 11 | E13: 960015 | F13: 33709585229 | G13: =IFERROR(IF(compras_mes3[[#This Row],[CUIT]]="","-",VLOOKUP(compras_mes3[[#This Row],[CUIT]],Lista_CUIT[#All],2,0)),"CUIT NO CARGADO") -> GOOGLE ARGENTINA S.R.L. | H13: 571266.35 | I13: =IF(compras_mes3[[#This Row],[NETO GRAVADO]]="","",compras_mes3[[#This Row],[NETO GRAVADO]]*0.21) -> 119965.93 | N13: 8569 | O13: 17137.99 | P13: =SUM(compras_mes3[[#This Row],[NETO GRAVADO]:[Otros / No Grav.]]) -> 716939.27 | Q13: =IFERROR(IF(compras_mes3[[#This Row],[CUIT]]="","-",VLOOKUP(compras_mes3[[#This Row],[CUIT]],Lista_CUIT[#All],3,0)),"CUIT NO CARGADO") -> Gastos Publicidad y Propaganda | R13: =IFERROR(IF(compras_mes3[[#This Row],[CUIT]]="","-",VLOOKUP(compras_mes3[[#This Row],[CUIT]],Lista_CUIT[#All],4,0)),"CUIT NO CARGADO") -> 0
B14: 31/03/2024 | C14: 1 | D14: 11 | E14: 967082 | F14: 33709585229 | G14: =IFERROR(IF(compras_mes3[[#This Row],[CUIT]]="","-",VLOOKUP(compras_mes3[[#This Row],[CUIT]],Lista_CUIT[#All],2,0)),"CUIT NO CARGADO") -> GOOGLE ARGENTINA S.R.L. | H14: 98213.46 | I14: =IF(compras_mes3[[#This Row],[NETO GRAVADO]]="","",compras_mes3[[#This Row],[NETO GRAVADO]]*0.21) -> 20624.827 | N14: 1473.2 | O14: 2946.4 | P14: =SUM(compras_mes3[[#This Row],[NETO GRAVADO]:[Otros / No Grav.]]) -> 123257.89 | Q14: =IFERROR(IF(compras_mes3[[#This Row],[CUIT]]="","-",VLOOKUP(compras_mes3[[#This Row],[CUIT]],Lista_CUIT[#All],3,0)),"CUIT NO CARGADO") -> Gastos Publicidad y Propaganda | R14: =IFERROR(IF(compras_mes3[[#This Row],[CUIT]]="","-",VLOOKUP(compras_mes3[[#This Row],[CUIT]],Lista_CUIT[#All],4,0)),"CUIT NO CARGADO") -> 0
B15: 31/03/2024 | C15: 1 | D15: 11 | E15: 965149 | F15: 33709585229 | G15: =IFERROR(IF(compras_mes3[[#This Row],[CUIT]]="","-",VLOOKUP(compras_mes3[[#This Row],[CUIT]],Lista_CUIT[#All],2,0)),"CUIT NO CARGADO") -> GOOGLE ARGENTINA S.R.L. | H15: 30531.42 | I15: =IF(compras_mes3[[#This Row],[NETO GRAVADO]]="","",compras_mes3[[#This Row],[NETO GRAVADO]]*0.21) -> 6411.5982 | N15: 457.97 | O15: 915.94 | P15: =SUM(compras_mes3[[#This Row],[NETO GRAVADO]:[Otros / No Grav.]]) -> 38316.928 | Q15: =IFERROR(IF(compras_mes3[[#This Row],[CUIT]]="","-",VLOOKUP(compras_mes3[[#This Row],[CUIT]],Lista_CUIT[#All],3,0)),"CUIT NO CARGADO") -> Gastos Publicidad y Propaganda | R15: =IFERROR(IF(compras_mes3[[#This Row],[CUIT]]="","-",VLOOKUP(compras_mes3[[#This Row],[CUIT]],Lista_CUIT[#All],4,0)),"CUIT NO CARGADO") -> 0
B16: 31/03/2024 | C16: 1 | D16: 11 | E16: 967210 | F16: 33709585229 | G16: =IFERROR(IF(compras_mes3[[#This Row],[CUIT]]="","-",VLOOKUP(compras_mes3[[#This Row],[CUIT]],Lista_CUIT[#All],2,0)),"CUIT NO CARGADO") -> GOOGLE ARGENTINA S.R.L. | H16: 47758.97 | I16: =IF(compras_mes3[[#This Row],[NETO GRAVADO]]="","",compras_mes3[[#This Row],[NETO GRAVADO]]*0.21) -> 10029.384 | N16: 716.38 | O16: 1432.77 | P16: =SUM(compras_mes3[[#This Row],[NETO GRAVADO]:[Otros / No Grav.]]) -> 59937.504 | Q16: =IFERROR(IF(compras_mes3[[#This Row],[CUIT]]="","-",VLOOKUP(compras_mes3[[#This Row],[CUIT]],Lista_CUIT[#All],3,0)),"CUIT NO CARGADO") -> Gastos Publicidad y Propaganda | R16: =IFERROR(IF(compras_mes3[[#This Row],[CUIT]]="","-",VLOOKUP(compras_mes3[[#This Row],[CUIT]],Lista_CUIT[#All],4,0)),"CUIT NO CARGADO") -> 0
B17: 31/03/2024 | C17: 3 | D17: 11 | E17: 707678 | F17: 33709585229 | G17: =IFERROR(IF(compras_mes3[[#This Row],[CUIT]]="","-",VLOOKUP(compras_mes3[[#This Row],[CUIT]],Lista_CUIT[#All],2,0)),"CUIT NO CARGADO") -> GOOGLE ARGENTINA S.R.L. | H17: -2192.75 | I17: =IF(compras_mes3[[#This Row],[NETO GRAVADO]]="","",compras_mes3[[#This Row],[NETO GRAVADO]]*0.21) -> -460.4775 | N17: -32.89 | O17: -65.78 | P17: =SUM(compras_mes3[[#This Row],[NETO GRAVADO]:[Otros / No Grav.]]) -> -2751.8975 | Q17: =IFERROR(IF(compras_mes3[[#This Row],[CUIT]]="","-",VLOOKUP(compras_mes3[[#This Row],[CUIT]],Lista_CUIT[#All],3,0)),"CUIT NO CARGADO") -> Gastos Publicidad y Propaganda | R17: =IFERROR(IF(compras_mes3[[#This Row],[CUIT]]="","-",VLOOKUP(compras_mes3[[#This Row],[CUIT]],Lista_CUIT[#All],4,0)),"CUIT NO CARGADO") -> 0
G18: =IFERROR(IF(compras_mes3[[#This Row],[CUIT]]="","-",VLOOKUP(compras_mes3[[#This Row],[CUIT]],Lista_CUIT[#All],2,0)),"CUIT NO CARGADO") -> - | I18: =IF(compras_mes3[[#This Row],[NETO GRAVADO]]="","",compras_mes3[[#This Row],[NETO GRAVADO]]*0.21) | P18: =SUM(compras_mes3[[#This Row],[NETO GRAVADO]:[Otros / No Grav.]]) -> 0 | Q18: =IFERROR(IF(compras_mes3[[#This Row],[CUIT]]="","-",VLOOKUP(compras_mes3[[#This Row],[CUIT]],Lista_CUIT[#All],3,0)),"CUIT NO CARGADO") -> - | R18: =IFERROR(IF(compras_mes3[[#This Row],[CUIT]]="","-",VLOOKUP(compras_mes3[[#This Row],[CUIT]],Lista_CUIT[#All],4,0)),"CUIT NO CARGADO") -> -
G19: =IFERROR(IF(compras_mes3[[#This Row],[CUIT]]="","-",VLOOKUP(compras_mes3[[#This Row],[CUIT]],Lista_CUIT[#All],2,0)),"CUIT NO CARGADO") -> - | I19: =IF(compras_mes3[[#This Row],[NETO GRAVADO]]="","",compras_mes3[[#This Row],[NETO GRAVADO]]*0.21) | P19: =SUM(compras_mes3[[#This Row],[NETO GRAVADO]:[Otros / No Grav.]]) -> 0 | Q19: =IFERROR(IF(compras_mes3[[#This Row],[CUIT]]="","-",VLOOKUP(compras_mes3[[#This Row],[CUIT]],Lista_CUIT[#All],3,0)),"CUIT NO CARGADO") -> - | R19: =IFERROR(IF(compras_mes3[[#This Row],[CUIT]]="","-",VLOOKUP(compras_mes3[[#This Row],[CUIT]],Lista_CUIT[#All],4,0)),"CUIT NO CARGADO") -> -
B20: Total | H20: =SUBTOTAL(109,compras_mes3[NETO GRAVADO]) -> 1081034.2 | I20: =SUBTOTAL(109,compras_mes3[IVA 21 %]) -> 227017.17 | J20: =SUBTOTAL(109,compras_mes3[IVA 27%]) -> 0 | K20: =SUBTOTAL(109,compras_mes3[IVA 10,5%]) -> 0 | L20: =SUBTOTAL(109,compras_mes3[PERC. IVA]) -> 0 | M20: =SUBTOTAL(109,compras_mes3[PERC IIBB BS AS]) -> 0 | N20: =SUBTOTAL(109,compras_mes3[PERC. IIBB CABA]) -> 16215.51 | O20: =SUBTOTAL(109,compras_mes3[Otros / No Grav.]) -> 32431.02 | P20: =SUBTOTAL(109,compras_mes3[TOTAL]) -> 1356697.9
D25: LIQUIDACION EXTRACTOS BANCARIOS-TARJETAS
D26: FECHA | E26: NRO CPTE | F26: BANCO | G26: NETO | H26: IVA 21% | I26: IVA 10,5% | J26: RET IIBB CABA | K26: PERC IVA | L26: PERC IIBB
D30: Total | G30: =SUBTOTAL(109,extracto_banco_mes3[NETO]) -> 0 | H30: =SUBTOTAL(109,extracto_banco_mes3[IVA 21%]) -> 0 | I30: =SUBTOTAL(109,extracto_banco_mes3[IVA 10,5%]) -> 0 | J30: =SUBTOTAL(109,extracto_banco_mes3[RET IIBB CABA]) -> 0 | K30: =SUBTOTAL(109,extracto_banco_mes3[PERC IVA]) -> 0 | L30: =SUBTOTAL(109,extracto_banco_mes3[PERC IIBB]) -> 0
D34: FACTURAS C
D35: FECHA | E35: PTO VTA | F35: FC Nº | G35: CUIT | H35: RAZON SOCIAL | I35: TOTAL | J35: TIPO DE GASTO | K35: Provincia
D36: 04/03/2024 | E36: 2 | F36: 732 | G36: 20400104094 | H36: =IFERROR(IF(factura_c_mes3[[#This Row],[CUIT]]="","-",VLOOKUP(factura_c_mes3[[#This Row],[CUIT]],Lista_CUIT[#All],2,0)),"CUIT NO CARGADO") -> BOTINDARI FEDERICO DANIEL | I36: 75000 | J36: =IFERROR(IF(factura_c_mes3[[#This Row],[CUIT]]="","-",VLOOKUP(factura_c_mes3[[#This Row],[CUIT]],Lista_CUIT[#All],3,0)),"CUIT NO CARGADO") -> HONORARIOS CONTABLE | K36: =IFERROR(IF(factura_c_mes3[[#This Row],[CUIT]]="","-",VLOOKUP(factura_c_mes3[[#This Row],[CUIT]],Lista_CUIT[#All],4,0)),"CUIT NO CARGADO") -> 0
D37: 05/03/2024 | E37: 1 | F37: 300 | G37: 27386311000 | H37: =IFERROR(IF(factura_c_mes3[[#This Row],[CUIT]]="","-",VLOOKUP(factura_c_mes3[[#This Row],[CUIT]],Lista_CUIT[#All],2,0)),"CUIT NO CARGADO") -> OPANASIUK MACARENA ANTONELLA | I37: 250000 | J37: =IFERROR(IF(factura_c_mes3[[#This Row],[CUIT]]="","-",VLOOKUP(factura_c_mes3[[#This Row],[CUIT]],Lista_CUIT[#All],3,0)),"CUIT NO CARGADO") -> Honorarios Profesionales | K37: =IFERROR(IF(factura_c_mes3[[#This Row],[CUIT]]="","-",VLOOKUP(factura_c_mes3[[#This Row],[CUIT]],Lista_CUIT[#All],4,0)),"CUIT NO CARGADO") -> 0
H38: =IFERROR(IF(factura_c_mes3[[#This Row],[CUIT]]="","-",VLOOKUP(factura_c_mes3[[#This Row],[CUIT]],Lista_CUIT[#All],2,0)),"CUIT NO CARGADO") -> - | J38: =IFERROR(IF(factura_c_mes3[[#This Row],[CUIT]]="","-",VLOOKUP(factura_c_mes3[[#This Row],[CUIT]],Lista_CUIT[#All],3,0)),"CUIT NO CARGADO") -> - | K38: =IFERROR(IF(factura_c_mes3[[#This Row],[CUIT]]="","-",VLOOKUP(factura_c_mes3[[#This Row],[CUIT]],Lista_CUIT[#All],4,0)),"CUIT NO CARGADO") -> -
H39: =IFERROR(IF(factura_c_mes3[[#This Row],[CUIT]]="","-",VLOOKUP(factura_c_mes3[[#This Row],[CUIT]],Lista_CUIT[#All],2,0)),"CUIT NO CARGADO") -> - | J39: =IFERROR(IF(factura_c_mes3[[#This Row],[CUIT]]="","-",VLOOKUP(factura_c_mes3[[#This Row],[CUIT]],Lista_CUIT[#All],3,0)),"CUIT NO CARGADO") -> - | K39: =IFERROR(IF(factura_c_mes3[[#This Row],[CUIT]]="","-",VLOOKUP(factura_c_mes3[[#This Row],[CUIT]],Lista_CUIT[#All],4,0)),"CUIT NO CARGADO") -> -
D40: Total | I40: =SUBTOTAL(109,factura_c_mes3[TOTAL]) -> 325000
B46: LIBRO IVA VENTAS | K46: =N1 -> 45352
B48: VENTAS "A"
B49: FECHA | C49: TIPO | D49: PTO VENTA | E49: Nº FACTURA | F49: CUIT | G49: RAZON SOCIAL | H49: IMPORTE NETO | I49: IVA 21% | J49: IVA 10,5% | K49: EXENTO | L49: TOTAL | M49: Provincia
B50: 01/03/2024 | C50: 1 | D50: 1 | E50: 150 | F50: 30715941763 | G50: =IFERROR(IF(venta_a_mes3[[#This Row],[CUIT]]="","-",VLOOKUP(venta_a_mes3[[#This Row],[CUIT]],Lista_CUIT[#All],2,0)),"CUIT NO CARGADO") -> TOURMALHYN S.R.L. | H50: 20661.14 | I50: =venta_a_mes3[[#This Row],[IMPORTE NETO]]*0.21 -> 4338.8394 | L50: =SUM(venta_a_mes3[[#This Row],[IMPORTE NETO]:[EXENTO]]) -> 24999.979
B51: 01/03/2024 | C51: 1 | D51: 1 | E51: 151 | F51: 30717969061 | G51: =IFERROR(IF(venta_a_mes3[[#This Row],[CUIT]]="","-",VLOOKUP(venta_a_mes3[[#This Row],[CUIT]],Lista_CUIT[#All],2,0)),"CUIT NO CARGADO") -> FABIO Y RAUL ROSSO S.A.S. | H51: 37685.95 | I51: =venta_a_mes3[[#This Row],[IMPORTE NETO]]*0.21 -> 7914.0495 | L51: =SUM(venta_a_mes3[[#This Row],[IMPORTE NETO]:[EXENTO]]) -> 45599.999
B52: 01/03/2024 | C52: 1 | D52: 1 | E52: 154 | F52: 30688955749 | G52: =IFERROR(IF(venta_a_mes3[[#This Row],[CUIT]]="","-",VLOOKUP(venta_a_mes3[[#This Row],[CUIT]],Lista_CUIT[#All],2,0)),"CUIT NO CARGADO") -> LISERAR S A | H52: 96694.24 | I52: =venta_a_mes3[[#This Row],[IMPORTE NETO]]*0.21 -> 20305.79 | L52: =SUM(venta_a_mes3[[#This Row],[IMPORTE NETO]:[EXENTO]]) -> 117000.03
B53: 01/03/2024 | C53: 1 | D53: 1 | E53: 146 | F53: 27165844748 | G53: =IFERROR(IF(venta_a_mes3[[#This Row],[CUIT]]="","-",VLOOKUP(venta_a_mes3[[#This Row],[CUIT]],Lista_CUIT[#All],2,0)),"CUIT NO CARGADO") -> DENATALE MARCELA BEATRIZ | H53: 96694.24 | I53: =venta_a_mes3[[#This Row],[IMPORTE NETO]]*0.21 -> 20305.79 | L53: =SUM(venta_a_mes3[[#This Row],[IMPORTE NETO]:[EXENTO]]) -> 117000.03
B54: 01/03/2024 | C54: 1 | D54: 1 | E54: 148 | F54: 20279415656 | G54: =IFERROR(IF(venta_a_mes3[[#This Row],[CUIT]]="","-",VLOOKUP(venta_a_mes3[[#This Row],[CUIT]],Lista_CUIT[#All],2,0)),"CUIT NO CARGADO") -> CECCO ALVARO GONZALO | H54: 75371.9 | I54: =venta_a_mes3[[#This Row],[IMPORTE NETO]]*0.21 -> 15828.099 | L54: =SUM(venta_a_mes3[[#This Row],[IMPORTE NETO]:[EXENTO]]) -> 91199.999
B55: 01/03/2024 | C55: 1 | D55: 1 | E55: 143 | F55: 20284212488 | G55: =IFERROR(IF(venta_a_mes3[[#This Row],[CUIT]]="","-",VLOOKUP(venta_a_mes3[[#This Row],[CUIT]],Lista_CUIT[#All],2,0)),"CUIT NO CARGADO") -> BARLETTA MAXIMILIANO SEBASTIAN | H55: 37685.95 | I55: =venta_a_mes3[[#This Row],[IMPORTE NETO]]*0.21 -> 7914.0495 | L55: =SUM(venta_a_mes3[[#This Row],[IMPORTE NETO]:[EXENTO]]) -> 45599.999
B56: 01/03/2024 | C56: 1 | D56: 1 | E56: 149 | F56: 20367341808 | G56: =IFERROR(IF(venta_a_mes3[[#This Row],[CUIT]]="","-",VLOOKUP(venta_a_mes3[[#This Row],[CUIT]],Lista_CUIT[#All],2,0)),"CUIT NO CARGADO") -> FEIDAS FERNANDO EMILIANO | H56: 49586.76 | I56: =venta_a_mes3[[#This Row],[IMPORTE NETO]]*0.21 -> 10413.22 | L56: =SUM(venta_a_mes3[[#This Row],[IMPORTE NETO]:[EXENTO]]) -> 59999.98
B57: 01/03/2024 | C57: 1 | D57: 1 | E57: 145 | F57: 30717973166 | G57: =IFERROR(IF(venta_a_mes3[[#This Row],[CUIT]]="","-",VLOOKUP(venta_a_mes3[[#This Row],[CUIT]],Lista_CUIT[#All],2,0)),"CUIT NO CARGADO") -> STM ESTILO S.R.L | H57: 37685.95 | I57: =venta_a_mes3[[#This Row],[IMPORTE NETO]]*0.21 -> 7914.0495 | L57: =SUM(venta_a_mes3[[#This Row],[IMPORTE NETO]:[EXENTO]]) -> 45599.999
B58: 01/03/2024 | C58: 1 | D58: 1 | E58: 144 | F58: 30715380567 | G58: =IFERROR(IF(venta_a_mes3[[#This Row],[CUIT]]="","-",VLOOKUP(venta_a_mes3[[#This Row],[CUIT]],Lista_CUIT[#All],2,0)),"CUIT NO CARGADO") -> SENS GROUP SRL | H58: 141205.24 | I58: =venta_a_mes3[[#This Row],[IMPORTE NETO]]*0.21 -> 29653.1 | L58: =SUM(venta_a_mes3[[#This Row],[IMPORTE NETO]:[EXENTO]]) -> 170858.34
B59: 01/03/2024 | C59: 1 | D59: 1 | E59: 142 | F59: 30717477681 | G59: =IFERROR(IF(venta_a_mes3[[#This Row],[CUIT]]="","-",VLOOKUP(venta_a_mes3[[#This Row],[CUIT]],Lista_CUIT[#All],2,0)),"CUIT NO CARGADO") -> GRUPO FAM SA | H59: 52479.33 | I59: =venta_a_mes3[[#This Row],[IMPORTE NETO]]*0.21 -> 11020.659 | L59: =SUM(venta_a_mes3[[#This Row],[IMPORTE NETO]:[EXENTO]]) -> 63499.989
B60: 01/03/2024 | C60: 1 | D60: 1 | E60: 141 | F60: 30716914077 | G60: =IFERROR(IF(venta_a_mes3[[#This Row],[CUIT]]="","-",VLOOKUP(venta_a_mes3[[#This Row],[CUIT]],Lista_CUIT[#All],2,0)),"CUIT NO CARGADO") -> BACANES | H60: 96694.24 | I60: =venta_a_mes3[[#This Row],[IMPORTE NETO]]*0.21 -> 20305.79 | L60: =SUM(venta_a_mes3[[#This Row],[IMPORTE NETO]:[EXENTO]]) -> 117000.03
...

Sheet Abr-24
B1: LIBRO IVA COMPRAS | G1: ='Ene-24'!G1:M1 -> RABLEB SRL | N1: =EDATE('Ene-24'!N1,3) -> 45383
B3: TOTAL COMPRAS | G3: TOTAL CREDITO FISCAL | J3: TOTAL VENTAS NETAS | M3: TOTAL DEBITO FISCAL | P3: RESULTADO
B4: =SUM(compras_mes4[[#Totals],[NETO GRAVADO]])+extracto_banco_mes4[[#Totals],[NETO]] -> 1085466.4 | G4: =compras_mes4[[#Totals],[IVA 21 %]]+compras_mes4[[#Totals],[IVA 27%]]+compras_mes4[[#Totals],[IVA 10,5%]]+extracto_banco_mes4[[#Totals],[IVA 21%]]+extracto_banco_mes4[[#Totals],[IVA 10,5%]] -> 227947.95 | J4: =venta_a_mes4[[#Totals],[IMPORTE NETO]]+ventas_b_mes4[[#Totals],[IMPORTE NETO]] -> 1892977 | M4: =venta_a_mes4[[#Totals],[IVA 21%]]+venta_a_mes4[[#Totals],[IVA 10,5%]]+ventas_b_mes4[[#Totals],[IVA 21%]]+ventas_b_mes4[[#Totals],[IVA 10,5%]] -> 397525.18 | P4: =G4-M4 -> -169577.23
B8: FECHA | C8: TIPO | D8: PTO VTA | E8: NRO. CPTE | F8: CUIT | G8: RAZON SOCIAL | H8: NETO GRAVADO | I8: IVA 21 % | J8: IVA 27% | K8: IVA 10,5% | L8: PERC. IVA | M8: PERC IIBB BS AS | N8: PERC. IIBB CABA | O8: Otros / No Grav. | P8: TOTAL | Q8: Tipo de Gasto | R8: Provincia
B9: 45408 | C9: 1 | D9: 11 | E9: 967928 | F9: 33709585229 | G9: =IFERROR(IF(compras_mes4[[#This Row],[CUIT]]="","-",VLOOKUP(compras_mes4[[#This Row],[CUIT]],Lista_CUIT[#All],2,0)),"CUIT NO CARGADO") -> GOOGLE ARGENTINA S.R.L. | H9: 10880.12 | I9: =IF(compras_mes4[[#This Row],[NETO GRAVADO]]="","",compras_mes4[[#This Row],[NETO GRAVADO]]*0.21) -> 2284.8252 | L9: 326.4 | N9: 163.2 | P9: =SUM(compras_mes4[[#This Row],[NETO GRAVADO]:[Otros / No Grav.]]) -> 13654.545 | Q9: =IFERROR(IF(compras_mes4[[#This Row],[CUIT]]="","-",VLOOKUP(compras_mes4[[#This Row],[CUIT]],Lista_CUIT[#All],3,0)),"CUIT NO CARGADO") -> Gastos Publicidad y Propaganda | R9: =IFERROR(IF(compras_mes4[[#This Row],[CUIT]]="","-",VLOOKUP(compras_mes4[[#This Row],[CUIT]],Lista_CUIT[#All],4,0)),"CUIT NO CARGADO") -> 0
B10: 45412 | C10: 1 | D10: 11 | E10: 976843 | F10: 33709585229 | G10: =IFERROR(IF(compras_mes4[[#This Row],[CUIT]]="","-",VLOOKUP(compras_mes4[[#This Row],[CUIT]],Lista_CUIT[#All],2,0)),"CUIT NO CARGADO") -> GOOGLE ARGENTINA S.R.L. | H10: 173192.04 | I10: =IF(compras_mes4[[#This Row],[NETO GRAVADO]]="","",compras_mes4[[#This Row],[NETO GRAVADO]]*0.21) -> 36370.328 | L10: 5195.76 | N10: 2597.88 | P10: =SUM(compras_mes4[[#This Row],[NETO GRAVADO]:[Otros / No Grav.]]) -> 217356.01 | Q10: =IFERROR(IF(compras_mes4[[#This Row],[CUIT]]="","-",VLOOKUP(compras_mes4[[#This Row],[CUIT]],Lista_CUIT[#All],3,0)),"CUIT NO CARGADO") -> Gastos Publicidad y Propaganda | R10: =IFERROR(IF(compras_mes4[[#This Row],[CUIT]]="","-",VLOOKUP(compras_mes4[[#This Row],[CUIT]],Lista_CUIT[#All],4,0)),"CUIT NO CARGADO") -> 0
B11: 45412 | C11: 1 | D11: 11 | E11: 971874 | F11: 33709585229 | G11: =IFERROR(IF(compras_mes4[[#This Row],[CUIT]]="","-",VLOOKUP(compras_mes4[[#This Row],[CUIT]],Lista_CUIT[#All],2,0)),"CUIT NO CARGADO") -> GOOGLE ARGENTINA S.R.L. | H11: 152788.55 | I11: =IF(compras_mes4[[#This Row],[NETO GRAVADO]]="","",compras_mes4[[#This Row],[NETO GRAVADO]]*0.21) -> 32085.595 | L11: 4583.66 | N11: 2291.83 | P11: =SUM(compras_mes4[[#This Row],[NETO GRAVADO]:[Otros / No Grav.]]) -> 191749.64 | Q11: =IFERROR(IF(compras_mes4[[#This Row],[CUIT]]="","-",VLOOKUP(compras_mes4[[#This Row],[CUIT]],Lista_CUIT[#All],3,0)),"CUIT NO CARGADO") -> Gastos Publicidad y Propaganda | R11: =IFERROR(IF(compras_mes4[[#This Row],[CUIT]]="","-",VLOOKUP(compras_mes4[[#This Row],[CUIT]],Lista_CUIT[#All],4,0)),"CUIT NO CARGADO") -> 0
B12: 45412 | C12: 1 | D12: 11 | E12: 969884 | F12: 33709585229 | G12: =IFERROR(IF(compras_mes4[[#This Row],[CUIT]]="","-",VLOOKUP(compras_mes4[[#This Row],[CUIT]],Lista_CUIT[#All],2,0)),"CUIT NO CARGADO") -> GOOGLE ARGENTINA S.R.L. | H12: 32999.28 | I12: =IF(compras_mes4[[#This Row],[NETO GRAVADO]]="","",compras_mes4[[#This Row],[NETO GRAVADO]]*0.21) -> 6929.8488 | L12: 989.98 | N12: 494.99 | P12: =SUM(compras_mes4[[#This Row],[NETO GRAVADO]:[Otros / No Grav.]]) -> 41414.099 | Q12: =IFERROR(IF(compras_mes4[[#This Row],[CUIT]]="","-",VLOOKUP(compras_mes4[[#This Row],[CUIT]],Lista_CUIT[#All],3,0)),"CUIT NO CARGADO") -> Gastos Publicidad y Propaganda | R12: =IFERROR(IF(compras_mes4[[#This Row],[CUIT]]="","-",VLOOKUP(compras_mes4[[#This Row],[CUIT]],Lista_CUIT[#All],4,0)),"CUIT NO CARGADO") -> 0
B13: 45412 | C13: 1 | D13: 11 | E13: 971340 | F13: 33709585229 | G13: =IFERROR(IF(compras_mes4[[#This Row],[CUIT]]="","-",VLOOKUP(compras_mes4[[#This Row],[CUIT]],Lista_CUIT[#All],2,0)),"CUIT NO CARGADO") -> GOOGLE ARGENTINA S.R.L. | H13: 597227.95 | I13: =IF(compras_mes4[[#This Row],[NETO GRAVADO]]="","",compras_mes4[[#This Row],[NETO GRAVADO]]*0.21) -> 125417.87 | L13: 17916.84 | N13: 8958.42 | P13: =SUM(compras_mes4[[#This Row],[NETO GRAVADO]:[Otros / No Grav.]]) -> 749521.08 | Q13: =IFERROR(IF(compras_mes4[[#This Row],[CUIT]]="","-",VLOOKUP(compras_mes4[[#This Row],[CUIT]],Lista_CUIT[#All],3,0)),"CUIT NO CARGADO") -> Gastos Publicidad y Propaganda | R13: =IFERROR(IF(compras_mes4[[#This Row],[CUIT]]="","-",VLOOKUP(compras_mes4[[#This Row],[CUIT]],Lista_CUIT[#All],4,0)),"CUIT NO CARGADO") -> 0
B14: 45412 | C14: 1 | D14: 11 | E14: 977142 | F14: 33709585229 | G14: =IFERROR(IF(compras_mes4[[#This Row],[CUIT]]="","-",VLOOKUP(compras_mes4[[#This Row],[CUIT]],Lista_CUIT[#All],2,0)),"CUIT NO CARGADO") -> GOOGLE ARGENTINA S.R.L. | H14: 52051.21 | I14: =IF(compras_mes4[[#This Row],[NETO GRAVADO]]="","",compras_mes4[[#This Row],[NETO GRAVADO]]*0.21) -> 10930.754 | L14: 1561.54 | N14: 780.77 | P14: =SUM(compras_mes4[[#This Row],[NETO GRAVADO]:[Otros / No Grav.]]) -> 65324.274 | Q14: =IFERROR(IF(compras_mes4[[#This Row],[CUIT]]="","-",VLOOKUP(compras_mes4[[#This Row],[CUIT]],Lista_CUIT[#All],3,0)),"CUIT NO CARGADO") -> Gastos Publicidad y Propaganda | R14: =IFERROR(IF(compras_mes4[[#This Row],[CUIT]]="","-",VLOOKUP(compras_mes4[[#This Row],[CUIT]],Lista_CUIT[#All],4,0)),"CUIT NO CARGADO") -> 0
B15: 45412 | C15: 1 | D15: 11 | E15: 977820 | F15: 33709585229 | G15: =IFERROR(IF(compras_mes4[[#This Row],[CUIT]]="","-",VLOOKUP(compras_mes4[[#This Row],[CUIT]],Lista_CUIT[#All],2,0)),"CUIT NO CARGADO") -> GOOGLE ARGENTINA S.R.L. | H15: 3153.56 | I15: =IF(compras_mes4[[#This Row],[NETO GRAVADO]]="","",compras_mes4[[#This Row],[NETO GRAVADO]]*0.21) -> 662.2476 | L15: 94.61 | N15: 47.3 | P15: =SUM(compras_mes4[[#This Row],[NETO GRAVADO]:[Otros / No Grav.]]) -> 3957.7176 | Q15: =IFERROR(IF(compras_mes4[[#This Row],[CUIT]]="","-",VLOOKUP(compras_mes4[[#This Row],[CUIT]],Lista_CUIT[#All],3,0)),"CUIT NO CARGADO") -> Gastos Publicidad y Propaganda | R15: =IFERROR(IF(compras_mes4[[#This Row],[CUIT]]="","-",VLOOKUP(compras_mes4[[#This Row],[CUIT]],Lista_CUIT[#All],4,0)),"CUIT NO CARGADO") -> 0
